Workbook
Name GOOGL_Drivers_01: 'Revenue Drivers'!$A$6:$EP$136
Name GOOGL_Drivers_02: 'Revenue Drivers'!$A$168:$EP$320
Name GOOGL_IS: IS!$A$6:$EP$182
Name GOOGL_JPMe_vs_Actual: #REF!
Name GOOGL_JPMe_vs_BBRG: #REF!
Name GOOGL_Old_New: #REF!
Name GOOGL_Segments: 'Segment As Reported'!$A$6:$EP$37
Name Linking_1: #REF!
Name Linking_2: 'Segment As Reported'!$A$6:$EP$34
Name Linking_3: #REF!
Name Linking_4: #REF!
Name Threshold: 0.01

Sheet CoverSheet
N2: North America Equities Research
N3: 45960
B7: Company Model
B9: Alphabet Inc. (GOOGL)
B11: Doug Anmuth
B12: (212) 622-6571
B13: douglas.anmuth@jpmorgan.com
B14: J.P. Morgan Securities LLC
B16: Dae Lee
B17: (415) 315-8500
B18: dae.k.lee@jpmorgan.com
B19: J.P. Morgan Securities LLC
B21: Margaret Hoffman
B22: (212) 622-1710
... B30: #$J&098$#*P

Sheet IS
A2: Alphabet Inc.
A3: Income Statement
BO5: with mmi, values only | BY5: Incl. Motorola | FA5: 3 yr CAGR | FB5: 3 yr CAGR | FC5: 3 yr CAGR | FD5: 3 yr CAGR | FE5: 3 yr CAGR | FF5: 3 yr CAGR | FG5: 5 yr CAGR | FH5: 5 yr CAGR | FI5: 5 yr CAGR | FJ5: 5 yr CAGR | FK5: 5 yr CAGR | FL5: 5 yr CAGR
A6: $ in millions, except per share amounts | B6: 3/99A | C6: 6/99A | D6: 9/99A | E6: 12/99A | F6: 1999A | G6: 3/00A | H6: 6/00A | I6: 9/00A | J6: 12/00A | K6: 2000A | L6: 3/01A | M6: 6/01A | N6: 9/01A | O6: 12/01A | P6: 2001A | Q6: 3/02A | R6: 6/02A | S6: 9/02A | T6: 12/02A | U6: 2002A | V6: 3/03A | W6: 6/03A | X6: 9/03A | Y6: 12/03A | Z6: 2003A | AA6: 3/04A | AB6: 6/04A | AC6: 9/04A | AD6: 12/04A | AE6: 2004A | AF6: 3/05A | AG6: 6/05A | AH6: 9/05A | AI6: 12/05A | AJ6: 2005A | AK6: 3/06A | AL6: 6/06A | AM6: 9/06A | AN6: 12/06A | AO6: 2006A | AP6: 3/07A | AQ6: 6/07A | AR6: 9/07A | AS6: 12/07A | AT6: 2007A | AU6: 3/08A | AV6: 6/08A | AW6: 9/08A | AX6: 12/08A | AY6: 2008A | AZ6: 3/09A | BA6: 6/09A | BB6: 9/09A | BC6: 12/09A | BD6: 2009A | BE6: 3/10A | BF6: 6/10A | BG6: 9/10A | BH6: 12/10A | BI6: 2010A | BJ6: 3/11A | BK6: 6/11A | BL6: 9/11A | BM6: 12/11A | BN6: 2011A | BO6: 3/12A | BP6: 6/12A | BQ6: 9/12A | BR6: 12/12A | BS6: 2012A | BT6: 3/12A | BU6: 6/12A | BV6: 9/12A | BW6: 12/12A | BX6: 2012A | BY6: 3/13A | BZ6: 6/13A | CA6: 9/13A | CB6: 12/13A | CC6: 2013A | CD6: 3/13A | CE6: 6/13A | CF6: 9/13A | CG6: 12/13A | CH6: 2013A | CI6: 3/14A | CJ6: 6/14A | CK6: 9/14A | CL6: 12/14A | CM6: 2014A | CN6: 3/15A | CO6: 6/15A | CP6: 9/15A | CQ6: 12/15A | CR6: 2015A | CS6: 3/16A | CT6: 6/16A | CU6: 9/16A | CV6: 12/16A | CW6: 2016A | CX6: 3/17A | CY6: 6/17A | CZ6: 9/17A | DA6: 12/17A | DB6: 2017A | DC6: 3/18A | DD6: 6/18A | DE6: 9/18A | DF6: 12/18A | DG6: 2018A | DH6: 3/19A | DI6: 6/19A | DJ6: 9/19A | DK6: 12/19A | DL6: 2019A | DM6: 3/20A | DN6: 6/20A | DO6: 9/20A | DP6: 12/20A | DQ6: 2020A | DR6: 3/21A | DS6: 6/21A | DT6: 9/21A | DU6: 12/21A | DV6: 2021A | DW6: 3/22A | DX6: 6/22A | DY6: 9/22A | DZ6: 12/22A | EA6: 2022A | EB6: 3/23A | EC6: 6/23A | ED6: 9/23A | EE6: 12/23A | EF6: 2023A | EG6: 3/24A | EH6: 6/24A | EI6: 9/24A | EJ6: 12/24A | EK6: 2024A | EL6: 3/25A | EM6: 6/25A | EN6: 9/25A | EO6: 12/25E | EP6: 2025E | EQ6: 3/26E | ER6: 6/26E | ES6: 9/26E | ET6: 12/26E | EU6: 2026E | EV6: 2027E | EW6: 2028E | EX6: 2029E | EY6: 2030E | FA6: 2019-2022 | FB6: 2020-2023 | FC6: 2021-2024 | FD6: 2022-2025 | FE6: 2023-2026 | FF6: 2024-2027 | FG6: 2019-2024 | FH6: 2020-2025 | FI6: 2021-2026 | FJ6: 2022-2027 | FK6: 2023-2028 | FL6: 2024-2029
A7: Gross Revenues | F7: 0.22 | K7: 19.108 | P7: 86.426 | Q7: 42.285 | R7: 78.525 | S7: 130.787 | T7: 187.911 | U7: =SUM(Q7:T7) -> 439.508 | V7: 248.618 | W7: 311.199 | X7: 393.942 | Y7: 512.175 | Z7: =Z9+Z8 -> 1465.934 | AA7: 651.623 | AB7: 700.212 | AC7: 805.887 | AD7: 1031.501 | AE7: =SUM(AA7:AD7) -> 3189.223 | AF7: 1256.516 | AG7: 1384.495 | AH7: 1578.456 | AI7: 1919.093 | AJ7: =SUM(AF7:AI7) -> 6138.56 | AK7: 2253.755 | AL7: 2455.991 | AM7: 2689.673 | AN7: 3205.498 | AO7: =SUM(AK7:AN7) -> 10604.917 | AP7: 3663.971 | AQ7: 3871.985 | AR7: 4231.351 | AS7: 4826.679 | AT7: =SUM(AP7:AS7) -> 16593.986 | AU7: 5186.043 | AV7: 5367.212 | AW7: 5541.391 | AX7: =5700.904 -> 5700.904 | AY7: =SUM(AU7:AX7) -> 21795.55 | AZ7: 5508.99 | BA7: 5522.897 | BB7: 5944.851 | BC7: =6673.825 -> 6673.825 | BD7: =SUM(AZ7:BC7) -> 23650.563 | BE7: 6775 | BF7: 6820 | BG7: 7286 | BH7: =8440 -> 8440 | BI7: =SUM(BE7:BH7) -> 29321 | BJ7: 8575 | BK7: 9026 | BL7: 9720 | BM7: 10584 | BN7: =SUM(BJ7:BM7) -> 37905 | BO7: 10645 | BP7: 12214 | BQ7: 14101 | BR7: 14419 | BS7: 51379 | BT7: ='Revenue Drivers'!BT69 -> 10645 | BU7: ='Revenue Drivers'!BU69 -> 10964 | BV7: ='Revenue Drivers'!BV69 -> 11526 | BW7: ='Revenue Drivers'!BW69 -> 12905 | BX7: 46039 | BY7: ='Revenue Drivers'!BY69 -> 0 | BZ7: ='Revenue Drivers'!BZ69 -> 0 | CA7: ='Revenue Drivers'!CA69 -> 0 | CB7: ='Revenue Drivers'!CB69 -> 0 | CC7: ='Revenue Drivers'!CC69 -> 0 | CD7: ='Revenue Drivers'!CD69 -> 12951 | CE7: ='Revenue Drivers'!CE69 -> 13107 | CF7: ='Revenue Drivers'!CF69 -> 13754 | ... EY7: ='Revenue Drivers'!EY69 -> 722335.87 | FA7: =(EA7/DL7)^(1/3)-1 -> 0.20448409 | FB7: =(EF7/DQ7)^(1/3)-1 -> 0.18975103 | FC7: =(EK7/DV7)^(1/3)-1 -> 0.1075433 | FD7: =(EP7/EA7)^(1/3)-1 -> 0.123643 | FE7: =(EU7/EF7)^(1/3)-1 -> 0.15065051 | FF7: =(EV7/EK7)^(1/3)-1 -> 0.14884805 | FG7: =(EK7/DL7)^(1/5)-1 -> 0.16678753 | FH7: =(EP7/DQ7)^(1/5)-1 -> 0.17062697 | FI7: =(EU7/DV7)^(1/5)-1 -> 0.126947 | FJ7: =(EV7/EA7)^(1/5)-1 -> 0.13414529 | FK7: =(EW7/EF7)^(1/5)-1 -> 0.14090809 | FL7: =(EX7/EK7)^(1/5)-1 -> 0.13424636
A8: Traffic Acquisition Costs (TAC) | F8: 0 | K8: 0 | P8: 0 | Q8: ='Revenue Drivers'!Q105 -> 0 | R8: ='Revenue Drivers'!R105 -> 14 | S8: ='Revenue Drivers'!S105 -> 29 | T8: ='Revenue Drivers'!T105 -> 51.5 | U8: 94.5 | V8: ='Revenue Drivers'!V105 -> 70.131 | W8: ='Revenue Drivers'!W105 -> 96.559 | X8: ='Revenue Drivers'!X105 -> 143.487 | Y8: ='Revenue Drivers'!Y105 -> 216.356 | Z8: =SUM(V8:Y8) -> 526.533 | AA8: ='Revenue Drivers'!AA105 -> 271.002 | AB8: ='Revenue Drivers'!AB105 -> 277.034 | AC8: ='Revenue Drivers'!AC105 -> 302.9 | AD8: ='Revenue Drivers'!AD105 -> 377.708 | AE8: =SUM(AA8:AD8) -> 1228.644 | AF8: 461.807 | AG8: 494.32 | AH8: 529.874 | AI8: 628.941 | AJ8: =SUM(AF8:AI8) -> 2114.942 | AK8: 722.736 | AL8: 785.159 | AM8: 825.264 | AN8: 975.618 | AO8: =SUM(AK8:AN8) -> 3308.777 | AP8: 1125.032 | AQ8: 1147.913 | AR8: 1221.12 | AS8: =1439.814 -> 1439.814 | AT8: =SUM(AP8:AS8) -> 4933.879 | AU8: =1486.384 -> 1486.384 | AV8: 1473.98 | AW8: 1495.206 | AX8: 1483.382 | AY8: =SUM(AU8:AX8) -> 5938.952 | AZ8: 1435.96 | BA8: 1453.354 | BB8: 1559.216 | BC8: 1720.886 | BD8: =SUM(AZ8:BC8) -> 6169.416 | BE8: 1711 | BF8: 1732 | BG8: 1805 | BH8: =2069 -> 2069 | BI8: =SUM(BE8:BH8) -> 7317 | BJ8: 2038 | BK8: 2110 | BL8: 2210 | BM8: 2450 | BN8: =SUM(BJ8:BM8) -> 8808 | BO8: 2510 | BP8: 2600 | BQ8: 2770 | BR8: 3080 | BS8: 10960 | BT8: =+'Revenue Drivers'!BT105 -> 2510 | BU8: =+'Revenue Drivers'!BU105 -> 2600 | BV8: =+'Revenue Drivers'!BV105 -> 2770 | BW8: =+'Revenue Drivers'!BW105 -> 3080 | BX8: 10956 | BY8: 2962 | BZ8: 3013 | CA8: 2972 | CB8: 3310 | CC8: 12257 | CD8: ='Revenue Drivers'!CD105 -> 2962 | CE8: ='Revenue Drivers'!CE105 -> 3013 | CF8: ='Revenue Drivers'!CF105 -> 2972 | CG8: ='Revenue Drivers'!CG105 -> 3310 | CH8: 12258 | CI8: 3232 | CJ8: ='Revenue Drivers'!CJ105 -> 3293 | CK8: ='Revenue Drivers'!CK105 -> 3348 | CL8: ='Revenue Drivers'!CL105 -> 3620 | CM8: 13497 | CN8: 3345 | CO8: ='Revenue Drivers'!CO105 -> 3377 | CP8: ='Revenue Drivers'!CP105 -> 3566 | CQ8: ='Revenue Drivers'!CQ105 -> 4055 | CR8: ='Revenue Drivers'!CR105 -> 14343 | CS8: ='Revenue Drivers'!CS105 -> 3788 | CT8: ='Revenue Drivers'!CT105 -> 3975 | CU8: ='Revenue Drivers'!CU105 -> 4182 | CV8: ='Revenue Drivers'!CV105 -> 4848 | ... EY8: ='Revenue Drivers'!EY105 -> 85065.792 | FA8: =(EA8/DL8)^(1/3)-1 -> 0.17615105 | FB8: =(EF8/DQ8)^(1/3)-1 -> 0.1579024 | FC8: =(EK8/DV8)^(1/3)-1 -> 0.064087022 | FD8: =(EP8/EA8)^(1/3)-1 -> 0.067707297 | FE8: =(EU8/EF8)^(1/3)-1 -> 0.085399978 | FF8: =(EV8/EK8)^(1/3)-1 -> 0.085380122 | FG8: =(EK8/DL8)^(1/5)-1 -> 0.12780215 | FH8: =(EP8/DQ8)^(1/5)-1 -> 0.12697491 | FI8: =(EU8/DV8)^(1/5)-1 -> 0.073854315 | FJ8: =(EV8/EA8)^(1/5)-1 -> 0.074741888 | FK8: =(EW8/EF8)^(1/5)-1 -> 0.081875981 | FL8: =(EX8/EK8)^(1/5)-1 -> 0.078828557
A9: Net Revenues excluding TAC | F9: =F7-F8 -> 0.22 | K9: =K7-K8 -> 19.108 | P9: =P7-P8 -> 86.426 | Q9: =Q7-Q8 -> 42.285 | R9: =R7-R8 -> 64.525 | S9: =S7-S8 -> 101.787 | T9: =T7-T8 -> 136.411 | U9: =U7-U8 -> 345.008 | V9: =V7-V8 -> 178.487 | W9: =W7-W8 -> 214.64 | ... Y9: =Y7-Y8 -> 295.819 | Z9: =SUM(V9:Y9) -> 939.401 | AA9: =AA7-AA8 -> 380.621 | AB9: =AB7-AB8 -> 423.178 | AC9: =AC7-AC8 -> 502.987 | AD9: =AD7-AD8 -> 653.793 | AE9: =SUM(AA9:AD9) -> 1960.579 | AF9: =AF7-AF8 -> 794.709 | AG9: =AG7-AG8 -> 890.175 | AH9: =AH7-AH8 -> 1048.582 | AI9: =AI7-AI8 -> 1290.152 | AJ9: =SUM(AF9:AI9) -> 4023.618 | AK9: =AK7-AK8 -> 1531.019 | AL9: =AL7-AL8 -> 1670.832 | AM9: =AM7-AM8 -> 1864.409 | AN9: =AN7-AN8 -> 2229.88 | AO9: =SUM(AK9:AN9) -> 7296.14 | AP9: =AP7-AP8 -> 2538.939 | AQ9: =AQ7-AQ8 -> 2724.072 | AR9: =AR7-AR8 -> 3010.231 | AS9: =AS7-AS8 -> 3386.865 | AT9: =SUM(AP9:AS9) -> 11660.107 | AU9: =AU7-AU8 -> 3699.659 | AV9: =AV7-AV8 -> 3893.232 | AW9: =AW7-AW8 -> 4046.185 | AX9: =AX7-AX8 -> 4217.522 | AY9: =SUM(AU9:AX9) -> 15856.598 | AZ9: =AZ7-AZ8 -> 4073.03 | BA9: =BA7-BA8 -> 4069.543 | BB9: =BB7-BB8 -> 4385.635 | BC9: =BC7-BC8 -> 4952.939 | BD9: =SUM(AZ9:BC9) -> 17481.147 | BE9: =BE7-BE8 -> 5064 | BF9: =BF7-BF8 -> 5088 | BG9: =BG7-BG8 -> 5481 | BH9: =BH7-BH8 -> 6371 | BI9: =SUM(BE9:BH9) -> 22004 | BJ9: =BJ7-BJ8 -> 6537 | BK9: =BK7-BK8 -> 6916 | BL9: =BL7-BL8 -> 7510 | BM9: =BM7-BM8 -> 8134 | BN9: =SUM(BJ9:BM9) -> 29097 | BO9: 8135 | BP9: 9614 | BQ9: 11331 | BR9: 11339 | BS9: 40419 | BT9: =BT7-BT8 -> 8135 | BU9: =BU7-BU8 -> 8364 | BV9: =BV7-BV8 -> 8756 | BW9: =BW7-BW8 -> 9825 | BX9: =BX7-BX8 -> 35083 | BY9: 11007 | BZ9: 11092 | CA9: 11921 | CB9: 13548 | CC9: 47568 | CD9: =CD7-CD8 -> 9989 | CE9: =CE7-CE8 -> 10094 | CF9: =CF7-CF8 -> 10782 | CG9: =CG7-CG8 -> 12397 | CH9: =CH7-CH8 -> 43261 | CI9: =CI7-CI8 -> 12188 | CJ9: =CJ7-CJ8 -> 12662 | CK9: =CK7-CK8 -> 13175 | ... EY9: =EY7-EY8 -> 637270.08 | FA9: =(EA9/DL9)^(1/3)-1 -> 0.21077003 | FB9: =(EF9/DQ9)^(1/3)-1 -> 0.19649897 | FC9: =(EK9/DV9)^(1/3)-1 -> 0.11644707 | FD9: =(EP9/EA9)^(1/3)-1 -> 0.1346695 | FE9: =(EU9/EF9)^(1/3)-1 -> 0.16274711 | FF9: =(EV9/EK9)^(1/3)-1 -> 0.15990776 | FG9: =(EK9/DL9)^(1/5)-1 -> 0.17499806 | FH9: =(EP9/DQ9)^(1/5)-1 -> 0.1793639 | FI9: =(EU9/DV9)^(1/5)-1 -> 0.13714301 | FJ9: =(EV9/EA9)^(1/5)-1 -> 0.1451285 | FK9: =(EW9/EF9)^(1/5)-1 -> 0.15127787 | FL9: =(EX9/EK9)^(1/5)-1 -> 0.14344578
A10: Other cost of revenues - non-GAAP | F10: =0.908-F8 -> 0.908 | K10: =6.081-K8 -> 6.081 | P10: =14.228-P8 -> 14.228 | Q10: =5.692-Q8 -> 5.692 | R10: =20.407-R8 -> 6.407 | S10: =39.622-S8 -> 10.622 | T10: =65.789-T8 -> 14.289 | U10: =SUM(Q10:T10) -> 37.01 | V10: =87.195-V8 -> 17.064 | W10: =117.401-W8 -> 20.842 | X10: =170.39-X8 -> 26.903 | Y10: =250.868-Y8 -> 34.512 | Z10: =SUM(V10:Y10) -> 99.321 | AA10: =315.398-AA8 -> 44.396 | AB10: =326.377-AB8 -> 49.343 | AC10: =362.099-AC8 -> 59.199 | AD10: =453.779-AD8 -> 76.071 | AE10: =SUM(AA10:AD10) -> 229.009 | AF10: 83.401 | AG10: =597.095-AG8 -> 102.775 | AH10: =653.826-AH8 -> 123.952 | AI10: 146.44 | AJ10: =SUM(AF10:AI10) -> 456.568 | AK10: =181.383-2.283 -> 179.1 | AL10: =203.873-2.322 -> 201.551 | AM10: =1048.728-2.149-AM8 -> 221.315 | AN10: =1283.148-10.874-AN8 -> 296.656 | AO10: =SUM(AK10:AN10) -> 898.622 | AP10: =345.394-4.389 -> 341.005 | AQ10: =412.342-7.659 -> 404.683 | AR10: =1662.579-AR8-4.031 -> 437.428 | AS10: =516.011-6.255 -> 509.756 | AT10: =SUM(AP10:AS10) -> 1692.872 | AU10: =624.152-9.148 -> 615.004 | AV10: =673.595-9.363 -> 664.232 | AW10: =678.184-10.729 -> 667.455 | AX10: =706.623-12.099 -> 694.524 | AY10: =SUM(AU10:AX10) -> 2641.215 | AZ10: =665.544-12.537 -> 653.007 | BA10: =654.617-13.592 -> 641.025 | BB10: =667.024-14.871 -> 652.153 | BC10: =2408.4-BC8-6.051 -> 681.463 | BD10: =SUM(AZ10:BC10) -> 2627.648 | BE10: =741-6 -> 735 | BF10: =735-8 -> 727 | BG10: =747-8 -> 739 | BH10: =2946-BH8-45 -> 832 | BI10: =SUM(BE10:BH10) -> 3033 | BJ10: =2936-BJ8-49 -> 849 | BK10: =3172-BK8-51 -> 1011 | BL10: =3378-BL8-72 -> 1096 | BM10: =3702-BM8-77 -> 1175 | BN10: =SUM(BJ10:BM10) -> 4131 | BO10: 1205 | BP10: 2318 | BQ10: 3590 | BR10: 2962 | BS10: 10075 | BT10: 1205 | BU10: 1302 | BV10: 1567 | BW10: 1782 | BX10: =+#REF! -> #REF! | BY10: 2982 | BZ10: 2935 | CA10: 3304 | CB10: 3959 | CC10: 13180 | CD10: 2075 | CE10: 2072 | CF10: 2304 | CG10: =6253-127-CG8 -> 2816 | CH10: =21993-CH8-469 -> 9266 | CI10: =2729-95 -> 2634 | CJ10: =6114-100-CJ8 -> 2721 | CK10: =6695-169-CK8 -> 3178 | CL10: =6921-171-CL8 -> 3130 | CM10: =SUM(CI10:CL10) -> 11663 | CN10: =3011-160 -> 2851 | CO10: =6583-163-CO8 -> 3043 | CP10: =7037-231-CP8 -> 3240 | CQ10: =8188-252-CQ8 -> 3881 | CR10: =SUM(CN10:CQ10) -> 13015 | CS10: =7648-241-CS8 -> 3619 | CT10: =8130-255-CT8 -> 3900 | CU10: =8699-325-CU8 -> 4192 | CV10: =10661-336-CV8 -> 5477 | CW10: =SUM(CS10:CV10) -> 17188 | CX10: =CX12-CX11 -> 4800.3315 | CY10: =CY12-CY11 -> 4917.4236 | CZ10: =CZ12-CZ11 -> 5314.7324 | DA10: =DA12-DA11 -> 7480.818 | DB10: =SUM(CX10:DA10) -> 22513.306 | FE10: =(EU10/EF10)^(1/3)-1 -> #DIV/0! | FF10: =(EV10/EK10)^(1/3)-1 -> #DIV/0! | FK10: =(EW10/EF10)^(1/5)-1 -> #DIV/0! | FL10: =(EX10/EK10)^(1/5)-1 -> #DIV/0!
A11: =CONCATENATE("SBC in ",A10) -> SBC in Other cost of revenues - non-GAAP | P11: 0.876 | U11: 1.065 | Z11: 8.557 | AE11: 11.314 | AJ11: 5.579 | AK11: 2.283 | AL11: 2.322 | AM11: 2.149 | AN11: 10.874 | AO11: =SUM(AK11:AN11) -> 17.628 | AP11: 4.389 | AQ11: 7.659 | AR11: 4.031 | AS11: 6.255 | AT11: =SUM(AP11:AS11) -> 22.334 | AU11: 9.148 | AV11: 9.363 | AW11: 10.729 | AX11: 12.099 | AY11: =SUM(AU11:AX11) -> 41.339 | AZ11: 12.537 | BA11: 13.592 | BB11: 14.871 | BC11: 6.051 | BD11: =SUM(AZ11:BC11) -> 47.051 | BE11: 6 | BF11: 8 | BG11: 8 | BH11: 45 | BI11: =SUM(BE11:BH11) -> 67 | BJ11: 49 | BK11: 51 | BL11: 72 | BM11: 77 | BN11: =SUM(BJ11:BM11) -> 249 | BX11: =BX12-BX10 -> #REF! | CD11: =CD12-CD10 -> 99 | CE11: =CE12-CE10 -> 110 | CF11: =CF12-CF10 -> 133 | CG11: 127 | CH11: =CH12-CH10 -> 469 | CI11: 95 | CJ11: 100 | CK11: 169 | CL11: 171 | CM11: =CM12-CM10 -> 531 | CN11: 160 | CO11: 163 | CP11: 231 | CQ11: 252 | CR11: =SUM(CN11:CQ11) -> 806 | CS11: 241 | CT11: 255 | CU11: 325 | CV11: 336 | CW11: =SUM(CS11:CV11) -> 1157 | CX11: =CV11/CV$24*CX$24 -> 365.66847 | CY11: =CX11/CX$24*CY$24 -> 364.57638 | CZ11: =CY11/CY$24*CZ$24 -> 331.26761 | DA11: =CZ11/CZ$24*DA$24 -> 336.18202 | DB11: =SUM(CX11:DA11) -> 1397.6945 | FE11: =(EU11/EF11)^(1/3)-1 -> #DIV/0! | FF11: =(EV11/EK11)^(1/3)-1 -> #DIV/0! | FK11: =(EW11/EF11)^(1/5)-1 -> #DIV/0! | FL11: =(EX11/EK11)^(1/5)-1 -> #DIV/0!
A12: Other cost of revenues | P12: =SUM(P10:P11) -> 15.104 | U12: =SUM(U10:U11) -> 38.075 | Z12: =SUM(Z10:Z11) -> 107.878 | AE12: =SUM(AE10:AE11) -> 240.323 | AJ12: =SUM(AJ10:AJ11) -> 462.147 | AK12: =SUM(AK10:AK11) -> 181.383 | AL12: =SUM(AL10:AL11) -> 203.873 | AM12: =SUM(AM10:AM11) -> 223.464 | AN12: =SUM(AN10:AN11) -> 307.53 | AO12: =SUM(AO10:AO11) -> 916.25 | AP12: =SUM(AP10:AP11) -> 345.394 | AQ12: =SUM(AQ10:AQ11) -> 412.342 | ... BN12: =SUM(BN10:BN11) -> 4380 | BX12: 6220 | BY12: =SUM(BY10,BY11) -> 2982 | BZ12: =SUM(BZ10,BZ11) -> 2935 | CA12: =SUM(CA10,CA11) -> 3304 | CB12: =SUM(CB10,CB11) -> 3959 | CC12: =SUM(BY12:CB12) -> 13180 | CD12: =5136-CD8 -> 2174 | CE12: =5195-CE8 -> 2182 | CF12: =5409-CF8 -> 2437 | CG12: =SUM(CG10,CG11) -> 2943 | CH12: 9735 | CI12: =SUM(CI10,CI11) -> 2729 | CJ12: =SUM(CJ10,CJ11) -> 2821 | CK12: =SUM(CK10,CK11) -> 3347 | CL12: =SUM(CL10,CL11) -> 3301 | CM12: 12194 | CN12: =SUM(CN10,CN11) -> 3011 | CO12: =SUM(CO10,CO11) -> 3206 | CP12: =SUM(CP10,CP11) -> 3471 | CQ12: =SUM(CQ10,CQ11) -> 4133 | CR12: =SUM(CN12:CQ12) -> 13821 | CS12: =SUM(CS10,CS11) -> 3860 | CT12: =SUM(CT10,CT11) -> 4155 | CU12: =SUM(CU10,CU11) -> 4517 | CV12: =SUM(CV10,CV11) -> 5813 | CW12: =SUM(CS12:CV12) -> 18345 | CX12: =9795-CX8 -> 5166 | CY12: =10373-CY8 -> 5282 | CZ12: =11148-CZ8 -> 5646 | DA12: =14267-DA8 -> 7817 | DB12: =SUM(CX12:DA12) -> 23911 | DC12: =13467-DC8 -> 7179 | DD12: =13883-DD8 -> 7463 | DE12: =14281-DE8 -> 7699 | DF12: =17918-DF8 -> 10482 | DG12: =SUM(DC12:DF12) -> 32823 | DH12: =16012-DH8 -> 9152 | DI12: =17296-DI8 -> 10058 | DJ12: =17568-DJ8 -> 10078 | DK12: =21020-DK8 -> 12519 | DL12: =SUM(DH12:DK12) -> 41807 | DM12: =18982-DM8 -> 11530 | DN12: =18553-DN8 -> 11859 | DO12: =21117-DO8 -> 12951 | DP12: =26080-DP8 -> 15614 | DQ12: =SUM(DM12:DP12) -> 51954 | DR12: =24103-DR8 -> 14391 | DS12: =26227-DS8 -> 15298 | DT12: =27621-DT8 -> 16123 | DU12: =32988-DU8 -> 19561 | DV12: =SUM(DR12:DU12) -> 65373 | DW12: =29599-DW8 -> 17609 | DX12: =30104-DX8 -> 17890 | DY12: =31158-DY8 -> 19332 | DZ12: =35342-DZ8 -> 22417 | EA12: =SUM(DW12:DZ12) -> 77248 | EB12: =30612-EB8 -> 18891 | EC12: =31916-EC8 -> 19379 | ED12: =33229-ED8 -> 20587 | EE12: =37575-EE8 -> 23589 | EF12: =SUM(EB12:EE12) -> 82446 | EG12: =33712-EG8 -> 20766 | EH12: =35507-EH8 -> 22120 | EI12: =36474-EI8 -> 22755 | EJ12: =40613-EJ8 -> 25765 | EK12: =SUM(EG12:EJ12) -> 91406 | EL12: =36361-EL8 -> 22613 | EM12: =39039-EM8 -> 24334 | EN12: =41369-EN8 -> 26493 | EO12: =EO9*EO114 -> 30428.208 | EP12: =SUM(EL12:EO12) -> 103868.21 | EQ12: =EQ9*EQ114 -> 27263.919 | ER12: =ER9*ER114 -> 29692.834 | ES12: =ES9*ES114 -> 32870.338 | ET12: =ET9*ET114 -> 37487.696 | EU12: =SUM(EQ12:ET12) -> 127314.79 | EV12: =EV9*EV114 -> 153359.36 | EW12: =EW9*EW114 -> 176392.71 | EX12: =EX9*EX114 -> 197287.56 | EY12: =EY9*EY114 -> 217309.1 | FA12: =(EA12/DL12)^(1/3)-1 -> 0.22709847 | FB12: =(EF12/DQ12)^(1/3)-1 -> 0.16640722 | FC12: =(EK12/DV12)^(1/3)-1 -> 0.1182153 | FD12: =(EP12/EA12)^(1/3)-1 -> 0.10373581 | FE12: =(EU12/EF12)^(1/3)-1 -> 0.15585428 | FF12: =(EV12/EK12)^(1/3)-1 -> 0.18826105 | FG12: =(EK12/DL12)^(1/5)-1 -> 0.16935167 | FH12: =(EP12/DQ12)^(1/5)-1 -> 0.14861036 | FI12: =(EU12/DV12)^(1/5)-1 -> 0.14260491 | FJ12: =(EV12/EA12)^(1/5)-1 -> 0.14700315 | FK12: =(EW12/EF12)^(1/5)-1 -> 0.16429279 | FL12: =(EX12/EK12)^(1/5)-1 -> 0.16633954
A13: Gross profit | F13: =F9-F10 -> -0.688 | K13: =K9-K10 -> 13.027 | P13: =P9-P10 -> 72.198 | Q13: =Q9-Q10 -> 36.593 | R13: =R9-R10 -> 58.118 | S13: =S9-S10 -> 91.165 | T13: =T9-T10 -> 122.122 | U13: =U9-U10 -> 307.998 | V13: =V9-V10 -> 161.423 | W13: =W9-W10 -> 193.798 | ... BN13: =BN9-BN10 -> 24966 | BO13: 6930 | BP13: 7296 | BQ13: 7741 | BR13: 8377 | BS13: 30344 | BT13: =BT9-BT10 -> 6930 | BU13: =BU9-BU10 -> 7062 | BV13: =BV9-BV10 -> 7189 | BW13: =BW9-BW10 -> 8043 | BX13: =BX9-BX12 -> 28863 | BY13: 8025 | BZ13: 8157 | CA13: 8617 | CB13: 9589 | CC13: 34388 | CD13: =CD9-CD12 -> 7815 | CE13: =CE9-CE12 -> 7912 | CF13: =CF9-CF12 -> 8345 | CG13: =CG9-CG12 -> 9454 | CH13: =CH9-CH12 -> 33526 | CI13: =CI9-CI12 -> 9459 | CJ13: =CJ9-CJ12 -> 9841 | CK13: =CK9-CK12 -> 9828 | ... EY13: =EY9-EY12 -> 419960.98 | FA13: =(EA13/DL13)^(1/3)-1 -> 0.20302965 | FB13: =(EF13/DQ13)^(1/3)-1 -> 0.21188787 | FC13: =(EK13/DV13)^(1/3)-1 -> 0.11565729 | FD13: =(EP13/EA13)^(1/3)-1 -> 0.14932313 | FE13: =(EU13/EF13)^(1/3)-1 -> 0.16598363 | FF13: =(EV13/EK13)^(1/3)-1 -> 0.14672274 | FG13: =(EK13/DL13)^(1/5)-1 -> 0.17758555 | FH13: =(EP13/DQ13)^(1/5)-1 -> 0.19447926 | FI13: =(EU13/DV13)^(1/5)-1 -> 0.13467485 | FJ13: =(EV13/EA13)^(1/5)-1 -> 0.14419942 | FK13: =(EW13/EF13)^(1/5)-1 -> 0.14490205 | FL13: =(EX13/EK13)^(1/5)-1 -> 0.13254789
A14: Operating expenses
A15: Research & development - non-GAAP | F15: 2.93 | K15: 10.516 | P15: 16.5 | Q15: 6.183 | R15: 6.457 | S15: 9.053 | T15: 10.055 | U15: =SUM(Q15:T15) -> 31.748 | V15: 12.505 | W15: 17.492 | X15: 32.774 | Y15: 28.457 | Z15: =SUM(V15:Y15) -> 91.228 | AA15: 35.019 | AB15: 45.762 | AC15: 57.409 | AD15: 87.442 | AE15: =SUM(AA15:AD15) -> 225.632 | AF15: 79.412 | AG15: 95.772 | AH15: =151.721 -> 151.721 | AI15: 157.072 | AJ15: =SUM(AF15:AI15) -> 483.977 | AK15: =246.599-73.086 -> 173.513 | AL15: =282.552-70.564 -> 211.988 | AM15: =312.632-61.714 -> 250.918 | AN15: =386.806-82.122 -> 304.684 | AO15: =SUM(AK15:AN15) -> 941.103 | AP15: =408.384-120.787 -> 287.597 | AQ15: =532.106-156.983 -> 375.123 | AR15: =548.712-130.65 -> 418.062 | AS15: =630.783-161.372 -> 469.411 | AT15: =SUM(AP15:AS15) -> 1550.193 | AU15: =673.069-193.8 -> 479.269 | AV15: =682.21-187.281 -> 494.929 | AW15: =704.571-169.263 -> 535.308 | AX15: =733.342-182.075 -> 551.267 | AY15: =SUM(AU15:AX15) -> 2060.773 | AZ15: =641.643-168.561 -> 473.082 | BA15: =707.626-182.209 -> 525.417 | BB15: =757.524-195.624 -> 561.9 | BC15: =736.234-178.948 -> 557.286 | BD15: =SUM(AZ15:BC15) -> 2117.685 | BE15: =818-191 -> 627 | BF15: =898-202 -> 696 | BG15: =994-244 -> 750 | BH15: =1051-224 -> 827 | BI15: =SUM(BE15:BH15) -> 2900 | BJ15: =1226-237 -> 989 | BK15: =1234-247 -> 987 | BL15: =1404-311 -> 1093 | BM15: =1298-266 -> 1032 | BN15: =SUM(BJ15:BM15) -> 4101 | BO15: 1142 | BP15: 1281 | BQ15: 1527 | BR15: 1487 | BS15: 5437 | BT15: 1142 | BU15: 1163 | BV15: 1190 | BW15: 1314 | BX15: =SUM(BT15:BW15) -> 4809 | BY15: 1476 | BZ15: 1566 | CA15: 1564 | CB15: 1642 | CC15: 6248 | CD15: 1279 | CE15: 1365 | CF15: 1385 | CG15: =1933-466 -> 1467 | CH15: =7137-1641 -> 5496 | CI15: =2126-456 -> 1670 | CJ15: =2238-447 -> 1791 | CK15: =2655-666 -> 1989 | CL15: =2813-631 -> 2182 | CM15: =SUM(CI15:CL15) -> 7632 | CN15: =2753-615 -> 2138 | CO15: =2789-583 -> 2206 | CP15: =3230-741 -> 2489 | CQ15: =3510-739 -> 2771 | CR15: =SUM(CN15:CQ15) -> 9604 | CS15: =3367-739 -> 2628 | CT15: =3363-739 -> 2624 | CU15: =3596-922 -> 2674 | CV15: =3622-907 -> 2715 | CW15: =SUM(CS15:CV15) -> 10641 | CX15: =CX17-CX16 -> 2954.9128 | CY15: =CY17-CY16 -> 3187.8608 | CZ15: =CZ17-CZ16 -> 3310.7746 | DA15: =DA17-DA16 -> 3398.5087 | DB15: =SUM(CX15:DA15) -> 12852.057
A16: =CONCATENATE("SBC in ",A15) -> SBC in Research & development - non-GAAP | P16: 4.44 | U16: 8.746 | Z16: 138.377 | AE16: 169.532 | AJ16: 115.532 | AK16: =AK17-AK15 -> 73.086 | AL16: =AL17-AL15 -> 70.564 | AM16: =AM17-AM15 -> 61.714 | AN16: =AN17-AN15 -> 82.122 | AO16: =SUM(AK16:AN16) -> 287.486 | AP16: 120.787 | AQ16: 156.983 | AR16: 130.65 | AS16: 161.372 | AT16: =SUM(AP16:AS16) -> 569.792 | AU16: 193.8 | AV16: 187.281 | AW16: 169.263 | AX16: 182.075 | AY16: =SUM(AU16:AX16) -> 732.419 | AZ16: 168.561 | BA16: 182.209 | BB16: 195.624 | BC16: 178.948 | BD16: =SUM(AZ16:BC16) -> 725.342 | BE16: 191 | BF16: 202 | BG16: 244 | BH16: 224 | BI16: =SUM(BE16:BH16) -> 861 | BJ16: 237 | BK16: 247 | BL16: 311 | BM16: 266 | BN16: =SUM(BJ16:BM16) -> 1061 | BX16: =BX17-BX15 -> 1274 | CD16: =CD17-CD15 -> 338 | CE16: =CE17-CE15 -> 401 | CF16: =CF17-CF15 -> 436 | CG16: 466 | CH16: =SUM(CD16:CG16) -> 1641 | CI16: 456 | CJ16: 447 | CK16: 666 | CL16: 631 | CM16: =SUM(CI16:CL16) -> 2200 | CN16: 615 | CO16: 583 | CP16: 741 | CQ16: 739 | CR16: =SUM(CN16:CQ16) -> 2678 | CS16: 739 | CT16: 739 | CU16: 922 | CV16: 907 | CW16: =SUM(CS16:CV16) -> 3307 | CX16: =CV16/CV$24*CX$24 -> 987.08722 | CY16: =CX16/CX$24*CY$24 -> 984.13922 | CZ16: =CY16/CY$24*CZ$24 -> 894.22535 | DA16: =CZ16/CZ$24*DA$24 -> 907.49133 | DB16: =SUM(CX16:DA16) -> 3772.9431
A17: Research & development | P17: =SUM(P15:P16) -> 20.94 | U17: =SUM(U15:U16) -> 40.494 | Z17: =SUM(Z15:Z16) -> 229.605 | AE17: =SUM(AE15:AE16) -> 395.164 | AJ17: =SUM(AJ15:AJ16) -> 599.509 | AK17: =246.599 -> 246.599 | AL17: =282.552 -> 282.552 | AM17: =312.632 -> 312.632 | AN17: =386.806 -> 386.806 | AO17: =SUM(AO15:AO16) -> 1228.589 | AP17: =SUM(AP15:AP16) -> 408.384 | AQ17: =SUM(AQ15:AQ16) -> 532.106 | AR17: =SUM(AR15:AR16) -> 548.712 | AS17: =SUM(AS15:AS16) -> 630.783 | AT17: =SUM(AT15:AT16) -> 2119.985 | AU17: =SUM(AU15:AU16) -> 673.069 | AV17: =SUM(AV15:AV16) -> 682.21 | ... BN17: =SUM(BN15:BN16) -> 5162 | BX17: 6083 | CD17: =1617 -> 1617 | CE17: 1766 | CF17: 1821 | CG17: =SUM(CG15,CG16) -> 1933 | CH17: =SUM(CH15:CH16) -> 7137 | CI17: =SUM(CI15,CI16) -> 2126 | CJ17: =SUM(CJ15,CJ16) -> 2238 | CK17: =SUM(CK15,CK16) -> 2655 | CL17: =SUM(CL15,CL16) -> 2813 | CM17: =SUM(CM15:CM16) -> 9832 | CN17: =SUM(CN15,CN16) -> 2753 | CO17: =SUM(CO15,CO16) -> 2789 | CP17: =SUM(CP15,CP16) -> 3230 | CQ17: =SUM(CQ15,CQ16) -> 3510 | CR17: =SUM(CN17:CQ17) -> 12282 | CS17: =SUM(CS15,CS16) -> 3367 | CT17: =SUM(CT15,CT16) -> 3363 | CU17: =SUM(CU15,CU16) -> 3596 | CV17: =SUM(CV15,CV16) -> 3622 | CW17: =SUM(CS17:CV17) -> 13948 | CX17: 3942 | CY17: 4172 | CZ17: 4205 | DA17: 4306 | DB17: =SUM(CX17:DA17) -> 16625 | DC17: 5039 | DD17: 5114 | DE17: 5232 | DF17: 6034 | DG17: =SUM(DC17:DF17) -> 21419 | DH17: 6029 | DI17: 6213 | DJ17: 6554 | DK17: 7222 | DL17: =SUM(DH17:DK17) -> 26018 | DM17: 6820 | DN17: 6875 | DO17: 6856 | DP17: 7022 | DQ17: =SUM(DM17:DP17) -> 27573 | DR17: 7485 | DS17: 7675 | DT17: 7694 | DU17: 8708 | DV17: =SUM(DR17:DU17) -> 31562 | DW17: 9119 | DX17: 9841 | DY17: 10273 | DZ17: 10267 | EA17: =SUM(DW17:DZ17) -> 39500 | EB17: =11468 -> 11468 | EC17: 10588 | ED17: 11258 | EE17: 12113 | EF17: =SUM(EB17:EE17) -> 45427 | EG17: 11903 | EH17: 11860 | EI17: 12447 | EJ17: 13116 | EK17: =SUM(EG17:EJ17) -> 49326 | EL17: 13556 | EM17: 13808 | EN17: 15151 | EO17: =EO9*EO117 -> 15742.038 | EP17: =SUM(EL17:EO17) -> 58257.038 | EQ17: =EQ9*EQ117 -> 16267.472 | ER17: =ER9*ER117 -> 16539.005 | ES17: =ES9*ES117 -> 17975.966 | ET17: =ET9*ET117 -> 18630.933 | EU17: =SUM(EQ17:ET17) -> 69413.376 | EV17: =EV9*EV117 -> 77831.027 | EW17: =EW9*EW117 -> 85083.541 | EX17: =EX9*EX117 -> 92298.272 | EY17: =EY9*EY117 -> 99414.132 | FA17: =(EA17/DL17)^(1/3)-1 -> 0.14932026 | FB17: =(EF17/DQ17)^(1/3)-1 -> 0.18107283 | FC17: =(EK17/DV17)^(1/3)-1 -> 0.16047858 | FD17: =(EP17/EA17)^(1/3)-1 -> 0.13828349 | FE17: =(EU17/EF17)^(1/3)-1 -> 0.15179813 | FF17: =(EV17/EK17)^(1/3)-1 -> 0.16419471 | FG17: =(EK17/DL17)^(1/5)-1 -> 0.13647634 | FH17: =(EP17/DQ17)^(1/5)-1 -> 0.16137608 | FI17: =(EU17/DV17)^(1/5)-1 -> 0.17072726 | FJ17: =(EV17/EA17)^(1/5)-1 -> 0.14527857 | FK17: =(EW17/EF17)^(1/5)-1 -> 0.13372128 | FL17: =(EX17/EK17)^(1/5)-1 -> 0.13350525
A18: Sales & marketing - non-GAAP | F18: 1.677 | K18: 10.385 | P18: 20.076 | Q18: 7.294 | R18: 11.176 | S18: 11.704 | T18: 13.675 | U18: =SUM(Q18:T18) -> 43.849 | V18: 17.767 | W18: 24.822 | X18: 36.575 | Y18: 41.164 | Z18: =SUM(V18:Y18) -> 120.328 | AA18: 47.904 | AB18: 56.777 | AC18: 65.512 | AD18: 76.107 | AE18: =SUM(AA18:AD18) -> 246.3 | AF18: 82.952 | AG18: 97.024 | AH18: 104.996 | AI18: 154.769 | AJ18: =SUM(AF18:AI18) -> 439.741 | AK18: =190.943-15.929 -> 175.014 | AL18: =196.397-14.285 -> 182.112 | AM18: =206.972-14.673 -> 192.299 | AN18: =255.206-14.502 -> 240.704 | AO18: =SUM(AK18:AN18) -> 790.129 | AP18: =302.552-27.25 -> 275.302 | AQ18: =355.604-36.385 -> 319.219 | AR18: =380.82-29.918 -> 350.902 | AS18: =422.291-38.085 -> 384.206 | AT18: =SUM(AP18:AS18) -> 1329.629 | AU18: =446.898-42.576 -> 404.322 | AV18: =484.552-42.593 -> 441.959 | AW18: =508.801-64.497 -> 444.304 | AX18: =505.993-56.354 -> 449.639 | AY18: =SUM(AU18:AX18) -> 1740.224 | AZ18: =433.941-59.026 -> 374.915 | BA18: =469.039-57.294 -> 411.745 | BB18: =497.812-62.26 -> 435.552 | BC18: =583.149-52.439 -> 530.71 | BD18: =SUM(AZ18:BC18) -> 1752.922 | BE18: =607-54 -> 553 | BF18: =629-56 -> 573 | BG18: =661-75 -> 586 | BH18: =902-76 -> 826 | BI18: =SUM(BE18:BH18) -> 2538 | BJ18: =1026-78 -> 948 | BK18: =1091-74 -> 1017 | BL18: =1204-104 -> 1100 | BM18: =1268-105 -> 1163 | BN18: =SUM(BJ18:BM18) -> 4228 | BO18: 1172 | BP18: 1294 | BQ18: 1521 | BR18: 1611 | BS18: 5598 | BT18: 1172 | BU18: 1185 | BV18: 1259 | BW18: 1401 | BX18: =SUM(BT18:BW18) -> 5017 | BY18: 1461 | BZ18: 1601 | CA18: 1646 | CB18: 1970 | CC18: 6678 | CD18: 1317 | CE18: 1458 | CF18: 1473 | CG18: =1908-154 -> 1754 | CH18: =6554-552 -> 6002 | CI18: =1729-147 -> 1582 | CJ18: =1941-158 -> 1783 | CK18: =2084-197 -> 1887 | CL18: =2377-213 -> 2164 | CM18: =SUM(CI18:CL18) -> 7416 | CN18: =2065-205 -> 1860 | CO18: =2080-196 -> 1884 | CP18: =2223-250 -> 1973 | CQ18: =2679-240 -> 2439 | CR18: =SUM(CN18:CQ18) -> 8156 | CS18: =2387-242 -> 2145 | CT18: =2415-238 -> 2177 | CU18: =2565-297 -> 2268 | CV18: =3118-301 -> 2817 | CW18: =SUM(CS18:CV18) -> 9407 | CX18: =CX20-CX19 -> 2316.422 | CY18: =CY20-CY19 -> 2570.4003 | CZ18: =CZ20-CZ19 -> 2745.2394 | DA18: =DA20-DA19 -> 4008.8369 | DB18: =SUM(CX18:DA18) -> 11640.899 | FE18: =(EU18/EF18)^(1/3)-1 -> #DIV/0! | FF18: =(EV18/EK18)^(1/3)-1 -> #DIV/0! | FK18: =(EW18/EF18)^(1/5)-1 -> #DIV/0! | FL18: =(EX18/EK18)^(1/5)-1 -> #DIV/0!
A19: =CONCATENATE("SBC in ",A18) -> SBC in Sales & marketing - non-GAAP | P19: 1.667 | U19: 4.934 | Z19: 44.607 | AE19: 49.449 | AJ19: 28.411 | AK19: =AK20-AK18 -> 15.929 | AL19: =AL20-AL18 -> 14.285 | AM19: =AM20-AM18 -> 14.673 | AN19: =AN20-AN18 -> 14.502 | AO19: =SUM(AK19:AN19) -> 59.389 | AP19: 27.25 | AQ19: 36.385 | AR19: 29.818 | AS19: 38.085 | AT19: =SUM(AP19:AS19) -> 131.538 | AU19: 42.576 | AV19: 42.593 | AW19: 64.497 | AX19: 56.354 | AY19: =SUM(AU19:AX19) -> 206.02 | AZ19: 59.026 | BA19: 57.294 | BB19: 62.26 | BC19: 52.439 | BD19: =SUM(AZ19:BC19) -> 231.019 | BE19: 54 | BF19: 56 | BG19: 75 | BH19: 76 | BI19: =SUM(BE19:BH19) -> 261 | BJ19: 78 | BK19: 74 | BL19: 104 | BM19: 105 | BN19: =SUM(BJ19:BM19) -> 361 | BX19: =BX20-BX18 -> 448 | CD19: =CD20-CD18 -> 118 | CE19: =CE20-CE18 -> 125 | CF19: =CF20-CF18 -> 155 | CG19: 154 | CH19: =SUM(CD19:CG19) -> 552 | CI19: 147 | CJ19: 158 | CK19: 197 | CL19: 213 | CM19: =SUM(CI19:CL19) -> 715 | CN19: 205 | CO19: 196 | CP19: 250 | CQ19: 240 | CR19: =SUM(CN19:CQ19) -> 891 | CS19: 242 | CT19: 238 | CU19: 297 | CV19: 301 | CW19: =SUM(CS19:CV19) -> 1078 | CX19: =CV19/CV$24*CX$24 -> 327.57801 | CY19: =CX19/CX$24*CY$24 -> 326.59967 | CZ19: =CY19/CY$24*CZ$24 -> 296.76056 | DA19: =CZ19/CZ$24*DA$24 -> 301.16306 | DB19: =SUM(CX19:DA19) -> 1252.1013 | FE19: =(EU19/EF19)^(1/3)-1 -> #DIV/0! | FF19: =(EV19/EK19)^(1/3)-1 -> #DIV/0! | FK19: =(EW19/EF19)^(1/5)-1 -> #DIV/0! | FL19: =(EX19/EK19)^(1/5)-1 -> #DIV/0!
A20: Sales & marketing | P20: =SUM(P18:P19) -> 21.743 | U20: =SUM(U18:U19) -> 48.783 | Z20: =SUM(Z18:Z19) -> 164.935 | AE20: =SUM(AE18:AE19) -> 295.749 | AJ20: =SUM(AJ18:AJ19) -> 468.152 | AK20: =190.943 -> 190.943 | AL20: =196.397 -> 196.397 | AM20: =206.972 -> 206.972 | AN20: =255.206 -> 255.206 | AO20: =SUM(AO18:AO19) -> 849.518 | AP20: =SUM(AP18:AP19) -> 302.552 | AQ20: =SUM(AQ18:AQ19) -> 355.604 | AR20: =SUM(AR18:AR19) -> 380.72 | AS20: =SUM(AS18:AS19) -> 422.291 | AT20: =SUM(AT18:AT19) -> 1461.167 | AU20: =SUM(AU18:AU19) -> 446.898 | AV20: =SUM(AV18:AV19) -> 484.552 | ... BN20: =SUM(BN18:BN19) -> 4589 | BX20: 5465 | CD20: 1435 | CE20: 1583 | CF20: 1628 | CG20: =SUM(CG18,CG19) -> 1908 | CH20: =SUM(CH18,CH19) -> 6554 | CI20: =SUM(CI18,CI19) -> 1729 | CJ20: =SUM(CJ18,CJ19) -> 1941 | CK20: =SUM(CK18,CK19) -> 2084 | CL20: =SUM(CL18,CL19) -> 2377 | CM20: =SUM(CI20:CL20) -> 8131 | CN20: =SUM(CN18,CN19) -> 2065 | CO20: =SUM(CO18,CO19) -> 2080 | CP20: =SUM(CP18,CP19) -> 2223 | CQ20: =SUM(CQ18,CQ19) -> 2679 | CR20: =SUM(CN20:CQ20) -> 9047 | CS20: =SUM(CS18,CS19) -> 2387 | CT20: =SUM(CT18,CT19) -> 2415 | CU20: =SUM(CU18,CU19) -> 2565 | CV20: =SUM(CV18,CV19) -> 3118 | CW20: =SUM(CS20:CV20) -> 10485 | CX20: 2644 | CY20: 2897 | CZ20: 3042 | DA20: 4310 | DB20: =SUM(CX20:DA20) -> 12893 | DC20: 3604 | DD20: 3780 | DE20: 3849 | DF20: 5100 | DG20: =SUM(DC20:DF20) -> 16333 | DH20: 3905 | DI20: 4212 | DJ20: 4609 | DK20: 5738 | DL20: =SUM(DH20:DK20) -> 18464 | DM20: 4500 | DN20: 3901 | DO20: 4231 | DP20: 5314 | DQ20: =SUM(DM20:DP20) -> 17946 | DR20: 4516 | DS20: 5276 | DT20: 5516 | DU20: 7604 | DV20: =SUM(DR20:DU20) -> 22912 | DW20: 5825 | DX20: 6630 | DY20: 6929 | DZ20: 7183 | EA20: =SUM(DW20:DZ20) -> 26567 | EB20: =6533 -> 6533 | EC20: 6781 | ED20: 6884 | EE20: 7719 | EF20: =SUM(EB20:EE20) -> 27917 | EG20: 6426 | EH20: 6792 | EI20: 7227 | EJ20: 7363 | EK20: =SUM(EG20:EJ20) -> 27808 | EL20: 6172 | EM20: 7101 | EN20: 7205 | EO20: =EO9*EO120 -> 7583.0549 | EP20: =SUM(EL20:EO20) -> 28061.055 | EQ20: =EQ9*EQ120 -> 6452.4608 | ER20: =ER9*ER120 -> 7737.5462 | ES20: =ES9*ES120 -> 7703.9854 | ET20: =ET9*ET120 -> 8016.9471 | EU20: =SUM(EQ20:ET20) -> 29910.939 | EV20: =EV9*EV120 -> 32237.703 | EW20: =EW9*EW120 -> 34240.937 | EX20: =EX9*EX120 -> 36342.445 | EY20: =EY9*EY120 -> 38236.205 | FA20: =(EA20/DL20)^(1/3)-1 -> 0.12894359 | FB20: =(EF20/DQ20)^(1/3)-1 -> 0.15868938 | FC20: =(EK20/DV20)^(1/3)-1 -> 0.066683518 | FD20: =(EP20/EA20)^(1/3)-1 -> 0.018404929 | FE20: =(EU20/EF20)^(1/3)-1 -> 0.023262604 | FF20: =(EV20/EK20)^(1/3)-1 -> 0.050504976 | FG20: =(EK20/DL20)^(1/5)-1 -> 0.085347456 | FH20: =(EP20/DQ20)^(1/5)-1 -> 0.093521349 | FI20: =(EU20/DV20)^(1/5)-1 -> 0.054759415 | FJ20: =(EV20/EA20)^(1/5)-1 -> 0.039451705 | FK20: =(EW20/EF20)^(1/5)-1 -> 0.041682526 | FL20: =(EX20/EK20)^(1/5)-1 -> 0.054991296
A21: General & administrative - non-GAAP | F21: 1.221 | K21: 4.357 | P21: 12.275 | Q21: 4.135 | R21: 5.653 | S21: 7.313 | T21: 7.199 | U21: =SUM(Q21:T21) -> 24.3 | V21: 10.027 | W21: 12.535 | X21: 13.853 | Y21: 20.284 | Z21: =SUM(V21:Y21) -> 56.699 | AA21: 21.506 | AB21: 25.577 | AC21: 40.774 | AD21: 51.843 | AE21: =SUM(AA21:AD21) -> 139.7 | AF21: 57.266 | AG21: 71.568 | AH21: 92.434 | AI21: 114.077 | AJ21: =SUM(AF21:AI21) -> 335.345 | AK21: =169.395-23.366 -> 146.029 | AL21: =172.638-21.978 -> 150.66 | AM21: =190.01-21.324 -> 168.686 | AN21: =219.744-26.929 -> 192.815 | AO21: =SUM(AK21:AN21) -> 658.19 | AP21: =261.4-31.44 -> 229.96 | AQ21: =319.405-40.497 -> 278.908 | AR21: =321.398-33.352 -> 288.046 | AS21: =377.046-39.588 -> 337.458 | AT21: =SUM(AP21:AS21) -> 1134.372 | AU21: =409.305-35.255 -> 374.05 | AV21: =474.91-33.539 -> 441.371 | AW21: =507.064-35.55 -> 471.514 | AX21: =411.36-35.644 -> 375.716 | AY21: =SUM(AU21:AX21) -> 1662.651 | AZ21: =448.311-37.359 -> 410.952 | BA21: =364.367-39.975 -> 324.392 | BB21: =389.557-44.772 -> 344.785 | BC21: =465.059-38.536 -> 426.523 | BD21: =SUM(AZ21:BC21) -> 1506.652 | BE21: =410-40 -> 370 | BF21: =461-43 -> 418 | BG21: =532-53 -> 479 | BH21: =559-51 -> 508 | BI21: =SUM(BE21:BH21) -> 1775 | BJ21: =591-68 -> 523 | BK21: =648-63 -> 585 | BL21: =676-84 -> 592 | BM21: =809-88 -> 721 | BN21: =SUM(BJ21:BM21) -> 2421 | BO21: 671 | BP21: 771 | BQ21: 893 | BR21: 1007 | BS21: 3342 | BT21: 671 | BU21: 726 | BV21: 789 | BW21: 904 | BX21: =SUM(BT21:BW21) -> 3090 | BY21: 1018 | BZ21: 1084 | CA21: 1077 | CB21: 1138 | CC21: 4317 | CD21: 915 | CE21: 991 | CF21: 1003 | CG21: =1184-126 -> 1058 | CH21: =4432-465 -> 3967 | CI21: =1489-141 -> 1348 | CJ21: =1404-175 -> 1229 | CK21: =1365-223 -> 1142 | CL21: =1593-186 -> 1407 | CM21: =SUM(CI21:CL21) -> 5126 | CN21: =1637-223 -> 1414 | CO21: =1450-190 -> 1260 | CP21: =1477-210 -> 1267 | CQ21: =1572-205 -> 1367 | CR21: =SUM(CN21:CQ21) -> 5308 | CS21: =1513-272 -> 1241 | CT21: =1624-271 -> 1353 | CU21: =1824-316 -> 1508 | CV21: =2024-302 -> 1722 | CW21: =SUM(CS21:CV21) -> 5824 | CX21: =CX23-CX22 -> 1472.3337 | CY21: =CY23-CY22 -> 1372.3153 | CZ21: =CZ23-CZ22 -> 1297.2535 | DA21: =DA23-DA22 -> 1473.8364 | DB21: =SUM(CX21:DA21) -> 5615.7389 | FE21: =(EU21/EF21)^(1/3)-1 -> #DIV/0! | FF21: =(EV21/EK21)^(1/3)-1 -> #DIV/0! | FK21: =(EW21/EF21)^(1/5)-1 -> #DIV/0! | FL21: =(EX21/EK21)^(1/5)-1 -> #DIV/0!
A22: =CONCATENATE("SBC in ",A21) -> SBC in General & administrative - non-GAAP | P22: 5.4 | U22: 6.89 | Z22: 37.82 | AE22: 48.451 | AJ22: 51.187 | AK22: =AK23-AK21 -> 23.366 | AL22: =AL23-AL21 -> 21.978 | AM22: =AM23-AM21 -> 21.324 | AN22: =AN23-AN21 -> 26.929 | AO22: =SUM(AK22:AN22) -> 93.597 | AP22: 31.44 | AQ22: 40.497 | AR22: 33.352 | AS22: 39.588 | AT22: =SUM(AP22:AS22) -> 144.877 | AU22: 35.255 | AV22: 33.539 | AW22: 35.55 | AX22: 35.644 | AY22: =SUM(AU22:AX22) -> 139.988 | AZ22: 37.359 | BA22: 39.975 | BB22: 44.772 | BC22: 38.536 | BD22: =SUM(AZ22:BC22) -> 160.642 | BE22: 40 | BF22: 43 | BG22: 53 | BH22: 51 | BI22: =SUM(BE22:BH22) -> 187 | BJ22: 68 | BK22: 63 | BL22: 84 | BM22: 88 | BN22: =SUM(BJ22:BM22) -> 303 | BX22: =BX23-BX21 -> 391 | CD22: =CD23-CD21 -> 100 | CE22: =CE23-CE21 -> 107 | CF22: =CF23-CF21 -> 132 | CG22: 126 | CH22: =SUM(CD22:CG22) -> 465 | CI22: 141 | CJ22: 175 | CK22: 223 | CL22: 186 | CM22: =SUM(CI22:CL22) -> 725 | CN22: 223 | CO22: 190 | CP22: 210 | CQ22: 205 | CR22: =SUM(CN22:CQ22) -> 828 | CS22: 272 | CT22: 271 | CU22: 316 | CV22: 302 | CW22: =SUM(CS22:CV22) -> 1161 | CX22: =CV22/CV$24*CX$24 -> 328.66631 | CY22: =CX22/CX$24*CY$24 -> 327.68472 | CZ22: =CY22/CY$24*CZ$24 -> 297.74648 | DA22: =CZ22/CZ$24*DA$24 -> 302.1636 | DB22: =SUM(CX22:DA22) -> 1256.2611 | FE22: =(EU22/EF22)^(1/3)-1 -> #DIV/0! | FF22: =(EV22/EK22)^(1/3)-1 -> #DIV/0! | FK22: =(EW22/EF22)^(1/5)-1 -> #DIV/0! | FL22: =(EX22/EK22)^(1/5)-1 -> #DIV/0!
A23: General & administrative | P23: =SUM(P21:P22) -> 17.675 | U23: =SUM(U21:U22) -> 31.19 | Z23: =SUM(Z21:Z22) -> 94.519 | AE23: =SUM(AE21:AE22) -> 188.151 | AJ23: =SUM(AJ21:AJ22) -> 386.532 | AK23: =169.395 -> 169.395 | AL23: =172.638 -> 172.638 | AM23: =190.01 -> 190.01 | AN23: =219.744 -> 219.744 | AO23: =SUM(AO21:AO22) -> 751.787 | AP23: =SUM(AP21:AP22) -> 261.4 | AQ23: =SUM(AQ21:AQ22) -> 319.405 | AR23: =SUM(AR21:AR22) -> 321.398 | AS23: =SUM(AS21:AS22) -> 377.046 | AT23: =SUM(AT21:AT22) -> 1279.249 | AU23: =SUM(AU21:AU22) -> 409.305 | AV23: =SUM(AV21:AV22) -> 474.91 | ... BN23: =SUM(BN21:BN22) -> 2724 | BX23: 3481 | CD23: 1015 | CE23: 1098 | CF23: 1135 | CG23: =SUM(CG21,CG22) -> 1184 | CH23: =SUM(CH21,CH22) -> 4432 | CI23: =SUM(CI21,CI22) -> 1489 | CJ23: =SUM(CJ21,CJ22) -> 1404 | CK23: =SUM(CK21,CK22) -> 1365 | CL23: =SUM(CL21,CL22) -> 1593 | CM23: =SUM(CI23:CL23) -> 5851 | CN23: =SUM(CN21,CN22) -> 1637 | CO23: =SUM(CO21,CO22) -> 1450 | CP23: =SUM(CP21,CP22) -> 1477 | CQ23: =SUM(CQ21,CQ22) -> 1572 | CR23: =SUM(CN23:CQ23) -> 6136 | CS23: =SUM(CS21,CS22) -> 1513 | CT23: =SUM(CT21,CT22) -> 1624 | CU23: =SUM(CU21,CU22) -> 1824 | CV23: =SUM(CV21,CV22) -> 2024 | CW23: =SUM(CS23:CV23) -> 6985 | CX23: 1801 | CY23: 1700 | CZ23: 1595 | DA23: 1776 | DB23: =SUM(CX23:DA23) -> 6872 | DC23: =2035-632 -> 1403 | DD23: =2002-238 -> 1764 | DE23: =2068-315 -> 1753 | DF23: =2021-18 -> 2003 | DG23: =SUM(DC23:DF23) -> 6923 | DH23: 2088 | DI23: 2043 | DJ23: =2591 -> 2591 | DK23: 2829 | DL23: =SUM(DH23:DK23) -> 9551 | DM23: 2880 | DN23: 2585 | DO23: 2756 | DP23: 2831 | DQ23: =SUM(DM23:DP23) -> 11052 | DR23: 2773 | DS23: 3341 | DT23: 3256 | DU23: 4140 | DV23: =SUM(DR23:DU23) -> 13510 | DW23: 3374 | DX23: 3657 | DY23: 3597 | DZ23: 5096 | EA23: =SUM(DW23:DZ23) -> 15724 | EB23: =3759 -> 3759 | EC23: 3481 | ED23: 3979 | EE23: 5206 | EF23: =SUM(EB23:EE23) -> 16425 | EG23: 3026 | EH23: 3158 | EI23: 3599 | EJ23: 4405 | EK23: =SUM(EG23:EJ23) -> 14188 | EL23: 3539 | EM23: 5209 | EN23: =7393-EN25 -> 3936 | EO23: =EO9*EO123 -> 4895.3899 | EP23: =SUM(EL23:EO23) -> 17579.39 | EQ23: =EQ9*EQ123 -> 3771.5088 | ER23: =ER9*ER123 -> 3820.4134 | ES23: =ES9*ES123 -> 4057.4323 | ET23: =ET9*ET123 -> 5194.0784 | EU23: =SUM(EQ23:ET23) -> 16843.433 | EV23: =EV9*EV123 -> 18421.545 | EW23: =EW9*EW123 -> 19714.479 | EX23: =EX9*EX123 -> 20767.111 | EY23: =EY9*EY123 -> 21667.183 | FA23: =(EA23/DL23)^(1/3)-1 -> 0.18078655 | FB23: =(EF23/DQ23)^(1/3)-1 -> 0.14118179 | FC23: =(EK23/DV23)^(1/3)-1 -> 0.016456062 | FD23: =(EP23/EA23)^(1/3)-1 -> 0.037879469 | FE23: =(EU23/EF23)^(1/3)-1 -> 0.0084206825 | FF23: =(EV23/EK23)^(1/3)-1 -> 0.090941901 | FG23: =(EK23/DL23)^(1/5)-1 -> 0.082366811 | FH23: =(EP23/DQ23)^(1/5)-1 -> 0.097267673 | FI23: =(EU23/DV23)^(1/5)-1 -> 0.045093273 | FJ23: =(EV23/EA23)^(1/5)-1 -> 0.032173257 | FK23: =(EW23/EF23)^(1/5)-1 -> 0.037184421 | FL23: =(EX23/EK23)^(1/5)-1 -> 0.079172778
A24: Stock compensation expense (incl. above) | F24: 0 | K24: 2.506 | P24: 12.383 | Q24: 3.774 | R24: 3.735 | S24: 6.182 | T24: 7.944 | U24: =SUM(Q24:T24) -> 21.635 | V24: 36.418 | W24: 34.165 | X24: 73.794 | Y24: 84.984 | Z24: =SUM(V24:Y24) -> 229.361 | AA24: 76.473 | AB24: 74.761 | AC24: 67.981 | AD24: 59.531 | AE24: =SUM(AA24:AD24) -> 278.746 | AF24: 48.908 | AG24: 47.338 | AH24: 46.308 | AI24: 58.154 | AJ24: =SUM(AF24:AI24) -> 200.708 | AK24: =2.283+73.086+15.929+23.366 -> 114.664 | AL24: =2.322+70.564+14.285+21.978 -> 109.149 | AM24: =2.149+61.714+14.673+21.324 -> 99.86 | AN24: =10.874+82.122+14.502+26.929 -> 134.427 | AO24: =SUM(AK24:AN24) -> 458.1 | AP24: =4.389+120.787+27.25+31.44 -> 183.866 | AQ24: =7.659+156.983+36.385+40.497 -> 241.524 | AR24: =4.031+130.655+29.918+33.352 -> 197.956 | AS24: =6.255+161.372+38.085+39.588 -> 245.3 | AT24: =SUM(AP24:AS24) -> 868.646 | AU24: =9.148+193.8+42.576+35.255 -> 280.779 | AV24: =9.363+187.281+42.593+33.539 -> 272.776 | AW24: =10.729+169.263+64.497+35.55 -> 280.039 | AX24: =12.099+182.075+56.354+35.644 -> 286.172 | AY24: =SUM(AU24:AX24) -> 1119.766 | AZ24: =12.537+168.561+59.026+37.359 -> 277.483 | BA24: =13.592+182.209+57.294+39.975 -> 293.07 | BB24: =14.871+195.624+62.26+44.772 -> 317.527 | BC24: =6.051+178.948+52.439+38.536 -> 275.974 | BD24: =SUM(AZ24:BC24) -> 1164.054 | BE24: =6+191+54+40 -> 291 | BF24: =8+202+56+43 -> 309 | BG24: =8+244+75+53 -> 380 | BH24: =45+224+76+51 -> 396 | BI24: =SUM(BE24:BH24) -> 1376 | BJ24: =49+237+78+68 -> 432 | BK24: 435 | BL24: 571 | BM24: =77+266+105+88 -> 536 | BN24: =SUM(BJ24:BM24) -> 1974 | BO24: 556 | BP24: 747 | BQ24: 1064 | BR24: 878 | BS24: 3245 | BT24: 556 | BU24: 552 | BV24: 688 | BW24: 677 | BX24: =SUM(BT24:BW24) -> 2473 | BY24: 593 | BZ24: 783 | CA24: 886 | CB24: 917 | CC24: 3179 | CD24: =SUM(CD11,CD16,CD19,CD22) -> 655 | CE24: 743 | CF24: 856 | CG24: =SUM(CG11,CG16,CG19,CG22) -> 873 | CH24: =469+1641+552+465 -> 3127 | CI24: =SUM(CI11,CI16,CI19,CI22) -> 839 | CJ24: =SUM(CJ11,CJ16,CJ19,CJ22) -> 880 | CK24: =SUM(CK11,CK16,CK19,CK22) -> 1255 | CL24: =SUM(CL11,CL16,CL19,CL22) -> 1201 | CM24: =SUM(CI24:CL24) -> 4175 | CN24: =SUM(CN11,CN16,CN19,CN22) -> 1203 | CO24: =SUM(CO11,CO16,CO19,CO22) -> 1132 | CP24: =SUM(CP11,CP16,CP19,CP22) -> 1432 | CQ24: =SUM(CQ11,CQ16,CQ19,CQ22) -> 1436 | CR24: =SUM(CN24:CQ24) -> 5203 | CS24: =SUM(CS11,CS16,CS19,CS22) -> 1494 | CT24: =SUM(CT11,CT16,CT19,CT22) -> 1503 | CU24: =SUM(CU11,CU16,CU19,CU22) -> 1860 | CV24: =SUM(CV11,CV16,CV19,CV22) -> 1846 | CW24: =SUM(CS24:CV24) -> 6703 | CX24: 2009 | CY24: 2003 | CZ24: 1820 | DA24: 1847 | DB24: =SUM(CX24:DA24) -> 7679 | DC24: 2457 | DD24: 2413 | DE24: =2230 -> 2230 | DF24: 2253 | DG24: =SUM(DC24:DF24) -> 9353 | DH24: 2769 | DI24: 2756 | DJ24: 2624 | DK24: 2645 | DL24: =SUM(DH24:DK24) -> 10794 | DM24: 3191 | DN24: 3382 | DO24: 3195 | DP24: 3223 | DQ24: =SUM(DM24:DP24) -> 12991 | DR24: 3745 | DS24: 3803 | DT24: 3874 | DU24: 3954 | DV24: =SUM(DR24:DU24) -> 15376 | DW24: 4504 | DX24: 4782 | DY24: 4976 | DZ24: 5100 | EA24: =SUM(DW24:DZ24) -> 19362 | EB24: 5284 | EC24: 5774 | ED24: 5743 | EE24: 5659 | EF24: =SUM(EB24:EE24) -> 22460 | EG24: 5264 | EH24: 5865 | EI24: 5846 | EJ24: 5810 | EK24: =SUM(EG24:EJ24) -> 22785 | EL24: 5516 | EM24: 5998 | EN24: 6368 | EO24: =EO9*EO126 -> 6527.1865 | EP24: =SUM(EL24:EO24) -> 24409.187 | EQ24: =EQ9*EQ126 -> 6452.4608 | ER24: =ER9*ER126 -> 7098.6445 | ES24: =ES9*ES126 -> 7478.2179 | ET24: =ET9*ET126 -> 7452.3734 | EU24: =SUM(EQ24:ET24) -> 28481.697 | EV24: =EV9*EV126 -> 30856.088 | EW24: =EW9*EW126 -> 33307.093 | EX24: =EX9*EX126 -> 35765.58 | EY24: =EY9*EY126 -> 38299.932 | FA24: =(EA24/DL24)^(1/3)-1 -> 0.21503634 | FB24: =(EF24/DQ24)^(1/3)-1 -> 0.20020581 | FC24: =(EK24/DV24)^(1/3)-1 -> 0.14007972 | FD24: =(EP24/EA24)^(1/3)-1 -> 0.080275094 | FE24: =(EU24/EB24)^(1/3)-1 -> 0.75334622 | FF24: =(EV24/EC24)^(1/3)-1 -> 0.74832175 | FG24: =(EK24/DL24)^(1/5)-1 -> 0.16116336 | FH24: =(EP24/DQ24)^(1/5)-1 -> 0.1344416 | FI24: =(EU24/DV24)^(1/5)-1 -> 0.13121329 | FJ24: =(EV24/EA24)^(1/5)-1 -> 0.097686009 | FK24: =(EW24/EF24)^(1/5)-1 -> 0.081995355 | FL24: =(EX24/EG24)^(1/5)-1 -> 0.46699921
A25: Other 1x item, incl. Impairment charge | BX25: 0 | CD25: 0 | CE25: 0 | CF25: 0 | CG25: 0 | CH25: 0 | CI25: 0 | CJ25: 0 | CK25: =CK47 -> 378 | CL25: =CL47 -> 0 | CM25: =SUM(CI25:CL25) -> 378 | CN25: 0 | CO25: 0 | CP25: 0 | CQ25: 0 | CR25: =SUM(CN25:CQ25) -> 0 | CS25: 0 | CT25: 0 | CU25: 0 | CV25: 0 | CW25: =SUM(CS25:CV25) -> 0 | CX25: 0 | CY25: 2736 | CZ25: 0 | DA25: 0 | DB25: =SUM(CX25:DA25) -> 2736 | DD25: =5071 -> 5071 | DE25: 0 | DF25: 0 | DG25: =SUM(DC25:DF25) -> 5071 | DH25: 1697 | DI25: 0 | DJ25: 0 | DK25: 0 | DL25: =SUM(DH25:DK25) -> 1697 | DM25: 0 | DN25: 0 | DO25: 0 | DP25: 0 | DQ25: =SUM(DM25:DP25) -> 0 | DR25: 0 | DS25: 0 | DT25: 0 | DU25: 0 | DV25: =SUM(DR25:DU25) -> 0 | DW25: 0 | DX25: 0 | DY25: 0 | DZ25: 0 | EA25: =SUM(DW25:DZ25) -> 0 | EB25: 0 | EC25: 0 | ED25: 0 | EE25: 0 | EF25: =SUM(EB25:EE25) -> 0 | EG25: 0 | EH25: 0 | EI25: 0 | EJ25: 0 | EK25: =SUM(EG25:EJ25) -> 0 | EL25: 0 | EM25: 0 | EN25: 3457 | EO25: 0 | EP25: =SUM(EL25:EO25) -> 3457 | EQ25: 0 | ER25: 0 | ES25: 0 | ET25: 0 | EU25: =SUM(EQ25:ET25) -> 0
A26: Total operating expenses | F26: =SUM(F15,F18,F21,F24) -> 5.828 | K26: =SUM(K15,K18,K21,K24) -> 27.764 | P26: =SUM(P15,P18,P21,P24) -> 61.234 | Q26: =SUM(Q15:Q24) -> 21.386 | R26: =SUM(R15:R24) -> 27.021 | S26: =SUM(S15:S24) -> 34.252 | T26: =SUM(T15:T24) -> 38.873 | U26: =SUM(U15,U18,U21,U24) -> 121.532 | V26: =SUM(V15:V24) -> 76.717 | W26: =SUM(W15:W24) -> 89.014 | X26: =SUM(X15:X24) -> 156.996 | Y26: =SUM(Y15:Y24) -> 174.889 | Z26: =SUM(Z15,Z18,Z21,Z24) -> 497.616 | AA26: =SUM(AA15,AA18,AA21,AA24) -> 180.902 | AB26: =SUM(AB15,AB18,AB21,AB24) -> 202.877 | AC26: =SUM(AC15,AC18,AC21,AC24) -> 231.676 | AD26: =SUM(AD15,AD18,AD21,AD24) -> 274.923 | AE26: =SUM(AE15,AE18,AE21,AE24) -> 890.378 | AF26: =SUM(AF15,AF18,AF21,AF24) -> 268.538 | AG26: =SUM(AG15,AG18,AG21,AG24) -> 311.702 | ... BW26: =SUM(BW15,BW18,BW21,BW24) -> 4296 | BX26: =SUM(BX17,BX20,BX23) -> 15029 | BY26: 4548 | BZ26: 5034 | CA26: 5173 | CB26: 5667 | CC26: 20422 | CD26: =SUM(CD17,CD20,CD23) -> 4067 | CE26: =SUM(CE17,CE20,CE23) -> 4447 | CF26: =SUM(CF17,CF20,CF23) -> 4584 | CG26: =SUM(CG17,CG20,CG23) -> 5025 | CH26: =SUM(CH17,CH20,CH23) -> 18123 | CI26: =SUM(CI17,CI20,CI23) -> 5344 | CJ26: =SUM(CJ17,CJ20,CJ23) -> 5583 | CK26: =SUM(CK17,CK20,CK23) -> 6104 | ... CW26: =SUM(CW17,CW20,CW23) -> 31418 | CX26: =SUM(CX17,CX20,CX23,CX25) -> 8387 | CY26: =SUM(CY17,CY20,CY23,CY25) -> 11505 | CZ26: =SUM(CZ17,CZ20,CZ23,CZ25) -> 8842 | DA26: =SUM(DA17,DA20,DA23,DA25) -> 10392 | DB26: =SUM(DB17,DB20,DB23,DB25) -> 39126 | DC26: =SUM(DC17,DC20,DC23,DC25) -> 10046 | DD26: =SUM(DD17,DD20,DD23,DD25) -> 15729 | DE26: =SUM(DE17,DE20,DE23,DE25) -> 10834 | ... EY26: =SUM(EY17,EY20,EY23,EY25) -> 159317.52 | FA26: =(EA26/DL26)^(1/3)-1 -> 0.13641989 | FB26: =(EF26/DQ26)^(1/3)-1 -> 0.16639105 | FC26: =(EK26/DV26)^(1/3)-1 -> 0.10337439 | FD26: =(EP26/EA26)^(1/3)-1 -> 0.094892688 | FE26: =(EU26/EF26)^(1/3)-1 -> 0.08973206 | FF26: =(EV26/EK26)^(1/3)-1 -> 0.12055097 | FG26: =(EK26/DL26)^(1/5)-1 -> 0.1038175 | FH26: =(EP26/DQ26)^(1/5)-1 -> 0.13669844 | FI26: =(EU26/DV26)^(1/5)-1 -> 0.11310407 | FJ26: =(EV26/EA26)^(1/5)-1 -> 0.094543304 | FK26: =(EW26/EF26)^(1/5)-1 -> 0.09144542 | FL26: =(EX26/EK26)^(1/5)-1 -> 0.1034676
A27: GAAP Operating income | F27: =F13-F26 -> -6.516 | K27: =K13-K26 -> -14.737 | P27: =P13-P26 -> 10.964 | Q27: =Q13-Q26 -> 15.207 | R27: =R13-R26 -> 31.097 | S27: =S13-S26 -> 56.913 | T27: =T13-T26 -> 83.249 | U27: =U13-U26 -> 186.466 | V27: =V13-V26 -> 84.706 | W27: =W13-W26 -> 104.784 | ... BN27: =BN13-BN26 -> 12242 | BO27: 3389 | BP27: 3203 | BQ27: 2736 | BR27: 3394 | BS27: 12722 | BT27: =BT13-BT26 -> 3389 | BU27: =BU13-BU26 -> 3436 | BV27: =BV13-BV26 -> 3263 | BW27: =BW13-BW26 -> 3747 | BX27: =BX13-BX26 -> 13834 | BY27: 3477 | BZ27: 3123 | CA27: 3444 | CB27: 3922 | CC27: 13966 | CD27: =CD13-CD26 -> 3748 | CE27: =CE13-CE26 -> 3465 | CF27: =CF13-CF26 -> 3761 | CG27: =CG13-CG26 -> 4429 | CH27: =CH13-CH26 -> 15403 | CI27: =CI13-CI26 -> 4115 | CJ27: =CJ13-CJ26 -> 4258 | CK27: =CK13-CK26 -> 3724 | ... EY27: =EY13-EY26 -> 260643.46 | FA27: =(EA27/DL27)^(1/3)-1 -> 0.29790209 | FB27: =(EF27/DQ27)^(1/3)-1 -> 0.26924987 | FC27: =(EK27/DV27)^(1/3)-1 -> 0.1260523 | FD27: =(EP27/EA27)^(1/3)-1 -> 0.20344605 | FE27: =(EU27/EF27)^(1/3)-1 -> 0.23751582 | FF27: =(EV27/EK27)^(1/3)-1 -> 0.16714112 | FG27: =(EK27/DL27)^(1/5)-1 -> 0.26841572 | FH27: =(EP27/DQ27)^(1/5)-1 -> 0.25908493 | FI27: =(EU27/DV27)^(1/5)-1 -> 0.15206866 | FJ27: =(EV27/EA27)^(1/5)-1 -> 0.19011925 | FK27: =(EW27/EF27)^(1/5)-1 -> 0.19261221 | FL27: =(EX27/EK27)^(1/5)-1 -> 0.154154
A28: Non-GAAP Operating income | CR28: =CR27 -> 19360 | CS28: =CS27 -> 5342 | CT28: =CT27 -> 5968 | CU28: =CU27 -> 5767 | CV28: =CV27 -> 6639 | CW28: =CW27 -> 23716 | CX28: =CX27 -> 6568 | CY28: =CY27+CY25 -> 6868 | CZ28: =CZ27 -> 7782 | DA28: =DA27 -> 7664 | DB28: =SUM(CX28:DA28) -> 28882 | DC28: =DC27 -> 7633 | DD28: =DD27+DD25 -> 8116 | DE28: =DE27 -> 8625 | DF28: =DF27 -> 8221 | DG28: =SUM(DC28:DF28) -> 32595 | DH28: =DH27+DH25 -> 8305 | DI28: =DI27 -> 9180 | DJ28: =DJ27 -> 9177 | DK28: =DK27 -> 9266 | DL28: =SUM(DH28:DK28) -> 35928 | DM28: =DM27 -> 7977 | DN28: =DN27 -> 6383 | DO28: =DO27 -> 11213 | DP28: =DP27 -> 15651 | DQ28: =SUM(DM28:DP28) -> 41224 | DR28: =DR27 -> 16437 | DS28: =DS27 -> 19361 | DT28: =DT27 -> 21031 | DU28: =DU27 -> 21885 | DV28: =SUM(DR28:DU28) -> 78714 | DW28: =DW27 -> 20094 | DX28: =DX27 -> 19453 | DY28: =DY27 -> 17135 | DZ28: =DZ27 -> 18160 | EA28: =SUM(DW28:DZ28) -> 74842 | EB28: =EB27 -> 17415 | EC28: =EC27 -> 21838 | ED28: =ED27 -> 21343 | EE28: =EE27 -> 23697 | EF28: =SUM(EB28:EE28) -> 84293 | EG28: =EG27 -> 25472 | EH28: =EH27 -> 27425 | EI28: =EI27 -> 28521 | EJ28: =EJ27 -> 30972 | EK28: =SUM(EG28:EJ28) -> 112390 | EL28: =EL27 -> 30606 | EM28: =EM27 -> 31271 | EN28: =EN27 -> 31228 | EO28: =EO27 -> 37339.346 | EP28: =SUM(EL28:EO28) -> 130444.35 | EQ28: =EQ27 -> 37124.37 | ER28: =ER27 -> 38929.529 | ES28: =ES27 -> 40112.084 | ET28: =ET27 -> 43585.093 | EU28: =SUM(EQ28:ET28) -> 159751.08 | EV28: =EV27 -> 178688.98 | EW28: =EW27 -> 203370.41 | EX28: =EX27 -> 230168.82 | EY28: =EY27 -> 260643.46
A29: JPMe Adjusted Operating income | F29: =F13-SUM(F15:F21) -> -6.516 | K29: =K13-SUM(K15:K21) -> -12.231 | P29: =P13-SUM(P15:P21) -> -25.443 | Q29: =Q13-SUM(Q15:Q21) -> 18.981 | R29: =R13-SUM(R15:R21) -> 34.832 | S29: =S13-SUM(S15:S21) -> 63.095 | T29: =T13-SUM(T15:T21) -> 91.193 | U29: =SUM(Q29:T29) -> 208.101 | V29: =V13-SUM(V15:V21) -> 121.124 | W29: =W13-SUM(W15:W21) -> 138.949 | X29: =X13-SUM(X15:X21) -> 140.35 | Y29: =Y13-SUM(Y15:Y21) -> 171.402 | Z29: =SUM(V29:Y29) -> 571.825 | AA29: =AA13-SUM(AA15:AA21) -> 231.796 | AB29: =AB13-SUM(AB15:AB21) -> 245.719 | AC29: =AC13-SUM(AC15:AC21) -> 280.093 | AD29: =AD13-SUM(AD15:AD21) -> 362.33 | AE29: =SUM(AA29:AD29) -> 1119.938 | AF29: =AF13-SUM(AF15:AF21) -> 491.678 | AG29: =AG13-SUM(AG15:AG21) -> 523.036 | AH29: =AH13-SUM(AH15:AH21) -> 575.479 | AI29: =AI13-SUM(AI15:AI21) -> 717.794 | AJ29: =SUM(AF29:AI29) -> 2307.987 | AK29: =AK13-SUM(AK15:AK21) -> 330.806 | AL29: =AL13-SUM(AL15:AL21) -> 360.723 | AM29: =AM13-SUM(AM15:AM21) -> 435.2 | AN29: =AN13-SUM(AN15:AN21) -> 456.385 | AO29: =SUM(AK29:AN29) -> 1583.114 | AP29: =AP13-SUM(AP15:AP21) -> 546.102 | AQ29: =AQ13-SUM(AQ15:AQ21) -> 265.061 | AR29: =AR13-SUM(AR15:AR21) -> 425.893 | AS29: =AS13-SUM(AS15:AS21) -> 433.503 | AT29: =AT13-SUM(AT15:AT21) -> 1670.559 | AU29: =AU13-SUM(AU15:AU21) -> 470.671 | AV29: =AV13-SUM(AV15:AV21) -> 454.105 | AW29: =AW13-SUM(AW15:AW21) -> 480.472 | ... BD29: =BD13-SUM(BD15:BD21) -> 3692.911 | BE29: =BE9-SUM(BE10,BE15,BE18,BE21)+BE25 -> 2779 | BF29: =BF9-SUM(BF10,BF15,BF18,BF21)+BF25 -> 2674 | BG29: =BG9-SUM(BG10,BG15,BG18,BG21)+BG25 -> 2927 | BH29: =BH9-SUM(BH10,BH15,BH18,BH21)+BH25 -> 3378 | BI29: =BI9-SUM(BI10,BI15,BI18,BI21)+BI25 -> 11758 | BJ29: =BJ9-SUM(BJ10,BJ15,BJ18,BJ21)+BJ25 -> 3228 | BK29: =BK9-SUM(BK10,BK15,BK18,BK21)+BK25 -> 3316 | BL29: =BL9-SUM(BL10,BL15,BL18,BL21)+BL25 -> 3629 | ... BN29: =BN9-SUM(BN10,BN15,BN18,BN21)+BN25 -> 14216 | BO29: 3945 | BP29: 3950 | BQ29: 3800 | BR29: 4272 | BS29: 15967 | BT29: =BT9-SUM(BT10,BT15,BT18,BT21)+BT25 -> 3945 | BU29: =BU9-SUM(BU10,BU15,BU18,BU21)+BU25 -> 3988 | BV29: =BV9-SUM(BV10,BV15,BV18,BV21)+BV25 -> 3951 | BW29: =BW9-SUM(BW10,BW15,BW18,BW21)+BW25 -> 4424 | BX29: =BX9-SUM(BX10,BX15,BX18,BX21)+BX25 -> #REF! | BY29: 4070 | BZ29: 3990 | CA29: 4342 | CB29: 4839 | CC29: 17241 | CD29: =CD27+CD24+CD25 -> 4403 | CE29: =CE27+CE24+CE25+84 -> 4292 | CF29: =CF27+CF24+CF25+12 -> 4629 | CG29: =CG27+CG24+CG25 -> 5302 | CH29: =SUM(CD29:CG29) -> 18626 | CI29: =CI27+CI24+CI25 -> 4954 | CJ29: =CJ27+CJ24+CJ25 -> 5138 | CK29: =CK27+CK24+CK25 -> 5357 | CL29: =CL27+CL24+CL25 -> 5600 | CM29: =CM27+CM24+CM25 -> 21049 | CN29: =CN27+CN24+CN25 -> 5650 | CO29: =CO27+CO24+CO25 -> 5957 | CP29: =CP27+CP24+CP25 -> 6140 | ... EY29: =EY27+EY24+EY25 -> 298943.39 | FA29: =(EA29/DL29)^(1/3)-1 -> 0.26332757 | FB29: =(EF29/DQ29)^(1/3)-1 -> 0.25339188 | FC29: =(EK29/DV29)^(1/3)-1 -> 0.12836854 | FD29: =(EP29/EA29)^(1/3)-1 -> 0.18890409 | FE29: =(EU29/EF29)^(1/3)-1 -> 0.20810602 | FF29: =(EV29/EK29)^(1/3)-1 -> 0.15733839 | FG29: =(EK29/DL29)^(1/5)-1 -> 0.23673027 | FH29: =(EP29/DQ29)^(1/5)-1 -> 0.2390193 | FI29: =(EU29/DV29)^(1/5)-1 -> 0.14876277 | FJ29: =(EV29/EA29)^(1/5)-1 -> 0.17338794 | FK29: =(EW29/EF29)^(1/5)-1 -> 0.17261482 | FL29: =(EX29/EK29)^(1/5)-1 -> 0.14492128
A30: Other income, expense and other, net | F30: 0.44 | K30: 0.047 | P30: -0.896 | Q30: -0.501 | R30: -0.31 | S30: -0.677 | T30: -0.063 | U30: =SUM(Q30:T30) -> -1.551 | V30: -0.047 | W30: 0.766 | X30: 0.464 | Y30: 3.007 | Z30: =SUM(V30:Y30) -> 4.19 | AA30: 0.3 | AB30: -1.498 | AC30: 3.866 | AD30: 7.374 | AE30: =SUM(AA30:AD30) -> 10.042 | AF30: 13.686 | AG30: 19.722 | AH30: 20.797 | AI30: 70.193 | AJ30: =SUM(AF30:AI30) -> 124.398 | AK30: 67.919 | AL30: =160.805 -> 160.805 | AM30: 108.18 | AN30: 124.139 | AO30: =SUM(AK30:AN30) -> 461.043 | AP30: 130.728 | AQ30: 137.13 | AR30: 154.428 | AS30: 167.294 | AT30: =SUM(AP30:AS30) -> 589.58 | AU30: 167.343 | AV30: 57.923 | AW30: 21.217 | AX30: =69.899 -> 69.899 | AY30: =SUM(AU30:AX30) -> 316.382 | AZ30: 6.21 | BA30: -17.718 | BB30: -7.177 | BC30: 87.688 | BD30: =SUM(AZ30:BC30) -> 69.003 | BE30: 18 | BF30: 69 | BG30: 167 | BH30: 160 | BI30: =SUM(BE30:BH30) -> 414 | BJ30: 96 | BK30: 204 | BL30: 302 | BM30: -18 | BN30: =SUM(BJ30:BM30) -> 584 | BO30: 156 | BP30: 254 | BQ30: 63 | BR30: 152 | BS30: 625 | BT30: 156 | BU30: 254 | BV30: 63 | BW30: 152 | BX30: 635 | BY30: 134 | BZ30: 247 | CA30: 24 | CB30: 125 | CC30: 530 | CD30: 134 | CE30: 236 | CF30: 24 | CG30: 112 | CH30: 496 | CI30: 357 | CJ30: 145 | CK30: 133 | CL30: 128 | CM30: =SUM(CI30:CL30) -> 763 | CN30: 157 | CO30: 131 | CP30: 183 | CQ30: -180 | CR30: =SUM(CN30:CQ30) -> 291 | CS30: -213 | CT30: 151 | CU30: 278 | CV30: 218 | CW30: =SUM(CS30:CV30) -> 434 | CX30: 251 | CY30: 245 | CZ30: 197 | DA30: 354 | DB30: =SUM(CX30:DA30) -> 1047 | DC30: 2910 | DD30: =1408-DD221 -> 1170 | DE30: =1773-DE221 -> 1458 | DF30: =1869-DF221 -> 1851 | DG30: =SUM(DC30:DF30) -> 7389 | DH30: 1538 | DI30: 2967 | DJ30: -549 | DK30: 1438 | DL30: =SUM(DH30:DK30) -> 5394 | DM30: -220 | DN30: 1894 | DO30: 2146 | DP30: 3038 | DQ30: =SUM(DM30:DP30) -> 6858 | DR30: 4846 | DS30: 2624 | DT30: 2033 | DU30: 2517 | DV30: =SUM(DR30:DU30) -> 12020 | DW30: -1160 | DX30: -439 | DY30: -902 | DZ30: -1013 | EA30: =SUM(DW30:DZ30) -> -3514 | EB30: 790 | EC30: 65 | ED30: -146 | EE30: 715 | EF30: =SUM(EB30:EE30) -> 1424 | EG30: 2843 | EH30: 126 | EI30: 3185 | EJ30: 1271 | EK30: =SUM(EG30:EJ30) -> 7425 | EL30: 11183 | EM30: 2662 | EN30: 12759 | EO30: =EO198 -> 950.78376 | EP30: =SUM(EL30:EO30) -> 27554.784 | EQ30: =EQ198 -> 937.47105 | ER30: =ER198 -> 827.10196 | ES30: =ES198 -> 733.79092 | ET30: =ET198 -> 745.27348 | EU30: =SUM(EQ30:ET30) -> 3243.6374 | EV30: =EV198 -> 2731.6579 | EW30: =EW198 -> 2450.3181 | EX30: =EX198 -> 2714.1656 | EY30: =EY198 -> 3638.3159
A31: One-time items | F31: 0 | K31: 0 | P31: 0 | Q31: 0 | R31: 0 | S31: 0 | T31: 0 | U31: =SUM(Q31:T31) -> 0 | V31: 0 | W31: 0 | X31: 0 | Y31: 0 | Z31: =SUM(V31:Y31) -> 0 | AA31: 0 | AB31: 0 | AC31: -201 | AD31: 0 | AE31: =SUM(AA31:AD31) -> -201 | AF31: 0 | AG31: 0 | AH31: 0 | AI31: -90 | AJ31: =SUM(AF31:AI31) -> -90 | AK31: 0 | AL31: 0 | AM31: 0 | AN31: 0 | AO31: =SUM(AK31:AN31) -> 0 | AP31: 0 | AQ31: 0 | AR31: 0 | AS31: 0 | AT31: =SUM(AP31:AS31) -> 0 | AU31: 0 | AV31: 0 | AW31: 0 | AX31: -1094.757 | AY31: =SUM(AU31:AX31) -> -1094.757 | AZ31: 0 | BA31: 0 | BB31: 0 | BC31: 0 | BD31: =SUM(AZ31:BC31) -> 0 | BE31: 0 | BF31: 0 | BG31: 0 | BH31: 0 | BI31: =SUM(BE31:BH31) -> 0 | BJ31: -500 | BK31: 0 | BL31: 0 | BM31: 0 | BN31: 0 | BP31: 0 | BQ31: 0 | BR31: 0 | BS31: 0 | BU31: 0 | BV31: 0 | BW31: 0 | BX31: 0 | CB31: 0 | CC31: 0 | CD31: 0 | CE31: 0 | CF31: 0 | CG31: 0 | CH31: 0 | CI31: 0 | CJ31: 0 | CK31: =-CK47 -> -378 | CL31: =-CL47 -> 0 | CM31: =SUM(CI31:CL31) -> -378 | CN31: 0 | CO31: 0 | CP31: =-CP47 -> 0 | CQ31: =-CQ47 -> 0 | CR31: =SUM(CN31:CQ31) -> 0 | CS31: 0 | CT31: 0 | CU31: 0 | CV31: 0 | CW31: =SUM(CS31:CV31) -> 0 | CX31: 0 | CY31: 0 | CZ31: 0 | DA31: 0 | DB31: =SUM(CX31:DA31) -> 0 | DC31: 0 | DD31: 0 | DE31: 0 | DF31: 0 | DG31: =SUM(DC31:DF31) -> 0 | DH31: 0 | DI31: 0 | DJ31: 0 | DK31: 0 | DL31: =SUM(DH31:DK31) -> 0 | DM31: 0 | DN31: 0 | DO31: 0 | DP31: 0 | DQ31: =SUM(DM31:DP31) -> 0 | DR31: 0 | DS31: 0 | DT31: 0 | DU31: 0 | DV31: =SUM(DR31:DU31) -> 0 | DW31: 0 | DX31: 0 | DY31: 0 | DZ31: 0 | EA31: =SUM(DW31:DZ31) -> 0 | EB31: 0 | EC31: 0 | ED31: 0 | EE31: 0 | EF31: =SUM(EB31:EE31) -> 0 | EG31: 0 | EH31: 0 | EI31: 0 | EJ31: 0 | EK31: =SUM(EG31:EJ31) -> 0 | EL31: 0 | EM31: 0 | EN31: 0 | EP31: =SUM(EL31:EO31) -> 0 | EU31: =SUM(EQ31:ET31) -> 0
