Workbook
Name _MailAutoSig: 'P&L'!$I$13
Name Case: Output!$C$6
Name Circ: Output!$C$7
Name IQ_CH: 110000
Name IQ_CQ: 5000
Name IQ_CY: 10000
Name IQ_DAILY: 500000
Name IQ_FH: 100000
Name IQ_FQ: 500
Name IQ_FY: 1000
Name IQ_LTM: 2000
Name IQ_MONTH: 15000
Name IQ_NTM: 6000
Name IQ_WEEK: 50000
Name IQ_YTD: 3000

Sheet Output
A1: in CADm unless otherwise stated
A2: FYE June
J3: 2023 | K3: =+J3+1 -> 2024 | L3: =+K3+1 -> 2025 | M3: =+L3+1 -> 2026 | N3: =+M3+1 -> 2027 | O3: =+N3+1 -> 2028 | P3: =+O3+1 -> 2029 | Q3: =+P3+1 -> 2030 | R3: =+Q3+1 -> 2031 | S3: =+R3+1 -> 2032
A5: x | B5: Cover
B6: Operating case | C6: 1 | D6: =+CHOOSE(Case, "Base", "Upside", "Downside") -> Base
B7: Circularity | C7: 1
B8: FX USDCAD (Bloomberg fwd) | J8: 1.3503 | K8: 1.344 | L8: 1.3365 | M8: 1.3303 | N8: 1.3236 | O8: 1.3172 | P8: 1.3128 | Q8: 1.3102 | R8: 1.3098 | S8: 1.3089
B10: Exit multiple (Content business)
B11: Base | C11: 15
B12: Upside | C12: 15
B13: Downside | C13: 11
A15: x | B15: Entry | G15: x | H15: Valuation
D16: 44958 | K16: 45473 | L16: =+EDATE(K16,12) -> 45838 | M16: =+EDATE(L16,12) -> 46203
B17: Capitalization | K17: FY2024 | L17: FY2025 | M17: FY2026 | O17: Bridge | P17: 2022 Entry | Q17: 2026 Exit | R17: Value | S17: % of value | T17: Bridge to TP
B18: Current share price (CAD) | D18: 2.81 | H18: Content | K18: =+K20-K19 -> 90.973135 | L18: =+L20-L19 -> 106.26103 | M18: =+M20-M19 -> 118.34244 | O18: Revenue | P18: =+'P&L'!I6 -> 507.223 | Q18: =+'P&L'!M6 -> 706.85889 | R18: =+(Q18-P18)*P19*P20/$M$31 -> 2.5559885 | S18: =+R18/$R$22 -> 0.66618286 | T18: =+$R$22*S18 -> 2.5559885
B19: Shares outstanding (mm) | D19: 173.117 | H19: TV | K19: =+'P&L'!K76 -> 14.970383 | L19: =+'P&L'!L76 -> 13.971568 | M19: =+'P&L'!M76 -> 13.012705 | O19: Margin | P19: =+'P&L'!I72 -> 0.14259043 | Q19: =+'P&L'!M72 -> 0.18582938 | R19: =+(Q19-P19)*Q18*P20/$M$31 -> 2.7443392 | S19: =+R19/$R$22 -> 0.71527385 | T19: =+$R$22*S19 -> 2.7443392
B20: Market cap (CADm) | D20: =+D18*D19 -> 486.45877 | H20: Total proportionate Adj. EBITDA | K20: =+'P&L'!K71 -> 105.94352 | L20: =+'P&L'!L71 -> 120.2326 | M20: =+'P&L'!M71 -> 131.35515 | O20: Multiple | P20: =+D28 -> 15.543886 | Q20: =+M26 -> 14.009349 | R20: =+(Q20-P20)*Q19*Q18/$M$31 -> -1.1643796 | S20: =+R20/$R$22 -> -0.30347936 | T20: =+$R$22*S20 -> -1.1643796
O21: FCF | R21: =+R22-SUM(R18:R20) -> -0.29918091 | S21: =+R21/$R$22 -> -0.077977345 | T21: =+$R$22*S21 -> -0.29918091
B22: (+) Net debt (incl leases) | D22: =+Quarterly!E96 -> 637.755 | H22: Content | I22: =+CHOOSE(Case,C11,C12,C13) -> 15 | K22: =+K18*$I22 -> 1364.597 | L22: =+L18*$I22 -> 1593.9154 | M22: =+M18*$I22 -> 1775.1366 | O22: Total value per share | R22: =+M33-D18 -> 3.8367671
B23: (+) NCI | D23: =+Quarterly!E82 -> 260.503 | H23: TV | I23: 5 | K23: =+K19*$I23 -> 74.851917 | L23: =+L19*$I23 -> 69.85784 | M23: =+M19*$I23 -> 65.063527
B24: EV (CADm) | D24: =+D22+D20+D23 -> 1384.7168 | H24: EV (excl. NCI) | K24: =SUM(K22:K23) -> 1439.4489 | L24: =SUM(L22:L23) -> 1663.7733 | M24: =SUM(M22:M23) -> 1840.2001
B25: LTM EBITDA | D25: =+D24/Summary!I19 -> 14.469501
H26: Implied multiple | K26: =+K24/K20 -> 13.586947 | L26: =+L24/L20 -> 13.837955 | M26: =+M24/M20 -> 14.009349
B27: EV excl NCI (CADm) | D27: =+D24-D23 -> 1124.2138
B28: LTM EBITDA | D28: =+D27/Summary!I22 -> 15.543886 | H28: (-) Net debt (incl leases) | K28: =+'BS & CFS'!K50 -> 636.68537 | L28: =+'BS & CFS'!L50 -> 666.6911 | M28: =+'BS & CFS'!M50 -> 689.55835
H29: Equity value | K29: =+K24-K28 -> 802.76358 | L29: =+L24-L28 -> 997.08216 | M29: =+M24-M28 -> 1150.6418
H31: Shares out (mm) | K31: =+'P&L'!K41 -> 173.113 | L31: =+'P&L'!L41 -> 173.113 | M31: =+'P&L'!M41 -> 173.113
H33: Price per share (CAD) | K33: =+K29/K31 -> 4.6372229 | L33: =+L29/L31 -> 5.7597186 | M33: =+M29/M31 -> 6.6467671
H34: Upside % | K34: =+K33/$D$18-1 -> 0.65025728 | L34: =+L33/$D$18-1 -> 1.0497219 | M34: =+M33/$D$18-1 -> 1.3653975
H35: MOIC | K35: =+K33/$D$18 -> 1.6502573 | L35: =+L33/$D$18 -> 2.0497219 | M35: =+M33/$D$18 -> 2.3653975
H36: IRR % | K36: =+K35^(1/(YEARFRAC($D$16,K16)))-1 -> 0.42517297 | L36: =+L35^(1/(YEARFRAC($D$16,L16)))-1 -> 0.34624976 | M36: =+M35^(1/(YEARFRAC($D$16,M16)))-1 -> 0.28683956

Sheet Summary
A1: in CADm unless otherwise stated
A2: FYE June
E3: 2018 | F3: =+E3+1 -> 2019 | G3: =+F3+1 -> 2020 | H3: =+G3+1 -> 2021 | I3: =+H3+1 -> 2022 | J3: =+I3+1 -> 2023 | K3: =+J3+1 -> 2024 | L3: =+K3+1 -> 2025 | M3: =+L3+1 -> 2026 | ... S3: =+R3+1 -> 2032 | U3: '18-'22 CAGR | V3: '22-'26 CAGR
A4: x | B4: Profit model
B5: =+'RevBuild Calcs'!B7 -> Content production and distribution | E5: =+'RevBuild Calcs'!E7 -> 164.374 | F5: =+'RevBuild Calcs'!F7 -> 143.763 | G5: =+'RevBuild Calcs'!G7 -> 145.225 | H5: =+'RevBuild Calcs'!H7 -> 185.084 | I5: =+'RevBuild Calcs'!I7 -> 206.572 | J5: =+'RevBuild Calcs'!J7 -> 216.9006 | K5: =+'RevBuild Calcs'!K7 -> 238.59066 | L5: =+'RevBuild Calcs'!L7 -> 262.44973 | ... S5: =+'RevBuild Calcs'!S7 -> 329.04763 | U5: =+(I5/E5)^(0.166666666666667)-1 -> 0.038818611 | V5: =+(M5/I5)^(0.166666666666667)-1 -> 0.049205749
B6: =+'RevBuild Calcs'!B8 -> WildBrain Spark | E6: =+'RevBuild Calcs'!E8 -> 57.282 | F6: =+'RevBuild Calcs'!F8 -> 68.996 | G6: =+'RevBuild Calcs'!G8 -> 62.278 | H6: =+'RevBuild Calcs'!H8 -> 45.754 | I6: =+'RevBuild Calcs'!I8 -> 55.41 | J6: =+'RevBuild Calcs'!J8 -> 45.65784 | K6: =+'RevBuild Calcs'!K8 -> 54.081711 | L6: =+'RevBuild Calcs'!L8 -> 69.630204 | ... S6: =+'RevBuild Calcs'!S8 -> 108.38647 | U6: =+(I6/E6)^(0.166666666666667)-1 -> -0.005522421 | V6: =+(M6/I6)^(0.166666666666667)-1 -> 0.052460987
B7: =+'RevBuild Calcs'!B9 -> Consumer Products | E7: =+'RevBuild Calcs'!E9 -> 157.746 | F7: =+'RevBuild Calcs'!F9 -> 174.572 | G7: =+'RevBuild Calcs'!G9 -> 168.604 | H7: =+'RevBuild Calcs'!H9 -> 175.194 | I7: =+'RevBuild Calcs'!I9 -> 203.557 | J7: =+'RevBuild Calcs'!J9 -> 223.9127 | K7: =+'RevBuild Calcs'!K9 -> 252.34961 | L7: =+'RevBuild Calcs'!L9 -> 284.41615 | ... S7: =+'RevBuild Calcs'!S9 -> 491.1406 | U7: =+(I7/E7)^(0.166666666666667)-1 -> 0.043409086 | V7: =+(M7/I7)^(0.166666666666667)-1 -> 0.078634948
B8: Canadian TV | E8: =+'RevBuild Calcs'!E12 -> 55.014 | F8: =+'RevBuild Calcs'!F12 -> 52.469 | G8: =+'RevBuild Calcs'!G12 -> 49.527 | H8: =+'RevBuild Calcs'!H12 -> 46.502 | I8: =+'RevBuild Calcs'!I12 -> 41.684 | J8: =+'RevBuild Calcs'!J12 -> 40.01664 | K8: =+'RevBuild Calcs'!K12 -> 38.415974 | L8: =+'RevBuild Calcs'!L12 -> 36.879335 | ... S8: =+'RevBuild Calcs'!S12 -> 28.867587 | U8: =+(I8/E8)^(0.166666666666667)-1 -> -0.045192048 | V8: =+(M8/I8)^(0.166666666666667)-1 -> -0.026847681
B9: Total revenue | E9: =SUM(E5:E8) -> 434.416 | F9: =SUM(F5:F8) -> 439.8 | G9: =SUM(G5:G8) -> 425.634 | H9: =SUM(H5:H8) -> 452.534 | I9: =SUM(I5:I8) -> 507.223 | J9: =SUM(J5:J8) -> 526.48778 | K9: =SUM(K5:K8) -> 583.43796 | L9: =SUM(L5:L8) -> 653.37542 | ... S9: =SUM(S5:S8) -> 957.4423 | U9: =+(I9/E9)^(0.166666666666667)-1 -> 0.026161038 | V9: =+(M9/I9)^(0.166666666666667)-1 -> 0.056871769
B10: % YoY | F10: =+F9/E9-1 -> 0.01239365 | G10: =+G9/F9-1 -> -0.032210095 | H10: =+H9/G9-1 -> 0.063199838 | I10: =+I9/H9-1 -> 0.12085059 | J10: =+J9/I9-1 -> 0.037980888 | K10: =+K9/J9-1 -> 0.10816999 | L10: =+L9/K9-1 -> 0.11987128 | M10: =+M9/L9-1 -> 0.081857183 | ... S10: =+S9/R9-1 -> 0.049855806
B12: Content business | H12: =+'RevBuild Calcs'!H18 -> 162.692 | I12: =+'RevBuild Calcs'!I18 -> 193.455 | J12: =+'RevBuild Calcs'!J18 -> 194.58846 | K12: =+'RevBuild Calcs'!K18 -> 223.45901 | L12: =+'RevBuild Calcs'!L18 -> 252.76339 | M12: =+'RevBuild Calcs'!M18 -> 275.29644 | N12: =+'RevBuild Calcs'!N18 -> 294.18696 | O12: =+'RevBuild Calcs'!O18 -> 310.88787 | ... S12: =+'RevBuild Calcs'!S18 -> 380.71563
B13: TV business | H13: =+'RevBuild Calcs'!H21 -> 32.195 | I13: =+'RevBuild Calcs'!I21 -> 28.106 | J13: =+'RevBuild Calcs'!J21 -> 26.010816 | K13: =+'RevBuild Calcs'!K21 -> 24.970383 | L13: =+'RevBuild Calcs'!L21 -> 23.971568 | M13: =+'RevBuild Calcs'!M21 -> 23.012705 | N13: =+'RevBuild Calcs'!N21 -> 22.092197 | O13: =+'RevBuild Calcs'!O21 -> 21.208509 | ... S13: =+'RevBuild Calcs'!S21 -> 18.763932
B14: Total gross profit | E14: =+'P&L'!E13 -> 190.172 | F14: =+'P&L'!F13 -> 186.797 | G14: =+'P&L'!G13 -> 187.845 | H14: =+'P&L'!H13 -> 199.259 | I14: =+'P&L'!I13 -> 221.561 | J14: =+'P&L'!J13 -> 220.59927 | K14: =+'P&L'!K13 -> 248.4294 | L14: =+'P&L'!L13 -> 276.73496 | ... S14: =+'P&L'!S13 -> 399.47956
B15: Gross margin % | E15: =+'P&L'!E14 -> 0.43776472 | F15: =+'P&L'!F14 -> 0.4247317 | G15: =+'P&L'!G14 -> 0.44132987 | H15: =+'P&L'!H14 -> 0.4403183 | I15: =+'P&L'!I14 -> 0.43681182 | J15: =+'P&L'!J14 -> 0.41900169 | K15: =+'P&L'!K14 -> 0.4258026 | L15: =+'P&L'!L14 -> 0.42354664 | ... S15: =+'P&L'!S14 -> 0.41723618
B17: Cash SG&A | E17: =+(E14-E19)*-1 -> -91.712 | F17: =+(F14-F19)*-1 -> -74.516 | G17: =+(G14-G19)*-1 -> -111.445 | H17: =+(H14-H19)*-1 -> -95.453 | I17: =+(I14-I19)*-1 -> -125.862 | J17: =+(J14-J19)*-1 -> -114.23815 | K17: =+(K14-K19)*-1 -> -110.45501 | L17: =+(L14-L19)*-1 -> -120.15135 | ... S17: =+(S14-S19)*-1 -> -162.2134
B19: Adj. EBITDA | E19: =+'P&L'!E68 -> 98.46 | F19: =+'P&L'!F68 -> 112.281 | G19: =+'P&L'!G68 -> 76.4 | H19: =+'P&L'!H68 -> 103.806 | I19: =+'P&L'!I68 -> 95.699 | J19: =+'P&L'!J68 -> 106.36113 | K19: =+'P&L'!K68 -> 137.97439 | L19: =+'P&L'!L68 -> 156.58362 | ... S19: =+'P&L'!S68 -> 237.26616
B20: EBITDA margin % | E20: =+E19/E9 -> 0.22664911 | F20: =+F19/F9 -> 0.25530014 | G20: =+G19/G9 -> 0.17949694 | H20: =+H19/H9 -> 0.22938829 | I20: =+I19/I9 -> 0.18867244 | J20: =+J19/J9 -> 0.20202012 | K20: =+K19/K9 -> 0.23648511 | L20: =+L19/L9 -> 0.23965336 | ... S20: =+S19/S9 -> 0.24781249
B22: Proportionate Adj. EBITDA | E22: =+'P&L'!E71 -> 89.64964 | F22: =+'P&L'!F71 -> 83.105748 | G22: =+'P&L'!G71 -> 56.018389 | H22: =+'P&L'!H71 -> 72.621356 | I22: =+'P&L'!I71 -> 72.325143 | J22: =+'P&L'!J71 -> 81.669301 | K22: =+'P&L'!K71 -> 105.94352 | L22: =+'P&L'!L71 -> 120.2326 | ... S22: =+'P&L'!S71 -> 182.18462
A24: x | B24: Mgmt compensation analysis
E25: 2018 | F25: =+E25+1 -> 2019 | G25: =+F25+1 -> 2020 | H25: =+G25+1 -> 2021 | I25: =+H25+1 -> 2022
B26: Salaries & benefits | E26: 4.205 | F26: 3.392 | G26: 4.709 | H26: 4.443 | I26: 4.071
B27: SBC | E27: 2.146 | F27: 1.838 | G27: 3.798 | H27: 2.895 | I27: 2.74
B28: Termination and other | E28: 2.899 | F28: 0.732 | G28: 1.388 | H28: 0 | I28: 0
B29: Total | E29: =+SUM(E26:E28) -> 9.25 | F29: =+SUM(F26:F28) -> 5.962 | G29: =+SUM(G26:G28) -> 9.895 | H29: =+SUM(H26:H28) -> 7.338 | I29: =+SUM(I26:I28) -> 6.811
B30: % SBC | E30: =+E27/E29 -> 0.232 | F30: =+F27/F29 -> 0.30828581 | G30: =+G27/G29 -> 0.38383022 | H30: =+H27/H29 -> 0.39452167 | I30: =+I27/I29 -> 0.40229041
A32: x | B32: Model Drivers

Sheet P&L
A1: in CADm unless otherwise stated
A2: FYE June
E3: 2018 | F3: =+E3+1 -> 2019 | G3: =+F3+1 -> 2020 | H3: =+G3+1 -> 2021 | I3: =+H3+1 -> 2022 | J3: =+I3+1 -> 2023 | K3: =+J3+1 -> 2024 | L3: =+K3+1 -> 2025 | M3: =+L3+1 -> 2026 | ... S3: =+R3+1 -> 2032
A5: x | B5: P&L
B6: Revenues | E6: 434.416 | F6: 439.8 | G6: 425.634 | H6: 452.534 | I6: 507.223 | J6: =+'RevBuild Calcs'!J14 -> 526.48778 | K6: =+'RevBuild Calcs'!K14 -> 583.43796 | L6: =+'RevBuild Calcs'!L14 -> 653.37542 | M6: =+'RevBuild Calcs'!M14 -> 706.85889 | N6: =+'RevBuild Calcs'!N14 -> 751.51717 | O6: =+'RevBuild Calcs'!O14 -> 790.89156 | P6: =+'RevBuild Calcs'!P14 -> 829.92286 | Q6: =+'RevBuild Calcs'!Q14 -> 870.20443 | ... S6: =+'RevBuild Calcs'!S14 -> 957.4423
B7: % YoY | F7: =+F6/E6-1 -> 0.01239365 | G7: =+G6/F6-1 -> -0.032210095 | H7: =+H6/G6-1 -> 0.063199838 | I7: =+I6/H6-1 -> 0.12085059 | J7: =+J6/I6-1 -> 0.037980888 | K7: =+K6/J6-1 -> 0.10816999 | L7: =+L6/K6-1 -> 0.11987128 | M7: =+M6/L6-1 -> 0.081857183 | ... S7: =+S6/R6-1 -> 0.049855806
B9: Income from litigation settlement | H9: 4.372
B11: Direct production costs and expense of film and television produced | E11: -244.244 | F11: -253.003 | G11: -237.789 | H11: -257.647 | I11: -285.662 | J11: =+J13-J6 -> -305.88851 | K11: =+K13-K6 -> -335.00856 | L11: =+L13-L6 -> -376.64045 | M11: =+M13-M6 -> -408.54974 | N11: =+N13-N6 -> -435.23801 | O11: =+O13-O6 -> -458.79519 | P11: =+P13-P6 -> -482.13689 | Q11: =+Q13-Q6 -> -506.20372 | ... S11: =+S13-S6 -> -557.96273
B13: Gross profit | E13: =+E6+E9+E11 -> 190.172 | F13: =+F6+F9+F11 -> 186.797 | G13: =+G6+G9+G11 -> 187.845 | H13: =+H6+H9+H11 -> 199.259 | I13: =+I6+I9+I11 -> 221.561 | J13: =+'RevBuild Calcs'!J26 -> 220.59927 | K13: =+'RevBuild Calcs'!K26 -> 248.4294 | L13: =+'RevBuild Calcs'!L26 -> 276.73496 | M13: =+'RevBuild Calcs'!M26 -> 298.30914 | N13: =+'RevBuild Calcs'!N26 -> 316.27916 | O13: =+'RevBuild Calcs'!O26 -> 332.09637 | P13: =+'RevBuild Calcs'!P26 -> 347.78597 | Q13: =+'RevBuild Calcs'!Q26 -> 364.00071 | ... S13: =+'RevBuild Calcs'!S26 -> 399.47956
B14: % margin | E14: =+E13/E6 -> 0.43776472 | F14: =+F13/F6 -> 0.4247317 | G14: =+G13/G6 -> 0.44132987 | H14: =+H13/H6 -> 0.4403183 | I14: =+I13/I6 -> 0.43681182 | J14: =+J13/J6 -> 0.41900169 | K14: =+K13/K6 -> 0.4258026 | L14: =+L13/L6 -> 0.42354664 | ... S14: =+S13/S6 -> 0.41723618
B16: Amortization of acquired and library content | E16: -15.916 | F16: -14.431 | G16: -12.082 | H16: -11.1 | I16: -10.241 | J16: =+'FS Calcs'!J44 -> -10 | K16: =+'FS Calcs'!K44 -> -10 | L16: =+'FS Calcs'!L44 -> -10 | M16: =+'FS Calcs'!M44 -> -10 | N16: =+'FS Calcs'!N44 -> -10 | O16: =+'FS Calcs'!O44 -> -10 | P16: =+'FS Calcs'!P44 -> -10 | Q16: =+'FS Calcs'!Q44 -> -10 | ... S16: =+'FS Calcs'!S44 -> -10
B17: Amortization of property and equipment and intangible assets | E17: -24.174 | F17: -22.651 | G17: -24.171 | H17: -22.924 | I17: -23.979 | J17: =+'FS Calcs'!J53+'FS Calcs'!J64 -> -31.589267 | K17: =+'FS Calcs'!K53+'FS Calcs'!K64 -> -29.79701 | L17: =+'FS Calcs'!L53+'FS Calcs'!L64 -> -29.985265 | M17: =+'FS Calcs'!M53+'FS Calcs'!M64 -> -28.779255 | N17: =+'FS Calcs'!N53+'FS Calcs'!N64 -> -29.523889 | O17: =+'FS Calcs'!O53+'FS Calcs'!O64 -> -29.940895 | P17: =+'FS Calcs'!P53+'FS Calcs'!P64 -> -30.232904 | Q17: =+'FS Calcs'!Q53+'FS Calcs'!Q64 -> -30.457155 | ... S17: =+'FS Calcs'!S53+'FS Calcs'!S64 -> -33.51048
B18: Write-down of investment in film and television programs, acquired and library content, and property and equipment | E18: -12.027 | F18: -104.871 | G18: -196.122 | H18: -7.832 | I18: -0.788 | J18: =+'FS Calcs'!J32+'FS Calcs'!J43+'FS Calcs'!J54+'FS Calcs'!J65 -> 0 | K18: =+'FS Calcs'!K32+'FS Calcs'!K43+'FS Calcs'!K54+'FS Calcs'!K65 -> 0 | L18: =+'FS Calcs'!L32+'FS Calcs'!L43+'FS Calcs'!L54+'FS Calcs'!L65 -> 0 | M18: =+'FS Calcs'!M32+'FS Calcs'!M43+'FS Calcs'!M54+'FS Calcs'!M65 -> 0 | N18: =+'FS Calcs'!N32+'FS Calcs'!N43+'FS Calcs'!N54+'FS Calcs'!N65 -> 0 | O18: =+'FS Calcs'!O32+'FS Calcs'!O43+'FS Calcs'!O54+'FS Calcs'!O65 -> 0 | P18: =+'FS Calcs'!P32+'FS Calcs'!P43+'FS Calcs'!P54+'FS Calcs'!P65 -> 0 | Q18: =+'FS Calcs'!Q32+'FS Calcs'!Q43+'FS Calcs'!Q54+'FS Calcs'!Q65 -> 0 | ... S18: =+'FS Calcs'!S32+'FS Calcs'!S43+'FS Calcs'!S54+'FS Calcs'!S65 -> 0
B20: Selling, general and administrative | E20: -86.2 | F20: -81.121 | G20: -83.098 | H20: -80.539 | I20: -104.129 | J20: =+'FS Calcs'!J104 -> -101.23057 | K20: =+'FS Calcs'!K104 -> -112.18068 | L20: =+'FS Calcs'!L104 -> -125.62792 | M20: =+'FS Calcs'!M104 -> -135.91147 | N20: =+'FS Calcs'!N104 -> -144.49815 | O20: =+'FS Calcs'!O104 -> -152.06887 | P20: =+'FS Calcs'!P104 -> -159.57362 | Q20: =+'FS Calcs'!Q104 -> -167.31877 | ... S20: =+'FS Calcs'!S104 -> -184.09246
B21: Share-based compensation | H21: -5.075 | I21: -7.414 | J21: -5 | K21: -5 | L21: -5 | M21: -5 | N21: -5 | O21: -5 | P21: -5 | Q21: -5 | R21: -5 | S21: -5
B22: Finance costs, net | E22: -50.109 | F22: -52.236 | G22: -49.404 | H22: -42.139 | I22: -30.486 | J22: =+IF(Circ=1, 'Debt Calcs'!J22, 0) -> -33.667631 | K22: =+IF(Circ=1, 'Debt Calcs'!K22, 0) -> -34.897668 | L22: =+IF(Circ=1, 'Debt Calcs'!L22, 0) -> -36.633587 | M22: =+IF(Circ=1, 'Debt Calcs'!M22, 0) -> -38.11403 | N22: =+IF(Circ=1, 'Debt Calcs'!N22, 0) -> -39.210471 | O22: =+IF(Circ=1, 'Debt Calcs'!O22, 0) -> -39.988572 | P22: =+IF(Circ=1, 'Debt Calcs'!P22, 0) -> -40.525313 | Q22: =+IF(Circ=1, 'Debt Calcs'!Q22, 0) -> -40.847902 | ... S22: =+IF(Circ=1, 'Debt Calcs'!S22, 0) -> -40.828171
B23: Change in fair value of embedded derivatives | E23: 11.251 | F23: 7.185 | G23: 1.955 | H23: -26.206 | I23: 13.716 | J23: 0 | K23: 0 | L23: 0 | M23: 0 | N23: 0 | O23: 0 | P23: 0 | Q23: 0 | R23: 0 | S23: 0
B24: Foreign exchange (loss) / gain | E24: -7.7 | F24: 1.081 | G24: -14.047 | H24: 24.979 | I24: -21.754 | J24: -12.5 | K24: -5 | L24: -5 | M24: -5 | N24: -5 | O24: -5 | P24: -5 | Q24: -5 | R24: -5 | S24: -5
B25: Reorganization, development and other expense | E25: -10.554 | F25: -1.661 | G25: -17.961 | H25: -8.612 | I25: -6.281 | J25: -2.5 | K25: -2.5 | L25: -2.5 | M25: -2.5 | N25: -2.5 | O25: -2.5 | P25: -2.5 | Q25: -2.5 | R25: -2.5 | S25: -2.5
B27: EBT | E27: =+E13+SUM(E16:E18,E20:E25) -> -5.257 | F27: =+F13+SUM(F16:F18,F20:F25) -> -81.908 | G27: =+G13+SUM(G16:G18,G20:G25) -> -207.085 | H27: =+H13+SUM(H16:H18,H20:H25) -> 19.811 | I27: =+I13+SUM(I16:I18,I20:I25) -> 30.205 | J27: =+J13+SUM(J16:J18,J20:J25) -> 24.111805 | K27: =+K13+SUM(K16:K18,K20:K25) -> 49.054041 | L27: =+L13+SUM(L16:L18,L20:L25) -> 61.988189 | ... S27: =+S13+SUM(S16:S18,S20:S25) -> 118.54846
B28: % margin | E28: =+E27/E6 -> -0.012101304 | F28: =+F27/F6 -> -0.1862392 | G28: =+G27/G6 -> -0.48653303 | H28: =+H27/H6 -> 0.043777926 | I28: =+I27/I6 -> 0.059549744 | J28: =+J27/J6 -> 0.045797464 | K28: =+K27/K6 -> 0.084077561 | L28: =+L27/L6 -> 0.09487377 | ... S28: =+S27/S6 -> 0.12381786
B30: Current income taxes (paid) / recovered | E30: -2.166 | F30: 1.77 | G30: -0.489 | H30: -3.049 | I30: -0.347 | J30: =+'FS Calcs'!J107 -> -6.9924236 | K30: =+'FS Calcs'!K107 -> -14.225672 | L30: =+'FS Calcs'!L107 -> -17.976575 | M30: =+'FS Calcs'!M107 -> -21.171273 | N30: =+'FS Calcs'!N107 -> -23.358528 | O30: =+'FS Calcs'!O107 -> -25.40343 | P30: =+'FS Calcs'!P107 -> -27.536698 | Q30: =+'FS Calcs'!Q107 -> -29.834296 | ... S30: =+'FS Calcs'!S107 -> -34.379052
B31: Deferred income taxes (paid) / recovered | E31: 0.675 | F31: 1.936 | G31: -1.217 | H31: 6.347 | I31: 1.904 | J31: =+'FS Calcs'!J108 -> 0 | K31: =+'FS Calcs'!K108 -> 0 | L31: =+'FS Calcs'!L108 -> 0 | M31: =+'FS Calcs'!M108 -> 0 | N31: =+'FS Calcs'!N108 -> 0 | O31: =+'FS Calcs'!O108 -> 0 | P31: =+'FS Calcs'!P108 -> 0 | Q31: =+'FS Calcs'!Q108 -> 0 | ... S31: =+'FS Calcs'!S108 -> 0
B32: Total | E32: =SUM(E30:E31) -> -1.491 | F32: =SUM(F30:F31) -> 3.706 | G32: =SUM(G30:G31) -> -1.706 | H32: =SUM(H30:H31) -> 3.298 | I32: =SUM(I30:I31) -> 1.557 | J32: =SUM(J30:J31) -> -6.9924236 | K32: =SUM(K30:K31) -> -14.225672 | L32: =SUM(L30:L31) -> -17.976575 | ... S32: =SUM(S30:S31) -> -34.379052
B34: Net income | E34: =+E32+E27 -> -6.748 | F34: =+F32+F27 -> -78.202 | G34: =+G32+G27 -> -208.791 | H34: =+H32+H27 -> 23.109 | I34: =+I32+I27 -> 31.762 | J34: =+J32+J27 -> 17.119382 | K34: =+K32+K27 -> 34.828369 | L34: =+L32+L27 -> 44.011614 | ... S34: =+S32+S27 -> 84.169404
B35: Attributable to NCI | E35: 7.312 | F35: 23.292 | G35: 27.175 | H35: 30.186 | I35: 26.122 | J35: =+'FS Calcs'!J98 -> 26.899258 | K35: =+'FS Calcs'!K98 -> 27.706235 | L35: =+'FS Calcs'!L98 -> 28.537422 | M35: =+'FS Calcs'!M98 -> 29.393545 | N35: =+'FS Calcs'!N98 -> 30.275351 | O35: =+'FS Calcs'!O98 -> 31.183612 | P35: =+'FS Calcs'!P98 -> 32.11912 | Q35: =+'FS Calcs'!Q98 -> 33.082694 | ... S35: =+'FS Calcs'!S98 -> 35.09743
B36: Attributable to common | E36: =+E34-E35 -> -14.06 | F36: =+F34-F35 -> -101.494 | G36: =+G34-G35 -> -235.966 | H36: =+H34-H35 -> -7.077 | I36: =+I34-I35 -> 5.64 | J36: =+J34-J35 -> -9.7798757 | K36: =+K34-K35 -> 7.1221337 | L36: =+L34-L35 -> 15.474192 | ... S36: =+S34-S35 -> 49.071975
B38: Basic EPS (CAD) | E38: -0.1 | F38: -0.75 | G38: -1.51 | H38: -0.04 | I38: 0.03 | J38: =+J$36/J41 -> -0.056494173 | K38: =+K$36/K41 -> 0.04114153 | L38: =+L$36/L41 -> 0.089387809 | M38: =+M$36/M41 -> 0.12962384 | N38: =+N$36/N41 -> 0.15546359 | O38: =+O$36/O41 -> 0.17913729 | P38: =+P$36/P41 -> 0.20390331 | Q38: =+Q$36/Q41 -> 0.23083126 | ... S38: =+S$36/S41 -> 0.28346788
B39: Diluted EPS (CAD) | E39: -0.1 | F39: -0.75 | G39: -1.51 | H39: -0.04 | I39: -0.01 | J39: =+J$36/J42 -> -0.051377306 | K39: =+K$36/K42 -> 0.037415204 | L39: =+L$36/L42 -> 0.081291656 | M39: =+M$36/M42 -> 0.11788337 | N39: =+N$36/N42 -> 0.14138274 | O39: =+O$36/O42 -> 0.16291223 | P39: =+P$36/P42 -> 0.1854351 | Q39: =+Q$36/Q42 -> 0.2099241 | ... S39: =+S$36/S42 -> 0.25779324
B41: Basic - WASO | E41: 134.506 | F41: 134.828 | G41: 156.748 | H41: 171.222 | I41: 172.584 | J41: 173.113 | K41: =+J41 -> 173.113 | L41: =+K41 -> 173.113 | M41: =+L41 -> 173.113 | N41: =+M41 -> 173.113 | O41: =+N41 -> 173.113 | P41: =+O41 -> 173.113 | Q41: =+P41 -> 173.113 | R41: =+Q41 -> 173.113 | S41: =+R41 -> 173.113
B42: Diluted - WASO | E42: 134.506 | F42: 134.828 | G42: 156.748 | H42: 171.222 | I42: 197.403 | J42: 190.354 | K42: =+J42 -> 190.354 | L42: =+K42 -> 190.354 | M42: =+L42 -> 190.354 | N42: =+M42 -> 190.354 | O42: =+N42 -> 190.354 | P42: =+O42 -> 190.354 | Q42: =+P42 -> 190.354 | R42: =+Q42 -> 190.354 | S42: =+R42 -> 190.354
B44: Dividend to common | E44: 0 | F44: 0 | G44: 0 | H44: 0 | I44: 0 | J44: =+'FS Calcs'!J76 -> 0 | K44: =+'FS Calcs'!K76 -> 0 | L44: =+'FS Calcs'!L76 -> 0 | M44: =+'FS Calcs'!M76 -> 0 | N44: =+'FS Calcs'!N76 -> 0 | O44: =+'FS Calcs'!O76 -> 0 | P44: =+'FS Calcs'!P76 -> 0 | Q44: =+'FS Calcs'!Q76 -> 0 | ... S44: =+'FS Calcs'!S76 -> 0
B45: Distribution to NCI | F45: -26.657 | G45: -33.46 | H45: -31.457 | I45: -33.609 | J45: =+'FS Calcs'!J82 -> -34.28118 | K45: =+'FS Calcs'!K82 -> -34.966804 | L45: =+'FS Calcs'!L82 -> -35.66614 | M45: =+'FS Calcs'!M82 -> -36.379462 | N45: =+'FS Calcs'!N82 -> -37.107052 | O45: =+'FS Calcs'!O82 -> -37.849193 | P45: =+'FS Calcs'!P82 -> -38.606177 | Q45: =+'FS Calcs'!Q82 -> -39.3783 | ... S45: =+'FS Calcs'!S82 -> -40.969183
A47: x | B47: Adj. EBITDA reconcillation
B48: EBT | E48: =+E27 -> -5.257 | F48: =+F27 -> -81.908 | G48: =+G27 -> -207.085 | H48: =+H27 -> 19.811 | I48: =+I27 -> 30.205 | J48: =+J27 -> 24.111805 | K48: =+K27 -> 49.054041 | L48: =+L27 -> 61.988189 | ... S48: =+S27 -> 118.54846
B49: Tax expense | E49: =+IF(E32<0,E32*-1, 0) -> 1.491 | F49: =+IF(F32<0,F32*-1, 0) -> 0 | G49: =+IF(G32<0,G32*-1, 0) -> 1.706 | H49: =+IF(H32<0,H32*-1, 0) -> 0 | I49: =+IF(I32<0,I32*-1, 0) -> 0 | J49: =+IF(J32<0,J32*-1, 0) -> 6.9924236 | K49: =+IF(K32<0,K32*-1, 0) -> 14.225672 | L49: =+IF(L32<0,L32*-1, 0) -> 17.976575 | ... S49: =+IF(S32<0,S32*-1, 0) -> 34.379052
B50: Interest | E50: =+E22*-1 -> 50.109 | F50: =+F22*-1 -> 52.236 | G50: =+G22*-1 -> 49.404 | H50: =+H22*-1 -> 42.139 | I50: =+I22*-1 -> 30.486 | J50: =+J22*-1 -> 33.667631 | K50: =+K22*-1 -> 34.897668 | L50: =+L22*-1 -> 36.633587 | ... S50: =+S22*-1 -> 40.828171
B51: D&A | E51: =+SUM(E16:E17)*-1 -> 40.09 | F51: =+SUM(F16:F17)*-1 -> 37.082 | G51: =+SUM(G16:G17)*-1 -> 36.253 | H51: =+SUM(H16:H17)*-1 -> 34.024 | I51: =+SUM(I16:I17)*-1 -> 34.22 | J51: =+SUM(J16:J17)*-1 -> 41.589267 | K51: =+SUM(K16:K17)*-1 -> 39.79701 | L51: =+SUM(L16:L17)*-1 -> 39.985265 | ... S51: =+SUM(S16:S17)*-1 -> 43.51048
B52: SBC | E52: =+E21*-1 -> 0 | F52: =+F21*-1 -> 0 | G52: =+G21*-1 -> 0 | H52: =+H21*-1 -> 5.075 | I52: =+I21*-1 -> 7.414 | J52: =+J21*-1 -> 5 | K52: =+K21*-1 -> 5 | L52: =+L21*-1 -> 5 | ... S52: =+S21*-1 -> 5
B53: Writedowns | E53: =+E18*-1 -> 12.027 | F53: =+F18*-1 -> 104.871 | G53: =+G18*-1 -> 196.122 | H53: =+H18*-1 -> 7.832 | I53: =+I18*-1 -> 0.788 | J53: =+J18*-1 -> 0 | K53: =+K18*-1 -> 0 | L53: =+L18*-1 -> 0 | ... S53: =+S18*-1 -> 0
...

Sheet BS & CFS
A1: in CADm unless otherwise stated
A2: FYE June
E3: 2018 | F3: =+E3+1 -> 2019 | G3: =+F3+1 -> 2020 | H3: =+G3+1 -> 2021 | I3: =+H3+1 -> 2022 | J3: =+I3+1 -> 2023 | K3: =+J3+1 -> 2024 | L3: =+K3+1 -> 2025 | M3: =+L3+1 -> 2026 | ... S3: =+R3+1 -> 2032
A5: x | B5: BS
B6: Cash & Equivalents | E6: 46.55 | F6: 39.999 | G6: 67.889 | H6: 78.431 | I6: 59.899 | J6: =+'Debt Calcs'!J70 -> 35 | K6: =+'Debt Calcs'!K70 -> 35 | L6: =+'Debt Calcs'!L70 -> 35 | M6: =+'Debt Calcs'!M70 -> 35 | N6: =+'Debt Calcs'!N70 -> 35 | O6: =+'Debt Calcs'!O70 -> 35 | P6: =+'Debt Calcs'!P70 -> 35 | Q6: =+'Debt Calcs'!Q70 -> 35 | ... S6: =+'Debt Calcs'!S70 -> 35
B7: Restricted Cash | E7: 0 | F7: 0 | G7: 16.637 | H7: 13.626 | I7: 8.835 | J7: =+I7 -> 8.835 | K7: =+J7 -> 8.835 | L7: =+K7 -> 8.835 | M7: =+L7 -> 8.835 | N7: =+M7 -> 8.835 | O7: =+N7 -> 8.835 | P7: =+O7 -> 8.835 | Q7: =+P7 -> 8.835 | ... S7: =+R7 -> 8.835
B8: Accounts Receivable | E8: 251.538 | F8: 265.71 | G8: 200.217 | H8: 195.24 | I8: 249.66 | J8: =+'FS Calcs'!J15 -> 259.14231 | K8: =+'FS Calcs'!K15 -> 287.17373 | L8: =+'FS Calcs'!L15 -> 321.59761 | M8: =+'FS Calcs'!M15 -> 347.92269 | N8: =+'FS Calcs'!N15 -> 369.90392 | O8: =+'FS Calcs'!O15 -> 389.28437 | P8: =+'FS Calcs'!P15 -> 408.49595 | Q8: =+'FS Calcs'!Q15 -> 428.32292 | ... S8: =+'FS Calcs'!S15 -> 471.26223
B9: Prepaid Expenses and Deposits | E9: 8.58 | F9: 7.182 | G9: 8.779 | H9: 6.184 | I9: 8.583 | J9: =+'FS Calcs'!J18 -> 8.583 | K9: =+'FS Calcs'!K18 -> 8.583 | L9: =+'FS Calcs'!L18 -> 8.583 | M9: =+'FS Calcs'!M18 -> 8.583 | N9: =+'FS Calcs'!N18 -> 8.583 | O9: =+'FS Calcs'!O18 -> 8.583 | P9: =+'FS Calcs'!P18 -> 8.583 | Q9: =+'FS Calcs'!Q18 -> 8.583 | ... S9: =+'FS Calcs'!S18 -> 8.583
B10: Investment in Film and Television Programs | E10: 186.008 | F10: 148.561 | G10: 140.548 | H10: 147.783 | I10: 163.563 | J10: =+'FS Calcs'!J35 -> 184.69614 | K10: =+'FS Calcs'!K35 -> 210.72025 | L10: =+'FS Calcs'!L35 -> 240.37205 | M10: =+'FS Calcs'!M35 -> 268.89098 | N10: =+'FS Calcs'!N35 -> 295.37913 | O10: =+'FS Calcs'!O35 -> 320.56192 | P10: =+'FS Calcs'!P35 -> 344.58462 | Q10: =+'FS Calcs'!Q35 -> 367.40746 | ... S10: =+'FS Calcs'!S35 -> 408.99204
B11: Total Current Assets | E11: =SUM(E6:E10) -> 492.676 | F11: =SUM(F6:F10) -> 461.452 | G11: =SUM(G6:G10) -> 434.07 | H11: =SUM(H6:H10) -> 441.264 | I11: =SUM(I6:I10) -> 490.54 | J11: =SUM(J6:J10) -> 496.25645 | K11: =SUM(K6:K10) -> 550.31198 | L11: =SUM(L6:L10) -> 614.38766 | ... S11: =SUM(S6:S10) -> 932.67227
B13: LT receivables | E13: 18.789 | F13: 14.318 | G13: 21.035 | H13: 51.997 | I13: 84.79 | J13: =+'FS Calcs'!J26 -> 88.0104 | K13: =+'FS Calcs'!K26 -> 97.530484 | L13: =+'FS Calcs'!L26 -> 109.22159 | M13: =+'FS Calcs'!M26 -> 118.16216 | N13: =+'FS Calcs'!N26 -> 125.62747 | O13: =+'FS Calcs'!O26 -> 132.20949 | P13: =+'FS Calcs'!P26 -> 138.73416 | Q13: =+'FS Calcs'!Q26 -> 145.46784 | ... S13: =+'FS Calcs'!S26 -> 160.05097
B14: Acquired and library content | E14: 147.088 | F14: 118.247 | G14: 109.076 | H14: 100.653 | I14: 92.732 | J14: =+'FS Calcs'!J46 -> 93.261756 | K14: =+'FS Calcs'!K46 -> 94.930515 | L14: =+'FS Calcs'!L46 -> 97.998023 | M14: =+'FS Calcs'!M46 -> 102.1352 | N14: =+'FS Calcs'!N46 -> 107.16554 | O14: =+'FS Calcs'!O46 -> 112.98338 | P14: =+'FS Calcs'!P46 -> 119.58183 | Q14: =+'FS Calcs'!Q46 -> 126.98592 | ... S14: =+'FS Calcs'!S46 -> 144.37427
B15: Property, Plant & Equipment | E15: 30.436 | F15: 19.352 | G15: 54.245 | H15: 47.229 | I15: 39.287 | J15: =+'FS Calcs'!J56 -> 31.389683 | K15: =+'FS Calcs'!K56 -> 27.013899 | L15: =+'FS Calcs'!L56 -> 24.563741 | M15: =+'FS Calcs'!M56 -> 24.563741 | N15: =+'FS Calcs'!N56 -> 24.563741 | O15: =+'FS Calcs'!O56 -> 24.563741 | P15: =+'FS Calcs'!P56 -> 24.563741 | Q15: =+'FS Calcs'!Q56 -> 24.563741 | ... S15: =+'FS Calcs'!S56 -> 24.563741
B16: Derivative assets | I16: 8.845 | J16: =+I16 -> 8.845 | K16: =+J16 -> 8.845 | L16: =+K16 -> 8.845 | M16: =+L16 -> 8.845 | N16: =+M16 -> 8.845 | O16: =+N16 -> 8.845 | P16: =+O16 -> 8.845 | Q16: =+P16 -> 8.845 | ... S16: =+R16 -> 8.845
B17: Intangible Assets | E17: 546.997 | F17: 465.832 | G17: 472.531 | H17: 433.595 | I17: 448.947 | J17: =+'FS Calcs'!J67 -> 443.68212 | K17: =+'FS Calcs'!K67 -> 438.68123 | L17: =+'FS Calcs'!L67 -> 434.01426 | M17: =+'FS Calcs'!M67 -> 429.97506 | N17: =+'FS Calcs'!N67 -> 426.75428 | O17: =+'FS Calcs'!O67 -> 424.49459 | P17: =+'FS Calcs'!P67 -> 423.30898 | Q17: =+'FS Calcs'!Q67 -> 423.30898 | ... S17: =+'FS Calcs'!S67 -> 423.30898
B18: Goodwill | E18: 240.806 | F18: 239.754 | G18: 55.344 | H18: 53.164 | I18: 54.033 | J18: =+I18 -> 54.033 | K18: =+J18 -> 54.033 | L18: =+K18 -> 54.033 | M18: =+L18 -> 54.033 | N18: =+M18 -> 54.033 | O18: =+N18 -> 54.033 | P18: =+O18 -> 54.033 | Q18: =+P18 -> 54.033 | ... S18: =+R18 -> 54.033
B19: Total Assets | E19: =+SUM(E13:E18,E11) -> 1476.792 | F19: =+SUM(F13:F18,F11) -> 1318.955 | G19: =+SUM(G13:G18,G11) -> 1146.301 | H19: =+SUM(H13:H18,H11) -> 1127.902 | I19: =+SUM(I13:I18,I11) -> 1219.174 | J19: =+SUM(J13:J18,J11) -> 1215.4784 | K19: =+SUM(K13:K18,K11) -> 1271.3461 | L19: =+SUM(L13:L18,L11) -> 1343.0633 | ... S19: =+SUM(S13:S18,S11) -> 1747.8482
B21: Bank Indebtedness | E21: 16.35 | F21: 0 | G21: 10 | H21: 0 | I21: 9.087 | J21: =+'Debt Calcs'!J7 -> 40.509 | K21: =+'Debt Calcs'!K7 -> 40.509 | L21: =+'Debt Calcs'!L7 -> 40.509 | M21: =+'Debt Calcs'!M7 -> 40.509 | N21: =+'Debt Calcs'!N7 -> 40.509 | O21: =+'Debt Calcs'!O7 -> 40.509 | P21: =+'Debt Calcs'!P7 -> 40.509 | Q21: =+'Debt Calcs'!Q7 -> 40.509 | ... S21: =+'Debt Calcs'!S7 -> 34.270117
B22: Accounts Payable and Accrued Liabilities | E22: 130.545 | F22: 103.487 | G22: 98.927 | H22: 130.299 | I22: 180.956 | J22: =+'FS Calcs'!J20 -> 193.76872 | K22: =+'FS Calcs'!K20 -> 212.21517 | L22: =+'FS Calcs'!L20 -> 238.58739 | M22: =+'FS Calcs'!M20 -> 258.80071 | N22: =+'FS Calcs'!N20 -> 275.70671 | O22: =+'FS Calcs'!O20 -> 290.62928 | P22: =+'FS Calcs'!P20 -> 305.41536 | Q22: =+'FS Calcs'!Q20 -> 320.66078 | ... S22: =+'FS Calcs'!S20 -> 353.44815
B23: Deferred Revenue | E23: 47.552 | F23: 64.299 | G23: 48.371 | H23: 42.004 | I23: 58.116 | J23: =+'FS Calcs'!J23 -> 52.648778 | K23: =+'FS Calcs'!K23 -> 58.343796 | L23: =+'FS Calcs'!L23 -> 65.337542 | M23: =+'FS Calcs'!M23 -> 70.685889 | N23: =+'FS Calcs'!N23 -> 75.151717 | O23: =+'FS Calcs'!O23 -> 79.089156 | P23: =+'FS Calcs'!P23 -> 82.992286 | Q23: =+'FS Calcs'!Q23 -> 87.020443 | ... S23: =+'FS Calcs'!S23 -> 95.74423
B24: Production Financing | E24: 93.683 | F24: 92.448 | G24: 66.688 | H24: 65.403 | I24: 84.235 | J24: =+'Debt Calcs'!J8 -> 85.26871 | K24: =+'Debt Calcs'!K8 -> 90 | L24: =+'Debt Calcs'!L8 -> 90 | M24: =+'Debt Calcs'!M8 -> 90 | N24: =+'Debt Calcs'!N8 -> 90 | O24: =+'Debt Calcs'!O8 -> 90 | P24: =+'Debt Calcs'!P8 -> 90 | Q24: =+'Debt Calcs'!Q8 -> 90 | ... S24: =+'Debt Calcs'!S8 -> 90
B25: Current Portion of Lease Liabilities | E25: 0 | F25: 0 | G25: 9.274 | H25: 9.428 | I25: 10.183 | J25: =+'Debt Calcs'!J9 -> 0 | K25: =+'Debt Calcs'!K9 -> 0 | L25: =+'Debt Calcs'!L9 -> 0 | M25: =+'Debt Calcs'!M9 -> 0 | N25: =+'Debt Calcs'!N9 -> 0 | O25: =+'Debt Calcs'!O9 -> 0 | P25: =+'Debt Calcs'!P9 -> 0 | Q25: =+'Debt Calcs'!Q9 -> 0 | ... S25: =+'Debt Calcs'!S9 -> 0
B26: Current Portion of Long-Term Debt | E26: 10.524 | F26: 11.007 | G26: 0 | H26: 3.532 | I26: 26.335 | J26: =+'Debt Calcs'!J10 -> 0 | K26: =+'Debt Calcs'!K10 -> 0 | L26: =+'Debt Calcs'!L10 -> 0 | M26: =+'Debt Calcs'!M10 -> 0 | N26: =+'Debt Calcs'!N10 -> 0 | O26: =+'Debt Calcs'!O10 -> 0 | P26: =+'Debt Calcs'!P10 -> 0 | Q26: =+'Debt Calcs'!Q10 -> 0 | ... S26: =+'Debt Calcs'!S10 -> 0
B27: Total Current Liabilities | E27: =SUM(E21:E26) -> 298.654 | F27: =SUM(F21:F26) -> 271.241 | G27: =SUM(G21:G26) -> 233.26 | H27: =SUM(H21:H26) -> 250.666 | I27: =SUM(I21:I26) -> 368.912 | J27: =SUM(J21:J26) -> 372.19521 | K27: =SUM(K21:K26) -> 401.06796 | L27: =SUM(L21:L26) -> 434.43393 | ... S27: =SUM(S21:S26) -> 573.46249
B29: Long-Term Debt | E29: 746.046 | F29: 523.061 | G29: 502.006 | H29: 478.862 | I29: 477.804 | J29: =+'Debt Calcs'!J13 -> 477.804 | K29: =+'Debt Calcs'!K13 -> 504.93737 | L29: =+'Debt Calcs'!L13 -> 534.9431 | M29: =+'Debt Calcs'!M13 -> 557.81035 | N29: =+'Debt Calcs'!N13 -> 574.10169 | O29: =+'Debt Calcs'!O13 -> 585.59967 | P29: =+'Debt Calcs'!P13 -> 593.27101 | Q29: =+'Debt Calcs'!Q13 -> 597.12073 | ... S29: =+'Debt Calcs'!S13 -> 597.12077
B30: Long-Term Lease Liabilities | E30: 0 | F30: 0 | G30: 41.552 | H30: 34.407 | I30: 26.056 | J30: =+'Debt Calcs'!J14 -> 36.239 | K30: =+'Debt Calcs'!K14 -> 36.239 | L30: =+'Debt Calcs'!L14 -> 36.239 | M30: =+'Debt Calcs'!M14 -> 36.239 | N30: =+'Debt Calcs'!N14 -> 36.239 | O30: =+'Debt Calcs'!O14 -> 36.239 | P30: =+'Debt Calcs'!P14 -> 36.239 | Q30: =+'Debt Calcs'!Q14 -> 36.239 | ... S30: =+'Debt Calcs'!S14 -> 36.239
B31: Deferred Taxes | E31: 17.679 | F31: 16.406 | G31: 18.261 | H31: 10.328 | I31: 7.761 | J31: =+I31 -> 7.761 | K31: =+J31 -> 7.761 | L31: =+K31 -> 7.761 | M31: =+L31 -> 7.761 | N31: =+M31 -> 7.761 | O31: =+N31 -> 7.761 | P31: =+O31 -> 7.761 | Q31: =+P31 -> 7.761 | ... S31: =+R31 -> 7.761
B32: Other Long-Term Liabilities (incl. derivatives) | E32: 13.621 | F32: 8.269 | G32: 9.736 | H32: 50.726 | I32: 23.238 | J32: =+I32 -> 23.238 | K32: =+J32 -> 23.238 | L32: =+K32 -> 23.238 | M32: =+L32 -> 23.238 | N32: =+M32 -> 23.238 | O32: =+N32 -> 23.238 | P32: =+O32 -> 23.238 | Q32: =+P32 -> 23.238 | ... S32: =+R32 -> 23.238
B33: Total Liabilities | E33: =+SUM(E29:E32,E27) -> 1076 | F33: =+SUM(F29:F32,F27) -> 818.977 | G33: =+SUM(G29:G32,G27) -> 804.815 | H33: =+SUM(H29:H32,H27) -> 824.989 | I33: =+SUM(I29:I32,I27) -> 903.771 | J33: =+SUM(J29:J32,J27) -> 917.23721 | K33: =+SUM(K29:K32,K27) -> 973.24333 | L33: =+SUM(L29:L32,L27) -> 1036.615 | ... S33: =+SUM(S29:S32,S27) -> 1237.8213
B35: Equity to common | E35: 315.078 | F35: 243.033 | G35: 81.351 | H35: 68.588 | I35: 79.428 | J35: =+'FS Calcs'!J78 -> 69.648124 | K35: =+'FS Calcs'!K78 -> 76.770258 | L35: =+'FS Calcs'!L78 -> 92.24445 | M35: =+'FS Calcs'!M78 -> 114.68402 | N35: =+'FS Calcs'!N78 -> 141.59679 | O35: =+'FS Calcs'!O78 -> 172.60778 | P35: =+'FS Calcs'!P78 -> 207.9061 | Q35: =+'FS Calcs'!Q78 -> 247.86599 | ... S35: =+'FS Calcs'!S78 -> 341.0516
B36: NCI | E36: 85.714 | F36: 256.945 | G36: 260.135 | H36: 234.325 | I36: 235.975 | J36: =+'FS Calcs'!J84 -> 228.59308 | K36: =+'FS Calcs'!K84 -> 221.33251 | L36: =+'FS Calcs'!L84 -> 214.20379 | M36: =+'FS Calcs'!M84 -> 207.21787 | N36: =+'FS Calcs'!N84 -> 200.38617 | O36: =+'FS Calcs'!O84 -> 193.72059 | P36: =+'FS Calcs'!P84 -> 187.23354 | Q36: =+'FS Calcs'!Q84 -> 180.93793 | ... S36: =+'FS Calcs'!S84 -> 168.97549
B37: Total Equity | E37: =+E36+E35 -> 400.792 | F37: =+F36+F35 -> 499.978 | G37: =+G36+G35 -> 341.486 | H37: =+H36+H35 -> 302.913 | I37: =+I36+I35 -> 315.403 | J37: =+J36+J35 -> 298.2412 | K37: =+K36+K35 -> 298.10277 | L37: =+L36+L35 -> 306.44824 | ... S37: =+S36+S35 -> 510.02708
B39: Balance | E39: =+E19=E33+E37 -> TRUE | F39: =+F19=F33+F37 -> TRUE | G39: =+G19=G33+G37 -> TRUE | H39: =+H19=H33+H37 -> TRUE | I39: =+I19=I33+I37 -> TRUE | J39: =+J19=J33+J37 -> FALSE | K39: =+K19=K33+K37 -> FALSE | L39: =+L19=L33+L37 -> FALSE | ... S39: =+S19=S33+S37 -> FALSE
B41: NWC (excl. investment in film and TV) | E41: =+SUM(E8:E9,E13)-SUM(E22:E23) -> 100.81 | F41: =+SUM(F8:F9,F13)-SUM(F22:F23) -> 119.424 | G41: =+SUM(G8:G9,G13)-SUM(G22:G23) -> 82.733 | H41: =+SUM(H8:H9,H13)-SUM(H22:H23) -> 81.118 | I41: =+SUM(I8:I9,I13)-SUM(I22:I23) -> 103.961 | J41: =+SUM(J8:J9,J13)-SUM(J22:J23) -> 109.31821 | K41: =+SUM(K8:K9,K13)-SUM(K22:K23) -> 122.72825 | L41: =+SUM(L8:L9,L13)-SUM(L22:L23) -> 135.47727 | ... S41: =+SUM(S8:S9,S13)-SUM(S22:S23) -> 190.70383
B42: NWC (incl. investment in film and TV) | E42: =+E41+E10 -> 286.818 | F42: =+F41+F10 -> 267.985 | G42: =+G41+G10 -> 223.281 | H42: =+H41+H10 -> 228.901 | I42: =+I41+I10 -> 267.524 | J42: =+J41+J10 -> 294.01435 | K42: =+K41+K10 -> 333.4485 | L42: =+L41+L10 -> 375.84932 | ... S42: =+S41+S10 -> 599.69587
B44: Total cash excl restricted cash | E44: =+E6 -> 46.55 | F44: =+F6 -> 39.999 | G44: =+G6 -> 67.889 | H44: =+H6 -> 78.431 | I44: =+I6 -> 59.899 | J44: =+J6 -> 35 | K44: =+K6 -> 35 | L44: =+L6 -> 35 | ... S44: =+S6 -> 35
B45: Total cash incl restricted cash | E45: =+E44+E7 -> 46.55 | F45: =+F44+F7 -> 39.999 | G45: =+G44+G7 -> 84.526 | H45: =+H44+H7 -> 92.057 | I45: =+I44+I7 -> 68.734 | J45: =+J44+J7 -> 43.835 | K45: =+K44+K7 -> 43.835 | L45: =+L44+L7 -> 43.835 | ... S45: =+S44+S7 -> 43.835
B47: Total debt excl lease | E47: =+E21+E26+E29+E24 -> 866.603 | F47: =+F21+F26+F29+F24 -> 626.516 | G47: =+G21+G26+G29+G24 -> 578.694 | H47: =+H21+H26+H29+H24 -> 547.797 | I47: =+I21+I26+I29+I24 -> 597.461 | J47: =+J21+J26+J29+J24 -> 603.58171 | K47: =+K21+K26+K29+K24 -> 635.44637 | L47: =+L21+L26+L29+L24 -> 665.4521 | ... S47: =+S21+S26+S29+S24 -> 721.39088
B48: Total debt incl lease | E48: =+E47+E25+E30 -> 866.603 | F48: =+F47+F25+F30 -> 626.516 | G48: =+G47+G25+G30 -> 629.52 | H48: =+H47+H25+H30 -> 591.632 | I48: =+I47+I25+I30 -> 633.7 | J48: =+J47+J25+J30 -> 639.82071 | K48: =+K47+K25+K30 -> 671.68537 | L48: =+L47+L25+L30 -> 701.6911 | ... S48: =+S47+S25+S30 -> 757.62988
B50: Net debt (excl restricted cash, incl leases) | E50: =+E48-E44 -> 820.053 | F50: =+F48-F44 -> 586.517 | G50: =+G48-G44 -> 561.631 | H50: =+H48-H44 -> 513.201 | I50: =+I48-I44 -> 573.801 | J50: =+J48-J44 -> 604.82071 | K50: =+K48-K44 -> 636.68537 | L50: =+L48-L44 -> 666.6911 | ... S50: =+S48-S44 -> 722.62988
...

Sheet RevBuild Calcs
A1: in CADm unless otherwise stated
A2: FYE June
E4: 2018 | F4: =+E4+1 -> 2019 | G4: =+F4+1 -> 2020 | H4: =+G4+1 -> 2021 | I4: =+H4+1 -> 2022 | J4: =+I4+1 -> 2023 | K4: =+J4+1 -> 2024 | L4: =+K4+1 -> 2025 | M4: =+L4+1 -> 2026 | ... S4: =+R4+1 -> 2032
A6: x | B6: Segmental Revenue
B7: Content production and distribution | E7: 164.374 | F7: 143.763 | G7: 145.225 | H7: 185.084 | I7: 206.572 | J7: =+J29 -> 216.9006 | K7: =+K29 -> 238.59066 | L7: =+L29 -> 262.44973 | M7: =+M29 -> 275.57221 | N7: =+N29 -> 283.83938 | O7: =+O29 -> 292.35456 | P7: =+P29 -> 301.1252 | Q7: =+Q29 -> 310.15895 | ... S7: =+S29 -> 329.04763
B8: WildBrain Spark | E8: 57.282 | F8: 68.996 | G8: 62.278 | H8: 45.754 | I8: 55.41 | J8: =+J36 -> 45.65784 | K8: =+K36 -> 54.081711 | L8: =+L36 -> 69.630204 | M8: =+M36 -> 75.305065 | N8: =+N36 -> 81.054607 | O8: =+O36 -> 86.825695 | P8: =+P36 -> 92.560532 | Q8: =+Q36 -> 98.197468 | ... S8: =+S36 -> 108.38647
B9: Consumer Products | E9: 157.746 | F9: 174.572 | G9: 168.604 | H9: 175.194 | I9: 203.557 | J9: =+J64 -> 223.9127 | K9: =+K64 -> 252.34961 | L9: =+L64 -> 284.41615 | M9: =+M64 -> 320.57745 | N9: =+N64 -> 352.63519 | O9: =+O64 -> 379.08283 | P9: =+P64 -> 404.91379 | Q9: =+Q64 -> 431.7776 | ... S9: =+S64 -> 491.1406
B10: Total content | E10: =SUM(E7:E9) -> 379.402 | F10: =SUM(F7:F9) -> 387.331 | G10: =SUM(G7:G9) -> 376.107 | H10: =SUM(H7:H9) -> 406.032 | I10: =SUM(I7:I9) -> 465.539 | J10: =SUM(J7:J9) -> 486.47114 | K10: =SUM(K7:K9) -> 545.02198 | L10: =SUM(L7:L9) -> 616.49608 | ... S10: =SUM(S7:S9) -> 928.57471
B12: Canadian Television Broadcasting | E12: 55.014 | F12: 52.469 | G12: 49.527 | H12: 46.502 | I12: 41.684 | J12: =+J82 -> 40.01664 | K12: =+K82 -> 38.415974 | L12: =+L82 -> 36.879335 | M12: =+M82 -> 35.404162 | N12: =+N82 -> 33.987996 | O12: =+O82 -> 32.628476 | P12: =+P82 -> 31.323337 | Q12: =+Q82 -> 30.070403 | ... S12: =+S82 -> 28.867587
B14: Total revenue | E14: =+E12+E10 -> 434.416 | F14: =+F12+F10 -> 439.8 | G14: =+G12+G10 -> 425.634 | H14: =+H12+H10 -> 452.534 | I14: =+I12+I10 -> 507.223 | J14: =+J12+J10 -> 526.48778 | K14: =+K12+K10 -> 583.43796 | L14: =+L12+L10 -> 653.37542 | ... S14: =+S12+S10 -> 957.4423
B15: Check | E15: =+E14='P&L'!E6 -> TRUE | F15: =+F14='P&L'!F6 -> TRUE | G15: =+G14='P&L'!G6 -> TRUE | H15: =+H14='P&L'!H6 -> TRUE | I15: =+I14='P&L'!I6 -> TRUE
A17: x | B17: Segmental gross profit
B18: Content | H18: 162.692 | I18: 193.455 | J18: =+J19*J10 -> 194.58846 | K18: =+K19*K10 -> 223.45901 | L18: =+L19*L10 -> 252.76339 | M18: =+M19*M10 -> 275.29644 | N18: =+N19*N10 -> 294.18696 | O18: =+O19*O10 -> 310.88787 | P18: =+P19*P10 -> 327.4258 | Q18: =+Q19*Q10 -> 344.45495 | ... S18: =+S19*S10 -> 380.71563
B19: % margin | H19: =+H18/H10 -> 0.40068763 | I19: =+I18/I10 -> 0.41555058 | J19: 0.4 | K19: 0.41 | L19: 0.41 | M19: 0.41 | N19: 0.41 | O19: 0.41 | P19: 0.41 | Q19: 0.41 | R19: 0.41 | S19: 0.41
B21: Canadian TV business | H21: 32.195 | I21: 28.106 | J21: =+J22*J12 -> 26.010816 | K21: =+K22*K12 -> 24.970383 | L21: =+L22*L12 -> 23.971568 | M21: =+M22*M12 -> 23.012705 | N21: =+N22*N12 -> 22.092197 | O21: =+O22*O12 -> 21.208509 | P21: =+P22*P12 -> 20.360169 | Q21: =+Q22*Q12 -> 19.545762 | ... S21: =+S22*S12 -> 18.763932
B22: % margin | H22: =+H21/H12 -> 0.69233581 | I22: =+I21/I12 -> 0.67426351 | J22: 0.65 | K22: =+J22 -> 0.65 | L22: =+K22 -> 0.65 | M22: =+L22 -> 0.65 | N22: =+M22 -> 0.65 | O22: =+N22 -> 0.65 | P22: =+O22 -> 0.65 | Q22: =+P22 -> 0.65 | R22: =+Q22 -> 0.65 | S22: =+R22 -> 0.65
B24: Adjustments | H24: =+'P&L'!H9 -> 4.372
B26: Total gross profit | H26: =+H21+H18+H24 -> 199.259 | I26: =+I21+I18+I24 -> 221.561 | J26: =+J21+J18+J24 -> 220.59927 | K26: =+K21+K18+K24 -> 248.4294 | L26: =+L21+L18+L24 -> 276.73496 | M26: =+M21+M18+M24 -> 298.30914 | N26: =+N21+N18+N24 -> 316.27916 | O26: =+O21+O18+O24 -> 332.09637 | ... S26: =+S21+S18+S24 -> 399.47956
H27: =+ROUND(H26-'P&L'!H13, 1)=0 -> TRUE | I27: =+I26='P&L'!I13 -> TRUE
A28: x | B28: Content production and distribution
B29: Revenue | E29: =+E7 -> 164.374 | F29: =+F7 -> 143.763 | G29: =+G7 -> 145.225 | H29: =+H7 -> 185.084 | I29: =+I7 -> 206.572 | J29: =+(1+J30)*I29 -> 216.9006 | K29: =+(1+K30)*J29 -> 238.59066 | L29: =+(1+L30)*K29 -> 262.44973 | M29: =+(1+M30)*L29 -> 275.57221 | N29: =+(1+N30)*M29 -> 283.83938 | O29: =+(1+O30)*N29 -> 292.35456 | P29: =+(1+P30)*O29 -> 301.1252 | Q29: =+(1+Q30)*P29 -> 310.15895 | ... S29: =+(1+S30)*R29 -> 329.04763
B30: % YoY | F30: =+F29/E29-1 -> -0.12539088 | G30: =+G29/F29-1 -> 0.010169515 | H30: =+H29/G29-1 -> 0.27446376 | I30: =+I29/H29-1 -> 0.11609864 | J30: =+CHOOSE(Case, J31,J32,J33) -> 0.05 | K30: =+CHOOSE(Case, K31,K32,K33) -> 0.1 | L30: =+CHOOSE(Case, L31,L32,L33) -> 0.1 | M30: =+CHOOSE(Case, M31,M32,M33) -> 0.05 | N30: =+CHOOSE(Case, N31,N32,N33) -> 0.03 | O30: =+CHOOSE(Case, O31,O32,O33) -> 0.03 | P30: =+CHOOSE(Case, P31,P32,P33) -> 0.03 | Q30: =+CHOOSE(Case, Q31,Q32,Q33) -> 0.03 | ... S30: =+CHOOSE(Case, S31,S32,S33) -> 0.03
B31: Base | J31: 0.05 | K31: 0.1 | L31: 0.1 | M31: 0.05 | N31: 0.03 | O31: 0.03 | P31: 0.03 | Q31: 0.03 | R31: 0.03 | S31: 0.03
B32: Upside | J32: 0.05 | K32: 0.15 | L32: 0.1 | M32: 0.05 | N32: 0.05 | O32: 0.05 | P32: 0.05 | Q32: 0.05 | R32: 0.05 | S32: 0.05
B33: Downside | J33: 0.05 | K33: 0.05 | L33: 0.05 | M33: 0.05 | N33: 0.05 | O33: 0.05 | P33: 0.05 | Q33: 0.05 | R33: 0.05 | S33: 0.05
A35: x | B35: Wildbrain Spark
B36: Revenue | E36: =+E8 -> 57.282 | F36: =+F8 -> 68.996 | G36: =+G8 -> 62.278 | H36: =+H8 -> 45.754 | I36: =+I8 -> 55.41 | J36: =+J39*J45 -> 45.65784 | K36: =+K39*K45 -> 54.081711 | L36: =+L39*L45 -> 69.630204 | M36: =+M39*M45 -> 75.305065 | N36: =+N39*N45 -> 81.054607 | O36: =+O39*O45 -> 86.825695 | P36: =+P39*P45 -> 92.560532 | Q36: =+Q39*Q45 -> 98.197468 | ... S36: =+S39*S45 -> 108.38647
B37: % YoY | F37: =+F36/E36-1 -> 0.20449705 | G37: =+G36/F36-1 -> -0.097367963 | H37: =+H36/G36-1 -> -0.26532644 | I37: =+I36/H36-1 -> 0.21104166 | J37: =+J36/I36-1 -> -0.176 | K37: =+K36/J36-1 -> 0.1845 | L37: =+L36/K36-1 -> 0.2875 | M37: =+M36/L36-1 -> 0.0815 | ... S37: =+S36/R36-1 -> 0.0506
B39: Views (billions) | E39: 25 | F39: =7.2+7+8.7+9.3 -> 32.2 | G39: =12+9.9+10.3+11.6 -> 43.8 | H39: 35 | I39: 32.9 | J39: =+(1+J40)*I39 -> 33.887 | K39: =+(1+K40)*J39 -> 34.90361 | L39: =+(1+L40)*K39 -> 35.950718 | M39: =+(1+M40)*L39 -> 37.02924 | N39: =+(1+N40)*M39 -> 38.140117 | O39: =+(1+O40)*N39 -> 39.284321 | P39: =+(1+P40)*O39 -> 40.46285 | Q39: =+(1+Q40)*P39 -> 41.676736 | ... S39: =+(1+S40)*R39 -> 44.214849
B40: % YoY | F40: =+F39/E39-1 -> 0.288 | G40: =+G39/F39-1 -> 0.36024845 | H40: =+H39/G39-1 -> -0.20091324 | I40: =+I39/H39-1 -> -0.06 | J40: =+CHOOSE(Case, J41,J42,J43) -> 0.03 | K40: =+CHOOSE(Case, K41,K42,K43) -> 0.03 | L40: =+CHOOSE(Case, L41,L42,L43) -> 0.03 | M40: =+CHOOSE(Case, M41,M42,M43) -> 0.03 | N40: =+CHOOSE(Case, N41,N42,N43) -> 0.03 | O40: =+CHOOSE(Case, O41,O42,O43) -> 0.03 | P40: =+CHOOSE(Case, P41,P42,P43) -> 0.03 | Q40: =+CHOOSE(Case, Q41,Q42,Q43) -> 0.03 | ... S40: =+CHOOSE(Case, S41,S42,S43) -> 0.03
B41: Base | J41: 0.03 | K41: 0.03 | L41: 0.03 | M41: 0.03 | N41: 0.03 | O41: 0.03 | P41: 0.03 | Q41: 0.03 | R41: 0.03 | S41: 0.03
B42: Upside | J42: 0.05 | K42: 0.05 | L42: 0.05 | M42: 0.05 | N42: 0.05 | O42: 0.05 | P42: 0.05 | Q42: 0.05 | R42: 0.05 | S42: 0.05
B43: Downside | J43: 0 | K43: 0.03 | L43: 0.03 | M43: 0.03 | N43: 0.03 | O43: 0.03 | P43: 0.03 | Q43: 0.03 | R43: 0.03 | S43: 0.03
B45: CPM (CAD) | E45: =+E36/E39 -> 2.29128 | F45: =+F36/F39 -> 2.1427329 | G45: =+G36/G39 -> 1.4218721 | H45: =+H36/H39 -> 1.3072571 | I45: =+I36/I39 -> 1.6841945 | J45: =+(1+J46)*I45 -> 1.3473556 | K45: =+(1+K46)*J45 -> 1.549459 | L45: =+(1+L46)*K45 -> 1.9368237 | M45: =+(1+M46)*L45 -> 2.0336649 | N45: =+(1+N46)*M45 -> 2.1251798 | O45: =+(1+O46)*N45 -> 2.210187 | P45: =+(1+P46)*O45 -> 2.2875436 | Q45: =+(1+Q46)*P45 -> 2.3561699 | ... S45: =+(1+S46)*R45 -> 2.4513591
B46: % YoY | F46: =+F45/E45-1 -> -0.064831483 | G46: =+G45/F45-1 -> -0.3364212 | H46: =+H45/G45-1 -> -0.080608516 | I46: =+I45/H45-1 -> 0.28834219 | J46: =+CHOOSE(Case, J47,J48,J49) -> -0.2 | K46: =+CHOOSE(Case, K47,K48,K49) -> 0.15 | L46: =+CHOOSE(Case, L47,L48,L49) -> 0.25 | M46: =+CHOOSE(Case, M47,M48,M49) -> 0.05 | N46: =+CHOOSE(Case, N47,N48,N49) -> 0.045 | O46: =+CHOOSE(Case, O47,O48,O49) -> 0.04 | P46: =+CHOOSE(Case, P47,P48,P49) -> 0.035 | Q46: =+CHOOSE(Case, Q47,Q48,Q49) -> 0.03 | ... S46: =+CHOOSE(Case, S47,S48,S49) -> 0.02
B47: Base | J47: -0.2 | K47: 0.15 | L47: 0.25 | M47: 0.05 | N47: 0.045 | O47: 0.04 | P47: 0.035 | Q47: 0.03 | R47: 0.02 | S47: 0.02
B48: Upside | J48: -0.2 | K48: 0.2 | L48: 0.3 | M48: 0.1 | N48: 0.05 | O48: 0.045 | P48: 0.04 | Q48: 0.03 | R48: 0.02 | S48: 0.02
B49: Downside | J49: -0.3 | K49: 0.1 | L49: 0.1 | M49: 0.05 | N49: 0.045 | O49: 0.04 | P49: 0.035 | Q49: 0.03 | R49: 0.02 | S49: 0.02
B51: Memo (based on Morgan Stanley analyst on Google)
B52: Youtube mobile CPM (USD) | E52: 1.3600422 | F52: 1.3511736 | G52: 1.4737851 | H52: 1.6806006 | I52: 1.4820115 | J52: 1.4822099 | K52: 1.5684875 | L52: 1.6575047 | M52: 1.7374636 | N52: 1.8087073 | O52: 1.8717475 | P52: 1.9271994 | Q52: 1.9757298 | R52: 1.9757298 | S52: 1.9757298
...

Sheet FS Calcs
A1: in CADm unless otherwise stated
A2: FYE June
E4: 2018 | F4: =+E4+1 -> 2019 | G4: =+F4+1 -> 2020 | H4: =+G4+1 -> 2021 | I4: =+H4+1 -> 2022 | J4: =+I4+1 -> 2023 | K4: =+J4+1 -> 2024 | L4: =+K4+1 -> 2025 | M4: =+L4+1 -> 2026 | ... S4: =+R4+1 -> 2032
B6: Content production and distribution | E6: =+'RevBuild Calcs'!E7 -> 164.374 | F6: =+'RevBuild Calcs'!F7 -> 143.763 | G6: =+'RevBuild Calcs'!G7 -> 145.225 | H6: =+'RevBuild Calcs'!H7 -> 185.084 | I6: =+'RevBuild Calcs'!I7 -> 206.572 | J6: =+'RevBuild Calcs'!J7 -> 216.9006 | K6: =+'RevBuild Calcs'!K7 -> 238.59066 | L6: =+'RevBuild Calcs'!L7 -> 262.44973 | ... S6: =+'RevBuild Calcs'!S7 -> 329.04763
B7: WildBrain Spark | E7: =+'RevBuild Calcs'!E8 -> 57.282 | F7: =+'RevBuild Calcs'!F8 -> 68.996 | G7: =+'RevBuild Calcs'!G8 -> 62.278 | H7: =+'RevBuild Calcs'!H8 -> 45.754 | I7: =+'RevBuild Calcs'!I8 -> 55.41 | J7: =+'RevBuild Calcs'!J8 -> 45.65784 | K7: =+'RevBuild Calcs'!K8 -> 54.081711 | L7: =+'RevBuild Calcs'!L8 -> 69.630204 | ... S7: =+'RevBuild Calcs'!S8 -> 108.38647
B8: Consumer Products | E8: =+'RevBuild Calcs'!E9 -> 157.746 | F8: =+'RevBuild Calcs'!F9 -> 174.572 | G8: =+'RevBuild Calcs'!G9 -> 168.604 | H8: =+'RevBuild Calcs'!H9 -> 175.194 | I8: =+'RevBuild Calcs'!I9 -> 203.557 | J8: =+'RevBuild Calcs'!J9 -> 223.9127 | K8: =+'RevBuild Calcs'!K9 -> 252.34961 | L8: =+'RevBuild Calcs'!L9 -> 284.41615 | ... S8: =+'RevBuild Calcs'!S9 -> 491.1406
B9: Canadian Television Broadcasting | E9: =+'RevBuild Calcs'!E12 -> 55.014 | F9: =+'RevBuild Calcs'!F12 -> 52.469 | G9: =+'RevBuild Calcs'!G12 -> 49.527 | H9: =+'RevBuild Calcs'!H12 -> 46.502 | I9: =+'RevBuild Calcs'!I12 -> 41.684 | J9: =+'RevBuild Calcs'!J12 -> 40.01664 | K9: =+'RevBuild Calcs'!K12 -> 38.415974 | L9: =+'RevBuild Calcs'!L12 -> 36.879335 | ... S9: =+'RevBuild Calcs'!S12 -> 28.867587
B10: Revenue | E10: =SUM(E6:E9) -> 434.416 | F10: =SUM(F6:F9) -> 439.8 | G10: =SUM(G6:G9) -> 425.634 | H10: =SUM(H6:H9) -> 452.534 | I10: =SUM(I6:I9) -> 507.223 | J10: =SUM(J6:J9) -> 526.48778 | K10: =SUM(K6:K9) -> 583.43796 | L10: =SUM(L6:L9) -> 653.37542 | ... S10: =SUM(S6:S9) -> 957.4423
B11: COGS | E11: =+'P&L'!E11 -> -244.244 | F11: =+'P&L'!F11 -> -253.003 | G11: =+'P&L'!G11 -> -237.789 | H11: =+'P&L'!H11 -> -257.647 | I11: =+'P&L'!I11 -> -285.662 | J11: =+'P&L'!J11 -> -305.88851 | K11: =+'P&L'!K11 -> -335.00856 | L11: =+'P&L'!L11 -> -376.64045 | ... S11: =+'P&L'!S11 -> -557.96273
B12: EBT | E12: =+'P&L'!E27 -> -5.257 | F12: =+'P&L'!F27 -> -81.908 | G12: =+'P&L'!G27 -> -207.085 | H12: =+'P&L'!H27 -> 19.811 | I12: =+'P&L'!I27 -> 30.205 | J12: =+'P&L'!J27 -> 24.111805 | K12: =+'P&L'!K27 -> 49.054041 | L12: =+'P&L'!L27 -> 61.988189 | ... S12: =+'P&L'!S27 -> 118.54845
A14: x | B14: WC items
B15: Account receivables | E15: =+'BS & CFS'!E8 -> 251.538 | F15: =+'BS & CFS'!F8 -> 265.71 | G15: =+'BS & CFS'!G8 -> 200.217 | H15: =+'BS & CFS'!H8 -> 195.24 | I15: =+'BS & CFS'!I8 -> 249.66 | J15: =+J16/365*J10 -> 259.14231 | K15: =+K16/365*K10 -> 287.17373 | L15: =+L16/365*L10 -> 321.59761 | M15: =+M16/365*M10 -> 347.92269 | N15: =+N16/365*N10 -> 369.90392 | O15: =+O16/365*O10 -> 389.28437 | P15: =+P16/365*P10 -> 408.49595 | Q15: =+Q16/365*Q10 -> 428.32292 | ... S15: =+S16/365*S10 -> 471.26223
B16: AR days | E16: =+E15/E10*365 -> 211.34436 | F16: =+F15/F10*365 -> 220.51876 | G16: =+G15/G10*365 -> 171.69494 | H16: =+H15/H10*365 -> 157.47458 | I16: =+I15/I10*365 -> 179.65648 | J16: =+I16 -> 179.65648 | K16: =+J16 -> 179.65648 | L16: =+K16 -> 179.65648 | M16: =+L16 -> 179.65648 | N16: =+M16 -> 179.65648 | O16: =+N16 -> 179.65648 | P16: =+O16 -> 179.65648 | Q16: =+P16 -> 179.65648 | ... S16: =+R16 -> 179.65648
B18: Prepaid expense and deposits | E18: =+'BS & CFS'!E9 -> 8.58 | F18: =+'BS & CFS'!F9 -> 7.182 | G18: =+'BS & CFS'!G9 -> 8.779 | H18: =+'BS & CFS'!H9 -> 6.184 | I18: =+'BS & CFS'!I9 -> 8.583 | J18: =+I18 -> 8.583 | K18: =+J18 -> 8.583 | L18: =+K18 -> 8.583 | M18: =+L18 -> 8.583 | N18: =+M18 -> 8.583 | O18: =+N18 -> 8.583 | P18: =+O18 -> 8.583 | Q18: =+P18 -> 8.583 | ... S18: =+R18 -> 8.583
B20: Accounts payables and accrued liabilities | E20: =+'BS & CFS'!E22 -> 130.545 | F20: =+'BS & CFS'!F22 -> 103.487 | G20: =+'BS & CFS'!G22 -> 98.927 | H20: =+'BS & CFS'!H22 -> 130.299 | I20: =+'BS & CFS'!I22 -> 180.956 | J20: =+J21/365*J11*-1 -> 193.76872 | K20: =+K21/365*K11*-1 -> 212.21517 | L20: =+L21/365*L11*-1 -> 238.58739 | M20: =+M21/365*M11*-1 -> 258.80071 | N20: =+N21/365*N11*-1 -> 275.70671 | O20: =+O21/365*O11*-1 -> 290.62928 | P20: =+P21/365*P11*-1 -> 305.41536 | Q20: =+Q21/365*Q11*-1 -> 320.66078 | ... S20: =+S21/365*S11*-1 -> 353.44815
B21: AP days | E21: =+E20/E11*365*-1 -> 195.08739 | F21: =+F20/F11*365*-1 -> 149.29766 | G21: =+G20/G11*365*-1 -> 151.8504 | H21: =+H20/H11*365*-1 -> 184.59029 | I21: =+I20/I11*365*-1 -> 231.2136 | J21: =+I21 -> 231.2136 | K21: =+J21 -> 231.2136 | L21: =+K21 -> 231.2136 | M21: =+L21 -> 231.2136 | N21: =+M21 -> 231.2136 | O21: =+N21 -> 231.2136 | P21: =+O21 -> 231.2136 | Q21: =+P21 -> 231.2136 | ... S21: =+R21 -> 231.2136
B23: Deferred revenue | E23: =+'BS & CFS'!E23 -> 47.552 | F23: =+'BS & CFS'!F23 -> 64.299 | G23: =+'BS & CFS'!G23 -> 48.371 | H23: =+'BS & CFS'!H23 -> 42.004 | I23: =+'BS & CFS'!I23 -> 58.116 | J23: =+J24*J10 -> 52.648778 | K23: =+K24*K10 -> 58.343796 | L23: =+L24*L10 -> 65.337542 | M23: =+M24*M10 -> 70.685889 | N23: =+N24*N10 -> 75.151717 | O23: =+O24*O10 -> 79.089156 | P23: =+P24*P10 -> 82.992286 | Q23: =+Q24*Q10 -> 87.020443 | ... S23: =+S24*S10 -> 95.74423
B24: % of total revenue | E24: =+E23/E10 -> 0.1094619 | F24: =+F23/F10 -> 0.14620055 | G24: =+G23/G10 -> 0.11364459 | H24: =+H23/H10 -> 0.092819545 | I24: =+I23/I10 -> 0.11457682 | J24: 0.1 | K24: 0.1 | L24: 0.1 | M24: 0.1 | N24: 0.1 | O24: 0.1 | P24: 0.1 | Q24: 0.1 | R24: 0.1 | S24: 0.1
B26: LT acccount receivables | E26: =+'BS & CFS'!E13 -> 18.789 | F26: =+'BS & CFS'!F13 -> 14.318 | G26: =+'BS & CFS'!G13 -> 21.035 | H26: =+'BS & CFS'!H13 -> 51.997 | I26: =+'BS & CFS'!I13 -> 84.79 | J26: =+J27/365*J10 -> 88.0104 | K26: =+K27/365*K10 -> 97.530484 | L26: =+L27/365*L10 -> 109.22159 | M26: =+M27/365*M10 -> 118.16216 | N26: =+N27/365*N10 -> 125.62747 | O26: =+O27/365*O10 -> 132.20949 | P26: =+P27/365*P10 -> 138.73416 | Q26: =+Q27/365*Q10 -> 145.46784 | ... S26: =+S27/365*S10 -> 160.05097
B27: AR days | E27: =+E26/E10*365 -> 15.786677 | F27: =+F26/F10*365 -> 11.882833 | G27: =+G26/G10*365 -> 18.038444 | H27: =+H26/H10*365 -> 41.93918 | I27: =+I26/I10*365 -> 61.015273 | J27: =+I27 -> 61.015273 | K27: =+J27 -> 61.015273 | L27: =+K27 -> 61.015273 | M27: =+L27 -> 61.015273 | N27: =+M27 -> 61.015273 | O27: =+N27 -> 61.015273 | P27: =+O27 -> 61.015273 | Q27: =+P27 -> 61.015273 | ... S27: =+R27 -> 61.015273
A29: x | B29: ST assets
B30: BoP investment in film and TV | F30: =+E35 -> 186.008 | G30: =+F35 -> 148.561 | H30: =+G35 -> 140.548 | I30: =+H35 -> 147.783 | J30: =+I35 -> 163.563 | K30: =+J35 -> 184.69614 | L30: =+K35 -> 210.72025 | M30: =+L35 -> 240.37205 | ... S30: =+R35 -> 388.96553
B31: Development cost | H31: =1.908+73.165+4.434 -> 79.507 | I31: =0.203+71.115+12.166 -> 83.484 | J31: =+J37*J6 -> 97.60527 | K31: =+K37*K6 -> 101.40103 | L31: =+L37*L6 -> 104.97989 | M31: =+M37*M6 -> 110.22888 | N31: =+N37*N6 -> 113.53575 | O31: =+O37*O6 -> 116.94182 | P31: =+P37*P6 -> 120.45008 | Q31: =+Q37*Q6 -> 124.06358 | ... S31: =+S37*S6 -> 131.61905
B32: Write down | H32: -7.453 | I32: -1.208 | J32: 0 | K32: =+J32 -> 0 | L32: =+K32 -> 0 | M32: =+L32 -> 0 | N32: =+M32 -> 0 | O32: =+N32 -> 0 | P32: =+O32 -> 0 | Q32: =+P32 -> 0 | R32: =+Q32 -> 0 | S32: =+R32 -> 0
B33: Expense | H33: =+'RevBuild Calcs'!H90*-1 -> -65.768 | I33: =+'RevBuild Calcs'!I90*-1 -> -59.287 | J33: =+J38*J11 -> -76.472127 | K33: =+K38*K11 -> -75.376926 | L33: =+L38*L11 -> -75.328091 | M33: =+M38*M11 -> -81.709949 | N33: =+N38*N11 -> -87.047603 | O33: =+O38*O11 -> -91.759037 | P33: =+P38*P11 -> -96.427377 | Q33: =+Q38*Q11 -> -101.24074 | ... S33: =+S38*S11 -> -111.59255
B34: FX & Other | H34: =+H35-SUM(H30:H33) -> 0.949 | I34: =+I35-SUM(I30:I33) -> -7.209 | J34: 0 | K34: =+J34 -> 0 | L34: =+K34 -> 0 | M34: =+L34 -> 0 | N34: =+M34 -> 0 | O34: =+N34 -> 0 | P34: =+O34 -> 0 | Q34: =+P34 -> 0 | R34: =+Q34 -> 0 | S34: =+R34 -> 0
B35: EoP investment in film and TV | E35: =+'BS & CFS'!E10 -> 186.008 | F35: =+'BS & CFS'!F10 -> 148.561 | G35: =+'BS & CFS'!G10 -> 140.548 | H35: =+'BS & CFS'!H10 -> 147.783 | I35: =+'BS & CFS'!I10 -> 163.563 | J35: =+SUM(J30:J34) -> 184.69614 | K35: =+SUM(K30:K34) -> 210.72025 | L35: =+SUM(L30:L34) -> 240.37205 | M35: =+SUM(M30:M34) -> 268.89098 | N35: =+SUM(N30:N34) -> 295.37913 | O35: =+SUM(O30:O34) -> 320.56192 | P35: =+SUM(P30:P34) -> 344.58462 | Q35: =+SUM(Q30:Q34) -> 367.40746 | ... S35: =+SUM(S30:S34) -> 408.99204
B37: Development cost as a % of content revenue | H37: =+H31/H6 -> 0.42957252 | I37: =+I31/I6 -> 0.40413996 | J37: 0.45 | K37: 0.425 | L37: 0.4 | M37: 0.4 | N37: 0.4 | O37: 0.4 | P37: 0.4 | Q37: 0.4 | R37: 0.4 | S37: 0.4
B38: Expense as a % of COGS | H38: =+H33/H11 -> 0.25526399 | I38: =+I33/I11 -> 0.20754248 | J38: 0.25 | K38: 0.225 | L38: 0.2 | M38: 0.2 | N38: 0.2 | O38: 0.2 | P38: 0.2 | Q38: 0.2 | R38: 0.2 | S38: 0.2
A40: x | B40: LT assets | J40: =+J39*J6 -> 0 | K40: =+K39*K6 -> 0 | L40: =+L39*L6 -> 0 | M40: =+M39*M6 -> 0 | N40: =+N39*N6 -> 0 | O40: =+O39*O6 -> 0 | P40: =+P39*P6 -> 0 | Q40: =+Q39*Q6 -> 0 | ... S40: =+S39*S6 -> 0
B41: BoP acquired and library content | F41: =+E46 -> 147.088 | G41: =+F46 -> 118.247 | H41: =+G46 -> 109.076 | I41: =+H46 -> 100.653 | J41: =+I46 -> 92.732 | K41: =+J46 -> 93.261756 | L41: =+K46 -> 94.930515 | M41: =+L46 -> 97.998023 | ... S41: =+R46 -> 135.22542
B42: Additions | H42: 8.918 | I42: 1 | J42: =+J48*J10 -> 10.529756 | K42: =+K48*K10 -> 11.668759 | L42: =+L48*L10 -> 13.067508 | M42: =+M48*M10 -> 14.137178 | N42: =+N48*N10 -> 15.030343 | O42: =+O48*O10 -> 15.817831 | P42: =+P48*P10 -> 16.598457 | Q42: =+Q48*Q10 -> 17.404089 | ... S42: =+S48*S10 -> 19.148846
B43: Write down | H43: -0.379 | I43: 0 | J43: 0 | K43: =+J43 -> 0 | L43: =+K43 -> 0 | M43: =+L43 -> 0 | N43: =+M43 -> 0 | O43: =+N43 -> 0 | P43: =+O43 -> 0 | Q43: =+P43 -> 0 | R43: =+Q43 -> 0 | S43: =+R43 -> 0
B44: Amortization | H44: -11.1 | I44: -10.241 | J44: =+J49 -> -10 | K44: =+K49 -> -10 | L44: =+L49 -> -10 | M44: =+M49 -> -10 | N44: =+N49 -> -10 | O44: =+O49 -> -10 | P44: =+P49 -> -10 | Q44: =+Q49 -> -10 | ... S44: =+S49 -> -10
B45: FX & Other | H45: =+H46-SUM(H41:H44) -> -5.862 | I45: =+I46-SUM(I41:I44) -> 1.32 | J45: 0 | K45: =+J45 -> 0 | L45: =+K45 -> 0 | M45: =+L45 -> 0 | N45: =+M45 -> 0 | O45: =+N45 -> 0 | P45: =+O45 -> 0 | Q45: =+P45 -> 0 | R45: =+Q45 -> 0 | S45: =+R45 -> 0
B46: EoP acquired and library content | E46: =+'BS & CFS'!E14 -> 147.088 | F46: =+'BS & CFS'!F14 -> 118.247 | G46: =+'BS & CFS'!G14 -> 109.076 | H46: =+'BS & CFS'!H14 -> 100.653 | I46: =+'BS & CFS'!I14 -> 92.732 | J46: =+SUM(J41:J45) -> 93.261756 | K46: =+SUM(K41:K45) -> 94.930515 | L46: =+SUM(L41:L45) -> 97.998023 | M46: =+SUM(M41:M45) -> 102.1352 | N46: =+SUM(N41:N45) -> 107.16554 | O46: =+SUM(O41:O45) -> 112.98338 | P46: =+SUM(P41:P45) -> 119.58183 | Q46: =+SUM(Q41:Q45) -> 126.98592 | ... S46: =+SUM(S41:S45) -> 144.37427
B48: Additions as a % of revenue | H48: =+H42/H10 -> 0.019706807 | I48: =+I42/I10 -> 0.0019715194 | J48: 0.02 | K48: 0.02 | L48: 0.02 | M48: 0.02 | N48: 0.02 | O48: 0.02 | P48: 0.02 | Q48: 0.02 | R48: 0.02 | S48: 0.02
B49: Amortization | H49: =+H44 -> -11.1 | I49: =+I44 -> -10.241 | J49: -10 | K49: -10 | L49: -10 | M49: -10 | N49: -10 | O49: -10 | P49: -10 | Q49: -10 | R49: -10 | S49: -10
B51: BoP PPE | F51: =+E56 -> 30.436 | G51: =+F56 -> 19.352 | H51: =+G56 -> 54.245 | I51: =+H56 -> 47.229 | J51: =+I56 -> 39.287 | K51: =+J56 -> 31.389683 | L51: =+K56 -> 27.013899 | M51: =+L56 -> 24.563741 | ... S51: =+R56 -> 24.563741
B52: Additions | H52: 5.733 | I52: 5.308 | J52: =+J59*J10 -> 7.8973167 | K52: =+K59*K10 -> 8.7515694 | L52: =+L59*L10 -> 9.8006312 | M52: =+M59*M10 -> 10.602883 | N52: =+N59*N10 -> 11.272758 | O52: =+O59*O10 -> 11.863373 | P52: =+P59*P10 -> 12.448843 | Q52: =+Q59*Q10 -> 13.053066 | ... S52: =+S59*S10 -> 14.361634
...

Sheet Debt Calcs
A1: in CADm unless otherwise stated
A2: FYE June
E4: 2018 | F4: =+E4+1 -> 2019 | G4: =+F4+1 -> 2020 | H4: =+G4+1 -> 2021 | I4: =+H4+1 -> 2022 | J4: =+I4+1 -> 2023 | K4: =+J4+1 -> 2024 | L4: =+K4+1 -> 2025 | M4: =+L4+1 -> 2026 | ... S4: =+R4+1 -> 2032
A6: x | B6: Current debt
B7: Bank indebtedness | E7: =+'BS & CFS'!E21 -> 16.35 | F7: =+'BS & CFS'!F21 -> 0 | G7: =+'BS & CFS'!G21 -> 10 | H7: =+'BS & CFS'!H21 -> 0 | I7: =+'BS & CFS'!I21 -> 9.087 | J7: =+J40 -> 40.509 | K7: =+K40 -> 40.509 | L7: =+L40 -> 40.509 | M7: =+M40 -> 40.509 | N7: =+N40 -> 40.509 | O7: =+O40 -> 40.509 | P7: =+P40 -> 40.509 | Q7: =+Q40 -> 40.509 | ... S7: =+S40 -> 34.270071
B8: Production Financing | E8: =+'BS & CFS'!E24 -> 93.683 | F8: =+'BS & CFS'!F24 -> 92.448 | G8: =+'BS & CFS'!G24 -> 66.688 | H8: =+'BS & CFS'!H24 -> 65.403 | I8: =+'BS & CFS'!I24 -> 84.235 | J8: =+J46 -> 85.26871 | K8: =+K46 -> 90 | L8: =+L46 -> 90 | M8: =+M46 -> 90 | N8: =+N46 -> 90 | O8: =+O46 -> 90 | P8: =+P46 -> 90 | Q8: =+Q46 -> 90 | ... S8: =+S46 -> 90
B9: Current Portion of Lease Liabilities | E9: =+'BS & CFS'!E25 -> 0 | F9: =+'BS & CFS'!F25 -> 0 | G9: =+'BS & CFS'!G25 -> 9.274 | H9: =+'BS & CFS'!H25 -> 9.428 | I9: =+'BS & CFS'!I25 -> 10.183 | J9: 0 | K9: 0 | L9: 0 | M9: 0 | N9: 0 | O9: 0 | P9: 0 | Q9: 0 | R9: 0 | S9: 0
B10: Current Portion of Long-Term Debt | E10: =+'BS & CFS'!E26 -> 10.524 | F10: =+'BS & CFS'!F26 -> 11.007 | G10: =+'BS & CFS'!G26 -> 0 | H10: =+'BS & CFS'!H26 -> 3.532 | I10: =+'BS & CFS'!I26 -> 26.335 | J10: =+J52 -> 0 | K10: =+K52 -> 0 | L10: =+L52 -> 0 | M10: =+M52 -> 0 | N10: =+N52 -> 0 | O10: =+O52 -> 0 | P10: =+P52 -> 0 | Q10: =+Q52 -> 0 | ... S10: =+S52 -> 0
A12: x | B12: LT debt
