Workbook
Name A_ALL_GOOGL: #REF!
Name A_ALL_KEYWORDS_TYPE_ScalarContributed_EQTY_200007003: #REF!,#REF!,#REF!,#REF!,#REF!
Name A_ALL_KEYWORDS_TYPE_Vector_ISSR_208002492: #REF!,#REF!,#REF!,#REF!,#REF!,#REF!,#REF!,#REF!,#REF!,#REF!,#REF!,#REF!,#REF!
Name A_ALL_SECTION_KEYWORDS_EQTY_200007003_13A: #REF!
Name A_ALL_SECTION_KEYWORDS_ISSR_208002492_131O: #REF!,#REF!
Name E_ALL_GOOGL: #REF!
Name E_ALL_KEYWORDS_TYPE_ScalarContributed_EQTY_200007003: #REF!,#REF!,#REF!,#REF!,#REF!
Name E_ALL_KEYWORDS_TYPE_Vector_ISSR_208002492: #REF!,#REF!,#REF!,#REF!,#REF!,#REF!,#REF!,#REF!,#REF!,#REF!,#REF!,#REF!,#REF!
Name E_ALL_SECTION_KEYWORDS_EQTY_200007003_13A: #REF!
Name E_ALL_SECTION_KEYWORDS_ISSR_208002492_131O: #REF!,#REF!
Name L_ALL_GOOGL: #REF!
Name L_ALL_KEYWORDS_TYPE_ScalarContributed_EQTY_200007003: #REF!,#REF!,#REF!,#REF!,#REF!
Name L_ALL_KEYWORDS_TYPE_Vector_ISSR_208002492: #REF!,#REF!,#REF!,#REF!,#REF!,#REF!,#REF!,#REF!,#REF!,#REF!,#REF!,#REF!,#REF!
Name L_ALL_SECTION_KEYWORDS_EQTY_200007003_13A: #REF!
Name L_ALL_SECTION_KEYWORDS_ISSR_208002492_131O: #REF!,#REF!
Name V_ALL_GOOGL: #REF!
Name V_ALL_KEYWORDS_TYPE_ScalarContributed_EQTY_200007003: #REF!,#REF!,#REF!,#REF!,#REF!
Name V_ALL_KEYWORDS_TYPE_Vector_ISSR_208002492: #REF!,#REF!,#REF!,#REF!,#REF!,#REF!,#REF!,#REF!,#REF!,#REF!,#REF!,#REF!,#REF!
Name V_ALL_SECTION_KEYWORDS_EQTY_200007003_13A: #REF!
Name V_ALL_SECTION_KEYWORDS_ISSR_208002492_131O: #REF!,#REF!

Sheet Cover
D4: Alphabet, Inc. (GOOGL)
D5: US Internet
D10: Eric Sheridan
D11: eric.sheridan@gs.com
D12: 212-357-1849 (New York)
D14: Alex Vegliante, CFA
D15: alex.vegliante@gs.com
D16: 212-934-1878 (New York)
D18: Aarshiya Sachdeva
D19: aarshiya.sachdeva@gs.com
D20: 212-855-6184 (New York)

Sheet P&L Summary
A1: GOOGL
A2: P&L Summary
A3: (USD Millions) | B3: ='Income Statement'!BB1 -> 1Q23 | C3: ='Income Statement'!BC1 -> 2Q23 | D3: ='Income Statement'!BD1 -> 3Q23 | E3: ='Income Statement'!BE1 -> 4Q23 | F3: ='Income Statement'!BF1 -> 1Q24 | G3: ='Income Statement'!BG1 -> 2Q24 | H3: ='Income Statement'!BH1 -> 3Q24 | I3: ='Income Statement'!BI1 -> 4Q24 | ... Q3: ='Income Statement'!BQ1 -> 4Q26E | S3: ='Income Statement'!CU1 -> 2022 | T3: ='Income Statement'!CV1 -> 2023 | U3: ='Income Statement'!CW1 -> 2024 | V3: ='Income Statement'!CX1 -> 2025E | W3: ='Income Statement'!CY1 -> 2026E
A5: Consolidated Total Revenue | B5: ='Income Statement'!BB64 -> 69787 | C5: ='Income Statement'!BC64 -> 74604 | D5: ='Income Statement'!BD64 -> 76693 | E5: ='Income Statement'!BE64 -> 86310 | F5: ='Income Statement'!BF64 -> 80539 | G5: ='Income Statement'!BG64 -> 84742 | H5: ='Income Statement'!BH64 -> 88268 | I5: ='Income Statement'!BI64 -> 96469 | ... Q5: ='Income Statement'!BQ64 -> 125967.83 | S5: ='Income Statement'!CU64 -> 282836 | T5: ='Income Statement'!CV64 -> 307394 | U5: ='Income Statement'!CW64 -> 350018 | V5: ='Income Statement'!CX64 -> 401166.92 | W5: ='Income Statement'!CY64 -> 456079.88
A6: GAAP Gross Profit | B6: ='Income Statement'!BB172 -> 39175 | C6: ='Income Statement'!BC172 -> 42688 | D6: ='Income Statement'!BD172 -> 43464 | E6: ='Income Statement'!BE172 -> 48735 | F6: ='Income Statement'!BF172 -> 46827 | G6: ='Income Statement'!BG172 -> 49235 | H6: ='Income Statement'!BH172 -> 51794 | I6: ='Income Statement'!BI172 -> 55856 | ... Q6: ='Income Statement'!BQ172 -> 71645.602 | S6: ='Income Statement'!CU172 -> 156633 | T6: ='Income Statement'!CV172 -> 174062 | U6: ='Income Statement'!CW172 -> 203712 | V6: ='Income Statement'!CX172 -> 236648.18 | W6: ='Income Statement'!CY172 -> 266977.57
A7: Total GAAP Operating Expenses | B7: ='Income Statement'!BB196 -> -21760 | C7: ='Income Statement'!BC196 -> -20850 | D7: ='Income Statement'!BD196 -> -22121 | E7: ='Income Statement'!BE196 -> -25038 | F7: ='Income Statement'!BF196 -> -21355 | G7: ='Income Statement'!BG196 -> -21810 | H7: ='Income Statement'!BH196 -> -23273 | I7: ='Income Statement'!BI196 -> -24884 | ... Q7: ='Income Statement'!BQ196 -> -30587.085 | S7: ='Income Statement'!CU196 -> -81791 | T7: ='Income Statement'!CV196 -> -89769 | U7: ='Income Statement'!CW196 -> -91322 | V7: ='Income Statement'!CX196 -> -106843.18 | W7: ='Income Statement'!CY196 -> -112239.94
A8: R&D | B8: ='Income Statement'!BB179 -> -11468 | C8: ='Income Statement'!BC179 -> -10588 | D8: ='Income Statement'!BD179 -> -11258 | E8: ='Income Statement'!BE179 -> -12113 | F8: ='Income Statement'!BF179 -> -11903 | G8: ='Income Statement'!BG179 -> -11860 | H8: ='Income Statement'!BH179 -> -12447 | I8: ='Income Statement'!BI179 -> -13116 | ... Q8: ='Income Statement'!BQ179 -> -17645.939 | S8: ='Income Statement'!CU179 -> -39500 | T8: ='Income Statement'!CV179 -> -45427 | U8: ='Income Statement'!CW179 -> -49326 | V8: ='Income Statement'!CX179 -> -57926.3 | W8: ='Income Statement'!CY179 -> -66186.273
A9: Sales & Marketing | B9: ='Income Statement'!BB184 -> -6533 | C9: ='Income Statement'!BC184 -> -6781 | D9: ='Income Statement'!BD184 -> -6884 | E9: ='Income Statement'!BE184 -> -7719 | F9: ='Income Statement'!BF184 -> -6426 | G9: ='Income Statement'!BG184 -> -6792 | H9: ='Income Statement'!BH184 -> -7227 | I9: ='Income Statement'!BI184 -> -7363 | ... Q9: ='Income Statement'!BQ184 -> -8155.9951 | S9: ='Income Statement'!CU184 -> -26567 | T9: ='Income Statement'!CV184 -> -27917 | U9: ='Income Statement'!CW184 -> -27808 | V9: ='Income Statement'!CX184 -> -28282.78 | W9: ='Income Statement'!CY184 -> -29555.505
A10: G&A | B10: ='Income Statement'!BB189 -> -3759 | C10: ='Income Statement'!BC189 -> -3481 | D10: ='Income Statement'!BD189 -> -3979 | E10: ='Income Statement'!BE189 -> -5206 | F10: ='Income Statement'!BF189 -> -3026 | G10: ='Income Statement'!BG189 -> -3158 | H10: ='Income Statement'!BH189 -> -3599 | I10: ='Income Statement'!BI189 -> -4405 | ... Q10: ='Income Statement'!BQ189 -> -4785.1515 | S10: ='Income Statement'!CU189 -> -15724 | T10: ='Income Statement'!CV189 -> -16425 | U10: ='Income Statement'!CW189 -> -14188 | V10: ='Income Statement'!CX189 -> -20634.1 | W10: ='Income Statement'!CY189 -> -16498.162
A11: Stock-Based Comp | B11: ='Income Statement'!BB228 -> -5284 | C11: ='Income Statement'!BC228 -> -5774 | D11: ='Income Statement'!BD228 -> -5743 | E11: ='Income Statement'!BE228 -> -5659 | F11: ='Income Statement'!BF228 -> -5264 | G11: ='Income Statement'!BG228 -> -5865 | H11: ='Income Statement'!BH228 -> -5846 | I11: ='Income Statement'!BI228 -> -5810 | ... Q11: ='Income Statement'!BQ228 -> -6966.19 | S11: ='Income Statement'!CU228 -> -19362 | T11: ='Income Statement'!CV228 -> -22460 | U11: ='Income Statement'!CW228 -> -22785 | V11: ='Income Statement'!CX228 -> -24273 | W11: ='Income Statement'!CY228 -> -26457.57
A12: GAAP Operating Income | B12: ='Income Statement'!BB201 -> 17415 | C12: ='Income Statement'!BC201 -> 21838 | D12: ='Income Statement'!BD201 -> 21343 | E12: ='Income Statement'!BE201 -> 23697 | F12: ='Income Statement'!BF201 -> 25472 | G12: ='Income Statement'!BG201 -> 27425 | H12: ='Income Statement'!BH201 -> 28521 | I12: ='Income Statement'!BI201 -> 30972 | ... Q12: ='Income Statement'!BQ201 -> 41058.517 | S12: ='Income Statement'!CU201 -> 74842 | T12: ='Income Statement'!CV201 -> 84293 | U12: ='Income Statement'!CW201 -> 112390 | V12: ='Income Statement'!CX201 -> 129805 | W12: ='Income Statement'!CY201 -> 154737.63
A13: Google Services OI | B13: ='Income Statement'!BB207 -> 21737 | C13: ='Income Statement'!BC207 -> 23454 | D13: ='Income Statement'!BD207 -> 23937 | E13: ='Income Statement'!BE207 -> 26730 | F13: ='Income Statement'!BF207 -> 27897 | G13: ='Income Statement'!BG207 -> 29674 | H13: ='Income Statement'!BH207 -> 30856 | I13: ='Income Statement'!BI207 -> 32836 | ... Q13: ='Income Statement'!BQ207 -> 40968.629 | S13: ='Income Statement'!CU207 -> 82699 | T13: ='Income Statement'!CV207 -> 95858 | U13: ='Income Statement'!CW207 -> 121263 | V13: ='Income Statement'!CX207 -> 136359.17 | W13: ='Income Statement'!CY207 -> 154526.62
A14: Google Cloud OI | B14: ='Income Statement'!BB212 -> 191 | C14: ='Income Statement'!BC212 -> 395 | D14: ='Income Statement'!BD212 -> 266 | E14: ='Income Statement'!BE212 -> 864 | F14: ='Income Statement'!BF212 -> 900 | G14: ='Income Statement'!BG212 -> 1172 | H14: ='Income Statement'!BH212 -> 1947 | I14: ='Income Statement'!BI212 -> 2093 | ... Q14: ='Income Statement'!BQ212 -> 5648.7375 | S14: ='Income Statement'!CU212 -> -1922 | T14: ='Income Statement'!CV212 -> 1716 | U14: ='Income Statement'!CW212 -> 6112 | V14: ='Income Statement'!CX212 -> 12446.51 | W14: ='Income Statement'!CY212 -> 19553.8
A15: Other Bets OI | B15: ='Income Statement'!BB218 -> -1225 | C15: ='Income Statement'!BC218 -> -813 | D15: ='Income Statement'!BD218 -> -1194 | E15: ='Income Statement'!BE218 -> -863 | F15: ='Income Statement'!BF218 -> -1020 | G15: ='Income Statement'!BG218 -> -1134 | H15: ='Income Statement'!BH218 -> -1116 | I15: ='Income Statement'!BI218 -> -1174 | ... Q15: ='Income Statement'!BQ218 -> -1574 | S15: ='Income Statement'!CU218 -> -4636 | T15: ='Income Statement'!CV218 -> -4095 | U15: ='Income Statement'!CW218 -> -4444 | V15: ='Income Statement'!CX218 -> -5272 | W15: ='Income Statement'!CY218 -> -6072
A16: Net Income | B16: ='Income Statement'!BB267 -> 15051 | C16: ='Income Statement'!BC267 -> 18368 | D16: ='Income Statement'!BD267 -> 19689 | E16: ='Income Statement'!BE267 -> 20687 | F16: ='Income Statement'!BF267 -> 23662 | G16: ='Income Statement'!BG267 -> 23619 | H16: ='Income Statement'!BH267 -> 26301 | I16: ='Income Statement'!BI267 -> 26536 | ... Q16: ='Income Statement'!BQ267 -> 34324.048 | S16: ='Income Statement'!CU267 -> 59972 | T16: ='Income Statement'!CV267 -> 73795 | U16: ='Income Statement'!CW267 -> 100118 | V16: ='Income Statement'!CX267 -> 128170.63 | W16: ='Income Statement'!CY267 -> 129614.83
A17: GAAP EPS | B17: ='Income Statement'!BB278 -> 1.1737503 | C17: ='Income Statement'!BC278 -> 1.4390473 | D17: ='Income Statement'!BD278 -> 1.5508034 | E17: ='Income Statement'!BE278 -> 1.6415648 | F17: ='Income Statement'!BF278 -> 1.88888 | G17: ='Income Statement'!BG278 -> 1.8902761 | H17: ='Income Statement'!BH278 -> 2.1178034 | I17: ='Income Statement'!BI278 -> 2.149012 | ... Q17: ='Income Statement'!BQ278 -> 2.8453081 | S17: ='Income Statement'!CU278 -> 4.5576606 | T17: ='Income Statement'!CV278 -> 5.8009237 | U17: ='Income Statement'!CW278 -> 8.0433831 | V17: ='Income Statement'!CX278 -> 10.492102 | W17: ='Income Statement'!CY278 -> 10.710306
A18: GAAP EBITDA | B18: ='Cash Flow Statement'!BB61 -> 20601 | C18: ='Cash Flow Statement'!BC61 -> 25235 | D18: ='Cash Flow Statement'!BD61 -> 25143 | E18: ='Cash Flow Statement'!BE61 -> 27013 | F18: ='Cash Flow Statement'!BF61 -> 28885 | G18: ='Cash Flow Statement'!BG61 -> 31133 | H18: ='Cash Flow Statement'!BH61 -> 32506 | I18: ='Cash Flow Statement'!BI61 -> 35177 | ... Q18: ='Cash Flow Statement'!BQ61 -> 52318.644 | S18: ='Cash Flow Statement'!CU61 -> 90770 | T18: ='Cash Flow Statement'!CV61 -> 97992 | U18: ='Cash Flow Statement'!CW61 -> 127701 | V18: ='Cash Flow Statement'!CX61 -> 153229.02 | W18: ='Cash Flow Statement'!CY61 -> 191078.28
A19: Capex | B19: ='Capex & Depreciation'!BB4 -> -6289 | C19: ='Capex & Depreciation'!BC4 -> -6888 | D19: ='Capex & Depreciation'!BD4 -> -8055 | E19: ='Capex & Depreciation'!BE4 -> -11019 | F19: ='Capex & Depreciation'!BF4 -> -12012 | G19: ='Capex & Depreciation'!BG4 -> -13186 | H19: ='Capex & Depreciation'!BH4 -> -13061 | I19: ='Capex & Depreciation'!BI4 -> -14276 | ... Q19: ='Capex & Depreciation'!BQ4 -> -37688.64 | S19: ='Capex & Depreciation'!CU4 -> -31485 | T19: ='Capex & Depreciation'!CV4 -> -32251 | U19: ='Capex & Depreciation'!CW4 -> -52535 | V19: ='Capex & Depreciation'!CX4 -> -92148 | W19: ='Capex & Depreciation'!CY4 -> -121635.36
A20: FCF | B20: ='Cash Flow Statement'!BB76 -> 17220 | C20: ='Cash Flow Statement'!BC76 -> 21778 | D20: ='Cash Flow Statement'!BD76 -> 22601 | E20: ='Cash Flow Statement'!BE76 -> 7896 | F20: ='Cash Flow Statement'!BF76 -> 16836 | G20: ='Cash Flow Statement'!BG76 -> 13454 | H20: ='Cash Flow Statement'!BH76 -> 17637 | I20: ='Cash Flow Statement'!BI76 -> 24837 | ... Q20: ='Cash Flow Statement'!BQ76 -> 16947.867 | S20: ='Cash Flow Statement'!CU76 -> 60010 | T20: ='Cash Flow Statement'!CV76 -> 69495 | U20: ='Cash Flow Statement'!CW76 -> 72764 | V20: ='Cash Flow Statement'!CX76 -> 48256.588 | W20: ='Cash Flow Statement'!CY76 -> 72643.967
A21: FCF Minus SBC | B21: ='Cash Flow Statement'!BB83 -> 11936 | C21: ='Cash Flow Statement'!BC83 -> 16004 | D21: ='Cash Flow Statement'!BD83 -> 16858 | E21: ='Cash Flow Statement'!BE83 -> 2237 | F21: ='Cash Flow Statement'!BF83 -> 11572 | G21: ='Cash Flow Statement'!BG83 -> 7589 | H21: ='Cash Flow Statement'!BH83 -> 11791 | I21: ='Cash Flow Statement'!BI83 -> 19027 | ... Q21: ='Cash Flow Statement'!BQ83 -> 9981.6768 | S21: ='Cash Flow Statement'!CU83 -> 40648 | T21: ='Cash Flow Statement'!CV83 -> 47035 | U21: ='Cash Flow Statement'!CW83 -> 49979 | V21: ='Cash Flow Statement'!CX83 -> 23983.588 | W21: ='Cash Flow Statement'!CY83 -> 46186.397
A23: As % of Revenue
A25: GAAP Gross Profit | B25: ='Income Statement'!BB173 -> 0.67466331 | C25: ='Income Statement'!BC173 -> 0.68777289 | D25: ='Income Statement'!BD173 -> 0.67858425 | E25: ='Income Statement'!BE173 -> 0.67384271 | F25: ='Income Statement'!BF173 -> 0.69277884 | G25: ='Income Statement'!BG173 -> 0.6900007 | H25: ='Income Statement'!BH173 -> 0.69476452 | I25: ='Income Statement'!BI173 -> 0.68433369 | ... Q25: ='Income Statement'!BQ173 -> 0.66183369 | S25: ='Income Statement'!CU173 -> 0.66971238 | T25: ='Income Statement'!CV173 -> 0.67858312 | U25: ='Income Statement'!CW173 -> 0.69027304 | V25: ='Income Statement'!CX173 -> 0.69358774 | W25: ='Income Statement'!CY173 -> 0.68120077
A26: Total GAAP Operating Expenses | B26: ='Income Statement'!BB197 -> -0.37474598 | C26: ='Income Statement'!BC197 -> -0.3359273 | D26: ='Income Statement'!BD197 -> -0.34536541 | E26: ='Income Statement'!BE197 -> -0.34619214 | F26: ='Income Statement'!BF197 -> -0.31593508 | G26: ='Income Statement'!BG197 -> -0.30565482 | H26: ='Income Statement'!BH197 -> -0.31218393 | I26: ='Income Statement'!BI197 -> -0.30487252 | ... Q26: ='Income Statement'!BQ197 -> -0.28255138 | S26: ='Income Statement'!CU197 -> -0.34971203 | T26: ='Income Statement'!CV197 -> -0.34996569 | U26: ='Income Statement'!CW197 -> -0.30944232 | V26: ='Income Statement'!CX197 -> -0.31314468 | W26: ='Income Statement'!CY197 -> -0.28638336
A27: R&D | B27: ='Income Statement'!BB180 -> -0.1974994 | C27: ='Income Statement'!BC180 -> -0.17058985 | D27: ='Income Statement'!BD180 -> -0.17576619 | E27: ='Income Statement'!BE180 -> -0.16748244 | F27: ='Income Statement'!BF180 -> -0.17609812 | G27: ='Income Statement'!BG180 -> -0.1662112 | H27: ='Income Statement'!BH180 -> -0.16696401 | I27: ='Income Statement'!BI180 -> -0.16069394 | ... Q27: ='Income Statement'!BQ180 -> -0.16300619 | S27: ='Income Statement'!CU180 -> -0.16888931 | T27: ='Income Statement'!CV180 -> -0.17709779 | U27: ='Income Statement'!CW180 -> -0.16713992 | V27: ='Income Statement'!CX180 -> -0.16977511 | W27: ='Income Statement'!CY180 -> -0.16887613
A28: Sales & Marketing | B28: ='Income Statement'!BB185 -> -0.1125099 | C28: ='Income Statement'!BC185 -> -0.1092529 | D28: ='Income Statement'!BD185 -> -0.10747685 | E28: ='Income Statement'!BE185 -> -0.10672806 | F28: ='Income Statement'!BF185 -> -0.095069016 | G28: ='Income Statement'!BG185 -> -0.095186042 | H28: ='Income Statement'!BH185 -> -0.09694295 | I28: ='Income Statement'!BI185 -> -0.090209627 | ... Q28: ='Income Statement'!BQ185 -> -0.075341852 | S28: ='Income Statement'!CU185 -> -0.11359195 | T28: ='Income Statement'!CV185 -> -0.10883481 | U28: ='Income Statement'!CW185 -> -0.094226716 | V28: ='Income Statement'!CX185 -> -0.082893473 | W28: ='Income Statement'!CY185 -> -0.075411701
A29: G&A | B29: ='Income Statement'!BB190 -> -0.064736679 | C29: ='Income Statement'!BC190 -> -0.056084554 | D29: ='Income Statement'!BD190 -> -0.062122371 | E29: ='Income Statement'!BE190 -> -0.071981638 | F29: ='Income Statement'!BF190 -> -0.044767949 | G29: ='Income Statement'!BG190 -> -0.044257585 | H29: ='Income Statement'!BH190 -> -0.048276972 | I29: ='Income Statement'!BI190 -> -0.053968954 | ... Q29: ='Income Statement'!BQ190 -> -0.044203334 | S29: ='Income Statement'!CU190 -> -0.067230771 | T29: ='Income Statement'!CV190 -> -0.064033091 | U29: ='Income Statement'!CW190 -> -0.048075685 | V29: ='Income Statement'!CX190 -> -0.060476099 | W29: ='Income Statement'!CY190 -> -0.042095522
A30: Stock-Based Comp | B30: ='Income Statement'!BB229 -> -0.090999897 | C30: ='Income Statement'!BC229 -> -0.093028501 | D30: ='Income Statement'!BD229 -> -0.089662925 | E30: ='Income Statement'!BE229 -> -0.078245119 | F30: ='Income Statement'!BF229 -> -0.077877887 | G30: ='Income Statement'!BG229 -> -0.082194661 | H30: ='Income Statement'!BH229 -> -0.078418222 | I30: ='Income Statement'!BI229 -> -0.071182661 | ... Q30: ='Income Statement'!BQ229 -> -0.064350904 | S30: ='Income Statement'!CU229 -> -0.08278569 | T30: ='Income Statement'!CV229 -> -0.087560622 | U30: ='Income Statement'!CW229 -> -0.077206406 | V30: ='Income Statement'!CX229 -> -0.071141283 | W30: ='Income Statement'!CY229 -> -0.067507232
A31: GAAP Operating Income | B31: ='Income Statement'!BB202 -> 0.29991734 | C31: ='Income Statement'!BC202 -> 0.35184559 | D31: ='Income Statement'!BD202 -> 0.33321884 | E31: ='Income Statement'!BE202 -> 0.32765057 | F31: ='Income Statement'!BF202 -> 0.37684376 | G31: ='Income Statement'!BG202 -> 0.38434588 | H31: ='Income Statement'!BH202 -> 0.38258058 | I31: ='Income Statement'!BI202 -> 0.37946117 | ... Q31: ='Income Statement'!BQ202 -> 0.37928231 | S31: ='Income Statement'!CU202 -> 0.32000034 | T31: ='Income Statement'!CV202 -> 0.32861743 | U31: ='Income Statement'!CW202 -> 0.38083072 | V31: ='Income Statement'!CX202 -> 0.38044306 | W31: ='Income Statement'!CY202 -> 0.39481741
A32: Google Services OI | B32: ='Income Statement'!BB208 -> 0.37676361 | C32: ='Income Statement'!BC208 -> 0.37964357 | D32: ='Income Statement'!BD208 -> 0.37545291 | E32: ='Income Statement'!BE208 -> 0.37375729 | F32: ='Income Statement'!BF208 -> 0.41621162 | G32: ='Income Statement'!BG208 -> 0.418604 | H32: ='Income Statement'!BH208 -> 0.41616314 | I32: ='Income Statement'!BI208 -> 0.40437926 | ... Q32: ='Income Statement'!BQ208 -> 0.38 | S32: ='Income Statement'!CU208 -> 0.3582323 | T32: ='Income Statement'!CV208 -> 0.37629002 | U32: ='Income Statement'!CW208 -> 0.41350138 | V32: ='Income Statement'!CX208 -> 0.40145039 | W32: ='Income Statement'!CY208 -> 0.39596253
A33: Google Cloud OI | B33: ='Income Statement'!BB213 -> 0.025623826 | C33: ='Income Statement'!BC213 -> 0.04918441 | D33: ='Income Statement'!BD213 -> 0.031625253 | E33: ='Income Statement'!BE213 -> 0.093994778 | F33: ='Income Statement'!BF213 -> 0.094004596 | G33: ='Income Statement'!BG213 -> 0.11326955 | H33: ='Income Statement'!BH213 -> 0.17149652 | I33: ='Income Statement'!BI213 -> 0.17507319 | ... Q33: ='Income Statement'!BQ213 -> 0.27 | S33: ='Income Statement'!CU213 -> -0.073135464 | T33: ='Income Statement'!CV213 -> 0.051861702 | U33: ='Income Statement'!CW213 -> 0.14138657 | V33: ='Income Statement'!CX213 -> 0.21541954 | W33: ='Income Statement'!CY213 -> 0.25388644
A34: Other Bets OI | B34: ='Income Statement'!BB219 -> -4.2534722 | C34: ='Income Statement'!BC219 -> -2.8526316 | D34: ='Income Statement'!BD219 -> -4.020202 | E34: ='Income Statement'!BE219 -> -1.3135464 | F34: ='Income Statement'!BF219 -> -2.0606061 | G34: ='Income Statement'!BG219 -> -3.1068493 | H34: ='Income Statement'!BH219 -> -2.8762887 | I34: ='Income Statement'!BI219 -> -2.935 | ... Q34: ='Income Statement'!BQ219 -> -3.569161 | S34: ='Income Statement'!CU219 -> -4.340824 | T34: ='Income Statement'!CV219 -> -2.6817289 | U34: ='Income Statement'!CW219 -> -2.6966019 | V34: ='Income Statement'!CX219 -> -3.3219912 | W34: ='Income Statement'!CY219 -> -3.6438923
A35: Net Income | B35: ='Income Statement'!BB268 -> 0.25920504 | C35: ='Income Statement'!BC268 -> 0.29593826 | D35: ='Income Statement'!BD268 -> 0.30739567 | E35: ='Income Statement'!BE268 -> 0.2860323 | F35: ='Income Statement'!BF268 -> 0.35006584 | G35: ='Income Statement'!BG268 -> 0.33100694 | H35: ='Income Statement'!BH268 -> 0.35280151 | I35: ='Income Statement'!BI268 -> 0.32511241 | ... Q35: ='Income Statement'!BQ268 -> 0.31707196 | S35: ='Income Statement'!CU268 -> 0.256421 | T35: ='Income Statement'!CV268 -> 0.28769083 | U35: ='Income Statement'!CW268 -> 0.33924735 | V35: ='Income Statement'!CX268 -> 0.37565291 | W35: ='Income Statement'!CY268 -> 0.33071588
A36: GAAP EBITDA | B36: ='Cash Flow Statement'!BB62 -> 0.35478593 | C36: ='Cash Flow Statement'!BC62 -> 0.40657676 | D36: ='Cash Flow Statement'!BD62 -> 0.39254656 | E36: ='Cash Flow Statement'!BE62 -> 0.37349981 | F36: ='Cash Flow Statement'!BF62 -> 0.42733715 | G36: ='Cash Flow Statement'!BG62 -> 0.4363114 | H36: ='Cash Flow Statement'!BH62 -> 0.43603536 | I36: ='Cash Flow Statement'!BI62 -> 0.43097977 | ... Q36: ='Cash Flow Statement'!BQ62 -> 0.48329891 | S36: ='Cash Flow Statement'!CU62 -> 0.38810335 | T36: ='Cash Flow Statement'!CV62 -> 0.38202317 | U36: ='Cash Flow Statement'!CW62 -> 0.43271166 | V36: ='Cash Flow Statement'!CX62 -> 0.44909609 | W36: ='Cash Flow Statement'!CY62 -> 0.4875416
A37: Capex | B37: ='Capex & Depreciation'!BB5 -> -0.10830779 | C37: ='Capex & Depreciation'!BC5 -> -0.11097685 | D37: ='Capex & Depreciation'!BD5 -> -0.12575916 | E37: ='Capex & Depreciation'!BE5 -> -0.15235606 | F37: ='Capex & Depreciation'!BF5 -> -0.17771071 | G37: ='Capex & Depreciation'!BG5 -> -0.18479434 | H37: ='Capex & Depreciation'!BH5 -> -0.1752002 | I37: ='Capex & Depreciation'!BI5 -> -0.17490597 | ... Q37: ='Capex & Depreciation'!BQ5 -> -0.34815273 | S37: ='Capex & Depreciation'!CU5 -> -0.13461974 | T37: ='Capex & Depreciation'!CV5 -> -0.12573097 | U37: ='Capex & Depreciation'!CW5 -> -0.17801354 | V37: ='Capex & Depreciation'!CX5 -> -0.27007486 | W37: ='Capex & Depreciation'!CY5 -> -0.31035604
A38: FCF | B38: ='Cash Flow Statement'!BB77 -> 0.29655909 | C38: ='Cash Flow Statement'!BC77 -> 0.35087889 | D38: ='Cash Flow Statement'!BD77 -> 0.35285944 | E38: ='Cash Flow Statement'!BE77 -> 0.10917538 | F38: ='Cash Flow Statement'!BF77 -> 0.24907905 | G38: ='Cash Flow Statement'!BG77 -> 0.18855021 | H38: ='Cash Flow Statement'!BH77 -> 0.23658265 | I38: ='Cash Flow Statement'!BI77 -> 0.30429669 | ... Q38: ='Cash Flow Statement'!BQ77 -> 0.15655768 | S38: ='Cash Flow Statement'!CU77 -> 0.25658348 | T38: ='Cash Flow Statement'!CV77 -> 0.27092722 | U38: ='Cash Flow Statement'!CW77 -> 0.246559 | V38: ='Cash Flow Statement'!CX77 -> 0.14143434 | W38: ='Cash Flow Statement'!CY77 -> 0.18535312
A39: FCF Minus SBC | B39: ='Cash Flow Statement'!BB84 -> 0.20555919 | C39: ='Cash Flow Statement'!BC84 -> 0.25785039 | D39: ='Cash Flow Statement'!BD84 -> 0.26319652 | E39: ='Cash Flow Statement'!BE84 -> 0.030930258 | F39: ='Cash Flow Statement'!BF84 -> 0.17120116 | G39: ='Cash Flow Statement'!BG84 -> 0.10635555 | H39: ='Cash Flow Statement'!BH84 -> 0.15816443 | I39: ='Cash Flow Statement'!BI84 -> 0.23311403 | ... Q39: ='Cash Flow Statement'!BQ84 -> 0.092206776 | S39: ='Cash Flow Statement'!CU84 -> 0.17379779 | T39: ='Cash Flow Statement'!CV84 -> 0.1833666 | U39: ='Cash Flow Statement'!CW84 -> 0.1693526 | V39: ='Cash Flow Statement'!CX84 -> 0.070293052 | W39: ='Cash Flow Statement'!CY84 -> 0.11784589
A41: Year-on-Year Growth
A43: Consolidated Total Revenue | B43: ='Income Statement'!BB66 -> 0.026113423 | C43: ='Income Statement'!BC66 -> 0.070589079 | D43: ='Income Statement'!BD66 -> 0.11001274 | E43: ='Income Statement'!BE66 -> 0.13494109 | F43: ='Income Statement'!BF66 -> 0.15406881 | G43: ='Income Statement'!BG66 -> 0.13589084 | H43: ='Income Statement'!BH66 -> 0.15092642 | I43: ='Income Statement'!BI66 -> 0.11770363 | ... Q43: ='Income Statement'!BQ66 -> 0.12311913 | S43: ='Income Statement'!CU66 -> 0.097808156 | T43: ='Income Statement'!CV66 -> 0.086827702 | U43: ='Income Statement'!CW66 -> 0.13866243 | V43: ='Income Statement'!CX66 -> 0.14613225 | W43: ='Income Statement'!CY66 -> 0.13688308
A44: GAAP Gross Profit | B44: ='Income Statement'!BB176 -> 0.019863584 | C44: ='Income Statement'!BC176 -> 0.078497259 | D44: ='Income Statement'!BD176 -> 0.14577951 | E44: ='Income Statement'!BE176 -> 0.19724365 | F44: ='Income Statement'!BF176 -> 0.19532865 | G44: ='Income Statement'!BG176 -> 0.15336863 | H44: ='Income Statement'!BH176 -> 0.19165286 | I44: ='Income Statement'!BI176 -> 0.14611675 | ... Q44: ='Income Statement'!BQ176 -> 0.11235075 | S44: ='Income Statement'!CU176 -> 0.067724168 | T44: ='Income Statement'!CV176 -> 0.11127285 | U44: ='Income Statement'!CW176 -> 0.1703416 | V44: ='Income Statement'!CX176 -> 0.16168013 | W44: ='Income Statement'!CY176 -> 0.12816237
A45: GAAP Gross Profit Margin (bps) | B45: ='Income Statement'!BB174 -> -110.0813 | C45: ='Income Statement'!BC174 -> -9.3967749 | D45: ='Income Statement'!BD174 -> 161.66763 | E45: ='Income Statement'!BE174 -> 289.74752 | F45: ='Income Statement'!BF174 -> 181.15524 | G45: ='Income Statement'!BG174 -> 22.278101 | H45: ='Income Statement'!BH174 -> 161.80264 | I45: ='Income Statement'!BI174 -> 104.90981 | ... Q45: ='Income Statement'!BQ174 -> -125 | S45: ='Income Statement'!CU174 -> -220.27655 | T45: ='Income Statement'!CV174 -> 88.70749 | U45: ='Income Statement'!CW174 -> 116.89919 | V45: ='Income Statement'!CX174 -> 33.147002 | W45: ='Income Statement'!CY174 -> -123.86973
...

Sheet Revenue Summary
A1: GOOGL
A2: Revenue & Key Metrics Summary
A3: (USD millions) | B3: ='Income Statement'!BB1 -> 1Q23 | C3: ='Income Statement'!BC1 -> 2Q23 | D3: ='Income Statement'!BD1 -> 3Q23 | E3: ='Income Statement'!BE1 -> 4Q23 | F3: ='Income Statement'!BF1 -> 1Q24 | G3: ='Income Statement'!BG1 -> 2Q24 | H3: ='Income Statement'!BH1 -> 3Q24 | I3: ='Income Statement'!BI1 -> 4Q24 | ... Q3: ='Income Statement'!BQ1 -> 4Q26E | S3: ='Income Statement'!CU1 -> 2022 | T3: ='Income Statement'!CV1 -> 2023 | U3: ='Income Statement'!CW1 -> 2024 | V3: ='Income Statement'!CX1 -> 2025E | W3: ='Income Statement'!CY1 -> 2026E
A5: Gross Consolidated Revenue | B5: ='Income Statement'!BB64 -> 69787 | C5: ='Income Statement'!BC64 -> 74604 | D5: ='Income Statement'!BD64 -> 76693 | E5: ='Income Statement'!BE64 -> 86310 | F5: ='Income Statement'!BF64 -> 80539 | G5: ='Income Statement'!BG64 -> 84742 | H5: ='Income Statement'!BH64 -> 88268 | I5: ='Income Statement'!BI64 -> 96469 | ... Q5: ='Income Statement'!BQ64 -> 125967.83 | S5: ='Income Statement'!CU64 -> 282836 | T5: ='Income Statement'!CV64 -> 307394 | U5: ='Income Statement'!CW64 -> 350018 | V5: ='Income Statement'!CX64 -> 401166.92 | W5: ='Income Statement'!CY64 -> 456079.88
A6: Google Segment Revenues | B6: ='Income Statement'!BB3 -> 69415 | C6: ='Income Statement'!BC3 -> 74316 | D6: ='Income Statement'!BD3 -> 76397 | E6: ='Income Statement'!BE3 -> 85503 | F6: ='Income Statement'!BF3 -> 79972 | G6: ='Income Statement'!BG3 -> 84275 | H6: ='Income Statement'!BH3 -> 87863 | I6: ='Income Statement'!BI3 -> 96049 | ... Q6: ='Income Statement'!BQ3 -> 125526.83 | S6: ='Income Statement'!CU3 -> 279808 | T6: ='Income Statement'!CV3 -> 305631 | U6: ='Income Statement'!CW3 -> 348159 | V6: ='Income Statement'!CX3 -> 399638.92 | W6: ='Income Statement'!CY3 -> 454413.53
A7: Google Services Revenue | B7: ='Income Statement'!BB8 -> 61961 | C7: ='Income Statement'!BC8 -> 66285 | D7: ='Income Statement'!BD8 -> 67986 | E7: ='Income Statement'!BE8 -> 76311 | F7: ='Income Statement'!BF8 -> 70398 | G7: ='Income Statement'!BG8 -> 73928 | H7: ='Income Statement'!BH8 -> 76510 | I7: ='Income Statement'!BI8 -> 84094 | ... Q7: ='Income Statement'!BQ8 -> 104605.58 | S7: ='Income Statement'!CU8 -> 253528 | T7: ='Income Statement'!CV8 -> 272543 | U7: ='Income Statement'!CW8 -> 304930 | V7: ='Income Statement'!CX8 -> 341860.92 | W7: ='Income Statement'!CY8 -> 377395.63
A8: Google Advertising Revenue | B8: ='Income Statement'!BB14 -> 54548 | C8: ='Income Statement'!BC14 -> 58143 | D8: ='Income Statement'!BD14 -> 59647 | E8: ='Income Statement'!BE14 -> 65517 | F8: ='Income Statement'!BF14 -> 61659 | G8: ='Income Statement'!BG14 -> 64616 | H8: ='Income Statement'!BH14 -> 65854 | I8: ='Income Statement'!BI14 -> 72461 | ... Q8: ='Income Statement'!BQ14 -> 89157.995 | S8: ='Income Statement'!CU14 -> 224473 | T8: ='Income Statement'!CV14 -> 237855 | U8: ='Income Statement'!CW14 -> 264590 | V8: ='Income Statement'!CX14 -> 293595.4 | W8: ='Income Statement'!CY14 -> 322907.25
A9: Google Search & Other | B9: ='Income Statement'!BB20 -> 40359 | C9: ='Income Statement'!BC20 -> 42628 | D9: ='Income Statement'!BD20 -> 44026 | E9: ='Income Statement'!BE20 -> 48020 | F9: ='Income Statement'!BF20 -> 46156 | G9: ='Income Statement'!BG20 -> 48509 | H9: ='Income Statement'!BH20 -> 49385 | I9: ='Income Statement'!BI20 -> 54034 | ... Q9: ='Income Statement'!BQ20 -> 68066.63 | S9: ='Income Statement'!CU20 -> 162450 | T9: ='Income Statement'!CV20 -> 175033 | U9: ='Income Statement'!CW20 -> 198084 | V9: ='Income Statement'!CX20 -> 223057.76 | W9: ='Income Statement'!CY20 -> 247793.14
A10: Youtube Ads | B10: ='Income Statement'!BB27 -> 6693 | C10: ='Income Statement'!BC27 -> 7665 | D10: ='Income Statement'!BD27 -> 7952 | E10: ='Income Statement'!BE27 -> 9200 | F10: ='Income Statement'!BF27 -> 8090 | G10: ='Income Statement'!BG27 -> 8663 | H10: ='Income Statement'!BH27 -> 8921 | I10: ='Income Statement'!BI27 -> 10473 | ... Q10: ='Income Statement'!BQ27 -> 13491.319 | S10: ='Income Statement'!CU27 -> 29243 | T10: ='Income Statement'!CV27 -> 31510 | U10: ='Income Statement'!CW27 -> 36147 | V10: ='Income Statement'!CX27 -> 40818.49 | W10: ='Income Statement'!CY27 -> 45989.344
A11: Google Network Members' Properties | B11: ='Income Statement'!BB34 -> 7496 | C11: ='Income Statement'!BC34 -> 7850 | D11: ='Income Statement'!BD34 -> 7669 | E11: ='Income Statement'!BE34 -> 8297 | F11: ='Income Statement'!BF34 -> 7413 | G11: ='Income Statement'!BG34 -> 7444 | H11: ='Income Statement'!BH34 -> 7548 | I11: ='Income Statement'!BI34 -> 7954 | ... Q11: ='Income Statement'!BQ34 -> 7600.047 | S11: ='Income Statement'!CU34 -> 32780 | T11: ='Income Statement'!CV34 -> 31312 | U11: ='Income Statement'!CW34 -> 30359 | V11: ='Income Statement'!CX34 -> 29719.15 | W11: ='Income Statement'!CY34 -> 29124.767
A12: Google Other | B12: ='Income Statement'!BB41 -> 7413 | C12: ='Income Statement'!BC41 -> 8142 | D12: ='Income Statement'!BD41 -> 8339 | E12: ='Income Statement'!BE41 -> 10794 | F12: ='Income Statement'!BF41 -> 8739 | G12: ='Income Statement'!BG41 -> 9312 | H12: ='Income Statement'!BH41 -> 10656 | I12: ='Income Statement'!BI41 -> 11633 | ... Q12: ='Income Statement'!BQ41 -> 15447.581 | S12: ='Income Statement'!CU41 -> 29055 | T12: ='Income Statement'!CV41 -> 34688 | U12: ='Income Statement'!CW41 -> 40340 | V12: ='Income Statement'!CX41 -> 48265.518 | W12: ='Income Statement'!CY41 -> 54488.381
A13: Google Cloud | B13: ='Income Statement'!BB47 -> 7454 | C13: ='Income Statement'!BC47 -> 8031 | D13: ='Income Statement'!BD47 -> 8411 | E13: ='Income Statement'!BE47 -> 9192 | F13: ='Income Statement'!BF47 -> 9574 | G13: ='Income Statement'!BG47 -> 10347 | H13: ='Income Statement'!BH47 -> 11353 | I13: ='Income Statement'!BI47 -> 11955 | ... Q13: ='Income Statement'!BQ47 -> 20921.25 | S13: ='Income Statement'!CU47 -> 26280 | T13: ='Income Statement'!CV47 -> 33088 | U13: ='Income Statement'!CW47 -> 43229 | V13: ='Income Statement'!CX47 -> 57778 | W13: ='Income Statement'!CY47 -> 77017.9
A14: Other Bets | B14: ='Income Statement'!BB53 -> 288 | C14: ='Income Statement'!BC53 -> 285 | D14: ='Income Statement'!BD53 -> 297 | E14: ='Income Statement'!BE53 -> 657 | F14: ='Income Statement'!BF53 -> 495 | G14: ='Income Statement'!BG53 -> 365 | H14: ='Income Statement'!BH53 -> 388 | I14: ='Income Statement'!BI53 -> 400 | ... Q14: ='Income Statement'!BQ53 -> 441 | S14: ='Income Statement'!CU53 -> 1068 | T14: ='Income Statement'!CV53 -> 1527 | U14: ='Income Statement'!CW53 -> 1648 | V14: ='Income Statement'!CX53 -> 1587 | W14: ='Income Statement'!CY53 -> 1666.35
A15: Total TAC | B15: ='Income Statement'!BB68 -> -11721 | C15: ='Income Statement'!BC68 -> -12537 | D15: ='Income Statement'!BD68 -> -12642 | E15: ='Income Statement'!BE68 -> -13986 | F15: ='Income Statement'!BF68 -> -12946 | G15: ='Income Statement'!BG68 -> -13387 | H15: ='Income Statement'!BH68 -> -13719 | I15: ='Income Statement'!BI68 -> -14848 | ... Q15: ='Income Statement'!BQ68 -> -17714.646 | S15: ='Income Statement'!CU68 -> -48955 | T15: ='Income Statement'!CV68 -> -50886 | U15: ='Income Statement'!CW68 -> -54900 | V15: ='Income Statement'!CX68 -> -59972.622 | W15: ='Income Statement'!CY68 -> -64157.875
A16: Net Consolidated Revenue | B16: ='Income Statement'!BB85 -> 58066 | C16: ='Income Statement'!BC85 -> 62067 | D16: ='Income Statement'!BD85 -> 64051 | E16: ='Income Statement'!BE85 -> 72324 | F16: ='Income Statement'!BF85 -> 67593 | G16: ='Income Statement'!BG85 -> 71355 | H16: ='Income Statement'!BH85 -> 74549 | I16: ='Income Statement'!BI85 -> 81621 | ... Q16: ='Income Statement'!BQ85 -> 108253.18 | S16: ='Income Statement'!CU85 -> 233881 | T16: ='Income Statement'!CV85 -> 256508 | U16: ='Income Statement'!CW85 -> 295118 | V16: ='Income Statement'!CX85 -> 341194.3 | W16: ='Income Statement'!CY85 -> 391922.01
A18: Year-on-Year Growth
A20: Gross Consolidated Revenue | B20: ='Income Statement'!BB66 -> 0.026113423 | C20: ='Income Statement'!BC66 -> 0.070589079 | D20: ='Income Statement'!BD66 -> 0.11001274 | E20: ='Income Statement'!BE66 -> 0.13494109 | F20: ='Income Statement'!BF66 -> 0.15406881 | G20: ='Income Statement'!BG66 -> 0.13589084 | H20: ='Income Statement'!BH66 -> 0.15092642 | I20: ='Income Statement'!BI66 -> 0.11770363 | ... Q20: ='Income Statement'!BQ66 -> 0.12311913 | S20: ='Income Statement'!CU66 -> 0.097808156 | T20: ='Income Statement'!CV66 -> 0.086827702 | U20: ='Income Statement'!CW66 -> 0.13866243 | V20: ='Income Statement'!CX66 -> 0.14613225 | W20: ='Income Statement'!CY66 -> 0.13688308
A21: Google Segment Revenues | B21: ='Income Statement'!BB5 -> 0.031533741 | C21: ='Income Statement'!BC5 -> 0.075220279 | D21: ='Income Statement'!BD5 -> 0.11945197 | E21: ='Income Statement'!BE5 -> 0.13771905 | F21: ='Income Statement'!BF5 -> 0.15208528 | G21: ='Income Statement'!BG5 -> 0.13400883 | H21: ='Income Statement'!BH5 -> 0.15008443 | I21: ='Income Statement'!BI5 -> 0.1233407 | ... Q21: ='Income Statement'!BQ5 -> 0.12339397 | S21: ='Income Statement'!CU5 -> 0.089870879 | T21: ='Income Statement'!CV5 -> 0.092288283 | U21: ='Income Statement'!CW5 -> 0.13914819 | V21: ='Income Statement'!CX5 -> 0.14786324 | W21: ='Income Statement'!CY5 -> 0.13706026
A22: Google Services Revenue | B22: ='Income Statement'!BB10 -> 0.0079548412 | C22: ='Income Statement'!BC10 -> 0.054804984 | D22: ='Income Statement'!BD10 -> 0.10767877 | E22: ='Income Statement'!BE10 -> 0.1249005 | F22: ='Income Statement'!BF10 -> 0.1361663 | G22: ='Income Statement'!BG10 -> 0.11530512 | H22: ='Income Statement'!BH10 -> 0.12537875 | I22: ='Income Statement'!BI10 -> 0.10199054 | ... Q22: ='Income Statement'!BQ10 -> 0.1010891 | S22: ='Income Statement'!CU10 -> 0.067355986 | T22: ='Income Statement'!CV10 -> 0.075001578 | U22: ='Income Statement'!CW10 -> 0.11883262 | V22: ='Income Statement'!CX10 -> 0.12111277 | W22: ='Income Statement'!CY10 -> 0.10394494
A23: Google Advertising Revenue | B23: ='Income Statement'!BB16 -> -0.0020672875 | C23: ='Income Statement'!BC16 -> 0.032955514 | D23: ='Income Statement'!BD16 -> 0.094801953 | E23: ='Income Statement'!BE16 -> 0.10966769 | F23: ='Income Statement'!BF16 -> 0.13036225 | G23: ='Income Statement'!BG16 -> 0.11132896 | H23: ='Income Statement'!BH16 -> 0.10406223 | I23: ='Income Statement'!BI16 -> 0.10598776 | ... Q23: ='Income Statement'!BQ16 -> 0.09816175 | S23: ='Income Statement'!CU16 -> 0.071485511 | T23: ='Income Statement'!CV16 -> 0.059615188 | U23: ='Income Statement'!CW16 -> 0.11240041 | V23: ='Income Statement'!CX16 -> 0.10962395 | W23: ='Income Statement'!CY16 -> 0.099837567
A24: Google Search & Other | B24: ='Income Statement'!BB22 -> 0.01870362 | C24: ='Income Statement'!BC22 -> 0.047654157 | D24: ='Income Statement'!BD22 -> 0.11348289 | E24: ='Income Statement'!BE22 -> 0.12712421 | F24: ='Income Statement'!BF22 -> 0.14363587 | G24: ='Income Statement'!BG22 -> 0.13796096 | H24: ='Income Statement'!BH22 -> 0.12172353 | I24: ='Income Statement'!BI22 -> 0.12523948 | ... Q24: ='Income Statement'!BQ22 -> 0.105 | S24: ='Income Statement'!CU22 -> 0.090627119 | T24: ='Income Statement'!CV22 -> 0.077457679 | U24: ='Income Statement'!CW22 -> 0.13169517 | V24: ='Income Statement'!CX22 -> 0.12607661 | W24: ='Income Statement'!CY22 -> 0.11089226
A25: Youtube Ads | B25: ='Income Statement'!BB29 -> -0.025622361 | C25: ='Income Statement'!BC29 -> 0.044277929 | D25: ='Income Statement'!BD29 -> 0.12459341 | E25: ='Income Statement'!BE29 -> 0.15534346 | F25: ='Income Statement'!BF29 -> 0.20872553 | G25: ='Income Statement'!BG29 -> 0.13020222 | H25: ='Income Statement'!BH29 -> 0.12185614 | I25: ='Income Statement'!BI29 -> 0.13836957 | ... Q25: ='Income Statement'!BQ29 -> 0.14 | S25: ='Income Statement'!CU29 -> 0.013797885 | T25: ='Income Statement'!CV29 -> 0.077522826 | U25: ='Income Statement'!CW29 -> 0.14715963 | V25: ='Income Statement'!CX29 -> 0.1292359 | W25: ='Income Statement'!CY29 -> 0.1266792
A26: Google Network Members' Properties | B26: ='Income Statement'!BB36 -> -0.082945926 | C26: ='Income Statement'!BC36 -> -0.049521734 | D26: ='Income Statement'!BD36 -> -0.025787602 | E26: ='Income Statement'!BE36 -> -0.02100295 | F26: ='Income Statement'!BF36 -> -0.011072572 | G26: ='Income Statement'!BG36 -> -0.051719745 | H26: ='Income Statement'!BH36 -> -0.015777807 | I26: ='Income Statement'!BI36 -> -0.041340243 | ... Q26: ='Income Statement'!BQ36 -> -0.02 | S26: ='Income Statement'!CU36 -> 0.034036781 | T26: ='Income Statement'!CV36 -> -0.044783405 | U26: ='Income Statement'!CW36 -> -0.030435616 | V26: ='Income Statement'!CX36 -> -0.021076122 | W26: ='Income Statement'!CY36 -> -0.02
A27: Google Other | B27: ='Income Statement'!BB43 -> 0.088386434 | C27: ='Income Statement'!BC43 -> 0.24248436 | D27: ='Income Statement'!BD43 -> 0.20942712 | E27: ='Income Statement'!BE43 -> 0.2271487 | F27: ='Income Statement'!BF43 -> 0.17887495 | G27: ='Income Statement'!BG43 -> 0.14369934 | H27: ='Income Statement'!BH43 -> 0.27785106 | I27: ='Income Statement'!BI43 -> 0.077728368 | ... Q27: ='Income Statement'!BQ43 -> 0.11829448 | S27: ='Income Statement'!CU43 -> 0.036494007 | T27: ='Income Statement'!CV43 -> 0.19387369 | U27: ='Income Statement'!CW43 -> 0.16293819 | V27: ='Income Statement'!CX43 -> 0.19646797 | W27: ='Income Statement'!CY43 -> 0.1289298
A28: Google Cloud | B28: ='Income Statement'!BB49 -> 0.28053599 | C28: ='Income Statement'!BC49 -> 0.27963671 | D28: ='Income Statement'!BD49 -> 0.22466511 | E28: ='Income Statement'!BE49 -> 0.25659604 | F28: ='Income Statement'!BF49 -> 0.28441105 | G28: ='Income Statement'!BG49 -> 0.28838252 | H28: ='Income Statement'!BH49 -> 0.34978005 | I28: ='Income Statement'!BI49 -> 0.30058747 | ... Q28: ='Income Statement'!BQ49 -> 0.25 | S28: ='Income Statement'!CU49 -> 0.3683224 | T28: ='Income Statement'!CV49 -> 0.25905632 | U28: ='Income Statement'!CW49 -> 0.30648574 | V28: ='Income Statement'!CX49 -> 0.33655648 | W28: ='Income Statement'!CY49 -> 0.33299699
A29: Other Bets | B29: ='Income Statement'!BB55 -> -0.34545455 | C29: ='Income Statement'!BC55 -> 0.47668394 | D29: ='Income Statement'!BD55 -> 0.42105263 | E29: ='Income Statement'!BE55 -> 1.9070796 | F29: ='Income Statement'!BF55 -> 0.71875 | G29: ='Income Statement'!BG55 -> 0.28070175 | H29: ='Income Statement'!BH55 -> 0.30639731 | I29: ='Income Statement'!BI55 -> -0.39117199 | ... Q29: ='Income Statement'!BQ55 -> 0.05 | S29: ='Income Statement'!CU55 -> 0.41832669 | T29: ='Income Statement'!CV55 -> 0.42977528 | U29: ='Income Statement'!CW55 -> 0.079240341 | V29: ='Income Statement'!CX55 -> -0.037014563 | W29: ='Income Statement'!CY55 -> 0.05
A30: Total TAC | B30: ='Income Statement'!BB70 -> -0.022435363 | C30: ='Income Statement'!BC70 -> 0.026445063 | D30: ='Income Statement'!BD70 -> 0.069000507 | E30: ='Income Statement'!BE70 -> 0.082088975 | F30: ='Income Statement'!BF70 -> 0.10451327 | G30: ='Income Statement'!BG70 -> 0.067799314 | H30: ='Income Statement'!BH70 -> 0.085192216 | I30: ='Income Statement'!BI70 -> 0.061633062 | ... Q30: ='Income Statement'!BQ70 -> 0.064350398 | S30: ='Income Statement'!CU70 -> 0.074375631 | T30: ='Income Statement'!CV70 -> 0.039444388 | U30: ='Income Statement'!CW70 -> 0.078882207 | V30: ='Income Statement'!CX70 -> 0.092397486 | W30: ='Income Statement'!CY70 -> 0.069786062
A31: Net Consolidated Revenue | B31: ='Income Statement'!BB87 -> 0.036504168 | C31: ='Income Statement'!BC87 -> 0.079970768 | D31: ='Income Statement'!BD87 -> 0.11848217 | E31: ='Income Statement'!BE87 -> 0.14576303 | F31: ='Income Statement'!BF87 -> 0.16407192 | G31: ='Income Statement'!BG87 -> 0.14964474 | H31: ='Income Statement'!BH87 -> 0.16390064 | I31: ='Income Statement'!BI87 -> 0.12854654 | ... Q31: ='Income Statement'!BQ87 -> 0.13335963 | S31: ='Income Statement'!CU87 -> 0.10284292 | T31: ='Income Statement'!CV87 -> 0.096745781 | U31: ='Income Statement'!CW87 -> 0.15052162 | V31: ='Income Statement'!CX87 -> 0.15612838 | W31: ='Income Statement'!CY87 -> 0.1486769
A33: Quarter-on-Quarter Growth
A35: Gross Consolidated Revenue | B35: ='Income Statement'!BB65 -> -0.082329581 | C35: ='Income Statement'!BC65 -> 0.069024317 | D35: ='Income Statement'!BD65 -> 0.02800118 | E35: ='Income Statement'!BE65 -> 0.12539606 | F35: ='Income Statement'!BF65 -> -0.066863631 | G35: ='Income Statement'!BG65 -> 0.052185898 | H35: ='Income Statement'!BH65 -> 0.041608647 | I35: ='Income Statement'!BI65 -> 0.092910228 | ... Q35: ='Income Statement'!BQ65 -> 0.081490786
A36: Google Segment Revenues | B36: ='Income Statement'!BB4 -> -0.076350911 | C36: ='Income Statement'!BC4 -> 0.070604336 | D36: ='Income Statement'!BD4 -> 0.028002045 | E36: ='Income Statement'!BE4 -> 0.11919316 | F36: ='Income Statement'!BF4 -> -0.064687789 | G36: ='Income Statement'!BG4 -> 0.053806332 | H36: ='Income Statement'!BH4 -> 0.042574904 | I36: ='Income Statement'!BI4 -> 0.093167773 | ... Q36: ='Income Statement'!BQ4 -> 0.08105703
A37: Google Services Revenue | B37: ='Income Statement'!BB9 -> -0.086632861 | C37: ='Income Statement'!BC9 -> 0.069785833 | D37: ='Income Statement'!BD9 -> 0.025661914 | E37: ='Income Statement'!BE9 -> 0.12245168 | F37: ='Income Statement'!BF9 -> -0.077485553 | G37: ='Income Statement'!BG9 -> 0.05014347 | H37: ='Income Statement'!BH9 -> 0.034925874 | I37: ='Income Statement'!BI9 -> 0.099124297 | ... Q37: ='Income Statement'!BQ9 -> 0.090140073
A38: Google Advertising Revenue | B38: ='Income Statement'!BB15 -> -0.076115308 | C38: ='Income Statement'!BC15 -> 0.065905258 | D38: ='Income Statement'!BD15 -> 0.025867258 | E38: ='Income Statement'!BE15 -> 0.098412326 | F38: ='Income Statement'!BF15 -> -0.05888548 | G38: ='Income Statement'!BG15 -> 0.047957314 | H38: ='Income Statement'!BH15 -> 0.019159341 | I38: ='Income Statement'!BI15 -> 0.100328 | ... Q38: ='Income Statement'!BQ15 -> 0.094116041
A39: Google Search & Other | B39: ='Income Statement'!BB21 -> -0.052694583 | C39: ='Income Statement'!BC21 -> 0.056220422 | D39: ='Income Statement'!BD21 -> 0.032795346 | E39: ='Income Statement'!BE21 -> 0.090719121 | F39: ='Income Statement'!BF21 -> -0.03881716 | G39: ='Income Statement'!BG21 -> 0.050979288 | H39: ='Income Statement'!BH21 -> 0.018058505 | I39: ='Income Statement'!BI21 -> 0.094137896 | ... Q39: ='Income Statement'!BQ21 -> 0.084047026
A40: Youtube Ads | B40: ='Income Statement'!BB28 -> -0.15948763 | C40: ='Income Statement'!BC28 -> 0.14522636 | D40: ='Income Statement'!BD28 -> 0.037442922 | E40: ='Income Statement'!BE28 -> 0.15694165 | F40: ='Income Statement'!BF28 -> -0.12065217 | G40: ='Income Statement'!BG28 -> 0.070828183 | H40: ='Income Statement'!BH28 -> 0.029781831 | I40: ='Income Statement'!BI28 -> 0.17397153 | ... Q40: ='Income Statement'!BQ28 -> 0.17394213
A41: Google Network Members' Properties | B41: ='Income Statement'!BB35 -> -0.11551622 | C41: ='Income Statement'!BC35 -> 0.047225187 | D41: ='Income Statement'!BD35 -> -0.023057325 | E41: ='Income Statement'!BE35 -> 0.081888121 | F41: ='Income Statement'!BF35 -> -0.10654453 | G41: ='Income Statement'!BG35 -> 0.0041818427 | H41: ='Income Statement'!BH35 -> 0.013970983 | I41: ='Income Statement'!BI35 -> 0.053789083 | ... Q41: ='Income Statement'!BQ35 -> 0.054548545
A42: Google Other | B42: ='Income Statement'!BB42 -> -0.15723056 | C42: ='Income Statement'!BC42 -> 0.098340753 | D42: ='Income Statement'!BD42 -> 0.024195529 | E42: ='Income Statement'!BE42 -> 0.29439981 | F42: ='Income Statement'!BF42 -> -0.19038355 | G42: ='Income Statement'!BG42 -> 0.065568143 | H42: ='Income Statement'!BH42 -> 0.1443299 | I42: ='Income Statement'!BI42 -> 0.091685435 | ... Q42: ='Income Statement'!BQ42 -> 0.06774528
A43: Google Cloud | B43: ='Income Statement'!BB48 -> 0.019002051 | C43: ='Income Statement'!BC48 -> 0.077408103 | D43: ='Income Statement'!BD48 -> 0.047316648 | E43: ='Income Statement'!BE48 -> 0.092854595 | F43: ='Income Statement'!BF48 -> 0.041557876 | G43: ='Income Statement'!BG48 -> 0.080739503 | H43: ='Income Statement'!BH48 -> 0.097226249 | I43: ='Income Statement'!BI48 -> 0.053025632 | ... Q43: ='Income Statement'!BQ48 -> 0.037821677
A44: Other Bets | B44: ='Income Statement'!BB54 -> 0.27433628 | C44: ='Income Statement'!BC54 -> -0.010416667 | D44: ='Income Statement'!BD54 -> 0.042105263 | E44: ='Income Statement'!BE54 -> 1.2121212 | F44: ='Income Statement'!BF54 -> -0.24657534 | G44: ='Income Statement'!BG54 -> -0.26262626 | H44: ='Income Statement'!BH54 -> 0.063013699 | I44: ='Income Statement'!BI54 -> 0.030927835 | ... Q44: ='Income Statement'!BQ54 -> 0.22093023
A45: Total TAC | B45: ='Income Statement'!BB69 -> -0.093152805 | C45: ='Income Statement'!BC69 -> 0.069618633 | D45: ='Income Statement'!BD69 -> 0.0083752094 | E45: ='Income Statement'!BE69 -> 0.10631229 | F45: ='Income Statement'!BF69 -> -0.074360074 | G45: ='Income Statement'!BG69 -> 0.034064576 | H45: ='Income Statement'!BH69 -> 0.024800179 | I45: ='Income Statement'!BI69 -> 0.082294628 | ... Q45: ='Income Statement'!BQ69 -> 0.094116041
...

Sheet NTM Valuation
B3: Last Reported Quarter | C3: 3Q25
B4: NTM | C4: =OFFSET('Income Statement'!A1,0,MATCH('NTM Valuation'!C3,'Income Statement'!1:1,0)+3) -> 3Q26E
B5: NTM Diluted Shares (mm) | C5: =HLOOKUP($C$4,'Shares Outstanding & Corporate'!A1:CC26,ROW('Shares Outstanding & Corporate'!A9),FALSE) -> 12087.925
B6: NTM Net Debt (Cash) | C6: =HLOOKUP(C4,'Balance Sheet'!A1:CC51,ROW('Balance Sheet'!A51),FALSE) -> -72036.651
C8: =+D8-1 -> -4 | D8: =+E8-1 -> -3 | E8: =+F8-1 -> -2 | F8: -1 | H8: 0 | J8: 1 | K8: =+J8+1 -> 2 | L8: =+K8+1 -> 3 | M8: =+L8+1 -> 4 | O8: =+M8+1 -> 5 | P8: =+O8+1 -> 6 | Q8: =+P8+1 -> 7 | R8: =+Q8+1 -> 8 | T8: =+R8+1 -> 9 | U8: =+T8+1 -> 10 | V8: =+U8+1 -> 11 | W8: =+V8+1 -> 12 | Y8: =+W8+1 -> 13 | Z8: =+Y8+1 -> 14 | AA8: =+Z8+1 -> 15 | AB8: =+AA8+1 -> 16 | AD8: =+AB8+1 -> 17 | AE8: =+AD8+1 -> 18 | AF8: =+AE8+1 -> 19 | AG8: =+AF8+1 -> 20
C10: LTM | H10: Current | J10: NTM | O10: NTM +1 | T10: NTM +2 | Y10: NTM + 3 | AD10: NTM +4
C11: =CONCATENATE(IF(LEFT(C12,2)="4Q","12/31",IF(LEFT(C12,2)="1Q","3/31",IF(LEFT(C12,2)="2Q","6/30","9/30"))),"/",MID(C12,3,3)) -> 9/30/24 | D11: =CONCATENATE(IF(LEFT(D12,2)="4Q","12/31",IF(LEFT(D12,2)="1Q","3/31",IF(LEFT(D12,2)="2Q","6/30","9/30"))),"/",MID(D12,3,3)) -> 12/31/24 | E11: =CONCATENATE(IF(LEFT(E12,2)="4Q","12/31",IF(LEFT(E12,2)="1Q","3/31",IF(LEFT(E12,2)="2Q","6/30","9/30"))),"/",MID(E12,3,3)) -> 3/31/25 | F11: =CONCATENATE(IF(LEFT(F12,2)="4Q","12/31",IF(LEFT(F12,2)="1Q","3/31",IF(LEFT(F12,2)="2Q","6/30","9/30"))),"/",MID(F12,3,3)) -> 6/30/25 | H11: =CONCATENATE(IF(LEFT(H12,2)="4Q","12/31",IF(LEFT(H12,2)="1Q","3/31",IF(LEFT(H12,2)="2Q","6/30","9/30"))),"/",MID(H12,3,3)) -> 9/30/25 | J11: =CONCATENATE(IF(LEFT(J12,2)="4Q","12/31",IF(LEFT(J12,2)="1Q","3/31",IF(LEFT(J12,2)="2Q","6/30","9/30"))),"/",MID(J12,3,3)) -> 12/31/25E | K11: =CONCATENATE(IF(LEFT(K12,2)="4Q","12/31",IF(LEFT(K12,2)="1Q","3/31",IF(LEFT(K12,2)="2Q","6/30","9/30"))),"/",MID(K12,3,3)) -> 3/31/26E | L11: =CONCATENATE(IF(LEFT(L12,2)="4Q","12/31",IF(LEFT(L12,2)="1Q","3/31",IF(LEFT(L12,2)="2Q","6/30","9/30"))),"/",MID(L12,3,3)) -> 6/30/26E | M11: =CONCATENATE(IF(LEFT(M12,2)="4Q","12/31",IF(LEFT(M12,2)="1Q","3/31",IF(LEFT(M12,2)="2Q","6/30","9/30"))),"/",MID(M12,3,3)) -> 9/30/26E | O11: =CONCATENATE(IF(LEFT(O12,2)="4Q","12/31",IF(LEFT(O12,2)="1Q","3/31",IF(LEFT(O12,2)="2Q","6/30","9/30"))),"/",MID(O12,3,3)) -> 12/31/26E | P11: =CONCATENATE(IF(LEFT(P12,2)="4Q","12/31",IF(LEFT(P12,2)="1Q","3/31",IF(LEFT(P12,2)="2Q","6/30","9/30"))),"/",MID(P12,3,3)) -> 3/31/27E | Q11: =CONCATENATE(IF(LEFT(Q12,2)="4Q","12/31",IF(LEFT(Q12,2)="1Q","3/31",IF(LEFT(Q12,2)="2Q","6/30","9/30"))),"/",MID(Q12,3,3)) -> 6/30/27E | R11: =CONCATENATE(IF(LEFT(R12,2)="4Q","12/31",IF(LEFT(R12,2)="1Q","3/31",IF(LEFT(R12,2)="2Q","6/30","9/30"))),"/",MID(R12,3,3)) -> 9/30/27E | T11: =CONCATENATE(IF(LEFT(T12,2)="4Q","12/31",IF(LEFT(T12,2)="1Q","3/31",IF(LEFT(T12,2)="2Q","6/30","9/30"))),"/",MID(T12,3,3)) -> 12/31/27E | U11: =CONCATENATE(IF(LEFT(U12,2)="4Q","12/31",IF(LEFT(U12,2)="1Q","3/31",IF(LEFT(U12,2)="2Q","6/30","9/30"))),"/",MID(U12,3,3)) -> 3/31/28E | V11: =CONCATENATE(IF(LEFT(V12,2)="4Q","12/31",IF(LEFT(V12,2)="1Q","3/31",IF(LEFT(V12,2)="2Q","6/30","9/30"))),"/",MID(V12,3,3)) -> 6/30/28E | W11: =CONCATENATE(IF(LEFT(W12,2)="4Q","12/31",IF(LEFT(W12,2)="1Q","3/31",IF(LEFT(W12,2)="2Q","6/30","9/30"))),"/",MID(W12,3,3)) -> 9/30/28E | Y11: =CONCATENATE(IF(LEFT(Y12,2)="4Q","12/31",IF(LEFT(Y12,2)="1Q","3/31",IF(LEFT(Y12,2)="2Q","6/30","9/30"))),"/",MID(Y12,3,3)) -> 12/31/28E | Z11: =CONCATENATE(IF(LEFT(Z12,2)="4Q","12/31",IF(LEFT(Z12,2)="1Q","3/31",IF(LEFT(Z12,2)="2Q","6/30","9/30"))),"/",MID(Z12,3,3)) -> 3/31/29E | AA11: =CONCATENATE(IF(LEFT(AA12,2)="4Q","12/31",IF(LEFT(AA12,2)="1Q","3/31",IF(LEFT(AA12,2)="2Q","6/30","9/30"))),"/",MID(AA12,3,3)) -> 6/30/29E | AB11: =CONCATENATE(IF(LEFT(AB12,2)="4Q","12/31",IF(LEFT(AB12,2)="1Q","3/31",IF(LEFT(AB12,2)="2Q","6/30","9/30"))),"/",MID(AB12,3,3)) -> 9/30/29E | AD11: =CONCATENATE(IF(LEFT(AD12,2)="4Q","12/31",IF(LEFT(AD12,2)="1Q","3/31",IF(LEFT(AD12,2)="2Q","6/30","9/30"))),"/",MID(AD12,3,3)) -> 12/31/29E | AE11: =CONCATENATE(IF(LEFT(AE12,2)="4Q","12/31",IF(LEFT(AE12,2)="1Q","3/31",IF(LEFT(AE12,2)="2Q","6/30","9/30"))),"/",MID(AE12,3,3)) -> 3/31/30E | AF11: =CONCATENATE(IF(LEFT(AF12,2)="4Q","12/31",IF(LEFT(AF12,2)="1Q","3/31",IF(LEFT(AF12,2)="2Q","6/30","9/30"))),"/",MID(AF12,3,3)) -> 6/30/30E | AG11: =CONCATENATE(IF(LEFT(AG12,2)="4Q","12/31",IF(LEFT(AG12,2)="1Q","3/31",IF(LEFT(AG12,2)="2Q","6/30","9/30"))),"/",MID(AG12,3,3)) -> 9/30/30E
C12: =OFFSET('Income Statement'!$A1,0,MATCH('NTM Valuation'!$C3,'Income Statement'!1:1,0)+C8-1) -> 3Q24 | D12: =OFFSET('Income Statement'!$A1,0,MATCH('NTM Valuation'!$C3,'Income Statement'!1:1,0)+D8-1) -> 4Q24 | E12: =OFFSET('Income Statement'!$A1,0,MATCH('NTM Valuation'!$C3,'Income Statement'!1:1,0)+E8-1) -> 1Q25 | F12: =OFFSET('Income Statement'!$A1,0,MATCH('NTM Valuation'!$C3,'Income Statement'!1:1,0)+F8-1) -> 2Q25 | H12: =OFFSET('Income Statement'!$A1,0,MATCH('NTM Valuation'!$C3,'Income Statement'!1:1,0)+H8-1) -> 3Q25 | J12: =OFFSET('Income Statement'!$A1,0,MATCH('NTM Valuation'!$C3,'Income Statement'!1:1,0)+J8-1) -> 4Q25E | K12: =OFFSET('Income Statement'!$A1,0,MATCH('NTM Valuation'!$C3,'Income Statement'!1:1,0)+K8-1) -> 1Q26E | L12: =OFFSET('Income Statement'!$A1,0,MATCH('NTM Valuation'!$C3,'Income Statement'!1:1,0)+L8-1) -> 2Q26E | M12: =OFFSET('Income Statement'!$A1,0,MATCH('NTM Valuation'!$C3,'Income Statement'!1:1,0)+M8-1) -> 3Q26E | O12: =OFFSET('Income Statement'!$A1,0,MATCH('NTM Valuation'!$C3,'Income Statement'!1:1,0)+O8-1) -> 4Q26E | P12: =OFFSET('Income Statement'!$A1,0,MATCH('NTM Valuation'!$C3,'Income Statement'!1:1,0)+P8-1) -> 1Q27E | Q12: =OFFSET('Income Statement'!$A1,0,MATCH('NTM Valuation'!$C3,'Income Statement'!1:1,0)+Q8-1) -> 2Q27E | R12: =OFFSET('Income Statement'!$A1,0,MATCH('NTM Valuation'!$C3,'Income Statement'!1:1,0)+R8-1) -> 3Q27E | T12: =OFFSET('Income Statement'!$A1,0,MATCH('NTM Valuation'!$C3,'Income Statement'!1:1,0)+T8-1) -> 4Q27E | U12: =OFFSET('Income Statement'!$A1,0,MATCH('NTM Valuation'!$C3,'Income Statement'!1:1,0)+U8-1) -> 1Q28E | V12: =OFFSET('Income Statement'!$A1,0,MATCH('NTM Valuation'!$C3,'Income Statement'!1:1,0)+V8-1) -> 2Q28E | W12: =OFFSET('Income Statement'!$A1,0,MATCH('NTM Valuation'!$C3,'Income Statement'!1:1,0)+W8-1) -> 3Q28E | Y12: =OFFSET('Income Statement'!$A1,0,MATCH('NTM Valuation'!$C3,'Income Statement'!1:1,0)+Y8-1) -> 4Q28E | Z12: =OFFSET('Income Statement'!$A1,0,MATCH('NTM Valuation'!$C3,'Income Statement'!1:1,0)+Z8-1) -> 1Q29E | AA12: =OFFSET('Income Statement'!$A1,0,MATCH('NTM Valuation'!$C3,'Income Statement'!1:1,0)+AA8-1) -> 2Q29E | AB12: =OFFSET('Income Statement'!$A1,0,MATCH('NTM Valuation'!$C3,'Income Statement'!1:1,0)+AB8-1) -> 3Q29E | AD12: =OFFSET('Income Statement'!$A1,0,MATCH('NTM Valuation'!$C3,'Income Statement'!1:1,0)+AD8-1) -> 4Q29E | AE12: =OFFSET('Income Statement'!$A1,0,MATCH('NTM Valuation'!$C3,'Income Statement'!1:1,0)+AE8-1) -> 1Q30E | AF12: =OFFSET('Income Statement'!$A1,0,MATCH('NTM Valuation'!$C3,'Income Statement'!1:1,0)+AF8-1) -> 2Q30E | AG12: =OFFSET('Income Statement'!$A1,0,MATCH('NTM Valuation'!$C3,'Income Statement'!1:1,0)+AG8-1) -> 3Q30E
B14: Sales | C14: =+HLOOKUP(C$12,'Income Statement'!$A$1:CH85,ROW('Income Statement'!$A85),FALSE) -> 74549 | D14: =+HLOOKUP(D$12,'Income Statement'!$A$1:CH85,ROW('Income Statement'!$A85),FALSE) -> 81621 | E14: =+HLOOKUP(E$12,'Income Statement'!$A$1:CH85,ROW('Income Statement'!$A85),FALSE) -> 76486 | F14: =+HLOOKUP(F$12,'Income Statement'!$A$1:CH85,ROW('Income Statement'!$A85),FALSE) -> 81723 | H14: =+HLOOKUP(H$12,'Income Statement'!$A$1:CH85,ROW('Income Statement'!$A85),FALSE) -> 87470 | J14: =+HLOOKUP(J$12,'Income Statement'!$A$1:CH85,ROW('Income Statement'!$A85),FALSE) -> 95515.296 | K14: =+HLOOKUP(K$12,'Income Statement'!$A$1:CH85,ROW('Income Statement'!$A85),FALSE) -> 89042.104 | L14: =+HLOOKUP(L$12,'Income Statement'!$A$1:CH85,ROW('Income Statement'!$A85),FALSE) -> 94341.454 | M14: =+HLOOKUP(M$12,'Income Statement'!$A$1:CH85,ROW('Income Statement'!$A85),FALSE) -> 100285.27 | O14: =+HLOOKUP(O$12,'Income Statement'!$A$1:CH85,ROW('Income Statement'!$A85),FALSE) -> 108253.18 | P14: =+HLOOKUP(P$12,'Income Statement'!$A$1:CH85,ROW('Income Statement'!$A85),FALSE) -> 101958.57 | Q14: =+HLOOKUP(Q$12,'Income Statement'!$A$1:CH85,ROW('Income Statement'!$A85),FALSE) -> 107600.44 | R14: =+HLOOKUP(R$12,'Income Statement'!$A$1:CH85,ROW('Income Statement'!$A85),FALSE) -> 114525.07 | T14: =+HLOOKUP(T$12,'Income Statement'!$A$1:CH85,ROW('Income Statement'!$A85),FALSE) -> 123228.19 | U14: =+HLOOKUP(U$12,'Income Statement'!$A$1:CH85,ROW('Income Statement'!$A85),FALSE) -> 116051.45 | V14: =+HLOOKUP(V$12,'Income Statement'!$A$1:CH85,ROW('Income Statement'!$A85),FALSE) -> 122012.27 | W14: =+HLOOKUP(W$12,'Income Statement'!$A$1:CH85,ROW('Income Statement'!$A85),FALSE) -> 130037.9 | Y14: =+HLOOKUP(Y$12,'Income Statement'!$A$1:CH85,ROW('Income Statement'!$A85),FALSE) -> 139488.54 | Z14: =+HLOOKUP(Z$12,'Income Statement'!$A$1:CH85,ROW('Income Statement'!$A85),FALSE) -> 130920.79 | AA14: =+HLOOKUP(AA$12,'Income Statement'!$A$1:CH85,ROW('Income Statement'!$A85),FALSE) -> 137151.82 | AB14: =+HLOOKUP(AB$12,'Income Statement'!$A$1:CH85,ROW('Income Statement'!$A85),FALSE) -> 146353.52 | AD14: =+HLOOKUP(AD$12,'Income Statement'!$A$1:CH85,ROW('Income Statement'!$A85),FALSE) -> 156533.25 | AE14: =+HLOOKUP(AE$12,'Income Statement'!$A$1:CH85,ROW('Income Statement'!$A85),FALSE) -> 146375.81 | AF14: =+HLOOKUP(AF$12,'Income Statement'!$A$1:CH85,ROW('Income Statement'!$A85),FALSE) -> 152817.15 | AG14: =+HLOOKUP(AG$12,'Income Statement'!$A$1:CH85,ROW('Income Statement'!$A85),FALSE) -> 163252.15
B15: YoY Growth | M15: =+SUM(J14:M14)/SUM(C14:F14)-1 -> 0.20613693 | R15: =+SUM(O14:R14)/SUM(J14:M14)-1 -> 0.14017766 | W15: =+SUM(T14:W14)/SUM(O14:R14)-1 -> 0.13645031 | AB15: =+SUM(Y14:AB14)/SUM(T14:W14)-1 -> 0.12737851 | AG15: =+SUM(AD14:AG14)/SUM(Y14:AB14)-1 -> 0.11746157
B19: Gross Profit | C19: =+HLOOKUP(C$12,'Income Statement'!$A$1:CH172,ROW('Income Statement'!A172),FALSE) -> 51794 | D19: =+HLOOKUP(D$12,'Income Statement'!$A$1:CH172,ROW('Income Statement'!B172),FALSE) -> 55856 | E19: =+HLOOKUP(E$12,'Income Statement'!$A$1:CH172,ROW('Income Statement'!C172),FALSE) -> 53873 | F19: =+HLOOKUP(F$12,'Income Statement'!$A$1:CH172,ROW('Income Statement'!D172),FALSE) -> 57389 | H19: =+HLOOKUP(H$12,'Income Statement'!$A$1:CH172,ROW('Income Statement'!F172),FALSE) -> 60977 | J19: =+HLOOKUP(J$12,'Income Statement'!$A$1:CH172,ROW('Income Statement'!H172),FALSE) -> 64409.182 | K19: =+HLOOKUP(K$12,'Income Statement'!$A$1:CH172,ROW('Income Statement'!I172),FALSE) -> 61603.879 | L19: =+HLOOKUP(L$12,'Income Statement'!$A$1:CH172,ROW('Income Statement'!J172),FALSE) -> 65070.89 | M19: =+HLOOKUP(M$12,'Income Statement'!$A$1:CH172,ROW('Income Statement'!K172),FALSE) -> 68657.201 | O19: =+HLOOKUP(O$12,'Income Statement'!$A$1:CH172,ROW('Income Statement'!M172),FALSE) -> 71645.602 | P19: =+HLOOKUP(P$12,'Income Statement'!$A$1:CH172,ROW('Income Statement'!N172),FALSE) -> 69520.567 | Q19: =+HLOOKUP(Q$12,'Income Statement'!$A$1:CH172,ROW('Income Statement'!O172),FALSE) -> 73140.113 | R19: =+HLOOKUP(R$12,'Income Statement'!$A$1:CH172,ROW('Income Statement'!P172),FALSE) -> 77260.791 | T19: =+HLOOKUP(T$12,'Income Statement'!$A$1:CH172,ROW('Income Statement'!R172),FALSE) -> 80324.286 | U19: =+HLOOKUP(U$12,'Income Statement'!$A$1:CH172,ROW('Income Statement'!S172),FALSE) -> 78259.427 | V19: =+HLOOKUP(V$12,'Income Statement'!$A$1:CH172,ROW('Income Statement'!T172),FALSE) -> 82021.292 | W19: =+HLOOKUP(W$12,'Income Statement'!$A$1:CH172,ROW('Income Statement'!U172),FALSE) -> 86750.757 | Y19: =+HLOOKUP(Y$12,'Income Statement'!$A$1:CH172,ROW('Income Statement'!W172),FALSE) -> 89877.168 | Z19: =+HLOOKUP(Z$12,'Income Statement'!$A$1:CH172,ROW('Income Statement'!X172),FALSE) -> 87828.359 | AA19: =+HLOOKUP(AA$12,'Income Statement'!$A$1:CH172,ROW('Income Statement'!Y172),FALSE) -> 91718.639 | AB19: =+HLOOKUP(AB$12,'Income Statement'!$A$1:CH172,ROW('Income Statement'!Z172),FALSE) -> 97122.981 | AD19: =+HLOOKUP(AD$12,'Income Statement'!$A$1:CH172,ROW('Income Statement'!AB172),FALSE) -> 100311.78 | AE19: =+HLOOKUP(AE$12,'Income Statement'!$A$1:CH172,ROW('Income Statement'!AC172),FALSE) -> 97830.44 | AF19: =+HLOOKUP(AF$12,'Income Statement'!$A$1:CH172,ROW('Income Statement'!AD172),FALSE) -> 101812.6 | AG19: =+HLOOKUP(AG$12,'Income Statement'!$A$1:CH172,ROW('Income Statement'!AE172),FALSE) -> 107929.1
M20: =+SUM(J19:M19)/SUM(C19:F19)-1 -> 0.18650943 | R20: =+SUM(O19:R19)/SUM(J19:M19)-1 -> 0.12252937 | W20: =+SUM(T19:W19)/SUM(O19:R19)-1 -> 0.12274599 | AB20: =+SUM(Y19:AB19)/SUM(T19:W19)-1 -> 0.11972108 | AG20: =+SUM(AD19:AG19)/SUM(Y19:AB19)-1 -> 0.11277341
