Workbook
Name circ: vDIA!$T$10
Name IQ_CH: 110000
Name IQ_CQ: 5000
Name IQ_CY: 10000
Name IQ_DAILY: 500000
Name IQ_EXPENSE_CODE_: "NB12825"
Name IQ_FH: 100000
Name IQ_FQ: 500
Name IQ_FY: 1000
Name IQ_LTM: 2000
Name IQ_MONTH: 15000
Name IQ_NTM: 6000
Name IQ_WEEK: 50000
Name IQ_YTD: 3000
Name tax: #REF!

Sheet Financials
B2: Bolthouse Farms Financial Summary
B3: ($ millions, FYE March 31st)
C5: Historical | F5: Budget | G5: Projected
C6: 2003 | D6: 2004 | E6: 2005 | F6: 2006 | G6: 2007 | H6: 2008 | I6: 2009 | J6: 2010 | K6: 2011
B7: Revenue:
B8: Cut & Peel | C8: 211.9 | D8: 217 | E8: 207.5 | F8: 231.2 | G8: 254 | H8: 269.2 | I8: 282.7 | J8: 291.1 | K8: 299.74959
B9: Organic | C9: 19 | D9: 20.9 | E9: 26.5 | F9: 40.6 | G9: 51.4 | H9: 57.8 | I9: 64.7 | J9: 71.1 | K9: 78.133076
B10: Beverage | C10: 0.1 | D10: 7.4 | E10: 37.8 | F10: 88 | G10: 169.6 | H10: 219.6 | I10: 270.8 | J10: 321.4 | K10: 381.4548
B11: Other | C11: 98.8 | D11: 106.3 | E11: 123.3 | F11: 126.4 | G11: 133.1 | H11: 136.1 | I11: 139.5 | J11: 144.1 | K11: 148.85168
B12: Total Revenue | C12: 329.8 | D12: 351.6 | E12: 395.1 | F12: 486.2 | G12: 608.1 | H12: 682.7 | I12: 757.7 | J12: 827.7 | K12: 908.18915
B14: Gross Profit:
B15: Cut & Peel | C15: 72.4 | D15: 76.3 | E15: 61 | F15: 70.3 | G15: 78.2 | H15: 83.4 | I15: 87.6 | J15: 90.3 | K15: 92.983127
B16: Organic | C16: 6 | D16: 6.9 | E16: 8.2 | F16: 12.7 | G16: 16.2 | H16: 18.3 | I16: 20.6 | J16: 22.6 | K16: 24.835549
B17: Beverage | C17: -1.5 | D17: -4.1 | E17: 6.3 | F17: 33.3 | G17: 57.6 | H17: 75.5 | I17: 97.2 | J17: 122.1 | K17: 144.91484
B18: Other | C18: 13 | D18: 6.7 | E18: 10.2 | F18: 14.8 | G18: 20.3 | H18: 22.7 | I18: 25.6 | J18: 29 | K18: 29.956272
B19: Gross Profit | C19: 89.9 | D19: 85.8 | E19: 85.7 | F19: 131.1 | G19: 172.3 | H19: 199.9 | I19: 231 | J19: 264 | K19: 292.68979
B21: Operating Expenses | C21: 24 | D21: 27.3 | E21: 28 | F21: 35.9 | G21: 41.4 | H21: 44.9 | I21: 48.8 | J21: 53.1 | K21: 61.280958
B23: EBIT | C23: 65.9 | D23: 58.5 | E23: 57.7 | F23: 95.2 | G23: 130.9 | H23: 155 | I23: 182.2 | J23: 210.9 | K23: 231.40883
B25: Plus: D&A | C25: 28 | D25: 34.7 | E25: 32.6 | F25: 30.9 | G25: 38.8 | H25: 43.7 | I25: 48.4 | J25: 52.7 | K25: 57.824778
B27: EBITDA | C27: 93.9 | D27: 93.2 | E27: 90.3 | F27: 126.1 | G27: 169.7 | H27: 198.7 | I27: 230.6 | J27: 263.6 | K27: 289.23361
B29: Clean SG&A | C29: =+C21-C25 -> -4 | D29: =+D21-D25 -> -7.4 | E29: =+E21-E25 -> -4.6 | F29: =+F21-F25 -> 5 | G29: =+G21-G25 -> 2.6 | H29: =+H21-H25 -> 1.2 | I29: =+I21-I25 -> 0.4 | J29: =+J21-J25 -> 0.4 | K29: =+K21-K25 -> 3.4561805
B32: Capital Expenditures
B33: Maintenance | C33: 5.9 | D33: 4.9 | E33: 5.3 | F33: 8.4 | G33: 6.5 | H33: 6.5 | I33: 6.5 | J33: 6.5 | K33: 6.5
B34: Expansion | C34: 51.8 | D34: 30.5 | E34: 42.2 | F34: 109 | G34: 20.5 | H34: 23.5 | I34: 8.5 | J34: 8.5 | K34: 8.5
B35: Total Capital Expenditures | C35: 57.7 | D35: 35.4 | E35: 47.5 | F35: 117.4 | G35: 27 | H35: 30 | I35: 15 | J35: 15 | K35: 15
C37: Historical | F37: Budget
C38: 2003 | D38: 2004 | E38: 2005 | F38: 2006
B39: Assets:
B40: Cash | D40: 4.4 | E40: 3 | F40: 0
B41: Accounts Receivable | D41: 33.1 | E41: 38.6 | F41: 47.500177
B42: Inventory | D42: 45.8 | E42: 56.3 | F42: 69.281346
B43: Prepayments and Other Current Assets | D43: 6.5 | E43: 7.4 | F43: 9.1062516
B44: Total Current Assets | D44: 89.8 | E44: 105.3 | F44: 125.88778
B45: PP&E | D45: 232.7 | E45: 238.1 | F45: 324.6
B46: Other | D46: 9.1 | E46: 16.9 | F46: 20.79671
B47: Total Assets | D47: 331.6 | E47: 360.3 | F47: 471.28448
B49: Liabilities and Shareholder Equity
B50: Accounts Payable | D50: 17.3 | E50: 26.3 | F50: 30.184648
B51: Other Current Liabilities | D51: 12.2 | E51: 18.8 | F51: 23.134801
B52: Total Current Liabilities | D52: 29.5 | E52: 45.1 | F52: 53.319449
...

Sheet vDIA
A1: in USDm unless otherwise stated
A3: x | B3: Txn assumptions
B5: Financing | C5: xEBITDA | D5: Floor | E5: Margin | F5: Interest rate | G5: Term | H5: Amort' | I5: Fee
B6: TLB | C6: 3 | D6: 0.03 | E6: 0.05 | F6: =+E6+D6 -> 0.08 | G6: 8 | H6: =+G6 -> 8 | I6: 0.04
B7: Snr sub | C7: 1.5 | F7: 0.1 | I7: 0.05
B9: Deal parameters | G9: S&U | L9: Purchase accounting | Q9: Switches
B10: FY26 EBITDA | E10: =+I44 -> 126.1 | G10: TLB | J10: =+C6*$I$44 -> 378.3 | L10: Purchase price | O10: =+J15 -> 947.93944 | Q10: Circularity | T10: 1
B11: Entry multiple | E11: 8 | G11: Snr sub | J11: =+C7*$I$44 -> 189.15 | L11: (-) net identifieable assets | O11: =+I70 -> 336.8 | Q11: Snr sub sweep | T11: 1
B12: Entry EV | E12: =+E11*E10 -> 1008.8 | G12: Sponsor equity | J12: =+J13-J11-J10 -> 465.9395 | L12: Goodwill | O12: =+O10-O11 -> 611.13944
G13: Total sources | J13: =+J18 -> 1033.3895
B14: (-) net debt | E14: =+I66-I50 -> 60.860556 | L14: Other assumptions
B15: Purchase EqV | E15: =+E12-E14 -> 947.93944 | G15: Purchase equity | J15: =+E15 -> 947.93944 | L15: Amort of DFF | O15: 5
G16: Refi debt | J16: =+I66 -> 60.860556 | L16: MIP | O16: 0.1
G17: Financing fees | J17: =+I6*J10+J11*I7 -> 24.5895 | L17: Tax | O17: 0.37
G18: Total uses | J18: =SUM(J15:J17) -> 1033.3895 | L18: Exit multiple | O18: 7
F20: Historical | G20: Historical | H20: Historical | I20: Budget | L20: Projected | M20: Projected | N20: Projected | O20: Projected | P20: Projected
A21: x | B21: P&L | F21: 2003 | G21: =+F21+1 -> 2004 | H21: =+G21+1 -> 2005 | I21: =+H21+1 -> 2006 | L21: =+I21+1 -> 2007 | M21: =+L21+1 -> 2008 | N21: =+M21+1 -> 2009 | O21: =+N21+1 -> 2010 | P21: =+O21+1 -> 2011
B22: Revenue | F22: =+Financials!C12 -> 329.8 | G22: =+Financials!D12 -> 351.6 | H22: =+Financials!E12 -> 395.1 | I22: =+Financials!F12 -> 486.2 | L22: =+Financials!G12 -> 608.1 | M22: =+Financials!H12 -> 682.7 | N22: =+Financials!I12 -> 757.7 | O22: =+Financials!J12 -> 827.7 | P22: =+Financials!K12 -> 908.18915
B23: % YoY
B25: Gross profit | F25: =+Financials!C19 -> 89.9 | G25: =+Financials!D19 -> 85.8 | H25: =+Financials!E19 -> 85.7 | I25: =+Financials!F19 -> 131.1 | L25: =+Financials!G19 -> 172.3 | M25: =+Financials!H19 -> 199.9 | N25: =+Financials!I19 -> 231 | O25: =+Financials!J19 -> 264 | P25: =+Financials!K19 -> 292.68979
B26: % margin | F26: =+F25/F22 -> 0.27258945 | G26: =+G25/G22 -> 0.2440273 | H26: =+H25/H22 -> 0.21690711 | I26: =+I25/I22 -> 0.26964212 | L26: =+L25/L22 -> 0.28334156 | M26: =+M25/M22 -> 0.29280797 | N26: =+N25/N22 -> 0.30487 | O26: =+O25/O22 -> 0.31895614 | P26: =+P25/P22 -> 0.32227845
B28: Opex | F28: =+Financials!C21*-1 -> -24 | G28: =+Financials!D21*-1 -> -27.3 | H28: =+Financials!E21*-1 -> -28 | I28: =+Financials!F21*-1 -> -35.9 | L28: =+Financials!G21*-1 -> -41.4 | M28: =+Financials!H21*-1 -> -44.9 | N28: =+Financials!I21*-1 -> -48.8 | O28: =+Financials!J21*-1 -> -53.1 | P28: =+Financials!K21*-1 -> -61.280958
B30: EBIT | F30: =+F28+F25 -> 65.9 | G30: =+G28+G25 -> 58.5 | H30: =+H28+H25 -> 57.7 | I30: =+I28+I25 -> 95.2 | L30: =+L28+L25 -> 130.9 | M30: =+M28+M25 -> 155 | N30: =+N28+N25 -> 182.2 | O30: =+O28+O25 -> 210.9 | P30: =+P28+P25 -> 231.40883
B31: % margin | F31: =+F30/F22 -> 0.19981807 | G31: =+G30/G22 -> 0.16638225 | H31: =+H30/H22 -> 0.14603898 | I31: =+I30/I22 -> 0.1958042 | L31: =+L30/L22 -> 0.21526065 | M31: =+M30/M22 -> 0.2270397 | N31: =+N30/N22 -> 0.24046456 | O31: =+O30/O22 -> 0.25480246 | P31: =+P30/P22 -> 0.25480246
B33: Interest | L33: =+IF(circ=1, L107+L112, 0) -> -46.737906 | M33: =+IF(circ=1, M107+M112, 0) -> -40.452487 | N33: =+IF(circ=1, N107+N112, 0) -> -33.436081 | O33: =+IF(circ=1, O107+O112, 0) -> -30.264 | P33: =+IF(circ=1, P107+P112, 0) -> -30.264
B34: Amort DFF | L34: =+MIN($J$17/$O$15, $J$17+SUM($J$34:K34))*-1 -> -4.9179 | M34: =+MIN($J$17/$O$15, $J$17+SUM($J$34:L34))*-1 -> -4.9179 | N34: =+MIN($J$17/$O$15, $J$17+SUM($J$34:M34))*-1 -> -4.9179 | O34: =+MIN($J$17/$O$15, $J$17+SUM($J$34:N34))*-1 -> -4.9179 | P34: =+MIN($J$17/$O$15, $J$17+SUM($J$34:O34))*-1 -> -4.9179
B36: EBT | L36: =+L34+L33+L30 -> 79.244194 | M36: =+M34+M33+M30 -> 109.62961 | N36: =+N34+N33+N30 -> 143.84602 | O36: =+O34+O33+O30 -> 175.7181 | P36: =+P34+P33+P30 -> 196.22693
B38: Tax rate | L38: =+$O$17 -> 0.37 | M38: =+$O$17 -> 0.37 | N38: =+$O$17 -> 0.37 | O38: =+$O$17 -> 0.37 | P38: =+$O$17 -> 0.37
B40: Net income | L40: =+L36*(1-L38) -> 49.923842 | M40: =+M36*(1-M38) -> 69.066656 | N40: =+N36*(1-N38) -> 90.622992 | O40: =+O36*(1-O38) -> 110.7024 | P40: =+P36*(1-P38) -> 123.62297
B42: Memo
B43: D&A | F43: =+Financials!C25 -> 28 | G43: =+Financials!D25 -> 34.7 | H43: =+Financials!E25 -> 32.6 | I43: =+Financials!F25 -> 30.9 | L43: =+Financials!G25 -> 38.8 | M43: =+Financials!H25 -> 43.7 | N43: =+Financials!I25 -> 48.4 | O43: =+Financials!J25 -> 52.7 | P43: =+Financials!K25 -> 57.824778
B44: EBITDA | F44: =+F43+F30 -> 93.9 | G44: =+G43+G30 -> 93.2 | H44: =+H43+H30 -> 90.3 | I44: =+I43+I30 -> 126.1 | L44: =+L43+L30 -> 169.7 | M44: =+M43+M30 -> 198.7 | N44: =+N43+N30 -> 230.6 | O44: =+O43+O30 -> 263.6 | P44: =+P43+P30 -> 289.23361
B46: Capex | F46: =+Financials!C35 -> 57.7 | G46: =+Financials!D35 -> 35.4 | H46: =+Financials!E35 -> 47.5 | I46: =+Financials!F35 -> 117.4 | L46: =+Financials!G35 -> 27 | M46: =+Financials!H35 -> 30 | N46: =+Financials!I35 -> 15 | O46: =+Financials!J35 -> 15 | P46: =+Financials!K35 -> 15
I48: Budget | J48: Adj. | K48: PF | L48: Projected | M48: Projected | N48: Projected | O48: Projected | P48: Projected
A49: x | B49: BS | I49: 2006 | K49: 2006 | L49: =+I49+1 -> 2007 | M49: =+L49+1 -> 2008 | N49: =+M49+1 -> 2009 | O49: =+N49+1 -> 2010 | P49: =+O49+1 -> 2011
B50: =+Financials!B40 -> Cash | I50: =+Financials!F40 -> 0 | K50: =+I50+J50 -> 0 | L50: =+K50+L114 -> 0 | M50: =+L50+M114 -> 0 | N50: =+M50+N114 -> 54.793978 | O50: =+N50+O114 -> 198.30128 | P50: =+O50+P114 -> 357.96747
B51: =+Financials!B41 -> Accounts Receivable | I51: =+Financials!F41 -> 47.500177 | K51: =+I51+J51 -> 47.500177 | L51: =+L77/365*L22 -> 59.409415 | M51: =+M77/365*M22 -> 66.697596 | N51: =+N77/365*N22 -> 74.024854 | O51: =+O77/365*O22 -> 80.863629 | P51: =+P77/365*P22 -> 88.727161
B52: =+Financials!B42 -> Inventory | I52: =+Financials!F42 -> 69.281346 | K52: =+I52+J52 -> 69.281346 | L52: =+L78/365*(L22-L25) -> 85.02622 | M52: =+M78/365*(M22-M25) -> 94.196097 | N52: =+N78/365*(N22-N25) -> 102.76115 | O52: =+O78/365*(O22-O25) -> 109.97999 | P52: =+P78/365*(P22-P25) -> 120.08624
B53: =+Financials!B43 -> Prepayments and Other Current Assets | I53: =+Financials!F43 -> 9.1062516 | K53: =+I53+J53 -> 9.1062516 | L53: =+L79*L22 -> 11.38937 | M53: =+M79*M22 -> 12.786586 | N53: =+N79*N22 -> 14.191293 | O53: =+O79*O22 -> 15.502354 | P53: =+P79*P22 -> 17.00987
B54: Current assets | I54: =+I53+I52+I51+I50 -> 125.88778 | K54: =+K53+K52+K51+K50 -> 125.88778 | L54: =+L53+L52+L51+L50 -> 155.82501 | M54: =+M53+M52+M51+M50 -> 173.68028 | N54: =+N53+N52+N51+N50 -> 245.77128 | O54: =+O53+O52+O51+O50 -> 404.64725 | P54: =+P53+P52+P51+P50 -> 583.79075
...
