Workbook
Name IQ_CH: 110000
Name IQ_CQ: 5000
Name IQ_CY: 10000
Name IQ_DAILY: 500000
Name IQ_FH: 100000
Name IQ_FQ: 500
Name IQ_FY: 1000
Name IQ_LTM: 2000
Name IQ_MONTH: 15000
Name IQ_NTM: 6000
Name IQ_WEEK: 50000
Name IQ_YTD: 3000

Sheet 1. Business Assessment
C3: Q1: Business Assessment
D7: Recommendation
D8: Do NOT invest in this business on account of an unfavourable risk-reward:
D9: Low base case returns, extremely sensitive to changes in COGS spend and revenue/store. Bulk of returns driven by EBITDA growth, which will require a lot of conviction / potential portfolio management
D10: Cannot lever up much as a result
D11: Complete wipe-out of returns in a relatively mild downside case (e.g. not assuming a business collapse)
D12: Potential remedies include ability to enter at a more attractive valuation or new value creation levers to make the base case more compelling
D14: Strengths
D15: #1 net promoter score and brand warmth, increased traffic from Fresh Look marketing initiative
D16: 3rd lowest exposure to food delivery growth in spheres of influence among UK supermarkets
D17: Captive fuel revenues diversify revenue streams
D18: Low capital intensity (capex spend did not meaningfully increase despite store openings during COVID)
D19: Negative NWC business model is a source of cash as the business grows
... D56: Ability to structure an investment with more downside protection, e.g. 1x liq pref convertible preferred stock

Sheet 2. Operating Model
C3: Q2: Operating Model | H3: The below populated model serves as a template, but you can amend as you see fit (if needed) | W3: Operating case | Y3: 1 | Z3: (1) = Base Case; (2) = Downside Case
C7: Entry assumptions | I7: Sources | K7: £m | L7: xEBITDA | N7: Uses | R7: £m
C9: Undisturbed share price (£p) | F9: 175 | I9: Net debt at closing | K9: =L9*$J$107 -> 2824 | L9: 4 | N9: Cash consideration to shareholders | R9: =+F12 -> 5489.575
C10: Premium to current share price (%) | F10: 0.3 | I10: o/w acquisition financing | K10: =+K9+K11 -> 3074 | L10: =K10/$J$107 -> 4.3541076 | N10: Repay existing net debt | R10: =+F13 -> 1836
C11: Diluted TSO (m) | F11: 2413 | I11: o/w min cash | K11: 250 | L11: =K11/$J$107 -> 0.35410765 | N11: Transaction fees | R11: =+R12*F14 -> 73.25575
C12: Equity purchase price | F12: =+F9*(1+F10)*F11/100 -> 5489.575 | I12: Equity | K12: =$R$13-K9 -> 4574.8308 | L12: =K12/$J$107 -> 6.4799302 | N12: Memo: transaction fees as % of EV | R12: 0.01
C13: Plus: Net debt and debt-like items¹ | F13: =54+1986+36-240 -> 1836 | I13: Total Sources | K13: =+K9+K12 -> 7398.8308 | L13: =K13/$J$107 -> 10.47993 | N13: Total Uses | R13: =SUM(R9:R11) -> 7398.8308
C14: Enterprise Value ¹ | F14: =+F12+F13 -> 7325.575
C15: Implied EV / FY22 EBITDA | F15: =+F14/$K$107 -> 8.8520776 | I15: IRR | J15: =F205 -> 0.1371174
C16: Implied EV / FY21 EBITDA | F16: =+F14/$J$107 -> 10.376169 | I16: MOIC | J16: =F206 -> 1.9018639
C17: ¹ Excludes leases (EBITDA shown net of lease costs)
H18: Actuals | K18: ="Projections - "&CHOOSE($Y$3,C78,C79) -> Projections - Base Case | Q18: CAGR
C19: As of Jan, £m | H19: 43496 | I19: =EOMONTH(H19,12) -> 43861 | J19: =EOMONTH(I19,12) -> 44227 | K19: =EOMONTH(J19,12) -> 44592 | L19: =EOMONTH(K19,12) -> 44957 | M19: =EOMONTH(L19,12) -> 45322 | N19: =EOMONTH(M19,12) -> 45688 | O19: =EOMONTH(N19,12) -> 46053 | Q19: '19-'21 | R19: '21-'26
B21: x | C21: KPIs | U21: Step-up
C23: Total number of stores | H23: 494 | I23: 492 | J23: 497 | K23: =J23+K24 -> 501 | L23: =K23+L24 -> 506 | M23: =L23+M24 -> 512 | N23: =M23+N24 -> 519 | O23: =N23+O24 -> 527 | Q23: =IFERROR((J23/H23)^0.5-1,"n.a.") -> 0.0030318412 | R23: =IFERROR((O23/J23)^(1/5)-1,"n.a.") -> 0.011791078
C24: =+"Change in no. of stores: "&CHOOSE($Y$3,C25,C26) -> Change in no. of stores: Base Case | H24: n.a. | I24: =I23-H23 -> -2 | J24: =J23-I23 -> 5 | K24: =+CHOOSE($Y$3,K25,K26) -> 4 | L24: =+CHOOSE($Y$3,L25,L26) -> 5 | M24: =+CHOOSE($Y$3,M25,M26) -> 6 | N24: =+CHOOSE($Y$3,N25,N26) -> 7 | O24: =+CHOOSE($Y$3,O25,O26) -> 8
C25: Base Case | K25: =4+$U$25 -> 4 | L25: =K25+1 -> 5 | M25: =L25+1 -> 6 | N25: =M25+1 -> 7 | O25: =N25+1 -> 8 | U25: 0
C26: Downside Case | K26: 4 | L26: =L25-1 -> 4 | M26: =M25-1 -> 5 | N26: =N25-1 -> 6 | O26: =O25-1 -> 7
C28: Petrol filling stations | H28: 335 | I28: 335 | J28: 338 | K28: =J28+K29 -> 341 | L28: =K28+L29 -> 344 | M28: =L28+M29 -> 347 | N28: =M28+N29 -> 350 | O28: =N28+O29 -> 353 | Q28: =IFERROR((J28/H28)^0.5-1,"n.a.") -> 0.0044676321 | R28: =IFERROR((O28/J28)^(1/5)-1,"n.a.") -> 0.0087222514
C29: =+"Change in no. of stations: "&CHOOSE($Y$3,C30,C31) -> Change in no. of stations: Base Case | H29: n.a. | I29: =I28-H28 -> 0 | J29: =J28-I28 -> 3 | K29: =+CHOOSE($Y$3,K30,K31) -> 3 | L29: =+CHOOSE($Y$3,L30,L31) -> 3 | M29: =+CHOOSE($Y$3,M30,M31) -> 3 | N29: =+CHOOSE($Y$3,N30,N31) -> 3 | O29: =+CHOOSE($Y$3,O30,O31) -> 3
C30: Base Case | K30: 3 | L30: 3 | M30: 3 | N30: 3 | O30: 3
C31: Downside Case | K31: =K30-1 -> 2 | L31: =L30-1 -> 2 | M31: =M30-1 -> 2 | N31: =N30-1 -> 2 | O31: =O30-1 -> 2
C33: Employees (FTE) | H33: 72120 | I33: 71263 | J33: 76991 | K33: =ROUND(+J33*(1+K34),0) -> 81927 | L33: =ROUND(+K33*(1+L34),0) -> 83391 | M33: =ROUND(+L33*(1+M34),0) -> 84613 | N33: =ROUND(+M33*(1+N34),0) -> 85567 | O33: =ROUND(+N33*(1+O34),0) -> 86226 | Q33: =IFERROR((J33/H33)^0.5-1,"n.a.") -> 0.033218375 | R33: =IFERROR((O33/J33)^(1/5)-1,"n.a.") -> 0.022915256
C34: =+"% growth: "&CHOOSE($Y$3,C35,C36) -> % growth: Base Case | I34: =IFERROR(I33/H33-1,"n.a.") -> -0.011882973 | J34: =IFERROR(J33/I33-1,"n.a.") -> 0.080378317 | K34: =+CHOOSE($Y$3,K35,K36) -> 0.064117607 | L34: =+CHOOSE($Y$3,L35,L36) -> 0.017864807 | M34: =+CHOOSE($Y$3,M35,M36) -> 0.014659158 | N34: =+CHOOSE($Y$3,N35,N36) -> 0.011271169 | O34: =+CHOOSE($Y$3,O35,O36) -> 0.0076972627
C35: Base Case | K35: =K74*0.6 -> 0.064117607 | L35: =L74*0.5 -> 0.017864807 | M35: =M74*0.4 -> 0.014659158 | N35: =N74*0.3 -> 0.011271169 | O35: =O74*0.2 -> 0.0076972627
C36: Downside Case | K36: =K74*0.3 -> 0.032058804 | L36: =L74*0.2 -> 0.0071459228 | M36: =M74*0.1 -> 0.0036647896 | N36: =M36 -> 0.0036647896 | O36: =N36 -> 0.0036647896
C38: % LfL revenue growth (excl. fuel) | H38: 0.048 | I38: -0.008 | J38: 0.086 | K38: =+CHOOSE($Y$3,K39,K40) -> 0 | L38: =+CHOOSE($Y$3,L39,L40) -> 0 | M38: =+CHOOSE($Y$3,M39,M40) -> 0 | N38: =+CHOOSE($Y$3,N39,N40) -> 0 | O38: =+CHOOSE($Y$3,O39,O40) -> 0
C39: Base Case
C40: Downside Case
C42: Revenue/Store | H42: =H67/H23 -> 28.279352 | I42: =I67/I23 -> 28.180894 | J42: =J67/J23 -> 30.392354 | K42: =+CHOOSE($Y$3,K43,K44) -> 31.392354 | L42: =+CHOOSE($Y$3,L43,L44) -> 32.392354 | M42: =+CHOOSE($Y$3,M43,M44) -> 33.392354 | N42: =+CHOOSE($Y$3,N43,N44) -> 34.392354 | O42: =+CHOOSE($Y$3,O43,O44) -> 35.392354
C43: Base Case | K43: =J42+1 -> 31.392354 | L43: =K43+1 -> 32.392354 | M43: =L43+1 -> 33.392354 | N43: =M43+1 -> 34.392354 | O43: =N43+1 -> 35.392354
C44: Downside Case | K44: =J42 -> 30.392354 | L44: =K44+0.25 -> 30.642354 | M44: =L44+0.25 -> 30.892354 | N44: =M44+0.25 -> 31.142354 | O44: =N44+0.25 -> 31.392354
C46: Revenue/Petrol Station | H46: =H70/H28 -> 11.238806 | I46: =I70/I28 -> 10.958209 | J46: =J70/J28 -> 7.3757396 | K46: =+CHOOSE($Y$3,K47,K48) -> 11 | L46: =+CHOOSE($Y$3,L47,L48) -> 11 | M46: =+CHOOSE($Y$3,M47,M48) -> 11 | N46: =+CHOOSE($Y$3,N47,N48) -> 11 | O46: =+CHOOSE($Y$3,O47,O48) -> 11
C47: Base Case | K47: 11 | L47: =K47 -> 11 | M47: =L47 -> 11 | N47: =M47 -> 11 | O47: =N47 -> 11
C48: Downside Case | K48: 11 | L48: =K48 -> 11 | M48: =L48 -> 11 | N48: =M48 -> 11 | O48: =N48 -> 11
C50: Comp/FTE | H50: =-(H89*10^6)/H33 -> 26344.981 | I50: =-(I89*10^6)/I33 -> 25890.013 | J50: =-(J89*10^6)/J33 -> 27769.48 | K50: =ROUND(+J50*(1+K51),0) -> 29713 | L50: =ROUND(+K50*(1+L51),0) -> 31199 | M50: =ROUND(+L50*(1+M51),0) -> 32135 | N50: =ROUND(+M50*(1+N51),0) -> 32456 | O50: =ROUND(+N50*(1+O51),0) -> 32781
C51: =+"% growth: "&CHOOSE($Y$3,C52,C53) -> % growth: Base Case | I51: =IFERROR(I50/H50-1,"n.a.") -> -0.01726961 | J51: =IFERROR(J50/I50-1,"n.a.") -> 0.072594266 | K51: =+CHOOSE($Y$3,K52,K53) -> 0.07 | L51: =+CHOOSE($Y$3,L52,L53) -> 0.05 | M51: =+CHOOSE($Y$3,M52,M53) -> 0.03 | N51: =+CHOOSE($Y$3,N52,N53) -> 0.01 | O51: =+CHOOSE($Y$3,O52,O53) -> 0.01
C52: Base Case | K52: 0.07 | L52: =K52-2% -> 0.05 | M52: =L52-2% -> 0.03 | N52: =M52-2% -> 0.01 | O52: 0.01
C53: Downside Case | K53: =K52 -> 0.07 | L53: =L52 -> 0.05 | M53: =M52 -> 0.03 | N53: =N52 -> 0.01 | O53: =O52 -> 0.01
C55: Maintenance Capex | K55: =K56*K$73 -> -584.35708 | L55: =L56*L73 -> -605.23594 | M55: =M56*M73 -> -627.41656 | N55: =N56*N73 -> -650.98895 | O55: =O56*O73 -> -676.04312
...

Sheet 3. Valuation
C3: Q3: Valuation
D12: LBO Ability to Pay Analysis (5Y Hold)
D14: Target IRR | G14: 0.2
D15: Exit Equity Value | G15: ='2. Operating Model'!O199 -> 8700.7053
D16: Required Entry Equity Value | G16: =G15/(1+G14)^5 -> 3496.6183
D17: (+) Net Debt | G17: ='2. Operating Model'!K9 -> 2824
D18: Required Sources | G18: =G16+G17 -> 6320.6183
D19: (-) Refi Existing Debt | G19: =-'2. Operating Model'!R10 -> -1836
D20: (-) Transaction Fees | G20: =-'2. Operating Model'!R11 -> -73.25575
D21: Required Equity Purchase Price | G21: =SUM(G18:G20) -> 4411.3626
D22: (+) Existing Net Debt | G22: ='2. Operating Model'!R10 -> 1836
D23: Implied Purchase EV | G23: =G21+G22 -> 6247.3626
D24: LTM EBITDA | G24: ='2. Operating Model'!J107 -> 706
D25: Entry LTM EBITDA Multiple | G25: =G23/G24 -> 8.8489555
D26: Implied Premium | G26: =G21/('2. Operating Model'!F9*'2. Operating Model'!F11/100)-1 -> 0.044665816
D28: Comps
D29: Current Trading Comps | G29: =AVERAGE(6.7,6.9,5.7) -> 6.4333333
D30: 5Y Avg. Trading Comps | G30: =AVERAGE(7,7.6,5) -> 6.5333333
D31: Current Transaction Comps | G31: 11.5
D32: 5Y Avg. Transaction Comps | G32: 10.4
D34: A 9-12x LTM EBITDA multiple is appropriate for this transaction, taking recent transactions and targeted returns into account
D35: DCF is not very meaningful in this instance as we are solving for a 5Y hold
