Workbook
Name circ: Input!$E$16
Name IQ_CH: 110000
Name IQ_CQ: 5000
Name IQ_CY: 10000
Name IQ_DAILY: 500000
Name IQ_FH: 100000
Name IQ_FQ: 500
Name IQ_FY: 1000
Name IQ_LTM: 2000
Name IQ_MONTH: 15000
Name IQ_NTM: 6000
Name IQ_WEEK: 50000
Name IQ_YTD: 3000

Sheet Instructions
B5: Instructions
A7: x | B7: Build a 5 year full three-statement annual LBO model (on the 'Input' tab)
A8: x | B8: Target private equity like returns of 20-25% IRR
A9: x | B9: Assume stable gross margins
A10: x | B10: Use the opex growth rates suggested
A11: x | B11: Determine an appropriate level of debt, based on the assumptions provided (including cash sweep). Please include 1.0x EBITDA of mezzanine financing (the rest can be senior debt - up to the level you deem appropriate)
A12: x | B12: Supply entry valuation metrics (EBITDA, EBITDA - Capex, EBIT, Unlevered FCF)
A13: x | B13: Supply relevant credit metrics (gross leverage, net leverage, interest coverage, cash flow coverage, etc.)
A14: x | B14: Show IRR% and Multiple-of-Money for a 3, 4, and 5 year exit
A15: x | B15: Please break out the components of value creation between multiples expansion, revenue growth, margin expansion, and deleveraging (i.e. what % of equity value created came from each effect?)
B16: Time limit: 3 hours
B18: Year 1 Assumptions
B20: P&L
A21: x | B21: Revenue | D21: 200
A22: x | B22: 5-yr Growth | D22: 0.11 | E22: CAGR
A23: x | B23: Gross Margin | D23: 0.5 | E23: of sales
A24: x | B24: EBITDA Margin | D24: 0.2 | E24: of sales | F24: 5-year growth CAGR
A25: x | B25: Opex - S&M | D25: 0.12 | E25: of sales | F25: 0.11
A26: x | B26: Opex - R&D | D26: 0.08 | E26: of sales | F26: 0.07
A27: x | B27: Opex - G&A | D27: =D23-D24-D25-D26 -> 0.1 | E27: of sales | F27: 0.05
A28: x | B28: Capex | D28: 0.04 | E28: of sales
A29: x | B29: Tax Rate | D29: 0.3 | E29: of PBT
B31: Balance Sheet
A32: x | B32: Min Cash / Opening Cash | D32: 15
A33: x | B33: Accounts Receivables | D33: 40
A34: x | B34: Other Current Assets | D34: 10
A35: x | B35: PP&E | D35: 50
A36: x | B36: Accounts Payables | D36: 20
A37: x | B37: Deferred Revenue | D37: 20
B39: Leverage Assumptions
B40: Senior debt assumptions
A41: x | B41: Cash Interest | D41: 0.07
A42: x | B42: Mandatory Amortization | D42: 0.05
A43: x | B43: Free Cash Flow Sweep | D43: 0.5 | E43: of cash flow after mandatory amortization
B45: Mezz debt assumptions
A46: x | B46: Cash Interest | D46: 0.06
A47: x | B47: PIK Interest | D47: 0.06
A48: x | B48: Total Mezz Interest | D48: =SUM(D46:D47) -> 0.12
B50: Deal
A51: x | B51: Entry | D51: 12 | E51: NTM basis
...

Sheet Input
B2: Deal parameters | I2: Sources | M2: Uses | Q2: Entry valuation
C3: Entry multiple | E3: =+Instructions!D51 -> 12 | I3: Senior debt | K3: =+K13*I40 -> 180.18018 | M3: Purchase EV | O3: =+E5 -> 480 | Q3: EV / EBITDA, NTM | T3: =+O3/J40 -> 12
C4: NTM EBITDA | E4: =+J40 -> 40 | I4: Mezz debt | K4: =+K18*I40 -> 36.036036 | M4: M&A fees | O4: =+$O$3*E8 -> 4.8 | Q4: EV / EBITDA - Capex, NTM | T4: =+O3/(J40+J126) -> 15
C5: Entry EV | E5: =+E4*E3 -> 480 | I5: Sponsor equity | K5: =+K7-K3-K4 -> 293.18378 | M5: Financing fees | O5: =+$O$3*E9 -> 9.6 | Q5: EV EBIT, NTM | T5: =+O3/J45 -> 14.304636
M6: Min cash | O6: =+Instructions!D32 -> 15
C7: Deal fees | E7: =+Instructions!D53 -> 0.03 | I7: Total | K7: =+O7 -> 509.4 | M7: Total | O7: =SUM(O3:O6) -> 509.4 | Q7: UFCF yield, NTM | T7: =+(J56+J120+J123)/$O$3 -> 0.060069444
C8: o/w M&A | E8: =0.333333333333333*$E$7 -> 0.01 | F8: << own assumptions
C9: o/w financing | E9: =(2/3)*$E$7 -> 0.02 | F9: << own assumptions | I9: Senior debt | M9: Credit metrics | O9: =+I20 -> 0 | P9: =+O9+1 -> 1 | Q9: =+P9+1 -> 2 | R9: =+Q9+1 -> 3 | S9: =+R9+1 -> 4 | T9: =+S9+1 -> 5
I10: Cash interest | K10: =+Instructions!D41 -> 0.07 | M10: Gross debt | O10: =+I166 -> 216.21622 | P10: =+J166 -> 207.99383 | Q10: =+K166 -> 197.12073 | R10: =+L166 -> 182.58514 | S10: =+M166 -> 163.5169 | T10: =+N166 -> 139.06416
C11: Assume cash free, debt free basis | I11: Mandatory amort' | K11: =+Instructions!D42 -> 0.05 | M11: Net debt | O11: =+I167 -> 201.21622 | P11: =+J167 -> 191.61829 | Q11: =+K167 -> 177.96475 | R11: =+L167 -> 159.62915 | S11: =+M167 -> 135.8825 | T11: =+N167 -> 105.89075
I12: Sweep | K12: =+Instructions!D43 -> 0.5 | M12: Senior debt | O12: =+I75 -> 180.18018 | P12: =+J75 -> 169.79563 | Q12: =+K75 -> 156.63064 | R12: =+L75 -> 139.66564 | S12: =+M75 -> 118.02223 | T12: =+N75 -> 90.839813
C13: Exit multiple, NTM | E13: =+Instructions!D52 -> 11 | I13: Quantum, LTM EBITDA | K13: 5
C14: MIP | E14: =+Instructions!D54 -> 0.05 | M14: Gross debt / EBITDA | O14: =+O10/I40 -> 6 | P14: =+P10/J40 -> 5.1998458 | Q14: =+Q10/K40 -> 4.2629917 | R14: =+R10/L40 -> 3.4274643 | S14: =+S10/M40 -> 2.6724225 | T14: =+T10/N40 -> 1.984066
I15: Mezz debt | M15: ND/EBITDA | O15: =+O11/I40 -> 5.58375 | P15: =+P11/J40 -> 4.7904574 | Q15: =+Q11/K40 -> 3.8487187 | R15: =+R11/L40 -> 2.9965375 | S15: =+S11/M40 -> 2.2207824 | T15: =+T11/N40 -> 1.510772
B16: Circularity | E16: 1 | I16: Cash interest | K16: =+Instructions!D46 -> 0.06
I17: PIK | K17: =+Instructions!D47 -> 0.06 | M17: EBIT / cash interest | P17: =+K45/(J147+J154+J159)*-1 -> 2.680879 | Q17: =+L45/(K147+K154+K159)*-1 -> 3.2457776 | R17: =+M45/(L147+L154+L159)*-1 -> 3.9964385 | S17: =+N45/(M147+M154+M159)*-1 -> 5.0549722 | T17: =+O45/(N147+N154+N159)*-1 -> 6.6696773
I18: Quantum, LTM EBITDA | K18: 1 | M18: OCF / ND | P18: =+J124/P11 -> 0.10312212 | Q18: =+K124/Q11 -> 0.13949634 | R18: =+L124/R11 -> 0.19183096 | S18: =+M124/S11 -> 0.27422861 | T18: =+N124/T11 -> 0.42370078
H20: Year | I20: 0 | J20: =+I20+1 -> 1 | K20: =+J20+1 -> 2 | L20: =+K20+1 -> 3 | M20: =+L20+1 -> 4 | N20: =+M20+1 -> 5 | O20: =+N20+1 -> 6
A21: x | B21: Income statement
C22: Revenue | I22: =+J22/(1+J23) -> 180.18018 | J22: =+Instructions!D21 -> 200 | K22: =+(1+K23)*J22 -> 222 | L22: =+(1+L23)*K22 -> 246.42 | M22: =+(1+M23)*L22 -> 273.5262 | N22: =+(1+N23)*M22 -> 303.61408 | O22: =+(1+O23)*N22 -> 337.01163
C23: % YoY | J23: =+K23 -> 0.11 | K23: =+Instructions!D22 -> 0.11 | L23: =+K23 -> 0.11 | M23: =+L23 -> 0.11 | N23: =+M23 -> 0.11 | O23: =+N23 -> 0.11
C25: Gross profit | I25: =+I26*I22 -> 90.09009 | J25: =+J26*J22 -> 100 | K25: =+K26*K22 -> 111 | L25: =+L26*L22 -> 123.21 | M25: =+M26*M22 -> 136.7631 | N25: =+N26*N22 -> 151.80704 | O25: =+O26*O22 -> 168.50582
C26: % margin | I26: =+J26 -> 0.5 | J26: =+Instructions!D23 -> 0.5 | K26: =+J26 -> 0.5 | L26: =+K26 -> 0.5 | M26: =+L26 -> 0.5 | N26: =+M26 -> 0.5 | O26: =+N26 -> 0.5
C28: Opex - S&M | J28: =+J29*J22*-1 -> -24 | K28: =+(1+K30)*J28 -> -26.64 | L28: =+(1+L30)*K28 -> -29.5704 | M28: =+(1+M30)*L28 -> -32.823144 | N28: =+(1+N30)*M28 -> -36.43369 | O28: =+(1+O30)*N28 -> -40.441396
C29: % of sales | J29: =+Instructions!D25 -> 0.12 | K29: =+K28/K22*-1 -> 0.12 | L29: =+L28/L22*-1 -> 0.12 | M29: =+M28/M22*-1 -> 0.12 | N29: =+N28/N22*-1 -> 0.12 | O29: =+O28/O22*-1 -> 0.12
C30: % YoY | K30: =+Instructions!$F$25 -> 0.11 | L30: =+Instructions!$F$25 -> 0.11 | M30: =+Instructions!$F$25 -> 0.11 | N30: =+Instructions!$F$25 -> 0.11 | O30: =+Instructions!$F$25 -> 0.11
C32: Opex - R&D | J32: =+J33*J22*-1 -> -16 | K32: =+(1+K34)*J32 -> -17.12 | L32: =+(1+L34)*K32 -> -18.3184 | M32: =+(1+M34)*L32 -> -19.600688 | N32: =+(1+N34)*M32 -> -20.972736 | O32: =+(1+O34)*N32 -> -22.440828
C33: % of sales | J33: =+Instructions!D26 -> 0.08 | K33: =+K32/K22*-1 -> 0.077117117 | L33: =+L32/L22*-1 -> 0.074338122 | M33: =+M32/M22*-1 -> 0.071659271 | N33: =+N32/N22*-1 -> 0.069076955 | O33: =+O32/O22*-1 -> 0.066587695
C34: % YoY | K34: =+Instructions!$F$26 -> 0.07 | L34: =+Instructions!$F$26 -> 0.07 | M34: =+Instructions!$F$26 -> 0.07 | N34: =+Instructions!$F$26 -> 0.07 | O34: =+Instructions!$F$26 -> 0.07
C36: Opex - G&A | J36: =+J37*J22*-1 -> -20 | K36: =+(1+K38)*J36 -> -21 | L36: =+(1+L38)*K36 -> -22.05 | M36: =+(1+M38)*L36 -> -23.1525 | N36: =+(1+N38)*M36 -> -24.310125 | O36: =+(1+O38)*N36 -> -25.525631
C37: % of sales | J37: =+Instructions!D27 -> 0.1 | K37: =+K36/K22*-1 -> 0.094594595 | L37: =+L36/L22*-1 -> 0.089481373 | M37: =+M36/M22*-1 -> 0.084644542 | N37: =+N36/N22*-1 -> 0.080069162 | O37: =+O36/O22*-1 -> 0.075741099
C38: % YoY | K38: =+Instructions!$F$27 -> 0.05 | L38: =+Instructions!$F$27 -> 0.05 | M38: =+Instructions!$F$27 -> 0.05 | N38: =+Instructions!$F$27 -> 0.05 | O38: =+Instructions!$F$27 -> 0.05
C40: EBITDA | I40: =+I41*I22 -> 36.036036 | J40: =+J36+J32+J28+J25 -> 40 | K40: =+K36+K32+K28+K25 -> 46.24 | L40: =+L36+L32+L28+L25 -> 53.2712 | M40: =+M36+M32+M28+M25 -> 61.186768 | N40: =+N36+N32+N28+N25 -> 70.09049 | O40: =+O36+O32+O28+O25 -> 80.097961
C41: % margin | I41: =+J41 -> 0.2 | J41: =+J40/J22 -> 0.2 | K41: =+K40/K22 -> 0.20828829 | L41: =+L40/L22 -> 0.2161805 | M41: =+M40/M22 -> 0.22369619 | N41: =+N40/N22 -> 0.23085388 | O41: =+O40/O22 -> 0.23767121
C43: D&A | J43: =+J104 -> -6.4444444 | K43: =+K104 -> -7.4311111 | L43: =+L104 -> -8.5263111 | M43: =+M104 -> -9.7419831 | N43: =+N104 -> -11.091379 | O43: =+O104 -> -12.589209
C45: EBIT | J45: =+J40+J43 -> 33.555556 | K45: =+K40+K43 -> 38.808889 | L45: =+L40+L43 -> 44.744889 | M45: =+M40+M43 -> 51.444785 | N45: =+N40+N43 -> 58.999111 | O45: =+O40+O43 -> 67.508752
C47: Net interest | J47: =+IF(circ=1, J147+J154+J159+J160, 0) -> -16.638343 | K47: =+IF(circ=1, K147+K154+K159+K160, 0) -> -16.07746 | L47: =+IF(circ=1, L147+L154+L159+L160, 0) -> -15.302063 | M47: =+IF(circ=1, M147+M154+M159+M160, 0) -> -14.24667 | N47: =+IF(circ=1, N147+N154+N159+N160, 0) -> -12.851422 | O47: =+IF(circ=1, O147+O154+O159+O160, 0) -> -11.055466
C48: Amort' financing fees | J48: =+J99 -> -1.3714286 | K48: =+K99 -> -1.3714286 | L48: =+L99 -> -1.3714286 | M48: =+M99 -> -1.3714286 | N48: =+N99 -> -1.3714286 | O48: =+O99 -> -1.3714286
C50: EBT | J50: =+J48+J47+J45 -> 15.545784 | K50: =+K48+K47+K45 -> 21.36 | L50: =+L48+L47+L45 -> 28.071397 | M50: =+M48+M47+M45 -> 35.826686 | N50: =+N48+N47+N45 -> 44.776261 | O50: =+O48+O47+O45 -> 55.081858
C52: Tax rate | J52: =+Instructions!$D$29 -> 0.3 | K52: =+Instructions!$D$29 -> 0.3 | L52: =+Instructions!$D$29 -> 0.3 | M52: =+Instructions!$D$29 -> 0.3 | N52: =+Instructions!$D$29 -> 0.3 | O52: =+Instructions!$D$29 -> 0.3
...
