Workbook

Sheet BBPTACShadowWks0001
D2: ='TEV Buildouts - Gold Solution'!C2 -> 94.06 | E2: ='TEV Buildouts - Gold Solution'!D2 -> 94.04 | F2: ='TEV Buildouts - Gold Solution'!E2 -> 80.57 | G2: ='TEV Buildouts - Gold Solution'!F2 -> 215.12 | H2: ='TEV Buildouts - Gold Solution'!G2 -> 266.6 | I2: ='TEV Buildouts - Gold Solution'!H2 -> 565.03 | J2: ='TEV Buildouts - Gold Solution'!I2 -> 49.6
D3: ='TEV Buildouts - Gold Solution'!$C$3 -> 676.7
D5: ='TEV Buildouts - Gold Solution'!C5 -> 15671
D6: ='TEV Buildouts - Gold Solution'!C6 -> -3352
D7: ='TEV Buildouts - Gold Solution'!C7 -> 12319
D8: ='TEV Buildouts - Gold Solution'!C8 -> 506
D9: ='TEV Buildouts - Gold Solution'!C9 -> 229
D10: ='TEV Buildouts - Gold Solution'!C10 -> 339
D11: ='TEV Buildouts - Gold Solution'!C11 -> 1074
D13: ='TEV Buildouts - Gold Solution'!$C$13 -> 77043.402
D26: ='TEV Buildouts - Gold Solution'!C26 -> 6176
D27: ='TEV Buildouts - Gold Solution'!C27 -> 6930
D34: ='TEV Buildouts - Gold Solution'!C34 -> 0.1
D35: ='TEV Buildouts - Gold Solution'!C35 -> 0.1
D45: ='TEV Buildouts - Gold Solution'!$C$51 -> 0.1725

Sheet BBPTACShadowWks0002
C3: ='Compsheet - Gold Solution'!C3 -> 94.06 | D3: ='Compsheet - Gold Solution'!D3 -> 63650.402 | E3: ='Compsheet - Gold Solution'!E3 -> 77043.402 | F3: ='Compsheet - Gold Solution'!F3 -> 1.6425333 | H3: ='Compsheet - Gold Solution'!H3 -> 11.117374 | I3: ='Compsheet - Gold Solution'!I3 -> 10.272454 | J3: ='Compsheet - Gold Solution'!J3 -> 9.3385942 | K3: ='Compsheet - Gold Solution'!K3 -> 8.4896311 | M3: ='Compsheet - Gold Solution'!M3 -> 0.040971386 | N3: ='Compsheet - Gold Solution'!N3 -> 0.042914123 | O3: ='Compsheet - Gold Solution'!O3 -> 0.050969647 | P3: ='Compsheet - Gold Solution'!P3 -> 0.059830724 | R3: ='Compsheet - Gold Solution'!AE3 -> 6930 | S3: ='Compsheet - Gold Solution'!AF3 -> 7500 | T3: ='Compsheet - Gold Solution'!AG3 -> 8250 | U3: ='Compsheet - Gold Solution'!AH3 -> 9075 | W3: ='Compsheet - Gold Solution'!R3 -> 0.082251082 | X3: ='Compsheet - Gold Solution'!S3 -> 0.1 | Y3: ='Compsheet - Gold Solution'!T3 -> 0.1 | AA3: ='Compsheet - Gold Solution'!V3 -> 0.19481615 | AB3: ='Compsheet - Gold Solution'!W3 -> 0.20273076 | AC3: ='Compsheet - Gold Solution'!X3 -> 0.21442676 | AD3: ='Compsheet - Gold Solution'!Y3 -> 0.22679754 | AF3: ='Compsheet - Gold Solution'!AA3 -> 0.0079146087 | AG3: ='Compsheet - Gold Solution'!AB3 -> 0.011696005 | AH3: ='Compsheet - Gold Solution'!AC3 -> 0.012370775
C4: ='Compsheet - Gold Solution'!C4 -> 94.04 | D4: ='Compsheet - Gold Solution'!D4 -> 4087.2605 | E4: ='Compsheet - Gold Solution'!E4 -> 5286.9285 | F4: ='Compsheet - Gold Solution'!F4 -> 2.716198 | H4: ='Compsheet - Gold Solution'!H4 -> 13.16014 | I4: ='Compsheet - Gold Solution'!I4 -> 10.680664 | J4: ='Compsheet - Gold Solution'!J4 -> 9.7096943 | K4: ='Compsheet - Gold Solution'!K4 -> 8.8269948 | M4: ='Compsheet - Gold Solution'!M4 -> 0.035939038 | N4: ='Compsheet - Gold Solution'!N4 -> 0.047700191 | O4: ='Compsheet - Gold Solution'!O4 -> 0.055307396 | P4: ='Compsheet - Gold Solution'!P4 -> 0.063675322 | R4: ='Compsheet - Gold Solution'!AE4 -> 401.738 | S4: ='Compsheet - Gold Solution'!AF4 -> 495 | T4: ='Compsheet - Gold Solution'!AG4 -> 544.5 | U4: ='Compsheet - Gold Solution'!AH4 -> 598.95 | W4: ='Compsheet - Gold Solution'!R4 -> 0.23214632 | X4: ='Compsheet - Gold Solution'!S4 -> 0.1 | Y4: ='Compsheet - Gold Solution'!T4 -> 0.1 | AA4: ='Compsheet - Gold Solution'!V4 -> 0.10024469 | AB4: ='Compsheet - Gold Solution'!W4 -> 0.11511628 | AC4: ='Compsheet - Gold Solution'!X4 -> 0.11946029 | AD4: ='Compsheet - Gold Solution'!Y4 -> 0.12396823 | AF4: ='Compsheet - Gold Solution'!AA4 -> 0.014871592 | AG4: ='Compsheet - Gold Solution'!AB4 -> 0.0043440105 | AH4: ='Compsheet - Gold Solution'!AC4 -> 0.0045079355
C5: ='Compsheet - Gold Solution'!C5 -> 80.57 | D5: ='Compsheet - Gold Solution'!D5 -> 4560.262 | E5: ='Compsheet - Gold Solution'!E5 -> 5600.992 | F5: ='Compsheet - Gold Solution'!F5 -> 1.8625225 | H5: ='Compsheet - Gold Solution'!H5 -> 12.097175 | I5: ='Compsheet - Gold Solution'!I5 -> 10.091877 | J5: ='Compsheet - Gold Solution'!J5 -> 9.344331 | K5: ='Compsheet - Gold Solution'!K5 -> 8.6521583 | M5: ='Compsheet - Gold Solution'!M5 -> 0.039479257 | N5: ='Compsheet - Gold Solution'!N5 -> 0.048161111 | O5: ='Compsheet - Gold Solution'!O5 -> 0.054899204 | P5: ='Compsheet - Gold Solution'!P5 -> 0.062176343 | R5: ='Compsheet - Gold Solution'!AE5 -> 463 | S5: ='Compsheet - Gold Solution'!AF5 -> 555 | T5: ='Compsheet - Gold Solution'!AG5 -> 599.4 | U5: ='Compsheet - Gold Solution'!AH5 -> 647.352 | W5: ='Compsheet - Gold Solution'!R5 -> 0.1987041 | X5: ='Compsheet - Gold Solution'!S5 -> 0.08 | Y5: ='Compsheet - Gold Solution'!T5 -> 0.08 | AA5: ='Compsheet - Gold Solution'!V5 -> 0.15970997 | AB5: ='Compsheet - Gold Solution'!W5 -> 0.16567164 | AC5: ='Compsheet - Gold Solution'!X5 -> 0.17204363 | AD5: ='Compsheet - Gold Solution'!Y5 -> 0.17866069 | AF5: ='Compsheet - Gold Solution'!AA5 -> 0.0059616723 | AG5: ='Compsheet - Gold Solution'!AB5 -> 0.0063719862 | AH5: ='Compsheet - Gold Solution'!AC5 -> 0.0066170626
C6: ='Compsheet - Gold Solution'!C6 -> 215.12 | D6: ='Compsheet - Gold Solution'!D6 -> 7155.7941 | E6: ='Compsheet - Gold Solution'!E6 -> 8233.6201 | F6: ='Compsheet - Gold Solution'!F6 -> 1.4530176 | H6: ='Compsheet - Gold Solution'!H6 -> 9.9212434 | I6: ='Compsheet - Gold Solution'!I6 -> 9.8230133 | J6: ='Compsheet - Gold Solution'!J6 -> 9.2669937 | K6: ='Compsheet - Gold Solution'!K6 -> 8.7424468 | M6: ='Compsheet - Gold Solution'!M6 -> 0.062370236 | N6: ='Compsheet - Gold Solution'!N6 -> 0.045532157 | O6: ='Compsheet - Gold Solution'!O6 -> 0.053668756 | P6: ='Compsheet - Gold Solution'!P6 -> 0.05907504 | R6: ='Compsheet - Gold Solution'!AE6 -> 829.898 | S6: ='Compsheet - Gold Solution'!AF6 -> 838.19698 | T6: ='Compsheet - Gold Solution'!AG6 -> 888.4888 | U6: ='Compsheet - Gold Solution'!AH6 -> 941.79813 | W6: ='Compsheet - Gold Solution'!R6 -> 0.01 | X6: ='Compsheet - Gold Solution'!S6 -> 0.06 | Y6: ='Compsheet - Gold Solution'!T6 -> 0.06 | AA6: ='Compsheet - Gold Solution'!V6 -> 0.36607118 | AB6: ='Compsheet - Gold Solution'!W6 -> 0.36973189 | AC6: ='Compsheet - Gold Solution'!X6 -> 0.37684212 | AD6: ='Compsheet - Gold Solution'!Y6 -> 0.38408908 | AF6: ='Compsheet - Gold Solution'!AA6 -> 0.0036607118 | AG6: ='Compsheet - Gold Solution'!AB6 -> 0.0071102286 | AH6: ='Compsheet - Gold Solution'!AC6 -> 0.0072469638
C7: ='Compsheet - Gold Solution'!C7 -> 266.6 | D7: ='Compsheet - Gold Solution'!D7 -> 35457.8 | E7: ='Compsheet - Gold Solution'!E7 -> 40627.2 | F7: ='Compsheet - Gold Solution'!F7 -> 1.9246939 | H7: ='Compsheet - Gold Solution'!H7 -> 19.748785 | I7: ='Compsheet - Gold Solution'!I7 -> 16.582531 | J7: ='Compsheet - Gold Solution'!J7 -> 15.075028 | K7: ='Compsheet - Gold Solution'!K7 -> 13.704571 | M7: ='Compsheet - Gold Solution'!M7 -> 0.027426502 | N7: ='Compsheet - Gold Solution'!N7 -> 0.031278306 | O7: ='Compsheet - Gold Solution'!O7 -> 0.036313726 | P7: ='Compsheet - Gold Solution'!P7 -> 0.041852687 | R7: ='Compsheet - Gold Solution'!AE7 -> 2057.2 | S7: ='Compsheet - Gold Solution'!AF7 -> 2450 | T7: ='Compsheet - Gold Solution'!AG7 -> 2695 | U7: ='Compsheet - Gold Solution'!AH7 -> 2964.5 | W7: ='Compsheet - Gold Solution'!R7 -> 0.19093914 | X7: ='Compsheet - Gold Solution'!S7 -> 0.1 | Y7: ='Compsheet - Gold Solution'!T7 -> 0.1 | AA7: ='Compsheet - Gold Solution'!V7 -> 0.27732542 | AB7: ='Compsheet - Gold Solution'!W7 -> 0.30581269 | AC7: ='Compsheet - Gold Solution'!X7 -> 0.31735279 | AD7: ='Compsheet - Gold Solution'!Y7 -> 0.32932837 | AF7: ='Compsheet - Gold Solution'!AA7 -> 0.028487263 | AG7: ='Compsheet - Gold Solution'!AB7 -> 0.011540101 | AH7: ='Compsheet - Gold Solution'!AC7 -> 0.011975577
C8: ='Compsheet - Gold Solution'!C8 -> 565.03 | D8: ='Compsheet - Gold Solution'!D8 -> 34466.83 | E8: ='Compsheet - Gold Solution'!E8 -> 40155.83 | F8: ='Compsheet - Gold Solution'!F8 -> 2.3613333 | H8: ='Compsheet - Gold Solution'!H8 -> 19.43651 | I8: ='Compsheet - Gold Solution'!I8 -> 17.847036 | J8: ='Compsheet - Gold Solution'!J8 -> 16.525033 | K8: ='Compsheet - Gold Solution'!K8 -> 15.300956 | M8: ='Compsheet - Gold Solution'!M8 -> 0.022054207 | N8: ='Compsheet - Gold Solution'!N8 -> 0.028529481 | O8: ='Compsheet - Gold Solution'!O8 -> 0.032306019 | P8: ='Compsheet - Gold Solution'!P8 -> 0.036384679 | R8: ='Compsheet - Gold Solution'!AE8 -> 2066 | S8: ='Compsheet - Gold Solution'!AF8 -> 2250 | T8: ='Compsheet - Gold Solution'!AG8 -> 2430 | U8: ='Compsheet - Gold Solution'!AH8 -> 2624.4 | W8: ='Compsheet - Gold Solution'!R8 -> 0.089060987 | X8: ='Compsheet - Gold Solution'!S8 -> 0.08 | Y8: ='Compsheet - Gold Solution'!T8 -> 0.08 | AA8: ='Compsheet - Gold Solution'!V8 -> 0.31609547 | AB8: ='Compsheet - Gold Solution'!W8 -> 0.3200569 | AC8: ='Compsheet - Gold Solution'!X8 -> 0.32609571 | AD8: ='Compsheet - Gold Solution'!Y8 -> 0.33224846 | AF8: ='Compsheet - Gold Solution'!AA8 -> 0.0039614278 | AG8: ='Compsheet - Gold Solution'!AB8 -> 0.0060388094 | AH8: ='Compsheet - Gold Solution'!AC8 -> 0.0061527492
C9: ='Compsheet - Gold Solution'!C9 -> 49.6 | D9: ='Compsheet - Gold Solution'!D9 -> 27413.92 | E9: ='Compsheet - Gold Solution'!E9 -> 33004.92 | F9: ='Compsheet - Gold Solution'!F9 -> 1.5002769 | H9: ='Compsheet - Gold Solution'!H9 -> 10.375643 | I9: ='Compsheet - Gold Solution'!I9 -> 9.8815646 | J9: ='Compsheet - Gold Solution'!J9 -> 9.0656556 | K9: ='Compsheet - Gold Solution'!K9 -> 8.3171153 | M9: ='Compsheet - Gold Solution'!M9 -> 0.060302449 | N9: ='Compsheet - Gold Solution'!N9 -> 0.061613898 | O9: ='Compsheet - Gold Solution'!O9 -> 0.06915066 | P9: ='Compsheet - Gold Solution'!P9 -> 0.07736573 | R9: ='Compsheet - Gold Solution'!AE9 -> 3181 | S9: ='Compsheet - Gold Solution'!AF9 -> 3340.05 | T9: ='Compsheet - Gold Solution'!AG9 -> 3640.6545 | U9: ='Compsheet - Gold Solution'!AH9 -> 3968.3134 | W9: ='Compsheet - Gold Solution'!R9 -> 0.05 | X9: ='Compsheet - Gold Solution'!S9 -> 0.09 | Y9: ='Compsheet - Gold Solution'!T9 -> 0.09 | AA9: ='Compsheet - Gold Solution'!V9 -> 0.27178742 | AB9: ='Compsheet - Gold Solution'!W9 -> 0.27440076 | AC9: ='Compsheet - Gold Solution'!X9 -> 0.28216682 | AD9: ='Compsheet - Gold Solution'!Y9 -> 0.29015268 | AF9: ='Compsheet - Gold Solution'!AA9 -> 0.0026133406 | AG9: ='Compsheet - Gold Solution'!AB9 -> 0.0077660594 | AH9: ='Compsheet - Gold Solution'!AC9 -> 0.0079858535

Sheet Grading
B3: Subtask Breakdown
C4: Section Name | D4: Total
C5: TEV Buildouts | D5: =COUNT('TEV Buildouts - Gold Solution'!C2:I3,'TEV Buildouts - Gold Solution'!C5:I6,'TEV Buildouts - Gold Solution'!C8:I10,'TEV Buildouts - Gold Solution'!C15:I19,'TEV Buildouts - Gold Solution'!C21:I21,'TEV Buildouts - Gold Solution'!D22:E22,'TEV Buildouts - Gold Solution'!H22,'TEV Buildouts - Gold Solution'!C26:I30,'TEV Buildouts - Gold Solution'!C32:I32,'TEV Buildouts - Gold Solution'!C33:E33,'TEV Buildouts - Gold Solution'!G33:H33,'TEV Buildouts - Gold Solution'!C37:I41,'TEV Buildouts - Gold Solution'!C43:I45,'TEV Buildouts - Gold Solution'!C53:I54,'TEV Buildouts - Gold Solution'!C57:I63) -> 249 | F5: << Note from OAI: Make sure that all the "Total" cells in this section contain the exact range that should be checked
C6: Summary Sheet | D6: =COUNT('Compsheet - Gold Solution'!C3:F9,'Compsheet - Gold Solution'!H3:K9,'Compsheet - Gold Solution'!M3:P9,'Compsheet - Gold Solution'!R3:T9,'Compsheet - Gold Solution'!V3:Y9,'Compsheet - Gold Solution'!AA3:AC9,'Compsheet - Gold Solution'!AE3:AH9) -> 182
C8: Total | D8: =SUM(D5:D6) -> 431
B12: Formatting
C13: Check | D13: Total
C14: Check that model's solution matches formatting of this range exactly in the gold solution | D14: =COUNT('Compsheet - Gold Solution'!C3:AH9,'TEV Buildouts - Gold Solution'!C2:I51,'TEV Buildouts - Gold Solution'!C53:E55,'TEV Buildouts - Gold Solution'!G53:H55,'TEV Buildouts - Gold Solution'!C57:I63) -> 526 | F14: << Note from OAI: Make sure that all the "Total" cells in this section contain the exact range that should be checked
C16: Total | D16: =SUM(D14) -> 526
B18: Citations
C19: Check | D19: Cell | E19: Total

Sheet Compsheet - Gold Solution
H1: EV/EBITDA | M1: Est. FCFF Yield | R1: Adj. EBITDA % Growth | V1: Adj. EBITDA Margin % | AA1: Margin Improvement % | AE1: Adj. EBITDA
A2: x | B2: Ticker | C2: Sh Px | D2: Mkt Cap | E2: TEV | F2: ND/EBITDA | H2: EV/'24 EBITDA | I2: EV/'25 EBITDA | J2: EV/'26 EBITDA | K2: EV/'27 EBITDA | M2: '24 FCFF Yield | N2: '25 FCFF Yield | O2: '26 FCFF Yield | P2: '27 FCFF Yield | R2: '25 Growth % | S2: '26 Growth % | T2: '27 Growth % | V2: '24 Margin % | W2: '25 Margin % | X2: '26 Margin % | Y2: '27 Margin % | AA2: '25 % | AB2: '26 % | AC2: '27 % | AE2: '24 EBITDA | AF2: '25 EBITDA | AG2: '26 EBITDA | AH2: '27 EBITDA
B3: ='TEV Buildouts - Gold Solution'!C1 -> CRH US EQUITY | C3: =INDEX('TEV Buildouts - Gold Solution'!$C$1:$I$63,2,MATCH('Compsheet - Gold Solution'!$B3,'TEV Buildouts - Gold Solution'!$C$1:$I$1,0)) -> 94.06 | D3: =INDEX('TEV Buildouts - Gold Solution'!$C$1:$I$63,4,MATCH('Compsheet - Gold Solution'!$B3,'TEV Buildouts - Gold Solution'!$C$1:$I$1,0)) -> 63650.402 | E3: =INDEX('TEV Buildouts - Gold Solution'!$C$1:$I$63,13,MATCH('Compsheet - Gold Solution'!$B3,'TEV Buildouts - Gold Solution'!$C$1:$I$1,0)) -> 77043.402 | F3: =INDEX('TEV Buildouts - Gold Solution'!$C$1:$I$63,7,MATCH('Compsheet - Gold Solution'!$B3,'TEV Buildouts - Gold Solution'!$C$1:$I$1,0))/AF3 -> 1.6425333 | H3: =$E3/AE3 -> 11.117374 | I3: =$E3/AF3 -> 10.272454 | J3: =$E3/AG3 -> 9.3385942 | K3: =$E3/AH3 -> 8.4896311 | M3: =INDEX('TEV Buildouts - Gold Solution'!$C$1:$I$63,58,MATCH('Compsheet - Gold Solution'!$B3,'TEV Buildouts - Gold Solution'!$C$1:$I$1,0))/$E3 -> 0.040971386 | N3: =INDEX('TEV Buildouts - Gold Solution'!$C$1:$I$63,59,MATCH('Compsheet - Gold Solution'!$B3,'TEV Buildouts - Gold Solution'!$C$1:$I$1,0))/$E3 -> 0.042914123 | O3: =INDEX('TEV Buildouts - Gold Solution'!$C$1:$I$63,60,MATCH('Compsheet - Gold Solution'!$B3,'TEV Buildouts - Gold Solution'!$C$1:$I$1,0))/$E3 -> 0.050969647 | P3: =INDEX('TEV Buildouts - Gold Solution'!$C$1:$I$63,61,MATCH('Compsheet - Gold Solution'!$B3,'TEV Buildouts - Gold Solution'!$C$1:$I$1,0))/$E3 -> 0.059830724 | R3: =AF3/AE3-1 -> 0.082251082 | S3: =AG3/AF3-1 -> 0.1 | T3: =AH3/AG3-1 -> 0.1 | V3: =AE3/INDEX('TEV Buildouts - Gold Solution'!$C$1:$I$63,16,MATCH('Compsheet - Gold Solution'!$B3,'TEV Buildouts - Gold Solution'!$C$1:$I$1,0)) -> 0.19481615 | W3: =AF3/INDEX('TEV Buildouts - Gold Solution'!$C$1:$I$63,17,MATCH('Compsheet - Gold Solution'!$B3,'TEV Buildouts - Gold Solution'!$C$1:$I$1,0)) -> 0.20273076 | X3: =AG3/INDEX('TEV Buildouts - Gold Solution'!$C$1:$I$63,18,MATCH('Compsheet - Gold Solution'!$B3,'TEV Buildouts - Gold Solution'!$C$1:$I$1,0)) -> 0.21442676 | Y3: =AH3/INDEX('TEV Buildouts - Gold Solution'!$C$1:$I$63,19,MATCH('Compsheet - Gold Solution'!$B3,'TEV Buildouts - Gold Solution'!$C$1:$I$1,0)) -> 0.22679754 | AA3: =W3-V3 -> 0.0079146087 | AB3: =X3-W3 -> 0.011696005 | AC3: =Y3-X3 -> 0.012370775 | AE3: =INDEX('TEV Buildouts - Gold Solution'!$C$1:$I$63,27,MATCH('Compsheet - Gold Solution'!$B3,'TEV Buildouts - Gold Solution'!$C$1:$I$1,0)) -> 6930 | AF3: =INDEX('TEV Buildouts - Gold Solution'!$C$1:$I$63,28,MATCH('Compsheet - Gold Solution'!$B3,'TEV Buildouts - Gold Solution'!$C$1:$I$1,0)) -> 7500 | AG3: =INDEX('TEV Buildouts - Gold Solution'!$C$1:$I$63,29,MATCH('Compsheet - Gold Solution'!$B3,'TEV Buildouts - Gold Solution'!$C$1:$I$1,0)) -> 8250 | AH3: =INDEX('TEV Buildouts - Gold Solution'!$C$1:$I$63,30,MATCH('Compsheet - Gold Solution'!$B3,'TEV Buildouts - Gold Solution'!$C$1:$I$1,0)) -> 9075
B4: ='TEV Buildouts - Gold Solution'!D1 -> GVA US EQUITY | C4: =INDEX('TEV Buildouts - Gold Solution'!$C$1:$I$63,2,MATCH('Compsheet - Gold Solution'!$B4,'TEV Buildouts - Gold Solution'!$C$1:$I$1,0)) -> 94.04 | D4: =INDEX('TEV Buildouts - Gold Solution'!$C$1:$I$63,4,MATCH('Compsheet - Gold Solution'!$B4,'TEV Buildouts - Gold Solution'!$C$1:$I$1,0)) -> 4087.2605 | E4: =INDEX('TEV Buildouts - Gold Solution'!$C$1:$I$63,13,MATCH('Compsheet - Gold Solution'!$B4,'TEV Buildouts - Gold Solution'!$C$1:$I$1,0)) -> 5286.9285 | F4: =INDEX('TEV Buildouts - Gold Solution'!$C$1:$I$63,7,MATCH('Compsheet - Gold Solution'!$B4,'TEV Buildouts - Gold Solution'!$C$1:$I$1,0))/AF4 -> 2.716198 | H4: =$E4/AE4 -> 13.16014 | I4: =$E4/AF4 -> 10.680664 | J4: =$E4/AG4 -> 9.7096943 | K4: =$E4/AH4 -> 8.8269948 | M4: =INDEX('TEV Buildouts - Gold Solution'!$C$1:$I$63,58,MATCH('Compsheet - Gold Solution'!$B4,'TEV Buildouts - Gold Solution'!$C$1:$I$1,0))/$E4 -> 0.035939038 | N4: =INDEX('TEV Buildouts - Gold Solution'!$C$1:$I$63,59,MATCH('Compsheet - Gold Solution'!$B4,'TEV Buildouts - Gold Solution'!$C$1:$I$1,0))/$E4 -> 0.047700191 | O4: =INDEX('TEV Buildouts - Gold Solution'!$C$1:$I$63,60,MATCH('Compsheet - Gold Solution'!$B4,'TEV Buildouts - Gold Solution'!$C$1:$I$1,0))/$E4 -> 0.055307396 | P4: =INDEX('TEV Buildouts - Gold Solution'!$C$1:$I$63,61,MATCH('Compsheet - Gold Solution'!$B4,'TEV Buildouts - Gold Solution'!$C$1:$I$1,0))/$E4 -> 0.063675322 | R4: =AF4/AE4-1 -> 0.23214632 | S4: =AG4/AF4-1 -> 0.1 | T4: =AH4/AG4-1 -> 0.1 | V4: =AE4/INDEX('TEV Buildouts - Gold Solution'!$C$1:$I$63,16,MATCH('Compsheet - Gold Solution'!$B4,'TEV Buildouts - Gold Solution'!$C$1:$I$1,0)) -> 0.10024469 | W4: =AF4/INDEX('TEV Buildouts - Gold Solution'!$C$1:$I$63,17,MATCH('Compsheet - Gold Solution'!$B4,'TEV Buildouts - Gold Solution'!$C$1:$I$1,0)) -> 0.11511628 | X4: =AG4/INDEX('TEV Buildouts - Gold Solution'!$C$1:$I$63,18,MATCH('Compsheet - Gold Solution'!$B4,'TEV Buildouts - Gold Solution'!$C$1:$I$1,0)) -> 0.11946029 | Y4: =AH4/INDEX('TEV Buildouts - Gold Solution'!$C$1:$I$63,19,MATCH('Compsheet - Gold Solution'!$B4,'TEV Buildouts - Gold Solution'!$C$1:$I$1,0)) -> 0.12396823 | AA4: =W4-V4 -> 0.014871592 | AB4: =X4-W4 -> 0.0043440105 | AC4: =Y4-X4 -> 0.0045079355 | AE4: =INDEX('TEV Buildouts - Gold Solution'!$C$1:$I$63,27,MATCH('Compsheet - Gold Solution'!$B4,'TEV Buildouts - Gold Solution'!$C$1:$I$1,0)) -> 401.738 | AF4: =INDEX('TEV Buildouts - Gold Solution'!$C$1:$I$63,28,MATCH('Compsheet - Gold Solution'!$B4,'TEV Buildouts - Gold Solution'!$C$1:$I$1,0)) -> 495 | AG4: =INDEX('TEV Buildouts - Gold Solution'!$C$1:$I$63,29,MATCH('Compsheet - Gold Solution'!$B4,'TEV Buildouts - Gold Solution'!$C$1:$I$1,0)) -> 544.5 | AH4: =INDEX('TEV Buildouts - Gold Solution'!$C$1:$I$63,30,MATCH('Compsheet - Gold Solution'!$B4,'TEV Buildouts - Gold Solution'!$C$1:$I$1,0)) -> 598.95
B5: ='TEV Buildouts - Gold Solution'!E1 -> KNF US EQUITY | C5: =INDEX('TEV Buildouts - Gold Solution'!$C$1:$I$63,2,MATCH('Compsheet - Gold Solution'!$B5,'TEV Buildouts - Gold Solution'!$C$1:$I$1,0)) -> 80.57 | D5: =INDEX('TEV Buildouts - Gold Solution'!$C$1:$I$63,4,MATCH('Compsheet - Gold Solution'!$B5,'TEV Buildouts - Gold Solution'!$C$1:$I$1,0)) -> 4560.262 | E5: =INDEX('TEV Buildouts - Gold Solution'!$C$1:$I$63,13,MATCH('Compsheet - Gold Solution'!$B5,'TEV Buildouts - Gold Solution'!$C$1:$I$1,0)) -> 5600.992 | F5: =INDEX('TEV Buildouts - Gold Solution'!$C$1:$I$63,7,MATCH('Compsheet - Gold Solution'!$B5,'TEV Buildouts - Gold Solution'!$C$1:$I$1,0))/AF5 -> 1.8625225 | H5: =$E5/AE5 -> 12.097175 | I5: =$E5/AF5 -> 10.091877 | J5: =$E5/AG5 -> 9.344331 | K5: =$E5/AH5 -> 8.6521583 | M5: =INDEX('TEV Buildouts - Gold Solution'!$C$1:$I$63,58,MATCH('Compsheet - Gold Solution'!$B5,'TEV Buildouts - Gold Solution'!$C$1:$I$1,0))/$E5 -> 0.039479257 | N5: =INDEX('TEV Buildouts - Gold Solution'!$C$1:$I$63,59,MATCH('Compsheet - Gold Solution'!$B5,'TEV Buildouts - Gold Solution'!$C$1:$I$1,0))/$E5 -> 0.048161111 | O5: =INDEX('TEV Buildouts - Gold Solution'!$C$1:$I$63,60,MATCH('Compsheet - Gold Solution'!$B5,'TEV Buildouts - Gold Solution'!$C$1:$I$1,0))/$E5 -> 0.054899204 | P5: =INDEX('TEV Buildouts - Gold Solution'!$C$1:$I$63,61,MATCH('Compsheet - Gold Solution'!$B5,'TEV Buildouts - Gold Solution'!$C$1:$I$1,0))/$E5 -> 0.062176343 | R5: =AF5/AE5-1 -> 0.1987041 | S5: =AG5/AF5-1 -> 0.08 | T5: =AH5/AG5-1 -> 0.08 | V5: =AE5/INDEX('TEV Buildouts - Gold Solution'!$C$1:$I$63,16,MATCH('Compsheet - Gold Solution'!$B5,'TEV Buildouts - Gold Solution'!$C$1:$I$1,0)) -> 0.15970997 | W5: =AF5/INDEX('TEV Buildouts - Gold Solution'!$C$1:$I$63,17,MATCH('Compsheet - Gold Solution'!$B5,'TEV Buildouts - Gold Solution'!$C$1:$I$1,0)) -> 0.16567164 | X5: =AG5/INDEX('TEV Buildouts - Gold Solution'!$C$1:$I$63,18,MATCH('Compsheet - Gold Solution'!$B5,'TEV Buildouts - Gold Solution'!$C$1:$I$1,0)) -> 0.17204363 | Y5: =AH5/INDEX('TEV Buildouts - Gold Solution'!$C$1:$I$63,19,MATCH('Compsheet - Gold Solution'!$B5,'TEV Buildouts - Gold Solution'!$C$1:$I$1,0)) -> 0.17866069 | AA5: =W5-V5 -> 0.0059616723 | AB5: =X5-W5 -> 0.0063719862 | AC5: =Y5-X5 -> 0.0066170626 | AE5: =INDEX('TEV Buildouts - Gold Solution'!$C$1:$I$63,27,MATCH('Compsheet - Gold Solution'!$B5,'TEV Buildouts - Gold Solution'!$C$1:$I$1,0)) -> 463 | AF5: =INDEX('TEV Buildouts - Gold Solution'!$C$1:$I$63,28,MATCH('Compsheet - Gold Solution'!$B5,'TEV Buildouts - Gold Solution'!$C$1:$I$1,0)) -> 555 | AG5: =INDEX('TEV Buildouts - Gold Solution'!$C$1:$I$63,29,MATCH('Compsheet - Gold Solution'!$B5,'TEV Buildouts - Gold Solution'!$C$1:$I$1,0)) -> 599.4 | AH5: =INDEX('TEV Buildouts - Gold Solution'!$C$1:$I$63,30,MATCH('Compsheet - Gold Solution'!$B5,'TEV Buildouts - Gold Solution'!$C$1:$I$1,0)) -> 647.352
B6: ='TEV Buildouts - Gold Solution'!F1 -> EXP US EQUITY | C6: =INDEX('TEV Buildouts - Gold Solution'!$C$1:$I$63,2,MATCH('Compsheet - Gold Solution'!$B6,'TEV Buildouts - Gold Solution'!$C$1:$I$1,0)) -> 215.12 | D6: =INDEX('TEV Buildouts - Gold Solution'!$C$1:$I$63,4,MATCH('Compsheet - Gold Solution'!$B6,'TEV Buildouts - Gold Solution'!$C$1:$I$1,0)) -> 7155.7941 | E6: =INDEX('TEV Buildouts - Gold Solution'!$C$1:$I$63,13,MATCH('Compsheet - Gold Solution'!$B6,'TEV Buildouts - Gold Solution'!$C$1:$I$1,0)) -> 8233.6201 | F6: =INDEX('TEV Buildouts - Gold Solution'!$C$1:$I$63,7,MATCH('Compsheet - Gold Solution'!$B6,'TEV Buildouts - Gold Solution'!$C$1:$I$1,0))/AF6 -> 1.4530176 | H6: =$E6/AE6 -> 9.9212434 | I6: =$E6/AF6 -> 9.8230133 | J6: =$E6/AG6 -> 9.2669937 | K6: =$E6/AH6 -> 8.7424468 | M6: =INDEX('TEV Buildouts - Gold Solution'!$C$1:$I$63,58,MATCH('Compsheet - Gold Solution'!$B6,'TEV Buildouts - Gold Solution'!$C$1:$I$1,0))/$E6 -> 0.062370236 | N6: =INDEX('TEV Buildouts - Gold Solution'!$C$1:$I$63,59,MATCH('Compsheet - Gold Solution'!$B6,'TEV Buildouts - Gold Solution'!$C$1:$I$1,0))/$E6 -> 0.045532157 | O6: =INDEX('TEV Buildouts - Gold Solution'!$C$1:$I$63,60,MATCH('Compsheet - Gold Solution'!$B6,'TEV Buildouts - Gold Solution'!$C$1:$I$1,0))/$E6 -> 0.053668756 | P6: =INDEX('TEV Buildouts - Gold Solution'!$C$1:$I$63,61,MATCH('Compsheet - Gold Solution'!$B6,'TEV Buildouts - Gold Solution'!$C$1:$I$1,0))/$E6 -> 0.05907504 | R6: =AF6/AE6-1 -> 0.01 | S6: =AG6/AF6-1 -> 0.06 | T6: =AH6/AG6-1 -> 0.06 | V6: =AE6/INDEX('TEV Buildouts - Gold Solution'!$C$1:$I$63,16,MATCH('Compsheet - Gold Solution'!$B6,'TEV Buildouts - Gold Solution'!$C$1:$I$1,0)) -> 0.36607118 | W6: =AF6/INDEX('TEV Buildouts - Gold Solution'!$C$1:$I$63,17,MATCH('Compsheet - Gold Solution'!$B6,'TEV Buildouts - Gold Solution'!$C$1:$I$1,0)) -> 0.36973189 | X6: =AG6/INDEX('TEV Buildouts - Gold Solution'!$C$1:$I$63,18,MATCH('Compsheet - Gold Solution'!$B6,'TEV Buildouts - Gold Solution'!$C$1:$I$1,0)) -> 0.37684212 | Y6: =AH6/INDEX('TEV Buildouts - Gold Solution'!$C$1:$I$63,19,MATCH('Compsheet - Gold Solution'!$B6,'TEV Buildouts - Gold Solution'!$C$1:$I$1,0)) -> 0.38408908 | AA6: =W6-V6 -> 0.0036607118 | AB6: =X6-W6 -> 0.0071102286 | AC6: =Y6-X6 -> 0.0072469638 | AE6: =INDEX('TEV Buildouts - Gold Solution'!$C$1:$I$63,27,MATCH('Compsheet - Gold Solution'!$B6,'TEV Buildouts - Gold Solution'!$C$1:$I$1,0)) -> 829.898 | AF6: =INDEX('TEV Buildouts - Gold Solution'!$C$1:$I$63,28,MATCH('Compsheet - Gold Solution'!$B6,'TEV Buildouts - Gold Solution'!$C$1:$I$1,0)) -> 838.19698 | AG6: =INDEX('TEV Buildouts - Gold Solution'!$C$1:$I$63,29,MATCH('Compsheet - Gold Solution'!$B6,'TEV Buildouts - Gold Solution'!$C$1:$I$1,0)) -> 888.4888 | AH6: =INDEX('TEV Buildouts - Gold Solution'!$C$1:$I$63,30,MATCH('Compsheet - Gold Solution'!$B6,'TEV Buildouts - Gold Solution'!$C$1:$I$1,0)) -> 941.79813
B7: ='TEV Buildouts - Gold Solution'!G1 -> VMC US EQUITY | C7: =INDEX('TEV Buildouts - Gold Solution'!$C$1:$I$63,2,MATCH('Compsheet - Gold Solution'!$B7,'TEV Buildouts - Gold Solution'!$C$1:$I$1,0)) -> 266.6 | D7: =INDEX('TEV Buildouts - Gold Solution'!$C$1:$I$63,4,MATCH('Compsheet - Gold Solution'!$B7,'TEV Buildouts - Gold Solution'!$C$1:$I$1,0)) -> 35457.8 | E7: =INDEX('TEV Buildouts - Gold Solution'!$C$1:$I$63,13,MATCH('Compsheet - Gold Solution'!$B7,'TEV Buildouts - Gold Solution'!$C$1:$I$1,0)) -> 40627.2 | F7: =INDEX('TEV Buildouts - Gold Solution'!$C$1:$I$63,7,MATCH('Compsheet - Gold Solution'!$B7,'TEV Buildouts - Gold Solution'!$C$1:$I$1,0))/AF7 -> 1.9246939 | H7: =$E7/AE7 -> 19.748785 | I7: =$E7/AF7 -> 16.582531 | J7: =$E7/AG7 -> 15.075028 | K7: =$E7/AH7 -> 13.704571 | M7: =INDEX('TEV Buildouts - Gold Solution'!$C$1:$I$63,58,MATCH('Compsheet - Gold Solution'!$B7,'TEV Buildouts - Gold Solution'!$C$1:$I$1,0))/$E7 -> 0.027426502 | N7: =INDEX('TEV Buildouts - Gold Solution'!$C$1:$I$63,59,MATCH('Compsheet - Gold Solution'!$B7,'TEV Buildouts - Gold Solution'!$C$1:$I$1,0))/$E7 -> 0.031278306 | O7: =INDEX('TEV Buildouts - Gold Solution'!$C$1:$I$63,60,MATCH('Compsheet - Gold Solution'!$B7,'TEV Buildouts - Gold Solution'!$C$1:$I$1,0))/$E7 -> 0.036313726 | P7: =INDEX('TEV Buildouts - Gold Solution'!$C$1:$I$63,61,MATCH('Compsheet - Gold Solution'!$B7,'TEV Buildouts - Gold Solution'!$C$1:$I$1,0))/$E7 -> 0.041852687 | R7: =AF7/AE7-1 -> 0.19093914 | S7: =AG7/AF7-1 -> 0.1 | T7: =AH7/AG7-1 -> 0.1 | V7: =AE7/INDEX('TEV Buildouts - Gold Solution'!$C$1:$I$63,16,MATCH('Compsheet - Gold Solution'!$B7,'TEV Buildouts - Gold Solution'!$C$1:$I$1,0)) -> 0.27732542 | W7: =AF7/INDEX('TEV Buildouts - Gold Solution'!$C$1:$I$63,17,MATCH('Compsheet - Gold Solution'!$B7,'TEV Buildouts - Gold Solution'!$C$1:$I$1,0)) -> 0.30581269 | X7: =AG7/INDEX('TEV Buildouts - Gold Solution'!$C$1:$I$63,18,MATCH('Compsheet - Gold Solution'!$B7,'TEV Buildouts - Gold Solution'!$C$1:$I$1,0)) -> 0.31735279 | Y7: =AH7/INDEX('TEV Buildouts - Gold Solution'!$C$1:$I$63,19,MATCH('Compsheet - Gold Solution'!$B7,'TEV Buildouts - Gold Solution'!$C$1:$I$1,0)) -> 0.32932837 | AA7: =W7-V7 -> 0.028487263 | AB7: =X7-W7 -> 0.011540101 | AC7: =Y7-X7 -> 0.011975577 | AE7: =INDEX('TEV Buildouts - Gold Solution'!$C$1:$I$63,27,MATCH('Compsheet - Gold Solution'!$B7,'TEV Buildouts - Gold Solution'!$C$1:$I$1,0)) -> 2057.2 | AF7: =INDEX('TEV Buildouts - Gold Solution'!$C$1:$I$63,28,MATCH('Compsheet - Gold Solution'!$B7,'TEV Buildouts - Gold Solution'!$C$1:$I$1,0)) -> 2450 | AG7: =INDEX('TEV Buildouts - Gold Solution'!$C$1:$I$63,29,MATCH('Compsheet - Gold Solution'!$B7,'TEV Buildouts - Gold Solution'!$C$1:$I$1,0)) -> 2695 | AH7: =INDEX('TEV Buildouts - Gold Solution'!$C$1:$I$63,30,MATCH('Compsheet - Gold Solution'!$B7,'TEV Buildouts - Gold Solution'!$C$1:$I$1,0)) -> 2964.5
B8: ='TEV Buildouts - Gold Solution'!H1 -> MLM US EQUITY | C8: =INDEX('TEV Buildouts - Gold Solution'!$C$1:$I$63,2,MATCH('Compsheet - Gold Solution'!$B8,'TEV Buildouts - Gold Solution'!$C$1:$I$1,0)) -> 565.03 | D8: =INDEX('TEV Buildouts - Gold Solution'!$C$1:$I$63,4,MATCH('Compsheet - Gold Solution'!$B8,'TEV Buildouts - Gold Solution'!$C$1:$I$1,0)) -> 34466.83 | E8: =INDEX('TEV Buildouts - Gold Solution'!$C$1:$I$63,13,MATCH('Compsheet - Gold Solution'!$B8,'TEV Buildouts - Gold Solution'!$C$1:$I$1,0)) -> 40155.83 | F8: =INDEX('TEV Buildouts - Gold Solution'!$C$1:$I$63,7,MATCH('Compsheet - Gold Solution'!$B8,'TEV Buildouts - Gold Solution'!$C$1:$I$1,0))/AF8 -> 2.3613333 | H8: =$E8/AE8 -> 19.43651 | I8: =$E8/AF8 -> 17.847036 | J8: =$E8/AG8 -> 16.525033 | K8: =$E8/AH8 -> 15.300956 | M8: =INDEX('TEV Buildouts - Gold Solution'!$C$1:$I$63,58,MATCH('Compsheet - Gold Solution'!$B8,'TEV Buildouts - Gold Solution'!$C$1:$I$1,0))/$E8 -> 0.022054207 | N8: =INDEX('TEV Buildouts - Gold Solution'!$C$1:$I$63,59,MATCH('Compsheet - Gold Solution'!$B8,'TEV Buildouts - Gold Solution'!$C$1:$I$1,0))/$E8 -> 0.028529481 | O8: =INDEX('TEV Buildouts - Gold Solution'!$C$1:$I$63,60,MATCH('Compsheet - Gold Solution'!$B8,'TEV Buildouts - Gold Solution'!$C$1:$I$1,0))/$E8 -> 0.032306019 | P8: =INDEX('TEV Buildouts - Gold Solution'!$C$1:$I$63,61,MATCH('Compsheet - Gold Solution'!$B8,'TEV Buildouts - Gold Solution'!$C$1:$I$1,0))/$E8 -> 0.036384679 | R8: =AF8/AE8-1 -> 0.089060987 | S8: =AG8/AF8-1 -> 0.08 | T8: =AH8/AG8-1 -> 0.08 | V8: =AE8/INDEX('TEV Buildouts - Gold Solution'!$C$1:$I$63,16,MATCH('Compsheet - Gold Solution'!$B8,'TEV Buildouts - Gold Solution'!$C$1:$I$1,0)) -> 0.31609547 | W8: =AF8/INDEX('TEV Buildouts - Gold Solution'!$C$1:$I$63,17,MATCH('Compsheet - Gold Solution'!$B8,'TEV Buildouts - Gold Solution'!$C$1:$I$1,0)) -> 0.3200569 | X8: =AG8/INDEX('TEV Buildouts - Gold Solution'!$C$1:$I$63,18,MATCH('Compsheet - Gold Solution'!$B8,'TEV Buildouts - Gold Solution'!$C$1:$I$1,0)) -> 0.32609571 | Y8: =AH8/INDEX('TEV Buildouts - Gold Solution'!$C$1:$I$63,19,MATCH('Compsheet - Gold Solution'!$B8,'TEV Buildouts - Gold Solution'!$C$1:$I$1,0)) -> 0.33224846 | AA8: =W8-V8 -> 0.0039614278 | AB8: =X8-W8 -> 0.0060388094 | AC8: =Y8-X8 -> 0.0061527492 | AE8: =INDEX('TEV Buildouts - Gold Solution'!$C$1:$I$63,27,MATCH('Compsheet - Gold Solution'!$B8,'TEV Buildouts - Gold Solution'!$C$1:$I$1,0)) -> 2066 | AF8: =INDEX('TEV Buildouts - Gold Solution'!$C$1:$I$63,28,MATCH('Compsheet - Gold Solution'!$B8,'TEV Buildouts - Gold Solution'!$C$1:$I$1,0)) -> 2250 | AG8: =INDEX('TEV Buildouts - Gold Solution'!$C$1:$I$63,29,MATCH('Compsheet - Gold Solution'!$B8,'TEV Buildouts - Gold Solution'!$C$1:$I$1,0)) -> 2430 | AH8: =INDEX('TEV Buildouts - Gold Solution'!$C$1:$I$63,30,MATCH('Compsheet - Gold Solution'!$B8,'TEV Buildouts - Gold Solution'!$C$1:$I$1,0)) -> 2624.4
B9: ='TEV Buildouts - Gold Solution'!I1 -> AMRZ US EQUITY | C9: =INDEX('TEV Buildouts - Gold Solution'!$C$1:$I$63,2,MATCH('Compsheet - Gold Solution'!$B9,'TEV Buildouts - Gold Solution'!$C$1:$I$1,0)) -> 49.6 | D9: =INDEX('TEV Buildouts - Gold Solution'!$C$1:$I$63,4,MATCH('Compsheet - Gold Solution'!$B9,'TEV Buildouts - Gold Solution'!$C$1:$I$1,0)) -> 27413.92 | E9: =INDEX('TEV Buildouts - Gold Solution'!$C$1:$I$63,13,MATCH('Compsheet - Gold Solution'!$B9,'TEV Buildouts - Gold Solution'!$C$1:$I$1,0)) -> 33004.92 | F9: =INDEX('TEV Buildouts - Gold Solution'!$C$1:$I$63,7,MATCH('Compsheet - Gold Solution'!$B9,'TEV Buildouts - Gold Solution'!$C$1:$I$1,0))/AF9 -> 1.5002769 | H9: =$E9/AE9 -> 10.375643 | I9: =$E9/AF9 -> 9.8815646 | J9: =$E9/AG9 -> 9.0656556 | K9: =$E9/AH9 -> 8.3171153 | M9: =INDEX('TEV Buildouts - Gold Solution'!$C$1:$I$63,58,MATCH('Compsheet - Gold Solution'!$B9,'TEV Buildouts - Gold Solution'!$C$1:$I$1,0))/$E9 -> 0.060302449 | N9: =INDEX('TEV Buildouts - Gold Solution'!$C$1:$I$63,59,MATCH('Compsheet - Gold Solution'!$B9,'TEV Buildouts - Gold Solution'!$C$1:$I$1,0))/$E9 -> 0.061613898 | O9: =INDEX('TEV Buildouts - Gold Solution'!$C$1:$I$63,60,MATCH('Compsheet - Gold Solution'!$B9,'TEV Buildouts - Gold Solution'!$C$1:$I$1,0))/$E9 -> 0.06915066 | P9: =INDEX('TEV Buildouts - Gold Solution'!$C$1:$I$63,61,MATCH('Compsheet - Gold Solution'!$B9,'TEV Buildouts - Gold Solution'!$C$1:$I$1,0))/$E9 -> 0.07736573 | R9: =AF9/AE9-1 -> 0.05 | S9: =AG9/AF9-1 -> 0.09 | T9: =AH9/AG9-1 -> 0.09 | V9: =AE9/INDEX('TEV Buildouts - Gold Solution'!$C$1:$I$63,16,MATCH('Compsheet - Gold Solution'!$B9,'TEV Buildouts - Gold Solution'!$C$1:$I$1,0)) -> 0.27178742 | W9: =AF9/INDEX('TEV Buildouts - Gold Solution'!$C$1:$I$63,17,MATCH('Compsheet - Gold Solution'!$B9,'TEV Buildouts - Gold Solution'!$C$1:$I$1,0)) -> 0.27440076 | X9: =AG9/INDEX('TEV Buildouts - Gold Solution'!$C$1:$I$63,18,MATCH('Compsheet - Gold Solution'!$B9,'TEV Buildouts - Gold Solution'!$C$1:$I$1,0)) -> 0.28216682 | Y9: =AH9/INDEX('TEV Buildouts - Gold Solution'!$C$1:$I$63,19,MATCH('Compsheet - Gold Solution'!$B9,'TEV Buildouts - Gold Solution'!$C$1:$I$1,0)) -> 0.29015268 | AA9: =W9-V9 -> 0.0026133406 | AB9: =X9-W9 -> 0.0077660594 | AC9: =Y9-X9 -> 0.0079858535 | AE9: =INDEX('TEV Buildouts - Gold Solution'!$C$1:$I$63,27,MATCH('Compsheet - Gold Solution'!$B9,'TEV Buildouts - Gold Solution'!$C$1:$I$1,0)) -> 3181 | AF9: =INDEX('TEV Buildouts - Gold Solution'!$C$1:$I$63,28,MATCH('Compsheet - Gold Solution'!$B9,'TEV Buildouts - Gold Solution'!$C$1:$I$1,0)) -> 3340.05 | AG9: =INDEX('TEV Buildouts - Gold Solution'!$C$1:$I$63,29,MATCH('Compsheet - Gold Solution'!$B9,'TEV Buildouts - Gold Solution'!$C$1:$I$1,0)) -> 3640.6545 | AH9: =INDEX('TEV Buildouts - Gold Solution'!$C$1:$I$63,30,MATCH('Compsheet - Gold Solution'!$B9,'TEV Buildouts - Gold Solution'!$C$1:$I$1,0)) -> 3968.3134
B11: Median | F11: =MEDIAN(F3:F9) -> 1.8625225 | H11: =MEDIAN(H3:H9) -> 12.097175 | I11: =MEDIAN(I3:I9) -> 10.272454 | J11: =MEDIAN(J3:J9) -> 9.344331 | K11: =MEDIAN(K3:K9) -> 8.7424468 | M11: =MEDIAN(M3:M9) -> 0.039479257 | N11: =MEDIAN(N3:N9) -> 0.045532157 | O11: =MEDIAN(O3:O9) -> 0.053668756 | P11: =MEDIAN(P3:P9) -> 0.059830724 | R11: =MEDIAN(R3:R9) -> 0.089060987 | S11: =MEDIAN(S3:S9) -> 0.09 | T11: =MEDIAN(T3:T9) -> 0.09 | V11: =MEDIAN(V3:V9) -> 0.27178742 | W11: =MEDIAN(W3:W9) -> 0.27440076 | X11: =MEDIAN(X3:X9) -> 0.28216682 | Y11: =MEDIAN(Y3:Y9) -> 0.29015268 | AA11: =MEDIAN(AA3:AA9) -> 0.0059616723 | AB11: =MEDIAN(AB3:AB9) -> 0.0071102286 | AC11: =MEDIAN(AC3:AC9) -> 0.0072469638
B12: Mean | F12: =AVERAGE(F3:F9) -> 1.9229394 | H12: =AVERAGE(H3:H9) -> 13.693839 | I12: =AVERAGE(I3:I9) -> 12.168448 | J12: =AVERAGE(J3:J9) -> 11.189333 | K12: =AVERAGE(K3:K9) -> 10.290553 | M12: =AVERAGE(M3:M9) -> 0.041220439 | N12: =AVERAGE(N3:N9) -> 0.04367561 | O12: =AVERAGE(O3:O9) -> 0.05037363 | P12: =AVERAGE(P3:P9) -> 0.057194361 | R12: =AVERAGE(R3:R9) -> 0.12187166 | S12: =AVERAGE(S3:S9) -> 0.087142857 | T12: =AVERAGE(T3:T9) -> 0.087142857 | V12: =AVERAGE(V3:V9) -> 0.24086433 | W12: =AVERAGE(W3:W9) -> 0.25050299 | X12: =AVERAGE(X3:X9) -> 0.25834116 | Y12: =AVERAGE(Y3:Y9) -> 0.26646358 | AA12: =AVERAGE(AA3:AA9) -> 0.0096386595 | AB12: =AVERAGE(AB3:AB9) -> 0.0078381715 | AC12: =AVERAGE(AC3:AC9) -> 0.0081224166

Sheet TEV Buildouts - Gold Solution
B1: 7/18/2025 in mm | C1: CRH US EQUITY | D1: GVA US EQUITY | E1: KNF US EQUITY | F1: EXP US EQUITY | G1: VMC US EQUITY | H1: MLM US EQUITY | I1: AMRZ US EQUITY
B2: Sh Px | C2: 94.06 | D2: 94.04 | E2: 80.57 | F2: 215.12 | G2: 266.6 | H2: 565.03 | I2: 49.6
B3: Dilut. Sh Out | C3: 676.7 | D3: 43.463 | E3: 56.6 | F3: =33.264197 -> 33.264197 | G3: 133 | H3: 61 | I3: =552.7 -> 552.7
B4: EqV | C4: =C2*C3 -> 63650.402 | D4: =D2*D3 -> 4087.2605 | E4: =E2*E3 -> 4560.262 | F4: =F2*F3 -> 7155.7941 | G4: =G2*G3 -> 35457.8 | H4: =H2*H3 -> 34466.83 | I4: =I2*I3 -> 27413.92
B5: (+) Debt | C5: =1458+14213 -> 15671 | D5: =1119+738.595 -> 1857.595 | E5: =11.8+1160.4 -> 1172.2 | F5: =15+1223.316 -> 1238.316 | G5: =4907.9+0.5 -> 4908.4 | H5: =125+5289 -> 5414 | I5: =5046+5 -> 5051
B6: (-) Cash | C6: -3352 | D6: =-379.074-43.708-90.295 -> -513.077 | E6: -138.5 | F6: =-20.401 -> -20.401 | G6: =-181.3-11.6 -> -192.9 | H6: =-101 -> -101 | I6: -40
B7: Net Debt | C7: =SUM(C5:C6) -> 12319 | D7: =SUM(D5:D6) -> 1344.518 | E7: =SUM(E5:E6) -> 1033.7 | F7: =SUM(F5:F6) -> 1217.915 | G7: =SUM(G5:G6) -> 4715.5 | H7: =SUM(H5:H6) -> 5313 | I7: =SUM(I5:I6) -> 5011
B8: (+) NCI/ Equity Inv. | C8: =-732+379+859 -> 506 | D8: =-151.499-93.667+44.763 -> -200.403 | E8: =-52.4 -> -52.4 | F8: =-140.089 -> -140.089 | G8: =24.4 -> 24.4 | H8: 3 | I8: =-1 -> -1
B9: (+) Pension | C9: =229 -> 229 | D9: 0 | E9: 0 | F9: 0 | G9: 0 | H9: 0 | I9: =23+235 -> 258
B10: (+) ARO Liabilities | C10: =339 -> 339 | D10: =55.553 -> 55.553 | E10: 59.43 | F10: 0 | G10: 429.5 | H10: 373 | I10: =27+242+54 -> 323
B11: Other debt-like items | C11: =SUM(C8:C10) -> 1074 | D11: =SUM(D8:D10) -> -144.85 | E11: =SUM(E8:E10) -> 7.03 | F11: =SUM(F8:F10) -> -140.089 | G11: =SUM(G8:G10) -> 453.9 | H11: =SUM(H8:H10) -> 376 | I11: =SUM(I8:I10) -> 580
B13: TEV | C13: =SUM(C4,C7,C11) -> 77043.402 | D13: =SUM(D4,D7,D11) -> 5286.9285 | E13: =SUM(E4,E7,E11) -> 5600.992 | F13: =SUM(F4,F7,F11) -> 8233.6201 | G13: =SUM(G4,G7,G11) -> 40627.2 | H13: =SUM(H4,H7,H11) -> 40155.83 | I13: =SUM(I4,I7,I11) -> 33004.92
B15: '23 Revenue | C15: 34949 | D15: 3509.138 | E15: 2830.35 | F15: 2252.717 | G15: 7782 | H15: 6777.2 | I15: 11677
B16: '24 Revenue | C16: 35572 | D16: 4007.574 | E16: 2899.005 | F16: 2267.04 | G16: 7418 | H16: 6536 | I16: 11704
B17: '25 Revenue Est. | C17: =C16*(1+C22) -> 36994.88 | D17: =AVERAGE(4200,4400) -> 4300 | E17: =AVERAGE(3250,3450) -> 3350 | F17: =F16*(1+F22) -> 2267.04 | G17: =G16*(1+G22) -> 8011.44 | H17: =AVERAGE(6830,7230) -> 7030 | I17: =I16*(1+I22) -> 12172.16
B18: '26 Revenue Est. | C18: =C17*(1+C23) -> 38474.675 | D18: =D17*(1+D23) -> 4558 | E18: =E17*(1+E23) -> 3484 | F18: =F17*(1+F23) -> 2357.7216 | G18: =G17*(1+G23) -> 8492.1264 | H18: =H17*(1+H23) -> 7451.8 | I18: =I17*(1+I23) -> 12902.49
B19: '27 Revenue Est. | C19: =C18*(1+C24) -> 40013.662 | D19: =D18*(1+D24) -> 4831.48 | E19: =E18*(1+E24) -> 3623.36 | F19: =F18*(1+F24) -> 2452.0305 | G19: =G18*(1+G24) -> 9001.654 | H19: =H18*(1+H24) -> 7898.908 | I19: =I18*(1+I24) -> 13676.639
B21: '24 % Rev Growth | C21: =C16/C15-1 -> 0.017825975 | D21: =D16/D15-1 -> 0.14203944 | E21: =E16/E15-1 -> 0.024256717 | F21: =F16/F15-1 -> 0.0063581 | G21: =G16/G15-1 -> -0.046774608 | H21: =H16/H15-1 -> -0.035589919 | I21: =I16/I15-1 -> 0.0023122377
B22: '25 % Rev Growth | C22: 0.04 | D22: =D17/D16-1 -> 0.072968334 | E22: =E17/E16-1 -> 0.15556889 | F22: 0 | G22: 0.08 | H22: =H17/H16-1 -> 0.075581395 | I22: 0.04
B23: '26 % Rev Growth | C23: 0.04 | D23: 0.06 | E23: 0.04 | F23: 0.04 | G23: 0.06 | H23: 0.06 | I23: 0.06
B24: '27 % Rev Growth | C24: 0.04 | D24: 0.06 | E24: 0.04 | F24: 0.04 | G24: 0.06 | H24: 0.06 | I24: 0.06
B26: '23 Adj. EBITDA | C26: 6176 | D26: 279.402 | E26: 432.4 | F26: 851.758 | G26: 2011 | H26: 2127.7 | I26: 2844
B27: '24 Adj. EBITDA | C27: 6930 | D27: 401.738 | E27: 463 | F27: 829.898 | G27: 2057.2 | H27: 2066 | I27: 3181
B28: '25 Adj. EBITDA Est. | C28: =C55 -> 7500 | D28: =D55 -> 495 | E28: =E55 -> 555 | F28: =F27*(1+F33) -> 838.19698 | G28: =G55 -> 2450 | H28: =H55 -> 2250 | I28: =I27*(1+I33) -> 3340.05
B29: '26 Adj. EBITDA Est. | C29: =C28*(1+C34) -> 8250 | D29: =D28*(1+D34) -> 544.5 | E29: =E28*(1+E34) -> 599.4 | F29: =F28*(1+F34) -> 888.4888 | G29: =G28*(1+G34) -> 2695 | H29: =H28*(1+H34) -> 2430 | I29: =I28*(1+I34) -> 3640.6545
B30: '27 Adj. EBITDA Est. | C30: =C29*(1+C35) -> 9075 | D30: =D29*(1+D35) -> 598.95 | E30: =E29*(1+E35) -> 647.352 | F30: =F29*(1+F35) -> 941.79813 | G30: =G29*(1+G35) -> 2964.5 | H30: =H29*(1+H35) -> 2624.4 | I30: =I29*(1+I35) -> 3968.3134
B32: '24 % EBITDA Growth | C32: =C27/C26-1 -> 0.12208549 | D32: =D27/D26-1 -> 0.43784941 | E32: =E27/E26-1 -> 0.070767808 | F32: =F27/F26-1 -> -0.025664567 | G32: =G27/G26-1 -> 0.022973645 | H32: =H27/H26-1 -> -0.028998449 | I32: =I27/I26-1 -> 0.11849508
B33: '25 % EBITDA Growth | C33: =C28/C27-1 -> 0.082251082 | D33: =D28/D27-1 -> 0.23214632 | E33: =E28/E27-1 -> 0.1987041 | F33: 0.01 | G33: =G28/G27-1 -> 0.19093914 | H33: =H28/H27-1 -> 0.089060987 | I33: 0.05
B34: '26 % EBITDA Growth | C34: 0.1 | D34: 0.1 | E34: 0.08 | F34: 0.06 | G34: 0.1 | H34: 0.08 | I34: 0.09
B35: '27 % EBITDA Growth | C35: 0.1 | D35: 0.1 | E35: 0.08 | F35: 0.06 | G35: 0.1 | H35: 0.08 | I35: 0.09
B37: '23 EBITDA Margin | C37: =C26/C15 -> 0.17671464 | D37: =D26/D15 -> 0.079621263 | E37: =E26/E15 -> 0.15277263 | F37: =F26/F15 -> 0.37810253 | G37: =G26/G15 -> 0.25841686 | H37: =H26/H15 -> 0.31394971 | I37: =I26/I15 -> 0.24355571
B38: '24 EBITDA Margin | C38: =C27/C16 -> 0.19481615 | D38: =D27/D16 -> 0.10024469 | E38: =E27/E16 -> 0.15970997 | F38: =F27/F16 -> 0.36607118 | G38: =G27/G16 -> 0.27732542 | H38: =H27/H16 -> 0.31609547 | I38: =I27/I16 -> 0.27178742
B39: '25 EBITDA Margin | C39: =C28/C17 -> 0.20273076 | D39: =D28/D17 -> 0.11511628 | E39: =E28/E17 -> 0.16567164 | F39: =F28/F17 -> 0.36973189 | G39: =G28/G17 -> 0.30581269 | H39: =H28/H17 -> 0.3200569 | I39: =I28/I17 -> 0.27440076
B40: '26 EBITDA Margin | C40: =C29/C18 -> 0.21442676 | D40: =D29/D18 -> 0.11946029 | E40: =E29/E18 -> 0.17204363 | F40: =F29/F18 -> 0.37684212 | G40: =G29/G18 -> 0.31735279 | H40: =H29/H18 -> 0.32609571 | I40: =I29/I18 -> 0.28216682
B41: '27 EBITDA Margin | C41: =C30/C19 -> 0.22679754 | D41: =D30/D19 -> 0.12396823 | E41: =E30/E19 -> 0.17866069 | F41: =F30/F19 -> 0.38408908 | G41: =G30/G19 -> 0.32932837 | H41: =H30/H19 -> 0.33224846 | I41: =I30/I19 -> 0.29015268
B43: '23 CAPEX | C43: 1817 | D43: 140.384 | E43: 124.283 | F43: 137.04 | G43: 872.6 | H43: 650.3 | I43: 630
B44: '24 CAPEX | C44: 2578 | D44: 136.405 | E44: 172.427 | F44: 179.432 | G44: 603.5 | H44: 855 | I44: 642
B45: '25 CAPEX Est. | C45: =AVERAGE(3000,2800) -> 2900 | D45: =AVERAGE(140,160) -> 150 | E45: =AVERAGE(5%*3250,7%*3450) -> 202 | F45: =AVERAGE(310,340) -> 325 | G45: 775 | H45: =AVERAGE(775,725) -> 750 | I45: =6%*I17 -> 730.3296
B46: '26 CAPEX Est. | C46: =C45 -> 2900 | D46: =D45 -> 150 | E46: =E45 -> 202 | F46: 300 | G46: =G45 -> 775 | H46: =H45 -> 750 | I46: =I45 -> 730.3296
B47: '27 CAPEX Est. | C47: =C46 -> 2900 | D47: =D46 -> 150 | E47: =E46 -> 202 | F47: 300 | G47: =G46 -> 775 | H47: =H46 -> 750 | I47: =I46 -> 730.3296
...
