Workbook

Sheet BBPTACShadowWks0001
D2: ='TEV Buildouts - Input'!C2 -> 0 | E2: ='TEV Buildouts - Input'!D2 -> 0 | F2: ='TEV Buildouts - Input'!E2 -> 0 | G2: ='TEV Buildouts - Input'!F2 -> 0 | H2: ='TEV Buildouts - Input'!G2 -> 0 | I2: ='TEV Buildouts - Input'!H2 -> 0 | J2: ='TEV Buildouts - Input'!I2 -> 0
D3: ='TEV Buildouts - Input'!$C$3 -> 0
D5: ='TEV Buildouts - Input'!C5 -> 0
D6: ='TEV Buildouts - Input'!C6 -> 0
D7: ='TEV Buildouts - Input'!C7 -> 0
D8: ='TEV Buildouts - Input'!C8 -> 0
D9: ='TEV Buildouts - Input'!C9 -> 0
D10: ='TEV Buildouts - Input'!C10 -> 0
D11: ='TEV Buildouts - Input'!C11 -> 0
D13: ='TEV Buildouts - Input'!$C$13 -> 0
D26: ='TEV Buildouts - Input'!C26 -> 0
D27: ='TEV Buildouts - Input'!C27 -> 0
D34: ='TEV Buildouts - Input'!C34 -> 0.1
D35: ='TEV Buildouts - Input'!C35 -> 0.1
D45: ='TEV Buildouts - Input'!$C$51 -> 0.1725

Sheet BBPTACShadowWks0002
C3: ='Compsheet - Input'!C3 -> 0 | D3: ='Compsheet - Input'!D3 -> 0 | E3: ='Compsheet - Input'!E3 -> 0 | F3: ='Compsheet - Input'!F3 -> 0 | H3: ='Compsheet - Input'!H3 -> 0 | I3: ='Compsheet - Input'!I3 -> 0 | J3: ='Compsheet - Input'!J3 -> 0 | K3: ='Compsheet - Input'!K3 -> 0 | M3: ='Compsheet - Input'!M3 -> 0 | N3: ='Compsheet - Input'!N3 -> 0 | O3: ='Compsheet - Input'!O3 -> 0 | P3: ='Compsheet - Input'!P3 -> 0 | R3: ='Compsheet - Input'!AE3 -> 0 | S3: ='Compsheet - Input'!AF3 -> 0 | T3: ='Compsheet - Input'!AG3 -> 0 | U3: ='Compsheet - Input'!AH3 -> 0 | W3: ='Compsheet - Input'!R3 -> 0 | X3: ='Compsheet - Input'!S3 -> 0 | Y3: ='Compsheet - Input'!T3 -> 0 | AA3: ='Compsheet - Input'!V3 -> 0 | AB3: ='Compsheet - Input'!W3 -> 0 | AC3: ='Compsheet - Input'!X3 -> 0 | AD3: ='Compsheet - Input'!Y3 -> 0 | AF3: ='Compsheet - Input'!AA3 -> 0 | AG3: ='Compsheet - Input'!AB3 -> 0 | AH3: ='Compsheet - Input'!AC3 -> 0
C4: ='Compsheet - Input'!C4 -> 0 | D4: ='Compsheet - Input'!D4 -> 0 | E4: ='Compsheet - Input'!E4 -> 0 | F4: ='Compsheet - Input'!F4 -> 0 | H4: ='Compsheet - Input'!H4 -> 0 | I4: ='Compsheet - Input'!I4 -> 0 | J4: ='Compsheet - Input'!J4 -> 0 | K4: ='Compsheet - Input'!K4 -> 0 | M4: ='Compsheet - Input'!M4 -> 0 | N4: ='Compsheet - Input'!N4 -> 0 | O4: ='Compsheet - Input'!O4 -> 0 | P4: ='Compsheet - Input'!P4 -> 0 | R4: ='Compsheet - Input'!AE4 -> 0 | S4: ='Compsheet - Input'!AF4 -> 0 | T4: ='Compsheet - Input'!AG4 -> 0 | U4: ='Compsheet - Input'!AH4 -> 0 | W4: ='Compsheet - Input'!R4 -> 0 | X4: ='Compsheet - Input'!S4 -> 0 | Y4: ='Compsheet - Input'!T4 -> 0 | AA4: ='Compsheet - Input'!V4 -> 0 | AB4: ='Compsheet - Input'!W4 -> 0 | AC4: ='Compsheet - Input'!X4 -> 0 | AD4: ='Compsheet - Input'!Y4 -> 0 | AF4: ='Compsheet - Input'!AA4 -> 0 | AG4: ='Compsheet - Input'!AB4 -> 0 | AH4: ='Compsheet - Input'!AC4 -> 0
C5: ='Compsheet - Input'!C5 -> 0 | D5: ='Compsheet - Input'!D5 -> 0 | E5: ='Compsheet - Input'!E5 -> 0 | F5: ='Compsheet - Input'!F5 -> 0 | H5: ='Compsheet - Input'!H5 -> 0 | I5: ='Compsheet - Input'!I5 -> 0 | J5: ='Compsheet - Input'!J5 -> 0 | K5: ='Compsheet - Input'!K5 -> 0 | M5: ='Compsheet - Input'!M5 -> 0 | N5: ='Compsheet - Input'!N5 -> 0 | O5: ='Compsheet - Input'!O5 -> 0 | P5: ='Compsheet - Input'!P5 -> 0 | R5: ='Compsheet - Input'!AE5 -> 0 | S5: ='Compsheet - Input'!AF5 -> 0 | T5: ='Compsheet - Input'!AG5 -> 0 | U5: ='Compsheet - Input'!AH5 -> 0 | W5: ='Compsheet - Input'!R5 -> 0 | X5: ='Compsheet - Input'!S5 -> 0 | Y5: ='Compsheet - Input'!T5 -> 0 | AA5: ='Compsheet - Input'!V5 -> 0 | AB5: ='Compsheet - Input'!W5 -> 0 | AC5: ='Compsheet - Input'!X5 -> 0 | AD5: ='Compsheet - Input'!Y5 -> 0 | AF5: ='Compsheet - Input'!AA5 -> 0 | AG5: ='Compsheet - Input'!AB5 -> 0 | AH5: ='Compsheet - Input'!AC5 -> 0
C6: ='Compsheet - Input'!C6 -> 0 | D6: ='Compsheet - Input'!D6 -> 0 | E6: ='Compsheet - Input'!E6 -> 0 | F6: ='Compsheet - Input'!F6 -> 0 | H6: ='Compsheet - Input'!H6 -> 0 | I6: ='Compsheet - Input'!I6 -> 0 | J6: ='Compsheet - Input'!J6 -> 0 | K6: ='Compsheet - Input'!K6 -> 0 | M6: ='Compsheet - Input'!M6 -> 0 | N6: ='Compsheet - Input'!N6 -> 0 | O6: ='Compsheet - Input'!O6 -> 0 | P6: ='Compsheet - Input'!P6 -> 0 | R6: ='Compsheet - Input'!AE6 -> 0 | S6: ='Compsheet - Input'!AF6 -> 0 | T6: ='Compsheet - Input'!AG6 -> 0 | U6: ='Compsheet - Input'!AH6 -> 0 | W6: ='Compsheet - Input'!R6 -> 0 | X6: ='Compsheet - Input'!S6 -> 0 | Y6: ='Compsheet - Input'!T6 -> 0 | AA6: ='Compsheet - Input'!V6 -> 0 | AB6: ='Compsheet - Input'!W6 -> 0 | AC6: ='Compsheet - Input'!X6 -> 0 | AD6: ='Compsheet - Input'!Y6 -> 0 | AF6: ='Compsheet - Input'!AA6 -> 0 | AG6: ='Compsheet - Input'!AB6 -> 0 | AH6: ='Compsheet - Input'!AC6 -> 0
C7: ='Compsheet - Input'!C7 -> 0 | D7: ='Compsheet - Input'!D7 -> 0 | E7: ='Compsheet - Input'!E7 -> 0 | F7: ='Compsheet - Input'!F7 -> 0 | H7: ='Compsheet - Input'!H7 -> 0 | I7: ='Compsheet - Input'!I7 -> 0 | J7: ='Compsheet - Input'!J7 -> 0 | K7: ='Compsheet - Input'!K7 -> 0 | M7: ='Compsheet - Input'!M7 -> 0 | N7: ='Compsheet - Input'!N7 -> 0 | O7: ='Compsheet - Input'!O7 -> 0 | P7: ='Compsheet - Input'!P7 -> 0 | R7: ='Compsheet - Input'!AE7 -> 0 | S7: ='Compsheet - Input'!AF7 -> 0 | T7: ='Compsheet - Input'!AG7 -> 0 | U7: ='Compsheet - Input'!AH7 -> 0 | W7: ='Compsheet - Input'!R7 -> 0 | X7: ='Compsheet - Input'!S7 -> 0 | Y7: ='Compsheet - Input'!T7 -> 0 | AA7: ='Compsheet - Input'!V7 -> 0 | AB7: ='Compsheet - Input'!W7 -> 0 | AC7: ='Compsheet - Input'!X7 -> 0 | AD7: ='Compsheet - Input'!Y7 -> 0 | AF7: ='Compsheet - Input'!AA7 -> 0 | AG7: ='Compsheet - Input'!AB7 -> 0 | AH7: ='Compsheet - Input'!AC7 -> 0
C8: ='Compsheet - Input'!C8 -> 0 | D8: ='Compsheet - Input'!D8 -> 0 | E8: ='Compsheet - Input'!E8 -> 0 | F8: ='Compsheet - Input'!F8 -> 0 | H8: ='Compsheet - Input'!H8 -> 0 | I8: ='Compsheet - Input'!I8 -> 0 | J8: ='Compsheet - Input'!J8 -> 0 | K8: ='Compsheet - Input'!K8 -> 0 | M8: ='Compsheet - Input'!M8 -> 0 | N8: ='Compsheet - Input'!N8 -> 0 | O8: ='Compsheet - Input'!O8 -> 0 | P8: ='Compsheet - Input'!P8 -> 0 | R8: ='Compsheet - Input'!AE8 -> 0 | S8: ='Compsheet - Input'!AF8 -> 0 | T8: ='Compsheet - Input'!AG8 -> 0 | U8: ='Compsheet - Input'!AH8 -> 0 | W8: ='Compsheet - Input'!R8 -> 0 | X8: ='Compsheet - Input'!S8 -> 0 | Y8: ='Compsheet - Input'!T8 -> 0 | AA8: ='Compsheet - Input'!V8 -> 0 | AB8: ='Compsheet - Input'!W8 -> 0 | AC8: ='Compsheet - Input'!X8 -> 0 | AD8: ='Compsheet - Input'!Y8 -> 0 | AF8: ='Compsheet - Input'!AA8 -> 0 | AG8: ='Compsheet - Input'!AB8 -> 0 | AH8: ='Compsheet - Input'!AC8 -> 0
C9: ='Compsheet - Input'!C9 -> 0 | D9: ='Compsheet - Input'!D9 -> 0 | E9: ='Compsheet - Input'!E9 -> 0 | F9: ='Compsheet - Input'!F9 -> 0 | H9: ='Compsheet - Input'!H9 -> 0 | I9: ='Compsheet - Input'!I9 -> 0 | J9: ='Compsheet - Input'!J9 -> 0 | K9: ='Compsheet - Input'!K9 -> 0 | M9: ='Compsheet - Input'!M9 -> 0 | N9: ='Compsheet - Input'!N9 -> 0 | O9: ='Compsheet - Input'!O9 -> 0 | P9: ='Compsheet - Input'!P9 -> 0 | R9: ='Compsheet - Input'!AE9 -> 0 | S9: ='Compsheet - Input'!AF9 -> 0 | T9: ='Compsheet - Input'!AG9 -> 0 | U9: ='Compsheet - Input'!AH9 -> 0 | W9: ='Compsheet - Input'!R9 -> 0 | X9: ='Compsheet - Input'!S9 -> 0 | Y9: ='Compsheet - Input'!T9 -> 0 | AA9: ='Compsheet - Input'!V9 -> 0 | AB9: ='Compsheet - Input'!W9 -> 0 | AC9: ='Compsheet - Input'!X9 -> 0 | AD9: ='Compsheet - Input'!Y9 -> 0 | AF9: ='Compsheet - Input'!AA9 -> 0 | AG9: ='Compsheet - Input'!AB9 -> 0 | AH9: ='Compsheet - Input'!AC9 -> 0

Sheet Compsheet - Input
H1: EV/EBITDA | M1: Est. FCFF Yield | R1: Adj. EBITDA % Growth | V1: Adj. EBITDA Margin % | AA1: Margin Improvement % | AE1: Adj. EBITDA
A2: x | B2: Ticker | C2: Sh Px | D2: Mkt Cap | E2: TEV | F2: ND/EBITDA | H2: EV/'24 EBITDA | I2: EV/'25 EBITDA | J2: EV/'26 EBITDA | K2: EV/'27 EBITDA | M2: '24 FCFF Yield | N2: '25 FCFF Yield | O2: '26 FCFF Yield | P2: '27 FCFF Yield | R2: '25 Growth % | S2: '26 Growth % | T2: '27 Growth % | V2: '24 Margin % | W2: '25 Margin % | X2: '26 Margin % | Y2: '27 Margin % | AA2: '25 % | AB2: '26 % | AC2: '27 % | AE2: '24 EBITDA | AF2: '25 EBITDA | AG2: '26 EBITDA | AH2: '27 EBITDA
B3: ='TEV Buildouts - Input'!C1 -> CRH US EQUITY
B4: ='TEV Buildouts - Input'!D1 -> GVA US EQUITY
B5: ='TEV Buildouts - Input'!E1 -> KNF US EQUITY
B6: ='TEV Buildouts - Input'!F1 -> EXP US EQUITY
B7: ='TEV Buildouts - Input'!G1 -> VMC US EQUITY
B8: ='TEV Buildouts - Input'!H1 -> MLM US EQUITY
B9: ='TEV Buildouts - Input'!I1 -> AMRZ US EQUITY
B11: Median
B12: Mean

Sheet TEV Buildouts - Input
B1: 7/18/2025 in mm | C1: CRH US EQUITY | D1: GVA US EQUITY | E1: KNF US EQUITY | F1: EXP US EQUITY | G1: VMC US EQUITY | H1: MLM US EQUITY | I1: AMRZ US EQUITY
B2: Sh Px
B3: Dilut. Sh Out
B4: EqV
B5: (+) Debt
B6: (-) Cash
B7: Net Debt
B8: (+) NCI/ Equity Inv.
B9: (+) Pension
B10: (+) ARO Liabilities
B11: Other debt-like items
B13: TEV
B15: '23 Revenue
... B21: '24 % Rev Growth
B22: '25 % Rev Growth | C22: 0.04 | F22: 0 | G22: 0.08 | I22: 0.04
B23: '26 % Rev Growth | C23: 0.04 | D23: 0.06 | E23: 0.04 | F23: 0.04 | G23: 0.06 | H23: 0.06 | I23: 0.06
B24: '27 % Rev Growth | C24: 0.04 | D24: 0.06 | E24: 0.04 | F24: 0.04 | G24: 0.06 | H24: 0.06 | I24: 0.06
B26: '23 Adj. EBITDA
B27: '24 Adj. EBITDA
B28: '25 Adj. EBITDA Est.
B29: '26 Adj. EBITDA Est.
B30: '27 Adj. EBITDA Est.
B32: '24 % EBITDA Growth
B33: '25 % EBITDA Growth | F33: 0.01 | I33: 0.05
B34: '26 % EBITDA Growth | C34: 0.1 | D34: 0.1 | E34: 0.08 | F34: 0.06 | G34: 0.1 | H34: 0.08 | I34: 0.09
B35: '27 % EBITDA Growth | C35: 0.1 | D35: 0.1 | E35: 0.08 | F35: 0.06 | G35: 0.1 | H35: 0.08 | I35: 0.09
B37: '23 EBITDA Margin
B38: '24 EBITDA Margin
B39: '25 EBITDA Margin
B40: '26 EBITDA Margin
B41: '27 EBITDA Margin
B43: '23 CAPEX
B44: '24 CAPEX
B45: '25 CAPEX Est.
B46: '26 CAPEX Est. | C46: =C45 -> 0 | D46: =D45 -> 0 | E46: =E45 -> 0 | F46: 300 | G46: =G45 -> 0 | H46: =H45 -> 0 | I46: =I45 -> 0
B47: '27 CAPEX Est. | C47: =C46 -> 0 | D47: =D46 -> 0 | E47: =E46 -> 0 | F47: 300 | G47: =G46 -> 0 | H47: =H46 -> 0 | I47: =I46 -> 0
B49: mCAPEX | C49: 1500 | D49: 100 | E49: 125 | F49: 155 | G49: 600 | H49: 600 | I49: 600
B51: Approx. tax rate on EBITDA | C51: =23%*0.75 -> 0.1725 | D51: =25%*0.75 -> 0.1875 | E51: =20%*0.75 -> 0.15 | F51: =22%*0.75 -> 0.165 | G51: =22%*0.75 -> 0.165 | H51: =21%*0.75 -> 0.1575 | I51: =23%*0.75 -> 0.1725
B53: Low EBITDA Guide
B54: High EBITDA Guide
...
