Workbook
Name \P: #REF!
Name _: #REF!
Name __EPS01: [2]XOM!$F$34
Name __EPS02: [2]XOM!$G$34
Name __EPS03: [2]XOM!$H$34
Name __EPS04: [2]XOM!$I$34
Name __EPS98: [2]XOM!$C$34
Name __EPS99: [2]XOM!$D$34
Name __lag1: [3]Chart!$C$28:$D$108
Name __lag2: [3]Chart!$G$28:$H$108
Name __ta1: #REF!
Name __TA27: #REF!
Name _1_bbl_CFPS: #REF!
Name _1_bbl_DACF: #REF!
Name _1_bbl_EPS: #REF!
Name _10_mmcf_d_CFPS: #REF!
Name _10_mmcf_d_EPS: #REF!
Name _1000_b_d_CFPS: #REF!
Name _1000_b_d_EPS: #REF!
Name _10c_mcf_CFPS: #REF!
Name _10c_mcf_DACF: #REF!
Name _10c_mcf_EPS: #REF!
Name _10Module1_.INTERNAL: #N/A
Name _10Module2_.CLIENTS: #N/A
Name _11Module1_.INTERNAL: #N/A
Name _11Module2_.CLIENTS: #N/A
Name _12Module1_.INTERNAL: #N/A
Name _12Module2_.CLIENTS: #N/A
Name _13Module1_.INTERNAL: #N/A
Name _13Module2_.CLIENTS: #N/A
Name _14Module1_.INTERNAL: #N/A
Name _14Module2_.CLIENTS: #N/A
Name _14Module2_.INTERNAL: #N/A
Name _15Module1_.INTERNAL: #N/A
Name _15Module2_.CLIENTS: #N/A
Name _15Module2_.INTERNAL: #N/A
Name _16Module1_.INTERNAL: #N/A
Name _16Module2_.INTERNAL: #N/A
Name _17Module1_.INTERNAL: #N/A
Name _17Module2_.CLIENTS: #N/A
Name _18Module1_.INTERNAL: #N/A
Name _18Module2_.CLIENTS: #N/A
Name _19Module2_.CLIENTS: #N/A
Name _19Module2_.INTERNAL: #N/A
Name _1Module1_.CLIENTS: #N/A
Name _20Module2_.CLIENTS: #N/A
Name _20Module2_.INTERNAL: #N/A
Name _21Module2_.CLIENTS: #N/A
Name _21Module2_.INTERNAL: #N/A
Name _22Module2_.CLIENTS: #N/A
Name _23Module2_.CLIENTS: #N/A
Name _23Module2_.INTERNAL: #N/A
Name _24Module2_.CLIENTS: #N/A
Name _24Module2_.INTERNAL: #N/A
Name _25_0_0Loan_Loss_Provision_f: #REF!
Name _25Module2_.CLIENTS: #N/A
Name _26_0_0Loan_Loss_Provision_f: #REF!
Name _26Module2_.CLIENTS: #N/A
Name _27_0_0Loan_Loss_Provision_f: #REF!
Name _27Module2_.CLIENTS: #N/A

Sheet MW UPLOAD
A1: Uploaded 244/244 values at 12/18/2024, 1:44:13 PM | D1: Period | E1: Q1 | F1: Q2 | G1: Q3 | H1: Q4 | I1: Q1 | J1: Q2 | K1: Q3 | L1: Q4 | M1: Q1 | N1: Q2 | O1: Q3 | P1: Q4 | Q1: Q1 | R1: Q2 | S1: Q3 | T1: Q4 | U1: Q1 | V1: Q2 | W1: Q3 | X1: Q4 | Y1: Q1 | Z1: Q2 | AA1: Q3 | AB1: Q4 | AC1: FY | AD1: FY | AE1: FY
A2: Namespace | B2: SecurityID | C2: Full metric name in model | D2: Metric name in MW database | E2: 2021 | F2: 2021 | G2: 2021 | H2: 2021 | I2: 2022 | J2: 2022 | K2: 2022 | L2: 2022 | M2: 2023 | N2: 2023 | O2: 2023 | P2: 2023 | Q2: 2024 | R2: 2024 | S2: 2024 | T2: 2024 | U2: 2025 | V2: 2025 | W2: 2025 | X2: 2025 | Y2: 2026 | Z2: 2026 | AA2: 2026 | AB2: 2026 | AC2: 2024 | AD2: 2025 | AE2: 2026
A3: AZAFAR | B3: 3626 | C3: Investment thesis | D3: THESIS
C4: Revenue | D4: SALES
A5: Company | B5: BBTicker | C5: Gross profit | D5: GP
A6: CAT US EQUITY | B6: CAT US | C6: EBITDA | D6: EBITDA | Q6: =Model!AT45 -> 4043 | R6: =Model!AU45 -> 4013 | S6: =Model!AV45 -> 3690 | T6: =Model!AW45 -> 3691.3916 | U6: =Model!AZ45 -> 3773.7288 | V6: =Model!BA45 -> 4000.4081 | W6: =Model!BB45 -> 3696.4937 | X6: =Model!BC45 -> 3804.2113 | Y6: =Model!BF45 -> 4058.7463 | Z6: =Model!BG45 -> 4304.3283 | AA6: =Model!BH45 -> 3995.0545 | AB6: =Model!BI45 -> 4114.994 | AC6: =SUM(Q6:T6) -> 15437.392 | AD6: =SUM(U6:X6) -> 15274.842 | AE6: =SUM(Y6:AB6) -> 16473.123
C7: Operating profit | D7: EBIT | Q7: =Model!AT35 -> 3519 | R7: =Model!AU35 -> 3482 | S7: =Model!AV35 -> 3147 | T7: =Model!AW35 -> 3100.1916 | U7: =Model!AZ35 -> 3231.5688 | V7: =Model!BA35 -> 3450.8981 | W7: =Model!BB35 -> 3134.4737 | X7: =Model!BC35 -> 3192.0793 | Y7: =Model!BF35 -> 3497.6791 | Z7: =Model!BG35 -> 3735.5436 | AA7: =Model!BH35 -> 3413.2261 | AB7: =Model!BI35 -> 3481.056 | AC7: =SUM(Q7:T7) -> 13248.192 | AD7: =SUM(U7:X7) -> 13009.02 | AE7: =SUM(Y7:AB7) -> 14127.505
C8: Adjusted operating profit | D8: AEBIT
C9: Pre-tax profit | D9: PBT
C10: Post-tax profit | D10: PAT
C11: Diluted weighted average shares | D11: WAS | Q11: =Model!AT81 -> 496.9 | R11: =Model!AU81 -> 489.5 | S11: =Model!AV81 -> 486.7 | T11: =Model!AW81 -> 484.47778 | U11: =Model!AZ81 -> 480.31111 | V11: =Model!BA81 -> 476.14444 | W11: =Model!BB81 -> 471.97778 | X11: =Model!BC81 -> 467.81111 | Y11: =Model!BF81 -> 463.64444 | Z11: =Model!BG81 -> 459.47778 | AA11: =Model!BH81 -> 454.61667 | AB11: =Model!BI81 -> 449.75556 | AC11: =T11 -> 484.47778 | AD11: =X11 -> 467.81111 | AE11: =AB11 -> 449.75556
C12: Reported diluted EPS | D12: EPS | Q12: =Model!AT65 -> 5.7476353 | R12: =Model!AU65 -> 5.4770174 | S12: =Model!AV65 -> 5.0626669 | T12: =Model!AW65 -> 4.9192627 | U12: =Model!AZ65 -> 5.1976532 | V12: =Model!BA65 -> 5.6001301 | W12: =Model!BB65 -> 5.1299912 | X12: =Model!BC65 -> 5.2711152 | Y12: =Model!BF65 -> 5.8293077 | Z12: =Model!BG65 -> 6.2833748 | AA12: =Model!BH65 -> 5.8010961 | AB12: =Model!BI65 -> 5.9806781 | AC12: =SUM(Q12:T12) -> 21.206582 | AD12: =SUM(U12:X12) -> 21.19889 | AE12: =SUM(Y12:AB12) -> 23.894457
C13: Adjusted diluted EPS | D13: AEPS | Q13: =Model!AT78 -> 5.598712 | R13: =Model!AU78 -> 5.9918284 | S13: =Model!AV78 -> 5.1736182 | T13: =Model!AW78 -> 5.1070939 | U13: =Model!AZ78 -> 5.1976532 | V13: =Model!BA78 -> 5.6001301 | W13: =Model!BB78 -> 5.1299912 | X13: =Model!BC78 -> 5.2711152 | Y13: =Model!BF78 -> 5.8293077 | Z13: =Model!BG78 -> 6.2833748 | AA13: =Model!BH78 -> 5.8010961 | AB13: =Model!BI78 -> 5.9806781 | AC13: =SUM(Q13:T13) -> 21.871253 | AD13: =SUM(U13:X13) -> 21.19889 | AE13: =SUM(Y13:AB13) -> 23.894457
C14: Dividend per share | D14: DPS
C15: Free Cash Flow | D15: FCF | Q15: =Model!AT162+Model!AT165 -> 1552 | R15: =Model!AU162+Model!AU165 -> 2680 | S15: =Model!AV162+Model!AV165 -> 3125 | T15: =Model!AW162+Model!AW165 -> 3568.6433 | U15: =Model!AZ162+Model!AZ165 -> 679.32546 | V15: =Model!BA162+Model!BA165 -> 2876.0156 | W15: =Model!BB162+Model!BB165 -> 2890.2851 | X15: =Model!BC162+Model!BC165 -> 3607.5332 | Y15: =Model!BF162+Model!BF165 -> 531.52503 | Z15: =Model!BG162+Model!BG165 -> 3077.9689 | AA15: =Model!BH162+Model!BH165 -> 3108.0668 | AB15: =Model!BI162+Model!BI165 -> 3834.5733 | AC15: =SUM(Q15:T15) -> 10925.643 | AD15: =SUM(U15:X15) -> 10053.159 | AE15: =SUM(Y15:AB15) -> 10552.134
C16: Net debt including lease liabilities | D16: ND | Q16: =Model!AT122-Model!AT99 -> 19872 | R16: =Model!AU122-Model!AU99 -> 19495 | S16: =Model!AV122-Model!AV99 -> 20146 | T16: =Model!AW122-Model!AW99 -> 18156.945 | U16: =Model!AZ122-Model!AZ99 -> 19732.334 | V16: =Model!BA122-Model!BA99 -> 19215.157 | W16: =Model!BB122-Model!BB99 -> 18619.792 | X16: =Model!BC122-Model!BC99 -> 17320.835 | Y16: =Model!BF122-Model!BF99 -> 19072.541 | Z16: =Model!BG122-Model!BG99 -> 18381.457 | AA16: =Model!BH122-Model!BH99 -> 17846.953 | AB16: =Model!BI122-Model!BI99 -> 16597.946 | AC16: =T16 -> 18156.945 | AD16: =X16 -> 17320.835 | AE16: =AB16 -> 16597.946
C17: Net debt ex lease liabilities | D17: NDXL
C18: Shareholders' funds | D18: EQUITY
C19: M&A sales growth | D19: MAG
C20: Organic sales growth | D20: OSG
C21: Adj gross profit | D21: GPA
C22: Share of adj assocs in EBIT | D22: JVEBIT
C23: Other income/expense in EBIT | D23: OTHEREBIT
C24: Total one-offs in EBIT | D24: EXINEBIT
C25: Net interest on debt | D25: NINT
C26: Net finance charge | D26: NFC
C27: Share of adj assocs below EBIT | D27: JVPBTA
C28: Other income/expense below EBIT | D28: OTHERPBT
... C35: Reported PAT | D35: RPAT
C36: Net capex | D36: CAPEX | Q36: =-Model!AT86 -> 500 | R36: =-Model!AU86 -> 341 | S36: =-Model!AV86 -> 444 | T36: =-Model!AW86 -> 647.8 | U36: =-Model!AZ86 -> 541.14 | V36: =-Model!BA86 -> 386.3 | W36: =-Model!BB86 -> 491.12 | X36: =-Model!BC86 -> 709.166 | Y36: =-Model!BF86 -> 584.0238 | Z36: =-Model!BG86 -> 433.652 | AA36: =-Model!BH86 -> 540.4154 | AB36: =-Model!BI86 -> 773.46182 | AC36: =-[52]Model!BG97 -> 884.57722 | AD36: =-[52]Model!BH97 -> 883.5114 | AE36: =-[52]Model!BI97 -> 904.45938
C37: Change in WC | D37: DWC
C38: New capitalised leases | D38: CFLEASE
C39: Acquisitions | D39: ACQS
C40: Disposals | D40: DISP
C41: Dividends paid | D41: DIVP
C42: Net equity issues/buy-backs | D42: SBB
C43: Property, plant and equipment | D43: PPE
C44: Intangible fixed assets | D44: INTANGIBLES
C45: Operating net working capital | D45: OWC
C46: Invested capital | D46: IC
...

Sheet Capitalization
A1: TO Fix this sheet --> TEV does it include Finco? Likely need to edit it out of debt assuming street does not count it. | S1: BEST_CONSENSUS_STAT_OVERRIDE
B2: CAT US EQUITY | C2: KEX | F2: Int. Rate | G2: Int. Exp | H2: / | I2: / | J2: Facility | S2: MEAN
E3: ($mm) | F3: (%) | G3: ($mm) | H3: 22 EBITDA | I3: 23 EBITDA | J3: ($mm) | S3: BEST_FPERIOD_OVERRIDE
B5: Revolving Credit Facility ($mm) | E5: 0 | F5: 0.02 | G5: =E5*F5 -> 0 | J5: 850
B6: Term Loan Due 2024 ($mm) | E6: 305 | F6: 0.02 | G6: =E6*F6 -> 6.1
B7: 3.29% Senior Notes due Feb 2023 ($mm) | E7: 350 | F7: 0.0329 | G7: =E7*F7 -> 11.515
B8: 4.2% Senior Notes due March 2028 ($mm) | E8: 500 | F8: 0.042 | G8: =E8*F8 -> 21
E9: 0 | F9: 0.08625 | G9: =E9*F9 -> 0
E10: 0 | F10: 0.081 | G10: =E10*F10 -> 0
E11: 0 | F11: 0.06251 | G11: =E11*F11 -> 0
E12: 0 | F12: 0.034 | G12: =E12*F12 -> 0
E13: 0 | F13: 0.0335 | G13: =E13*F13 -> 0
E14: 0 | F14: 0.026 | G14: =E14*F14 -> 0
E15: 0 | F15: 0.0725 | G15: =E15*F15 -> 0
E16: 0 | F16: 0.0795 | G16: =E16*F16 -> 0
E17: 0 | F17: 0.0325 | G17: =E17*F17 -> 0
E18: 0 | F18: 0.038 | G18: =E18*F18 -> 0
E19: 0 | F19: 0.068 | G19: =E19*F19 -> 0
E20: 0 | F20: 0.0425 | G20: =E20*F20 -> 0
... E41: 0 | F41: 0.0465 | G41: =E41*F41 -> 0
B74: Others ($mm) | E74: 3.097 | F74: 0.02 | G74: =E74*F74 -> 0.06194
B75: Total Debt ($mm) | E75: =SUM(E5:E74) -> 1158.097 | G75: =SUM(G5:G74) -> 38.67694 | H75: =$E75/$E$88 -> #NAME? | I75: =$E75/$E$89 -> #NAME?
B76: Less: Investments ($mm) | E76: 0
B77: Less: Cash ($mm) | E77: =-32.398 -> -32.398
B78: Net Debt ($mm) | E78: =E75+E77+E76 -> 1125.699 | H78: =$E78/$E$88 -> #NAME? | I78: =$E78/$E$89 -> #NAME?
B80: Shares Outstanding (mm) | E80: 60.3
B81: Share Price ($/share) | E81: {=_xll.BDP("kex us equity","px_last")} -> #NAME?
B82: Equity Value ($mm) | E82: =E80*E81 -> #NAME? | H82: =$E82/$E$88 -> #NAME? | I82: =$E82/$E$89 -> #NAME?
B84: Enterprise Value ($mm) | E84: =E82+E78 -> #NAME? | H84: =$E84/$E$88 -> #NAME? | I84: =$E84/$E$89 -> #NAME?
E87: Consensus
B88: 2022 EBITDA ($mm) | D88: =Model!AL35 -> 7904 | E88: ='Relative to Street'!R18 -> #NAME? | H88: FY2
B89: 2023 EBITDA ($mm) | D89: =Model!AR35 -> 12966 | E89: ='Relative to Street'!S18 -> #NAME? | F89: =E89/E88-1 -> #NAME? | H89: FY3
B90: 2022 CFPS ($mm) | D90: =Model!AL162/Model!AL81 -> 14.646958 | E90: ='Relative to Street'!R47 -> #NAME? | F90: =$E$80/E90 -> #NAME?
B91: 2023 CFPS ($mm) | D91: =Model!AR162/Model!AR81 -> 25.092502 | E91: ='Relative to Street'!S47 -> #NAME? | F91: =$E$80/E91 -> #NAME?
B92: 2022 EPS ($) | D92: =Model!AL78 -> 13.84162 | E92: ='Relative to Street'!R41 -> #NAME? | F92: =$E$81/E92 -> #NAME? | G92: =D92/E92-1 -> #NAME?
B93: 2023 EPS ($) | D93: =Model!AR78 -> 21.2074 | E93: ='Relative to Street'!S41 -> #NAME? | F93: =$E$81/E93 -> #NAME? | G93: =D93/E93-1 -> #NAME?

Sheet Relative to Street
F1: 2 | R1: 2 | S1: 3
B2: CAT US EQUITY | F2: 22Q1 | G2: 22Q2 | H2: 22Q3 | I2: 22Q4 | J2: 23Q1 | K2: 23Q2 | L2: 23Q3 | M2: 23Q4 | N2: 24Q1 | O2: 24Q2 | P2: 24Q3 | Q2: 24Q4 | R2: 22Y | S2: 23Y | T2: 24Y | U2: 25Y | V2: 26Y
F3: Q1 2022 | G3: Q2 2022 | H3: Q3 2022 | I3: Q4 2022 | J3: Q1 2023 | K3: Q2 2023 | L3: Q3 2023 | M3: Q4 2023 | N3: Q1 2024 | O3: Q2 2024 | P3: Q3 2024 | Q3: Q4 2024 | R3: 2022 | S3: 2023 | T3: 2024 | U3: 2025 | V3: 2026
C5: Revenue ($mm)
D6: Asad Zafar | F6: =Model!AH9 -> 13589 | G6: =Model!AI9 -> 14247 | H6: =Model!AJ9 -> 14994 | I6: =Model!AK9 -> 16597 | J6: =Model!AN9 -> 15862 | K6: =Model!AO9 -> 17318 | L6: =Model!AP9 -> 16810 | M6: =Model!AQ9 -> 17070 | N6: =Model!AT9 -> 15799 | O6: =Model!AU9 -> 16689 | P6: =Model!AV9 -> 16106 | Q6: =Model!AW9 -> 16687.25 | R6: =Model!AL9 -> 59427 | S6: =Model!AR9 -> 67060 | T6: =Model!AX9 -> 65281.25 | U6: =Model!BD9 -> 64977.725 | V6: =Model!BJ9 -> 68040.728
D7: Street | F7: =_xll.BDP($B$2, "BEST_Sales","BEST_CONSENSUS_STAT_OVERRIDE","MEAN","BEST_FPERIOD_OVERRIDE",F$2) -> #NAME? | G7: =_xll.BDP($B$2, "BEST_Sales","BEST_CONSENSUS_STAT_OVERRIDE","MEAN","BEST_FPERIOD_OVERRIDE",G$2) -> #NAME? | H7: =_xll.BDP($B$2, "BEST_Sales","BEST_CONSENSUS_STAT_OVERRIDE","MEAN","BEST_FPERIOD_OVERRIDE",H$2) -> #NAME? | I7: =_xll.BDP($B$2, "BEST_Sales","BEST_CONSENSUS_STAT_OVERRIDE","MEAN","BEST_FPERIOD_OVERRIDE",I$2) -> #NAME? | J7: =_xll.BDP($B$2, "BEST_Sales","BEST_CONSENSUS_STAT_OVERRIDE","MEAN","BEST_FPERIOD_OVERRIDE",J$2) -> #NAME? | K7: =_xll.BDP($B$2, "BEST_Sales","BEST_CONSENSUS_STAT_OVERRIDE","MEAN","BEST_FPERIOD_OVERRIDE",K$2) -> #NAME? | L7: =_xll.BDP($B$2, "BEST_Sales","BEST_CONSENSUS_STAT_OVERRIDE","MEAN","BEST_FPERIOD_OVERRIDE",L$2) -> #NAME? | M7: =_xll.BDP($B$2, "BEST_Sales","BEST_CONSENSUS_STAT_OVERRIDE","MEAN","BEST_FPERIOD_OVERRIDE",M$2) -> #NAME? | ... V7: =_xll.BDP($B$2, "BEST_Sales","BEST_CONSENSUS_STAT_OVERRIDE","MEAN","BEST_FPERIOD_OVERRIDE",V$2) -> #NAME?
D8: Guidance | Z8: =_xll.snt("","SE.Gross_Margin") -> #NAME?
D9: Asad Zafar relative to Street (%) | F9: =F6/F7-1 -> #NAME? | G9: =G6/G7-1 -> #NAME? | H9: =H6/H7-1 -> #NAME? | I9: =I6/I7-1 -> #NAME? | J9: =J6/J7-1 -> #NAME? | K9: =K6/K7-1 -> #NAME? | L9: =L6/L7-1 -> #NAME? | M9: =M6/M7-1 -> #NAME? | ... V9: =V6/V7-1 -> #NAME?
C11: Gross Margin (%)
D12: Asad Zafar | F12: =Model!AK24 -> 0.30023498 | G12: =Model!AL24 -> 0.30418833 | H12: =Model!AM24 -> 0 | I12: =Model!AN24 -> 0.36306897 | J12: =Model!AO24 -> 0.36106941 | K12: =Model!AP24 -> 0.37043427 | L12: =Model!AQ24 -> 0.35465729 | M12: =Model!AR24 -> 0.36225768 | ... Q12: =Model!AV24 -> 0.37501552 | R12: =Model!AR24 -> 0.36225768 | S12: =Model!DD24 -> 0 | T12: =Model!AY24 -> 0 | U12: =Model!AZ24 -> 0.37561348 | V12: =Model!BA24 -> 0.39379119
D13: Street | F13: =_xll.snt("ODFL","SE.Gross_Margin",,"FQ"&F$1)/100 -> #NAME? | G13: =_xll.snt("ODFL","SE.Gross_Margin",,"FQ"&G$1)/100 -> #NAME? | H13: =_xll.snt("ODFL","SE.Gross_Margin",,"FQ"&H$1)/100 -> #NAME? | I13: =_xll.snt("ODFL","SE.Gross_Margin",,"FQ"&I$1)/100 -> #NAME? | J13: =_xll.snt("ODFL","SE.Gross_Margin",,"FQ"&J$1)/100 -> #NAME? | K13: =_xll.snt("ODFL","SE.Gross_Margin",,"FQ"&K$1)/100 -> #NAME? | L13: =_xll.snt("ODFL","SE.Gross_Margin",,"FQ"&L$1)/100 -> #NAME? | M13: =_xll.snt("ODFL","SE.Gross_Margin",,"FQ"&M$1)/100 -> #NAME? | ... Q13: =_xll.snt("ODFL","SE.Gross_Margin",,"FQ"&Q$1)/100 -> #NAME? | R13: =_xll.snt("ODFL","SE.Gross_Margin",,"FY"&R$1)/100 -> #NAME? | S13: =_xll.snt("ODFL","SE.Gross_Margin",,"FY"&S$1)/100 -> #NAME? | T13: =_xll.snt("ODFL","SE.Gross_Margin",,"FY"&T$1)/100 -> #NAME? | U13: =_xll.snt("ODFL","SE.Gross_Margin",,"FY"&U$1)/100 -> #NAME? | V13: =_xll.snt("ODFL","SE.Gross_Margin",,"FY"&V$1)/100 -> #NAME?
D14: Asad Zafar relative to Street (%) | F14: =F12/F13-1 -> #NAME? | G14: =G12/G13-1 -> #NAME? | H14: =H12/H13-1 -> #NAME? | I14: =I12/I13-1 -> #NAME? | J14: =J12/J13-1 -> #NAME? | K14: =K12/K13-1 -> #NAME? | L14: =L12/L13-1 -> #NAME? | M14: =M12/M13-1 -> #NAME? | ... V14: =V12/V13-1 -> #NAME?
C16: Adjusted EBITDA ($mm)
D17: Asad Zafar | F17: =Model!AH50 -> 2425 | G17: =Model!AI50 -> 2525 | H17: =Model!AJ50 -> 3025 | I17: =Model!AK50 -> 3372 | J17: =Model!AN50 -> 3874 | K17: =Model!AO50 -> 4225 | L17: =Model!AP50 -> 4020 | M17: =Model!AQ50 -> 3771 | N17: =Model!AT50 -> 4037 | O17: =Model!AU50 -> 4271 | P17: =Model!AV50 -> 3760 | Q17: =Model!AW50 -> 3771.3916 | R17: =Model!AL50 -> 11347 | S17: =Model!AR50 -> 15890 | T17: =Model!AX50 -> 15839.392 | U17: =Model!BD50 -> 15274.842 | V17: =Model!BJ50 -> 16473.123
D18: Street | F18: =_xll.BDP($B$2, "BEST_EBITDA","BEST_CONSENSUS_STAT_OVERRIDE","MEAN","BEST_FPERIOD_OVERRIDE",F$2) -> #NAME? | G18: =_xll.BDP($B$2, "BEST_EBITDA","BEST_CONSENSUS_STAT_OVERRIDE","MEAN","BEST_FPERIOD_OVERRIDE",G$2) -> #NAME? | H18: =_xll.BDP($B$2, "BEST_EBITDA","BEST_CONSENSUS_STAT_OVERRIDE","MEAN","BEST_FPERIOD_OVERRIDE",H$2) -> #NAME? | I18: =_xll.BDP($B$2, "BEST_EBITDA","BEST_CONSENSUS_STAT_OVERRIDE","MEAN","BEST_FPERIOD_OVERRIDE",I$2) -> #NAME? | J18: =_xll.BDP($B$2, "BEST_EBITDA","BEST_CONSENSUS_STAT_OVERRIDE","MEAN","BEST_FPERIOD_OVERRIDE",J$2) -> #NAME? | K18: =_xll.BDP($B$2, "BEST_EBITDA","BEST_CONSENSUS_STAT_OVERRIDE","MEAN","BEST_FPERIOD_OVERRIDE",K$2) -> #NAME? | L18: =_xll.BDP($B$2, "BEST_EBITDA","BEST_CONSENSUS_STAT_OVERRIDE","MEAN","BEST_FPERIOD_OVERRIDE",L$2) -> #NAME? | M18: =_xll.BDP($B$2, "BEST_EBITDA","BEST_CONSENSUS_STAT_OVERRIDE","MEAN","BEST_FPERIOD_OVERRIDE",M$2) -> #NAME? | ... R18: =_xll.BDP($B$2, "BEST_EBITDA","BEST_CONSENSUS_STAT_OVERRIDE","MEAN","BEST_FPERIOD_OVERRIDE",R$2) -> #NAME? | S18: =_xll.BDP($B$2, "BEST_EBITDA","BEST_CONSENSUS_STAT_OVERRIDE","MEdian","BEST_FPERIOD_OVERRIDE",S$2) -> #NAME? | T18: =_xll.BDP($B$2, "BEST_EBITDA","BEST_CONSENSUS_STAT_OVERRIDE","MEdian","BEST_FPERIOD_OVERRIDE",T$2) -> #NAME? | U18: =_xll.BDP($B$2, "BEST_EBITDA","BEST_CONSENSUS_STAT_OVERRIDE","MEdian","BEST_FPERIOD_OVERRIDE",U$2) -> #NAME? | V18: =_xll.BDP($B$2, "BEST_EBITDA","BEST_CONSENSUS_STAT_OVERRIDE","MEdian","BEST_FPERIOD_OVERRIDE",V$2) -> #NAME?
D19: Guidance
D20: Asad Zafar relative to Street (%) | F20: =F17/F18-1 -> #NAME? | G20: =G17/G18-1 -> #NAME? | H20: =H17/H18-1 -> #NAME? | I20: =I17/I18-1 -> #NAME? | J20: =J17/J18-1 -> #NAME? | K20: =K17/K18-1 -> #NAME? | L20: =L17/L18-1 -> #NAME? | M20: =M17/M18-1 -> #NAME? | ... V20: =V17/V18-1 -> #NAME?
C22: Capital Expenditure:
D23: Asad Zafar | F23: =Model!AH86 -> -346 | G23: =Model!AI86 -> -240 | H23: =Model!AJ86 -> -282 | I23: =Model!AK86 -> -428 | J23: =Model!AN86 -> -422 | K23: =Model!AO86 -> -261 | L23: =Model!AP86 -> -378 | M23: =Model!AQ86 -> -536 | N23: =Model!AT86 -> -500 | O23: =Model!AU86 -> -341 | P23: =Model!AV86 -> -444 | Q23: =Model!AW86 -> -647.8 | R23: =Model!AL86 -> -1296 | S23: =Model!AR86 -> -1597 | T23: =Model!AX86 -> -1932.8 | U23: =Model!BD86 -> -2127.726 | V23: =Model!BJ86 -> -2331.553
D24: Street | F24: =-_xll.BDP($B$2, "BEST_Capex","BEST_CONSENSUS_STAT_OVERRIDE","MEAN","BEST_FPERIOD_OVERRIDE",F$2) -> #NAME? | G24: =-_xll.BDP($B$2, "BEST_Capex","BEST_CONSENSUS_STAT_OVERRIDE","MEAN","BEST_FPERIOD_OVERRIDE",G$2) -> #NAME? | H24: =-_xll.BDP($B$2, "BEST_Capex","BEST_CONSENSUS_STAT_OVERRIDE","MEAN","BEST_FPERIOD_OVERRIDE",H$2) -> #NAME? | I24: =-_xll.BDP($B$2, "BEST_Capex","BEST_CONSENSUS_STAT_OVERRIDE","MEAN","BEST_FPERIOD_OVERRIDE",I$2) -> #NAME? | J24: =-_xll.BDP($B$2, "BEST_Capex","BEST_CONSENSUS_STAT_OVERRIDE","MEAN","BEST_FPERIOD_OVERRIDE",J$2) -> #NAME? | K24: =-_xll.BDP($B$2, "BEST_Capex","BEST_CONSENSUS_STAT_OVERRIDE","MEAN","BEST_FPERIOD_OVERRIDE",K$2) -> #NAME? | L24: =-_xll.BDP($B$2, "BEST_Capex","BEST_CONSENSUS_STAT_OVERRIDE","MEAN","BEST_FPERIOD_OVERRIDE",L$2) -> #NAME? | M24: =-_xll.BDP($B$2, "BEST_Capex","BEST_CONSENSUS_STAT_OVERRIDE","MEAN","BEST_FPERIOD_OVERRIDE",M$2) -> #NAME? | ... V24: =-_xll.BDP($B$2, "BEST_Capex","BEST_CONSENSUS_STAT_OVERRIDE","MEAN","BEST_FPERIOD_OVERRIDE",V$2) -> #NAME?
D25: Asad Zafar relative to Street (%) | F25: =F23/F24-1 -> #NAME? | G25: =G23/G24-1 -> #NAME? | H25: =H23/H24-1 -> #NAME? | I25: =I23/I24-1 -> #NAME? | J25: =J23/J24-1 -> #NAME? | K25: =K23/K24-1 -> #NAME? | L25: =L23/L24-1 -> #NAME? | M25: =M23/M24-1 -> #NAME? | ... V25: =V23/V24-1 -> #NAME?
C27: Adjusted EBITDA Margin (%)
D28: Asad Zafar | F28: =Model!AH51 -> 0.17845316 | G28: =Model!AI51 -> 0.17723029 | H28: =Model!AJ51 -> 0.20174737 | I28: =Model!AK51 -> 0.20316925 | J28: =Model!AN51 -> 0.2442315 | K28: =Model!AO51 -> 0.24396582 | L28: =Model!AP51 -> 0.23914337 | M28: =Model!AQ51 -> 0.22091388 | N28: =Model!AT51 -> 0.2555225 | O28: =Model!AU51 -> 0.25591707 | P28: =Model!AV51 -> 0.23345337 | Q28: =Model!AW51 -> 0.22600438 | R28: =Model!AL51 -> 0.19094015 | S28: =Model!AR51 -> 0.23695198 | T28: =Model!AX51 -> 0.24263309 | U28: =Model!BD51 -> 0.23507813 | V28: =Model!BJ51 -> 0.2421068
D29: Street | F29: =F18/F7 -> #NAME? | G29: =G18/G7 -> #NAME? | H29: =H18/H7 -> #NAME? | I29: =I18/I7 -> #NAME? | J29: =J18/J7 -> #NAME? | K29: =K18/K7 -> #NAME? | L29: =L18/L7 -> #NAME? | M29: =M18/M7 -> #NAME? | ... V29: =V18/V7 -> #NAME?
D30: Guidance
D31: Asad Zafar relative to Street (%) | F31: =F28/F29-1 -> #NAME? | G31: =G28/G29-1 -> #NAME? | H31: =H28/H29-1 -> #NAME? | I31: =I28/I29-1 -> #NAME? | J31: =J28/J29-1 -> #NAME? | K31: =K28/K29-1 -> #NAME? | L31: =L28/L29-1 -> #NAME? | M31: =M28/M29-1 -> #NAME? | ... V31: =V28/V29-1 -> #NAME?
C33: Adjusted EBIT ($mm)
D34: Asad Zafar | F34: =Model!AH40 -> 1868 | G34: =Model!AI40 -> 1972 | H34: =Model!AJ40 -> 2474 | I34: =Model!AK40 -> 2814 | J34: =Model!AN40 -> 3342 | K34: =Model!AO40 -> 3683 | L34: =Model!AP40 -> 3495 | M34: =Model!AQ40 -> 3226 | N34: =Model!AT40 -> 3513 | O34: =Model!AU40 -> 3740 | P34: =Model!AV40 -> 3217 | Q34: =Model!AW40 -> 3180.1916 | R34: =Model!AL40 -> 9128 | S34: =Model!AR40 -> 13746 | T34: =Model!AX40 -> 13650.192 | U34: =Model!BD40 -> 13009.02 | V34: =Model!BJ40 -> 14127.505
D35: Street | F35: =_xll.BDP($B$2, "BEST_EBIT","BEST_CONSENSUS_STAT_OVERRIDE","MEAN","BEST_FPERIOD_OVERRIDE",F$2) -> #NAME? | G35: =_xll.BDP($B$2, "BEST_EBIT","BEST_CONSENSUS_STAT_OVERRIDE","MEAN","BEST_FPERIOD_OVERRIDE",G$2) -> #NAME? | H35: =_xll.BDP($B$2, "BEST_EBIT","BEST_CONSENSUS_STAT_OVERRIDE","MEAN","BEST_FPERIOD_OVERRIDE",H$2) -> #NAME? | I35: =_xll.BDP($B$2, "BEST_EBIT","BEST_CONSENSUS_STAT_OVERRIDE","MEAN","BEST_FPERIOD_OVERRIDE",I$2) -> #NAME? | J35: =_xll.BDP($B$2, "BEST_EBIT","BEST_CONSENSUS_STAT_OVERRIDE","MEAN","BEST_FPERIOD_OVERRIDE",J$2) -> #NAME? | K35: =_xll.BDP($B$2, "BEST_EBIT","BEST_CONSENSUS_STAT_OVERRIDE","MEAN","BEST_FPERIOD_OVERRIDE",K$2) -> #NAME? | L35: =_xll.BDP($B$2, "BEST_EBIT","BEST_CONSENSUS_STAT_OVERRIDE","MEAN","BEST_FPERIOD_OVERRIDE",L$2) -> #NAME? | M35: =_xll.BDP($B$2, "BEST_EBIT","BEST_CONSENSUS_STAT_OVERRIDE","MEAN","BEST_FPERIOD_OVERRIDE",M$2) -> #NAME? | ... V35: =_xll.BDP($B$2, "BEST_EBIT","BEST_CONSENSUS_STAT_OVERRIDE","MEAN","BEST_FPERIOD_OVERRIDE",V$2) -> #NAME?
D36: Guidance
D37: Asad Zafar relative to Street (%) | F37: =F34/F35-1 -> #NAME? | G37: =G34/G35-1 -> #NAME? | H37: =H34/H35-1 -> #NAME? | I37: =I34/I35-1 -> #NAME? | J37: =J34/J35-1 -> #NAME? | K37: =K34/K35-1 -> #NAME? | L37: =L34/L35-1 -> #NAME? | M37: =M34/M35-1 -> #NAME? | ... V37: =V34/V35-1 -> #NAME?
C39: Adjusted EPS ($/share)
D40: Asad Zafar | F40: =Model!AH78 -> 2.8757199 | G40: =Model!AI78 -> 3.1810522 | H40: =Model!AJ78 -> 3.9446498 | I40: =Model!AK78 -> 3.8606258 | J40: =Model!AN78 -> 4.9075857 | K40: =Model!AO78 -> 5.5514563 | L40: =Model!AP78 -> 5.520874 | M40: =Model!AQ78 -> 5.2307692 | N40: =Model!AT78 -> 5.598712 | O40: =Model!AU78 -> 5.9918284 | P40: =Model!AV78 -> 5.1736182 | Q40: =Model!AW78 -> 5.1070939 | R40: =Model!AL78 -> 13.84162 | S40: =Model!AR78 -> 21.2074 | T40: =Model!AX78 -> 21.878617 | U40: =Model!BD78 -> 21.199987 | V40: =Model!BJ78 -> 23.894826
D41: Street | F41: =_xll.BDP($B$2, "BEST_EPS","BEST_CONSENSUS_STAT_OVERRIDE","MEAN","BEST_FPERIOD_OVERRIDE",F$2) -> #NAME? | G41: =_xll.BDP($B$2, "BEST_EPS","BEST_CONSENSUS_STAT_OVERRIDE","MEAN","BEST_FPERIOD_OVERRIDE",G$2) -> #NAME? | H41: =_xll.BDP($B$2, "BEST_EPS","BEST_CONSENSUS_STAT_OVERRIDE","MEAN","BEST_FPERIOD_OVERRIDE",H$2) -> #NAME? | I41: =_xll.BDP($B$2, "BEST_EPS","BEST_CONSENSUS_STAT_OVERRIDE","MEAN","BEST_FPERIOD_OVERRIDE",I$2) -> #NAME? | J41: =_xll.BDP($B$2, "BEST_EPS","BEST_CONSENSUS_STAT_OVERRIDE","MEAN","BEST_FPERIOD_OVERRIDE",J$2) -> #NAME? | K41: =_xll.BDP($B$2, "BEST_EPS","BEST_CONSENSUS_STAT_OVERRIDE","MEAN","BEST_FPERIOD_OVERRIDE",K$2) -> #NAME? | L41: =_xll.BDP($B$2, "BEST_EPS","BEST_CONSENSUS_STAT_OVERRIDE","MEAN","BEST_FPERIOD_OVERRIDE",L$2) -> #NAME? | M41: =_xll.BDP($B$2, "BEST_EPS","BEST_CONSENSUS_STAT_OVERRIDE","MEAN","BEST_FPERIOD_OVERRIDE",M$2) -> #NAME? | ... V41: =_xll.BDP($B$2, "BEST_EPS","BEST_CONSENSUS_STAT_OVERRIDE","MEAN","BEST_FPERIOD_OVERRIDE",V$2) -> #NAME?
D42: Guidance
D43: Asad Zafar relative to Street (%) | F43: =F40/F41-1 -> #NAME? | G43: =G40/G41-1 -> #NAME? | H43: =H40/H41-1 -> #NAME? | I43: =I40/I41-1 -> #NAME? | J43: =J40/J41-1 -> #NAME? | K43: =K40/K41-1 -> #NAME? | L43: =L40/L41-1 -> #NAME? | M43: =M40/M41-1 -> #NAME? | ... V43: =V40/V41-1 -> #NAME?
C45: CFPS ($/share)
D46: Asad Zafar | F46: =(Model!AH162)/Model!AH81 -> 0.58146015 | G46: =(Model!AI162)/Model!AI81 -> 4.180865 | H46: =(Model!AJ162)/Model!AJ81 -> 4.7028718 | I46: =(Model!AK162)/Model!AK81 -> 5.2582069 | J46: =(Model!AN162)/Model!AN81 -> 3.0284944 | K46: =(Model!AO162)/Model!AO81 -> 6.3087379 | L46: =(Model!AP162)/Model!AP81 -> 7.9204058 | M46: =(Model!AQ162)/Model!AQ81 -> 7.8954635 | N46: =(Model!AT162)/Model!AT81 -> 4.1296035 | O46: =(Model!AU162)/Model!AU81 -> 6.1716037 | P46: =(Model!AV162)/Model!AV81 -> 7.3330594 | Q46: =(Model!AW162)/Model!AW81 -> 8.7030686 | R46: =(Model!AL162)/Model!AL81 -> 14.646958 | S46: =(Model!AR162)/Model!AR81 -> 25.092502 | T46: =Model!AX162/Model!AX81 -> 26.274191 | U46: =(Model!BD162)/Model!BD81 -> 25.694758 | V46: =(Model!BJ162)/Model!BJ81 -> 28.199674
D47: Street | F47: =_xll.BDP($B$2, "BEST_CPS","BEST_CONSENSUS_STAT_OVERRIDE","MEAN","BEST_FPERIOD_OVERRIDE",F$2) -> #NAME? | G47: =_xll.BDP($B$2, "BEST_CPS","BEST_CONSENSUS_STAT_OVERRIDE","MEAN","BEST_FPERIOD_OVERRIDE",G$2) -> #NAME? | H47: =_xll.BDP($B$2, "BEST_CPS","BEST_CONSENSUS_STAT_OVERRIDE","MEAN","BEST_FPERIOD_OVERRIDE",H$2) -> #NAME? | I47: =_xll.BDP($B$2, "BEST_CPS","BEST_CONSENSUS_STAT_OVERRIDE","MEAN","BEST_FPERIOD_OVERRIDE",I$2) -> #NAME? | J47: =_xll.BDP($B$2, "BEST_CPS","BEST_CONSENSUS_STAT_OVERRIDE","MEAN","BEST_FPERIOD_OVERRIDE",J$2) -> #NAME? | K47: =_xll.BDP($B$2, "BEST_CPS","BEST_CONSENSUS_STAT_OVERRIDE","MEAN","BEST_FPERIOD_OVERRIDE",K$2) -> #NAME? | L47: =_xll.BDP($B$2, "BEST_CPS","BEST_CONSENSUS_STAT_OVERRIDE","MEAN","BEST_FPERIOD_OVERRIDE",L$2) -> #NAME? | M47: =_xll.BDP($B$2, "BEST_CPS","BEST_CONSENSUS_STAT_OVERRIDE","MEAN","BEST_FPERIOD_OVERRIDE",M$2) -> #NAME? | ... V47: =_xll.BDP($B$2, "BEST_CPS","BEST_CONSENSUS_STAT_OVERRIDE","MEAN","BEST_FPERIOD_OVERRIDE",V$2) -> #NAME?
D48: Guidance
...

Sheet Business Build-up
C2: 42735 | D2: =EOMONTH(C2,3) -> 42825 | E2: =EOMONTH(D2,3) -> 42916 | F2: =EOMONTH(E2,3) -> 43008 | G2: =EOMONTH(F2,3) -> 43100 | J2: =EOMONTH(G2,3) -> 43190 | K2: =EOMONTH(J2,3) -> 43281 | L2: =EOMONTH(K2,3) -> 43373 | M2: =EOMONTH(L2,3) -> 43465 | P2: =EOMONTH(M2,3) -> 43555 | Q2: =EOMONTH(P2,3) -> 43646 | R2: =EOMONTH(Q2,3) -> 43738 | S2: =EOMONTH(R2,3) -> 43830 | V2: =EOMONTH(S2,3) -> 43921 | W2: =EOMONTH(V2,3) -> 44012 | X2: =EOMONTH(W2,3) -> 44104 | Y2: =EOMONTH(X2,3) -> 44196 | AB2: =EOMONTH(Y2,3) -> 44286 | AC2: =EOMONTH(AB2,3) -> 44377 | AD2: =EOMONTH(AC2,3) -> 44469 | AE2: =EOMONTH(AD2,3) -> 44561 | AH2: =EOMONTH(AE2,3) -> 44651 | AI2: =EOMONTH(AH2,3) -> 44742 | AJ2: =EOMONTH(AI2,3) -> 44834 | AK2: =EOMONTH(AJ2,3) -> 44926 | AN2: =EOMONTH(AK2,3) -> 45016 | AO2: =EOMONTH(AN2,3) -> 45107 | AP2: =EOMONTH(AO2,3) -> 45199 | AQ2: =EOMONTH(AP2,3) -> 45291 | AT2: =EOMONTH(AQ2,3) -> 45382 | AU2: =EOMONTH(AT2,3) -> 45473 | AV2: =EOMONTH(AU2,3) -> 45565 | AW2: =EOMONTH(AV2,3) -> 45657 | AZ2: =EOMONTH(AW2,3) -> 45747 | BA2: =EOMONTH(AZ2,3) -> 45838 | BB2: =EOMONTH(BA2,3) -> 45930 | BC2: =EOMONTH(BB2,3) -> 46022 | BF2: =EOMONTH(BC2,3) -> 46112 | BG2: =EOMONTH(BF2,3) -> 46203 | BH2: =EOMONTH(BG2,3) -> 46295 | BI2: =EOMONTH(BH2,3) -> 46387 | BL2: =EOMONTH(BI2,3) -> 46477 | BM2: =EOMONTH(BL2,3) -> 46568 | BN2: =EOMONTH(BM2,3) -> 46660 | BO2: =EOMONTH(BN2,3) -> 46752 | BR2: =EOMONTH(BO2,3) -> 46843 | BS2: =EOMONTH(BR2,3) -> 46934 | BT2: =EOMONTH(BS2,3) -> 47026 | BU2: =EOMONTH(BT2,3) -> 47118 | BX2: =EOMONTH(BU2,3) -> 47208 | BY2: =EOMONTH(BX2,3) -> 47299 | BZ2: =EOMONTH(BY2,3) -> 47391 | CA2: =EOMONTH(BZ2,3) -> 47483 | CD2: =EOMONTH(CA2,3) -> 47573 | CE2: =EOMONTH(CD2,3) -> 47664 | CF2: =EOMONTH(CE2,3) -> 47756 | CG2: =EOMONTH(CF2,3) -> 47848 | CJ2: =EOMONTH(CG2,3) -> 47938 | CK2: =EOMONTH(CJ2,3) -> 48029 | CL2: =EOMONTH(CK2,3) -> 48121 | CM2: =EOMONTH(CL2,3) -> 48213
D3: 1-2017 | E3: 2-2017 | F3: 3-2017 | G3: 4-2017 | J3: 1-2018 | K3: 2-2018 | L3: 3-2018 | M3: 4-2018 | P3: 1-2019 | Q3: 2-2019 | R3: 3-2019 | S3: 4-2019 | V3: 1-2020 | W3: 2-2020 | X3: 3-2020 | Y3: 4-2020 | AB3: 1-2021 | AC3: 2-2021 | AD3: 3-2021 | AE3: 4-2021 | AH3: 1-2022 | AI3: 2-2022 | AJ3: 3-2022 | AK3: 4-2022 | AN3: 1-2023 | AO3: 2-2023 | AP3: 3-2023 | AQ3: 4-2023 | AT3: 1-2024 | AU3: 2-2024 | AV3: 3-2024 | AW3: 4-2024 | AZ3: =CONCATENATE(RIGHT(AZ4,1),"-",RIGHT(AW3,4)+1) -> 1-2025 | BA3: =CONCATENATE(RIGHT(BA4,1),"-",RIGHT(AZ3,4)) -> 2-2025 | BB3: =CONCATENATE(RIGHT(BB4,1),"-",RIGHT(BA3,4)) -> 3-2025 | BC3: =CONCATENATE(RIGHT(BC4,1),"-",RIGHT(BB3,4)) -> 4-2025 | BF3: =CONCATENATE(RIGHT(BF4,1),"-",RIGHT(BC3,4)+1) -> 1-2026 | BG3: =CONCATENATE(RIGHT(BG4,1),"-",RIGHT(BF3,4)) -> 2-2026 | BH3: =CONCATENATE(RIGHT(BH4,1),"-",RIGHT(BG3,4)) -> 3-2026 | BI3: =CONCATENATE(RIGHT(BI4,1),"-",RIGHT(BH3,4)) -> 4-2026 | BL3: =CONCATENATE(RIGHT(BL4,1),"-",RIGHT(BI3,4)+1) -> 1-2027 | BM3: =CONCATENATE(RIGHT(BM4,1),"-",RIGHT(BL3,4)) -> 2-2027 | BN3: =CONCATENATE(RIGHT(BN4,1),"-",RIGHT(BM3,4)) -> 3-2027 | BO3: =CONCATENATE(RIGHT(BO4,1),"-",RIGHT(BN3,4)) -> 4-2027 | BR3: =CONCATENATE(RIGHT(BR4,1),"-",RIGHT(BO3,4)+1) -> 1-2028 | BS3: =CONCATENATE(RIGHT(BS4,1),"-",RIGHT(BR3,4)) -> 2-2028 | BT3: =CONCATENATE(RIGHT(BT4,1),"-",RIGHT(BS3,4)) -> 3-2028 | BU3: =CONCATENATE(RIGHT(BU4,1),"-",RIGHT(BT3,4)) -> 4-2028 | BX3: =CONCATENATE(RIGHT(BX4,1),"-",RIGHT(BU3,4)+1) -> 1-2029 | BY3: =CONCATENATE(RIGHT(BY4,1),"-",RIGHT(BX3,4)) -> 2-2029 | BZ3: =CONCATENATE(RIGHT(BZ4,1),"-",RIGHT(BY3,4)) -> 3-2029 | CA3: =CONCATENATE(RIGHT(CA4,1),"-",RIGHT(BZ3,4)) -> 4-2029 | CD3: =CONCATENATE(RIGHT(CD4,1),"-",RIGHT(CA3,4)+1) -> 1-2030 | CE3: =CONCATENATE(RIGHT(CE4,1),"-",RIGHT(CD3,4)) -> 2-2030 | CF3: =CONCATENATE(RIGHT(CF4,1),"-",RIGHT(CE3,4)) -> 3-2030 | CG3: =CONCATENATE(RIGHT(CG4,1),"-",RIGHT(CF3,4)) -> 4-2030 | CJ3: =CONCATENATE(RIGHT(CJ4,1),"-",RIGHT(CG3,4)+1) -> 1-2031 | CK3: =CONCATENATE(RIGHT(CK4,1),"-",RIGHT(CJ3,4)) -> 2-2031 | CL3: =CONCATENATE(RIGHT(CL4,1),"-",RIGHT(CK3,4)) -> 3-2031 | CM3: =CONCATENATE(RIGHT(CM4,1),"-",RIGHT(CL3,4)) -> 4-2031
D4: Q1 | E4: Q2 | F4: Q3 | G4: Q4 | H4: 2017 | J4: Q1 | K4: Q2 | L4: Q3 | M4: Q4 | N4: 2018 | P4: Q1 | Q4: Q2 | R4: Q3 | S4: Q4 | T4: =N4+1 -> 2019 | V4: Q1 | W4: Q2 | X4: Q3 | Y4: Q4 | Z4: =T4+1 -> 2020 | AB4: Q1 | AC4: Q2 | AD4: Q3 | AE4: Q4 | AF4: =Z4+1 -> 2021 | AH4: Q1 | AI4: Q2 | AJ4: Q3 | AK4: Q4 | AL4: =AF4+1 -> 2022 | AN4: Q1 | AO4: Q2 | AP4: Q3 | AQ4: Q4 | AR4: =AL4+1 -> 2023 | AT4: Q1 | AU4: Q2 | AV4: Q3 | AW4: Q4 | AX4: =AR4+1 -> 2024 | AZ4: Q1 | BA4: Q2 | BB4: Q3 | BC4: Q4 | BD4: =AX4+1 -> 2025 | BF4: Q1 | BG4: Q2 | BH4: Q3 | BI4: Q4 | BJ4: =BD4+1 -> 2026 | BL4: Q1 | BM4: Q2 | BN4: Q3 | BO4: Q4 | BP4: =BJ4+1 -> 2027 | BR4: Q1 | BS4: Q2 | BT4: Q3 | BU4: Q4 | BV4: =BP4+1 -> 2028 | BX4: Q1 | BY4: Q2 | BZ4: Q3 | CA4: Q4 | CB4: =BV4+1 -> 2029 | CD4: Q1 | CE4: Q2 | CF4: Q3 | CG4: Q4 | CH4: =CB4+1 -> 2030 | CJ4: Q1 | CK4: Q2 | CL4: Q3 | CM4: Q4 | CN4: =CH4+1 -> 2031
B5: Days | D5: =D2-C2 -> 90 | E5: =E2-D2 -> 91 | F5: =F2-E2 -> 92 | G5: =G2-F2 -> 92 | H5: =SUM(D5:G5) -> 365 | J5: =J2-G2 -> 90 | K5: =K2-J2 -> 91 | L5: =L2-K2 -> 92 | M5: =M2-L2 -> 92 | N5: =SUM(J5:M5) -> 365 | P5: =P2-M2 -> 90 | Q5: =Q2-P2 -> 91 | R5: =R2-Q2 -> 92 | S5: =S2-R2 -> 92 | T5: =SUM(P5:S5) -> 365 | V5: =V2-S2 -> 91 | W5: =W2-V2 -> 91 | X5: =X2-W2 -> 92 | Y5: =Y2-X2 -> 92 | Z5: =SUM(V5:Y5) -> 366 | AB5: =AB2-Y2 -> 90 | AC5: =AC2-AB2 -> 91 | AD5: =AD2-AC2 -> 92 | AE5: =AE2-AD2 -> 92 | AF5: =SUM(AB5:AE5) -> 365 | AH5: =AH2-AE2 -> 90 | AI5: =AI2-AH2 -> 91 | AJ5: =AJ2-AI2 -> 92 | AK5: =AK2-AJ2 -> 92 | AL5: =SUM(AH5:AK5) -> 365 | AN5: =AN2-AK2 -> 90 | AO5: =AO2-AN2 -> 91 | AP5: =AP2-AO2 -> 92 | AQ5: =AQ2-AP2 -> 92 | AR5: =SUM(AN5:AQ5) -> 365 | AT5: =AT2-AQ2 -> 91 | AU5: =AU2-AT2 -> 91 | AV5: =AV2-AU2 -> 92 | AW5: =AW2-AV2 -> 92 | AX5: =SUM(AT5:AW5) -> 366 | AZ5: =AZ2-AW2 -> 90 | BA5: =BA2-AZ2 -> 91 | BB5: =BB2-BA2 -> 92 | BC5: =BC2-BB2 -> 92 | BD5: =SUM(AZ5:BC5) -> 365 | BF5: =BF2-BC2 -> 90 | BG5: =BG2-BF2 -> 91 | BH5: =BH2-BG2 -> 92 | BI5: =BI2-BH2 -> 92 | BJ5: =SUM(BF5:BI5) -> 365 | BL5: =BL2-BI2 -> 90 | BM5: =BM2-BL2 -> 91 | BN5: =BN2-BM2 -> 92 | BO5: =BO2-BN2 -> 92 | BP5: =SUM(BL5:BO5) -> 365 | BR5: =BR2-BO2 -> 91 | BS5: =BS2-BR2 -> 91 | BT5: =BT2-BS2 -> 92 | BU5: =BU2-BT2 -> 92 | BV5: =SUM(BR5:BU5) -> 366 | BX5: =BX2-BU2 -> 90 | BY5: =BY2-BX2 -> 91 | BZ5: =BZ2-BY2 -> 92 | CA5: =CA2-BZ2 -> 92 | CB5: =SUM(BX5:CA5) -> 365 | CD5: =CD2-CA2 -> 90 | CE5: =CE2-CD2 -> 91 | CF5: =CF2-CE2 -> 92 | CG5: =CG2-CF2 -> 92 | CH5: =SUM(CD5:CG5) -> 365 | CJ5: =CJ2-CG2 -> 90 | CK5: =CK2-CJ2 -> 91 | CL5: =CL2-CK2 -> 92 | CM5: =CM2-CL2 -> 92 | CN5: =SUM(CJ5:CM5) -> 365
B6: Revenue Buildup:
B7: ME&T | D7: 9130 | E7: 10639 | F7: 10713 | G7: 12194 | H7: =SUM(D7:G7) -> 42676 | J7: 12150 | K7: 13279 | L7: 12763 | M7: 13630 | N7: =SUM(J7:M7) -> 51822 | P7: 12724 | Q7: 13671 | R7: 11974 | S7: 12386 | T7: =SUM(P7:S7) -> 50755 | V7: 9914 | W7: 9310 | X7: 9228 | Y7: 10570 | Z7: =SUM(V7:Y7) -> 39022 | AB7: 11191 | AC7: 12193 | AD7: 11707 | AE7: 13097 | AF7: =SUM(AB7:AE7) -> 48188 | AH7: 12886 | AI7: 13539 | AJ7: 14278 | AK7: 15871 | AL7: =SUM(AH7:AK7) -> 56574 | AN7: 15099 | AO7: 16545 | AP7: 15988 | AQ7: 16237 | AR7: =SUM(AN7:AQ7) -> 63869 | AT7: 14960 | AU7: 15840 | AV7: 15231 | AW7: =AW57 -> 15812.6 | AX7: =SUM(AT7:AW7) -> 61843.6 | AZ7: =AZ57 -> 14513.1 | BA7: =BA57 -> 15556.75 | BB7: =BB57 -> 15263.14 | BC7: =BC57 -> 16035.202 | BD7: =SUM(AZ7:BC7) -> 61368.192 | BF7: =BF57 -> 15199.025 | BG7: =BG57 -> 16291.806 | BH7: =BH57 -> 15982.659 | BI7: =BI57 -> 16787.549 | BJ7: =SUM(BF7:BI7) -> 64261.039 | BL7: =BL57 -> 15820.402 | BM7: =BM57 -> 16961.505 | BN7: =BN57 -> 16637.861 | BO7: =BO57 -> 17479.691 | BP7: =SUM(BL7:BO7) -> 66899.46 | BR7: =BR57 -> 16468.267 | BS7: =BS57 -> 17659.897 | BT7: =BT57 -> 17321.065 | BU7: =BU57 -> 18201.645 | BV7: =SUM(BR7:BU7) -> 69650.874 | BX7: =BX57 -> 17143.787 | BY7: =BY57 -> 18388.252 | BZ7: =BZ57 -> 18033.508 | CA7: =CA57 -> 18954.739 | CB7: =SUM(BX7:CA7) -> 72520.286 | CD7: =CD57 -> 17848.183 | CE7: =CE57 -> 19147.898 | CF7: =CF57 -> 18776.482 | CG7: =CG57 -> 19740.361 | CH7: =SUM(CD7:CG7) -> 75512.925 | CJ7: =CJ57 -> 18582.73 | CK7: =CK57 -> 19940.224 | CL7: =CL57 -> 19551.34 | CM7: =CM57 -> 20559.965 | CN7: =SUM(CJ7:CM7) -> 78634.258
B8: Financial Products | D8: 692 | E8: 692 | F8: 700 | G8: 702 | H8: =SUM(D8:G8) -> 2786 | J8: 709 | K8: 732 | L8: 747 | M8: 712 | N8: =SUM(J8:M8) -> 2900 | P8: 742 | Q8: 761 | R8: 784 | S8: 758 | T8: =SUM(P8:S8) -> 3045 | V8: 721 | W8: 687 | X8: 653 | Y8: 665 | Z8: =SUM(V8:Y8) -> 2726 | AB8: 696 | AC8: 696 | AD8: 690 | AE8: 701 | AF8: =SUM(AB8:AE8) -> 2783 | AH8: 703 | AI8: 708 | AJ8: 716 | AK8: 726 | AL8: =SUM(AH8:AK8) -> 2853 | AN8: 763 | AO8: 773 | AP8: 822 | AQ8: 833 | AR8: =SUM(AN8:AQ8) -> 3191 | AT8: 839 | AU8: 849 | AV8: 875 | AW8: =AW277 -> 874.65 | AX8: =SUM(AT8:AW8) -> 3437.65 | AZ8: =AZ277 -> 880.95 | BA8: =BA277 -> 891.45 | BB8: =BB277 -> 918.75 | BC8: =BC277 -> 918.3825 | BD8: =SUM(AZ8:BC8) -> 3609.5325 | BF8: =BF277 -> 922.58588 | BG8: =BG277 -> 933.57099 | BH8: =BH277 -> 962.06073 | BI8: =BI277 -> 961.47162 | BJ8: =SUM(BF8:BI8) -> 3779.6892 | BL8: =BL277 -> 960.30369 | BM8: =BM277 -> 971.94684 | BN8: =BN277 -> 1001.5 | BO8: =BO277 -> 1001.1126 | BP8: =SUM(BL8:BO8) -> 3934.8631 | BR8: =BR277 -> 999.6293 | BS8: =BS277 -> 1011.9669 | BT8: =BT277 -> 1042.6248 | BU8: =BU277 -> 1042.4609 | BV8: =SUM(BR8:BU8) -> 4096.6819 | BX8: =BX277 -> 1040.6336 | BY8: =BY277 -> 1053.7039 | BZ8: =BZ277 -> 1085.5096 | CA8: =CA277 -> 1085.5928 | CB8: =SUM(BX8:CA8) -> 4265.4399 | CD8: =CD277 -> 1083.3907 | CE8: =CE277 -> 1097.2339 | CF8: =CF277 -> 1130.2322 | CG8: =CG277 -> 1130.5877 | CH8: =SUM(CD8:CG8) -> 4441.4445 | CJ8: =CJ277 -> 1127.9779 | CK8: =CK277 -> 1142.6366 | CL8: =CL277 -> 1176.8741 | CM8: =CM277 -> 1177.5288 | CN8: =SUM(CJ8:CM8) -> 4625.0174
B9: Total Revenue ($mm) | D9: =SUM(D7:D8) -> 9822 | E9: =SUM(E7:E8) -> 11331 | F9: =SUM(F7:F8) -> 11413 | G9: =SUM(G7:G8) -> 12896 | H9: =SUM(H7:H8) -> 45462 | J9: =SUM(J7:J8) -> 12859 | K9: =SUM(K7:K8) -> 14011 | L9: =SUM(L7:L8) -> 13510 | M9: =SUM(M7:M8) -> 14342 | N9: =SUM(N7:N8) -> 54722 | P9: =SUM(P7:P8) -> 13466 | Q9: =SUM(Q7:Q8) -> 14432 | R9: =SUM(R7:R8) -> 12758 | S9: =SUM(S7:S8) -> 13144 | T9: =SUM(T7:T8) -> 53800 | V9: =SUM(V7:V8) -> 10635 | W9: =SUM(W7:W8) -> 9997 | X9: =SUM(X7:X8) -> 9881 | Y9: =SUM(Y7:Y8) -> 11235 | Z9: =SUM(Z7:Z8) -> 41748 | AB9: =SUM(AB7:AB8) -> 11887 | AC9: =SUM(AC7:AC8) -> 12889 | AD9: =SUM(AD7:AD8) -> 12397 | AE9: =SUM(AE7:AE8) -> 13798 | AF9: =SUM(AF7:AF8) -> 50971 | AH9: =SUM(AH7:AH8) -> 13589 | AI9: =SUM(AI7:AI8) -> 14247 | AJ9: =SUM(AJ7:AJ8) -> 14994 | AK9: =SUM(AK7:AK8) -> 16597 | AL9: =SUM(AL7:AL8) -> 59427 | AN9: =SUM(AN7:AN8) -> 15862 | AO9: =SUM(AO7:AO8) -> 17318 | AP9: =SUM(AP7:AP8) -> 16810 | AQ9: =SUM(AQ7:AQ8) -> 17070 | AR9: =SUM(AR7:AR8) -> 67060 | AT9: =SUM(AT7:AT8) -> 15799 | AU9: =SUM(AU7:AU8) -> 16689 | AV9: =SUM(AV7:AV8) -> 16106 | AW9: =SUM(AW7:AW8) -> 16687.25 | AX9: =SUM(AX7:AX8) -> 65281.25 | AZ9: =SUM(AZ7:AZ8) -> 15394.05 | BA9: =SUM(BA7:BA8) -> 16448.2 | BB9: =SUM(BB7:BB8) -> 16181.89 | BC9: =SUM(BC7:BC8) -> 16953.585 | BD9: =SUM(BD7:BD8) -> 64977.725 | BF9: =SUM(BF7:BF8) -> 16121.611 | BG9: =SUM(BG7:BG8) -> 17225.377 | BH9: =SUM(BH7:BH8) -> 16944.719 | BI9: =SUM(BI7:BI8) -> 17749.021 | BJ9: =SUM(BJ7:BJ8) -> 68040.728 | BL9: =SUM(BL7:BL8) -> 16780.706 | BM9: =SUM(BM7:BM8) -> 17933.452 | BN9: =SUM(BN7:BN8) -> 17639.361 | BO9: =SUM(BO7:BO8) -> 18480.803 | BP9: =SUM(BP7:BP8) -> 70834.323 | BR9: =SUM(BR7:BR8) -> 17467.897 | BS9: =SUM(BS7:BS8) -> 18671.864 | BT9: =SUM(BT7:BT8) -> 18363.69 | BU9: =SUM(BU7:BU8) -> 19244.106 | BV9: =SUM(BV7:BV8) -> 73747.556 | BX9: =SUM(BX7:BX8) -> 18184.421 | BY9: =SUM(BY7:BY8) -> 19441.956 | BZ9: =SUM(BZ7:BZ8) -> 19119.017 | CA9: =SUM(CA7:CA8) -> 20040.332 | CB9: =SUM(CB7:CB8) -> 76785.726 | CD9: =SUM(CD7:CD8) -> 18931.574 | CE9: =SUM(CE7:CE8) -> 20245.132 | CF9: =SUM(CF7:CF8) -> 19906.714 | CG9: =SUM(CG7:CG8) -> 20870.949 | CH9: =SUM(CH7:CH8) -> 79954.369 | CJ9: =SUM(CJ7:CJ8) -> 19710.708 | CK9: =SUM(CK7:CK8) -> 21082.861 | CL9: =SUM(CL7:CL8) -> 20728.214 | CM9: =SUM(CM7:CM8) -> 21737.493 | CN9: =SUM(CN7:CN8) -> 83259.276
B10: Growth YoY (%) | J10: =J9/D9-1 -> 0.30920383 | K10: =K9/E9-1 -> 0.23651928 | L10: =L9/F9-1 -> 0.18373784 | M10: =M9/G9-1 -> 0.11212779 | N10: =N9/H9-1 -> 0.2036866 | P10: =P9/J9-1 -> 0.047204293 | Q10: =Q9/K9-1 -> 0.03004782 | R10: =R9/L9-1 -> -0.055662472 | S10: =S9/M9-1 -> -0.083530888 | T10: =T9/N9-1 -> -0.016848799 | V10: =V9/P9-1 -> -0.21023318 | W10: =W9/Q9-1 -> -0.30730322 | X10: =X9/R9-1 -> -0.22550557 | Y10: =Y9/S9-1 -> -0.14523737 | Z10: =Z9/T9-1 -> -0.22401487 | AB10: =AB9/V9-1 -> 0.11772449 | AC10: =AC9/W9-1 -> 0.28928679 | AD10: =AD9/X9-1 -> 0.2546301 | AE10: =AE9/Y9-1 -> 0.22812639 | AF10: =AF9/Z9-1 -> 0.22092076 | AH10: =AH9/AB9-1 -> 0.14318163 | AI10: =AI9/AC9-1 -> 0.10536116 | AJ10: =AJ9/AD9-1 -> 0.20948617 | AK10: =AK9/AE9-1 -> 0.20285549 | AL10: =AL9/AF9-1 -> 0.16589826 | AN10: =AN9/AH9-1 -> 0.16726764 | AO10: =AO9/AI9-1 -> 0.21555415 | AP10: =AP9/AJ9-1 -> 0.12111511 | AQ10: =AQ9/AK9-1 -> 0.028499126 | AR10: =AR9/AL9-1 -> 0.1284433 | AT10: =AT9/AN9-1 -> -0.0039717564 | AU10: =AU9/AO9-1 -> -0.036320591 | AV10: =AV9/AP9-1 -> -0.041879833 | AW10: =AW9/AQ9-1 -> -0.022422378 | AX10: =AX9/AR9-1 -> -0.026524754 | AZ10: =AZ9/AT9-1 -> -0.025631369 | BA10: =BA9/AU9-1 -> -0.014428666 | BB10: =BB9/AV9-1 -> 0.0047119086 | BC10: =BC9/AW9-1 -> 0.015960359 | BD10: =BD9/AX9-1 -> -0.004649505 | BF10: =BF9/AZ9-1 -> 0.047262473 | BG10: =BG9/BA9-1 -> 0.047249972 | BH10: =BH9/BB9-1 -> 0.047140929 | BI10: =BI9/BC9-1 -> 0.046918491 | BJ10: =BJ9/BD9-1 -> 0.04713929 | BL10: =BL9/BF9-1 -> 0.040882712 | BM10: =BM9/BG9-1 -> 0.041106523 | BN10: =BN9/BH9-1 -> 0.04099458 | BO10: =BO9/BI9-1 -> 0.041229443 | BP10: =BP9/BJ9-1 -> 0.04105768 | BR10: =BR9/BL9-1 -> 0.040951229 | BS10: =BS9/BM9-1 -> 0.041175115 | BT10: =BT9/BN9-1 -> 0.041063214 | BU10: =BU9/BO9-1 -> 0.041302438 | BV10: =BV9/BP9-1 -> 0.041127429 | BX10: =BX9/BR9-1 -> 0.0410195 | BY10: =BY9/BS9-1 -> 0.041243436 | BZ10: =BZ9/BT9-1 -> 0.041131574 | CA10: =CA9/BU9-1 -> 0.041375056 | CB10: =CB9/BV9-1 -> 0.041196886 | CD10: =CD9/BX9-1 -> 0.04108752 | CE10: =CE9/BY9-1 -> 0.041311483 | CF10: =CF9/BZ9-1 -> 0.041199658 | CG10: =CG9/CA9-1 -> 0.041447296 | CH10: =CH9/CB9-1 -> 0.041266046 | CJ10: =CJ9/CD9-1 -> 0.041155287 | CK10: =CK9/CE9-1 -> 0.04137925 | CL10: =CL9/CF9-1 -> 0.041267461 | CM10: =CM9/CG9-1 -> 0.041519155 | CN10: =CN9/CH9-1 -> 0.041334908
B11: Growth YoY ($mm) | J11: =J9-D9 -> 3037 | K11: =K9-E9 -> 2680 | L11: =L9-F9 -> 2097 | M11: =M9-G9 -> 1446 | N11: =N9-H9 -> 9260 | P11: =P9-J9 -> 607 | Q11: =Q9-K9 -> 421 | R11: =R9-L9 -> -752 | S11: =S9-M9 -> -1198 | T11: =T9-N9 -> -922 | V11: =V9-P9 -> -2831 | W11: =W9-Q9 -> -4435 | X11: =X9-R9 -> -2877 | Y11: =Y9-S9 -> -1909 | Z11: =Z9-T9 -> -12052 | AB11: =AB9-V9 -> 1252 | AC11: =AC9-W9 -> 2892 | AD11: =AD9-X9 -> 2516 | AE11: =AE9-Y9 -> 2563 | AF11: =AF9-Z9 -> 9223 | AH11: =AH9-AB9 -> 1702 | AI11: =AI9-AC9 -> 1358 | AJ11: =AJ9-AD9 -> 2597 | AK11: =AK9-AE9 -> 2799 | AL11: =AL9-AF9 -> 8456 | AN11: =AN9-AH9 -> 2273 | AO11: =AO9-AI9 -> 3071 | AP11: =AP9-AJ9 -> 1816 | AQ11: =AQ9-AK9 -> 473 | AR11: =AR9-AL9 -> 7633 | AT11: =AT9-AN9 -> -63 | AU11: =AU9-AO9 -> -629 | AV11: =AV9-AP9 -> -704 | AW11: =AW9-AQ9 -> -382.75 | AX11: =AX9-AR9 -> -1778.75 | AZ11: =AZ9-AT9 -> -404.95 | BA11: =BA9-AU9 -> -240.8 | BB11: =BB9-AV9 -> 75.89 | BC11: =BC9-AW9 -> 266.3345 | BD11: =BD9-AX9 -> -303.5255 | BF11: =BF9-AZ9 -> 727.56088 | BG11: =BG9-BA9 -> 777.17699 | BH11: =BH9-BB9 -> 762.82933 | BI11: =BI9-BC9 -> 795.4366 | BJ11: =BJ9-BD9 -> 3063.0038 | BL11: =BL9-BF9 -> 659.09517 | BM11: =BM9-BG9 -> 708.07535 | BN11: =BN9-BH9 -> 694.64164 | BO11: =BO9-BI9 -> 731.78226 | BP11: =BP9-BJ9 -> 2793.5944 | BR11: =BR9-BL9 -> 687.19054 | BS11: =BS9-BM9 -> 738.41197 | BT11: =BT9-BN9 -> 724.32885 | BU11: =BU9-BO9 -> 763.30223 | BV11: =BV9-BP9 -> 2913.2336 | BX11: =BX9-BR9 -> 716.52438 | BY11: =BY9-BS9 -> 770.09185 | BZ11: =BZ9-BT9 -> 755.32747 | CA11: =CA9-BU9 -> 796.22595 | CB11: =CB9-BV9 -> 3038.1696 | CD11: =CD9-BX9 -> 747.15276 | CE11: =CE9-BY9 -> 803.17603 | CF11: =CF9-BZ9 -> 787.69697 | CG11: =CG9-CA9 -> 830.61756 | CH11: =CH9-CB9 -> 3168.6433 | CJ11: =CJ9-CD9 -> 779.13434 | CK11: =CK9-CE9 -> 837.72839 | CL11: =CL9-CF9 -> 821.49956 | CM11: =CM9-CG9 -> 866.54417 | CN11: =CN9-CH9 -> 3304.9065
B12: Growth QoQ (%) | J12: =J9/G9-1 -> -0.0028691067 | K12: =K9/J9-1 -> 0.08958706 | L12: =L9/K9-1 -> -0.035757619 | M12: =M9/L9-1 -> 0.061584012 | N12: =AVERAGE(J12:M12) -> 0.028136086 | P12: =P9/M9-1 -> -0.061079347 | Q12: =Q9/P9-1 -> 0.071736225 | R12: =R9/Q9-1 -> -0.11599224 | S12: =S9/R9-1 -> 0.030255526 | T12: =AVERAGE(P12:S12) -> -0.018769959 | V12: =V9/S9-1 -> -0.19088558 | W12: =W9/V9-1 -> -0.059990597 | X12: =X9/W9-1 -> -0.011603481 | Y12: =Y9/X9-1 -> 0.13703066 | Z12: =AVERAGE(V12:Y12) -> -0.031362247 | AB12: =AB9/Y9-1 -> 0.058032933 | AC12: =AC9/AB9-1 -> 0.084293766 | AD12: =AD9/AC9-1 -> -0.038172085 | AE12: =AE9/AD9-1 -> 0.11301121 | AF12: =AVERAGE(AB12:AE12) -> 0.054291457 | AH12: =AH9/AE9-1 -> -0.015147123 | AI12: =AI9/AH9-1 -> 0.048421517 | AJ12: =AJ9/AI9-1 -> 0.052432091 | AK12: =AK9/AJ9-1 -> 0.10690943 | AL12: =AVERAGE(AH12:AK12) -> 0.048153979 | AN12: =AN9/AK9-1 -> -0.044285112 | AO12: =AO9/AN9-1 -> 0.091791703 | AP12: =AP9/AO9-1 -> -0.029333641 | AQ12: =AQ9/AP9-1 -> 0.015466984 | AR12: =AVERAGE(AN12:AQ12) -> 0.0084099836 | AT12: =AT9/AQ9-1 -> -0.074458114 | AU12: =AU9/AT9-1 -> 0.056332679 | AV12: =AV9/AU9-1 -> -0.03493319 | AW12: =AW9/AV9-1 -> 0.036089035 | AX12: =AVERAGE(AT12:AW12) -> -0.0042423972 | AZ12: =AZ9/AW9-1 -> -0.077496292 | BA12: =BA9/AZ9-1 -> 0.068477756 | BB12: =BB9/BA9-1 -> -0.016190829 | BC12: =BC9/BB9-1 -> 0.047688774 | BD12: =AVERAGE(AZ12:BC12) -> 0.0056198522 | BF12: =BF9/BC9-1 -> -0.049073612 | BG12: =BG9/BF9-1 -> 0.068465001 | BH12: =BH9/BG9-1 -> -0.016293267 | BI12: =BI9/BH9-1 -> 0.04746622 | BJ12: =AVERAGE(BF12:BI12) -> 0.012641086 | BL12: =BL9/BI9-1 -> -0.054555969 | BM12: =BM9/BL9-1 -> 0.068694743 | BN12: =BN9/BM9-1 -> -0.016399038 | BO12: =BO9/BN9-1 -> 0.047702544 | BP12: =AVERAGE(BL12:BO12) -> 0.01136057 | BR12: =BR9/BO9-1 -> -0.05480859 | BS12: =BS9/BR9-1 -> 0.068924596 | BT12: =BT9/BS9-1 -> -0.016504752 | BU12: =BU9/BT9-1 -> 0.047943293 | BV12: =AVERAGE(BR12:BU12) -> 0.011388637 | BX12: =BX9/BU9-1 -> -0.055065413 | BY12: =BY9/BX9-1 -> 0.069154536 | BZ12: =BZ9/BY9-1 -> -0.01661041 | CA12: =CA9/BZ9-1 -> 0.048188368 | CB12: =AVERAGE(BX12:CA12) -> 0.01141677 | CD12: =CD9/CA9-1 -> -0.055326321 | CE12: =CE9/CD9-1 -> 0.069384536 | CF12: =CF9/CE9-1 -> -0.016716015 | CG12: =CG9/CF9-1 -> 0.048437669 | CH12: =AVERAGE(CD12:CG12) -> 0.011444967 | CJ12: =CJ9/CG9-1 -> -0.055591196 | CK12: =CK9/CJ9-1 -> 0.069614573 | CL12: =CL9/CK9-1 -> -0.016821568 | CM12: =CM9/CL9-1 -> 0.048691096 | CN12: =AVERAGE(CJ12:CM12) -> 0.011473226
B13: Growth QoQ ($mm) | J13: =J9-G9 -> -37 | K13: =K9-J9 -> 1152 | L13: =L9-K9 -> -501 | M13: =M9-L9 -> 832 | N13: =AVERAGE(J13:M13) -> 361.5 | P13: =P9-M9 -> -876 | Q13: =Q9-P9 -> 966 | R13: =R9-Q9 -> -1674 | S13: =S9-R9 -> 386 | T13: =AVERAGE(P13:S13) -> -299.5 | V13: =V9-S9 -> -2509 | W13: =W9-V9 -> -638 | X13: =X9-W9 -> -116 | Y13: =Y9-X9 -> 1354 | Z13: =AVERAGE(V13:Y13) -> -477.25 | AB13: =AB9-Y9 -> 652 | AC13: =AC9-AB9 -> 1002 | AD13: =AD9-AC9 -> -492 | AE13: =AE9-AD9 -> 1401 | AF13: =AVERAGE(AB13:AE13) -> 640.75 | AH13: =AH9-AE9 -> -209 | AI13: =AI9-AH9 -> 658 | AJ13: =AJ9-AI9 -> 747 | AK13: =AK9-AJ9 -> 1603 | AL13: =AVERAGE(AH13:AK13) -> 699.75 | AN13: =AN9-AK9 -> -735 | AO13: =AO9-AN9 -> 1456 | AP13: =AP9-AO9 -> -508 | AQ13: =AQ9-AP9 -> 260 | AR13: =AVERAGE(AN13:AQ13) -> 118.25 | AT13: =AT9-AQ9 -> -1271 | AU13: =AU9-AT9 -> 890 | AV13: =AV9-AU9 -> -583 | AW13: =AW9-AV9 -> 581.25 | AX13: =AVERAGE(AT13:AW13) -> -95.6875 | AZ13: =AZ9-AW9 -> -1293.2 | BA13: =BA9-AZ9 -> 1054.15 | BB13: =BB9-BA9 -> -266.31 | BC13: =BC9-BB9 -> 771.6945 | BD13: =AVERAGE(AZ13:BC13) -> 66.583625 | BF13: =BF9-BC9 -> -831.97362 | BG13: =BG9-BF9 -> 1103.7661 | BH13: =BH9-BG9 -> -280.65766 | BI13: =BI9-BH9 -> 804.30177 | BJ13: =AVERAGE(BF13:BI13) -> 198.85915 | BL13: =BL9-BI9 -> -968.31505 | BM13: =BM9-BL9 -> 1152.7463 | BN13: =BN9-BM9 -> -294.09137 | BO13: =BO9-BN9 -> 841.44239 | BP13: =AVERAGE(BL13:BO13) -> 182.94556 | BR13: =BR9-BO9 -> -1012.9068 | BS13: =BS9-BR9 -> 1203.9677 | BT13: =BT9-BS9 -> -308.17449 | BU13: =BU9-BT9 -> 880.41577 | BV13: =AVERAGE(BR13:BU13) -> 190.82556 | BX13: =BX9-BU9 -> -1059.6846 | BY13: =BY9-BX9 -> 1257.5352 | BZ13: =BZ9-BY9 -> -322.93887 | CA13: =CA9-BZ9 -> 921.31425 | CB13: =AVERAGE(BX13:CA13) -> 199.05649 | CD13: =CD9-CA9 -> -1108.7578 | CE13: =CE9-CD9 -> 1313.5585 | CF13: =CF9-CE9 -> -338.41793 | CG13: =CG9-CF9 -> 964.23484 | CH13: =AVERAGE(CD13:CG13) -> 207.65439 | CJ13: =CJ9-CG9 -> -1160.241 | CK13: =CK9-CJ9 -> 1372.1525 | CL13: =CL9-CK9 -> -354.64676 | CM13: =CM9-CL9 -> 1009.2795 | CN13: =AVERAGE(CJ13:CM13) -> 216.63604
B15: Cost of Goods Sold ($mm) | D15: 6801 | E15: 7816 | F15: 7678 | G15: =H15-SUM(D15:F15) -> 8965 | H15: 31260 | J15: 8566 | K15: 9422 | L15: 9022 | M15: =N15-SUM(J15:L15) -> 9987 | N15: 36997 | P15: 9003 | Q15: 9941 | R15: 8569 | S15: =T15-SUM(P15:R15) -> 9117 | T15: 36630 | V15: 7266 | W15: 7113 | X15: 6919 | Y15: =Z15-SUM(V15:X15) -> 7784 | Z15: 29082 | AB15: 8012 | AC15: 8881 | AD15: 8617 | AE15: =AF15-SUM(AB15:AD15) -> 10003 | AF15: 35513 | AH15: 9559 | AI15: 9975 | AJ15: 10202 | AK15: =AL15-SUM(AH15:AJ15) -> 11614 | AL15: 41350 | AN15: 10103 | AO15: 11065 | AP15: 10583 | AQ15: =AR15-SUM(AN15:AP15) -> 11016 | AR15: 42767 | AT15: 9662 | AU15: 10150 | AV15: 10066 | AW15: =AW9-AW17 -> 10650.102 | AX15: =AX9-AX17 -> 40528.102 | AZ15: =AZ9-AZ17 -> 9611.8373 | BA15: =BA9-BA17 -> 9971.0438 | BB15: =BB9-BB17 -> 10202.696 | BC15: =BC9-BC17 -> 10781.065 | BD15: =BD9-BD17 -> 40566.642 | BF15: =BF9-BF17 -> 9955.9624 | BG15: =BG9-BG17 -> 10324.03 | BH15: =BH9-BH17 -> 10556.059 | BI15: =BI9-BI17 -> 11151.237 | BJ15: =BJ9-BJ17 -> 41987.289 | BL15: =BL9-BL17 -> 10310.133 | BM15: =BM9-BM17 -> 10692.063 | BN15: =BN9-BN17 -> 10923.02 | BO15: =BO9-BO17 -> 11540.478 | BP15: =BP9-BP17 -> 43465.694 | BR15: =BR9-BR17 -> 10676.277 | BS15: =BS9-BS17 -> 11072.537 | BT15: =BT9-BT17 -> 11302.235 | BU15: =BU9-BU17 -> 11943.129 | BV15: =BV9-BV17 -> 44994.177 | BX15: =BX9-BX17 -> 11058.352 | BY15: =BY9-BY17 -> 11469.66 | BZ15: =BZ9-BZ17 -> 11697.99 | CA15: =CA9-CA17 -> 12363.464 | CB15: =CB9-CB17 -> 46589.466 | CD15: =CD9-CD17 -> 11457.075 | CE15: =CE9-CE17 -> 11884.184 | CF15: =CF9-CF17 -> 12111.031 | CG15: =CG9-CG17 -> 12802.284 | CH15: =CH9-CH17 -> 48254.574 | CJ15: =CJ9-CJ17 -> 11867.555 | CK15: =CK9-CK17 -> 12311.181 | CL15: =CL9-CL17 -> 12536.252 | CM15: =CM9-CM17 -> 13254.54 | CN15: =CN9-CN17 -> 49969.529
B17: Gross Margin ($mm) | D17: =D9-D15 -> 3021 | E17: =E9-E15 -> 3515 | F17: =F9-F15 -> 3735 | G17: =G9-G15 -> 3931 | H17: =H9-H15 -> 14202 | J17: =J9-J15 -> 4293 | K17: =K9-K15 -> 4589 | L17: =L9-L15 -> 4488 | M17: =M9-M15 -> 4355 | N17: =N9-N15 -> 17725 | P17: =P9-P15 -> 4463 | Q17: =Q9-Q15 -> 4491 | R17: =R9-R15 -> 4189 | S17: =S9-S15 -> 4027 | T17: =T9-T15 -> 17170 | V17: =V9-V15 -> 3369 | W17: =W9-W15 -> 2884 | X17: =X9-X15 -> 2962 | Y17: =Y9-Y15 -> 3451 | Z17: =Z9-Z15 -> 12666 | AB17: =AB9-AB15 -> 3875 | AC17: =AC9-AC15 -> 4008 | AD17: =AD9-AD15 -> 3780 | AE17: =AE9-AE15 -> 3795 | AF17: =AF9-AF15 -> 15458 | AH17: =AH9-AH15 -> 4030 | AI17: =AI9-AI15 -> 4272 | AJ17: =AJ9-AJ15 -> 4792 | AK17: =AK9-AK15 -> 4983 | AL17: =AL9-AL15 -> 18077 | AN17: =AN9-AN15 -> 5759 | AO17: =AO9-AO15 -> 6253 | AP17: =AP9-AP15 -> 6227 | AQ17: =AQ9-AQ15 -> 6054 | AR17: =AR9-AR15 -> 24293 | AT17: =AT9-AT15 -> 6137 | AU17: =AU9-AU15 -> 6539 | AV17: =AV9-AV15 -> 6040 | AW17: =AW42+AW39 -> 6037.1476 | AX17: =AX42+AX39 -> 24753.148 | AZ17: =AZ42+AZ39 -> 5782.2127 | BA17: =BA42+BA39 -> 6477.1562 | BB17: =BB42+BB39 -> 5979.1937 | BC17: =BC42+BC39 -> 6172.5195 | BD17: =BD42+BD39 -> 24411.082 | BF17: =BF42+BF39 -> 6165.6485 | BG17: =BG42+BG39 -> 6901.3473 | BH17: =BH42+BH39 -> 6388.6599 | BI17: =BI42+BI39 -> 6597.7841 | BJ17: =BJ42+BJ39 -> 26053.44 | BL17: =BL42+BL39 -> 6470.5727 | BM17: =BM42+BM39 -> 7241.3894 | BN17: =BN42+BN39 -> 6716.3407 | BO17: =BO42+BO39 -> 6940.3258 | BP17: =BP42+BP39 -> 27368.629 | BR17: =BR42+BR39 -> 6791.6199 | BS17: =BS42+BS39 -> 7599.3272 | BT17: =BT42+BT39 -> 7061.4549 | BU17: =BU42+BU39 -> 7300.9768 | BV17: =BV42+BV39 -> 28753.379 | BX17: =BX42+BX39 -> 7126.0689 | BY17: =BY42+BY39 -> 7972.296 | BZ17: =BZ42+BZ39 -> 7421.0269 | CA17: =CA42+CA39 -> 7676.868 | CB17: =CB42+CB39 -> 30196.26 | CD17: =CD42+CD39 -> 7474.4985 | CE17: =CE42+CE39 -> 8360.9484 | CF17: =CF42+CF39 -> 7795.6829 | CG17: =CG42+CG39 -> 8068.6655 | CH17: =CH42+CH39 -> 31699.795 | CJ17: =CJ42+CJ39 -> 7843.1531 | CK17: =CK42+CK39 -> 8771.6795 | CL17: =CL42+CL39 -> 8191.9614 | CM17: =CM42+CM39 -> 8482.953 | CN17: =CN42+CN39 -> 33289.747
B18: Gross Margin (%) | D18: =D17/D9 -> 0.30757483 | E18: =E17/E9 -> 0.31021093 | F18: =F17/F9 -> 0.32725839 | G18: =G17/G9 -> 0.3048232 | H18: =H17/H9 -> 0.31239277 | J18: =J17/J9 -> 0.33385178 | K18: =K17/K9 -> 0.32752837 | L18: =L17/L9 -> 0.33219837 | M18: =M17/M9 -> 0.3036536 | N18: =N17/N9 -> 0.32390994 | P18: =P17/P9 -> 0.3314273 | Q18: =Q17/Q9 -> 0.31118348 | R18: =R17/R9 -> 0.328343 | S18: =S17/S9 -> 0.30637553 | T18: =T17/T9 -> 0.31914498 | V18: =V17/V9 -> 0.3167842 | W18: =W17/W9 -> 0.28848655 | X18: =X17/X9 -> 0.29976723 | Y18: =Y17/Y9 -> 0.30716511 | Z18: =Z17/Z9 -> 0.30339178 | AB18: =AB17/AB9 -> 0.32598637 | AC18: =AC17/AC9 -> 0.31096284 | AD18: =AD17/AD9 -> 0.30491248 | AE18: =AE17/AE9 -> 0.27503986 | AF18: =AF17/AF9 -> 0.30327049 | AH18: =AH17/AH9 -> 0.2965634 | AI18: =AI17/AI9 -> 0.2998526 | AJ18: =AJ17/AJ9 -> 0.3195945 | AK18: =AK17/AK9 -> 0.30023498 | AL18: =AL17/AL9 -> 0.30418833 | AN18: =AN17/AN9 -> 0.36306897 | AO18: =AO17/AO9 -> 0.36106941 | AP18: =AP17/AP9 -> 0.37043427 | AQ18: =AQ17/AQ9 -> 0.35465729 | AR18: =AR17/AR9 -> 0.36225768 | AT18: =AT17/AT9 -> 0.38844231 | AU18: =AU17/AU9 -> 0.39181497 | AV18: =AV17/AV9 -> 0.37501552 | AW18: =AW17/AW9 -> 0.36178205 | AX18: =AX17/AX9 -> 0.37917699 | AZ18: =AZ17/AZ9 -> 0.37561348 | BA18: =BA17/BA9 -> 0.39379119 | BB18: =BB17/BB9 -> 0.36949909 | BC18: =BC17/BC9 -> 0.36408345 | BD18: =BD17/BD9 -> 0.37568385 | BF18: =BF17/BF9 -> 0.38244618 | BG18: =BG17/BG9 -> 0.40065 | BH18: =BH17/BH9 -> 0.37702955 | BI18: =BI17/BI9 -> 0.37172665 | BJ18: =BJ17/BJ9 -> 0.38290948 | BL18: =BL17/BL9 -> 0.38559597 | BM18: =BM17/BM9 -> 0.40379227 | BN18: =BN17/BN9 -> 0.38075873 | BO18: =BO17/BO9 -> 0.37554243 | BP18: =BP17/BP9 -> 0.38637524 | BR18: =BR17/BR9 -> 0.38880582 | BS18: =BS17/BS9 -> 0.40699349 | BT18: =BT17/BT9 -> 0.38453355 | BU18: =BU17/BU9 -> 0.37938769 | BV18: =BV17/BV9 -> 0.38988924 | BX18: =BX17/BX9 -> 0.39187769 | BY18: =BY17/BY9 -> 0.41005627 | BZ18: =BZ17/BZ9 -> 0.38814897 | CA18: =CA17/CA9 -> 0.38307091 | CB18: =CB17/CB9 -> 0.39325356 | CD18: =CD17/CD9 -> 0.39481654 | CE18: =CE17/CE9 -> 0.41298562 | CF18: =CF17/CF9 -> 0.39161073 | CG18: =CG17/CG9 -> 0.38659792 | CH18: =CH17/CH9 -> 0.39647358 | CJ18: =CJ17/CJ9 -> 0.39791331 | CK18: =CK17/CK9 -> 0.41605737 | CL18: =CL17/CL9 -> 0.39520826 | CM18: =CM17/CM9 -> 0.39024523 | CN18: =CN17/CN9 -> 0.39983229
B20: Expenses:
B21: SG&A ($mm) | D21: 1061 | E21: 1304 | F21: 1254 | G21: =H21-SUM(D21:F21) -> 1380 | H21: 4999 | J21: 1276 | K21: 1440 | L21: 1299 | M21: =N21-SUM(J21:L21) -> 1463 | N21: 5478 | P21: 1319 | Q21: 1309 | R21: 1251 | S21: 1283 | T21: =+SUM(P21:S21) -> 5162 | V21: 1121 | W21: 1179 | X21: 1126 | Y21: =Z21-SUM(V21:X21) -> 1216 | Z21: 4642 | AB21: 1239 | AC21: 1364 | AD21: 1340 | AE21: =AF21-SUM(AB21:AD21) -> 1422 | AF21: 5365 | AH21: 1346 | AI21: 1425 | AJ21: 1401 | AK21: =AL21-SUM(AH21:AJ21) -> 1479 | AL21: 5651 | AN21: 1463 | AO21: 1528 | AP21: 1624 | AQ21: =AR21-SUM(AN21:AP21) -> 1756 | AR21: 6371 | AT21: 1577 | AU21: 1652 | AV21: 1669 | AW21: =AW$9*AW22 -> 1668.725 | AX21: =SUM(AT21:AW21) -> 6566.725 | AZ21: =AZ$9*AZ22 -> 1539.405 | BA21: =BA$9*BA22 -> 1644.82 | BB21: =BB$9*BB22 -> 1618.189 | BC21: =BC$9*BC22 -> 1695.3585 | BD21: =SUM(AZ21:BC21) -> 6497.7725 | BF21: =BF$9*BF22 -> 1612.1611 | BG21: =BG$9*BG22 -> 1722.5377 | BH21: =BH$9*BH22 -> 1694.4719 | BI21: =BI$9*BI22 -> 1774.9021 | BJ21: =SUM(BF21:BI21) -> 6804.0728 | BL21: =BL$9*BL22 -> 1678.0706 | BM21: =BM$9*BM22 -> 1793.3452 | BN21: =BN$9*BN22 -> 1763.9361 | BO21: =BO$9*BO22 -> 1848.0803 | BP21: =SUM(BL21:BO21) -> 7083.4323 | BR21: =BR$9*BR22 -> 1746.7897 | BS21: =BS$9*BS22 -> 1867.1864 | BT21: =BT$9*BT22 -> 1836.369 | BU21: =BU$9*BU22 -> 1924.4106 | BV21: =SUM(BR21:BU21) -> 7374.7556 | BX21: =BX$9*BX22 -> 1818.4421 | BY21: =BY$9*BY22 -> 1944.1956 | BZ21: =BZ$9*BZ22 -> 1911.9017 | CA21: =CA$9*CA22 -> 2004.0332 | CB21: =SUM(BX21:CA21) -> 7678.5726 | CD21: =CD$9*CD22 -> 1893.1574 | CE21: =CE$9*CE22 -> 2024.5132 | CF21: =CF$9*CF22 -> 1990.6714 | CG21: =CG$9*CG22 -> 2087.0949 | CH21: =SUM(CD21:CG21) -> 7995.4369 | CJ21: =CJ$9*CJ22 -> 1971.0708 | CK21: =CK$9*CK22 -> 2108.2861 | CL21: =CL$9*CL22 -> 2072.8214 | CM21: =CM$9*CM22 -> 2173.7493 | CN21: =SUM(CJ21:CM21) -> 8325.9276
B22: % of Revenue | D22: =D21/D$9 -> 0.10802281 | E22: =E21/E$9 -> 0.11508252 | F22: =F21/F$9 -> 0.1098747 | G22: =G21/G$9 -> 0.10700993 | H22: =H21/H$9 -> 0.10995997 | J22: =J21/J$9 -> 0.099230111 | K22: =K21/K$9 -> 0.10277639 | L22: =L21/L$9 -> 0.096150999 | M22: =M21/M$9 -> 0.10200809 | N22: =N21/N$9 -> 0.10010599 | P22: =P21/P$9 -> 0.097950394 | Q22: =Q21/Q$9 -> 0.09070122 | R22: =R21/R$9 -> 0.098056122 | S22: =S21/S$9 -> 0.097611077 | T22: =T21/T$9 -> 0.095947955 | V22: =V21/V$9 -> 0.10540668 | W22: =W21/W$9 -> 0.11793538 | X22: =X21/X$9 -> 0.11395608 | Y22: =Y21/Y$9 -> 0.1082332 | Z22: =Z21/Z$9 -> 0.11119096 | AB22: =AB21/AB$9 -> 0.10423151 | AC22: =AC21/AC$9 -> 0.10582667 | AD22: =AD21/AD$9 -> 0.10809067 | AE22: =AE21/AE$9 -> 0.10305841 | AF22: =AF21/AF$9 -> 0.10525593 | AH22: =AH21/AH$9 -> 0.099050703 | AI22: =AI21/AI$9 -> 0.10002106 | AJ22: =AJ21/AJ$9 -> 0.093437375 | AK22: =AK21/AK$9 -> 0.08911249 | AL22: =AL21/AL$9 -> 0.095091457 | AN22: =AN21/AN$9 -> 0.09223301 | AO22: =AO21/AO$9 -> 0.088231897 | AP22: =AP21/AP$9 -> 0.096609161 | AQ22: =AQ21/AQ$9 -> 0.10287053 | AR22: =AR21/AR$9 -> 0.095004474 | AT22: =AT21/AT$9 -> 0.099816444 | AU22: =AU21/AU$9 -> 0.098987357 | AV22: =AV21/AV$9 -> 0.10362598 | AW22: 0.1 | AX22: =AX21/AX$9 -> 0.10059129 | AZ22: 0.1 | BA22: 0.1 | BB22: 0.1 | BC22: 0.1 | BD22: =BD21/BD$9 -> 0.1 | BF22: 0.1 | BG22: 0.1 | BH22: 0.1 | BI22: 0.1 | BJ22: =BJ21/BJ$9 -> 0.1 | BL22: 0.1 | BM22: 0.1 | BN22: 0.1 | BO22: 0.1 | BP22: =BP21/BP$9 -> 0.1 | BR22: 0.1 | BS22: 0.1 | BT22: 0.1 | BU22: 0.1 | BV22: =BV21/BV$9 -> 0.1 | BX22: 0.1 | BY22: 0.1 | BZ22: 0.1 | CA22: 0.1 | CB22: =CB21/CB$9 -> 0.1 | CD22: 0.1 | CE22: 0.1 | CF22: 0.1 | CG22: 0.1 | CH22: =CH21/CH$9 -> 0.1 | CJ22: 0.1 | CK22: 0.1 | CL22: 0.1 | CM22: 0.1 | CN22: =CN21/CN$9 -> 0.1
B23: Change YoY ($mm) | J23: =J21-D21 -> 215 | K23: =K21-E21 -> 136 | L23: =L21-F21 -> 45 | M23: =M21-G21 -> 83 | N23: =N21-H21 -> 479 | P23: =P21-J21 -> 43 | Q23: =Q21-K21 -> -131 | R23: =R21-L21 -> -48 | S23: =S21-M21 -> -180 | T23: =T21-N21 -> -316 | V23: =V21-P21 -> -198 | W23: =W21-Q21 -> -130 | X23: =X21-R21 -> -125 | Y23: =Y21-S21 -> -67 | Z23: =Z21-T21 -> -520 | AB23: =AB21-V21 -> 118 | AC23: =AC21-W21 -> 185 | AD23: =AD21-X21 -> 214 | AE23: =AE21-Y21 -> 206 | AF23: =AF21-Z21 -> 723 | AH23: =AH21-AB21 -> 107 | AI23: =AI21-AC21 -> 61 | AJ23: =AJ21-AD21 -> 61 | AK23: =AK21-AE21 -> 57 | AL23: =AL21-AF21 -> 286 | AN23: =AN21-AH21 -> 117 | AO23: =AO21-AI21 -> 103 | AP23: =AP21-AJ21 -> 223 | AQ23: =AQ21-AK21 -> 277 | AR23: =AR21-AL21 -> 720 | AT23: =AT21-AN21 -> 114 | AU23: =AU21-AO21 -> 124 | AV23: =AV21-AP21 -> 45 | AW23: =AW21-AQ21 -> -87.275 | AX23: =AX21-AR21 -> 195.725 | AZ23: =AZ21-AT21 -> -37.595 | BA23: =BA21-AU21 -> -7.18 | BB23: =BB21-AV21 -> -50.811 | BC23: =BC21-AW21 -> 26.63345 | BD23: =BD21-AX21 -> -68.95255 | BF23: =BF21-AZ21 -> 72.756088 | BG23: =BG21-BA21 -> 77.717699 | BH23: =BH21-BB21 -> 76.282933 | BI23: =BI21-BC21 -> 79.54366 | BJ23: =BJ21-BD21 -> 306.30038 | BL23: =BL21-BF21 -> 65.909517 | BM23: =BM21-BG21 -> 70.807535 | BN23: =BN21-BH21 -> 69.464164 | BO23: =BO21-BI21 -> 73.178226 | BP23: =BP21-BJ21 -> 279.35944 | BR23: =BR21-BL21 -> 68.719054 | BS23: =BS21-BM21 -> 73.841197 | BT23: =BT21-BN21 -> 72.432885 | BU23: =BU21-BO21 -> 76.330223 | BV23: =BV21-BP21 -> 291.32336 | BX23: =BX21-BR21 -> 71.652438 | BY23: =BY21-BS21 -> 77.009185 | BZ23: =BZ21-BT21 -> 75.532747 | CA23: =CA21-BU21 -> 79.622595 | CB23: =CB21-BV21 -> 303.81696 | CD23: =CD21-BX21 -> 74.715276 | CE23: =CE21-BY21 -> 80.317603 | CF23: =CF21-BZ21 -> 78.769697 | CG23: =CG21-CA21 -> 83.061756 | CH23: =CH21-CB21 -> 316.86433 | CJ23: =CJ21-CD21 -> 77.913434 | CK23: =CK21-CE21 -> 83.772839 | CL23: =CL21-CF21 -> 82.149956 | CM23: =CM21-CG21 -> 86.654417 | CN23: =CN21-CH21 -> 330.49065
