Workbook
Name CIRC: 'IS - Gold Solution'!$O$2

Sheet Grading
B3: Subtask Breakdown
C4: Section Name | D4: Total
C5: Income Statement Summary | D5: =COUNT('IS - Gold Solution'!F4:L57) -> 287 | F5: << Note from OAI: Make sure that all the "Total" cells in this section contain the exact range that should be checked
C6: EBITDA Calculation | D6: =COUNT('IS - Gold Solution'!F60:L74) -> 91
C7: Aggregates Revenue | D7: =COUNT('IS - Gold Solution'!F79:L83) -> 35
C8: Ready-Mix Concrete Revenue Build | D8: =COUNT('IS - Gold Solution'!F86:L90) -> 35
C9: Asphalt Revenue Build | D9: =COUNT('IS - Gold Solution'!F93:L97) -> 35
C10: Gross Margin Build | D10: =COUNT('IS - Gold Solution'!F101:L117) -> 105
C11: Balance Sheet | D11: =COUNT('BS - Gold Solution'!F4:L47) -> 245
C12: Cash Flow Statement | D12: =COUNT('CFS - Gold Solution'!F3:L43) -> 245
C13: Debt Schedule | D13: =COUNT('Debt - Gold Solution'!F4:L18) -> 84
C14: Business Metrics/ KPIs | D14: =COUNT('BS - Gold Solution'!F49:L75) -> 146
C15: Valuation | D15: =COUNT('Valuation - Gold Solution'!D3:I19) -> 58
C16: Key items are not hardcoded | D16: =COUNT('IS - Gold Solution'!F10:L10,'IS - Gold Solution'!F12:L12,'IS - Gold Solution'!F26:L26,'IS - Gold Solution'!F28:L28,'IS - Gold Solution'!F37:L37,'IS - Gold Solution'!F45:L45,'IS - Gold Solution'!F50:L50,'IS - Gold Solution'!F52:L52,'IS - Gold Solution'!F55:L55,'IS - Gold Solution'!F60:L60,'IS - Gold Solution'!F64:L64,'IS - Gold Solution'!F70:L70,'IS - Gold Solution'!F73:L73,'IS - Gold Solution'!F83:L83,'IS - Gold Solution'!F90:L90,'IS - Gold Solution'!F106:L106,'IS - Gold Solution'!F107:L108,'IS - Gold Solution'!F101:L105,'IS - Gold Solution'!F111:L113,'BS - Gold Solution'!F9:L9,'BS - Gold Solution'!F16:L16,'BS - Gold Solution'!F27:L27,'BS - Gold Solution'!F34:L34,'BS - Gold Solution'!F36:L36,'BS - Gold Solution'!F38:L39,'BS - Gold Solution'!F46:L46,'BS - Gold Solution'!F68:L68,'BS - Gold Solution'!F66:L66,'CFS - Gold Solution'!F25:L25,'CFS - Gold Solution'!F34:L34,'CFS - Gold Solution'!F42:L42,'CFS - Gold Solution'!F36:L38,'Debt - Gold Solution'!F9:L9,'Debt - Gold Solution'!F11:L11,'Debt - Gold Solution'!F17:L18) -> 322
C18: Total | D18: =SUM(D5:D9) -> 483
B22: Formatting
C23: Check | D23: Total
C24: Check that model's solution matches formatting of this range exactly in the gold solution | D24: =COUNT('Valuation - Gold Solution'!E3:I8,'IS - Gold Solution'!F4:L12,'IS - Gold Solution'!F15:L22,'IS - Gold Solution'!F24:L31,'IS - Gold Solution'!F34:L40,'IS - Gold Solution'!F43:L56,'IS - Gold Solution'!F60:L60,'IS - Gold Solution'!F62:L73,'IS - Gold Solution'!F79:L117,'IS - Gold Solution'!F122:L128,'BS - Gold Solution'!F4:L75,'CFS - Gold Solution'!F3:L43,'Debt - Gold Solution'!F4:L18) -> 1352 | F24: << Note from OAI: Make sure that all the "Total" cells in this section contain the exact range that should be checked
C26: Total | D26: =SUM(D24) -> 1352
B28: Citations
C29: Check | D29: Cell | E29: Total
C30: Citation Checks | E30: =COUNT('IS - Gold Solution'!D4:E9,'IS - Gold Solution'!D11:E11,'IS - Gold Solution'!D24:E25,'IS - Gold Solution'!D34:E34,'IS - Gold Solution'!D43:E44,'IS - Gold Solution'!D47:E47,'IS - Gold Solution'!D55:E55,'IS - Gold Solution'!D61:E62,'IS - Gold Solution'!D66:E69,'IS - Gold Solution'!D79:E79,'IS - Gold Solution'!D81:E81,'IS - Gold Solution'!D86:E86,'IS - Gold Solution'!D88:E88,'IS - Gold Solution'!D93:E93,'IS - Gold Solution'!D95:E95,'IS - Gold Solution'!D107:E107,'IS - Gold Solution'!D131:E136,'IS - Gold Solution'!D138:E138,'IS - Gold Solution'!D153:E160,'BS - Gold Solution'!D4:E8,'BS - Gold Solution'!D19:E26,'BS - Gold Solution'!D29:E33,'BS - Gold Solution'!D36:E36,'CFS - Gold Solution'!D5:E18,'CFS - Gold Solution'!D21:E24,'CFS - Gold Solution'!D27:E33) -> 172

Sheet Valuation - Gold Solution
D2: 2025 | E2: =D2+1 -> 2026 | F2: =E2+1 -> 2027 | G2: =F2+1 -> 2028 | H2: =G2+1 -> 2029 | I2: =H2+1 -> 2030
C3: Share Px | D3: 80 | E3: =E5/E4 -> 92.104461 | F3: =F5/F4 -> 106.66973 | G3: =G5/G4 -> 124.18863 | H3: =H5/H4 -> 145.26819 | I3: =I5/I4 -> 170.87704
C4: Shares Out | D4: ='IS - Gold Solution'!F55 -> 54.425 | E4: ='IS - Gold Solution'!G55 -> 52.05 | F4: ='IS - Gold Solution'!H55 -> 49.675 | G4: ='IS - Gold Solution'!I55 -> 47.3 | H4: ='IS - Gold Solution'!J55 -> 44.925 | I4: ='IS - Gold Solution'!K55 -> 42.55
C5: EqV | D5: =D3*D4 -> 4354 | E5: =E7-E6 -> 4794.0372 | F5: =F7-F6 -> 5298.8189 | G5: =G7-G6 -> 5874.1223 | H5: =H7-H6 -> 6526.1733 | I5: =I7-I6 -> 7270.8181
C6: (+) Net Debt | D6: ='BS - Gold Solution'!F67 -> 911.85739 | E6: ='BS - Gold Solution'!G67 -> 916.58632 | F6: ='BS - Gold Solution'!H67 -> 883.68381 | G6: ='BS - Gold Solution'!I67 -> 810.18065 | H6: ='BS - Gold Solution'!J67 -> 692.79699 | I6: ='BS - Gold Solution'!K67 -> 518.78988
C7: TEV | D7: =SUM(D5:D6) -> 5265.8574 | E7: =E10*E8 -> 5710.6235 | F7: =F10*F8 -> 6182.5027 | G7: =G10*G8 -> 6684.3029 | H7: =H10*H8 -> 7218.9703 | I7: =I10*I8 -> 7789.608
C8: NTM EBITDA | D8: ='IS - Gold Solution'!G70 -> 571.12762 | E8: ='IS - Gold Solution'!H70 -> 619.36634 | F8: ='IS - Gold Solution'!I70 -> 670.54571 | G8: ='IS - Gold Solution'!J70 -> 724.97027 | H8: ='IS - Gold Solution'!K70 -> 782.95955 | I8: ='IS - Gold Solution'!L70 -> 844.85013
C10: EV/EBITDA Mult. | D10: =D7/D8 -> 9.2201063 | E10: =D10 -> 9.2201063 | F10: =E10 -> 9.2201063 | G10: =F10 -> 9.2201063 | H10: =G10 -> 9.2201063 | I10: =H10 -> 9.2201063
C13: Sh Px | D13: =D3 -> 80 | E13: =E3 -> 92.104461 | F13: =F3 -> 106.66973 | G13: =G3 -> 124.18863 | H13: =H3 -> 145.26819 | I13: =I3 -> 170.87704
C14: % Upside | D14: =D13/$D$3-1 -> 0 | E14: =E13/$D$3-1 -> 0.15130576 | F14: =F13/$D$3-1 -> 0.33337164 | G14: =G13/$D$3-1 -> 0.5523579 | H14: =H13/$D$3-1 -> 0.81585233 | I14: =I13/$D$3-1 -> 1.135963
C16: YE 2030 Sh Px | D16: =I13 -> 170.87704
C17: PV Factor | D17: =1/(1+0.08)^5 -> 0.6805832
C18: YE 2025 Sh Px | D18: =D16*D17 -> 116.29604
C19: % Upside | D19: =D18/D3-1 -> 0.45370053

Sheet IS - Gold Solution
B1: Knife River (KNF) Income Statement | O1: Circ
B2: ($ million) | C2: 2022 | D2: 2023 | E2: 2024 | F2: 2025E | G2: 2026E | H2: 2027E | I2: 2028E | J2: 2029E | K2: 2030E | L2: 2031E | O2: 1
B3: Revenue
B4: Aggregates | C4: 496.6 | D4: 547.9 | E4: 556.1 | F4: =F83 -> 636.60905 | G4: =G83 -> 675.1239 | H4: =H83 -> 733.6909 | I4: =I83 -> 797.33858 | J4: =J83 -> 866.5077 | K4: =K83 -> 941.67725 | L4: =L83 -> 1023.3677
B5: Ready-Mix Concrete | C5: 609.5 | D5: 653.9 | E5: 655.5 | F5: =F90 -> 812.00992 | G5: =G90 -> 844.73392 | H5: =H90 -> 887.47746 | I5: =I90 -> 932.38382 | J5: =J90 -> 979.56244 | K5: =K90 -> 1029.1283 | L5: =L90 -> 1081.2022
B6: Asphalt | C6: 427.5 | D6: 452.4 | E6: 441.5 | F6: =F97 -> 459.35949 | G6: =G97 -> 477.91761 | H6: =H97 -> 497.22548 | I6: =I97 -> 517.31339 | J6: =J97 -> 538.21285 | K6: =K97 -> 559.95665 | L6: =L97 -> 582.5789
B7: Liquid Asphalt | C7: 207.5 | D7: 253.2 | E7: 238.9 | F7: =E7*(1+F18) -> 248.456 | G7: =F7*(1+G18) -> 258.39424 | H7: =G7*(1+H18) -> 268.73001 | I7: =H7*(1+I18) -> 279.47921 | J7: =I7*(1+J18) -> 290.65838 | K7: =J7*(1+K18) -> 302.28471 | L7: =K7*(1+L18) -> 314.3761
B8: Other | C8: 199.8 | D8: 249 | E8: 265.8 | F8: =E8*(1+F19) -> 281.748 | G8: =F8*(1+G19) -> 298.65288 | H8: =G8*(1+H19) -> 316.57205 | I8: =H8*(1+I19) -> 335.56638 | J8: =I8*(1+J19) -> 355.70036 | K8: =J8*(1+K19) -> 377.04238 | L8: =K8*(1+L19) -> 399.66492
B9: Internal Sales | C9: -593.9 | D9: -633.4 | E9: -617 | F9: =E9/SUM(E4:E8)*SUM(F4:F8) -> -697.17239 | G9: =F9/SUM(F4:F8)*SUM(G4:G8) -> -730.52438 | H9: =G9/SUM(G4:G8)*SUM(H4:H8) -> -773.09314 | I9: =H9/SUM(H4:H8)*SUM(I4:I8) -> -818.38178 | J9: =I9/SUM(I4:I8)*SUM(J4:J8) -> -866.57983 | K9: =J9/SUM(J4:J8)*SUM(K4:K8) -> -917.89095 | L9: =K9/SUM(K4:K8)*SUM(L4:L8) -> -972.53413
B10: Construction Materials Revenue | C10: =SUM(C4:C9) -> 1347 | D10: =SUM(D4:D9) -> 1523 | E10: =SUM(E4:E9) -> 1540.8 | F10: =SUM(F4:F9) -> 1741.0101 | G10: =SUM(G4:G9) -> 1824.2982 | H10: =SUM(H4:H9) -> 1930.6028 | I10: =SUM(I4:I9) -> 2043.6996 | J10: =SUM(J4:J9) -> 2164.0619 | ... L10: =SUM(L4:L9) -> 2428.6557
B11: Contracting Services | C11: 1187.7 | D11: 1307.3 | E11: 1358.2 | F11: =E11*(1+F21) -> 1480.438 | G11: =F11*(1+G21) -> 1539.6555 | H11: =G11*(1+H21) -> 1601.2417 | I11: =H11*(1+I21) -> 1665.2914 | J11: =I11*(1+J21) -> 1731.9031 | K11: =J11*(1+K21) -> 1801.1792 | L11: =K11*(1+L21) -> 1873.2264
B12: Total Revenue | C12: =+C10+C11 -> 2534.7 | D12: =+D10+D11 -> 2830.3 | E12: =+E10+E11 -> 2899 | F12: =+F10+F11 -> 3221.4481 | G12: =+G10+G11 -> 3363.9537 | H12: =+H10+H11 -> 3531.8445 | I12: =+I10+I11 -> 3708.991 | J12: =+J10+J11 -> 3895.965 | ... L12: =+L10+L11 -> 4301.8821
B14: Revenue Growth (Y/Y)
B15: Aggregates | D15: =D4/C4-1 -> 0.10330246 | E15: =E4/D4-1 -> 0.014966235 | F15: =F4/E4-1 -> 0.14477441 | G15: =G4/F4-1 -> 0.0605 | H15: =H4/G4-1 -> 0.08675 | I15: =I4/H4-1 -> 0.08675 | J15: =J4/I4-1 -> 0.08675 | K15: =K4/J4-1 -> 0.08675 | L15: =L4/K4-1 -> 0.08675
B16: Ready-Mix Concrete | D16: =D5/C5-1 -> 0.072846596 | E16: =E5/D5-1 -> 0.0024468573 | F16: =F5/E5-1 -> 0.23876418 | G16: =G5/F5-1 -> 0.0403 | H16: =H5/G5-1 -> 0.0506 | I16: =I5/H5-1 -> 0.0506 | J16: =J5/I5-1 -> 0.0506 | K16: =K5/J5-1 -> 0.0506 | L16: =L5/K5-1 -> 0.0506
B17: Asphalt | D17: =D6/C6-1 -> 0.058245614 | E17: =E6/D6-1 -> -0.024093722 | F17: =F6/E6-1 -> 0.040451843 | G17: =G6/F6-1 -> 0.0404 | H17: =H6/G6-1 -> 0.0404 | I17: =I6/H6-1 -> 0.0404 | J17: =J6/I6-1 -> 0.0404 | K17: =K6/J6-1 -> 0.0404 | L17: =L6/K6-1 -> 0.0404
B18: Liquid Asphalt | D18: =D7/C7-1 -> 0.22024096 | E18: =E7/D7-1 -> -0.056477093 | F18: 0.04 | G18: 0.04 | H18: 0.04 | I18: 0.04 | J18: 0.04 | K18: 0.04 | L18: 0.04
B19: Other | D19: =D8/C8-1 -> 0.24624625 | E19: =E8/D8-1 -> 0.06746988 | F19: 0.06 | G19: 0.06 | H19: 0.06 | I19: 0.06 | J19: 0.06 | K19: 0.06 | L19: 0.06
B20: Construction Materials Revenue Growth | D20: =D10/C10-1 -> 0.13066073 | E20: =E10/D10-1 -> 0.011687459 | F20: =F10/E10-1 -> 0.12993904 | G20: =G10/F10-1 -> 0.047838951 | H20: =H10/G10-1 -> 0.058271502 | I20: =I10/H10-1 -> 0.058581099 | J20: =J10/I10-1 -> 0.058894326 | K20: =K10/J10-1 -> 0.059211076 | L20: =L10/K10-1 -> 0.059531233
B21: Contracting Services | D21: =D11/C11-1 -> 0.10069883 | E21: =E11/D11-1 -> 0.03893521 | F21: 0.09 | G21: 0.04 | H21: 0.04 | I21: 0.04 | J21: 0.04 | K21: 0.04 | L21: 0.04
B22: Total Revenue Growth | D22: =D12/C12-1 -> 0.1166213 | E22: =E12/D12-1 -> 0.024273045 | F22: =F12/E12-1 -> 0.11122735 | G22: =G12/F12-1 -> 0.044236509 | H22: =H12/G12-1 -> 0.049908777 | I22: =I12/H12-1 -> 0.050156937 | J22: =J12/I12-1 -> 0.050411006 | K22: =K12/J12-1 -> 0.05067103 | L22: =L12/K12-1 -> 0.050937046
B24: Cost Of Revenues - Construction Materials | C24: 1086.2 | D24: 1133 | E24: 1147.5 | F24: =F10-F106 -> 1275.8434 | G24: =G10-G106 -> 1319.3391 | H24: =H10-H106 -> 1378.1685 | I24: =I10-I106 -> 1440.1323 | J24: =J10-J106 -> 1505.4238 | K24: =K10-K106 -> 1574.2497 | L24: =L10-L106 -> 1646.8311
B25: Cost Of Revenues - Contracting Services | C25: 1087.6 | D25: 1158.4 | E25: 1181.7 | F25: =F11-F107 -> 1287.9811 | G25: =G11-G107 -> 1336.421 | H25: =H11-H107 -> 1386.6753 | I25: =I11-I107 -> 1438.8118 | J25: =J11-J107 -> 1492.9004 | K25: =K11-K107 -> 1549.0141 | L25: =L11-L107 -> 1607.2282
B26: Total Cost of Revenue | C26: =SUM(C24:C25) -> 2173.8 | D26: =SUM(D24:D25) -> 2291.4 | E26: =SUM(E24:E25) -> 2329.2 | F26: =F12-F28 -> 2563.8244 | G26: =G12-G28 -> 2655.7601 | H26: =H12-H28 -> 2764.8438 | I26: =I12-I28 -> 2878.944 | J26: =J12-J28 -> 2998.3242 | K26: =K12-K28 -> 3123.2638 | L26: =L12-L28 -> 3254.0593
B28: Gross Profit | C28: =C12-C26 -> 360.9 | D28: =D12-D26 -> 538.9 | E28: =E12-E26 -> 569.8 | F28: =F108 -> 657.62364 | G28: =G108 -> 708.19357 | H28: =H108 -> 767.00067 | I28: =I108 -> 830.04697 | J28: =J108 -> 897.64075 | K28: =K108 -> 970.11371 | L28: =L108 -> 1047.8228
B29: Y/Y % change | D29: =D28/C28-1 -> 0.49321142 | E29: =E28/D28-1 -> 0.057339024 | F29: =F28/E28-1 -> 0.15413064 | G29: =G28/F28-1 -> 0.076897976 | H29: =H28/G28-1 -> 0.083038184 | I29: =I28/H28-1 -> 0.08219849 | J29: =J28/I28-1 -> 0.081433682 | K29: =K28/J28-1 -> 0.080737156 | L29: =L28/K28-1 -> 0.080103076
B31: Gross Margin (%) | C31: =C28/C12 -> 0.14238371 | D31: =D28/D12 -> 0.19040384 | E31: =E28/E12 -> 0.19655053 | F31: =F28/F12 -> 0.20413914 | G31: =G28/G12 -> 0.21052417 | H31: =H28/H12 -> 0.21716717 | I31: =I28/I12 -> 0.2237932 | J31: =J28/J12 -> 0.23040268 | ... L31: =L28/L12 -> 0.24357311
B32: Y/Y % change | D32: =(ROUND(D31,3)-ROUND(C31,3))*10000 -> 480 | E32: =(ROUND(E31,3)-ROUND(D31,3))*10000 -> 70 | F32: =(ROUND(F31,3)-ROUND(E31,3))*10000 -> 70 | G32: =(ROUND(G31,3)-ROUND(F31,3))*10000 -> 70 | H32: =(ROUND(H31,3)-ROUND(G31,3))*10000 -> 60 | I32: =(ROUND(I31,3)-ROUND(H31,3))*10000 -> 70 | J32: =(ROUND(J31,3)-ROUND(I31,3))*10000 -> 60 | K32: =(ROUND(K31,3)-ROUND(J31,3))*10000 -> 70 | L32: =(ROUND(L31,3)-ROUND(K31,3))*10000 -> 70
B34: Selling, General & Administrative Expenses | C34: 166.6 | D34: 242.5 | E34: 253.6 | F34: =F12*F35 -> 289.93033 | G34: =G12*G35 -> 302.75583 | H34: =H12*H35 -> 317.86601 | I34: =I12*I35 -> 333.80919 | J34: =J12*J35 -> 350.63685 | K34: =K12*K35 -> 368.40398 | L34: =L12*L35 -> 387.16939
B35: SG&A (% of Sales) | C35: =C34/C12 -> 0.0657277 | D35: =D34/D12 -> 0.085679963 | E35: =E34/E12 -> 0.087478441 | F35: 0.09 | G35: 0.09 | H35: 0.09 | I35: 0.09 | J35: 0.09 | K35: 0.09 | L35: 0.09
B37: Operating Income | C37: =C28-C34 -> 194.3 | D37: =D28-D34 -> 296.4 | E37: =E28-E34 -> 316.2 | F37: =F28-F34 -> 367.69331 | G37: =G28-G34 -> 405.43773 | H37: =H28-H34 -> 449.13467 | I37: =I28-I34 -> 496.23778 | J37: =J28-J34 -> 547.00391 | ... L37: =L28-L34 -> 660.65342
B38: Y/Y % change | D38: =D37/C37-1 -> 0.52547607 | E38: =E37/D37-1 -> 0.066801619 | F38: =F37/E37-1 -> 0.16285045 | G38: =G37/F37-1 -> 0.10265191 | H38: =H37/G37-1 -> 0.10777718 | I38: =I37/H37-1 -> 0.10487525 | J38: =J37/I37-1 -> 0.10230201 | K38: =K37/J37-1 -> 0.10000995 | L38: =L37/K37-1 -> 0.097960327
B40: Operating Margin | C40: =C37/C12 -> 0.076656015 | D40: =D37/D12 -> 0.10472388 | E40: =E37/E12 -> 0.10907209 | F40: =F37/F12 -> 0.11413914 | G40: =G37/G12 -> 0.12052417 | H40: =H37/H12 -> 0.12716717 | I40: =I37/I12 -> 0.1337932 | J40: =J37/J12 -> 0.14040268 | ... L40: =L37/L12 -> 0.15357311
B41: Y/Y % change | D41: =(ROUND(D40,3)-ROUND(C40,3))*10000 -> 280 | E41: =(ROUND(E40,3)-ROUND(D40,3))*10000 -> 40 | F41: =(ROUND(F40,3)-ROUND(E40,3))*10000 -> 50 | G41: =(ROUND(G40,3)-ROUND(F40,3))*10000 -> 70 | H41: =(ROUND(H40,3)-ROUND(G40,3))*10000 -> 60 | I41: =(ROUND(I40,3)-ROUND(H40,3))*10000 -> 70 | J41: =(ROUND(J40,3)-ROUND(I40,3))*10000 -> 60 | K41: =(ROUND(K40,3)-ROUND(J40,3))*10000 -> 70 | L41: =(ROUND(L40,3)-ROUND(K40,3))*10000 -> 70
B43: Net Interest Expense | C43: 30.1 | D43: 58.1 | E43: 55.2 | F43: =IF('IS - Gold Solution'!CIRC=1,'Debt - Gold Solution'!F17-'Debt - Gold Solution'!F18,0) -> 72.2795 | G43: =IF('IS - Gold Solution'!CIRC=1,'Debt - Gold Solution'!G17-'Debt - Gold Solution'!G18,0) -> 72.66283 | H43: =IF('IS - Gold Solution'!CIRC=1,'Debt - Gold Solution'!H17-'Debt - Gold Solution'!H18,0) -> 72.240226 | I43: =IF('IS - Gold Solution'!CIRC=1,'Debt - Gold Solution'!I17-'Debt - Gold Solution'!I18,0) -> 70.644141 | J43: =IF('IS - Gold Solution'!CIRC=1,'Debt - Gold Solution'!J17-'Debt - Gold Solution'!J18,0) -> 67.780839 | K43: =IF('IS - Gold Solution'!CIRC=1,'Debt - Gold Solution'!K17-'Debt - Gold Solution'!K18,0) -> 51.366673 | L43: =IF('IS - Gold Solution'!CIRC=1,'Debt - Gold Solution'!L17-'Debt - Gold Solution'!L18,0) -> 22.522462
B44: Other Income | C44: -5.4 | D44: 7 | E44: 10 | F44: 0 | G44: 0 | H44: 0 | I44: 0 | J44: 0 | K44: 0 | L44: 0
B45: Pre-Tax Income | C45: =C37-C43+C44 -> 158.8 | D45: =D37-D43+D44 -> 245.3 | E45: =E37-E43+E44 -> 271 | F45: =F37-F43+F44 -> 295.41381 | G45: =G37-G43+G44 -> 332.77491 | H45: =H37-H43+H44 -> 376.89444 | I45: =I37-I43+I44 -> 425.59364 | J45: =J37-J43+J44 -> 479.22307 | ... L45: =L37-L43+L44 -> 638.13096
B47: Income Tax Expense | C47: 42.6 | D47: 62.4 | E47: 69.3 | F47: =+F45*F48 -> 73.853453 | G47: =+G45*G48 -> 83.193726 | H47: =+H45*H48 -> 94.223611 | I47: =+I45*I48 -> 106.39841 | J47: =+J45*J48 -> 119.80577 | K47: =+K45*K48 -> 137.58577 | L47: =+L45*L48 -> 159.53274
B48: Effective Tax Rate | C48: =+C47/C45 -> 0.26826196 | D48: =+D47/D45 -> 0.25438239 | E48: =+E47/E45 -> 0.25571956 | F48: 0.25 | G48: 0.25 | H48: 0.25 | I48: 0.25 | J48: 0.25 | K48: 0.25 | L48: 0.25
B50: Net Income (Loss) | C50: =C45-C47 -> 116.2 | D50: =D45-D47 -> 182.9 | E50: =E45-E47 -> 201.7 | F50: =F45-F47 -> 221.56036 | G50: =G45-G47 -> 249.58118 | H50: =H45-H47 -> 282.67083 | I50: =I45-I47 -> 319.19523 | J50: =J45-J47 -> 359.4173 | ... L50: =L45-L47 -> 478.59822
...

Sheet BS - Gold Solution
B1: Knife River (KNF) Balance Sheet
B2: ($ million) | C2: 2022 | D2: ='IS - Gold Solution'!D2 -> 2023 | E2: ='IS - Gold Solution'!E2 -> 2024 | F2: ='IS - Gold Solution'!F2 -> 2025E | G2: ='IS - Gold Solution'!G2 -> 2026E | H2: ='IS - Gold Solution'!H2 -> 2027E | I2: ='IS - Gold Solution'!I2 -> 2028E | J2: ='IS - Gold Solution'!J2 -> 2029E | K2: ='IS - Gold Solution'!K2 -> 2030E | L2: ='IS - Gold Solution'!L2 -> 2031E
B3: Assets
B4: Cash & cash equivalents | C4: 10.1 | D4: 262.32 | E4: 281.134 | F4: ='CFS - Gold Solution'!F38 -> 260.30761 | G4: ='CFS - Gold Solution'!G38 -> 255.57868 | H4: ='CFS - Gold Solution'!H38 -> 288.48119 | I4: ='CFS - Gold Solution'!I38 -> 361.98435 | J4: ='CFS - Gold Solution'!J38 -> 479.36801 | K4: ='CFS - Gold Solution'!K38 -> 388.68712 | L4: ='CFS - Gold Solution'!L38 -> 206.48205
B5: Accounts receivable (net) | C5: 210.2 | D5: 266.785 | E5: 267.24 | F5: =E5-'CFS - Gold Solution'!F14 -> 287.24 | G5: =F5-'CFS - Gold Solution'!G14 -> 307.24 | H5: =G5-'CFS - Gold Solution'!H14 -> 327.24 | I5: =H5-'CFS - Gold Solution'!I14 -> 347.24 | J5: =I5-'CFS - Gold Solution'!J14 -> 367.24 | K5: =J5-'CFS - Gold Solution'!K14 -> 387.24 | L5: =K5-'CFS - Gold Solution'!L14 -> 407.24
B6: Costs and earnings in excess of billings | C6: 31.1 | D6: 27.293 | E6: 31.283 | F6: =E6 -> 31.283 | G6: =F6 -> 31.283 | H6: =G6 -> 31.283 | I6: =H6 -> 31.283 | J6: =I6 -> 31.283 | K6: =J6 -> 31.283 | L6: =K6 -> 31.283
B7: Inventories (net) | C7: 323.3 | D7: 319.623 | E7: 380.336 | F7: =E7-'CFS - Gold Solution'!F15 -> 390.336 | G7: =F7-'CFS - Gold Solution'!G15 -> 400.336 | H7: =G7-'CFS - Gold Solution'!H15 -> 410.336 | I7: =H7-'CFS - Gold Solution'!I15 -> 420.336 | J7: =I7-'CFS - Gold Solution'!J15 -> 430.336 | K7: =J7-'CFS - Gold Solution'!K15 -> 440.336 | L7: =K7-'CFS - Gold Solution'!L15 -> 450.336
B8: Other current assets | C8: 33.9 | D8: 37.522 | E8: 27.675 | F8: =E8 -> 27.675 | G8: =F8 -> 27.675 | H8: =G8 -> 27.675 | I8: =H8 -> 27.675 | J8: =I8 -> 27.675 | K8: =J8 -> 27.675 | L8: =K8 -> 27.675
B9: Total Current Assets | C9: =SUM(C4:C8) -> 608.6 | D9: =SUM(D4:D8) -> 913.543 | E9: =SUM(E4:E8) -> 987.668 | F9: =SUM(F4:F8) -> 996.84161 | G9: =SUM(G4:G8) -> 1022.1127 | H9: =SUM(H4:H8) -> 1085.0152 | I9: =SUM(I4:I8) -> 1188.5183 | J9: =SUM(J4:J8) -> 1335.902 | ... L9: =SUM(L4:L8) -> 1123.016
B11: Property, plant and equipment (net) | C11: 1315.2 | D11: 1315.047 | E11: 1441.7 | F11: =F46 -> 1518.9258 | G11: =G46 -> 1563.2359 | H11: =H46 -> 1603.0042 | I11: =I46 -> 1638.6963 | J11: =J46 -> 1670.7299 | K11: =K46 -> 1699.4801 | L11: =L46 -> 1725.2834
B12: Goodwill | C12: 274.5 | D12: 274.478 | E12: 297.225 | F12: =E12-'CFS - Gold Solution'!F22 -> 747.225 | G12: =F12-'CFS - Gold Solution'!G22 -> 747.225 | H12: =G12-'CFS - Gold Solution'!H22 -> 747.225 | I12: =H12-'CFS - Gold Solution'!I22 -> 747.225 | J12: =I12-'CFS - Gold Solution'!J22 -> 747.225 | K12: =J12-'CFS - Gold Solution'!K22 -> 747.225 | L12: =K12-'CFS - Gold Solution'!L22 -> 747.225
B13: Intangible assets (net) | C13: 13.4 | D13: 10.821 | E13: 29.414 | F13: =E13 -> 29.414 | G13: =F13 -> 29.414 | H13: =G13 -> 29.414 | I13: =H13 -> 29.414 | J13: =I13 -> 29.414 | K13: =J13 -> 29.414 | L13: =K13 -> 29.414
B14: Operating lease right-of-use assets (net) | C14: 45.9 | D14: 44.706 | E14: 49.378 | F14: =E14 -> 49.378 | G14: =F14 -> 49.378 | H14: =G14 -> 49.378 | I14: =H14 -> 49.378 | J14: =I14 -> 49.378 | K14: =J14 -> 49.378 | L14: =K14 -> 49.378
B15: Other noncurrent assets | C15: 36.7 | D15: 41.218 | E15: 45.817 | F15: =E15 -> 45.817 | G15: =F15 -> 45.817 | H15: =G15 -> 45.817 | I15: =H15 -> 45.817 | J15: =I15 -> 45.817 | K15: =J15 -> 45.817 | L15: =K15 -> 45.817
B16: Total Assets | C16: =SUM(C9:C15) -> 2294.3 | D16: =SUM(D9:D15) -> 2599.813 | E16: =SUM(E9:E15) -> 2851.202 | F16: =SUM(F9:F15) -> 3387.6014 | G16: =SUM(G9:G15) -> 3457.1825 | H16: =SUM(H9:H15) -> 3559.8534 | I16: =SUM(I9:I15) -> 3699.0486 | J16: =SUM(J9:J15) -> 3878.4659 | ... L16: =SUM(L9:L15) -> 3720.1334
B18: Liabilities and Equity
B19: Long-term debt - current portion | C19: 87.4 | D19: 7.082 | E19: 10.475 | F19: =-'Debt - Gold Solution'!F10 -> 0 | G19: =-'Debt - Gold Solution'!G10 -> 0 | H19: =-'Debt - Gold Solution'!H10 -> 0 | I19: =-'Debt - Gold Solution'!I10 -> 0 | J19: =-'Debt - Gold Solution'!J10 -> 0 | K19: =-'Debt - Gold Solution'!K10 -> 0 | L19: =-'Debt - Gold Solution'!L10 -> 0
B20: Accounts payable | C20: 39.8 | D20: 107.656 | E20: 140.834 | F20: =E20+'CFS - Gold Solution'!F16 -> 145.834 | G20: =F20+'CFS - Gold Solution'!G16 -> 150.834 | H20: =G20+'CFS - Gold Solution'!H16 -> 155.834 | I20: =H20+'CFS - Gold Solution'!I16 -> 160.834 | J20: =I20+'CFS - Gold Solution'!J16 -> 165.834 | K20: =J20+'CFS - Gold Solution'!K16 -> 170.834 | L20: =K20+'CFS - Gold Solution'!L16 -> 175.834
B21: Billings in excess of costs and estimated earnings on uncompleted contracts | C21: 0 | D21: 51.376 | E21: 42.126 | F21: =E21 -> 42.126 | G21: =F21 -> 42.126 | H21: =G21 -> 42.126 | I21: =H21 -> 42.126 | J21: =I21 -> 42.126 | K21: =J21 -> 42.126 | L21: =K21 -> 42.126
B22: Accrued compensation | C22: 29.2 | D22: 48.098 | E22: 50.655 | F22: =E22 -> 50.655 | G22: =F22 -> 50.655 | H22: =G22 -> 50.655 | I22: =H22 -> 50.655 | J22: =I22 -> 50.655 | K22: =J22 -> 50.655 | L22: =K22 -> 50.655
B23: Current operating lease liabilities | C23: 20.3 | D23: 12.948 | E23: 14.844 | F23: =E23 -> 14.844 | G23: =F23 -> 14.844 | H23: =G23 -> 14.844 | I23: =H23 -> 14.844 | J23: =I23 -> 14.844 | K23: =J23 -> 14.844 | L23: =K23 -> 14.844
B24: Other taxes payable | C24: 238.2 | D24: 9.3 | E24: 8.286 | F24: =E24 -> 8.286 | G24: =F24 -> 8.286 | H24: =G24 -> 8.286 | I24: =H24 -> 8.286 | J24: =I24 -> 8.286 | K24: =J24 -> 8.286 | L24: =K24 -> 8.286
B25: Accrued interest | C25: 13.2 | D25: 7.247 | E25: 5.535 | F25: =E25 -> 5.535 | G25: =F25 -> 5.535 | H25: =G25 -> 5.535 | I25: =H25 -> 5.535 | J25: =I25 -> 5.535 | K25: =J25 -> 5.535 | L25: =K25 -> 5.535
B26: Other accrued liabilities | C26: 88.8 | D26: 103.564 | E26: 97.282 | F26: =E26+'CFS - Gold Solution'!F17 -> 102.282 | G26: =F26+'CFS - Gold Solution'!G17 -> 107.282 | H26: =G26+'CFS - Gold Solution'!H17 -> 112.282 | I26: =H26+'CFS - Gold Solution'!I17 -> 117.282 | J26: =I26+'CFS - Gold Solution'!J17 -> 122.282 | K26: =J26+'CFS - Gold Solution'!K17 -> 127.282 | L26: =K26+'CFS - Gold Solution'!L17 -> 132.282
B27: Total Current Liabilities | C27: =SUM(C19:C26) -> 516.9 | D27: =SUM(D19:D26) -> 347.271 | E27: =SUM(E19:E26) -> 370.037 | F27: =SUM(F19:F26) -> 369.562 | G27: =SUM(G19:G26) -> 379.562 | H27: =SUM(H19:H26) -> 389.562 | I27: =SUM(I19:I26) -> 399.562 | J27: =SUM(J19:J26) -> 409.562 | ... L27: =SUM(L19:L26) -> 429.562
B29: Long-term debt | C29: 0.4 | D29: 674.577 | E29: 666.911 | F29: ='Debt - Gold Solution'!F11 -> 1172.165 | G29: ='Debt - Gold Solution'!G11 -> 1172.165 | H29: ='Debt - Gold Solution'!H11 -> 1172.165 | I29: ='Debt - Gold Solution'!I11 -> 1172.165 | J29: ='Debt - Gold Solution'!J11 -> 1172.165 | K29: ='Debt - Gold Solution'!K11 -> 907.477 | L29: ='Debt - Gold Solution'!L11 -> 482.477
B30: Related-party notes payable | C30: 446.4 | D30: 0 | E30: 0 | F30: =E30 -> 0 | G30: =F30 -> 0 | H30: =G30 -> 0 | I30: =H30 -> 0 | J30: =I30 -> 0 | K30: =J30 -> 0 | L30: =K30 -> 0
B31: Deferred income taxes, net | C31: 175.8 | D31: 174.542 | E31: 174.727 | F31: =E31 -> 174.727 | G31: =F31 -> 174.727 | H31: =G31 -> 174.727 | I31: =H31 -> 174.727 | J31: =I31 -> 174.727 | K31: =J31 -> 174.727 | L31: =K31 -> 174.727
B32: Noncurrent operating lease liabilities | C32: 32.7 | D32: 31.758 | E32: 34.534 | F32: =E32 -> 34.534 | G32: =F32 -> 34.534 | H32: =G32 -> 34.534 | I32: =H32 -> 34.534 | J32: =I32 -> 34.534 | K32: =J32 -> 34.534 | L32: =K32 -> 34.534
B33: Other noncurrent liabilities | C33: 93.5 | D33: 105.653 | E33: 128.908 | F33: =E33 -> 128.908 | G33: =F33 -> 128.908 | H33: =G33 -> 128.908 | I33: =H33 -> 128.908 | J33: =I33 -> 128.908 | K33: =J33 -> 128.908 | L33: =K33 -> 128.908
B34: Total Liabilities | C34: =SUM(C29:C33,C27) -> 1265.7 | D34: =SUM(D29:D33,D27) -> 1333.801 | E34: =SUM(E29:E33,E27) -> 1375.117 | F34: =SUM(F29:F33,F27) -> 1879.896 | G34: =SUM(G29:G33,G27) -> 1889.896 | H34: =SUM(H29:H33,H27) -> 1899.896 | I34: =SUM(I29:I33,I27) -> 1909.896 | J34: =SUM(J29:J33,J27) -> 1919.896 | ... L34: =SUM(L29:L33,L27) -> 1250.208
B36: Total Equity | C36: 1028.6 | D36: 1266.012 | E36: 1476.085 | F36: =E36+'IS - Gold Solution'!F50+'CFS - Gold Solution'!F9+'CFS - Gold Solution'!F32 -> 1507.6454 | G36: =F36+'IS - Gold Solution'!G50+'CFS - Gold Solution'!G9+'CFS - Gold Solution'!G32 -> 1567.2265 | H36: =G36+'IS - Gold Solution'!H50+'CFS - Gold Solution'!H9+'CFS - Gold Solution'!H32 -> 1659.8974 | I36: =H36+'IS - Gold Solution'!I50+'CFS - Gold Solution'!I9+'CFS - Gold Solution'!I32 -> 1789.0926 | J36: =I36+'IS - Gold Solution'!J50+'CFS - Gold Solution'!J9+'CFS - Gold Solution'!J32 -> 1958.5099 | K36: =J36+'IS - Gold Solution'!K50+'CFS - Gold Solution'!K9+'CFS - Gold Solution'!K32 -> 2181.2672 | L36: =K36+'IS - Gold Solution'!L50+'CFS - Gold Solution'!L9+'CFS - Gold Solution'!L32 -> 2469.8654
B38: Total Liabilities and Equity | C38: =SUM(C36,C34) -> 2294.3 | D38: =SUM(D36,D34) -> 2599.813 | E38: =SUM(E36,E34) -> 2851.202 | F38: =SUM(F36,F34) -> 3387.5414 | G38: =SUM(G36,G34) -> 3457.1225 | H38: =SUM(H36,H34) -> 3559.7934 | I38: =SUM(I36,I34) -> 3698.9886 | J38: =SUM(J36,J34) -> 3878.4059 | ... L38: =SUM(L36,L34) -> 3720.0734
B39: Check | C39: =IF(ABS(C16-C38)<0.1,0,C16-C38) -> 0 | D39: =IF(ABS(D16-D38)<0.1,0,D16-D38) -> 0 | E39: =IF(ABS(E16-E38)<0.1,0,E16-E38) -> 0 | F39: =IF(ABS(F16-F38)<0.1,0,F16-F38) -> 0 | G39: =IF(ABS(G16-G38)<0.1,0,G16-G38) -> 0 | H39: =IF(ABS(H16-H38)<0.1,0,H16-H38) -> 0 | I39: =IF(ABS(I16-I38)<0.1,0,I16-I38) -> 0 | J39: =IF(ABS(J16-J38)<0.1,0,J16-J38) -> 0 | ... L39: =IF(ABS(L16-L38)<0.1,0,L16-L38) -> 0
B43: Beginning PP&E | F43: =E46 -> 1441.7 | G43: =F46 -> 1518.9258 | H43: =G46 -> 1563.2359 | I43: =H46 -> 1603.0042 | J43: =I46 -> 1638.6963 | K43: =J46 -> 1670.7299 | L43: =K46 -> 1699.4801
B44: (+) CAPEX | F44: =-'CFS - Gold Solution'!F21 -> 225 | G44: =-'CFS - Gold Solution'!G21 -> 200 | H44: =-'CFS - Gold Solution'!H21 -> 200 | I44: =-'CFS - Gold Solution'!I21 -> 200 | J44: =-'CFS - Gold Solution'!J21 -> 200 | K44: =-'CFS - Gold Solution'!K21 -> 200 | L44: =-'CFS - Gold Solution'!L21 -> 200
B45: (-) D&A | F45: =-F47*F43 -> -147.77425 | G45: =-G47*G43 -> -155.68989 | H45: =-H47*H43 -> -160.23168 | I45: =-I47*I43 -> -164.30793 | J45: =-J47*J43 -> -167.96637 | K45: =-K47*K43 -> -171.24981 | L45: =-L47*L43 -> -174.19671
B46: Ending PP&E | C46: =C11 -> 1315.2 | D46: =D11 -> 1315.047 | E46: =E11 -> 1441.7 | F46: =SUM(F43:F45) -> 1518.9258 | G46: =SUM(G43:G45) -> 1563.2359 | H46: =SUM(H43:H45) -> 1603.0042 | I46: =SUM(I43:I45) -> 1638.6963 | J46: =SUM(J43:J45) -> 1670.7299 | K46: =SUM(K43:K45) -> 1699.4801 | L46: =SUM(L43:L45) -> 1725.2834
B47: D&A % of Beg. PP&E | D47: ='IS - Gold Solution'!D61/C46 -> 0.09413017 | E47: ='IS - Gold Solution'!E61/D46 -> 0.10410274 | F47: 0.1025 | G47: 0.1025 | H47: 0.1025 | I47: 0.1025 | J47: 0.1025 | K47: 0.1025 | L47: 0.1025
B49: Book Value / Common Share | C49: =C36/'IS - Gold Solution'!C55 -> 18.173145 | D49: =D36/'IS - Gold Solution'!D55 -> 22.328254 | E49: =E36/'IS - Gold Solution'!E55 -> 25.987412 | F49: =F36/'IS - Gold Solution'!F55 -> 27.701339 | G49: =G36/'IS - Gold Solution'!G55 -> 30.11002 | H49: =H36/'IS - Gold Solution'!H55 -> 33.415146 | I49: =I36/'IS - Gold Solution'!I55 -> 37.824368 | J49: =J36/'IS - Gold Solution'!J55 -> 43.595101 | ... L49: =L36/'IS - Gold Solution'!L55 -> 61.477671
...

Sheet CFS - Gold Solution
B1: Knife River (KNF) Cash Flow Statement
B2: ($ million) | C2: =+'IS - Gold Solution'!C2 -> 2022 | D2: =+'IS - Gold Solution'!D2 -> 2023 | E2: =+'IS - Gold Solution'!E2 -> 2024 | F2: =+'IS - Gold Solution'!F2 -> 2025E | G2: =+'IS - Gold Solution'!G2 -> 2026E | H2: =+'IS - Gold Solution'!H2 -> 2027E | I2: =+'IS - Gold Solution'!I2 -> 2028E | J2: =+'IS - Gold Solution'!J2 -> 2029E | ... L2: =+'IS - Gold Solution'!L2 -> 2031E
B3: Consolidated net earnings | C3: ='IS - Gold Solution'!C50 -> 116.2 | D3: ='IS - Gold Solution'!D50 -> 182.9 | E3: ='IS - Gold Solution'!E50 -> 201.7 | F3: ='IS - Gold Solution'!F50 -> 221.56036 | G3: ='IS - Gold Solution'!G50 -> 249.58118 | H3: ='IS - Gold Solution'!H50 -> 282.67083 | I3: ='IS - Gold Solution'!I50 -> 319.19523 | J3: ='IS - Gold Solution'!J50 -> 359.4173 | ... L3: ='IS - Gold Solution'!L50 -> 478.59822
B4: Adjustments to Reconcile Net Loss to Net Cash | C4: =SUM(C5:C12) -> 112.346 | D4: =SUM(D5:D12) -> 128.87 | E4: =SUM(E5:E12) -> 137.424 | F4: =SUM(F5:F12) -> 157.77425 | G4: =SUM(G5:G12) -> 165.68989 | H4: =SUM(H5:H12) -> 170.23168 | I4: =SUM(I5:I12) -> 174.30793 | J4: =SUM(J5:J12) -> 177.96637 | ... L4: =SUM(L5:L12) -> 184.19671
B5: DD&A | C5: 117.798 | D5: 123.805 | E5: 136.871 | F5: ='IS - Gold Solution'!F61 -> 147.77425 | G5: ='IS - Gold Solution'!G61 -> 155.68989 | H5: ='IS - Gold Solution'!H61 -> 160.23168 | I5: ='IS - Gold Solution'!I61 -> 164.30793 | J5: ='IS - Gold Solution'!J61 -> 167.96637 | K5: ='IS - Gold Solution'!K61 -> 171.24981 | L5: ='IS - Gold Solution'!L61 -> 174.19671
B6: Deferred income taxes | C6: 2.078 | D6: -1.606 | E6: -0.35 | F6: 0 | G6: 0 | H6: 0 | I6: 0 | J6: 0 | K6: 0 | L6: 0
B7: Provision for credit losses | C7: 0.538 | D7: 2.001 | E7: 1.099 | F7: 0 | G7: 0 | H7: 0 | I7: 0 | J7: 0 | K7: 0 | L7: 0
B8: Amortization of debt issuance costs | C8: 0.483 | D8: 3.115 | E8: 2.762 | F8: 0 | G8: 0 | H8: 0 | I8: 0 | J8: 0 | K8: 0 | L8: 0
B9: Stock-based compensation | C9: 1.272 | D9: 2.888 | E9: 7.826 | F9: 10 | G9: 10 | H9: 10 | I9: 10 | J9: 10 | K9: 10 | L9: 10
B10: Pension and postretirement benefits | C10: 1.306 | D10: 1.182 | E10: 1.628 | F10: 0 | G10: 0 | H10: 0 | I10: 0 | J10: 0 | K10: 0 | L10: 0
B11: Unrealized (gains) losses on investments | C11: 2.525 | D11: -2.202 | E11: -2.918 | F11: 0 | G11: 0 | H11: 0 | I11: 0 | J11: 0 | K11: 0 | L11: 0
B12: Gains on sales | C12: =-14.092+0.438 -> -13.654 | D12: =-0.027-0.286 -> -0.313 | E12: =-9.215-0.279 -> -9.494 | F12: 0 | G12: 0 | H12: 0 | I12: 0 | J12: 0 | K12: 0 | L12: 0
B13: Working capital changes (net of M&A) | C13: =+SUM(C14:C17) -> -29.015 | D13: =+SUM(D14:D17) -> 20.09 | E13: =+SUM(E14:E17) -> -16.03 | F13: =+SUM(F14:F17) -> -20 | G13: =+SUM(G14:G17) -> -20 | H13: =+SUM(H14:H17) -> -20 | I13: =+SUM(I14:I17) -> -20 | J13: =+SUM(J14:J17) -> -20 | ... L13: =+SUM(L14:L17) -> -20
B14: Accounts receivable (net) | C14: =-32.506-8.004 -> -40.51 | D14: =-54.817+16.05 -> -38.767 | E14: 14.061 | F14: -20 | G14: -20 | H14: -20 | I14: -20 | J14: -20 | K14: -20 | L14: -20
B15: Inventories (net) | C15: -31.033 | D15: 3.654 | E15: -44.303 | F15: -10 | G15: -10 | H15: -10 | I15: -10 | J15: -10 | K15: -10 | L15: -10
B16: Accounts payable (net) | C16: =17.489+3.578 -> 21.067 | D16: =33.092-7.31 -> 25.782 | E16: 7.308 | F16: 5 | G16: 5 | H16: 5 | I16: 5 | J16: 5 | K16: 5 | L16: 5
B17: Other assets and liabilities (net) | C17: =21.417+0.044 -> 21.461 | D17: =-19.556+48.977 -> 29.421 | E17: =10.907-4.003 -> 6.904 | F17: 5 | G17: 5 | H17: 5 | I17: 5 | J17: 5 | K17: 5 | L17: 5
B18: Other items (net) | C18: =-0.426+8.319 -> 7.893 | D18: =-1.756+5.65 -> 3.894 | E18: =-2.651+1.903 -> -0.748 | F18: 0 | G18: 0 | H18: 0 | I18: 0 | J18: 0 | K18: 0 | L18: 0
B19: Cash from Operations | C19: =C3+C4+C13+C18 -> 207.424 | D19: =D3+D4+D13+D18 -> 335.754 | E19: =E3+E4+E13+E18 -> 322.346 | F19: =F3+F4+F13+F18 -> 359.33461 | G19: =G3+G4+G13+G18 -> 395.27107 | H19: =H3+H4+H13+H18 -> 432.90251 | I19: =I3+I4+I13+I18 -> 473.50316 | J19: =J3+J4+J13+J18 -> 517.38367 | ... L19: =L3+L4+L13+L18 -> 642.79493
B21: Additions to PP&E (CAPEX) | C21: -178.162 | D21: -124.283 | E21: -172.427 | F21: -225 | G21: -200 | H21: -200 | I21: -200 | J21: -200 | K21: -200 | L21: -200
B22: Acquisitions, net of cash acquired | C22: 1.745 | D22: 0 | E22: -130.981 | F22: -450 | G22: 0 | H22: 0 | I22: 0 | J22: 0 | K22: 0 | L22: 0
B23: Proceeds from divestitures and sales of assets | C23: 22.878 | D23: 8.284 | E23: 11.996 | F23: 0 | G23: 0 | H23: 0 | I23: 0 | J23: 0 | K23: 0 | L23: 0
B24: Other investing activities (net) | C24: -2.339 | D24: -1.89 | E24: -3.389 | F24: 0 | G24: 0 | H24: 0 | I24: 0 | J24: 0 | K24: 0 | L24: 0
B25: Cash from Investing | C25: =SUM(C21:C24) -> -155.878 | D25: =SUM(D21:D24) -> -117.889 | E25: =SUM(E21:E24) -> -294.801 | F25: =SUM(F21:F24) -> -675 | G25: =SUM(G21:G24) -> -200 | H25: =SUM(H21:H24) -> -200 | I25: =SUM(I21:I24) -> -200 | J25: =SUM(J21:J24) -> -200 | ... L25: =SUM(L21:L24) -> -200
B27: Issuance of debt | C27: 208 | D27: =205.275+700 -> 905.275 | E27: 0 | F27: 0 | G27: 0 | H27: 0 | I27: 0 | J27: 0 | K27: 0 | L27: 0
B28: Repayment of debt | C28: =-207.007-0.298 -> -207.305 | D28: -3.653 | E28: -7.036 | F28: ='Debt - Gold Solution'!F12 -> 494.779 | G28: ='Debt - Gold Solution'!G12 -> 0 | H28: ='Debt - Gold Solution'!H12 -> 0 | I28: ='Debt - Gold Solution'!I12 -> 0 | J28: ='Debt - Gold Solution'!J12 -> 0 | K28: ='Debt - Gold Solution'!K12 -> -264.688 | L28: ='Debt - Gold Solution'!L12 -> -425
B29: Debt issuance costs | C29: -0.807 | D29: -16.64 | E29: 0 | F29: 0 | G29: 0 | H29: 0 | I29: 0 | J29: 0 | K29: 0 | L29: 0
B30: Proceeds from issuance of common stock | C30: 0 | D30: 0 | E30: 0 | F30: 0 | G30: 0 | H30: 0 | I30: 0 | J30: 0 | K30: 0 | L30: 0
B31: Dividend | C31: 0 | D31: 0 | E31: 0 | F31: 0 | G31: 0 | H31: 0 | I31: 0 | J31: 0 | K31: 0 | L31: 0
B32: Buybacks | C32: 0 | D32: 0 | E32: 0 | F32: -200 | G32: -200 | H32: -200 | I32: -200 | J32: -200 | K32: -200 | L32: -200
B33: Other | C33: -55.212 | D33: -850.589 | E33: -1.673 | F33: 0 | G33: 0 | H33: 0 | I33: 0 | J33: 0 | K33: 0 | L33: 0
B34: Cash from Financing | C34: =SUM(C27:C33) -> -55.324 | D34: =SUM(D27:D33) -> 34.393 | E34: =SUM(E27:E33) -> -8.709 | F34: =SUM(F27:F33) -> 294.779 | G34: =SUM(G27:G33) -> -200 | H34: =SUM(H27:H33) -> -200 | I34: =SUM(I27:I33) -> -200 | J34: =SUM(J27:J33) -> -200 | ... L34: =SUM(L27:L33) -> -625
B36: Cash at the Beginning of the Period | D36: =C38 -> 10.1 | E36: =D38 -> 262.358 | F36: =E38 -> 281.194 | G36: =F38 -> 260.30761 | H36: =G38 -> 255.57868 | I36: =H38 -> 288.48119 | J36: =I38 -> 361.98435 | K36: =J38 -> 479.36801 | L36: =K38 -> 388.68712
B37: Net decrease/increase in cash | D37: =+D19+D25+D34 -> 252.258 | E37: =+E19+E25+E34 -> 18.836 | F37: =+F19+F25+F34 -> -20.88639 | G37: =+G19+G25+G34 -> -4.7289318 | H37: =+H19+H25+H34 -> 32.902508 | I37: =+I19+I25+I34 -> 73.503159 | J37: =+J19+J25+J34 -> 117.38367 | K37: =+K19+K25+K34 -> -90.680888 | L37: =+L19+L25+L34 -> -182.20507
B38: Cash at the End of the Period | C38: ='BS - Gold Solution'!C4 -> 10.1 | D38: =+D37+D36 -> 262.358 | E38: =+E37+E36 -> 281.194 | F38: =+F37+F36 -> 260.30761 | G38: =+G37+G36 -> 255.57868 | H38: =+H37+H36 -> 288.48119 | I38: =+I37+I36 -> 361.98435 | J38: =+J37+J36 -> 479.36801 | K38: =+K37+K36 -> 388.68712 | L38: =+L37+L36 -> 206.48205
B42: Free Cash Flow | C42: =IC19+C21 -> -178.162 | D42: =D19+D21 -> 211.471 | E42: =E19+E21 -> 149.919 | F42: =F19+F21 -> 134.33461 | G42: =G19+G21 -> 195.27107 | H42: =H19+H21 -> 232.90251 | I42: =I19+I21 -> 273.50316 | J42: =J19+J21 -> 317.38367 | K42: =K19+K21 -> 374.00711 | L42: =L19+L21 -> 442.79493
B43: Free Cash Flow / Share | C43: =+C42/'IS - Gold Solution'!C55 -> -3.1477385 | D43: =+D42/'IS - Gold Solution'!D55 -> 3.7296473 | E43: =+E42/'IS - Gold Solution'!E55 -> 2.639419 | F43: =+F42/'IS - Gold Solution'!F55 -> 2.4682519 | G43: =+G42/'IS - Gold Solution'!G55 -> 3.7516055 | H43: =+H42/'IS - Gold Solution'!H55 -> 4.6885256 | I43: =+I42/'IS - Gold Solution'!I55 -> 5.7823078 | J43: =+J42/'IS - Gold Solution'!J55 -> 7.0647449 | ... L43: =+L42/'IS - Gold Solution'!L55 -> 11.021653

Sheet Debt - Gold Solution
B1: Debt Schedule
B2: Year Ending December 31 | C2: Interest
B3: (in millions) | C3: Rate | D3: 2023 | E3: =D3+1 -> 2024 | F3: =E3+1 -> 2025 | G3: =F3+1 -> 2026 | H3: =G3+1 -> 2027 | I3: =H3+1 -> 2028 | J3: =I3+1 -> 2029 | K3: =J3+1 -> 2030 | L3: =K3+1 -> 2031
B4: Term Loan Due Mar 2030 | C4: 0.0605 | D4: 271.562 | E4: 264.688 | F4: 264.688 | G4: =F4 -> 264.688 | H4: =G4 -> 264.688 | I4: =H4 -> 264.688 | J4: =I4 -> 264.688 | K4: 0 | L4: 0
B5: Senior Notes due May 1, 2031 | C5: 0.0775 | D5: 425 | E5: 425 | F5: 425 | G5: =F5 -> 425 | H5: =G5 -> 425 | I5: =H5 -> 425 | J5: =I5 -> 425 | K5: =J5 -> 425 | L5: 0
B6: Term Loan Due Mar 2032 | C6: 0.0629 | D6: 0 | E6: 0 | F6: 500 | G6: =F6 -> 500 | H6: =G6 -> 500 | I6: =H6 -> 500 | J6: =I6 -> 500 | K6: =J6 -> 500 | L6: =K6 -> 500
B7: Other Notes due January 1, 2061 | C7: - | D7: 0.423 | E7: 0.262 | F7: 0.243 | G7: =F7 -> 0.243 | H7: =G7 -> 0.243 | I7: =H7 -> 0.243 | J7: =I7 -> 0.243 | K7: =J7 -> 0.243 | L7: =K7 -> 0.243
B8: Less Unamort. Debt Issuance Costs | C8: - | D8: -15.326 | E8: -12.564 | F8: -17.766 | G8: =F8 -> -17.766 | H8: =G8 -> -17.766 | I8: =H8 -> -17.766 | J8: =I8 -> -17.766 | K8: =J8 -> -17.766 | L8: =K8 -> -17.766
B9: Total Long Term Debt | C9: =SUMPRODUCT(C4:C5,E4:E5)/SUM(E4:E5) -> 0.070975751 | D9: =SUM(D4:D8) -> 681.659 | E9: =SUM(E4:E8) -> 677.386 | F9: =SUM(F4:F8) -> 1172.165 | G9: =SUM(G4:G8) -> 1172.165 | H9: =SUM(H4:H8) -> 1172.165 | I9: =SUM(I4:I8) -> 1172.165 | J9: =SUM(J4:J8) -> 1172.165 | K9: =SUM(K4:K8) -> 907.477 | L9: =SUM(L4:L8) -> 482.477
B10: Less Current Maturities | D10: -7.082 | E10: -10.475 | F10: 0 | G10: =F10 -> 0 | H10: =G10 -> 0 | I10: =H10 -> 0 | J10: =I10 -> 0 | K10: =J10 -> 0 | L10: =K10 -> 0
B11: Long-term debt | D11: =D9+D10 -> 674.577 | E11: =E9+E10 -> 666.911 | F11: =F9+F10 -> 1172.165 | G11: =G9+G10 -> 1172.165 | H11: =H9+H10 -> 1172.165 | I11: =I9+I10 -> 1172.165 | J11: =J9+J10 -> 1172.165 | K11: =K9+K10 -> 907.477 | L11: =L9+L10 -> 482.477
B12: Change in Debt | E12: =E9-D9 -> -4.273 | F12: =F9-E9 -> 494.779 | G12: =G9-F9 -> 0 | H12: =H9-G9 -> 0 | I12: =I9-H9 -> 0 | J12: =J9-I9 -> 0 | K12: =K9-J9 -> -264.688 | L12: =L9-K9 -> -425
B14: Average Cash | C14: 0.03 | D14: =AVERAGE('BS - Gold Solution'!C4,'BS - Gold Solution'!D4) -> 136.21 | E14: =AVERAGE('BS - Gold Solution'!D4,'BS - Gold Solution'!E4) -> 271.727 | F14: =AVERAGE('BS - Gold Solution'!E4,'BS - Gold Solution'!F4) -> 270.72081 | G14: =AVERAGE('BS - Gold Solution'!F4,'BS - Gold Solution'!G4) -> 257.94314 | H14: =AVERAGE('BS - Gold Solution'!G4,'BS - Gold Solution'!H4) -> 272.02993 | I14: =AVERAGE('BS - Gold Solution'!H4,'BS - Gold Solution'!I4) -> 325.23277 | J14: =AVERAGE('BS - Gold Solution'!I4,'BS - Gold Solution'!J4) -> 420.67618 | K14: =AVERAGE('BS - Gold Solution'!J4,'BS - Gold Solution'!K4) -> 434.02757 | L14: =AVERAGE('BS - Gold Solution'!K4,'BS - Gold Solution'!L4) -> 297.58459
B17: Modelled Interest Expense | D17: =SUMPRODUCT(D4:D6,$C$4:$C$6) -> 49.367001 | E17: =SUMPRODUCT(E4:E6,$C$4:$C$6) -> 48.951124 | F17: =SUMPRODUCT(F4:F6,$C$4:$C$6) -> 80.401124 | G17: =SUMPRODUCT(G4:G6,$C$4:$C$6) -> 80.401124 | H17: =SUMPRODUCT(H4:H6,$C$4:$C$6) -> 80.401124 | I17: =SUMPRODUCT(I4:I6,$C$4:$C$6) -> 80.401124 | J17: =SUMPRODUCT(J4:J6,$C$4:$C$6) -> 80.401124 | K17: =SUMPRODUCT(K4:K6,$C$4:$C$6) -> 64.3875 | L17: =SUMPRODUCT(L4:L6,$C$4:$C$6) -> 31.45
B18: Modelled Interest Income | D18: =D14*$C$14 -> 4.0863 | E18: =E14*$C$14 -> 8.15181 | F18: =F14*$C$14 -> 8.1216242 | G18: =G14*$C$14 -> 7.7382943 | H18: =H14*$C$14 -> 8.160898 | I18: =I14*$C$14 -> 9.756983 | J18: =J14*$C$14 -> 12.620285 | K18: =K14*$C$14 -> 13.020827 | L18: =L14*$C$14 -> 8.9275376
