Workbook
Name circ: Model!$T$6
Name IQ_CH: 110000
Name IQ_CQ: 5000
Name IQ_CY: 10000
Name IQ_DAILY: 500000
Name IQ_FH: 100000
Name IQ_FQ: 500
Name IQ_FY: 1000
Name IQ_LTM: 2000
Name IQ_MONTH: 15000
Name IQ_NTM: 6000
Name IQ_WEEK: 50000
Name IQ_YTD: 3000

Sheet Model
A1: unless otherwise stated, in HKDm
A2: Dec year end, assume txn close on 31 Dec 2017
A3: x | B3: Transaction assumptions
C4: Entry assumptions | H4: Sources | L4: Uses | P4: Switches
C5: FY17 EBITDA | F5: =+K44 -> 376.3 | H5: 1L debt | J5: =+F11*G44 -> 1899 | L5: Purchase EV | N5: =+F7 -> 3988.78 | P5: Revenue case | T5: 2 | U5: =+CHOOSE(T5, "Mgmt. case", "Adj. mgmt. case") -> Adj. mgmt. case
C6: EBITDA multiple | F6: 10.6 | H6: 2L debt | J6: =+F17*G44 -> 633 | L6: Refi existing debt | N6: =+H82 -> 1511 | P6: Circularity | T6: 1
C7: Purchase EV | F7: =+F6*F5 -> 3988.78 | H7: Total equity | J7: =+J11-J5-J6-J10 -> 2843.6278 | L7: M&A fees | N7: =+N5*L14 -> 39.8878 | P7: Adjsutments to mgmt. case
H8: Sponsor equity | J8: =+J7-J9 -> 2132.7209 | L8: Financing fees | N8: =+L15*(J6+J5) -> 75.96 | P8: Growth of customers | T8: =+RevBuild!R8 -> 1
H9: Mgmt roll | J9: =+L13*J7 -> 710.90695 | L9: Minimum cash | N9: 150 | P9: Expansion of SoW | T9: =+RevBuild!R9 -> 1
C10: 1L TL assumptions | H10: Cash on BS | J10: =+H63 -> 390 | P10: E-commerce | T10: =+RevBuild!R10 -> 1
C11: Quantum, FY16 EBITDA | F11: 6 | H11: Total | J11: =+N11 -> 5765.6278 | L11: Total | N11: =+SUM(N5:N9) -> 5765.6278 | P11: Cross selling | T11: =+RevBuild!R11 -> 0
C12: Cash interest | F12: 0.07 | P12: Growth from other customers | T12: =+RevBuild!R12 -> 0
C13: Maturity (years) | F13: 5 | H13: Mgmt roll | L13: 0.25
C14: Sweep | F14: 1 | H14: M&A fees % of EV | L14: 0.01
H15: Financing fees % of debt load | L15: 0.03
C16: 2L assumptions
C17: Quantum, FY16 EBITDA | F17: 2 | H17: HKD/USD | L17: 0.13
C18: Cash interest | F18: 0.09
C19: Maturity (years) | F19: 7 | H19: PG equity ticket (USDm) | L19: =+J8*L17 -> 277.25371
C20: Sweep | F20: 0
F22: Investment year count | K22: 0 | L22: =+K22+1 -> 1 | M22: =+L22+1 -> 2 | N22: =+M22+1 -> 3 | O22: =+N22+1 -> 4 | P22: =+O22+1 -> 5 | V22: 0 | W22: =+V22+1 -> 1 | X22: =+W22+1 -> 2 | Y22: =+X22+1 -> 3 | Z22: =+Y22+1 -> 4 | AA22: =+Z22+1 -> 5
F23: Year | G23: =+K23-1 -> 2016 | K23: 2017 | L23: =+K23+1 -> 2018 | M23: =+L23+1 -> 2019 | N23: =+M23+1 -> 2020 | O23: =+N23+1 -> 2021 | P23: =+O23+1 -> 2022 | Q23: 5Y CAGR | V23: 2017 | W23: =+V23+1 -> 2018 | X23: =+W23+1 -> 2019 | Y23: =+X23+1 -> 2020 | Z23: =+Y23+1 -> 2021 | AA23: =+Z23+1 -> 2022
A24: x | B24: Income statement | T24: LBO output and credit metrics
C25: Revenue | G25: 1220 | K25: =+CHOOSE($T$5, K27,K28) -> 1296 | L25: =+CHOOSE($T$5, L27,L28) -> 1400.6 | M25: =+CHOOSE($T$5, M27,M28) -> 1505.2 | N25: =+CHOOSE($T$5, N27,N28) -> 1609.8 | O25: =+CHOOSE($T$5, O27,O28) -> 1714.4 | P25: =+CHOOSE($T$5, P27,P28) -> 1819 | Q25: =+(P25/K25)^(1/$P$22)-1 -> 0.070152177 | T25: EBITDA | Y25: =+N44 -> 483.65953 | Z25: =+O44 -> 525.38852 | AA25: =+P44 -> 569.54035
C26: YoY % | K26: =+K25/G25-1 -> 0.062295082 | L26: =+L25/K25-1 -> 0.080709877 | M26: =+M25/L25-1 -> 0.074682279 | N26: =+N25/M25-1 -> 0.069492426 | O26: =+O25/N25-1 -> 0.064977016 | P26: =+P25/O25-1 -> 0.061012599 | T26: Exit multiple | Y26: 14 | Z26: 14 | AA26: 14 | AB26: << Avery trading price
C27: Memo: mgmt. projections | K27: 1296 | L27: 1384 | M27: 1490 | N27: 1621 | O27: 1769 | P27: 1938 | T27: Exit EV | Y27: =+Y26*Y25 -> 6771.2334 | Z27: =+Z26*Z25 -> 7355.4393 | AA27: =+AA26*AA25 -> 7973.5649
C28: Adj. mgmt. projections | K28: =+RevBuild!K13 -> 1296 | L28: =+RevBuild!L13 -> 1400.6 | M28: =+RevBuild!M13 -> 1505.2 | N28: =+RevBuild!N13 -> 1609.8 | O28: =+RevBuild!O13 -> 1714.4 | P28: =+RevBuild!P13 -> 1819
T29: (-) net debt | Y29: =+Y37 -> 1669.3782 | Z29: =+Z37 -> 1312.5689 | AA29: =+AA37 -> 885.84878
C30: COGS | G30: -600 | K30: =+CHOOSE($T$5, K32,K33) -> -618 | L30: =+CHOOSE($T$5, L32,L33) -> -668.92818 | M30: =+CHOOSE($T$5, M32,M33) -> -719.26336 | N30: =+CHOOSE($T$5, N32,N33) -> -769.64528 | O30: =+CHOOSE($T$5, O32,O33) -> -820.85743 | P30: =+CHOOSE($T$5, P32,P33) -> -872.89474 | T30: Exit EqV | Y30: =+Y27-Y29 -> 5101.8553 | Z30: =+Z27-Z29 -> 6042.8705 | AA30: =+AA27-AA29 -> 7087.7161
C31: % of sales | G31: =+G30/G25*-1 -> 0.49180328 | K31: =+K30/K25*-1 -> 0.47685185 | L31: =+L30/L25*-1 -> 0.47760116 | M31: =+M30/M25*-1 -> 0.47785235 | N31: =+N30/N25*-1 -> 0.47809994 | O31: =+O30/O25*-1 -> 0.47880158 | P31: =+P30/P25*-1 -> 0.47987616
C32: Memo: mgmt. projections | K32: -618 | L32: -661 | M32: -712 | N32: -775 | O32: -847 | P32: -930 | T32: MOIC | Y32: =+Y30/$J$7 -> 1.7941361 | Z32: =+Z30/$J$7 -> 2.1250568 | AA32: =+AA30/$J$7 -> 2.4924908
C33: Adj. mgmt. projections | K33: =+K32/K$27*K$28 -> -618 | L33: =+L32/L$27*L$28 -> -668.92818 | M33: =+M32/M$27*M$28 -> -719.26336 | N33: =+N32/N$27*N$28 -> -769.64528 | O33: =+O32/O$27*O$28 -> -820.85743 | P33: =+P32/P$27*P$28 -> -872.89474 | T33: IRR | Y33: =+Y32^(1/Y22)-1 -> 0.21511802 | Z33: =+Z32^(1/Z22)-1 -> 0.20737626 | AA33: =+AA32^(1/AA22)-1 -> 0.20040201
C35: Gross profit | G35: =+G30+G25 -> 620 | K35: =+K30+K25 -> 678 | L35: =+L30+L25 -> 731.67182 | M35: =+M30+M25 -> 785.93664 | N35: =+N30+N25 -> 840.15472 | O35: =+O30+O25 -> 893.54257 | P35: =+P30+P25 -> 946.10526 | Q35: =+(P35/K35)^(1/$P$22)-1 -> 0.068912001 | T35: Credit metrics
T36: Total debt | V36: =+K77+K80+K81 -> 2532 | W36: =+L77+L80+L81 -> 2349.4784 | X36: =+M77+M80+M81 -> 2113.3458 | Y36: =+N77+N80+N81 -> 1819.3782 | Z36: =+O77+O80+O81 -> 1462.5689 | AA36: =+P77+P80+P81 -> 1035.8488
C37: SG&A | G37: -317 | K37: =+CHOOSE($T$5, K39,K40) -> -316 | L37: =+CHOOSE($T$5, L39,L40) -> -341.04205 | M37: =+CHOOSE($T$5, M39,M40) -> -359.63168 | N37: =+CHOOSE($T$5, N39,N40) -> -374.39519 | O37: =+CHOOSE($T$5, O39,O40) -> -387.65404 | P37: =+CHOOSE($T$5, P39,P40) -> -397.96491 | T37: Net debt | V37: =+V36-K63 -> 2382 | W37: =+W36-L63 -> 2199.4784 | X37: =+X36-M63 -> 1963.3458 | Y37: =+Y36-N63 -> 1669.3782 | Z37: =+Z36-O63 -> 1312.5689 | AA37: =+AA36-P63 -> 885.84878
C38: % of sales | K38: =+K37/K25*-1 -> 0.24382716 | L38: =+L37/L25*-1 -> 0.24349711 | M38: =+M37/M25*-1 -> 0.23892617 | N38: =+N37/N25*-1 -> 0.23257249 | O38: =+O37/O25*-1 -> 0.22611645 | P38: =+P37/P25*-1 -> 0.21878225
C39: Memo: mgmt. projections | K39: -316 | L39: -337 | M39: -356 | N39: -377 | O39: -400 | P39: -424 | T39: Debt / EBITDA | V39: =+V36/K44 -> 6.7286739 | W39: =+W36/L44 -> 5.7878938 | X39: =+X36/M44 -> 4.7737115 | Y39: =+Y36/N44 -> 3.7616919 | Z39: =+Z36/O44 -> 2.7837853 | AA39: =+AA36/P44 -> 1.8187452
C40: Adj. mgmt. projections | K40: =+K39/K$27*K$28 -> -316 | L40: =+L39/L$27*L$28 -> -341.04205 | M40: =+M39/M$27*M$28 -> -359.63168 | N40: =+N39/N$27*N$28 -> -374.39519 | O40: =+O39/O$27*O$28 -> -387.65404 | P40: =+P39/P$27*P$28 -> -397.96491 | T40: ND / EBITDA | V40: =+V37/K44 -> 6.3300558 | W40: =+W37/L44 -> 5.4183717 | X40: =+X37/M44 -> 4.4348853 | Y40: =+Y37/N44 -> 3.4515564 | Z40: =+Z37/O44 -> 2.4982823 | AA40: =+AA37/P44 -> 1.5553749
C42: Other income / (losses) | G42: 13.5 | K42: 14.3 | L42: 15.3 | M42: 16.4 | N42: 17.9 | O42: 19.5 | P42: 21.4 | T42: EBIT / interest | W42: =+L50/L53*-1 -> 1.4213116 | X42: =+M50/M53*-1 -> 1.7599562 | Y42: =+N50/N53*-1 -> 2.2468951 | Z42: =+O50/O53*-1 -> 2.9721355 | AA42: =+P50/P53*-1 -> 4.2232253
C44: EBITDA | G44: =+G42+G37+G35 -> 316.5 | K44: =+K42+K37+K35 -> 376.3 | L44: =+L42+L37+L35 -> 405.92977 | M44: =+M42+M37+M35 -> 442.70497 | N44: =+N42+N37+N35 -> 483.65953 | O44: =+O42+O37+O35 -> 525.38852 | P44: =+P42+P37+P35 -> 569.54035 | Q44: =+(P44/K44)^(1/$P$22)-1 -> 0.086420761 | T44: Ability to pay analysis
...

Sheet RevBuild
K6: =+Model!K23 -> 2017 | L6: =+Model!L23 -> 2018 | M6: =+Model!M23 -> 2019 | N6: =+Model!N23 -> 2020 | O6: =+Model!O23 -> 2021 | P6: =+Model!P23 -> 2022 | R6: Switch
E7: 2017 revenue | K7: =+Model!K25 -> 1296 | P7: =+K7 -> 1296
E8: Growth of top 50 customers (excl e-comm) | P8: =248*R8 -> 248 | R8: 1
E9: Expansion of wallet share of top 50 customers (excl e-comm) | P9: =78*R9 -> 78 | R9: 1
E10: E-Commerce | P10: =197*R10 -> 197 | R10: 1
E11: Cross-selling | P11: =18*R11 -> 0 | R11: 0 | S11: << lack of evidence for ability to cross sell
E12: Revenue growth from other customers and new customers | P12: =102*R12 -> 0 | R12: 0 | S12: << lack of evidence on other customers and new customers
E13: Discounted mgmt base case | K13: =+SUM(K7:K12) -> 1296 | L13: =+($P$13-$K$13)/COUNTA($L$6:$P$6)+K13 -> 1400.6 | M13: =+($P$13-$K$13)/COUNTA($L$6:$P$6)+L13 -> 1505.2 | N13: =+($P$13-$K$13)/COUNTA($L$6:$P$6)+M13 -> 1609.8 | O13: =+($P$13-$K$13)/COUNTA($L$6:$P$6)+N13 -> 1714.4 | P13: =+SUM(P7:P12) -> 1819 | S13: << linear interpolation in years in between
