Workbook

Sheet Data
B2: Summary P&L
B3: (€m, FYE 31-Dec) | C3: 2017A | D3: 2018A | E3: 2019A | F3: 2020E
C4: GAAP | D4: GAAP | E4: IFRS | F4: IFRS
B5: Output
B6: AMS Europe | C6: 31.5 | D6: 32.4 | E6: 37.3 | F6: 53.946401
B7: ECS Europe | C7: 31 | D7: 32.9 | E7: 38.9 | F7: 42.650783
B8: Americas & Asia | C8: 18.6 | D8: 22.8 | E8: 28.3 | F8: 32.533501
B9: Others | C9: 62.8 | D9: 57.9 | E9: 42.6 | F9: 36.202339
B10: Total Output | C10: 143.9 | D10: 146 | E10: 147.1 | F10: 165.33302
B12: Gross profit
B13: AMS Europe | C13: 9.5 | D13: 9.2 | E13: 11.2 | F13: 15.564811
B14: ECS Europe | C14: 11.1 | D14: 10.3 | E14: 14.4 | F14: 15.21323
B15: Americas & Asia | C15: 4 | D15: 3.8 | E15: 5.4 | F15: 6.9185281
B16: Others | C16: 16 | D16: 15.6 | E16: 15 | F16: 14.528397
B17: Total Gross Profit | C17: 40.6 | D17: 38.9 | E17: 46 | F17: 52.224966
B19: Overheads and Other
B20: Personnel expenses | C20: -23.774162 | D20: -24.428558 | E20: -25.728552 | F20: -26.453284
B21: Other operating expenses | C21: -11.355504 | D21: -9.1910144 | E21: -9.1900621 | F21: -9.3418151
B22: Other operating income | C22: 1.9575444 | D22: 1.9168258 | E22: 1.9825992 | F22: 2.1493293
B23: Total Overheads and Other | C23: -33.172121 | D23: -31.702747 | E23: -32.936015 | F23: -33.64577
B25: EBITDA | C25: 7.4278788 | D25: 7.1972532 | E25: 13.063985 | F25: 18.579196
B27: Other items:
B28: D&A | C28: -3.2109359 | D28: -2.9779364 | E28: -5.5279112 | F28: -4.3133125
B29: Capex | C29: -2 | D29: -2.7 | E29: -2.8 | F29: -3.140329
B30: IFRS-16 leasing costs | C30: n.a. | D30: n.a. | E30: -1.4 | F30: -1.5701645
B31: Financial lease costs (IAS 17) | C31: n.a. | D31: -1 | E31: -1.4 | F31: -1.4
B32: Factoring (fees and interest) | C32: n.a. | D32: -1.4432411 | E32: -1.7267365 | F32: -1.9366145
B34: % Growth
B35: Total Output | C35: n.a. | D35: =+D10/C10-1 -> 0.014593468 | E35: =+E10/D10-1 -> 0.0075342466 | F35: =+F10/E10-1 -> 0.12394986
B36: Total Gross Profit | D36: =D17/C17-1 -> -0.041871921 | E36: =E17/D17-1 -> 0.18251928 | F36: =F17/E17-1 -> 0.13532535
B37: Total Overheads and Other | D37: =D23/C23-1 -> -0.044295459 | E37: =E23/D23-1 -> 0.038900995 | F37: =F23/E23-1 -> 0.021549491
B38: EBITDA | D38: =D25/C25-1 -> -0.031048658 | E38: =E25/D25-1 -> 0.81513481 | F38: =F25/E25-1 -> 0.42216917
B40: % of Total Output
B41: Total Gross Profit | C41: =+C17/C10 -> 0.28214038 | D41: =+D17/D10 -> 0.26643836 | E41: =+E17/E10 -> 0.31271244 | F41: =+F17/F10 -> 0.3158774
B42: Total Overheads and Other | C42: =C23/C10 -> -0.23052204 | D42: =D23/D10 -> -0.2171421 | E42: =E23/E10 -> -0.22390221 | F42: =F23/F10 -> -0.20350302
B43: EBITDA | C43: =C25/C10 -> 0.051618338 | D43: =D25/D10 -> 0.049296254 | E43: =E25/E10 -> 0.088810229 | F43: =F25/F10 -> 0.11237438
B45: Summary Balance sheet
B46: (€m) | D46: =D3 -> 2018A | E46: =E3 -> 2019A | F46: =F3 -> 2020E
B47: Assets
B48: Tangible assets(1) | D48: 3.0813375 | E48: 7.1965907 | F48: 7.4236071
...

Sheet Model
B2: Reverse Logistics Group (RLG) - LBO Model (July 2020)
B4: €m, FY Dec | C4: 2017 | D4: 2018 | E4: 2019 | F4: 2020 | G4: 2021 | H4: 2022 | I4: 2023 | J4: 2024 | K4: 2025
B6: Key Assumptions (Inputs)
B7: Entry EV / EBITDA multiple | C7: 8
B8: Exit EV / EBITDA multiple | C8: 8
B9: Entry date (FY2020E base) | C9: 2020
B10: Exit year | C10: 2025
B11: Tax rate | C11: 0.25
B12: D&A as % of revenue | C12: 0.0261
B13: Capex as % of revenue (incl. catch-up) | C13: 0.03
B14: NWC as % of revenue (Trade WC) | C14: 0.03
B15: Transaction fees (% of EV) | C15: 0.02
B16: Financing fees (% of new debt) | C16: 0.02
B17: Revolver (max) | C17: 10
B18: Cash minimum | C18: 5
... B22: Amortization (% of opening senior debt) | C22: 0.05
B25: Revenue Growth Assumptions (CAGR 2020-2025)
B26: Europe AMS | C26: 0.07
B27: Europe ECS | C27: 0.05
B28: Americas & Asia | C28: 0.12
B29: Others | C29: -0.05
B31: Operating Forecast
B32: Revenue
B33: Europe AMS | C33: =Data!C6 -> 31.5 | D33: =Data!D6 -> 32.4 | E33: =Data!E6 -> 37.3 | F33: =Data!F6 -> 53.946401 | G33: =F33*(1+$C$26) -> 57.722649 | H33: =G33*(1+$C$26) -> 61.763235 | I33: =H33*(1+$C$26) -> 66.086661 | J33: =I33*(1+$C$26) -> 70.712727 | K33: =J33*(1+$C$26) -> 75.662618
B34: Europe ECS | C34: =Data!C7 -> 31 | D34: =Data!D7 -> 32.9 | E34: =Data!E7 -> 38.9 | F34: =Data!F7 -> 42.650783 | G34: =F34*(1+$C$27) -> 44.783322 | H34: =G34*(1+$C$27) -> 47.022488 | I34: =H34*(1+$C$27) -> 49.373613 | J34: =I34*(1+$C$27) -> 51.842293 | K34: =J34*(1+$C$27) -> 54.434408
B35: Americas & Asia | C35: =Data!C8 -> 18.6 | D35: =Data!D8 -> 22.8 | E35: =Data!E8 -> 28.3 | F35: =Data!F8 -> 32.533501 | G35: =F35*(1+$C$28) -> 36.437521 | H35: =G35*(1+$C$28) -> 40.810024 | I35: =H35*(1+$C$28) -> 45.707227 | J35: =I35*(1+$C$28) -> 51.192094 | K35: =J35*(1+$C$28) -> 57.335145
B36: Others | C36: =Data!C9 -> 62.8 | D36: =Data!D9 -> 57.9 | E36: =Data!E9 -> 42.6 | F36: =Data!F9 -> 36.202339 | G36: =F36*(1+$C$29) -> 34.392222 | H36: =G36*(1+$C$29) -> 32.672611 | I36: =H36*(1+$C$29) -> 31.03898 | J36: =I36*(1+$C$29) -> 29.487031 | K36: =J36*(1+$C$29) -> 28.01268
B37: Total Revenue | C37: =Data!C10 -> 143.9 | D37: =Data!D10 -> 146 | E37: =Data!E10 -> 147.1 | F37: =Data!F10 -> 165.33302 | G37: =SUM(G33:G36) -> 173.33571 | H37: =SUM(H33:H36) -> 182.26836 | I37: =SUM(I33:I36) -> 192.20648 | J37: =SUM(J33:J36) -> 203.23415 | K37: =SUM(K33:K36) -> 215.44485
B39: Cost of Sales (variable)
B40: Gross margin (based on 2020E) | C40: =Data!F17/Data!F10 -> 0.3158774
B41: COGS | C41: =-C37*(1-$C$40) -> -98.445242 | D41: =-D37*(1-$C$40) -> -99.881899 | E41: =-E37*(1-$C$40) -> -100.63443 | F41: =-F37*(1-$C$40) -> -113.10806 | G41: =-G37*(1-$C$40) -> -118.58288 | H41: =-H37*(1-$C$40) -> -124.6939 | I41: =-I37*(1-$C$40) -> -131.4928 | J41: =-J37*(1-$C$40) -> -139.03707 | K41: =-K37*(1-$C$40) -> -147.39069
B42: Gross Profit | C42: =C37+C41 -> 45.454758 | D42: =D37+D41 -> 46.118101 | E42: =E37+E41 -> 46.465566 | F42: =F37+F41 -> 52.224966 | G42: =G37+G41 -> 54.752835 | H42: =H37+H41 -> 57.574455 | I42: =I37+I41 -> 60.713684 | J42: =J37+J41 -> 64.197074 | K42: =K37+K41 -> 68.05416
B44: Operating Expenses (fixed / semi-fixed)
B45: Personnel expenses (% revenue) | C45: =Data!F20/Data!F10 -> -0.16
B46: Other operating expenses (% revenue) | C46: =Data!F21/Data!F10 -> -0.05650302
B47: Other operating income (% revenue) | C47: =Data!F22/Data!F10 -> 0.013
B49: Personnel expenses | C49: =C37*$C$45 -> -23.024 | D49: =D37*$C$45 -> -23.36 | E49: =E37*$C$45 -> -23.536 | F49: =F37*$C$45 -> -26.453284 | G49: =G37*$C$45 -> -27.733714 | H49: =H37*$C$45 -> -29.162937 | I49: =I37*$C$45 -> -30.753037 | J49: =J37*$C$45 -> -32.517463 | K49: =K37*$C$45 -> -34.471176
B50: Other operating expenses | C50: =C37*$C$46 -> -8.1307845 | D50: =D37*$C$46 -> -8.2494409 | E50: =E37*$C$46 -> -8.3115942 | F50: =F37*$C$46 -> -9.3418151 | G50: =G37*$C$46 -> -9.7939913 | H50: =H37*$C$46 -> -10.298713 | I50: =I37*$C$46 -> -10.860247 | J50: =J37*$C$46 -> -11.483343 | K50: =K37*$C$46 -> -12.173285
B51: Other operating income | C51: =C37*$C$47 -> 1.8707 | D51: =D37*$C$47 -> 1.898 | E51: =E37*$C$47 -> 1.9123 | F51: =F37*$C$47 -> 2.1493293 | G51: =G37*$C$47 -> 2.2533643 | H51: =H37*$C$47 -> 2.3694886 | I51: =I37*$C$47 -> 2.4986842 | J51: =J37*$C$47 -> 2.6420439 | K51: =K37*$C$47 -> 2.8007831
B52: Total Opex | C52: =SUM(C49:C51) -> -29.284085 | D52: =SUM(D49:D51) -> -29.711441 | E52: =SUM(E49:E51) -> -29.935294 | F52: =SUM(F49:F51) -> -33.64577 | G52: =SUM(G49:G51) -> -35.274341 | H52: =SUM(H49:H51) -> -37.092161 | I52: =SUM(I49:I51) -> -39.114599 | J52: =SUM(J49:J51) -> -41.358762 | K52: =SUM(K49:K51) -> -43.843678
...
