Workbook

Sheet BBPTACShadowWks0001
S5: =#REF! -> #REF!
V27: =#REF! -> #REF! | W27: =#REF! -> #REF! | X27: =#REF! -> #REF!
V28: =#REF! -> #REF! | W28: =#REF! -> #REF! | X28: =#REF! -> #REF!
T29: =#REF! -> #REF! | V29: =#REF! -> #REF! | W29: =#REF! -> #REF! | X29: =#REF! -> #REF!
L36: =#REF! -> #REF! | M36: =#REF! -> #REF!
J37: =#REF! -> #REF! | K37: =#REF! -> #REF!
G128: =#REF! -> #REF! | H128: =#REF! -> #REF! | I128: =#REF! -> #REF! | J128: =#REF! -> #REF! | K128: =#REF! -> #REF! | L128: =#REF! -> #REF! | M128: =#REF! -> #REF!
G129: =#REF! -> #REF! | H129: =#REF! -> #REF! | I129: =#REF! -> #REF! | J129: =#REF! -> #REF! | K129: =#REF! -> #REF! | L129: =#REF! -> #REF! | M129: =#REF! -> #REF!
G130: =#REF! -> #REF! | H130: =#REF! -> #REF! | I130: =#REF! -> #REF! | J130: =#REF! -> #REF! | K130: =#REF! -> #REF! | L130: =#REF! -> #REF! | M130: =#REF! -> #REF!
G131: =#REF! -> #REF! | H131: =#REF! -> #REF! | I131: =#REF! -> #REF! | J131: =#REF! -> #REF! | K131: =#REF! -> #REF! | L131: =#REF! -> #REF! | M131: =#REF! -> #REF!
K134: =#REF! -> #REF!
G147: =#REF! -> #REF!
G148: =#REF! -> #REF!
G149: =#REF! -> #REF!
E192: =#REF! -> #REF!
G193: =#REF! -> #REF!
G194: =#REF! -> #REF! | H194: =#REF! -> #REF!
G195: =#REF! -> #REF! | H195: =#REF! -> #REF!
G196: =#REF! -> #REF!
G197: =#REF! -> #REF!
G198: =#REF! -> #REF!
G199: =#REF! -> #REF! | H199: =#REF! -> #REF! | I199: =#REF! -> #REF! | J199: =#REF! -> #REF!
G200: =#REF! -> #REF! | H200: =#REF! -> #REF! | I200: =#REF! -> #REF! | J200: =#REF! -> #REF!
G201: =#REF! -> #REF! | H201: =#REF! -> #REF! | I201: =#REF! -> #REF! | J201: =#REF! -> #REF!
G202: =#REF! -> #REF! | H202: =#REF! -> #REF! | I202: =#REF! -> #REF! | J202: =#REF! -> #REF!
G203: =#REF! -> #REF!
G204: =#REF! -> #REF! | H204: =#REF! -> #REF!
G205: =#REF! -> #REF!
P242: =#REF! -> #REF!
P243: =#REF! -> #REF!
P244: =#REF! -> #REF!
M245: =#REF! -> #REF! | N245: =#REF! -> #REF! | O245: =#REF! -> #REF! | P245: =#REF! -> #REF!
M246: =#REF! -> #REF! | N246: =#REF! -> #REF!
L247: =#REF! -> #REF!
K282: =#REF! -> #REF! | L282: =#REF! -> #REF! | M282: =#REF! -> #REF! | N282: =#REF! -> #REF! | O282: =#REF! -> #REF!
P285: =#REF! -> #REF!
P286: =#REF! -> #REF!

Sheet Model Shell
A1: Kirby Corp
A2: US$mm unless otherwise specified | G2: =AQ3 -> 2Q24 | J2: Act. | K2: Act. | L2: Act. | M2: Act. | N2: Act. | O2: Act. | P2: Est. | R2: Act. | S2: Act. | T2: Act. | U2: Act. | V2: Act. | W2: Act. | X2: Act. | Y2: Act. | Z2: Act. | AA2: Act. | AB2: Act. | AC2: Act. | AD2: Act. | AE2: Act. | AF2: Act. | AG2: Act. | AH2: Act. | AI2: Act. | AJ2: Act. | AK2: Act. | AL2: Act. | AM2: Act. | AN2: Act. | AO2: Act. | AP2: Act. | AQ2: Act. | AR2: Est. | AS2: Est. | AT2: Est. | AU2: Est. | AV2: Est. | AW2: Est.
G3: LQA | H3: LTM | J3: 2018 | K3: =J3+1 -> 2019 | L3: =K3+1 -> 2020 | M3: =L3+1 -> 2021 | N3: =M3+1 -> 2022 | O3: =N3+1 -> 2023 | P3: =O3+1 -> 2024 | R3: 1Q18 | S3: 2Q18 | T3: 3Q18 | U3: 4Q18 | V3: 1Q19 | W3: 2Q19 | X3: 3Q19 | Y3: 4Q19 | Z3: 1Q20 | AA3: 2Q20 | AB3: 3Q20 | AC3: 4Q20 | AD3: 1Q21 | AE3: 2Q21 | AF3: 3Q21 | AG3: 4Q21 | AH3: 1Q22 | AI3: 2Q22 | AJ3: 3Q22 | AK3: 4Q22 | AL3: 1Q23 | AM3: 2Q23 | AN3: 3Q23 | AO3: 4Q23 | AP3: 1Q24 | AQ3: 2Q24 | AR3: 3Q24 | AS3: 4Q24 | AT3: 1Q25 | AU3: 2Q25 | AV3: 3Q25 | AW3: 4Q25
A5: x | B5: Income Statement
B7: Marine Transport | G7: =OFFSET(R7,0,MATCH($G$2,$R$3:$AW$3,0)-1)*4 -> 1939.232 | H7: =SUM(OFFSET(R7,0,MATCH($G$2,$R$3:$AW$3,0)-4),OFFSET(R7,0,MATCH($G$2,$R$3:$AW$3,0)-3),OFFSET(R7,0,MATCH($G$2,$R$3:$AW$3,0)-2),OFFSET(R7,0,MATCH($G$2,$R$3:$AW$3,0)-1)) -> 1842.7 | J7: =SUM(R7:U7) -> 1483.143 | K7: =SUM(V7:Y7) -> 1587.082 | L7: =SUM(Z7:AC7) -> 1404.265 | M7: =SUM(AD7:AG7) -> 1322.918 | N7: =SUM(AH7:AK7) -> 1616.967 | O7: =SUM(AL7:AO7) -> 1721.937 | R7: 340.403 | S7: 378.163 | T7: 382.04 | U7: 382.537 | V7: 368.121 | W7: 404.286 | X7: 412.665 | Y7: 402.01 | Z7: 403.257 | AA7: 380.987 | AB7: 320.602 | AC7: 299.419 | AD7: 300.951 | AE7: 332.887 | AF7: 338.514 | AG7: 350.566 | AH7: 355.536 | AI7: 405.655 | AJ7: 433.04 | AK7: 422.736 | AL7: 412.495 | AM7: 426.962 | AN7: 429.885 | AO7: 452.595 | AP7: 475.412 | AQ7: 484.808
B8: Distribution & Services | G8: =OFFSET(R8,0,MATCH($G$2,$R$3:$AW$3,0)-1)*4 -> 1358.328 | H8: =SUM(OFFSET(R8,0,MATCH($G$2,$R$3:$AW$3,0)-4),OFFSET(R8,0,MATCH($G$2,$R$3:$AW$3,0)-3),OFFSET(R8,0,MATCH($G$2,$R$3:$AW$3,0)-2),OFFSET(R8,0,MATCH($G$2,$R$3:$AW$3,0)-1)) -> 1353.66 | J8: =SUM(R8:U8) -> 1487.554 | K8: =SUM(V8:Y8) -> 1251.317 | L8: =SUM(Z8:AC8) -> 767.143 | M8: =SUM(AD8:AG8) -> 923.742 | N8: =SUM(AH8:AK8) -> 1167.787 | O8: =SUM(AL8:AO8) -> 1369.703 | R8: 401.285 | S8: 424.508 | T8: 322.805 | U8: 338.956 | V8: 376.5 | W8: 366.756 | X8: 254.144 | Y8: 253.917 | Z8: 240.669 | AA8: 160.172 | AB8: 175.965 | AC8: 190.337 | AD8: 195.899 | AE8: 226.737 | AF8: 260.406 | AG8: 240.7 | AH8: 255.246 | AI8: 292.309 | AJ8: 312.803 | AK8: 307.429 | AL8: 337.949 | AM8: 350.286 | AN8: 334.887 | AO8: 346.581 | AP8: 332.61 | AQ8: 339.582
B9: Total Revenues | G9: =SUM(G7:G8) -> 3297.56 | H9: =SUM(H7:H8) -> 3196.36 | J9: =SUM(J7:J8) -> 2970.697 | K9: =SUM(K7:K8) -> 2838.399 | L9: =SUM(L7:L8) -> 2171.408 | M9: =SUM(M7:M8) -> 2246.66 | N9: =SUM(N7:N8) -> 2784.754 | O9: =SUM(O7:O8) -> 3091.64 | R9: =SUM(R7:R8) -> 741.688 | S9: =SUM(S7:S8) -> 802.671 | T9: =SUM(T7:T8) -> 704.845 | U9: =SUM(U7:U8) -> 721.493 | V9: =SUM(V7:V8) -> 744.621 | W9: =SUM(W7:W8) -> 771.042 | X9: =SUM(X7:X8) -> 666.809 | Y9: =SUM(Y7:Y8) -> 655.927 | ... AQ9: =SUM(AQ7:AQ8) -> 824.39
C10: Y/Y Growth % | G10: =G9/G7 -> 1.7004464 | H10: =H9/H7 -> 1.7346068 | K10: =K9/J9-1 -> -0.04453433 | L10: =L9/K9-1 -> -0.23498846 | M10: =M9/L9-1 -> 0.034655855 | N10: =N9/M9-1 -> 0.23950843 | O10: =O9/N9-1 -> 0.11020219 | V10: =V9/R9-1 -> 0.003954493 | W10: =W9/S9-1 -> -0.039404688 | X10: =X9/T9-1 -> -0.053963637 | Y10: =Y9/U9-1 -> -0.090875449 | Z10: =Z9/V9-1 -> -0.13522987 | AA10: =AA9/W9-1 -> -0.29814589 | AB10: =AB9/X9-1 -> -0.25530849 | AC10: =AC9/Y9-1 -> -0.25333764 | ... AQ10: =AQ9/AM9-1 -> 0.060652456
C11: Sequential Growth % | S11: =S9/R9-1 -> 0.082221905 | T11: =T9/S9-1 -> -0.12187559 | U11: =U9/T9-1 -> 0.023619377 | V11: =V9/U9-1 -> 0.032055751 | W11: =W9/V9-1 -> 0.03548248 | X11: =X9/W9-1 -> -0.13518459 | Y11: =Y9/X9-1 -> -0.016319516 | Z11: =Z9/Y9-1 -> -0.018296243 | ... AQ11: =AQ9/AP9-1 -> 0.020256874
B13: Cash COGS & OpEX | G13: =OFFSET(R13,0,MATCH($G$2,$R$3:$AW$3,0)-1)*4 -> -2216.928 | H13: =SUM(OFFSET(R13,0,MATCH($G$2,$R$3:$AW$3,0)-4),OFFSET(R13,0,MATCH($G$2,$R$3:$AW$3,0)-3),OFFSET(R13,0,MATCH($G$2,$R$3:$AW$3,0)-2),OFFSET(R13,0,MATCH($G$2,$R$3:$AW$3,0)-1)) -> -2197.186 | J13: =SUM(R13:U13) -> -2160.946 | K13: =SUM(V13:Y13) -> -2030.046 | L13: =SUM(Z13:AC13) -> -1510.818 | M13: =SUM(AD13:AG13) -> -1652.961 | N13: =SUM(AH13:AK13) -> -2060.941 | O13: =SUM(AL13:AO13) -> -2180.422 | R13: -553.317 | S13: -588.628 | T13: -498.421 | U13: -520.58 | V13: -536.655 | W13: -563.495 | X13: -458.514 | Y13: -471.382 | Z13: -453.568 | AA13: -373.539 | AB13: -340.764 | AC13: -342.947 | AD13: -363.04 | AE13: -409.479 | AF13: -446.519 | AG13: -433.923 | AH13: -450.618 | AI13: -523.862 | AJ13: -552.392 | AK13: -534.069 | AL13: -542.08 | AM13: -546.069 | AN13: -530.541 | AO13: -561.732 | AP13: -550.681 | AQ13: -554.232
B14: Cash Gross Profit | G14: =G9+SUM(G13:G13) -> 1080.632 | H14: =H9+SUM(H13:H13) -> 999.174 | J14: =J9+SUM(J13:J13) -> 809.751 | K14: =K9+SUM(K13:K13) -> 808.353 | L14: =L9+SUM(L13:L13) -> 660.59 | M14: =M9+SUM(M13:M13) -> 593.699 | N14: =N9+SUM(N13:N13) -> 723.813 | O14: =O9+SUM(O13:O13) -> 911.218 | R14: =R9+SUM(R13:R13) -> 188.371 | S14: =S9+SUM(S13:S13) -> 214.043 | T14: =T9+SUM(T13:T13) -> 206.424 | U14: =U9+SUM(U13:U13) -> 200.913 | V14: =V9+SUM(V13:V13) -> 207.966 | W14: =W9+SUM(W13:W13) -> 207.547 | X14: =X9+SUM(X13:X13) -> 208.295 | Y14: =Y9+SUM(Y13:Y13) -> 184.545 | ... AQ14: =AQ9+SUM(AQ13:AQ13) -> 270.158
C15: Gross Margin % | G15: =G14/G9 -> 0.32770655 | H15: =H14/H9 -> 0.31259745 | J15: =J14/J9 -> 0.27257947 | K15: =K14/K9 -> 0.28479188 | L15: =L14/L9 -> 0.30422196 | M15: =M14/M9 -> 0.2642585 | N15: =N14/N9 -> 0.25991991 | O15: =O14/O9 -> 0.29473613 | R15: =R14/R9 -> 0.25397607 | S15: =S14/S9 -> 0.26666343 | T15: =T14/T9 -> 0.29286439 | U15: =U14/U9 -> 0.2784684 | V15: =V14/V9 -> 0.27929108 | W15: =W14/W9 -> 0.2691773 | X15: =X14/X9 -> 0.31237581 | Y15: =Y14/Y9 -> 0.28134991 | ... AQ15: =AQ14/AQ9 -> 0.32770655
B17: SG&A | G17: =OFFSET(R17,0,MATCH($G$2,$R$3:$AW$3,0)-1)*4 -> -321.532 | H17: =SUM(OFFSET(R17,0,MATCH($G$2,$R$3:$AW$3,0)-4),OFFSET(R17,0,MATCH($G$2,$R$3:$AW$3,0)-3),OFFSET(R17,0,MATCH($G$2,$R$3:$AW$3,0)-2),OFFSET(R17,0,MATCH($G$2,$R$3:$AW$3,0)-1)) -> -334.057 | J17: =SUM(R17:U17) -> -304.397 | K17: =SUM(V17:Y17) -> -277.388 | L17: =SUM(Z17:AC17) -> -258.272 | M17: =SUM(AD17:AG17) -> -266.911 | N17: =SUM(AH17:AK17) -> -301.392 | O17: =SUM(AL17:AO17) -> -335.213 | R17: -76.796 | S17: -92.588 | T17: -70.032 | U17: -64.981 | V17: -72.796 | W17: -69.15 | X17: -64.656 | Y17: -70.786 | Z17: -72.08 | AA17: -65.612 | AB17: -61.72 | AC17: -58.86 | AD17: -69.629 | AE17: -62.74 | AF17: -66.065 | AG17: -68.477 | AH17: -75.765 | AI17: -69.275 | AJ17: -75.381 | AK17: -80.971 | AL17: -88.849 | AM17: -82.896 | AN17: -79.125 | AO17: -84.343 | AP17: -90.206 | AQ17: -80.383
B18: Taxes other than Income | G18: =OFFSET(R18,0,MATCH($G$2,$R$3:$AW$3,0)-1)*4 -> -41.24 | H18: =SUM(OFFSET(R18,0,MATCH($G$2,$R$3:$AW$3,0)-4),OFFSET(R18,0,MATCH($G$2,$R$3:$AW$3,0)-3),OFFSET(R18,0,MATCH($G$2,$R$3:$AW$3,0)-2),OFFSET(R18,0,MATCH($G$2,$R$3:$AW$3,0)-1)) -> -34.176 | J18: =SUM(R18:U18) -> -39.251 | K18: =SUM(V18:Y18) -> -41.933 | L18: =SUM(Z18:AC18) -> -42 | M18: =SUM(AD18:AG18) -> -36.251 | N18: =SUM(AH18:AK18) -> -35.071 | O18: =SUM(AL18:AO18) -> -34.766 | R18: -8.535 | S18: -10.552 | T18: -10.523 | U18: -9.641 | V18: -9.998 | W18: -10.579 | X18: -10.909 | Y18: -10.447 | Z18: -11.406 | AA18: -13.065 | AB18: -9.077 | AC18: -8.452 | AD18: -8.26 | AE18: -10.364 | AF18: -9.917 | AG18: -7.71 | AH18: -9.59 | AI18: -9.621 | AJ18: -9.121 | AK18: -6.739 | AL18: -9.186 | AM18: -9.758 | AN18: -9.666 | AO18: -6.156 | AP18: -8.044 | AQ18: -10.31
B19: D&A | G19: =OFFSET(R19,0,MATCH($G$2,$R$3:$AW$3,0)-1)*4 -> -237.928 | H19: =SUM(OFFSET(R19,0,MATCH($G$2,$R$3:$AW$3,0)-4),OFFSET(R19,0,MATCH($G$2,$R$3:$AW$3,0)-3),OFFSET(R19,0,MATCH($G$2,$R$3:$AW$3,0)-2),OFFSET(R19,0,MATCH($G$2,$R$3:$AW$3,0)-1)) -> -225.474 | J19: =SUM(R19:U19) -> -224.972 | K19: =SUM(V19:Y19) -> -219.632 | L19: =SUM(Z19:AC19) -> -219.924 | M19: =SUM(AD19:AG19) -> -213.718 | N19: =SUM(AH19:AK19) -> -201.443 | O19: =SUM(AL19:AO19) -> -211.156 | R19: -54.218 | S19: -55.492 | T19: -57.93 | U19: -57.332 | V19: -55.223 | W19: -55.093 | X19: -54.455 | Y19: -54.861 | Z19: -55.789 | AA19: -54.502 | AB19: -54.779 | AC19: -54.854 | AD19: -54.89 | AE19: -55.132 | AF19: -53.462 | AG19: -50.234 | AH19: -49.964 | AI19: -50.115 | AJ19: -50.419 | AK19: -50.945 | AL19: -51.109 | AM19: -51.697 | AN19: -53.445 | AO19: -54.905 | AP19: -57.642 | AQ19: -59.482
B20: Core EBIT | G20: =G14+SUM(G17:G19) -> 479.932 | H20: =H14+SUM(H17:H19) -> 405.467 | J20: =J14+SUM(J17:J19) -> 241.131 | K20: =K14+SUM(K17:K19) -> 269.4 | L20: =L14+SUM(L17:L19) -> 140.394 | M20: =M14+SUM(M17:M19) -> 76.819 | N20: =N14+SUM(N17:N19) -> 185.907 | O20: =O14+SUM(O17:O19) -> 330.083 | R20: =R14+SUM(R17:R19) -> 48.822 | S20: =S14+SUM(S17:S19) -> 55.411 | T20: =T14+SUM(T17:T19) -> 67.939 | U20: =U14+SUM(U17:U19) -> 68.959 | V20: =V14+SUM(V17:V19) -> 69.949 | W20: =W14+SUM(W17:W19) -> 72.725 | X20: =X14+SUM(X17:X19) -> 78.275 | Y20: =Y14+SUM(Y17:Y19) -> 48.451 | ... AQ20: =AQ14+SUM(AQ17:AQ19) -> 119.983
C21: % Margin | G21: =G20/G9 -> 0.14554155 | H21: =H20/H9 -> 0.12685273 | J21: =J20/J9 -> 0.08116984 | K21: =K20/K9 -> 0.09491266 | L21: =L20/L9 -> 0.064655744 | M21: =M20/M9 -> 0.034192535 | N21: =N20/N9 -> 0.066758859 | O21: =O20/O9 -> 0.10676631 | R21: =R20/R9 -> 0.065825522 | S21: =S20/S9 -> 0.069033265 | T21: =T20/T9 -> 0.096388568 | U21: =U20/U9 -> 0.095578197 | V21: =V20/V9 -> 0.093939064 | W21: =W20/W9 -> 0.094320413 | X21: =X20/X9 -> 0.11738744 | Y21: =Y20/Y9 -> 0.073866452 | ... AQ21: =AQ20/AQ9 -> 0.14554155
B22: (+) D&A | G22: =OFFSET(R22,0,MATCH($G$2,$R$3:$AW$3,0)-1)*4 -> 237.928 | H22: =SUM(OFFSET(R22,0,MATCH($G$2,$R$3:$AW$3,0)-4),OFFSET(R22,0,MATCH($G$2,$R$3:$AW$3,0)-3),OFFSET(R22,0,MATCH($G$2,$R$3:$AW$3,0)-2),OFFSET(R22,0,MATCH($G$2,$R$3:$AW$3,0)-1)) -> 225.474 | J22: =SUM(R22:U22) -> 224.972 | K22: =SUM(V22:Y22) -> 219.632 | L22: =SUM(Z22:AC22) -> 219.924 | M22: =SUM(AD22:AG22) -> 213.718 | N22: =SUM(AH22:AK22) -> 201.443 | O22: =SUM(AL22:AO22) -> 211.156 | R22: =-R19 -> 54.218 | S22: =-S19 -> 55.492 | T22: =-T19 -> 57.93 | U22: =-U19 -> 57.332 | V22: =-V19 -> 55.223 | W22: =-W19 -> 55.093 | X22: =-X19 -> 54.455 | Y22: =-Y19 -> 54.861 | ... AQ22: =-AQ19 -> 59.482
B23: Core EBITDA | G23: =G20+G22 -> 717.86 | H23: =H20+H22 -> 630.941 | J23: =J20+J22 -> 466.103 | K23: =K20+K22 -> 489.032 | L23: =L20+L22 -> 360.318 | M23: =M20+M22 -> 290.537 | N23: =N20+N22 -> 387.35 | O23: =O20+O22 -> 541.239 | R23: =R20+R22 -> 103.04 | S23: =S20+S22 -> 110.903 | T23: =T20+T22 -> 125.869 | U23: =U20+U22 -> 126.291 | V23: =V20+V22 -> 125.172 | W23: =W20+W22 -> 127.818 | X23: =X20+X22 -> 132.73 | Y23: =Y20+Y22 -> 103.312 | ... AQ23: =AQ20+AQ22 -> 179.465
C24: % Margin | G24: =G23/G9 -> 0.2176943 | H24: =H23/H9 -> 0.1973936 | J24: =J23/J9 -> 0.15690022 | K24: =K23/K9 -> 0.17229149 | L24: =L23/L9 -> 0.16593749 | M24: =M23/M9 -> 0.12931952 | N24: =N23/N9 -> 0.13909667 | O24: =O23/O9 -> 0.17506534 | R24: =R23/R9 -> 0.13892634 | S24: =S23/S9 -> 0.13816744 | T24: =T23/T9 -> 0.17857685 | U24: =U23/U9 -> 0.1750412 | V24: =V23/V9 -> 0.16810162 | W24: =W23/W9 -> 0.16577307 | X24: =X23/X9 -> 0.1990525 | Y24: =Y23/Y9 -> 0.15750533 | ... AQ24: =AQ23/AQ9 -> 0.2176943
B26: Impairments & other charges | G26: =OFFSET(R26,0,MATCH($G$2,$R$3:$AW$3,0)-1)*4 -> 0 | H26: =SUM(OFFSET(R26,0,MATCH($G$2,$R$3:$AW$3,0)-4),OFFSET(R26,0,MATCH($G$2,$R$3:$AW$3,0)-3),OFFSET(R26,0,MATCH($G$2,$R$3:$AW$3,0)-2),OFFSET(R26,0,MATCH($G$2,$R$3:$AW$3,0)-1)) -> 0 | J26: =SUM(R26:U26) -> -87.81 | K26: =SUM(V26:Y26) -> -35.525 | L26: =SUM(Z26:AC26) -> -561.274 | M26: =SUM(AD26:AG26) -> -340.713 | N26: =SUM(AH26:AK26) -> 0 | O26: =SUM(AL26:AO26) -> 0 | R26: 0 | S26: 0 | T26: 0 | U26: =-82.705-2.702-2.403 -> -87.81 | V26: 0 | W26: 0 | X26: 0 | Y26: -35.525 | Z26: -561.274 | AA26: 0 | AB26: 0 | AC26: 0 | AD26: 0 | AE26: 0 | AF26: -340.713 | AG26: 0 | AH26: 0 | AI26: 0 | AJ26: 0 | AK26: 0 | AL26: 0 | AM26: 0 | AN26: 0 | AO26: 0 | AP26: 0 | AQ26: 0
B27: Gains on disposals | G27: =OFFSET(R27,0,MATCH($G$2,$R$3:$AW$3,0)-1)*4 -> 2.06 | H27: =SUM(OFFSET(R27,0,MATCH($G$2,$R$3:$AW$3,0)-4),OFFSET(R27,0,MATCH($G$2,$R$3:$AW$3,0)-3),OFFSET(R27,0,MATCH($G$2,$R$3:$AW$3,0)-2),OFFSET(R27,0,MATCH($G$2,$R$3:$AW$3,0)-1)) -> 2.896 | J27: =SUM(R27:U27) -> 1.968 | K27: =SUM(V27:Y27) -> 8.152 | L27: =SUM(Z27:AC27) -> 0.118 | M27: =SUM(AD27:AG27) -> 5.761 | N27: =SUM(AH27:AK27) -> 8.279 | O27: =SUM(AL27:AO27) -> 5.009 | R27: 1.898 | S27: 0.442 | T27: 0.018 | U27: -0.39 | V27: 2.157 | W27: 3.118 | X27: -0.374 | Y27: 3.251 | Z27: 0.492 | AA27: -0.189 | AB27: -0.316 | AC27: 0.131 | AD27: 2.133 | AE27: 2.119 | AF27: 0.83 | AG27: 0.679 | AH27: 4.849 | AI27: 2.745 | AJ27: 0.377 | AK27: 0.308 | AL27: 2.23 | AM27: 0.472 | AN27: 1.528 | AO27: 0.779 | AP27: 0.074 | AQ27: 0.515
B28: Other Income/Expenses Net | G28: =OFFSET(R28,0,MATCH($G$2,$R$3:$AW$3,0)-1)*4 -> 12.352 | H28: =SUM(OFFSET(R28,0,MATCH($G$2,$R$3:$AW$3,0)-4),OFFSET(R28,0,MATCH($G$2,$R$3:$AW$3,0)-3),OFFSET(R28,0,MATCH($G$2,$R$3:$AW$3,0)-2),OFFSET(R28,0,MATCH($G$2,$R$3:$AW$3,0)-1)) -> 9.691 | J28: =SUM(R28:U28) -> 5.726 | K28: =SUM(V28:Y28) -> 3.787 | L28: =SUM(Z28:AC28) -> 8.147 | M28: =SUM(AD28:AG28) -> 10.001 | N28: =SUM(AH28:AK28) -> 16.686 | O28: =SUM(AL28:AO28) -> 11.041 | R28: 1.591 | S28: 1.541 | T28: 1.454 | U28: 1.14 | V28: -0.568 | W28: 2.381 | X28: 0.864 | Y28: 1.11 | Z28: 2.723 | AA28: 2.29 | AB28: 1.172 | AC28: 1.962 | AD28: 3.791 | AE28: 2.523 | AF28: 1.832 | AG28: 1.855 | AH28: 4.308 | AI28: 3.749 | AJ28: 3.805 | AK28: 4.824 | AL28: 6.443 | AM28: 1.264 | AN28: 1.589 | AO28: 1.745 | AP28: 3.269 | AQ28: 3.088
B29: Other EBIT Components | G29: =SUM(G26:G28) -> 14.412 | H29: =SUM(H26:H28) -> 12.587 | J29: =SUM(J26:J28) -> -80.116 | K29: =SUM(K26:K28) -> -23.586 | L29: =SUM(L26:L28) -> -553.009 | M29: =SUM(M26:M28) -> -324.951 | N29: =SUM(N26:N28) -> 24.965 | O29: =SUM(O26:O28) -> 16.05 | R29: =SUM(R26:R28) -> 3.489 | S29: =SUM(S26:S28) -> 1.983 | T29: =SUM(T26:T28) -> 1.472 | U29: =SUM(U26:U28) -> -87.06 | V29: =SUM(V26:V28) -> 1.589 | W29: =SUM(W26:W28) -> 5.499 | X29: =SUM(X26:X28) -> 0.49 | Y29: =SUM(Y26:Y28) -> -31.164 | ... AQ29: =SUM(AQ26:AQ28) -> 3.603
B30: As Reported Core EBIT | G30: =G20 -> 479.932 | H30: =H20 -> 405.467 | J30: =J20 -> 241.131 | K30: =K20 -> 269.4 | L30: =L20 -> 140.394 | M30: =M20 -> 76.819 | N30: =N20 -> 185.907 | O30: =O20 -> 330.083 | R30: =R20 -> 48.822 | S30: =S20 -> 55.411 | T30: =T20 -> 67.939 | U30: =U20 -> 68.959 | V30: =V20 -> 69.949 | W30: =W20 -> 72.725 | X30: =X20 -> 78.275 | Y30: =Y20 -> 48.451 | ... AQ30: =AQ20 -> 119.983
B31: Total EBIT | G31: =SUM(G29:G30) -> 494.344 | H31: =SUM(H29:H30) -> 418.054 | J31: =SUM(J29:J30) -> 161.015 | K31: =SUM(K29:K30) -> 245.814 | L31: =SUM(L29:L30) -> -412.615 | M31: =SUM(M29:M30) -> -248.132 | N31: =SUM(N29:N30) -> 210.872 | O31: =SUM(O29:O30) -> 346.133 | R31: =SUM(R29:R30) -> 52.311 | S31: =SUM(S29:S30) -> 57.394 | T31: =SUM(T29:T30) -> 69.411 | U31: =SUM(U29:U30) -> -18.101 | V31: =SUM(V29:V30) -> 71.538 | W31: =SUM(W29:W30) -> 78.224 | X31: =SUM(X29:X30) -> 78.765 | Y31: =SUM(Y29:Y30) -> 17.287 | ... AQ31: =SUM(AQ29:AQ30) -> 123.586
C32: % Margin | G32: =G31/G9 -> 0.14991206 | H32: =H31/H9 -> 0.13079065 | J32: =J31/J9 -> 0.054201085 | K32: =K31/K9 -> 0.086603046 | L32: =L31/L9 -> -0.19002187 | M32: =M31/M9 -> -0.11044484 | N32: =N31/N9 -> 0.075723744 | O32: =O31/O9 -> 0.11195773 | R32: =R31/R9 -> 0.070529657 | S32: =S31/S9 -> 0.071503767 | T32: =T31/T9 -> 0.09847697 | U32: =U31/U9 -> -0.025088254 | V32: =V31/V9 -> 0.096073036 | W32: =W31/W9 -> 0.10145232 | X32: =X31/X9 -> 0.11812228 | Y32: =Y31/Y9 -> 0.026355067 | ... AQ32: =AQ31/AQ9 -> 0.14991206
B34: Interest expense, net | G34: =OFFSET(R34,0,MATCH($G$2,$R$3:$AW$3,0)-1)*4 -> -51.276 | H34: =SUM(OFFSET(R34,0,MATCH($G$2,$R$3:$AW$3,0)-4),OFFSET(R34,0,MATCH($G$2,$R$3:$AW$3,0)-3),OFFSET(R34,0,MATCH($G$2,$R$3:$AW$3,0)-2),OFFSET(R34,0,MATCH($G$2,$R$3:$AW$3,0)-1)) -> -52.471 | J34: =SUM(R34:U34) -> -46.856 | K34: =SUM(V34:Y34) -> -55.994 | L34: =SUM(Z34:AC34) -> -48.739 | M34: =SUM(AD34:AG34) -> -42.469 | N34: =SUM(AH34:AK34) -> -44.597 | O34: =SUM(AL34:AO34) -> -52.008 | R34: -9.78 | S34: -12.54 | T34: -12.345 | U34: -12.191 | V34: -13.201 | W34: -15.515 | X34: -14.31 | Y34: -12.968 | Z34: -12.799 | AA34: -12.708 | AB34: -11.809 | AC34: -11.423 | AD34: -10.966 | AE34: -10.706 | AF34: -10.5 | AG34: -10.297 | AH34: -10.203 | AI34: -10.649 | AJ34: -11.755 | AK34: -11.99 | AL34: -13.221 | AM34: -12.286 | AN34: -13.386 | AO34: -13.115 | AP34: -13.151 | AQ34: -12.819
B36: PBT | G36: =G31+G34 -> 443.068 | H36: =H31+H34 -> 365.583 | J36: =J31+J34 -> 114.159 | K36: =K31+K34 -> 189.82 | L36: =L31+L34 -> -461.354 | M36: =M31+M34 -> -290.601 | N36: =N31+N34 -> 166.275 | O36: =O31+O34 -> 294.125 | R36: =R31+R34 -> 42.531 | S36: =S31+S34 -> 44.854 | T36: =T31+T34 -> 57.066 | U36: =U31+U34 -> -30.292 | V36: =V31+V34 -> 58.337 | W36: =W31+W34 -> 62.709 | X36: =X31+X34 -> 64.455 | Y36: =Y31+Y34 -> 4.319 | ... AQ36: =AQ31+AQ34 -> 110.767
B37: (-) Taxes | G37: =OFFSET(R37,0,MATCH($G$2,$R$3:$AW$3,0)-1)*4 -> -107.14 | H37: =SUM(OFFSET(R37,0,MATCH($G$2,$R$3:$AW$3,0)-4),OFFSET(R37,0,MATCH($G$2,$R$3:$AW$3,0)-3),OFFSET(R37,0,MATCH($G$2,$R$3:$AW$3,0)-2),OFFSET(R37,0,MATCH($G$2,$R$3:$AW$3,0)-1)) -> -86.72 | J37: =SUM(R37:U37) -> -35.081 | K37: =SUM(V37:Y37) -> -46.801 | L37: =SUM(Z37:AC37) -> 189.759 | M37: =SUM(AD37:AG37) -> 43.83 | N37: =SUM(AH37:AK37) -> -43.414 | O37: =SUM(AL37:AO37) -> -71.22 | R37: -9.865 | S37: -16.061 | T37: -15.116 | U37: 5.961 | V37: -13.88 | W37: -15.269 | X37: -16.305 | Y37: -1.347 | Z37: 172.809 | AA37: 1.429 | AB37: 8.419 | AC37: 7.102 | AD37: 0.891 | AE37: -5.493 | AF37: 60.442 | AG37: -12.01 | AH37: -6.213 | AI37: -11.03 | AJ37: -11.713 | AK37: -14.458 | AL37: -14.051 | AM37: -18.96 | AN37: -18.722 | AO37: -19.487 | AP37: -21.726 | AQ37: -26.785
B38: Net Income | G38: =SUM(G36:G37) -> 335.928 | H38: =SUM(H36:H37) -> 278.863 | J38: =SUM(J36:J37) -> 79.078 | K38: =SUM(K36:K37) -> 143.019 | L38: =SUM(L36:L37) -> -271.595 | M38: =SUM(M36:M37) -> -246.771 | N38: =SUM(N36:N37) -> 122.861 | O38: =SUM(O36:O37) -> 222.905 | R38: =SUM(R36:R37) -> 32.666 | S38: =SUM(S36:S37) -> 28.793 | T38: =SUM(T36:T37) -> 41.95 | U38: =SUM(U36:U37) -> -24.331 | V38: =SUM(V36:V37) -> 44.457 | W38: =SUM(W36:W37) -> 47.44 | X38: =SUM(X36:X37) -> 48.15 | Y38: =SUM(Y36:Y37) -> 2.972 | ... AQ38: =SUM(AQ36:AQ37) -> 83.982
B39: (-) NCI | G39: =OFFSET(R39,0,MATCH($G$2,$R$3:$AW$3,0)-1)*4 -> -0.512 | H39: =SUM(OFFSET(R39,0,MATCH($G$2,$R$3:$AW$3,0)-4),OFFSET(R39,0,MATCH($G$2,$R$3:$AW$3,0)-3),OFFSET(R39,0,MATCH($G$2,$R$3:$AW$3,0)-2),OFFSET(R39,0,MATCH($G$2,$R$3:$AW$3,0)-1)) -> -0.431 | J39: =SUM(R39:U39) -> -0.626 | K39: =SUM(V39:Y39) -> -0.672 | L39: =SUM(Z39:AC39) -> -0.954 | M39: =SUM(AD39:AG39) -> -0.183 | N39: =SUM(AH39:AK39) -> -0.4709 | O39: =SUM(AL39:AO39) -> -0.33 | R39: -0.195 | S39: -0.191 | T39: -0.134 | U39: -0.106 | V39: -0.161 | W39: -0.153 | X39: -0.163 | Y39: -0.195 | Z39: -0.278 | AA39: -0.261 | AB39: -0.204 | AC39: -0.211 | AD39: -0.255 | AE39: -0.162 | AF39: 0.422 | AG39: -0.188 | AH39: -0.152 | AI39: -0.1499 | AJ39: -0.153 | AK39: -0.016 | AL39: 0.077 | AM39: 0.049 | AN39: -0.4 | AO39: -0.056 | AP39: 0.153 | AQ39: -0.128
B40: Net Income to Shareholders | G40: =SUM(G38:G39) -> 335.416 | H40: =SUM(H38:H39) -> 278.432 | J40: =SUM(J38:J39) -> 78.452 | K40: =SUM(K38:K39) -> 142.347 | L40: =SUM(L38:L39) -> -272.549 | M40: =SUM(M38:M39) -> -246.954 | N40: =SUM(N38:N39) -> 122.3901 | O40: =SUM(O38:O39) -> 222.575 | R40: =SUM(R38:R39) -> 32.471 | S40: =SUM(S38:S39) -> 28.602 | T40: =SUM(T38:T39) -> 41.816 | U40: =SUM(U38:U39) -> -24.437 | V40: =SUM(V38:V39) -> 44.296 | W40: =SUM(W38:W39) -> 47.287 | X40: =SUM(X38:X39) -> 47.987 | Y40: =SUM(Y38:Y39) -> 2.777 | ... AQ40: =SUM(AQ38:AQ39) -> 83.854
B42: Diluted Shares Outstanding | G42: =OFFSET(R42,0,MATCH($G$2,$R$3:$AW$3,0)-1) -> 58.639161 | H42: =AVERAGE(OFFSET(R42,0,MATCH($G$2,$R$3:$AW$3,0)-4),OFFSET(R42,0,MATCH($G$2,$R$3:$AW$3,0)-3),OFFSET(R42,0,MATCH($G$2,$R$3:$AW$3,0)-2),OFFSET(R42,0,MATCH($G$2,$R$3:$AW$3,0)-1)) -> 59.13929 | J42: 59.689 | K42: 59.75 | L42: 59.912 | M42: 60.053 | N42: 60.329 | O42: 59.857 | R42: 59.493 | S42: 59.72 | T42: 59.784 | U42: 59.645 | V42: 59.823 | W42: 59.907 | X42: 59.906 | Y42: 59.998 | Z42: 59.883 | AA42: 59.937 | AB42: 59.931 | AC42: 59.975 | AD42: 60.016 | AE42: 60.274 | AF42: 60.062 | AG42: 60.311 | AH42: 60.463 | AI42: 60.467 | AJ42: 60.182 | AK42: 60.211 | AL42: 60.272 | AM42: 60.085 | AN42: 59.764 | AO42: 59.335 | AP42: 58.819 | AQ42: 58.639161
B43: Fully Diluted EPS | G43: =OFFSET(R43,0,MATCH($G$2,$R$3:$AW$3,0)-1)*4 -> 5.72 | H43: =SUM(OFFSET(R43,0,MATCH($G$2,$R$3:$AW$3,0)-4),OFFSET(R43,0,MATCH($G$2,$R$3:$AW$3,0)-3),OFFSET(R43,0,MATCH($G$2,$R$3:$AW$3,0)-2),OFFSET(R43,0,MATCH($G$2,$R$3:$AW$3,0)-1)) -> 4.7120982 | J43: =J40/J42 -> 1.314346 | K43: =K40/K42 -> 2.3823766 | L43: =L40/L42 -> -4.5491554 | M43: =M40/M42 -> -4.1122675 | N43: =N40/N42 -> 2.0287109 | O43: =O40/O42 -> 3.7184456 | R43: =R40/R42 -> 0.5457953 | S43: =S40/S42 -> 0.47893503 | T43: =T40/T42 -> 0.69945136 | U43: =U40/U42 -> -0.40970744 | V43: =V40/V42 -> 0.740451 | W43: =W40/W42 -> 0.78934014 | X43: =X40/X42 -> 0.80103829 | Y43: =Y40/Y42 -> 0.046284876 | ... AQ43: =AQ40/AQ42 -> 1.43
A46: x | B46: Balance Sheet
B48: Cash and cash equivalents | G48: =OFFSET(R48,0,MATCH($G$2,$R$3:$AW$3,0)-1) -> 53.54 | H48: =G48 -> 53.54 | J48: =U48 -> 7.8 | K48: =Y48 -> 24.737 | L48: =AC48 -> 80.338 | M48: =AG48 -> 34.813 | N48: =AK48 -> 80.577 | O48: =AO48 -> 32.577 | R48: 7.01 | S48: 4.198 | T48: 3.617 | U48: 7.8 | V48: 7.289 | W48: 22.521 | X48: 9.425 | Y48: 24.737 | Z48: 322.571 | AA48: 108.471 | AB48: 119.586 | AC48: 80.338 | AD48: 52.333 | AE48: 53.052 | AF48: 54.377 | AG48: 34.813 | AH48: 32.398 | AI48: 25.104 | AJ48: 36.991 | AK48: 80.577 | AL48: 26.699 | AM48: 36.603 | AN48: 42.116 | AO48: 32.577 | AP48: 75.216 | AQ48: 53.54
B49: Trade Receivables | G49: =OFFSET(R49,0,MATCH($G$2,$R$3:$AW$3,0)-1) -> 550.159 | H49: =G49 -> 550.159 | J49: =U49 -> 417.644 | K49: =Y49 -> 379.174 | L49: =AC49 -> 315.283 | M49: =AG49 -> 417.958 | N49: =AK49 -> 483.406 | O49: =AO49 -> 526.691 | R49: 485.865 | S49: 448.281 | T49: 400.87 | U49: 417.644 | V49: 439.975 | W49: 450.958 | X49: 382.465 | Y49: 379.174 | Z49: 389.616 | AA49: 348.453 | AB49: 304.021 | AC49: 315.283 | AD49: 347.275 | AE49: 352.372 | AF49: 389.579 | AG49: 417.958 | AH49: 420.823 | AI49: 445.425 | AJ49: 482.744 | AK49: 483.406 | AL49: 526.489 | AM49: 519.741 | AN49: 514.631 | AO49: 526.691 | AP49: 529.141 | AQ49: 550.159
B50: Other Receivables | G50: =OFFSET(R50,0,MATCH($G$2,$R$3:$AW$3,0)-1) -> 47.666 | H50: =G50 -> 47.666 | J50: =U50 -> 104.239 | K50: =Y50 -> 104.175 | L50: =AC50 -> 284.899 | M50: =AG50 -> 149.964 | N50: =AK50 -> 114.556 | O50: =AO50 -> 52.025 | R50: 110.64 | S50: 116.673 | T50: 111.221 | U50: 104.239 | V50: 122.18 | W50: 99.568 | X50: 99.736 | Y50: 104.175 | Z50: 253.688 | AA50: 228.409 | AB50: 257.656 | AC50: 284.899 | AD50: 171.749 | AE50: 165.478 | AF50: 150.811 | AG50: 149.964 | AH50: 125.757 | AI50: 127.181 | AJ50: 133.278 | AK50: 114.556 | AL50: 109.539 | AM50: 40.011 | AN50: 53.936 | AO50: 52.025 | AP50: 55.949 | AQ50: 47.666
B51: Inventory | G51: =OFFSET(R51,0,MATCH($G$2,$R$3:$AW$3,0)-1) -> 445.304 | H51: =G51 -> 445.304 | J51: =U51 -> 507.441 | K51: =Y51 -> 351.401 | L51: =AC51 -> 309.675 | M51: =AG51 -> 331.35 | N51: =AK51 -> 461.848 | O51: =AO51 -> 454.389 | R51: 372.182 | S51: 384.007 | T51: 453.173 | U51: 507.441 | V51: 491.566 | W51: 428.26 | X51: 410.261 | Y51: 351.401 | Z51: 341.498 | AA51: 335.958 | AB51: 321.433 | AC51: 309.675 | AD51: 326.475 | AE51: 325.545 | AF51: 308.82 | AG51: 331.35 | AH51: 360.457 | AI51: 370.385 | AJ51: 392.47 | AK51: 461.848 | AL51: 475.218 | AM51: 504.514 | AN51: 505.506 | AO51: 454.389 | AP51: 446.803 | AQ51: 445.304
...

Sheet BBPTACShadowWks0002
K2: ='Marine DCF'!K2 -> 0 | L2: ='Marine DCF'!L2 -> 1 | M2: ='Marine DCF'!M2 -> 2 | N2: ='Marine DCF'!N2 -> 3 | O2: ='Marine DCF'!O2 -> 4 | P2: ='Marine DCF'!P2 -> 5 | Q2: ='Marine DCF'!Q2 -> 6 | R2: ='Marine DCF'!R2 -> 7
E3: ='Marine DCF'!E3 -> 2018 | F3: ='Marine DCF'!F3 -> 2019 | G3: ='Marine DCF'!G3 -> 2020 | H3: ='Marine DCF'!H3 -> 2021 | I3: ='Marine DCF'!I3 -> 2022 | J3: ='Marine DCF'!J3 -> 2023 | K3: ='Marine DCF'!K3 -> 2024 | L3: ='Marine DCF'!L3 -> 2025 | ... Q3: ='Marine DCF'!Q3 -> 2030
E4: ='Marine DCF'!E4 -> 14501 | F4: ='Marine DCF'!F4 -> 14611 | G4: ='Marine DCF'!G4 -> 13006 | H4: ='Marine DCF'!H4 -> 13696 | I4: ='Marine DCF'!I4 -> 13775 | J4: ='Marine DCF'!J4 -> 13571 | K4: ='Marine DCF'!K4 -> 13320 | L4: ='Marine DCF'!L4 -> 13586.4 | ... R4: ='Marine DCF'!R4 -> 15000.483
F5: ='Marine DCF'!F5 -> 0.0075856837 | G5: ='Marine DCF'!G5 -> -0.10984874 | H5: ='Marine DCF'!H5 -> 0.053052437 | I5: ='Marine DCF'!I5 -> 0.0057681075 | J5: ='Marine DCF'!J5 -> -0.014809437 | K5: ='Marine DCF'!K5 -> 0.02 | L5: ='Marine DCF'!L5 -> 0.02 | M5: ='Marine DCF'!M5 -> 0.02 | ... Q5: ='Marine DCF'!Q5 -> 0.02
E6: ='Marine DCF'!E6 -> 7.7083856 | F6: ='Marine DCF'!F6 -> 8.368818 | G6: ='Marine DCF'!G6 -> 8.4279871 | H6: ='Marine DCF'!H6 -> 7.3369451 | I6: ='Marine DCF'!I6 -> 9.2789982 | J6: ='Marine DCF'!J6 -> 10.440181 | K6: ='Marine DCF'!K6 -> 11.8 | L6: ='Marine DCF'!L6 -> 12.626 | ... R6: ='Marine DCF'!R6 -> 14.20122
F7: ='Marine DCF'!F7 -> 0.085677134 | G7: ='Marine DCF'!G7 -> 0.0070701823 | H7: ='Marine DCF'!H7 -> -0.12945463 | I7: ='Marine DCF'!I7 -> 0.26469506 | J7: ='Marine DCF'!J7 -> 0.125141 | K7: ='Marine DCF'!K7 -> 0.07 | L7: ='Marine DCF'!L7 -> 0.07 | M7: ='Marine DCF'!M7 -> 0.05 | ... Q7: ='Marine DCF'!Q7 -> 0
E8: ='Marine DCF'!$E$8 -> 1117.793 | F8: ='Marine DCF'!F8 -> 1222.768 | G8: ='Marine DCF'!G8 -> 1096.144 | H8: ='Marine DCF'!H8 -> 1004.868 | I8: ='Marine DCF'!I8 -> 1278.182 | J8: ='Marine DCF'!J8 -> 1416.837 | K8: ='Marine DCF'!K8 -> 1571.76 | L8: ='Marine DCF'!L8 -> 1715.4189 | M8: ='Marine DCF'!M8 -> 1837.2136 | ... R8: ='Marine DCF'!R8 -> 2130.2516
F9: ='Marine DCF'!F9 -> 0.093912737 | G9: ='Marine DCF'!G9 -> -0.10355521 | H9: ='Marine DCF'!H9 -> -0.083270081 | I9: ='Marine DCF'!I9 -> 0.27198995 | J9: ='Marine DCF'!J9 -> 0.10847829 | K9: ='Marine DCF'!K9 -> 0.10934426 | L9: ='Marine DCF'!L9 -> 0.0914 | M9: ='Marine DCF'!M9 -> 0.071 | ... R9: ='Marine DCF'!R9 -> 0
E10: ='Marine DCF'!E10 -> 365.35 | F10: ='Marine DCF'!F10 -> 364.314 | G10: ='Marine DCF'!G10 -> 308.121 | H10: ='Marine DCF'!H10 -> 318.05 | I10: ='Marine DCF'!I10 -> 338.785 | J10: ='Marine DCF'!J10 -> 305.1 | K10: ='Marine DCF'!K10 -> 367.472 | L10: ='Marine DCF'!L10 -> 367.472 | ... R10: ='Marine DCF'!R10 -> 350
F11: ='Marine DCF'!F11 -> -0.0028356371 | G11: ='Marine DCF'!G11 -> -0.15424332 | H11: ='Marine DCF'!H11 -> 0.032224353 | I11: ='Marine DCF'!I11 -> 0.065194152 | J11: ='Marine DCF'!J11 -> -0.099428841 | K11: ='Marine DCF'!K11 -> 0.04 | L11: ='Marine DCF'!L11 -> 0 | M11: ='Marine DCF'!M11 -> 0 | ... R11: ='Marine DCF'!R11 -> -0.04754648
E12: ='Marine DCF'!E12 -> 1483.143 | F12: ='Marine DCF'!F12 -> 1587.082 | G12: ='Marine DCF'!G12 -> 1404.265 | H12: ='Marine DCF'!H12 -> 1322.918 | I12: ='Marine DCF'!I12 -> 1616.967 | J12: ='Marine DCF'!J12 -> 1721.937 | K12: ='Marine DCF'!K12 -> 1939.232 | L12: ='Marine DCF'!L12 -> 2082.8909 | ... R12: ='Marine DCF'!R12 -> 2480.2516
E14: ='Marine DCF'!E14 -> 147.416 | F14: ='Marine DCF'!F14 -> 215.842 | G14: ='Marine DCF'!G14 -> 163.656 | H14: ='Marine DCF'!H14 -> 63.015 | I14: ='Marine DCF'!I14 -> 136.184 | J14: ='Marine DCF'!J14 -> 238.94 | K14: ='Marine DCF'!K14 -> 379.504 | L14: ='Marine DCF'!L14 -> 374.92036 | ... R14: ='Marine DCF'!R14 -> 322.43271
E15: ='Marine DCF'!E15 -> 0.099394327 | F15: ='Marine DCF'!F15 -> 0.13599927 | G15: ='Marine DCF'!G15 -> 0.11654211 | H15: ='Marine DCF'!H15 -> 0.047633338 | I15: ='Marine DCF'!I15 -> 0.08422188 | J15: ='Marine DCF'!J15 -> 0.13876234 | K15: ='Marine DCF'!K15 -> 0.19569809 | L15: ='Marine DCF'!L15 -> 0.18 | ... R15: ='Marine DCF'!R15 -> 0.13
E16: ='Marine DCF'!E16 -> 182.307 | F16: ='Marine DCF'!F16 -> 179.742 | G16: ='Marine DCF'!G16 -> 186.798 | H16: ='Marine DCF'!H16 -> 185.979 | I16: ='Marine DCF'!I16 -> 177.551 | J16: ='Marine DCF'!J16 -> 184.225 | K16: ='Marine DCF'!K16 -> 196.188 | L16: ='Marine DCF'!L16 -> 206.188 | ... R16: ='Marine DCF'!R16 -> 256.188
F17: ='Marine DCF'!F17 -> -2.565 | G17: ='Marine DCF'!G17 -> 7.056 | H17: ='Marine DCF'!H17 -> -0.819 | I17: ='Marine DCF'!I17 -> -8.428 | J17: ='Marine DCF'!J17 -> 6.674 | K17: ='Marine DCF'!K17 -> 11.963 | L17: ='Marine DCF'!L17 -> 10 | M17: ='Marine DCF'!M17 -> 10 | ... Q17: ='Marine DCF'!Q17 -> 10
E18: ='Marine DCF'!E18 -> 329.723 | F18: ='Marine DCF'!F18 -> 395.584 | G18: ='Marine DCF'!G18 -> 350.454 | H18: ='Marine DCF'!H18 -> 248.994 | I18: ='Marine DCF'!I18 -> 313.735 | J18: ='Marine DCF'!J18 -> 423.165 | K18: ='Marine DCF'!K18 -> 575.692 | L18: ='Marine DCF'!L18 -> 581.10836 | ... R18: ='Marine DCF'!R18 -> 578.62071
E19: ='Marine DCF'!E19 -> 0 | F19: ='Marine DCF'!F19 -> 0 | G19: ='Marine DCF'!G19 -> 0 | H19: ='Marine DCF'!H19 -> 0 | I19: ='Marine DCF'!I19 -> 0 | J19: ='Marine DCF'!J19 -> 0 | K19: ='Marine DCF'!K19 -> 0 | L19: ='Marine DCF'!L19 -> 0 | ... R19: ='Marine DCF'!R19 -> -57.862071 | S19: ='Marine DCF'!$S$19 -> 0.1
E20: ='Marine DCF'!E20 -> -150 | F20: ='Marine DCF'!F20 -> -150 | G20: ='Marine DCF'!G20 -> -150 | H20: ='Marine DCF'!H20 -> -150 | I20: ='Marine DCF'!I20 -> -150 | J20: ='Marine DCF'!J20 -> -240 | K20: ='Marine DCF'!K20 -> -240 | L20: ='Marine DCF'!L20 -> -240 | ... R20: ='Marine DCF'!R20 -> -150
E21: ='Marine DCF'!E21 -> 179.723 | F21: ='Marine DCF'!F21 -> 245.584 | G21: ='Marine DCF'!G21 -> 200.454 | H21: ='Marine DCF'!H21 -> 98.994 | I21: ='Marine DCF'!I21 -> 163.735 | J21: ='Marine DCF'!J21 -> 183.165 | K21: ='Marine DCF'!K21 -> 335.692 | L21: ='Marine DCF'!L21 -> 341.10836 | ... R21: ='Marine DCF'!R21 -> 370.75864
E22: ='Marine DCF'!E22 -> 0.54507268 | F22: ='Marine DCF'!F22 -> 0.62081378 | G22: ='Marine DCF'!G22 -> 0.57198377 | H22: ='Marine DCF'!H22 -> 0.39757585 | I22: ='Marine DCF'!I22 -> 0.52188949 | J22: ='Marine DCF'!J22 -> 0.43284534 | K22: ='Marine DCF'!K22 -> 0.58311041 | L22: ='Marine DCF'!L22 -> 0.58699613 | ... R22: ='Marine DCF'!R22 -> 0.64076282
K24: ='Marine DCF'!K24 -> 1 | L24: ='Marine DCF'!L24 -> 0.92592593 | M24: ='Marine DCF'!M24 -> 0.85733882 | N24: ='Marine DCF'!N24 -> 0.79383224 | O24: ='Marine DCF'!O24 -> 0.73502985 | P24: ='Marine DCF'!P24 -> 0.6805832 | Q24: ='Marine DCF'!Q24 -> 0.63016963 | R24: ='Marine DCF'!R24 -> 0.5834904 | S24: ='Marine DCF'!S24 -> 0.08
K26: ='Marine DCF'!K25 -> 335.692 | L26: ='Marine DCF'!L25 -> 315.84107 | M26: ='Marine DCF'!M25 -> 373.00949 | N26: ='Marine DCF'!N25 -> 333.8216 | O26: ='Marine DCF'!O25 -> 328.75666 | P26: ='Marine DCF'!P25 -> 315.54622 | Q26: ='Marine DCF'!Q25 -> 302.5819 | R26: ='Marine DCF'!R25 -> 3894.0139 | S26: ='Marine DCF'!S26 -> 0.02
E28: ='Marine DCF'!E27 -> 6199.2628
E29: ='Marine DCF'!#REF! -> #REF!
E30: ='Marine DCF'!E28 -> 0.054150309

Sheet Marine DCF
A2: x | B2: Marine Transport DCF | K2: 0 | L2: =K2+1 -> 1 | M2: =L2+1 -> 2 | N2: =M2+1 -> 3 | O2: =N2+1 -> 4 | P2: =O2+1 -> 5 | Q2: =P2+1 -> 6 | R2: =Q2+1 -> 7
E3: 2018 | F3: =E3+1 -> 2019 | G3: =F3+1 -> 2020 | H3: =G3+1 -> 2021 | I3: =H3+1 -> 2022 | J3: =I3+1 -> 2023 | K3: =J3+1 -> 2024 | L3: =K3+1 -> 2025 | M3: =L3+1 -> 2026 | ... Q3: =P3+1 -> 2030 | R3: LT Normalized
B4: Ton Miles | E4: ='Model Shell'!J112 -> 14501 | F4: ='Model Shell'!K112 -> 14611 | G4: ='Model Shell'!L112 -> 13006 | H4: ='Model Shell'!M112 -> 13696 | I4: ='Model Shell'!N112 -> 13775 | J4: ='Model Shell'!O112 -> 13571 | K4: ='Model Shell'!G112 -> 13320 | L4: =K4*(1+L5) -> 13586.4 | M4: =L4*(1+M5) -> 13858.128 | N4: =M4*(1+N5) -> 14135.291 | O4: =N4*(1+O5) -> 14417.996 | P4: =O4*(1+P5) -> 14706.356 | Q4: =P4*(1+Q5) -> 15000.483 | R4: =Q4 -> 15000.483
C5: % Growth | F5: =F4/E4-1 -> 0.0075856837 | G5: =G4/F4-1 -> -0.10984874 | H5: =H4/G4-1 -> 0.053052437 | I5: =I4/H4-1 -> 0.0057681075 | J5: =J4/I4-1 -> -0.014809437 | K5: 0.02 | L5: 0.02 | M5: 0.02 | N5: 0.02 | O5: 0.02 | P5: 0.02 | Q5: 0.02
B6: Pricing | E6: ='Model Shell'!J113 -> 7.7083856 | F6: ='Model Shell'!K113 -> 8.368818 | G6: ='Model Shell'!L113 -> 8.4279871 | H6: ='Model Shell'!M113 -> 7.3369451 | I6: ='Model Shell'!N113 -> 9.2789982 | J6: ='Model Shell'!O113 -> 10.440181 | K6: ='Model Shell'!G113 -> 11.8 | L6: =K6*(1+L7) -> 12.626 | M6: =L6*(1+M7) -> 13.2573 | N6: =M6*(1+N7) -> 13.787592 | O6: =N6*(1+O7) -> 14.20122 | P6: =O6*(1+P7) -> 14.20122 | Q6: =P6*(1+Q7) -> 14.20122 | R6: =Q6 -> 14.20122
C7: % Growth | F7: =F6/E6-1 -> 0.085677134 | G7: =G6/F6-1 -> 0.0070701823 | H7: =H6/G6-1 -> -0.12945463 | I7: =I6/H6-1 -> 0.26469506 | J7: =J6/I6-1 -> 0.125141 | K7: 0.07 | L7: 0.07 | M7: 0.05 | N7: 0.04 | O7: 0.03 | P7: 0 | Q7: 0
B8: Inland Revenue | E8: =E6*E4/100 -> 1117.793 | F8: =F6*F4/100 -> 1222.768 | G8: =G6*G4/100 -> 1096.144 | H8: =H6*H4/100 -> 1004.868 | I8: =I6*I4/100 -> 1278.182 | J8: =J6*J4/100 -> 1416.837 | K8: =K6*K4/100 -> 1571.76 | L8: =L6*L4/100 -> 1715.4189 | ... R8: =R6*R4/100 -> 2130.2516
F9: =F8/E8-1 -> 0.093912737 | G9: =G8/F8-1 -> -0.10355521 | H9: =H8/G8-1 -> -0.083270081 | I9: =I8/H8-1 -> 0.27198995 | J9: =J8/I8-1 -> 0.10847829 | K9: =K8/J8-1 -> 0.10934426 | L9: =L8/K8-1 -> 0.0914 | M9: =M8/L8-1 -> 0.071 | ... R9: =R8/Q8-1 -> 0
B10: (+) Coastal Revenue | E10: ='Model Shell'!J115 -> 365.35 | F10: ='Model Shell'!K115 -> 364.314 | G10: ='Model Shell'!L115 -> 308.121 | H10: ='Model Shell'!M115 -> 318.05 | I10: ='Model Shell'!N115 -> 338.785 | J10: ='Model Shell'!O115 -> 305.1 | K10: ='Model Shell'!G115 -> 367.472 | L10: =K10*(1+L11) -> 367.472 | M10: =L10*(1+M11) -> 367.472 | N10: =M10*(1+N11) -> 367.472 | O10: =N10*(1+O11) -> 367.472 | P10: =O10*(1+P11) -> 367.472 | Q10: =P10*(1+Q11) -> 367.472 | R10: =350 -> 350
C11: % Growth | F11: =F10/E10-1 -> -0.0028356371 | G11: =G10/F10-1 -> -0.15424332 | H11: =H10/G10-1 -> 0.032224353 | I11: =I10/H10-1 -> 0.065194152 | J11: =J10/I10-1 -> -0.099428841 | K11: 0.04 | L11: 0 | M11: 0 | N11: 0 | O11: 0 | P11: 0 | Q11: 0 | R11: =R10/Q10-1 -> -0.04754648
B12: Total Revenue | E12: =E10+E8 -> 1483.143 | F12: =F10+F8 -> 1587.082 | G12: =G10+G8 -> 1404.265 | H12: =H10+H8 -> 1322.918 | I12: =I10+I8 -> 1616.967 | J12: =J10+J8 -> 1721.937 | K12: =K10+K8 -> 1939.232 | L12: =L10+L8 -> 2082.8909 | ... R12: =R10+R8 -> 2480.2516
B14: EBIT | E14: =E12*E15 -> 147.416 | F14: =F12*F15 -> 215.842 | G14: =G12*G15 -> 163.656 | H14: =H12*H15 -> 63.015 | I14: =I12*I15 -> 136.184 | J14: =J12*J15 -> 238.94 | K14: =K12*K15 -> 379.504 | L14: =L12*L15 -> 374.92036 | ... R14: =R12*R15 -> 322.43271
C15: EBIT Margin % | E15: ='Model Shell'!J96/'Model Shell'!J91 -> 0.099394327 | F15: ='Model Shell'!K96/'Model Shell'!K91 -> 0.13599927 | G15: ='Model Shell'!L96/'Model Shell'!L91 -> 0.11654211 | H15: ='Model Shell'!M96/'Model Shell'!M91 -> 0.047633338 | I15: ='Model Shell'!N96/'Model Shell'!N91 -> 0.08422188 | J15: ='Model Shell'!O96/'Model Shell'!O91 -> 0.13876234 | K15: ='Model Shell'!G96/'Model Shell'!G91 -> 0.19569809 | L15: 0.18 | M15: 0.19 | N15: 0.2 | O15: 0.2 | P15: 0.2 | Q15: 0.2 | R15: 0.13
B16: (+) D&A | E16: ='Model Shell'!J97 -> 182.307 | F16: ='Model Shell'!K97 -> 179.742 | G16: ='Model Shell'!L97 -> 186.798 | H16: ='Model Shell'!M97 -> 185.979 | I16: ='Model Shell'!N97 -> 177.551 | J16: ='Model Shell'!O97 -> 184.225 | K16: ='Model Shell'!G97 -> 196.188 | L16: =K16+L17 -> 206.188 | M16: =L16+M17 -> 216.188 | N16: =M16+N17 -> 226.188 | O16: =N16+O17 -> 236.188 | P16: =O16+P17 -> 246.188 | Q16: =P16+Q17 -> 256.188 | R16: =Q16 -> 256.188
C17: Step-up $mm | F17: =F16-E16 -> -2.565 | G17: =G16-F16 -> 7.056 | H17: =H16-G16 -> -0.819 | I17: =I16-H16 -> -8.428 | J17: =J16-I16 -> 6.674 | K17: =K16-J16 -> 11.963 | L17: 10 | M17: 10 | N17: 10 | O17: 10 | P17: 10 | Q17: 10
B18: EBITDA | E18: =E16+E14 -> 329.723 | F18: =F16+F14 -> 395.584 | G18: =G16+G14 -> 350.454 | H18: =H16+H14 -> 248.994 | I18: =I16+I14 -> 313.735 | J18: =J16+J14 -> 423.165 | K18: =K16+K14 -> 575.692 | L18: =L16+L14 -> 581.10836 | ... R18: =R16+R14 -> 578.62071 | S18: Tax on EBITDA
B19: (-) Tax | E19: 0 | F19: 0 | G19: 0 | H19: 0 | I19: 0 | J19: 0 | K19: 0 | L19: 0 | M19: 0 | N19: =N18*(-$S$19) -> -68.946564 | O19: =O18*(-$S$19) -> -71.918867 | P19: =P18*(-$S$19) -> -73.73788 | Q19: =Q18*(-$S$19) -> -75.573272 | R19: =R18*(-$S$19) -> -57.862071 | S19: 0.1
B20: (-) mCAPEX | E20: -150 | F20: -150 | G20: -150 | H20: -150 | I20: -150 | J20: -240 | K20: -240 | L20: -240 | M20: -200 | N20: -200 | O20: -200 | P20: -200 | Q20: -200 | R20: -150
B21: FCFF | E21: =SUM(E18:E20) -> 179.723 | F21: =SUM(F18:F20) -> 245.584 | G21: =SUM(G18:G20) -> 200.454 | H21: =SUM(H18:H20) -> 98.994 | I21: =SUM(I18:I20) -> 163.735 | J21: =SUM(J18:J20) -> 183.165 | K21: =SUM(K18:K20) -> 335.692 | L21: =SUM(L18:L20) -> 341.10836 | ... R21: =SUM(R18:R20) -> 370.75864
C22: Conversion % | E22: =E21/E18 -> 0.54507268 | F22: =F21/F18 -> 0.62081378 | G22: =G21/G18 -> 0.57198377 | H22: =H21/H18 -> 0.39757585 | I22: =I21/I18 -> 0.52188949 | J22: =J21/J18 -> 0.43284534 | K22: =K21/K18 -> 0.58311041 | L22: =L21/L18 -> 0.58699613 | ... R22: =R21/R18 -> 0.64076282
S23: Disc Rate
B24: PV Factor | K24: =1/(1+$S$24)^K2 -> 1 | L24: =1/(1+$S$24)^L2 -> 0.92592593 | M24: =1/(1+$S$24)^M2 -> 0.85733882 | N24: =1/(1+$S$24)^N2 -> 0.79383224 | O24: =1/(1+$S$24)^O2 -> 0.73502985 | P24: =1/(1+$S$24)^P2 -> 0.6805832 | Q24: =1/(1+$S$24)^Q2 -> 0.63016963 | R24: =1/(1+$S$24)^R2 -> 0.5834904 | S24: 0.08
B25: PV | K25: =K21*K24 -> 335.692 | L25: =L21*L24 -> 315.84107 | M25: =M21*M24 -> 373.00949 | N25: =N21*N24 -> 333.8216 | O25: =O21*O24 -> 328.75666 | P25: =P21*P24 -> 315.54622 | Q25: =Q21*Q24 -> 302.5819 | R25: =(R21/(S24-S26))*Q24 -> 3894.0139 | S25: Terminal G
S26: 0.02
A27: x | B27: TEV | E27: =SUM(K25:R25) -> 6199.2628
C28: Impl FCF Yield | E28: =K21/E27 -> 0.054150309
