Workbook
Name IQ_CH: 110000
Name IQ_CQ: 5000
Name IQ_CY: 10000
Name IQ_DAILY: 500000
Name IQ_FH: 100000
Name IQ_FQ: 500
Name IQ_FY: 1000
Name IQ_LTM: 2000
Name IQ_MONTH: 15000
Name IQ_NTM: 6000
Name IQ_WEEK: 50000
Name IQ_YTD: 3000

Sheet LBO
A1: as of 3Q2021
B2: Dave & Buster's (Public-to-Private) | Q2: Additional work / comments
B3: (in US$m unless otherwise stated)
A5: x | B5: Transaction Dashboard | E5: Last Close Price | F5: 39.82 | H5: Equity Purchase Price | I5: =F8 -> 2647.923
E6: FDSO (m) | F6: 49.257269 | H6: (-) Acquired BV | I6: =-G120 -> -153.232
B7: Sources | E7: Control Premium | F7: 0.35 | H7: (+) Existing Goodwill | I7: =G105 -> 272.597
B8: Existing Cash | C8: =G100 -> 11.891 | E8: Equity Purchase Price | F8: =F5*(1+F7)*F6 -> 2647.923 | H8: Pro Forma Goodwill | I8: =SUM(I5:I7) -> 2767.288
B9: Rollover Leases | C9: =G113 -> 1267.791 | E9: (+) Existing Debt | F9: =G114+G113 -> 1864.179
B10: Term Loan | C10: =I11*$I$18 -> 992.084 | E10: (-) Existing Cash | F10: =-G100 -> -11.891 | H10: Instrument | I10: xEBITDA | J10: Margin | K10: Floor | L10: DFF | M10: Amort | N10: PIK | O10: Sweep
B11: Senior Notes | C11: =I12*$I$18 -> 496.042 | E11: Acquisition EV | F11: =F8+F9 -> 4512.102 | H11: Term Loan | I11: 4 | J11: 400 | K11: 0.0125 | L11: 0.01 | M11: 0 | N11: 0 | O11: 1
B12: Common Equity | C12: =C24-SUM(C8:C11) -> 1787.4149 | E12: Implied LTM EBITDA Multiple | F12: =F11/I18 -> 18.192419 | H12: Senior Notes | I12: 2 | J12: 0.09 | L12: 0.01 | M12: 0 | N12: 0 | O12: 1
B13: o/w Sponsor | C13: =C12*(1-F17) -> 1698.0441 | E13: Implied FY22 EBITDA Multiple | F13: =F11/L92 -> 18.64984 | H13: RCF | I13: 0 | J13: 350 | K13: 0.0125
B14: o/w Management | C14: =C12*F17 -> 89.370744
B15: Total | C15: =SUM(C8:C12) -> 4555.2229 | E15: Hold Period | F15: 5 | H15: 9M21 Adjusted EBITDA | I15: 264.066
E16: Entry Date | F16: 44227 | H16: FY20 Adjusted EBITDA | I16: =K92 -> -81.273
B17: Uses | E17: Management Rollover | F17: 0.05 | H17: 9M20 Adjusted EBITDA | I17: -65.228
B18: EPP | C18: =F8 -> 2647.923 | E18: Sweet Equity Pot | F18: 0.05 | H18: LTM EBITDA | I18: =I15+I16-I17 -> 248.021
B19: Refi Debt | C19: =G114 -> 596.388 | E19: Cash Interest | F19: 0.01
B20: Rollover Leases | C20: =G113 -> 1267.791 | E20: Circularity Toggle | F20: 1
B21: Fund Cash Balance | C21: =F21 -> 15 | E21: Min. Cash Balance | F21: 15
B22: Financing Fees | C22: =SUMPRODUCT(L11:L12,C10:C11) -> 14.88126 | E22: Transaction Fees | F22: 0.005
B23: Transaction Fees | C23: =F22*C18 -> 13.239615 | E23: DFF Amortisation | F23: 8
B24: Total | C24: =SUM(C18:C23) -> 4555.2229
A26: x | B26: Operating Assumptions | I26: 2019 | J26: =I26+1 -> 2020 | K26: =J26+1 -> 2021 | L26: =K26+1 -> 2022 | M26: =L26+1 -> 2023 | N26: =M26+1 -> 2024 | O26: =N26+1 -> 2025 | P26: =O26+1 -> 2026 | R26: 9MFY22 | S26: Step-Up
B28: Number of Stores | H28: 106 | I28: 121 | J28: 136 | K28: 140 | L28: =K28+L29 -> 144 | M28: =L28+M29 -> 149 | N28: =M28+N29 -> 155 | O28: =N28+O29 -> 162 | P28: =O28+P29 -> 170
B29: New Stores | I29: =I28-H28 -> 15 | J29: =J28-I28 -> 15 | K29: =K28-J28 -> 4 | L29: 4 | M29: =L29+1+$S$29 -> 5 | N29: =M29+1 -> 6 | O29: =N29+1 -> 7 | P29: =O29+1 -> 8 | S29: 0
B30: F&B / Store | I30: =I63/I28 -> 4.4336281 | J30: =J63/J28 -> 4.1439412 | K30: =K63/K28 -> 1.1392929 | L30: =R30 -> 2.2132867 | M30: =L30+0.25+$S$30 -> 2.4632867 | N30: =M30+0.25 -> 2.7132867 | O30: =N30+0.25 -> 2.9632867 | P30: =O30+0.25 -> 3.2132867 | R30: =316.5/143 -> 2.2132867 | S30: 0
B31: Amusement / Store | I31: =I64/I28 -> 6.023405 | J31: =J64/J28 -> 5.8170221 | K31: =K64/K28 -> 1.97865 | L31: =R31 -> 4.5065944 | M31: =L31+0.25+$S$30 -> 4.7565944 | N31: =M31+0.25 -> 5.0065944 | O31: =N31+0.25 -> 5.2565944 | P31: =O31+0.25 -> 5.5065944 | R31: =644.443/143 -> 4.5065944
B32: COGS Spend - F&B | I32: =I67/I63 -> 0.25947259 | J32: =J67/J63 -> 0.26295655 | K32: =K67/K63 -> 0.28342769 | L32: 0.28 | M32: =L32 -> 0.28 | N32: =M32 -> 0.28 | O32: =N32 -> 0.28 | P32: =O32 -> 0.28 | R32: =86.366/316.5 -> 0.27287836
B33: COGS Spend - Amusement | I33: =I68/I64 -> 0.11122453 | J33: =J68/J64 -> 0.10758866 | K33: =K68/K64 -> 0.10720874 | L33: 0.1 | M33: =L33 -> 0.1 | N33: =M33 -> 0.1 | O33: =N33 -> 0.1 | P33: =O33 -> 0.1 | R33: =63.729/644.443 -> 0.098890049
B34: SG&A Spend | I34: =I71/I65 -> 0.58689592 | J34: =J71/J65 -> 0.60668448 | K34: =K71/K65 -> 1.0633247 | L34: 0.6 | M34: 0.595 | N34: 0.59 | O34: 0.58 | P34: 0.57 | R34: 0.5832173
B35: SBC / Sales | I35: =I88/I65 -> 0.0058657979 | J35: =J88/J65 -> 0.0050616709 | K35: =K88/K65 -> 0.016001851 | L35: =AVERAGE(I35:J35) -> 0.0054637344 | M35: =L35 -> 0.0054637344 | N35: =M35 -> 0.0054637344 | O35: =N35 -> 0.0054637344 | P35: =O35 -> 0.0054637344
B36: Pre-Opening Cost / Sales | I36: =I89/I65 -> 0.018306316 | J36: =J89/J65 -> 0.014003932 | K36: =K89/K65 -> 0.02583205 | L36: =AVERAGE(I36:J36) -> 0.016155124 | M36: =L36 -> 0.016155124 | N36: =M36 -> 0.016155124 | O36: =N36 -> 0.016155124 | P36: =O36 -> 0.016155124
B37: D&A Spend | I37: =I72/I65 -> 0.093475782 | J37: =J72/J65 -> 0.097778755 | K37: =K72/K65 -> 0.31795002 | L37: 0.12 | M37: 0.095 | N37: 0.095 | O37: 0.095 | P37: 0.095
B38: Effective Tax Rate | I38: =I81 -> 0.20736103 | J38: =J81 -> 0.21140929 | K38: =K81 -> 0.28729434 | L38: 0.21 | M38: =L38 -> 0.21 | N38: =M38 -> 0.21 | O38: =N38 -> 0.21 | P38: =O38 -> 0.21
B40: Maintenance Capex | I40: =29+22.5 -> 51.5 | J40: =19+22 -> 41 | K40: 19 | L40: =L41*L65 -> 33.868201 | M40: =M41*M65 -> 37.65168 | N40: =N41*N65 -> 41.880355 | O40: =O41*O65 -> 46.606726 | P40: =P41*P65 -> 51.883293
B41: Maintenance Capex / Sales | I41: =I40/I65 -> 0.040701778 | J41: =J40/J65 -> 0.030265204 | K41: =K40/K65 -> 0.043526868 | L41: 0.035 | M41: 0.035 | N41: 0.035 | O41: 0.035 | P41: 0.035
B42: Growth Capex | I42: 164.5 | J42: 187 | K42: 64 | L42: =+L43*L29 -> 46.866667 | M42: =+M43*M29 -> 58.583333 | N42: =+N43*N29 -> 70.3 | O42: =+O43*O29 -> 82.016667 | P42: =+P43*P29 -> 93.733333
B43: Growth Capex / New Stores | I43: =I42/I29 -> 10.966667 | J43: =J42/J29 -> 12.466667 | K43: =K42/K29 -> 16 | L43: =AVERAGE(I43:J43) -> 11.716667 | M43: =L43 -> 11.716667 | N43: =M43 -> 11.716667 | O43: =N43 -> 11.716667 | P43: =O43 -> 11.716667
B44: Total Capex | I44: =I40+I42 -> 216 | J44: =J40+J42 -> 228 | K44: =K40+K42 -> 83 | L44: =L40+L42 -> 80.734868 | M44: =M40+M42 -> 96.235013 | N44: =N40+N42 -> 112.18036 | O44: =O40+O42 -> 128.62339 | P44: =P40+P42 -> 145.61663
...

Sheet Mgmt Return Analysis
B2: Assumptions and guide
B3: Assume FY26 exit
B4: Exit multiple range from 15x to 19x; 0.5x increments
B5: Use circularity
B6: Mgmt has sweet equity hurdle rate of 200% - meaning total exit equity value has to be at least 200% higher than entry equity value for mgmt to earn their sweet equity
B8: Mgmt return analysis
B9: ($ in millions, except per share values)
B11: Key Inputs
B12: LTM Adjusted EBITDA (FY26) | C12: =LBO!P92 -> 402.6784
B13: Net Debt (FY26) | C13: =LBO!P179-LBO!P100 -> 1056.2196
B14: Entry Equity Value | C14: =LBO!C12 -> 1787.4149
B15: Management Rollover % | C15: =LBO!F17 -> 0.05
B16: Sweet Equity Pot % | C16: =LBO!F18 -> 0.05
B17: Sweet Equity Hurdle | C17: 2
B18: Hurdle Threshold (3x Entry Equity) | C18: =C14*(1+C17) -> 5362.2447
B20: Exit Multiple Sensitivity Analysis
B22: Exit Multiple | C22: 15.0x | D22: 15.5x | E22: 16.0x | F22: 16.5x | G22: 17.0x | H22: 17.5x | I22: 18.0x | J22: 18.5x | K22: 19.0x
B23: Exit Enterprise Value | C23: =$C$12*15 -> 6040.176 | D23: =$C$12*15.5 -> 6241.5152 | E23: =$C$12*16 -> 6442.8544 | F23: =$C$12*16.5 -> 6644.1936 | G23: =$C$12*17 -> 6845.5328 | H23: =$C$12*17.5 -> 7046.872 | I23: =$C$12*18 -> 7248.2112 | J23: =$C$12*18.5 -> 7449.5504 | K23: =$C$12*19 -> 7650.8896
B24: Exit Equity Value | C24: =C23-$C$13 -> 4983.9564 | D24: =D23-$C$13 -> 5185.2956 | E24: =E23-$C$13 -> 5386.6348 | F24: =F23-$C$13 -> 5587.974 | G24: =G23-$C$13 -> 5789.3132 | H24: =H23-$C$13 -> 5990.6524 | I24: =I23-$C$13 -> 6191.9916 | J24: =J23-$C$13 -> 6393.3308 | K24: =K23-$C$13 -> 6594.67
B25: Equity Gain | C25: =C24-$C$14 -> 3196.5415 | D25: =D24-$C$14 -> 3397.8807 | E25: =E24-$C$14 -> 3599.2199 | F25: =F24-$C$14 -> 3800.5591 | G25: =G24-$C$14 -> 4001.8983 | H25: =H24-$C$14 -> 4203.2375 | I25: =I24-$C$14 -> 4404.5767 | J25: =J24-$C$14 -> 4605.9159 | K25: =K24-$C$14 -> 4807.2551
B26: Hurdle Met? | C26: =IF(C24>=$C$18,"Yes","No") -> No | D26: =IF(D24>=$C$18,"Yes","No") -> No | E26: =IF(E24>=$C$18,"Yes","No") -> Yes | F26: =IF(F24>=$C$18,"Yes","No") -> Yes | G26: =IF(G24>=$C$18,"Yes","No") -> Yes | H26: =IF(H24>=$C$18,"Yes","No") -> Yes | I26: =IF(I24>=$C$18,"Yes","No") -> Yes | J26: =IF(J24>=$C$18,"Yes","No") -> Yes | K26: =IF(K24>=$C$18,"Yes","No") -> Yes
B28: Management Returns
B29: Mgmt Rollover Value at Exit | C29: =$C$15*C24 -> 249.19782 | D29: =$C$15*D24 -> 259.26478 | E29: =$C$15*E24 -> 269.33174 | F29: =$C$15*F24 -> 279.3987 | G29: =$C$15*G24 -> 289.46566 | H29: =$C$15*H24 -> 299.53262 | I29: =$C$15*I24 -> 309.59958 | J29: =$C$15*J24 -> 319.66654 | K29: =$C$15*K24 -> 329.7335
B30: Sweet Equity Value | C30: =IF(C24>=$C$18,$C$16*C25,0) -> 0 | D30: =IF(D24>=$C$18,$C$16*D25,0) -> 0 | E30: =IF(E24>=$C$18,$C$16*E25,0) -> 179.961 | F30: =IF(F24>=$C$18,$C$16*F25,0) -> 190.02796 | G30: =IF(G24>=$C$18,$C$16*G25,0) -> 200.09492 | H30: =IF(H24>=$C$18,$C$16*H25,0) -> 210.16188 | I30: =IF(I24>=$C$18,$C$16*I25,0) -> 220.22884 | J30: =IF(J24>=$C$18,$C$16*J25,0) -> 230.2958 | K30: =IF(K24>=$C$18,$C$16*K25,0) -> 240.36276
B31: Total Mgmt Equity Value at Exit | C31: =C29+C30 -> 249.19782 | D31: =D29+D30 -> 259.26478 | E31: =E29+E30 -> 449.29274 | F31: =F29+F30 -> 469.42666 | G31: =G29+G30 -> 489.56058 | H31: =H29+H30 -> 509.6945 | I31: =I29+I30 -> 529.82842 | J31: =J29+J30 -> 549.96234 | K31: =K29+K30 -> 570.09626
