Workbook
Name circ: LBO!$M$12
Name IQ_CH: 110000
Name IQ_CQ: 5000
Name IQ_CY: 10000
Name IQ_DAILY: 500000
Name IQ_FH: 100000
Name IQ_FQ: 500
Name IQ_FY: 1000
Name IQ_LTM: 2000
Name IQ_MONTH: 15000
Name IQ_NTM: 6000
Name IQ_WEEK: 50000
Name IQ_YTD: 3000

Sheet Data
C2: Summary P&L
C3: (€m, FYE 31-Dec) | D3: 2017A | E3: 2018A | F3: 2019A | G3: 2020E
D4: GAAP | E4: GAAP | F4: IFRS | G4: IFRS
C5: Output
C6: AMS Europe | D6: 31.5 | E6: 32.4 | F6: 37.3 | G6: 53.946401
C7: ECS Europe | D7: 31 | E7: 32.9 | F7: 38.9 | G7: 42.650783
C8: Americas & Asia | D8: 18.6 | E8: 22.8 | F8: 28.3 | G8: 32.533501
C9: Others | D9: 62.8 | E9: 57.9 | F9: 42.6 | G9: 36.202339
C10: Total Output | D10: 143.9 | E10: 146 | F10: 147.1 | G10: 165.33302
C12: Gross profit
C13: AMS Europe | D13: 9.5 | E13: 9.2 | F13: 11.2 | G13: 15.564811
C14: ECS Europe | D14: 11.1 | E14: 10.3 | F14: 14.4 | G14: 15.21323
C15: Americas & Asia | D15: 4 | E15: 3.8 | F15: 5.4 | G15: 6.9185281
C16: Others | D16: 16 | E16: 15.6 | F16: 15 | G16: 14.528397
C17: Total Gross Profit | D17: 40.6 | E17: 38.9 | F17: 46 | G17: 52.224966
C19: Overheads and Other
C20: Personnel expenses | D20: -23.774162 | E20: -24.428558 | F20: -25.728552 | G20: -26.453284
C21: Other operating expenses | D21: -11.355504 | E21: -9.1910144 | F21: -9.1900621 | G21: -9.3418151
C22: Other operating income | D22: 1.9575444 | E22: 1.9168258 | F22: 1.9825992 | G22: 2.1493293
C23: Total Overheads and Other | D23: -33.172121 | E23: -31.702747 | F23: -32.936015 | G23: -33.64577
C25: EBITDA | D25: 7.4278788 | E25: 7.1972532 | F25: 13.063985 | G25: 18.579196
D26: =+D17+D23 | E26: =+E17+E23 | F26: =+F17+F23 | G26: =+G17+G23
C27: Other items:
C28: D&A | D28: -3.2109359 | E28: -2.9779364 | F28: -5.5279112 | G28: -4.3133125
C29: Capex | D29: -2 | E29: -2.7 | F29: -2.8 | G29: -3.140329
C30: IFRS-16 leasing costs | D30: n.a. | E30: n.a. | F30: -1.4 | G30: -1.5701645
C31: Financial lease costs (IAS 17) | D31: n.a. | E31: -1 | F31: -1.4 | G31: -1.4
C32: Factoring (fees and interest) | D32: n.a. | E32: -1.4432411 | F32: -1.7267365 | G32: -1.9366145
C34: % Growth
C35: Total Output | D35: n.a. | E35: =+E10/D10-1 | F35: =+F10/E10-1 | G35: =+G10/F10-1
C36: Total Gross Profit | E36: =E17/D17-1 | F36: =F17/E17-1 | G36: =G17/F17-1
C37: Total Overheads and Other | E37: =E23/D23-1 | F37: =F23/E23-1 | G37: =G23/F23-1
C38: EBITDA | E38: =E25/D25-1 | F38: =F25/E25-1 | G38: =G25/F25-1
C40: % of Total Output
C41: Total Gross Profit | D41: =+D17/D10 | E41: =+E17/E10 | F41: =+F17/F10 | G41: =+G17/G10
C42: Total Overheads and Other | D42: =D23/D10 | E42: =E23/E10 | F42: =F23/F10 | G42: =G23/G10
C43: EBITDA | D43: =D25/D10 | E43: =E25/E10 | F43: =F25/F10 | G43: =G25/G10
C45: Summary Balance sheet
C46: (€m) | E46: =E3 | F46: =F3 | G46: =G3
C47: Assets
...

Sheet LBO
A1: in EURm unless otherwise stated | D1: Historical | E1: Historical | F1: Historical | G1: Estimated | H1: 1 | I1: =+H1+1 | J1: =+I1+1 | K1: =+J1+1 | L1: =+K1+1 | N1: CAGR
D2: 2017 | E2: =+D2+1 | F2: =+E2+1 | G2: =+F2+1 | H2: =+G2+1 | I2: =+H2+1 | J2: =+I2+1 | K2: =+J2+1 | L2: =+K2+1 | N2: 20-'25
A4: x | B4: Cover
C5: Txn assumptions | F5: Sources and Uses | K5: Other assumptions | O5: Financing assumptions | R5: xEBITDA | S5: Cash inter' | T5: PIK | U5: Maturity
C6: Purchase multiple | D6: 12 | F6: Revolver | I6: =+R6*$G$92 | K6: Min cash | M6: 20 | O6: Revolver | R6: 0 | S6: 0.04 | U6: 2027
C7: Pricing EBITDA (FY20E) | D7: =+G92 | F7: 1L debt | I7: =+R7*$G$92 | K7: Fees % of EV | M7: 0.05 | O7: 1L TLB | R7: 4 | S7: 0.06 | U7: 2027
C8: Purchase EV | D8: =+D7*D6 | F8: PIK notes | I8: =+R8*$G$92 | K8: Exit multiple | M8: 12 | O8: PIK notes | R8: 2 | T8: 0.08 | U8: 2027
F9: Sponsor equity | I9: =+I12-I10-I11-I8-I7-I6
C10: (-) debt | D10: =+Data!G61+Data!G62 | F10: Rolled lease liabilities | I10: =+D12
C11: (-) debt like items | D11: =+Data!G60+Data!G63 | F11: Cash on BS | I11: =+D13 | K11: Switches
C12: (-) leases | D12: =+Data!G65 | F12: Total sources | I12: =+I19 | K12: Circ switch | M12: 1
C13: (+) cash and equivalents | D13: =+Data!G54+Data!G50
C14: Purchase EqV | D14: =+D8-D10-D11+D12+D13 | F14: Purchase EqV | I14: =+D14
F15: Debt & debt-like items | I15: =+D10+D11
F16: Lease liabilities | I16: =+D12
F17: Fees | I17: =+M7*D8
F18: Min cash | I18: =+M6
F19: Total uses | I19: =SUM(I14:I18)
A20: x | B20: Operating assumptions
C21: AMS Europe | D21: =+Data!D6 | E21: =+Data!E6 | F21: =+Data!F6 | G21: =+Data!G6 | H21: =+G21*(1+$N21) | I21: =+H21*(1+$N21) | J21: =+I21*(1+$N21) | K21: =+J21*(1+$N21) | L21: =+K21*(1+$N21) | N21: 0.07
C22: ECS Europe | D22: =+Data!D7 | E22: =+Data!E7 | F22: =+Data!F7 | G22: =+Data!G7 | H22: =+G22*(1+$N22) | I22: =+H22*(1+$N22) | J22: =+I22*(1+$N22) | K22: =+J22*(1+$N22) | L22: =+K22*(1+$N22) | N22: 0.05
C23: Americas & Asia | D23: =+Data!D8 | E23: =+Data!E8 | F23: =+Data!F8 | G23: =+Data!G8 | H23: =+G23*(1+$N23) | I23: =+H23*(1+$N23) | J23: =+I23*(1+$N23) | K23: =+J23*(1+$N23) | L23: =+K23*(1+$N23) | N23: =+(L32/G32)^(0.2)-1
C24: Others | D24: =+Data!D9 | E24: =+Data!E9 | F24: =+Data!F9 | G24: =+Data!G9 | H24: =+G24*(1+$N24) | I24: =+H24*(1+$N24) | J24: =+I24*(1+$N24) | K24: =+J24*(1+$N24) | L24: =+K24*(1+$N24) | N24: =+(L38/G38)^(0.2)-1
C25: Total revenue | D25: =SUM(D21:D24) | E25: =SUM(E21:E24) | F25: =SUM(F21:F24) | G25: =SUM(G21:G24) | H25: =SUM(H21:H24) | I25: =SUM(I21:I24) | J25: =SUM(J21:J24) | K25: =SUM(K21:K24) | L25: =SUM(L21:L24)
C27: Memo: Europe
C28: Revenue | D28: =+D22+D21 | E28: =+E22+E21 | F28: =+F22+F21 | G28: =+G22+G21 | H28: =+H22+H21 | I28: =+I22+I21 | J28: =+J22+J21 | K28: =+K22+K21 | L28: =+L22+L21
C29: % YoY | E29: =+E28/D28-1 | F29: =+F28/E28-1 | G29: =+G28/F28-1 | H29: =+H28/G28-1 | I29: =+I28/H28-1 | J29: =+J28/I28-1 | K29: =+K28/J28-1 | L29: =+L28/K28-1
C31: Memo: Americas & Asia
C32: Revenue | D32: =+D23 | E32: =+E23 | F32: =+F23 | G32: =+G23 | H32: =+(1+H33)*G32 | I32: =+(1+I33)*H32 | J32: =+(1+J33)*I32 | K32: =+(1+K33)*J32 | L32: =+(1+L33)*K32
C33: % YoY | E33: =+E32/D32-1 | F33: =+F32/E32-1 | G33: =+G32/F32-1 | H33: =+H34+H35 | I33: =+I34+I35 | J33: =+J34+J35 | K33: =+K34+K35 | L33: =+L34+L35
C34: Baseline growth | H34: =+$N$21 | I34: =+$N$21 | J34: =+$N$21 | K34: =+$N$21 | L34: =+$N$21
C35: Excess growth | H35: 0.15 | I35: 0.125 | J35: 0.1 | K35: 0.075 | L35: 0.05
C37: Memo: Others
C38: Revenue | D38: =+D24 | E38: =+E24 | F38: =+F24 | G38: =+G24 | H38: =+(1+H39)*G38 | I38: =+(1+I39)*H38 | J38: =+(1+J39)*I38 | K38: =+(1+K39)*J38 | L38: =+(1+L39)*K38
C39: % YoY | E39: =+E38/D38-1 | F39: =+F38/E38-1 | G39: =+G38/F38-1 | H39: 0 | I39: 0 | J39: 0 | K39: 0 | L39: 0
C41: AMS Europe | D41: =+Data!D13 | E41: =+Data!E13 | F41: =+Data!F13 | G41: =+Data!G13
C42: ECS Europe | D42: =+Data!D14 | E42: =+Data!E14 | F42: =+Data!F14 | G42: =+Data!G14
C43: Americas & Asia | D43: =+Data!D15 | E43: =+Data!E15 | F43: =+Data!F15 | G43: =+Data!G15
C44: Others | D44: =+Data!D16 | E44: =+Data!E16 | F44: =+Data!F16 | G44: =+Data!G16
C45: Total gross profit | D45: =SUM(D41:D44) | E45: =SUM(E41:E44) | F45: =SUM(F41:F44) | G45: =SUM(G41:G44) | H45: =+H46*H25 | I45: =+I46*I25 | J45: =+J46*J25 | K45: =+K46*K25 | L45: =+L46*L25
...
