Workbook

Sheet BBPTACShadowWks0001
S5: =#REF!
V27: =#REF! | W27: =#REF! | X27: =#REF!
V28: =#REF! | W28: =#REF! | X28: =#REF!
T29: =#REF! | V29: =#REF! | W29: =#REF! | X29: =#REF!
L36: =#REF! | M36: =#REF!
J37: =#REF! | K37: =#REF!
G128: =#REF! | H128: =#REF! | I128: =#REF! | J128: =#REF! | K128: =#REF! | L128: =#REF! | M128: =#REF!
G129: =#REF! | H129: =#REF! | I129: =#REF! | J129: =#REF! | K129: =#REF! | L129: =#REF! | M129: =#REF!
G130: =#REF! | H130: =#REF! | I130: =#REF! | J130: =#REF! | K130: =#REF! | L130: =#REF! | M130: =#REF!
G131: =#REF! | H131: =#REF! | I131: =#REF! | J131: =#REF! | K131: =#REF! | L131: =#REF! | M131: =#REF!
K134: =#REF!
G147: =#REF!
G148: =#REF!
G149: =#REF!
E192: =#REF!
G193: =#REF!
G194: =#REF! | H194: =#REF!
G195: =#REF! | H195: =#REF!
G196: =#REF!
G197: =#REF!
G198: =#REF!
G199: =#REF! | H199: =#REF! | I199: =#REF! | J199: =#REF!
G200: =#REF! | H200: =#REF! | I200: =#REF! | J200: =#REF!
G201: =#REF! | H201: =#REF! | I201: =#REF! | J201: =#REF!
G202: =#REF! | H202: =#REF! | I202: =#REF! | J202: =#REF!
G203: =#REF!
G204: =#REF! | H204: =#REF!
G205: =#REF!
P242: =#REF!
P243: =#REF!
P244: =#REF!
M245: =#REF! | N245: =#REF! | O245: =#REF! | P245: =#REF!
M246: =#REF! | N246: =#REF!
L247: =#REF!
K282: =#REF! | L282: =#REF! | M282: =#REF! | N282: =#REF! | O282: =#REF!
P285: =#REF!
P286: =#REF!

Sheet Model Shell
A1: Kirby Corp
A2: US$mm unless otherwise specified | G2: 2Q24 LQA | J2: Act. | K2: Act. | L2: Act. | M2: Act. | N2: Act. | O2: Act. | P2: Est. | R2: Act. | S2: Act. | T2: Act. | U2: Act. | V2: Act. | W2: Act. | X2: Act. | Y2: Act. | Z2: Act. | AA2: Act. | AB2: Act. | AC2: Act. | AD2: Act. | AE2: Act. | AF2: Act. | AG2: Act. | AH2: Act. | AI2: Act. | AJ2: Act. | AK2: Act. | AL2: Act. | AM2: Act. | AN2: Act. | AO2: Act. | AP2: Act. | AQ2: Est. | AR2: Est. | AS2: Est. | AT2: Est. | AU2: Est. | AV2: Est. | AW2: Est.
G3: LQA | H3: LTM | J3: 2018 | K3: =J3+1 | L3: =K3+1 | M3: =L3+1 | N3: =M3+1 | O3: =N3+1 | P3: =O3+1 | R3: 1Q18 | S3: 2Q18 | T3: 3Q18 | U3: 4Q18 | V3: 1Q19 | W3: 2Q19 | X3: 3Q19 | Y3: 4Q19 | Z3: 1Q20 | AA3: 2Q20 | AB3: 3Q20 | AC3: 4Q20 | AD3: 1Q21 | AE3: 2Q21 | AF3: 3Q21 | AG3: 4Q21 | AH3: 1Q22 | AI3: 2Q22 | AJ3: 3Q22 | AK3: 4Q22 | AL3: 1Q23 | AM3: 2Q23 | AN3: 3Q23 | AO3: 4Q23 | AP3: 1Q24 | AQ3: 2Q24 | AR3: 3Q24 | AS3: 4Q24 | AT3: 1Q25 | AU3: 2Q25 | AV3: 3Q25 | AW3: 4Q25
A5: x | B5: Income Statement
B7: Marine Transport | G7: =OFFSET(R7,0,MATCH($G$2,$R$3:$AW$3,0)-1)*4 | H7: =SUM(OFFSET(R7,0,MATCH($G$2,$R$3:$AW$3,0)-4),OFFSET(R7,0,MATCH($G$2,$R$3:$AW$3,0)-3),OFFSET(R7,0,MATCH($G$2,$R$3:$AW$3,0)-2),OFFSET(R7,0,MATCH($G$2,$R$3:$AW$3,0)-1)) | J7: =SUM(R7:U7) | K7: =SUM(V7:Y7) | L7: =SUM(Z7:AC7) | M7: =SUM(AD7:AG7) | N7: =SUM(AH7:AK7) | O7: =SUM(AL7:AO7) | R7: 340.403 | S7: 378.163 | T7: 382.04 | U7: 382.537 | V7: 368.121 | W7: 404.286 | X7: 412.665 | Y7: 402.01 | Z7: 403.257 | AA7: 380.987 | AB7: 320.602 | AC7: 299.419 | AD7: 300.951 | AE7: 332.887 | AF7: 338.514 | AG7: 350.566 | AH7: 355.536 | AI7: 405.655 | AJ7: 433.04 | AK7: 422.736 | AL7: 412.495 | AM7: 426.962 | AN7: 429.885 | AO7: 452.595 | AP7: 475.412
B8: Distribution & Services | G8: =OFFSET(R8,0,MATCH($G$2,$R$3:$AW$3,0)-1)*4 | H8: =SUM(OFFSET(R8,0,MATCH($G$2,$R$3:$AW$3,0)-4),OFFSET(R8,0,MATCH($G$2,$R$3:$AW$3,0)-3),OFFSET(R8,0,MATCH($G$2,$R$3:$AW$3,0)-2),OFFSET(R8,0,MATCH($G$2,$R$3:$AW$3,0)-1)) | J8: =SUM(R8:U8) | K8: =SUM(V8:Y8) | L8: =SUM(Z8:AC8) | M8: =SUM(AD8:AG8) | N8: =SUM(AH8:AK8) | O8: =SUM(AL8:AO8) | R8: 401.285 | S8: 424.508 | T8: 322.805 | U8: 338.956 | V8: 376.5 | W8: 366.756 | X8: 254.144 | Y8: 253.917 | Z8: 240.669 | AA8: 160.172 | AB8: 175.965 | AC8: 190.337 | AD8: 195.899 | AE8: 226.737 | AF8: 260.406 | AG8: 240.7 | AH8: 255.246 | AI8: 292.309 | AJ8: 312.803 | AK8: 307.429 | AL8: 337.949 | AM8: 350.286 | AN8: 334.887 | AO8: 346.581 | AP8: 332.61
B9: Total Revenues | G9: =SUM(G7:G8) | H9: =SUM(H7:H8) | J9: =SUM(J7:J8) | K9: =SUM(K7:K8) | L9: =SUM(L7:L8) | M9: =SUM(M7:M8) | N9: =SUM(N7:N8) | O9: =SUM(O7:O8) | R9: =SUM(R7:R8) | S9: =SUM(S7:S8) | T9: =SUM(T7:T8) | U9: =SUM(U7:U8) | V9: =SUM(V7:V8) | W9: =SUM(W7:W8) | X9: =SUM(X7:X8) | Y9: =SUM(Y7:Y8) | ... AP9: =SUM(AP7:AP8)
C10: Y/Y Growth % | G10: =G9/G7 | H10: =H9/H7 | K10: =K9/J9-1 | L10: =L9/K9-1 | M10: =M9/L9-1 | N10: =N9/M9-1 | O10: =O9/N9-1 | V10: =V9/R9-1 | W10: =W9/S9-1 | X10: =X9/T9-1 | Y10: =Y9/U9-1 | Z10: =Z9/V9-1 | AA10: =AA9/W9-1 | AB10: =AB9/X9-1 | AC10: =AC9/Y9-1 | ... AP10: =AP9/AL9-1
C11: Sequential Growth % | S11: =S9/R9-1 | T11: =T9/S9-1 | U11: =U9/T9-1 | V11: =V9/U9-1 | W11: =W9/V9-1 | X11: =X9/W9-1 | Y11: =Y9/X9-1 | Z11: =Z9/Y9-1 | ... AP11: =AP9/AO9-1
B13: Cash COGS & OpEX | G13: =OFFSET(R13,0,MATCH($G$2,$R$3:$AW$3,0)-1)*4 | H13: =SUM(OFFSET(R13,0,MATCH($G$2,$R$3:$AW$3,0)-4),OFFSET(R13,0,MATCH($G$2,$R$3:$AW$3,0)-3),OFFSET(R13,0,MATCH($G$2,$R$3:$AW$3,0)-2),OFFSET(R13,0,MATCH($G$2,$R$3:$AW$3,0)-1)) | J13: =SUM(R13:U13) | K13: =SUM(V13:Y13) | L13: =SUM(Z13:AC13) | M13: =SUM(AD13:AG13) | N13: =SUM(AH13:AK13) | O13: =SUM(AL13:AO13) | R13: -553.317 | S13: -588.628 | T13: -498.421 | U13: -520.58 | V13: -536.655 | W13: -563.495 | X13: -458.514 | Y13: -471.382 | Z13: -453.568 | AA13: -373.539 | AB13: -340.764 | AC13: -342.947 | AD13: -363.04 | AE13: -409.479 | AF13: -446.519 | AG13: -433.923 | AH13: -450.618 | AI13: -523.862 | AJ13: -552.392 | AK13: -534.069 | AL13: -542.08 | AM13: -546.069 | AN13: -530.541 | AO13: -561.732 | AP13: -550.681
B14: Cash Gross Profit | G14: =G9+SUM(G13:G13) | H14: =H9+SUM(H13:H13) | J14: =J9+SUM(J13:J13) | K14: =K9+SUM(K13:K13) | L14: =L9+SUM(L13:L13) | M14: =M9+SUM(M13:M13) | N14: =N9+SUM(N13:N13) | O14: =O9+SUM(O13:O13) | R14: =R9+SUM(R13:R13) | S14: =S9+SUM(S13:S13) | T14: =T9+SUM(T13:T13) | U14: =U9+SUM(U13:U13) | V14: =V9+SUM(V13:V13) | W14: =W9+SUM(W13:W13) | X14: =X9+SUM(X13:X13) | Y14: =Y9+SUM(Y13:Y13) | ... AP14: =AP9+SUM(AP13:AP13)
C15: Gross Margin % | G15: =G14/G9 | H15: =H14/H9 | J15: =J14/J9 | K15: =K14/K9 | L15: =L14/L9 | M15: =M14/M9 | N15: =N14/N9 | O15: =O14/O9 | R15: =R14/R9 | S15: =S14/S9 | T15: =T14/T9 | U15: =U14/U9 | V15: =V14/V9 | W15: =W14/W9 | X15: =X14/X9 | Y15: =Y14/Y9 | ... AP15: =AP14/AP9
B17: SG&A | G17: =OFFSET(R17,0,MATCH($G$2,$R$3:$AW$3,0)-1)*4 | H17: =SUM(OFFSET(R17,0,MATCH($G$2,$R$3:$AW$3,0)-4),OFFSET(R17,0,MATCH($G$2,$R$3:$AW$3,0)-3),OFFSET(R17,0,MATCH($G$2,$R$3:$AW$3,0)-2),OFFSET(R17,0,MATCH($G$2,$R$3:$AW$3,0)-1)) | J17: =SUM(R17:U17) | K17: =SUM(V17:Y17) | L17: =SUM(Z17:AC17) | M17: =SUM(AD17:AG17) | N17: =SUM(AH17:AK17) | O17: =SUM(AL17:AO17) | R17: -76.796 | S17: -92.588 | T17: -70.032 | U17: -64.981 | V17: -72.796 | W17: -69.15 | X17: -64.656 | Y17: -70.786 | Z17: -72.08 | AA17: -65.612 | AB17: -61.72 | AC17: -58.86 | AD17: -69.629 | AE17: -62.74 | AF17: -66.065 | AG17: -68.477 | AH17: -75.765 | AI17: -69.275 | AJ17: -75.381 | AK17: -80.971 | AL17: -88.849 | AM17: -82.896 | AN17: -79.125 | AO17: -84.343 | AP17: -90.206
B18: Taxes other than Income | G18: =OFFSET(R18,0,MATCH($G$2,$R$3:$AW$3,0)-1)*4 | H18: =SUM(OFFSET(R18,0,MATCH($G$2,$R$3:$AW$3,0)-4),OFFSET(R18,0,MATCH($G$2,$R$3:$AW$3,0)-3),OFFSET(R18,0,MATCH($G$2,$R$3:$AW$3,0)-2),OFFSET(R18,0,MATCH($G$2,$R$3:$AW$3,0)-1)) | J18: =SUM(R18:U18) | K18: =SUM(V18:Y18) | L18: =SUM(Z18:AC18) | M18: =SUM(AD18:AG18) | N18: =SUM(AH18:AK18) | O18: =SUM(AL18:AO18) | R18: -8.535 | S18: -10.552 | T18: -10.523 | U18: -9.641 | V18: -9.998 | W18: -10.579 | X18: -10.909 | Y18: -10.447 | Z18: -11.406 | AA18: -13.065 | AB18: -9.077 | AC18: -8.452 | AD18: -8.26 | AE18: -10.364 | AF18: -9.917 | AG18: -7.71 | AH18: -9.59 | AI18: -9.621 | AJ18: -9.121 | AK18: -6.739 | AL18: -9.186 | AM18: -9.758 | AN18: -9.666 | AO18: -6.156 | AP18: -8.044
B19: D&A | G19: =OFFSET(R19,0,MATCH($G$2,$R$3:$AW$3,0)-1)*4 | H19: =SUM(OFFSET(R19,0,MATCH($G$2,$R$3:$AW$3,0)-4),OFFSET(R19,0,MATCH($G$2,$R$3:$AW$3,0)-3),OFFSET(R19,0,MATCH($G$2,$R$3:$AW$3,0)-2),OFFSET(R19,0,MATCH($G$2,$R$3:$AW$3,0)-1)) | J19: =SUM(R19:U19) | K19: =SUM(V19:Y19) | L19: =SUM(Z19:AC19) | M19: =SUM(AD19:AG19) | N19: =SUM(AH19:AK19) | O19: =SUM(AL19:AO19) | R19: -54.218 | S19: -55.492 | T19: -57.93 | U19: -57.332 | V19: -55.223 | W19: -55.093 | X19: -54.455 | Y19: -54.861 | Z19: -55.789 | AA19: -54.502 | AB19: -54.779 | AC19: -54.854 | AD19: -54.89 | AE19: -55.132 | AF19: -53.462 | AG19: -50.234 | AH19: -49.964 | AI19: -50.115 | AJ19: -50.419 | AK19: -50.945 | AL19: -51.109 | AM19: -51.697 | AN19: -53.445 | AO19: -54.905 | AP19: -57.642
B20: Core EBIT | G20: =G14+SUM(G17:G19) | H20: =H14+SUM(H17:H19) | J20: =J14+SUM(J17:J19) | K20: =K14+SUM(K17:K19) | L20: =L14+SUM(L17:L19) | M20: =M14+SUM(M17:M19) | N20: =N14+SUM(N17:N19) | O20: =O14+SUM(O17:O19) | R20: =R14+SUM(R17:R19) | S20: =S14+SUM(S17:S19) | T20: =T14+SUM(T17:T19) | U20: =U14+SUM(U17:U19) | V20: =V14+SUM(V17:V19) | W20: =W14+SUM(W17:W19) | X20: =X14+SUM(X17:X19) | Y20: =Y14+SUM(Y17:Y19) | ... AP20: =AP14+SUM(AP17:AP19)
C21: % Margin | G21: =G20/G9 | H21: =H20/H9 | J21: =J20/J9 | K21: =K20/K9 | L21: =L20/L9 | M21: =M20/M9 | N21: =N20/N9 | O21: =O20/O9 | R21: =R20/R9 | S21: =S20/S9 | T21: =T20/T9 | U21: =U20/U9 | V21: =V20/V9 | W21: =W20/W9 | X21: =X20/X9 | Y21: =Y20/Y9 | ... AP21: =AP20/AP9
B22: (+) D&A | G22: =OFFSET(R22,0,MATCH($G$2,$R$3:$AW$3,0)-1)*4 | H22: =SUM(OFFSET(R22,0,MATCH($G$2,$R$3:$AW$3,0)-4),OFFSET(R22,0,MATCH($G$2,$R$3:$AW$3,0)-3),OFFSET(R22,0,MATCH($G$2,$R$3:$AW$3,0)-2),OFFSET(R22,0,MATCH($G$2,$R$3:$AW$3,0)-1)) | J22: =SUM(R22:U22) | K22: =SUM(V22:Y22) | L22: =SUM(Z22:AC22) | M22: =SUM(AD22:AG22) | N22: =SUM(AH22:AK22) | O22: =SUM(AL22:AO22) | R22: =-R19 | S22: =-S19 | T22: =-T19 | U22: =-U19 | V22: =-V19 | W22: =-W19 | X22: =-X19 | Y22: =-Y19 | ... AP22: =-AP19
B23: Core EBITDA | G23: =G20+G22 | H23: =H20+H22 | J23: =J20+J22 | K23: =K20+K22 | L23: =L20+L22 | M23: =M20+M22 | N23: =N20+N22 | O23: =O20+O22 | R23: =R20+R22 | S23: =S20+S22 | T23: =T20+T22 | U23: =U20+U22 | V23: =V20+V22 | W23: =W20+W22 | X23: =X20+X22 | Y23: =Y20+Y22 | ... AP23: =AP20+AP22
C24: % Margin | G24: =G23/G9 | H24: =H23/H9 | J24: =J23/J9 | K24: =K23/K9 | L24: =L23/L9 | M24: =M23/M9 | N24: =N23/N9 | O24: =O23/O9 | R24: =R23/R9 | S24: =S23/S9 | T24: =T23/T9 | U24: =U23/U9 | V24: =V23/V9 | W24: =W23/W9 | X24: =X23/X9 | Y24: =Y23/Y9 | ... AP24: =AP23/AP9
B26: Impairments & other charges | G26: =OFFSET(R26,0,MATCH($G$2,$R$3:$AW$3,0)-1)*4 | H26: =SUM(OFFSET(R26,0,MATCH($G$2,$R$3:$AW$3,0)-4),OFFSET(R26,0,MATCH($G$2,$R$3:$AW$3,0)-3),OFFSET(R26,0,MATCH($G$2,$R$3:$AW$3,0)-2),OFFSET(R26,0,MATCH($G$2,$R$3:$AW$3,0)-1)) | J26: =SUM(R26:U26) | K26: =SUM(V26:Y26) | L26: =SUM(Z26:AC26) | M26: =SUM(AD26:AG26) | N26: =SUM(AH26:AK26) | O26: =SUM(AL26:AO26) | R26: 0 | S26: 0 | T26: 0 | U26: =-82.705-2.702-2.403 | V26: 0 | W26: 0 | X26: 0 | Y26: -35.525 | Z26: -561.274 | AA26: 0 | AB26: 0 | AC26: 0 | AD26: 0 | AE26: 0 | AF26: -340.713 | AG26: 0 | AH26: 0 | AI26: 0 | AJ26: 0 | AK26: 0 | AL26: 0 | AM26: 0 | AN26: 0 | AO26: 0 | AP26: 0
B27: Gains on disposals | G27: =OFFSET(R27,0,MATCH($G$2,$R$3:$AW$3,0)-1)*4 | H27: =SUM(OFFSET(R27,0,MATCH($G$2,$R$3:$AW$3,0)-4),OFFSET(R27,0,MATCH($G$2,$R$3:$AW$3,0)-3),OFFSET(R27,0,MATCH($G$2,$R$3:$AW$3,0)-2),OFFSET(R27,0,MATCH($G$2,$R$3:$AW$3,0)-1)) | J27: =SUM(R27:U27) | K27: =SUM(V27:Y27) | L27: =SUM(Z27:AC27) | M27: =SUM(AD27:AG27) | N27: =SUM(AH27:AK27) | O27: =SUM(AL27:AO27) | R27: 1.898 | S27: 0.442 | T27: 0.018 | U27: -0.39 | V27: 2.157 | W27: 3.118 | X27: -0.374 | Y27: 3.251 | Z27: 0.492 | AA27: -0.189 | AB27: -0.316 | AC27: 0.131 | AD27: 2.133 | AE27: 2.119 | AF27: 0.83 | AG27: 0.679 | AH27: 4.849 | AI27: 2.745 | AJ27: 0.377 | AK27: 0.308 | AL27: 2.23 | AM27: 0.472 | AN27: 1.528 | AO27: 0.779 | AP27: 0.074
B28: Other Income/Expenses Net | G28: =OFFSET(R28,0,MATCH($G$2,$R$3:$AW$3,0)-1)*4 | H28: =SUM(OFFSET(R28,0,MATCH($G$2,$R$3:$AW$3,0)-4),OFFSET(R28,0,MATCH($G$2,$R$3:$AW$3,0)-3),OFFSET(R28,0,MATCH($G$2,$R$3:$AW$3,0)-2),OFFSET(R28,0,MATCH($G$2,$R$3:$AW$3,0)-1)) | J28: =SUM(R28:U28) | K28: =SUM(V28:Y28) | L28: =SUM(Z28:AC28) | M28: =SUM(AD28:AG28) | N28: =SUM(AH28:AK28) | O28: =SUM(AL28:AO28) | R28: 1.591 | S28: 1.541 | T28: 1.454 | U28: 1.14 | V28: -0.568 | W28: 2.381 | X28: 0.864 | Y28: 1.11 | Z28: 2.723 | AA28: 2.29 | AB28: 1.172 | AC28: 1.962 | AD28: 3.791 | AE28: 2.523 | AF28: 1.832 | AG28: 1.855 | AH28: 4.308 | AI28: 3.749 | AJ28: 3.805 | AK28: 4.824 | AL28: 6.443 | AM28: 1.264 | AN28: 1.589 | AO28: 1.745 | AP28: 3.269
B29: Other EBIT Components | G29: =SUM(G26:G28) | H29: =SUM(H26:H28) | J29: =SUM(J26:J28) | K29: =SUM(K26:K28) | L29: =SUM(L26:L28) | M29: =SUM(M26:M28) | N29: =SUM(N26:N28) | O29: =SUM(O26:O28) | R29: =SUM(R26:R28) | S29: =SUM(S26:S28) | T29: =SUM(T26:T28) | U29: =SUM(U26:U28) | V29: =SUM(V26:V28) | W29: =SUM(W26:W28) | X29: =SUM(X26:X28) | Y29: =SUM(Y26:Y28) | ... AP29: =SUM(AP26:AP28)
B30: As Reported Core EBIT | G30: =G20 | H30: =H20 | J30: =J20 | K30: =K20 | L30: =L20 | M30: =M20 | N30: =N20 | O30: =O20 | R30: =R20 | S30: =S20 | T30: =T20 | U30: =U20 | V30: =V20 | W30: =W20 | X30: =X20 | Y30: =Y20 | ... AP30: =AP20
B31: Total EBIT | G31: =SUM(G29:G30) | H31: =SUM(H29:H30) | J31: =SUM(J29:J30) | K31: =SUM(K29:K30) | L31: =SUM(L29:L30) | M31: =SUM(M29:M30) | N31: =SUM(N29:N30) | O31: =SUM(O29:O30) | R31: =SUM(R29:R30) | S31: =SUM(S29:S30) | T31: =SUM(T29:T30) | U31: =SUM(U29:U30) | V31: =SUM(V29:V30) | W31: =SUM(W29:W30) | X31: =SUM(X29:X30) | Y31: =SUM(Y29:Y30) | ... AP31: =SUM(AP29:AP30) | AQ31: 484.8
C32: % Margin | G32: =G31/G9 | H32: =H31/H9 | J32: =J31/J9 | K32: =K31/K9 | L32: =L31/L9 | M32: =M31/M9 | N32: =N31/N9 | O32: =O31/O9 | R32: =R31/R9 | S32: =S31/S9 | T32: =T31/T9 | U32: =U31/U9 | V32: =V31/V9 | W32: =W31/W9 | X32: =X31/X9 | Y32: =Y31/Y9 | ... AP32: =AP31/AP9
B34: Interest expense, net | G34: =OFFSET(R34,0,MATCH($G$2,$R$3:$AW$3,0)-1)*4 | H34: =SUM(OFFSET(R34,0,MATCH($G$2,$R$3:$AW$3,0)-4),OFFSET(R34,0,MATCH($G$2,$R$3:$AW$3,0)-3),OFFSET(R34,0,MATCH($G$2,$R$3:$AW$3,0)-2),OFFSET(R34,0,MATCH($G$2,$R$3:$AW$3,0)-1)) | J34: =SUM(R34:U34) | K34: =SUM(V34:Y34) | L34: =SUM(Z34:AC34) | M34: =SUM(AD34:AG34) | N34: =SUM(AH34:AK34) | O34: =SUM(AL34:AO34) | R34: -9.78 | S34: -12.54 | T34: -12.345 | U34: -12.191 | V34: -13.201 | W34: -15.515 | X34: -14.31 | Y34: -12.968 | Z34: -12.799 | AA34: -12.708 | AB34: -11.809 | AC34: -11.423 | AD34: -10.966 | AE34: -10.706 | AF34: -10.5 | AG34: -10.297 | AH34: -10.203 | AI34: -10.649 | AJ34: -11.755 | AK34: -11.99 | AL34: -13.221 | AM34: -12.286 | AN34: -13.386 | AO34: -13.115 | AP34: -13.151
B36: PBT | G36: =G31+G34 | H36: =H31+H34 | J36: =J31+J34 | K36: =K31+K34 | L36: =L31+L34 | M36: =M31+M34 | N36: =N31+N34 | O36: =O31+O34 | R36: =R31+R34 | S36: =S31+S34 | T36: =T31+T34 | U36: =U31+U34 | V36: =V31+V34 | W36: =W31+W34 | X36: =X31+X34 | Y36: =Y31+Y34 | ... AP36: =AP31+AP34
B37: (-) Taxes | G37: =OFFSET(R37,0,MATCH($G$2,$R$3:$AW$3,0)-1)*4 | H37: =SUM(OFFSET(R37,0,MATCH($G$2,$R$3:$AW$3,0)-4),OFFSET(R37,0,MATCH($G$2,$R$3:$AW$3,0)-3),OFFSET(R37,0,MATCH($G$2,$R$3:$AW$3,0)-2),OFFSET(R37,0,MATCH($G$2,$R$3:$AW$3,0)-1)) | J37: =SUM(R37:U37) | K37: =SUM(V37:Y37) | L37: =SUM(Z37:AC37) | M37: =SUM(AD37:AG37) | N37: =SUM(AH37:AK37) | O37: =SUM(AL37:AO37) | R37: -9.865 | S37: -16.061 | T37: -15.116 | U37: 5.961 | V37: -13.88 | W37: -15.269 | X37: -16.305 | Y37: -1.347 | Z37: 172.809 | AA37: 1.429 | AB37: 8.419 | AC37: 7.102 | AD37: 0.891 | AE37: -5.493 | AF37: 60.442 | AG37: -12.01 | AH37: -6.213 | AI37: -11.03 | AJ37: -11.713 | AK37: -14.458 | AL37: -14.051 | AM37: -18.96 | AN37: -18.722 | AO37: -19.487 | AP37: -21.726
B38: Net Income | G38: =SUM(G36:G37) | H38: =SUM(H36:H37) | J38: =SUM(J36:J37) | K38: =SUM(K36:K37) | L38: =SUM(L36:L37) | M38: =SUM(M36:M37) | N38: =SUM(N36:N37) | O38: =SUM(O36:O37) | R38: =SUM(R36:R37) | S38: =SUM(S36:S37) | T38: =SUM(T36:T37) | U38: =SUM(U36:U37) | V38: =SUM(V36:V37) | W38: =SUM(W36:W37) | X38: =SUM(X36:X37) | Y38: =SUM(Y36:Y37) | ... AP38: =SUM(AP36:AP37)
B39: (-) NCI | G39: =OFFSET(R39,0,MATCH($G$2,$R$3:$AW$3,0)-1)*4 | H39: =SUM(OFFSET(R39,0,MATCH($G$2,$R$3:$AW$3,0)-4),OFFSET(R39,0,MATCH($G$2,$R$3:$AW$3,0)-3),OFFSET(R39,0,MATCH($G$2,$R$3:$AW$3,0)-2),OFFSET(R39,0,MATCH($G$2,$R$3:$AW$3,0)-1)) | J39: =SUM(R39:U39) | K39: =SUM(V39:Y39) | L39: =SUM(Z39:AC39) | M39: =SUM(AD39:AG39) | N39: =SUM(AH39:AK39) | O39: =SUM(AL39:AO39) | R39: -0.195 | S39: -0.191 | T39: -0.134 | U39: -0.106 | V39: -0.161 | W39: -0.153 | X39: -0.163 | Y39: -0.195 | Z39: -0.278 | AA39: -0.261 | AB39: -0.204 | AC39: -0.211 | AD39: -0.255 | AE39: -0.162 | AF39: 0.422 | AG39: -0.188 | AH39: -0.152 | AI39: -0.1499 | AJ39: -0.153 | AK39: -0.016 | AL39: 0.077 | AM39: 0.049 | AN39: -0.4 | AO39: -0.056 | AP39: 0.153
B40: Net Income to Shareholders | G40: =SUM(G38:G39) | H40: =SUM(H38:H39) | J40: =SUM(J38:J39) | K40: =SUM(K38:K39) | L40: =SUM(L38:L39) | M40: =SUM(M38:M39) | N40: =SUM(N38:N39) | O40: =SUM(O38:O39) | R40: =SUM(R38:R39) | S40: =SUM(S38:S39) | T40: =SUM(T38:T39) | U40: =SUM(U38:U39) | V40: =SUM(V38:V39) | W40: =SUM(W38:W39) | X40: =SUM(X38:X39) | Y40: =SUM(Y38:Y39) | ... AP40: =SUM(AP38:AP39)
B42: Diluted Shares Outstanding | G42: =OFFSET(R42,0,MATCH($G$2,$R$3:$AW$3,0)-1) | H42: =AVERAGE(OFFSET(R42,0,MATCH($G$2,$R$3:$AW$3,0)-4),OFFSET(R42,0,MATCH($G$2,$R$3:$AW$3,0)-3),OFFSET(R42,0,MATCH($G$2,$R$3:$AW$3,0)-2),OFFSET(R42,0,MATCH($G$2,$R$3:$AW$3,0)-1)) | J42: 59.689 | K42: 59.75 | L42: 59.912 | M42: 60.053 | N42: 60.329 | O42: 59.857 | R42: 59.493 | S42: 59.72 | T42: 59.784 | U42: 59.645 | V42: 59.823 | W42: 59.907 | X42: 59.906 | Y42: 59.998 | Z42: 59.883 | AA42: 59.937 | AB42: 59.931 | AC42: 59.975 | AD42: 60.016 | AE42: 60.274 | AF42: 60.062 | AG42: 60.311 | AH42: 60.463 | AI42: 60.467 | AJ42: 60.182 | AK42: 60.211 | AL42: 60.272 | AM42: 60.085 | AN42: 59.764 | AO42: 59.335 | AP42: 58.819
B43: Fully Diluted EPS | G43: =OFFSET(R43,0,MATCH($G$2,$R$3:$AW$3,0)-1)*4 | H43: =SUM(OFFSET(R43,0,MATCH($G$2,$R$3:$AW$3,0)-4),OFFSET(R43,0,MATCH($G$2,$R$3:$AW$3,0)-3),OFFSET(R43,0,MATCH($G$2,$R$3:$AW$3,0)-2),OFFSET(R43,0,MATCH($G$2,$R$3:$AW$3,0)-1)) | J43: =J40/J42 | K43: =K40/K42 | L43: =L40/L42 | M43: =M40/M42 | N43: =N40/N42 | O43: =O40/O42 | R43: =R40/R42 | S43: =S40/S42 | T43: =T40/T42 | U43: =U40/U42 | V43: =V40/V42 | W43: =W40/W42 | X43: =X40/X42 | Y43: =Y40/Y42 | ... AP43: =AP40/AP42
A46: x | B46: Balance Sheet
B48: Cash and cash equivalents | G48: =OFFSET(R48,0,MATCH($G$2,$R$3:$AW$3,0)-1) | H48: =G48 | J48: =U48 | K48: =Y48 | L48: =AC48 | M48: =AG48 | N48: =AK48 | O48: =AO48 | R48: 7.01 | S48: 4.198 | T48: 3.617 | U48: 7.8 | V48: 7.289 | W48: 22.521 | X48: 9.425 | Y48: 24.737 | Z48: 322.571 | AA48: 108.471 | AB48: 119.586 | AC48: 80.338 | AD48: 52.333 | AE48: 53.052 | AF48: 54.377 | AG48: 34.813 | AH48: 32.398 | AI48: 25.104 | AJ48: 36.991 | AK48: 80.577 | AL48: 26.699 | AM48: 36.603 | AN48: 42.116 | AO48: 32.577 | AP48: 75.216
B49: Trade Receivables | G49: =OFFSET(R49,0,MATCH($G$2,$R$3:$AW$3,0)-1) | H49: =G49 | J49: =U49 | K49: =Y49 | L49: =AC49 | M49: =AG49 | N49: =AK49 | O49: =AO49 | R49: 485.865 | S49: 448.281 | T49: 400.87 | U49: 417.644 | V49: 439.975 | W49: 450.958 | X49: 382.465 | Y49: 379.174 | Z49: 389.616 | AA49: 348.453 | AB49: 304.021 | AC49: 315.283 | AD49: 347.275 | AE49: 352.372 | AF49: 389.579 | AG49: 417.958 | AH49: 420.823 | AI49: 445.425 | AJ49: 482.744 | AK49: 483.406 | AL49: 526.489 | AM49: 519.741 | AN49: 514.631 | AO49: 526.691 | AP49: 529.141
B50: Other Receivables | G50: =OFFSET(R50,0,MATCH($G$2,$R$3:$AW$3,0)-1) | H50: =G50 | J50: =U50 | K50: =Y50 | L50: =AC50 | M50: =AG50 | N50: =AK50 | O50: =AO50 | R50: 110.64 | S50: 116.673 | T50: 111.221 | U50: 104.239 | V50: 122.18 | W50: 99.568 | X50: 99.736 | Y50: 104.175 | Z50: 253.688 | AA50: 228.409 | AB50: 257.656 | AC50: 284.899 | AD50: 171.749 | AE50: 165.478 | AF50: 150.811 | AG50: 149.964 | AH50: 125.757 | AI50: 127.181 | AJ50: 133.278 | AK50: 114.556 | AL50: 109.539 | AM50: 40.011 | AN50: 53.936 | AO50: 52.025 | AP50: 55.949
B51: Inventory | G51: =OFFSET(R51,0,MATCH($G$2,$R$3:$AW$3,0)-1) | H51: =G51 | J51: =U51 | K51: =Y51 | L51: =AC51 | M51: =AG51 | N51: =AK51 | O51: =AO51 | R51: 372.182 | S51: 384.007 | T51: 453.173 | U51: 507.441 | V51: 491.566 | W51: 428.26 | X51: 410.261 | Y51: 351.401 | Z51: 341.498 | AA51: 335.958 | AB51: 321.433 | AC51: 309.675 | AD51: 326.475 | AE51: 325.545 | AF51: 308.82 | AG51: 331.35 | AH51: 360.457 | AI51: 370.385 | AJ51: 392.47 | AK51: 461.848 | AL51: 475.218 | AM51: 504.514 | AN51: 505.506 | AO51: 454.389 | AP51: 446.803
...

Sheet BBPTACShadowWks0002
K2: ='Marine DCF'!K2 | L2: ='Marine DCF'!L2 | M2: ='Marine DCF'!M2 | N2: ='Marine DCF'!N2 | O2: ='Marine DCF'!O2 | P2: ='Marine DCF'!P2 | Q2: ='Marine DCF'!Q2 | R2: ='Marine DCF'!R2
E3: ='Marine DCF'!E3 | F3: ='Marine DCF'!F3 | G3: ='Marine DCF'!G3 | H3: ='Marine DCF'!H3 | I3: ='Marine DCF'!I3 | J3: ='Marine DCF'!J3 | K3: ='Marine DCF'!K3 | L3: ='Marine DCF'!L3 | ... Q3: ='Marine DCF'!Q3
E4: ='Marine DCF'!E4 | F4: ='Marine DCF'!F4 | G4: ='Marine DCF'!G4 | H4: ='Marine DCF'!H4 | I4: ='Marine DCF'!I4 | J4: ='Marine DCF'!J4 | K4: ='Marine DCF'!K4 | L4: ='Marine DCF'!L4 | ... R4: ='Marine DCF'!R4
F5: ='Marine DCF'!F5 | G5: ='Marine DCF'!G5 | H5: ='Marine DCF'!H5 | I5: ='Marine DCF'!I5 | J5: ='Marine DCF'!J5 | K5: ='Marine DCF'!K5 | L5: ='Marine DCF'!L5 | M5: ='Marine DCF'!M5 | ... Q5: ='Marine DCF'!Q5
E6: ='Marine DCF'!E6 | F6: ='Marine DCF'!F6 | G6: ='Marine DCF'!G6 | H6: ='Marine DCF'!H6 | I6: ='Marine DCF'!I6 | J6: ='Marine DCF'!J6 | K6: ='Marine DCF'!K6 | L6: ='Marine DCF'!L6 | ... R6: ='Marine DCF'!R6
F7: ='Marine DCF'!F7 | G7: ='Marine DCF'!G7 | H7: ='Marine DCF'!H7 | I7: ='Marine DCF'!I7 | J7: ='Marine DCF'!J7 | K7: ='Marine DCF'!K7 | L7: ='Marine DCF'!L7 | M7: ='Marine DCF'!M7 | ... Q7: ='Marine DCF'!Q7
E8: ='Marine DCF'!$E$8 | F8: ='Marine DCF'!F8 | G8: ='Marine DCF'!G8 | H8: ='Marine DCF'!H8 | I8: ='Marine DCF'!I8 | J8: ='Marine DCF'!J8 | K8: ='Marine DCF'!K8 | L8: ='Marine DCF'!L8 | M8: ='Marine DCF'!M8 | ... R8: ='Marine DCF'!R8
F9: ='Marine DCF'!F9 | G9: ='Marine DCF'!G9 | H9: ='Marine DCF'!H9 | I9: ='Marine DCF'!I9 | J9: ='Marine DCF'!J9 | K9: ='Marine DCF'!K9 | L9: ='Marine DCF'!L9 | M9: ='Marine DCF'!M9 | ... R9: ='Marine DCF'!R9
E10: ='Marine DCF'!E10 | F10: ='Marine DCF'!F10 | G10: ='Marine DCF'!G10 | H10: ='Marine DCF'!H10 | I10: ='Marine DCF'!I10 | J10: ='Marine DCF'!J10 | K10: ='Marine DCF'!K10 | L10: ='Marine DCF'!L10 | ... R10: ='Marine DCF'!R10
F11: ='Marine DCF'!F11 | G11: ='Marine DCF'!G11 | H11: ='Marine DCF'!H11 | I11: ='Marine DCF'!I11 | J11: ='Marine DCF'!J11 | K11: ='Marine DCF'!K11 | L11: ='Marine DCF'!L11 | M11: ='Marine DCF'!M11 | ... R11: ='Marine DCF'!R11
E12: ='Marine DCF'!E12 | F12: ='Marine DCF'!F12 | G12: ='Marine DCF'!G12 | H12: ='Marine DCF'!H12 | I12: ='Marine DCF'!I12 | J12: ='Marine DCF'!J12 | K12: ='Marine DCF'!K12 | L12: ='Marine DCF'!L12 | ... R12: ='Marine DCF'!R12
E14: ='Marine DCF'!E14 | F14: ='Marine DCF'!F14 | G14: ='Marine DCF'!G14 | H14: ='Marine DCF'!H14 | I14: ='Marine DCF'!I14 | J14: ='Marine DCF'!J14 | K14: ='Marine DCF'!K14 | L14: ='Marine DCF'!L14 | ... R14: ='Marine DCF'!R14
E15: ='Marine DCF'!E15 | F15: ='Marine DCF'!F15 | G15: ='Marine DCF'!G15 | H15: ='Marine DCF'!H15 | I15: ='Marine DCF'!I15 | J15: ='Marine DCF'!J15 | K15: ='Marine DCF'!K15 | L15: ='Marine DCF'!L15 | ... R15: ='Marine DCF'!R15
E16: ='Marine DCF'!E16 | F16: ='Marine DCF'!F16 | G16: ='Marine DCF'!G16 | H16: ='Marine DCF'!H16 | I16: ='Marine DCF'!I16 | J16: ='Marine DCF'!J16 | K16: ='Marine DCF'!K16 | L16: ='Marine DCF'!L16 | ... R16: ='Marine DCF'!R16
F17: ='Marine DCF'!F17 | G17: ='Marine DCF'!G17 | H17: ='Marine DCF'!H17 | I17: ='Marine DCF'!I17 | J17: ='Marine DCF'!J17 | K17: ='Marine DCF'!K17 | L17: ='Marine DCF'!L17 | M17: ='Marine DCF'!M17 | ... Q17: ='Marine DCF'!Q17
E18: ='Marine DCF'!E18 | F18: ='Marine DCF'!F18 | G18: ='Marine DCF'!G18 | H18: ='Marine DCF'!H18 | I18: ='Marine DCF'!I18 | J18: ='Marine DCF'!J18 | K18: ='Marine DCF'!K18 | L18: ='Marine DCF'!L18 | ... R18: ='Marine DCF'!R18
E19: ='Marine DCF'!E19 | F19: ='Marine DCF'!F19 | G19: ='Marine DCF'!G19 | H19: ='Marine DCF'!H19 | I19: ='Marine DCF'!I19 | J19: ='Marine DCF'!J19 | K19: ='Marine DCF'!K19 | L19: ='Marine DCF'!L19 | ... R19: ='Marine DCF'!R19 | S19: ='Marine DCF'!$S$19
E20: ='Marine DCF'!E20 | F20: ='Marine DCF'!F20 | G20: ='Marine DCF'!G20 | H20: ='Marine DCF'!H20 | I20: ='Marine DCF'!I20 | J20: ='Marine DCF'!J20 | K20: ='Marine DCF'!K20 | L20: ='Marine DCF'!L20 | ... R20: ='Marine DCF'!R20
E21: ='Marine DCF'!E21 | F21: ='Marine DCF'!F21 | G21: ='Marine DCF'!G21 | H21: ='Marine DCF'!H21 | I21: ='Marine DCF'!I21 | J21: ='Marine DCF'!J21 | K21: ='Marine DCF'!K21 | L21: ='Marine DCF'!L21 | ... R21: ='Marine DCF'!R21
E22: ='Marine DCF'!E22 | F22: ='Marine DCF'!F22 | G22: ='Marine DCF'!G22 | H22: ='Marine DCF'!H22 | I22: ='Marine DCF'!I22 | J22: ='Marine DCF'!J22 | K22: ='Marine DCF'!K22 | L22: ='Marine DCF'!L22 | ... R22: ='Marine DCF'!R22
K24: ='Marine DCF'!K24 | L24: ='Marine DCF'!L24 | M24: ='Marine DCF'!M24 | N24: ='Marine DCF'!N24 | O24: ='Marine DCF'!O24 | P24: ='Marine DCF'!P24 | Q24: ='Marine DCF'!Q24 | R24: ='Marine DCF'!R24 | S24: ='Marine DCF'!S24
K26: ='Marine DCF'!K25 | L26: ='Marine DCF'!L25 | M26: ='Marine DCF'!M25 | N26: ='Marine DCF'!N25 | O26: ='Marine DCF'!O25 | P26: ='Marine DCF'!P25 | Q26: ='Marine DCF'!Q25 | R26: ='Marine DCF'!R25 | S26: ='Marine DCF'!S26
E28: ='Marine DCF'!E27
E29: ='Marine DCF'!#REF!
E30: ='Marine DCF'!E28

Sheet Marine DCF
A2: x | B2: Marine Transport DCF | K2: 1 | L2: =K2+1 | M2: =L2+1 | N2: =M2+1 | O2: =N2+1 | P2: =O2+1 | Q2: =P2+1 | R2: =Q2+1
E3: 2018 | F3: =E3+1 | G3: =F3+1 | H3: =G3+1 | I3: =H3+1 | J3: =I3+1 | K3: =J3+1 | L3: =K3+1 | M3: =L3+1 | ... Q3: =P3+1 | R3: LT Normalized
B4: Ton Miles | E4: ='Model Shell'!J112 | F4: ='Model Shell'!K112 | G4: ='Model Shell'!L112 | H4: ='Model Shell'!M112 | I4: ='Model Shell'!N112 | J4: ='Model Shell'!O112 | K4: =J4*(1+K5) | L4: =K4*(1+L5) | M4: =L4*(1+M5) | N4: =M4*(1+N5) | O4: =N4*(1+O5) | P4: =O4*(1+P5) | Q4: =P4*(1+Q5) | R4: =Q4
C5: % Growth | F5: =F4/E4-1 | G5: =G4/F4-1 | H5: =H4/G4-1 | I5: =I4/H4-1 | J5: =J4/I4-1 | K5: 0.02 | L5: 0.02 | M5: 0.02 | N5: 0.02 | O5: 0.02 | P5: 0.02 | Q5: 0.02
B6: Pricing | E6: ='Model Shell'!J113 | F6: ='Model Shell'!K113 | G6: ='Model Shell'!L113 | H6: ='Model Shell'!M113 | I6: ='Model Shell'!N113 | J6: ='Model Shell'!O113 | K6: =J6*(1+K7) | L6: =K6*(1+L7) | M6: =L6*(1+M7) | N6: =M6*(1+N7) | O6: =N6*(1+O7) | P6: =O6*(1+P7) | Q6: =P6*(1+Q7) | R6: =Q6
C7: % Growth | F7: =F6/E6-1 | G7: =G6/F6-1 | H7: =H6/G6-1 | I7: =I6/H6-1 | J7: =J6/I6-1 | K7: 0.07 | L7: 0.07 | M7: 0.05 | N7: 0.04 | O7: 0.03 | P7: 0 | Q7: 0
B8: Inland Revenue | E8: =E6*E4/100 | F8: =F6*F4/100 | G8: =G6*G4/100 | H8: =H6*H4/100 | I8: =I6*I4/100 | J8: =J6*J4/100 | K8: =K6*K4/100 | L8: =L6*L4/100 | ... R8: =R6*R4/100
F9: =F8/E8-1 | G9: =G8/F8-1 | H9: =H8/G8-1 | I9: =I8/H8-1 | J9: =J8/I8-1 | K9: =K8/J8-1 | L9: =L8/K8-1 | M9: =M8/L8-1 | ... R9: =R8/Q8-1
B10: (+) Coastal Revenue | E10: ='Model Shell'!J115 | F10: ='Model Shell'!K115 | G10: ='Model Shell'!L115 | H10: ='Model Shell'!M115 | I10: ='Model Shell'!N115 | J10: ='Model Shell'!O115 | K10: =J10*(1+K11) | L10: =K10*(1+L11) | M10: =L10*(1+M11) | N10: =M10*(1+N11) | O10: =N10*(1+O11) | P10: =O10*(1+P11) | Q10: =P10*(1+Q11) | R10: =350
C11: % Growth | F11: =F10/E10-1 | G11: =G10/F10-1 | H11: =H10/G10-1 | I11: =I10/H10-1 | J11: =J10/I10-1 | K11: 0.04 | L11: 0 | M11: 0 | N11: 0 | O11: 0 | P11: 0 | Q11: 0 | R11: =R10/Q10-1
B12: Total Revenue | E12: =E10+E8 | F12: =F10+F8 | G12: =G10+G8 | H12: =H10+H8 | I12: =I10+I8 | J12: =J10+J8 | K12: =K10+K8 | L12: =L10+L8 | ... R12: =R10+R8
B14: EBIT | E14: =E12*E15 | F14: =F12*F15 | G14: =G12*G15 | H14: =H12*H15 | I14: =I12*I15 | J14: =J12*J15 | K14: =K12*K15 | L14: =L12*L15 | ... R14: =R12*R15
C15: EBIT Margin % | E15: ='Model Shell'!J96/'Model Shell'!J91 | F15: ='Model Shell'!K96/'Model Shell'!K91 | G15: ='Model Shell'!L96/'Model Shell'!L91 | H15: ='Model Shell'!M96/'Model Shell'!M91 | I15: ='Model Shell'!N96/'Model Shell'!N91 | J15: ='Model Shell'!O96/'Model Shell'!O91 | K15: 0.17 | L15: 0.18 | M15: 0.19 | N15: 0.2 | O15: 0.2 | P15: 0.2 | Q15: 0.2 | R15: 0.13
B16: (+) D&A | E16: ='Model Shell'!J97 | F16: ='Model Shell'!K97 | G16: ='Model Shell'!L97 | H16: ='Model Shell'!M97 | I16: ='Model Shell'!N97 | J16: ='Model Shell'!O97 | K16: =J16+K17 | L16: =K16+L17 | M16: =L16+M17 | N16: =M16+N17 | O16: =N16+O17 | P16: =O16+P17 | Q16: =P16+Q17 | R16: =Q16
C17: Step-up $mm | F17: =F16-E16 | G17: =G16-F16 | H17: =H16-G16 | I17: =I16-H16 | J17: =J16-I16 | K17: 10 | L17: 10 | M17: 10 | N17: 10 | O17: 10 | P17: 10 | Q17: 10
B18: EBITDA | E18: =E16+E14 | F18: =F16+F14 | G18: =G16+G14 | H18: =H16+H14 | I18: =I16+I14 | J18: =J16+J14 | K18: =K16+K14 | L18: =L16+L14 | ... R18: =R16+R14 | S18: Tax on EBITDA
B19: (-) Tax | E19: 0 | F19: 0 | G19: 0 | H19: 0 | I19: 0 | J19: 0 | K19: 0 | L19: 0 | M19: 0 | N19: =N18*(-$S$19) | O19: =O18*(-$S$19) | P19: =P18*(-$S$19) | Q19: =Q18*(-$S$19) | R19: =R18*(-$S$19) | S19: 0.1
B20: (-) mCAPEX | E20: -150 | F20: -150 | G20: -150 | H20: -150 | I20: -150 | J20: -240 | K20: -240 | L20: -240 | M20: -200 | N20: -200 | O20: -200 | P20: -200 | Q20: -200 | R20: -150
B21: FCFF | E21: =SUM(E18:E20) | F21: =SUM(F18:F20) | G21: =SUM(G18:G20) | H21: =SUM(H18:H20) | I21: =SUM(I18:I20) | J21: =SUM(J18:J20) | K21: =SUM(K18:K20) | L21: =SUM(L18:L20) | ... R21: =SUM(R18:R20)
C22: Conversion % | E22: =E21/E18 | F22: =F21/F18 | G22: =G21/G18 | H22: =H21/H18 | I22: =I21/I18 | J22: =J21/J18 | K22: =K21/K18 | L22: =L21/L18 | ... R22: =R21/R18
S23: Disc Rate
B24: PV Factor | K24: =1/(1+$S$24)^K2 | L24: =1/(1+$S$24)^L2 | M24: =1/(1+$S$24)^M2 | N24: =1/(1+$S$24)^N2 | O24: =1/(1+$S$24)^O2 | P24: =1/(1+$S$24)^P2 | Q24: =1/(1+$S$24)^Q2 | R24: =1/(1+$S$24)^R2 | S24: 0.08
B25: PV | K25: =K21*K24 | L25: =L21*L24 | M25: =M21*M24 | N25: =N21*N24 | O25: =O21*O24 | P25: =P21*P24 | Q25: =Q21*Q24 | R25: =(R21/(S24-S26))*Q24 | S25: Terminal G
S26: 0.02
A27: x | B27: TEV | E27: =SUM(K25:R25)
C28: Impl FCF Yield | E28: =K21/E27
