Workbook
Name _2001_MODEL: #REF!
Name _4WORD_M_001_07: #N/A
Name _4WORD_O_005_L_: #N/A
Name _CHANGE: #REF!
Name _PB1: #REF!
Name _PB2: #REF!
Name _TOP12: #REF!
Name _TOP14: #REF!
Name _TOP15: #REF!
Name _TOP16: #REF!
Name _TOP17: #REF!
Name _TOP18: #REF!
Name AAAForecast: #REF!
Name ACE: #REF!
Name ACEE: #REF!
Name Acquirer: #REF!
Name ALL: #REF!
Name ALLE: #REF!
Name allearnings: #REF!
Name allquarter: #REF!
Name Annuities: #REF!
Name Argentina: #REF!
Name AssetAnal9: #REF!
Name AssetGathering: #REF!
Name AssetMngmt: #REF!
Name AssetsManaged: #REF!
Name asumpmatrix: #REF!
Name AUM: #REF!
Name Auto: #REF!
Name AutoHome: #REF!
Name AxesFormat: #REF!
Name BalanceSheet: #REF!
Name BODY: #REF!
Name Business_Line: #REF!
Name BV: #REF!
Name CapStruc10: #REF!
Name cash: #REF!
Name Cashflow: #REF!
Name CB: #REF!
Name CBE: #REF!
Name Charts1: #REF!
Name Charts2: #REF!
Name Chile1: #REF!
Name Chile2: #REF!
Name CINF: #REF!
Name CINFE: #REF!
Name Closed_End: #REF!
Name ClosedBlock: #REF!
Name CLval: #REF!
Name CNF: #REF!
Name Comm_Lines: #N/A
Name Commercial_lines: RANGE33
Name Consolidated: #REF!
Name ConsolidatedBal: #REF!
Name ConsolidatedInc: #REF!
Name ConsolidatedSales: #REF!
Name ConsolIncome: #REF!
Name ConvDate: #REF!
Name Current_GS: #REF!
Name Current_JW: #REF!

Sheet Segments
S1: 14Y | X1: 15Y | Y1: CQ1 | Z1: CQ2 | AA1: CQ3 | AB1: CQ4 | AC1: 16Y | AD1: CQ1 | AE1: CQ2 | AF1: CQ3 | AG1: CQ4 | AH1: 17Y | AI1: CQ1 | AJ1: CQ2 | AK1: CQ3 | AL1: CQ4 | AM1: 18Y | AN1: CQ1 | AO1: CQ2 | AP1: CQ3 | AQ1: CQ4 | AR1: 19Y | AS1: CQ1 | AT1: CQ2 | AU1: CQ3 | AV1: CQ4 | AW1: 20Y
B3: Moody's (MCO)
B4: Segments
B5: ($ in Millions, except per share data)
E6: 2012A | J6: 2013A | O6: 2014A | T6: 2015A | Y6: 2016A | AD6: 2017A | AI6: 2018A | AN6: 2019A | AS6: 2020A | AX6: 2021A | BC6: 2022A | BH6: 2023A | BM6: 2024A | BR6: 2025E | BW6: 2026E | CB6: 2027E
E7: 1Q12A | F7: 2Q12A | G7: 3Q12A | H7: 4Q12A | I7: 2012A | J7: 1Q13A | K7: 2Q13A | L7: 3Q13A | M7: 4Q13A | N7: 2013A | O7: 1Q14A | P7: 2Q14A | Q7: 3Q14A | R7: 4Q14A | S7: 2014A | T7: 1Q15A | U7: 2Q15A | V7: 3Q15A | W7: 4Q15A | X7: 2015A | Y7: 1Q16A | Z7: 2Q16A | AA7: 3Q16A | AB7: 4Q16A | AC7: 2016A | AD7: 1Q17A | AE7: 2Q17A | AF7: 3Q17A | AG7: 4Q17A | AH7: 2017A | AI7: 1Q18A | AJ7: 2Q18A | AK7: 3Q18A | AL7: 4Q18A | AM7: 2018A | AN7: 1Q19A | AO7: 2Q19A | AP7: 3Q19A | AQ7: 4Q19A | AR7: 2019A | AS7: 1Q20A | AT7: 2Q20A | AU7: 3Q20A | AV7: 4Q20A | AW7: 2020A | AX7: 1Q21A | AY7: 2Q21A | AZ7: 3Q21A | BA7: 4Q21A | BB7: 2021A | BC7: 1Q22A | BD7: 2Q22A | BE7: 3Q22A | BF7: 4Q22A | BG7: 2022A | BH7: 1Q23A | BI7: 2Q23A | BJ7: 3Q23A | BK7: 4Q23A | BL7: 2023A | BM7: 1Q24A | BN7: 2Q24A | BO7: 3Q24A | BP7: 4Q24A | BQ7: 2024A | BR7: 1Q25A | BS7: 2Q25A | BT7: 3Q25E | BU7: 4Q25E | BV7: 2025E | BW7: 1Q26E | BX7: 2Q26E | BY7: 3Q26E | BZ7: 4Q26E | CA7: 2026E | CB7: 1Q27E | CC7: 2Q27E | CD7: 3Q27E | CE7: 4Q27E | CF7: 2027E
B8: MOODY'S INVESTOR SERVICE (MIS, RATINGS)
B9: MIS-rated Issuance (in $bln) | AI9: 1400 | AJ9: 1300 | AK9: 1100 | AL9: 856 | AM9: =SUM(AI9:AL9) -> 4656 | AN9: =AS9/(1+AS10) -> 1229.661 | AO9: 1168 | AP9: 1189 | AQ9: 1013 | AR9: =SUM(AN9:AQ9) -> 4599.661 | AS9: 1451 | AT9: 1843 | AU9: 1270 | AV9: 983 | AW9: =SUM(AS9:AV9) -> 5547 | AX9: 1803 | AY9: 1595 | AZ9: 1436 | BA9: 1211 | BB9: =SUM(AX9:BA9) -> 6045 | BC9: 1409 | BD9: 1111 | BE9: 859 | BF9: 791 | BG9: =SUM(BC9:BF9) -> 4170 | BH9: 1264 | BI9: 1173 | BJ9: 994 | BK9: 942 | BL9: =SUM(BH9:BK9) -> 4373 | BM9: 1767 | BN9: 1708 | BO9: 1537 | BP9: 1253 | BQ9: =SUM(BM9:BP9) -> 6265 | BR9: 1924 | BS9: 1511 | BT9: 1764
B10: % y/y | AN10: =AN9/AI9-1 -> -0.1216707 | AO10: =AO9/AJ9-1 -> -0.10153846 | AP10: =AP9/AK9-1 -> 0.080909091 | AQ10: =AQ9/AL9-1 -> 0.18341121 | AR10: =AR9/AM9-1 -> -0.012100297 | AS10: 0.18 | AT10: =AT9/AO9-1 -> 0.57791096 | AU10: =AU9/AP9-1 -> 0.068124474 | AV10: =AV9/AQ9-1 -> -0.029615005 | AW10: =AW9/AR9-1 -> 0.20595843 | AX10: =AX9/AS9-1 -> 0.24259132 | AY10: =AY9/AT9-1 -> -0.13456321 | AZ10: =AZ9/AU9-1 -> 0.13070866 | BA10: =BA9/AV9-1 -> 0.23194303 | ... BT10: =BT9/BO9-1 -> 0.14769031
B11: % qtr/qtr | AJ11: =AJ9/AI9-1 -> -0.071428571 | AK11: =AK9/AJ9-1 -> -0.15384615 | AL11: =AL9/AK9-1 -> -0.22181818 | AN11: =AN9/AL9-1 -> 0.43651988 | AO11: =AO9/AN9-1 -> -0.050144728 | AP11: =AP9/AO9-1 -> 0.017979452 | AQ11: =AQ9/AP9-1 -> -0.14802355 | AS11: =AS9/AQ9-1 -> 0.43237907 | AT11: =AT9/AS9-1 -> 0.27015851 | AU11: =AU9/AT9-1 -> -0.31090613 | AV11: =AV9/AU9-1 -> -0.22598425 | AX11: =AX9/AV9-1 -> 0.83418108 | AY11: =AY9/AX9-1 -> -0.11536328 | AZ11: =AZ9/AY9-1 -> -0.09968652 | BA11: =BA9/AZ9-1 -> -0.15668524 | BC11: =BC9/BA9-1 -> 0.16350124 | BD11: =BD9/BC9-1 -> -0.21149752 | BE11: =BE9/BD9-1 -> -0.22682268 | BF11: =BF9/BE9-1 -> -0.079161816 | BH11: =BH9/BF9-1 -> 0.59797724 | BI11: =BI9/BH9-1 -> -0.071993671 | BJ11: =BJ9/BI9-1 -> -0.15260017 | BK11: =BK9/BJ9-1 -> -0.052313883 | BM11: =BM9/BK9-1 -> 0.87579618 | BN11: =BN9/BM9-1 -> -0.033389926 | BO11: =BO9/BN9-1 -> -0.1001171 | BP11: =BP9/BO9-1 -> -0.18477554 | BR11: =BR9/BP9-1 -> 0.53551476 | BS11: =BS9/BR9-1 -> -0.21465696 | BT11: =BT9/BS9-1 -> 0.16743878
B12: Take Rate (total revenues / total issuance; in bps) | AI12: =AI60/AI9*10 -> 5.355 | AJ12: =AJ60/AJ9*10 -> 6.0223077 | AK12: =AK60/AK9*10 -> 6.1490909 | AL12: =AL60/AL9*10 -> 7.3294393 | AM12: =AM60/AM9*10 -> 6.0919244 | AN12: =AN60/AN9*10 -> 5.7121433 | AO12: =AO60/AO9*10 -> 6.6044521 | AP12: =AP60/AP9*10 -> 6.567704 | ... BT12: =BT60/BT9*10 -> 6.4876984
B13: Implied Realized Price % Y/Y | AN13: =AN12/AI12-1 -> 0.066693436 | AO13: =AO12/AJ12-1 -> 0.096664666 | AP13: =AP12/AK12-1 -> 0.068077225 | AQ13: =AQ12/AL12-1 -> 0.016873095 | AR13: =AR12/AM12-1 -> 0.07409545 | AS13: =AS12/AN12-1 -> 0.0026157291 | AT13: =AT12/AO12-1 -> -0.20062472 | AU13: =AU12/AP12-1 -> 0.033451207 | ... BT13: =BT12/BO12-1 -> -0.031884227
B14: Mix Impact (% y/y change in Transaction revs - % y/y change in issuance) | AN14: =AN28-AN10 -> 0.0069838771 | AO14: =AO28-AO10 -> 0.06463586 | AP14: =AP28-AP10 -> 0.1446991 | AQ14: =AQ28-AQ10 -> 0.1323001 | AR14: =AR28-AR10 -> 0.085049707 | AS14: =AS28-AS10 -> 0.086162479 | AT14: =AT28-AT10 -> -0.1876262 | AU14: =AU28-AU10 -> 0.076881794 | ... BT14: =BT28-BT10 -> -0.012690306
B16: Corporates (2024: 73% transaction) | C16: =BQ16/BQ$31 -> 0.51410493 | E16: 200.5 | F16: 191.5 | G16: 220.7 | H16: 244.9 | I16: =SUM(E16:H16) -> 857.6 | J16: 258.3 | K16: 262.9 | L16: 232.9 | M16: 242.6 | N16: =SUM(J16:M16) -> 996.7 | O16: 264.4 | P16: 320.9 | Q16: 260.7 | R16: 263.3 | S16: =SUM(O16:R16) -> 1109.3 | T16: 298.7 | U16: 319.6 | V16: 248.3 | W16: 246.1 | X16: =SUM(T16:W16) -> 1112.7 | Y16: 240.3 | Z16: 304.8 | AA16: 299.6 | AB16: 277.6 | AC16: =SUM(Y16:AB16) -> 1122.3 | AD16: 352.8 | AE16: 355.8 | AF16: 350.2 | AG16: 333.9 | AH16: =SUM(AD16:AG16) -> 1392.7 | AI16: 389.6 | AJ16: 391 | AK16: =78+39+55+135 -> 307 | AL16: =145+57+19+70 -> 291 | AM16: =SUM(AI16:AL16) -> 1378.6 | AN16: 355.4 | AO16: 387.4 | AP16: 392 | AQ16: 362 | AR16: =SUM(AN16:AQ16) -> 1496.8 | AS16: 453 | AT16: 572 | AU16: 461 | AV16: 371 | AW16: =SUM(AS16:AV16) -> 1857 | AX16: 605 | AY16: 550 | AZ16: 488 | BA16: 444 | BB16: =SUM(AX16:BA16) -> 2087 | BC16: 417 | BD16: 322 | BE16: 277 | BF16: 253 | BG16: =SUM(BC16:BF16) -> 1269 | BH16: 356 | BI16: 365 | BJ16: 346 | BK16: 337 | BL16: =SUM(BH16:BK16) -> 1404 | BM16: 529 | BN16: 525 | BO16: 515 | BP16: 381 | BQ16: =SUM(BM16:BP16) -> 1950 | BR16: 564 | BS16: 512 | BT16: 576
B17: % y/y | J17: =J16/E16-1 -> 0.2882793 | K17: =K16/F16-1 -> 0.37284595 | L17: =L16/G16-1 -> 0.055278659 | M17: =M16/H16-1 -> -0.0093915884 | N17: =N16/I16-1 -> 0.16219683 | O17: =O16/J16-1 -> 0.02361595 | P17: =P16/K16-1 -> 0.2206162 | Q17: =Q16/L16-1 -> 0.11936453 | ... AC17: =AC16/X16-1 -> 0.0086276624 | AD17: =IFERROR( AD16/Y16-1, "NA") -> 0.46816479 | AE17: =IFERROR( AE16/Z16-1, "NA") -> 0.16732283 | AF17: =IFERROR( AF16/AA16-1, "NA") -> 0.16889186 | AG17: =IFERROR( AG16/AB16-1, "NA") -> 0.2028098 | AH17: =AH16/AC16-1 -> 0.2409338 | AI17: =IFERROR( AI16/AD16-1, "NA") -> 0.10430839 | AJ17: =IFERROR( AJ16/AE16-1, "NA") -> 0.098931984 | AK17: =IFERROR( AK16/AF16-1, "NA") -> -0.12335808 | AL17: =IFERROR( AL16/AG16-1, "NA") -> -0.12848158 | AM17: =AM16/AH16-1 -> -0.010124219 | AN17: =IFERROR( AN16/AI16-1, "NA") -> -0.087782341 | AO17: =IFERROR( AO16/AJ16-1, "NA") -> -0.0092071611 | AP17: =IFERROR( AP16/AK16-1, "NA") -> 0.27687296 | AQ17: =IFERROR( AQ16/AL16-1, "NA") -> 0.24398625 | AR17: =AR16/AM16-1 -> 0.085739156 | AS17: =IFERROR( AS16/AN16-1, "NA") -> 0.27462015 | AT17: =IFERROR( AT16/AO16-1, "NA") -> 0.47651007 | AU17: =IFERROR( AU16/AP16-1, "NA") -> 0.17602041 | AV17: =IFERROR( AV16/AQ16-1, "NA") -> 0.024861878 | AW17: =AW16/AR16-1 -> 0.24064671 | AX17: =IFERROR( AX16/AS16-1, "NA") -> 0.33554084 | AY17: =IFERROR( AY16/AT16-1, "NA") -> -0.038461538 | AZ17: =IFERROR( AZ16/AU16-1, "NA") -> 0.05856833 | BA17: =IFERROR( BA16/AV16-1, "NA") -> 0.1967655 | BB17: =BB16/AW16-1 -> 0.12385568 | BC17: =IFERROR( BC16/AX16-1, "NA") -> -0.3107438 | BD17: =IFERROR( BD16/AY16-1, "NA") -> -0.41454545 | BE17: =IFERROR( BE16/AZ16-1, "NA") -> -0.43237705 | BF17: =IFERROR( BF16/BA16-1, "NA") -> -0.43018018 | BG17: =BG16/BB16-1 -> -0.39195017 | BH17: =IFERROR( BH16/BC16-1, "NA") -> -0.14628297 | BI17: =IFERROR( BI16/BD16-1, "NA") -> 0.13354037 | BJ17: =IFERROR( BJ16/BE16-1, "NA") -> 0.24909747 | BK17: =IFERROR( BK16/BF16-1, "NA") -> 0.33201581 | BL17: =BL16/BG16-1 -> 0.10638298 | BM17: =IFERROR( BM16/BH16-1, "NA") -> 0.48595506 | BN17: =IFERROR( BN16/BI16-1, "NA") -> 0.43835616 | BO17: =IFERROR( BO16/BJ16-1, "NA") -> 0.48843931 | BP17: =IFERROR( BP16/BK16-1, "NA") -> 0.1305638 | BQ17: =BQ16/BL16-1 -> 0.38888889 | BR17: =IFERROR( BR16/BM16-1, "NA") -> 0.066162571 | BS17: =IFERROR( BS16/BN16-1, "NA") -> -0.024761905 | BT17: =IFERROR( BT16/BO16-1, "NA") -> 0.1184466
B18: Financial services (2024: 57% transaction) | C18: =BQ18/BQ$31 -> 0.19166886 | E18: 78.7 | F18: 77.9 | G18: 82.6 | H18: 86.2 | I18: =SUM(E18:H18) -> 325.4 | J18: 86.5 | K18: 84.5 | L18: 78.9 | M18: 88.9 | N18: =SUM(J18:M18) -> 338.8 | O18: 85.4 | P18: 92.2 | Q18: 91.8 | R18: 85.3 | S18: =SUM(O18:R18) -> 354.7 | T18: 93.8 | U18: 90.4 | V18: 89.5 | W18: 91.9 | X18: =SUM(T18:W18) -> 365.6 | Y18: 94.9 | Z18: 89.7 | AA18: 95.8 | AB18: 88.5 | AC18: =SUM(Y18:AB18) -> 368.9 | AD18: 112.3 | AE18: 102.4 | AF18: 102.1 | AG18: 119 | AH18: =SUM(AD18:AG18) -> 435.8 | AI18: 114.3 | AJ18: 120.6 | AK18: =73+38+6+3 -> 120 | AL18: =63+15+6+3 -> 87 | AM18: =SUM(AI18:AL18) -> 441.9 | AN18: 115.8 | AO18: 125.2 | AP18: 120.5 | AQ18: 115 | AR18: =SUM(AN18:AQ18) -> 476.5 | AS18: 125 | AT18: 142 | AU18: 134 | AV18: 129 | AW18: =SUM(AS18:AV18) -> 530 | AX18: 162 | AY18: 150 | AZ18: 153 | BA18: 137 | BB18: =SUM(AX18:BA18) -> 602 | BC18: 131 | BD18: 128 | BE18: 109 | BF18: 123 | BG18: =SUM(BC18:BF18) -> 491 | BH18: 142 | BI18: 145 | BJ18: 126 | BK18: 132 | BL18: =SUM(BH18:BK18) -> 545 | BM18: 195 | BN18: 195 | BO18: 170 | BP18: 167 | BQ18: =SUM(BM18:BP18) -> 727 | BR18: 191 | BS18: 191 | BT18: 208
B19: % y/y | J19: =J18/E18-1 -> 0.099110546 | K19: =K18/F18-1 -> 0.084724005 | L19: =L18/G18-1 -> -0.044794189 | M19: =M18/H18-1 -> 0.031322506 | N19: =N18/I18-1 -> 0.041180086 | O19: =O18/J18-1 -> -0.012716763 | P19: =P18/K18-1 -> 0.09112426 | Q19: =Q18/L18-1 -> 0.1634981 | ... AC19: =AC18/X18-1 -> 0.0090262582 | AD19: =IFERROR( AD18/Y18-1, "NA") -> 0.1833509 | AE19: =IFERROR( AE18/Z18-1, "NA") -> 0.14158305 | AF19: =IFERROR( AF18/AA18-1, "NA") -> 0.065762004 | AG19: =IFERROR( AG18/AB18-1, "NA") -> 0.34463277 | AH19: =AH18/AC18-1 -> 0.18134996 | AI19: =IFERROR( AI18/AD18-1, "NA") -> 0.017809439 | AJ19: =IFERROR( AJ18/AE18-1, "NA") -> 0.17773437 | AK19: =IFERROR( AK18/AF18-1, "NA") -> 0.17531832 | AL19: =IFERROR( AL18/AG18-1, "NA") -> -0.26890756 | AM19: =AM18/AH18-1 -> 0.013997246 | AN19: =IFERROR( AN18/AI18-1, "NA") -> 0.01312336 | AO19: =IFERROR( AO18/AJ18-1, "NA") -> 0.03814262 | AP19: =IFERROR( AP18/AK18-1, "NA") -> 0.0041666667 | AQ19: =IFERROR( AQ18/AL18-1, "NA") -> 0.32183908 | AR19: =AR18/AM18-1 -> 0.078298258 | AS19: =IFERROR( AS18/AN18-1, "NA") -> 0.079447323 | AT19: =IFERROR( AT18/AO18-1, "NA") -> 0.1341853 | AU19: =IFERROR( AU18/AP18-1, "NA") -> 0.1120332 | AV19: =IFERROR( AV18/AQ18-1, "NA") -> 0.12173913 | AW19: =AW18/AR18-1 -> 0.11227702 | AX19: =IFERROR( AX18/AS18-1, "NA") -> 0.296 | AY19: =IFERROR( AY18/AT18-1, "NA") -> 0.056338028 | AZ19: =IFERROR( AZ18/AU18-1, "NA") -> 0.14179104 | BA19: =IFERROR( BA18/AV18-1, "NA") -> 0.062015504 | BB19: =BB18/AW18-1 -> 0.13584906 | BC19: =IFERROR( BC18/AX18-1, "NA") -> -0.19135802 | BD19: =IFERROR( BD18/AY18-1, "NA") -> -0.14666667 | BE19: =IFERROR( BE18/AZ18-1, "NA") -> -0.2875817 | BF19: =IFERROR( BF18/BA18-1, "NA") -> -0.10218978 | BG19: =BG18/BB18-1 -> -0.18438538 | BH19: =IFERROR( BH18/BC18-1, "NA") -> 0.083969466 | BI19: =IFERROR( BI18/BD18-1, "NA") -> 0.1328125 | BJ19: =IFERROR( BJ18/BE18-1, "NA") -> 0.1559633 | BK19: =IFERROR( BK18/BF18-1, "NA") -> 0.073170732 | BL19: =BL18/BG18-1 -> 0.10997963 | BM19: =IFERROR( BM18/BH18-1, "NA") -> 0.37323944 | BN19: =IFERROR( BN18/BI18-1, "NA") -> 0.34482759 | BO19: =IFERROR( BO18/BJ18-1, "NA") -> 0.34920635 | BP19: =IFERROR( BP18/BK18-1, "NA") -> 0.26515152 | BQ19: =BQ18/BL18-1 -> 0.33394495 | BR19: =IFERROR( BR18/BM18-1, "NA") -> -0.020512821 | BS19: =IFERROR( BS18/BN18-1, "NA") -> -0.020512821 | BT19: =IFERROR( BT18/BO18-1, "NA") -> 0.22352941
B20: Structured (2024: 56% transaction) | C20: =BQ20/BQ$31 -> 0.13656736 | E20: 94.2 | F20: 90.8 | G20: 93 | H20: 102.9 | I20: =SUM(E20:H20) -> 380.9 | J20: 93 | K20: 97.2 | L20: 83.5 | M20: 108.7 | N20: =SUM(J20:M20) -> 382.4 | O20: 95.3 | P20: 110.6 | Q20: 102.1 | R20: 118.5 | S20: =SUM(O20:R20) -> 426.5 | T20: 101.3 | U20: 121.2 | V20: 112.5 | W20: 114.1 | X20: =SUM(T20:W20) -> 449.1 | Y20: 90.6 | Z20: 111.5 | AA20: 104.2 | AB20: 130.5 | AC20: =SUM(Y20:AB20) -> 436.8 | AD20: 100.2 | AE20: 119.2 | AF20: 128.3 | AG20: 147.8 | AH20: =SUM(AD20:AG20) -> 495.5 | AI20: 117.8 | AJ20: 128.2 | AK20: =1+51+15+24+25 -> 116 | AL20: =48+24+23+26 -> 121 | AM20: =SUM(AI20:AL20) -> 483 | AN20: 100.7 | AO20: 112.1 | AP20: 105.4 | AQ20: 109 | AR20: =SUM(AN20:AQ20) -> 427.2 | AS20: 96 | AT20: 81 | AU20: 88 | AV20: 97 | AW20: =SUM(AS20:AV20) -> 362 | AX20: 116 | AY20: 140 | AZ20: 143 | BA20: 161 | BB20: =SUM(AX20:BA20) -> 560 | BC20: 144 | BD20: 123 | BE20: 101 | BF20: 94 | BG20: =SUM(BC20:BF20) -> 462 | BH20: 99 | BI20: 102 | BJ20: 102 | BK20: 102 | BL20: =SUM(BH20:BK20) -> 405 | BM20: 114 | BN20: 131 | BO20: 135 | BP20: 138 | BQ20: =SUM(BM20:BP20) -> 518 | BR20: 138 | BS20: 135 | BT20: 146
B21: % y/y | J21: =J20/E20-1 -> -0.012738854 | K21: =K20/F20-1 -> 0.070484581 | L21: =L20/G20-1 -> -0.10215054 | M21: =M20/H20-1 -> 0.056365403 | N21: =N20/I20-1 -> 0.0039380415 | O21: =O20/J20-1 -> 0.024731183 | P21: =P20/K20-1 -> 0.13786008 | Q21: =Q20/L20-1 -> 0.22275449 | ... AC21: =AC20/X20-1 -> -0.02738811 | AD21: =IFERROR( AD20/Y20-1, "NA") -> 0.10596026 | AE21: =IFERROR( AE20/Z20-1, "NA") -> 0.069058296 | AF21: =IFERROR( AF20/AA20-1, "NA") -> 0.23128599 | AG21: =IFERROR( AG20/AB20-1, "NA") -> 0.13256705 | AH21: =AH20/AC20-1 -> 0.13438645 | AI21: =IFERROR( AI20/AD20-1, "NA") -> 0.1756487 | AJ21: =IFERROR( AJ20/AE20-1, "NA") -> 0.075503356 | AK21: =IFERROR( AK20/AF20-1, "NA") -> -0.095869057 | AL21: =IFERROR( AL20/AG20-1, "NA") -> -0.18132612 | AM21: =AM20/AH20-1 -> -0.025227043 | AN21: =IFERROR( AN20/AI20-1, "NA") -> -0.14516129 | AO21: =IFERROR( AO20/AJ20-1, "NA") -> -0.12558502 | AP21: =IFERROR( AP20/AK20-1, "NA") -> -0.09137931 | AQ21: =IFERROR( AQ20/AL20-1, "NA") -> -0.099173554 | AR21: =AR20/AM20-1 -> -0.11552795 | AS21: =IFERROR( AS20/AN20-1, "NA") -> -0.046673287 | AT21: =IFERROR( AT20/AO20-1, "NA") -> -0.27743087 | AU21: =IFERROR( AU20/AP20-1, "NA") -> -0.16508539 | AV21: =IFERROR( AV20/AQ20-1, "NA") -> -0.11009174 | AW21: =AW20/AR20-1 -> -0.15262172 | AX21: =IFERROR( AX20/AS20-1, "NA") -> 0.20833333 | AY21: =IFERROR( AY20/AT20-1, "NA") -> 0.72839506 | AZ21: =IFERROR( AZ20/AU20-1, "NA") -> 0.625 | BA21: =IFERROR( BA20/AV20-1, "NA") -> 0.65979381 | BB21: =BB20/AW20-1 -> 0.54696133 | BC21: =IFERROR( BC20/AX20-1, "NA") -> 0.24137931 | BD21: =IFERROR( BD20/AY20-1, "NA") -> -0.12142857 | BE21: =IFERROR( BE20/AZ20-1, "NA") -> -0.29370629 | BF21: =IFERROR( BF20/BA20-1, "NA") -> -0.41614907 | BG21: =BG20/BB20-1 -> -0.175 | BH21: =IFERROR( BH20/BC20-1, "NA") -> -0.3125 | BI21: =IFERROR( BI20/BD20-1, "NA") -> -0.17073171 | BJ21: =IFERROR( BJ20/BE20-1, "NA") -> 0.0099009901 | BK21: =IFERROR( BK20/BF20-1, "NA") -> 0.085106383 | BL21: =BL20/BG20-1 -> -0.12337662 | BM21: =IFERROR( BM20/BH20-1, "NA") -> 0.15151515 | BN21: =IFERROR( BN20/BI20-1, "NA") -> 0.28431373 | BO21: =IFERROR( BO20/BJ20-1, "NA") -> 0.32352941 | BP21: =IFERROR( BP20/BK20-1, "NA") -> 0.35294118 | BQ21: =BQ20/BL20-1 -> 0.27901235 | BR21: =IFERROR( BR20/BM20-1, "NA") -> 0.21052632 | BS21: =IFERROR( BS20/BN20-1, "NA") -> 0.030534351 | BT21: =IFERROR( BT20/BO20-1, "NA") -> 0.081481481
B22: Governments/public/other (2024: 68% transaction) | C22: =BQ22/BQ$31 -> 0.15765885 | E22: 79.2 | F22: 81.1 | G22: 77 | H22: 85.3 | I22: =SUM(E22:H22) -> 322.6 | J22: 83.45 | K22: 92.7 | L22: =82.7+0.1 -> 82.8 | M22: =82.48+3.32 -> 85.8 | N22: =SUM(J22:M22) -> 344.75 | O22: =80.7+3.3 -> 84 | P22: =98+3.3 -> 101.3 | Q22: =88.5+3.5 -> 92 | R22: =90.1+7.9 -> 98 | S22: =SUM(O22:R22) -> 375.3 | T22: =100.7+7.8 -> 108.5 | U22: =99.9+8.1 -> 108 | V22: =90.6+7.2 -> 97.8 | W22: 85.3 | X22: =SUM(T22:W22) -> 399.6 | Y22: =91.5+7.8 -> 99.3 | Z22: =112.3+7.3 -> 119.6 | AA22: =105.2+7.5 -> 112.7 | AB22: =103.2+8 -> 111.2 | AC22: =SUM(Y22:AB22) -> 442.8 | AD22: =98.1+4.8 -> 102.9 | AE22: =104.7+4.6 -> 109.3 | AF22: =109.2+4.4 -> 113.6 | AG22: =119.3+4.7 -> 124 | AH22: =SUM(AD22:AG22) -> 449.8 | AI22: =93.2+5 -> 98.2 | AJ22: =108.1+4.4 -> 112.5 | AK22: =99+4.8 -> 103.8 | AL22: =90.8+4.8 -> 95.6 | AM22: =SUM(AI22:AL22) -> 410.1 | AN22: 92.7 | AO22: =108.6+5.1 -> 113.7 | AP22: =119.8+8.9 -> 128.7 | AQ22: =125+9 -> 134 | AR22: =SUM(AN22:AQ22) -> 469.1 | AS22: =109+11 -> 120 | AT22: =133+10 -> 143 | AU22: =133+9 -> 142 | AV22: =121+17 -> 138 | AW22: =SUM(AS22:AV22) -> 543 | AX22: =143+10 -> 153 | AY22: =130+10 -> 140 | AZ22: =130+11 -> 141 | BA22: =118+11 -> 129 | BB22: =SUM(AX22:BA22) -> 563 | BC22: =123+12 -> 135 | BD22: =122+11 -> 133 | BE22: =92+11 -> 103 | BF22: =94+12 -> 106 | BG22: =SUM(BC22:BF22) -> 477 | BH22: =129+7 -> 136 | BI22: =127 +8 -> 135 | BJ22: =115+7 -> 122 | BK22: =105+8 -> 113 | BL22: =SUM(BH22:BK22) -> 506 | BM22: =141+8 -> 149 | BN22: =154+10 -> 164 | BO22: =154+8 -> 162 | BP22: =115+8 -> 123 | BQ22: =SUM(BM22:BP22) -> 598 | BR22: =163+9 -> 172 | BS22: =162+10 -> 172 | BT22: =161+7 -> 168
B23: % y/y | J23: =J22/E22-1 -> 0.053661616 | K23: =K22/F22-1 -> 0.14303329 | L23: =L22/G22-1 -> 0.075324675 | M23: =M22/H22-1 -> 0.0058616647 | N23: =N22/I22-1 -> 0.06866088 | O23: =O22/J22-1 -> 0.0065907729 | P23: =P22/K22-1 -> 0.092772384 | Q23: =Q22/L22-1 -> 0.11111111 | ... AC23: =AC22/X22-1 -> 0.10810811 | AD23: =IFERROR( AD22/Y22-1, "NA") -> 0.036253776 | AE23: =IFERROR( AE22/Z22-1, "NA") -> -0.086120401 | AF23: =IFERROR( AF22/AA22-1, "NA") -> 0.007985803 | AG23: =IFERROR( AG22/AB22-1, "NA") -> 0.11510791 | AH23: =AH22/AC22-1 -> 0.015808491 | AI23: =IFERROR( AI22/AD22-1, "NA") -> -0.045675413 | AJ23: =IFERROR( AJ22/AE22-1, "NA") -> 0.029277219 | AK23: =IFERROR( AK22/AF22-1, "NA") -> -0.086267606 | AL23: =IFERROR( AL22/AG22-1, "NA") -> -0.22903226 | AM23: =AM22/AH22-1 -> -0.08826145 | AN23: =IFERROR( AN22/AI22-1, "NA") -> -0.056008147 | AO23: =IFERROR( AO22/AJ22-1, "NA") -> 0.010666667 | AP23: =IFERROR( AP22/AK22-1, "NA") -> 0.23988439 | AQ23: =IFERROR( AQ22/AL22-1, "NA") -> 0.40167364 | AR23: =AR22/AM22-1 -> 0.14386735 | AS23: =IFERROR( AS22/AN22-1, "NA") -> 0.29449838 | AT23: =IFERROR( AT22/AO22-1, "NA") -> 0.25769569 | AU23: =IFERROR( AU22/AP22-1, "NA") -> 0.1033411 | AV23: =IFERROR( AV22/AQ22-1, "NA") -> 0.029850746 | AW23: =AW22/AR22-1 -> 0.15753571 | AX23: =IFERROR( AX22/AS22-1, "NA") -> 0.275 | AY23: =IFERROR( AY22/AT22-1, "NA") -> -0.020979021 | AZ23: =IFERROR( AZ22/AU22-1, "NA") -> -0.0070422535 | BA23: =IFERROR( BA22/AV22-1, "NA") -> -0.065217391 | BB23: =BB22/AW22-1 -> 0.036832413 | BC23: =IFERROR( BC22/AX22-1, "NA") -> -0.11764706 | BD23: =IFERROR( BD22/AY22-1, "NA") -> -0.05 | BE23: =IFERROR( BE22/AZ22-1, "NA") -> -0.26950355 | BF23: =IFERROR( BF22/BA22-1, "NA") -> -0.17829457 | BG23: =BG22/BB22-1 -> -0.15275311 | BH23: =IFERROR( BH22/BC22-1, "NA") -> 0.0074074074 | BI23: =IFERROR( BI22/BD22-1, "NA") -> 0.015037594 | BJ23: =IFERROR( BJ22/BE22-1, "NA") -> 0.18446602 | BK23: =IFERROR( BK22/BF22-1, "NA") -> 0.066037736 | BL23: =BL22/BG22-1 -> 0.060796646 | BM23: =IFERROR( BM22/BH22-1, "NA") -> 0.095588235 | BN23: =IFERROR( BN22/BI22-1, "NA") -> 0.21481481 | BO23: =IFERROR( BO22/BJ22-1, "NA") -> 0.32786885 | BP23: =IFERROR( BP22/BK22-1, "NA") -> 0.088495575 | BQ23: =BQ22/BL22-1 -> 0.18181818 | BR23: =IFERROR( BR22/BM22-1, "NA") -> 0.15436242 | BS23: =IFERROR( BS22/BN22-1, "NA") -> 0.048780488 | BT23: =IFERROR( BT22/BO22-1, "NA") -> 0.037037037
B24: Leveraged Loans | I24: 120 | N24: 155 | S24: 212 | X24: 242 | AC24: 204 | AH24: 254 | AI24: 110 | AJ24: 121 | AK24: 78 | AL24: 70 | AM24: =SUM(AI24:AL24) -> 379 | AN24: 73 | AO24: 83 | AP24: 90 | AQ24: 96 | AR24: =SUM(AN24:AQ24) -> 342 | AS24: 89 | AT24: 43 | AU24: 72 | AV24: 82 | AW24: =SUM(AS24:AV24) -> 286 | AX24: 180 | AY24: 157 | AZ24: 145 | BA24: 124 | BB24: =SUM(AX24:BA24) -> 606 | BC24: 113 | BD24: 72 | BE24: 47 | BF24: 43 | BG24: =SUM(BC24:BF24) -> 275 | BH24: 59 | BI24: 68 | BJ24: 82 | BK24: 83 | BL24: =SUM(BH24:BK24) -> 292 | BM24: 155 | BN24: 147 | BO24: 120 | BP24: 105 | BQ24: =SUM(BM24:BP24) -> 527 | BR24: 160 | BS24: 98 | BT24: 155
B25: % y/y | I25: N/A | N25: =N24/I24-1 -> 0.29166667 | S25: =S24/N24-1 -> 0.36774194 | X25: =X24/S24-1 -> 0.14150943 | AC25: =AC24/X24-1 -> -0.15702479 | AH25: =AH24/AC24-1 -> 0.24509804 | AI25: N/A | AJ25: N/A | AK25: N/A | AL25: N/A | AM25: =AM24/AH24-1 -> 0.49212598 | AN25: =AN24/AI24-1 -> -0.33636364 | AO25: =AO24/AJ24-1 -> -0.31404959 | AP25: =AP24/AK24-1 -> 0.15384615 | AQ25: =AQ24/AL24-1 -> 0.37142857 | AR25: =AR24/AM24-1 -> -0.09762533 | AS25: =AS24/AN24-1 -> 0.21917808 | AT25: =AT24/AO24-1 -> -0.48192771 | ... BT25: =BT24/BO24-1 -> 0.29166667
B26: % of Ratings Revenue | I26: =I24/I31 -> 0.06360986 | N26: =N24/N31 -> 0.07514605 | S26: =S24/S31 -> 0.093565187 | X26: =X24/X31 -> 0.10367578 | AC26: =AC24/AC31 -> 0.086046904 | AH26: =AH24/AH31 -> 0.09157113 | AI26: =AI24/AI31 -> 0.152799 | AJ26: =AJ24/AJ31 -> 0.16084009 | AK26: =AK24/AK31 -> 0.12096774 | AL26: =AL24/AL31 -> 0.11756802 | AM26: =AM24/AM31 -> 0.13972865 | AN26: =AN24/AN31 -> 0.10893896 | AO26: =AO24/AO31 -> 0.1124052 | ... BT26: =BT24/BT31 -> 0.14149695
B27: Transaction | C27: =BQ27/BQ$31 -> 0.66359083 | E27: =0.62*E31 -> 280.612 | F27: =0.6*F31 -> 264.78 | G27: =0.62*G31 -> 293.446 | H27: =0.65*H31 -> 337.545 | I27: =SUM(E27:H27) -> 1176.383 | J27: =0.64*J31 -> 333.6 | K27: 343.6 | L27: 280.2 | M27: 319.6 | N27: =SUM(J27:M27) -> 1277 | O27: 315.6 | P27: 402.8 | Q27: 326.2 | R27: 338.4 | S27: =SUM(O27:R27) -> 1383 | T27: 380.9 | U27: 412.2 | V27: 316.3 | W27: 322.6 | X27: =SUM(T27:W27) -> 1432 | Y27: 294.5 | Z27: 389.2 | AA27: 382.7 | AB27: 374.5 | AC27: =SUM(Y27:AB27) -> 1440.9 | AD27: 431 | AE27: 449.1 | AF27: 450.5 | AG27: 477.2 | AH27: =SUM(AD27:AG27) -> 1807.8 | AI27: 463 | AJ27: 495.9 | AK27: 390.5 | AL27: 336.7 | AM27: =SUM(AI27:AL27) -> 1686.1 | AN27: 409.9 | AO27: 477.6 | AP27: 478.6 | AQ27: 443 | AR27: =SUM(AN27:AQ27) -> 1809.1 | AS27: 519 | AT27: 664 | AU27: 548 | AV27: 451 | AW27: =SUM(AS27:AV27) -> 2182 | AX27: 745 | AY27: 686 | AZ27: 631 | BA27: 578 | BB27: =SUM(AX27:BA27) -> 2640 | BC27: 529 | BD27: 409 | BE27: 296 | BF27: 277 | BG27: =SUM(BC27:BF27) -> 1511 | BH27: 431 | BI27: 443 | BJ27: 388 | BK27: 375 | BL27: =SUM(BH27:BK27) -> 1637 | BM27: 677 | BN27: 692 | BO27: 663 | BP27: 485 | BQ27: =SUM(BM27:BP27) -> 2517 | BR27: 732 | BS27: 663 | BT27: =BO27*(1+BT28) -> 752.505 | BU27: =BP27*(1+BU28) -> 550.475 | BV27: =SUM(BR27:BU27) -> 2697.98 | BW27: =BR27*(1+BW28) -> 805.2 | BX27: =BS27*(1+BX28) -> 729.3 | BY27: =BT27*(1+BY28) -> 812.7054 | BZ27: =BU27*(1+BZ28) -> 594.513 | CA27: =SUM(BW27:BZ27) -> 2941.7184 | CB27: =BW27*(1+CB28) -> 865.59 | CC27: =BX27*(1+CC28) -> 783.9975 | CD27: =BY27*(1+CD28) -> 873.65831 | CE27: =BZ27*(1+CE28) -> 639.10148 | CF27: =SUM(CB27:CE27) -> 3162.3473
B28: % y/y | I28: =IFERROR( I27/#REF!-1, "NA") -> NA | J28: =IFERROR( J27/E27-1, "NA") -> 0.18883013 | K28: =IFERROR( K27/F27-1, "NA") -> 0.29768109 | L28: =IFERROR( L27/G27-1, "NA") -> -0.045139481 | M28: =IFERROR( M27/H27-1, "NA") -> -0.053163282 | N28: =IFERROR( N27/I27-1, "NA") -> 0.085530818 | O28: =IFERROR( O27/J27-1, "NA") -> -0.053956835 | P28: =IFERROR( P27/K27-1, "NA") -> 0.17229336 | Q28: =IFERROR( Q27/L27-1, "NA") -> 0.16416845 | ... BS28: =IFERROR( BS27/BN27-1, "NA") -> -0.041907514 | BT28: 0.135 | BU28: 0.135 | BV28: =IFERROR( BV27/BQ27-1, "NA") -> 0.071903059 | BW28: 0.1 | BX28: 0.1 | BY28: 0.08 | BZ28: 0.08 | CA28: =IFERROR( CA27/BV27-1, "NA") -> 0.09034107 | CB28: 0.075 | CC28: 0.075 | CD28: 0.075 | CE28: 0.075 | CF28: =IFERROR( CF27/CA27-1, "NA") -> 0.075
B29: Non-transaction (MCO deems "recurring") | C29: =BQ29/BQ$31 -> 0.33640917 | E29: =0.38*E31 -> 171.988 | F29: =0.4*F31 -> 176.52 | G29: =0.38*G31 -> 179.854 | H29: =0.35*H31 -> 181.755 | I29: =SUM(E29:H29) -> 710.117 | J29: =0.36*J31 -> 187.65 | K29: 193.7 | L29: 197.9 | M29: 206.4 | N29: =SUM(J29:M29) -> 785.65 | O29: 213.5 | P29: 222.2 | Q29: 220.4 | R29: 226.7 | S29: =SUM(O29:R29) -> 882.8 | T29: 221.4 | U29: 227 | V29: 231.8 | W29: 222 | X29: =SUM(T29:W29) -> 902.2 | Y29: 230.6 | Z29: 236.4 | AA29: 229.6 | AB29: 233.3 | AC29: =SUM(Y29:AB29) -> 929.9 | AD29: 237.2 | AE29: 237.6 | AF29: 243.7 | AG29: 247.5 | AH29: =SUM(AD29:AG29) -> 966 | AI29: 256.9 | AJ29: 256.4 | AK29: 254.3 | AL29: 258.7 | AM29: =SUM(AI29:AL29) -> 1026.3 | AN29: 260.2 | AO29: 260.8 | AP29: 268 | AQ29: 277 | AR29: =SUM(AN29:AQ29) -> 1066 | AS29: 275 | AT29: 274 | AU29: 277 | AV29: 284 | AW29: =SUM(AS29:AV29) -> 1110 | AX29: 291 | AY29: 294 | AZ29: 294 | BA29: 293 | BB29: =SUM(AX29:BA29) -> 1172 | BC29: 298 | BD29: 297 | BE29: 294 | BF29: 299 | BG29: =SUM(BC29:BF29) -> 1188 | BH29: 302 | BI29: 304 | BJ29: 308 | BK29: 309 | BL29: =SUM(BH29:BK29) -> 1223 | BM29: 310 | BN29: 323 | BO29: 319 | BP29: 324 | BQ29: =SUM(BM29:BP29) -> 1276 | BR29: 333 | BS29: 347 | BT29: =BO29*(1+BT30) -> 342.925 | BU29: =BP29*(1+BU30) -> 348.3 | BV29: =SUM(BR29:BU29) -> 1371.225 | BW29: =BR29*(1+BW30) -> 354.645 | BX29: =BS29*(1+BX30) -> 369.555 | BY29: =BT29*(1+BY30) -> 361.78587 | BZ29: =BU29*(1+BZ30) -> 367.4565 | CA29: =SUM(BW29:BZ29) -> 1453.4424 | CB29: =BW29*(1+CB30) -> 374.15047 | CC29: =BX29*(1+CC30) -> 389.88052 | CD29: =BY29*(1+CD30) -> 381.6841 | CE29: =BZ29*(1+CE30) -> 387.66661 | CF29: =SUM(CB29:CE29) -> 1533.3817
B30: % y/y | I30: =IFERROR( I29/#REF!-1, "NA") -> NA | J30: =IFERROR( J29/E29-1, "NA") -> 0.091064493 | K30: =IFERROR( K29/F29-1, "NA") -> 0.097326082 | L30: =IFERROR( L29/G29-1, "NA") -> 0.10033694 | M30: =IFERROR( M29/H29-1, "NA") -> 0.13559462 | N30: =IFERROR( N29/I29-1, "NA") -> 0.10636698 | O30: =IFERROR( O29/J29-1, "NA") -> 0.13775646 | P30: =IFERROR( P29/K29-1, "NA") -> 0.14713474 | Q30: =IFERROR( Q29/L29-1, "NA") -> 0.11369378 | ... BS30: =IFERROR( BS29/BN29-1, "NA") -> 0.074303406 | BT30: 0.075 | BU30: 0.075 | BV30: =IFERROR( BV29/BQ29-1, "NA") -> 0.074627743 | BW30: 0.065 | BX30: 0.065 | BY30: 0.055 | BZ30: 0.055 | CA30: =IFERROR( CA29/BV29-1, "NA") -> 0.059959069 | CB30: 0.055 | CC30: 0.055 | CD30: 0.055 | CE30: 0.055 | CF30: =IFERROR( CF29/CA29-1, "NA") -> 0.055
B31: RATINGS REVENUE | E31: =E16+E18+E20+E22 -> 452.6 | F31: =F16+F18+F20+F22 -> 441.3 | G31: =G16+G18+G20+G22 -> 473.3 | H31: =H16+H18+H20+H22 -> 519.3 | I31: =I16+I18+I20+I22 -> 1886.5 | J31: =J16+J18+J20+J22 -> 521.25 | K31: =K29+K27 -> 537.3 | L31: =L29+L27 -> 478.1 | M31: =M29+M27 -> 526 | N31: =N16+N18+N20+N22 -> 2062.65 | O31: =O29+O27 -> 529.1 | P31: =P29+P27 -> 625 | Q31: =Q29+Q27 -> 546.6 | R31: =R29+R27 -> 565.1 | S31: =S29+S27 -> 2265.8 | T31: =T29+T27 -> 602.3 | U31: =U29+U27 -> 639.2 | V31: =V29+V27 -> 548.1 | ... AN31: =AN29+AN27 -> 670.1 | AO31: =AO16+AO18+AO20+AO22 -> 738.4 | AP31: =AP16+AP18+AP20+AP22 -> 746.6 | AQ31: =AQ16+AQ18+AQ20+AQ22 -> 720 | AR31: =AR29+AR27 -> 2875.1 | AS31: =AS16+AS18+AS20+AS22 -> 794 | AT31: =AT16+AT18+AT20+AT22 -> 938 | AU31: =AU16+AU18+AU20+AU22 -> 825 | AV31: =AV16+AV18+AV20+AV22 -> 735 | AW31: =AW29+AW27 -> 3292 | AX31: =AX29+AX27 -> 1036 | AY31: =AY29+AY27 -> 980 | AZ31: =AZ29+AZ27 -> 925 | BA31: =BA29+BA27 -> 871 | BB31: =BB29+BB27 -> 3812 | BC31: =BC29+BC27 -> 827 | BD31: =BD29+BD27 -> 706 | ... CF31: =CF29+CF27 -> 4695.729
B32: Reported growth % y/y | J32: =IFERROR( J31/E31-1, "NA") -> 0.15167919 | K32: =IFERROR( K31/F31-1, "NA") -> 0.21753909 | L32: =IFERROR( L31/G31-1, "NA") -> 0.010141559 | M32: =IFERROR( M31/H31-1, "NA") -> 0.012901983 | N32: =IFERROR( N31/I31-1, "NA") -> 0.093373973 | O32: =IFERROR( O31/J31-1, "NA") -> 0.015059952 | P32: =IFERROR( P31/K31-1, "NA") -> 0.16322353 | Q32: =IFERROR( Q31/L31-1, "NA") -> 0.14327547 | ... CF32: =IFERROR( CF31/CA31-1, "NA") -> 0.06838617
B33: M&A impact % y/y | O33: 0 | P33: 0.02 | Q33: 0.02 | R33: 0.02 | S33: =SUMPRODUCT(O33:R33,J$31:M$31)/N$31 -> 0.014945822 | T33: 0.02 | U33: 0 | V33: 0 | W33: 0 | X33: =SUMPRODUCT(T33:W33,O$31:R$31)/S$31 -> 0.0046703151 | Y33: 0 | Z33: 0 | AA33: 0 | AB33: 0 | AC33: =SUMPRODUCT(Y33:AB33,T$31:W$31)/X$31 -> 0 | AD33: 0 | AE33: 0 | AF33: 0 | AG33: 0 | AH33: =SUMPRODUCT(AD33:AG33,Y$31:AB$31)/AC$31 -> 0 | AI33: 0 | AJ33: 0 | AK33: 0 | AL33: 0 | AM33: =SUMPRODUCT(AI33:AL33,AD$31:AG$31)/AH$31 -> 0 | AN33: 0 | AO33: 0 | AP33: 0 | AQ33: 0 | AR33: =SUMPRODUCT(AN33:AQ33,AI$31:AL$31)/AM$31 -> 0 | AS33: 0 | AT33: 0 | AU33: 0 | AV33: 0 | AW33: =SUMPRODUCT(AS33:AV33,AN$31:AQ$31)/AR$31 -> 0 | AX33: 0 | AY33: 0 | AZ33: 0 | BA33: 0 | BB33: =SUMPRODUCT(AX33:BA33,AS$31:AV$31)/AW$31 -> 0 | BC33: 0 | BD33: 0 | BE33: 0 | BF33: 0 | BG33: =SUMPRODUCT(BC33:BF33,AX$31:BA$31)/BB$31 -> 0 | BH33: 0 | BI33: =BI216/BD31 -> 0 | BJ33: =BJ216/BE31 -> 0 | BK33: =BK216/BF31 -> 0 | BL33: =SUMPRODUCT(BH33:BK33,BC$31:BF$31)/BG$31 -> 0 | BM33: 0 | BN33: =BN216/BI31 -> 0 | BO33: =BO216/BJ31 -> 0.0043103448 | BP33: =BP216/BK31 -> 0.0043859649 | BQ33: =SUMPRODUCT(BM33:BP33,BH$31:BK$31)/BL$31 -> 0.0020979021 | BR33: =BR216/BM31 -> 0.0040526849 | BS33: =BS216/BN31 -> 0.002955665 | BT33: =BT216/BO31 -> 0 | BU33: =BU216/BP31 -> 0.0024721879 | BV33: =SUMPRODUCT(BR33:BU33,BM$31:BP$31)/BQ$31 -> 0.002372792 | BW33: =BW216/BR31 -> 0.0018779343 | BX33: =BX216/BS31 -> 0.001980198 | BY33: =BY216/BT31 -> 0.00091288353 | BZ33: =BZ216/BU31 -> 0 | CA33: =SUMPRODUCT(BW33:BZ33,BR$31:BU$31)/BV$31 -> 0.0012287412 | CB33: 0 | CC33: =CC216/BX31 -> 0 | CD33: =CD216/BY31 -> 0 | CE33: =CE216/BZ31 -> 0 | CF33: =SUMPRODUCT(CB33:CE33,BW$31:BZ$31)/CA$31 -> 0
B34: Organic growth % y/y | O34: =O32-O33 -> 0.015059952 | P34: =P32-P33 -> 0.14322353 | Q34: =Q32-Q33 -> 0.12327547 | R34: =R32-R33 -> 0.054334601 | S34: =SUMPRODUCT(O34:R34,J$31:M$31)/N$31 -> 0.083543985 | T34: =T32-T33 -> 0.11834814 | U34: =U32-U33 -> 0.02272 | V34: =V32-V33 -> 0.0027442371 | W34: =W32-W33 -> -0.036276765 | X34: =SUMPRODUCT(T34:W34,O$31:R$31)/S$31 -> 0.025517698 | Y34: =Y32-Y33 -> -0.12817533 | Z34: =Z32-Z33 -> -0.021276596 | AA34: =AA32-AA33 -> 0.11713191 | AB34: =AB32-AB33 -> 0.11604848 | AC34: =SUMPRODUCT(Y34:AB34,T$31:W$31)/X$31 -> 0.01567989 | AD34: =AD32-AD33 -> 0.27251952 | AE34: =AE32-AE33 -> 0.09766624 | AF34: =AF32-AF33 -> 0.13375796 | AG34: =AG32-AG33 -> 0.192333 | AH34: =SUMPRODUCT(AD34:AG34,Y$31:AB$31)/AC$31 -> 0.16998482 | AI34: =AI32-AI33 -> 0.077372044 | AJ34: =AJ32-AJ33 -> 0.095529343 | AK34: =AK32-AK33 -> -0.071161049 | AL34: =AL32-AL33 -> -0.17841866 | AM34: =SUMPRODUCT(AI34:AL34,AD$31:AG$31)/AH$31 -> -0.022135698 | AN34: =AN32-AN33 -> -0.069176274 | AO34: =AO32-AO33 -> -0.018476672 | AP34: =AP32-AP33 -> 0.15787841 | AQ34: =AQ32-AQ33 -> 0.20927108 | AR34: =SUMPRODUCT(AN34:AQ34,AI$31:AL$31)/AM$31 -> 0.059983778 | AS34: =AS32-AS33 -> 0.18489778 | AT34: =AT32-AT33 -> 0.27031419 | AU34: =AU32-AU33 -> 0.10500938 | AV34: =AV32-AV33 -> 0.020833333 | AW34: =SUMPRODUCT(AS34:AV34,AN$31:AQ$31)/AR$31 -> 0.14500365 | AX34: =AX32-AX33 -> 0.30478589 | AY34: =AY32-AY33 -> 0.044776119 | AZ34: =AZ32-AZ33 -> 0.12121212 | BA34: =BA32-BA33 -> 0.18503401 | BB34: =SUMPRODUCT(AX34:BA34,AS$31:AV$31)/AW$31 -> 0.15795869 | BC34: =BC32-BC33 -> -0.20173745 | BD34: =BD32-BD33 -> -0.27959184 | BE34: =BE32-BE33 -> -0.36216216 | BF34: =BF32-BF33 -> -0.33869116 | BG34: =SUMPRODUCT(BC34:BF34,AX$31:BA$31)/BB$31 -> -0.29197272 | BH34: =BH32-BH33 -> -0.11366385 | BI34: =BI32-BI33 -> 0.058073654 | BJ34: =BJ32-BJ33 -> 0.17966102 | BK34: =BK32-BK33 -> 0.1875 | BL34: =SUMPRODUCT(BH34:BK34,BC$31:BF$31)/BG$31 -> 0.059651723 | BM34: =BM32-BM33 -> 0.34652115 | BN34: =BN32-BN33 -> 0.35876841 | BO34: =BO32-BO33 -> 0.4066092 | BP34: =BP32-BP33 -> 0.17836257 | BQ34: =SUMPRODUCT(BM34:BP34,BH$31:BK$31)/BL$31 -> 0.32412587 | BR34: =BR32-BR33 -> 0.074974671 | BS34: =BS32-BS33 -> -0.0078817734 | BT34: =BT32-BT33 -> 0.11550916 | BU34: =BU32-BU33 -> 0.10849815 | BV34: =SUMPRODUCT(BR34:BU34,BM$31:BP$31)/BQ$31 -> 0.070446876 | BW34: =BW32-BW33 -> 0.087178404 | BX34: =BX32-BX33 -> 0.08599505 | BY34: =BY32-BY33 -> 0.071260852 | BZ34: =BZ32-BZ33 -> 0.070311813 | CA34: =SUMPRODUCT(BW34:BZ34,BR$31:BU$31)/BV$31 -> 0.078874319 | CB34: =CB32-CB33 -> 0.068884614 | CC34: =CC32-CC33 -> 0.068273817 | CD34: =CD32-CD33 -> 0.068839275 | CE34: =CE32-CE33 -> 0.06736033 | CF34: =SUMPRODUCT(CB34:CE34,BW$31:BZ$31)/CA$31 -> 0.06838617
B35: FX impact % y/y | O35: 0 | P35: 0.01 | Q35: 0 | R35: -0.03 | S35: =SUMPRODUCT(O35:R35,J$31:M$31)/N$31 -> -0.0050454512 | T35: -0.05 | U35: -0.05 | V35: -0.05 | W35: -0.04 | X35: =SUMPRODUCT(T35:W35,O$31:R$31)/S$31 -> -0.047505958 | Y35: -0.014 | Z35: 0 | AA35: 0 | AB35: 0 | AC35: =SUMPRODUCT(Y35:AB35,T$31:W$31)/X$31 -> -0.0036124582 | AD35: 0 | AE35: 0 | AF35: 0.01 | AG35: 0.03 | AH35: =SUMPRODUCT(AD35:AG35,Y$31:AB$31)/AC$31 -> 0.010273747 | AI35: 0.032 | AJ35: 0.01 | AK35: 0 | AL35: -0.01 | AM35: =SUMPRODUCT(AI35:AL35,AD$31:AG$31)/AH$31 -> 0.0075717067 | AN35: -0.02 | AO35: -0.018 | AP35: -0.01 | AQ35: -0.01 | AR35: =SUMPRODUCT(AN35:AQ35,AI$31:AL$31)/AM$31 -> -0.014872954 | AS35: -0.01 | AT35: -0.01 | AU35: 0 | AV35: 0.02 | AW35: =SUMPRODUCT(AS35:AV35,AN$31:AQ$31)/AR$31 -> 0.00010956141 | AX35: 0.03 | AY35: 0.02 | AZ35: 0.002 | BA35: 0 | BB35: =SUMPRODUCT(AX35:BA35,AS$31:AV$31)/AW$31 -> 0.013435601 | BC35: -0.01 | BD35: =-20/AY31 -> -0.020408163 | BE35: =-(67-41)/AZ31 -> -0.028108108 | BF35: =-(51-32)/BA31 -> -0.021814007 | BG35: =SUMPRODUCT(BC35:BF35,AX$31:BA$31)/BB$31 -> -0.01976915 | BH35: =-10/BC31 -> -0.012091898 | BI35: 0 | BJ35: 0 | BK35: =9/BF31 -> 0.015625 | BL35: =SUMPRODUCT(BH35:BK35,BC$31:BF$31)/BG$31 -> -0.0003705076 | BM35: =1/BH31 -> 0.0013642565 | BN35: =-5/BI31 -> -0.0066934404 | BO35: =3/BJ31 -> 0.0043103448 | BP35: =-4/BK31 -> -0.0058479532 | BQ35: =SUMPRODUCT(BM35:BP35,BH$31:BK$31)/BL$31 -> -0.0017482517 | BR35: =-6/BM31 -> -0.0060790274 | BS35: =12/BN31 -> 0.01182266 | BT35: =BT246 -> 0.010183299 | BU35: =BU246 -> 0.015241758 | BV35: =SUMPRODUCT(BR35:BU35,BM$31:BP$31)/BQ$31 -> 0.0074691753 | BW35: =BW245*$BB$247 -> 0.021364132 | BX35: =BX245*$BB$247 -> 0.003008046 | BY35: =BY245*$BB$247 -> -0.0022191205 | BZ35: =BZ245*$BB$247 -> -0.0036363533 | CA35: =SUMPRODUCT(BW35:BZ35,BR$31:BU$31)/BV$31 -> 0.004937518 | CB35: =CB245*$BB$247 -> -0.00099011186 | CC35: =CC245*$BB$247 -> -0.00099011186 | CD35: =CD245*$BB$247 -> -0.00099011186 | CE35: =CE245*$BB$247 -> -0.00099011186 | CF35: =SUMPRODUCT(CB35:CE35,BW$31:BZ$31)/CA$31 -> -0.00099011186
B36: MIS organic constant currency growth % y/y | O36: =IFERROR(O32-O33-O35,"NA") -> 0.015059952 | P36: =IFERROR(P32-P33-P35,"NA") -> 0.13322353 | Q36: =IFERROR(Q32-Q33-Q35,"NA") -> 0.12327547 | R36: =IFERROR(R32-R33-R35,"NA") -> 0.084334601 | S36: =SUMPRODUCT(O36:R36,J$31:M$31)/N$31 -> 0.088589436 | T36: =IFERROR(T32-T33-T35,"NA") -> 0.16834814 | U36: =IFERROR(U32-U33-U35,"NA") -> 0.07272 | V36: =IFERROR(V32-V33-V35,"NA") -> 0.052744237 | W36: =IFERROR(W32-W33-W35,"NA") -> 0.0037232348 | X36: =SUMPRODUCT(T36:W36,O$31:R$31)/S$31 -> 0.073023656 | Y36: =IFERROR(Y32-Y33-Y35,"NA") -> -0.11417533 | Z36: =IFERROR(Z32-Z33-Z35,"NA") -> -0.021276596 | AA36: =IFERROR(AA32-AA33-AA35,"NA") -> 0.11713191 | AB36: =IFERROR(AB32-AB33-AB35,"NA") -> 0.11604848 | AC36: =SUMPRODUCT(Y36:AB36,T$31:W$31)/X$31 -> 0.019292349 | AD36: =IFERROR(AD32-AD33-AD35,"NA") -> 0.27251952 | AE36: =IFERROR(AE32-AE33-AE35,"NA") -> 0.09766624 | AF36: =IFERROR(AF32-AF33-AF35,"NA") -> 0.12375796 | AG36: =IFERROR(AG32-AG33-AG35,"NA") -> 0.162333 | AH36: =SUMPRODUCT(AD36:AG36,Y$31:AB$31)/AC$31 -> 0.15971107 | AI36: =IFERROR(AI32-AI33-AI35,"NA") -> 0.045372044 | AJ36: =IFERROR(AJ32-AJ33-AJ35,"NA") -> 0.085529343 | AK36: =IFERROR(AK32-AK33-AK35,"NA") -> -0.071161049 | AL36: =IFERROR(AL32-AL33-AL35,"NA") -> -0.16841866 | AM36: =SUMPRODUCT(AI36:AL36,AD$31:AG$31)/AH$31 -> -0.029707405 | AN36: =IFERROR(AN32-AN33-AN35,"NA") -> -0.049176274 | AO36: =IFERROR(AO32-AO33-AO35,"NA") -> -0.00047667154 | AP36: =IFERROR(AP32-AP33-AP35,"NA") -> 0.16787841 | AQ36: =IFERROR(AQ32-AQ33-AQ35,"NA") -> 0.21927108 | AR36: =SUMPRODUCT(AN36:AQ36,AI$31:AL$31)/AM$31 -> 0.074856732 | AS36: =IFERROR(AS32-AS33-AS35,"NA") -> 0.19489778 | AT36: =IFERROR(AT32-AT33-AT35,"NA") -> 0.28031419 | AU36: =IFERROR(AU32-AU33-AU35,"NA") -> 0.10500938 | AV36: =IFERROR(AV32-AV33-AV35,"NA") -> 0.00083333333 | AW36: =SUMPRODUCT(AS36:AV36,AN$31:AQ$31)/AR$31 -> 0.14489409 | AX36: =IFERROR(AX32-AX33-AX35,"NA") -> 0.27478589 | AY36: =IFERROR(AY32-AY33-AY35,"NA") -> 0.024776119 | AZ36: =IFERROR(AZ32-AZ33-AZ35,"NA") -> 0.11921212 | BA36: =IFERROR(BA32-BA33-BA35,"NA") -> 0.18503401 | BB36: =SUMPRODUCT(AX36:BA36,AS$31:AV$31)/AW$31 -> 0.14452309 | BC36: =IFERROR(BC32-BC33-BC35,"NA") -> -0.19173745 | BD36: =IFERROR(BD32-BD33-BD35,"NA") -> -0.25918367 | BE36: =IFERROR(BE32-BE33-BE35,"NA") -> -0.33405405 | BF36: =IFERROR(BF32-BF33-BF35,"NA") -> -0.31687715 | BG36: =SUMPRODUCT(BC36:BF36,AX$31:BA$31)/BB$31 -> -0.27220357 | BH36: =IFERROR(BH32-BH33-BH35,"NA") -> -0.10157195 | BI36: =IFERROR(BI32-BI33-BI35,"NA") -> 0.058073654 | BJ36: =IFERROR(BJ32-BJ33-BJ35,"NA") -> 0.17966102 | BK36: =IFERROR(BK32-BK33-BK35,"NA") -> 0.171875 | BL36: =SUMPRODUCT(BH36:BK36,BC$31:BF$31)/BG$31 -> 0.06002223 | BM36: =IFERROR(BM32-BM33-BM35,"NA") -> 0.34515689 | BN36: =IFERROR(BN32-BN33-BN35,"NA") -> 0.36546185 | BO36: =IFERROR(BO32-BO33-BO35,"NA") -> 0.40229885 | BP36: =IFERROR(BP32-BP33-BP35,"NA") -> 0.18421053 | BQ36: =SUMPRODUCT(BM36:BP36,BH$31:BK$31)/BL$31 -> 0.32587413 | BR36: =IFERROR(BR32-BR33-BR35,"NA") -> 0.081053698 | BS36: =IFERROR(BS32-BS33-BS35,"NA") -> -0.019704433 | BT36: =IFERROR(BT32-BT33-BT35,"NA") -> 0.10532587 | BU36: =IFERROR(BU32-BU33-BU35,"NA") -> 0.093256388 | BV36: =SUMPRODUCT(BR36:BU36,BM$31:BP$31)/BQ$31 -> 0.062977701 | BW36: =IFERROR(BW32-BW33-BW35,"NA") -> 0.065814271 | BX36: =IFERROR(BX32-BX33-BX35,"NA") -> 0.082987004 | BY36: =IFERROR(BY32-BY33-BY35,"NA") -> 0.073479972 | BZ36: =IFERROR(BZ32-BZ33-BZ35,"NA") -> 0.073948167 | CA36: =SUMPRODUCT(BW36:BZ36,BR$31:BU$31)/BV$31 -> 0.073936801 | CB36: =IFERROR(CB32-CB33-CB35,"NA") -> 0.069874726 | CC36: =IFERROR(CC32-CC33-CC35,"NA") -> 0.069263929 | CD36: =IFERROR(CD32-CD33-CD35,"NA") -> 0.069829387 | CE36: =IFERROR(CE32-CE33-CE35,"NA") -> 0.068350441 | CF36: =SUMPRODUCT(CB36:CE36,BW$31:BZ$31)/CA$31 -> 0.069376282
B37: Reported growth % sequential | O37: =O31/M31-1 -> 0.0058935361 | P37: =P31/O31-1 -> 0.18125118 | Q37: =Q31/P31-1 -> -0.12544 | R37: =R31/Q31-1 -> 0.033845591 | T37: =T31/R31-1 -> 0.065829057 | U37: =U31/T31-1 -> 0.06126515 | V37: =V31/U31-1 -> -0.1425219 | W37: =W31/V31-1 -> -0.006385696 | Y37: =Y31/W31-1 -> -0.035806096 | Z37: =Z31/Y31-1 -> 0.19139212 | AA37: =AA31/Z31-1 -> -0.021259591 | AB37: =AB31/AA31-1 -> -0.0073493386 | AD37: =AD31/AB31-1 -> 0.099374794 | AE37: =AE31/AD31-1 -> 0.027686321 | AF37: =AF31/AE31-1 -> 0.0109218 | AG37: =AG31/AF31-1 -> 0.043935465 | AI37: =AI31/AG31-1 -> -0.0066234304 | AJ37: =AJ31/AI31-1 -> 0.045006251 | AK37: =AK31/AJ31-1 -> -0.14289512 | AL37: =AL31/AK31-1 -> -0.076612903 | AN37: =AN31/AL31-1 -> 0.12546187 | AO37: =AO31/AN31-1 -> 0.10192509 | AP37: =AP31/AO31-1 -> 0.011105092 | AQ37: =AQ31/AP31-1 -> -0.035628181 | AS37: =AS31/AQ31-1 -> 0.10277778 | AT37: =AT31/AS31-1 -> 0.1813602 | AU37: =AU31/AT31-1 -> -0.12046908 | AV37: =AV31/AU31-1 -> -0.10909091 | AX37: =AX31/AV31-1 -> 0.40952381 | AY37: =AY31/AX31-1 -> -0.054054054 | AZ37: =AZ31/AY31-1 -> -0.056122449 | BA37: =BA31/AZ31-1 -> -0.058378378 | BC37: =BC31/BA31-1 -> -0.050516648 | BD37: =BD31/BC31-1 -> -0.14631197 | BE37: =BE31/BD31-1 -> -0.16430595 | BF37: =BF31/BE31-1 -> -0.023728814 | BH37: =BH31/BF31-1 -> 0.27256944 | BI37: =BI31/BH31-1 -> 0.019099591 | BJ37: =BJ31/BI31-1 -> -0.068273092 | BK37: =BK31/BJ31-1 -> -0.017241379 | BM37: =BM31/BK31-1 -> 0.44298246 | BN37: =BN31/BM31-1 -> 0.028368794 | BO37: =BO31/BN31-1 -> -0.032512315 | BP37: =BP31/BO31-1 -> -0.17617108 | BR37: =BR31/BP31-1 -> 0.31644005 | BS37: =BS31/BR31-1 -> -0.051643192 | BT37: =BT31/BS31-1 -> 0.084584158 | BU37: =BU31/BT31-1 -> -0.17952311 | BW37: =BW31/BU31-1 -> 0.29047314 | BX37: =BX31/BW31-1 -> -0.052584613 | BY37: =BY31/BX31-1 -> 0.068831898 | BZ37: =BZ31/BY31-1 -> -0.18094794 | CB37: =CB31/BZ31-1 -> 0.28875237 | CC37: =CC31/CB31-1 -> -0.053125998 | CD37: =CD31/CC31-1 -> 0.069397652 | CE37: =CE31/CD31-1 -> -0.18208126
AS38: =AS31/$AW$31 -> 0.24119077 | AT38: =AT31/$AW$31 -> 0.28493317 | AU38: =AU31/$AW$31 -> 0.25060753
B39: Operating and SG&A expenses | L39: 235.6 | M39: 269.7 | N39: 1034 | O39: 248.6 | P39: 271.7 | Q39: 263.4 | R39: 292.6 | S39: =SUM(O39:R39) -> 1076.3 | T39: 281.6 | U39: 287 | V39: 268.1 | W39: 283.9 | X39: =SUM(T39:W39) -> 1120.6 | Y39: 278.6 | Z39: 281.3 | AA39: 272.8 | AB39: 285.5 | AC39: =SUM(Y39:AB39) -> 1118.2 | AD39: 286.2 | AE39: 289.7 | AF39: 317.3 | AG39: 346.1 | AH39: =SUM(AD39:AG39) -> 1239.3 | AI39: 310.4 | AJ39: 303.6 | AK39: =303.5-AK43 -> 287.7 | AL39: 277.3 | AM39: =SUM(AI39:AL39) -> 1179 | AN39: 316.8 | AO39: 307 | AP39: =339.9-AP43-AP46 -> 312.6 | AQ39: =348-AQ43-AQ46 -> 328 | AR39: =SUM(AN39:AQ39) -> 1264.4 | AS39: =343-AS43-AS46 -> 328 | AT39: =369-AT43-AT46 -> 350 | AU39: =339-AU43-AU46 -> 309 | AV39: =425-AV43-AV46 -> 400 | AW39: =SUM(AS39:AV39) -> 1387 | AX39: =366-AX43-AX46 -> 348 | AY39: =362-AY43-AY46 -> 344 | AZ39: =404-AZ43-AZ46 -> 387 | BA39: 423 | BB39: =SUM(AX39:BA39) -> 1502 | BC39: 360 | BD39: 334 | BE39: 344 | BF39: 347 | BG39: =SUM(BC39:BF39) -> 1385 | BH39: 336 | BI39: 350 | BJ39: 348 | BK39: 352 | BL39: =SUM(BH39:BK39) -> 1386 | BM39: 366 | BN39: 392 | BO39: 416 | BP39: 418 | BQ39: =SUM(BM39:BP39) -> 1592 | BR39: 379 | BS39: 380 | BT39: =BT31-BT52 -> 392.84886 | BU39: =BU31-BU52 -> 405.96522 | BV39: =SUM(BR39:BU39) -> 1557.8141 | BW39: =BW31-BW52 -> 395.35468 | BX39: =BX31-BX52 -> 396.94777 | BY39: =BY31-BY52 -> 430.01092 | BZ39: =BZ31-BZ52 -> 441.72415 | CA39: =SUM(BW39:BZ39) -> 1664.0375 | CB39: =CB31-CB52 -> 407.09178 | CC39: =CC31-CC52 -> 409.37543 | CD39: =CD31-CD52 -> 447.05913 | CE39: =CE31-CE52 -> 461.21115 | CF39: =SUM(CB39:CE39) -> 1724.7375
B40: % y/y | L40: =IFERROR(L39/G39-1,"NA") -> NA | M40: =IFERROR(M39/H39-1,"NA") -> NA | N40: =IFERROR(N39/I39-1,"NA") -> NA | O40: =IFERROR(O39/J39-1,"NA") -> NA | P40: =IFERROR(P39/K39-1,"NA") -> NA | Q40: =IFERROR(Q39/L39-1,"NA") -> 0.1179966 | R40: =IFERROR(R39/M39-1,"NA") -> 0.084909158 | S40: =IFERROR(S39/N39-1,"NA") -> 0.040909091 | ... AH40: =IFERROR(AH39/AC39-1,"NA") -> 0.10829905 | AI40: =AI39/AD39-1 -> 0.084556254 | AJ40: =AJ39/AE39-1 -> 0.04798067 | AK40: =AK39/AF39-1 -> -0.09328711 | AL40: =AL39/AG39-1 -> -0.19878648 | AM40: =IFERROR(AM39/AH39-1,"NA") -> -0.0486565 | AN40: =AN39/AI39-1 -> 0.020618557 | AO40: =AO39/AJ39-1 -> 0.011198946 | AP40: =AP39/AK39-1 -> 0.086548488 | AQ40: =AQ39/AL39-1 -> 0.18283448 | AR40: =IFERROR(AR39/AM39-1,"NA") -> 0.072434266 | AS40: =AS39/AN39-1 -> 0.035353535 | AT40: =AT39/AO39-1 -> 0.14006515 | AU40: =AU39/AP39-1 -> -0.011516315 | AV40: =AV39/AQ39-1 -> 0.2195122 | AW40: =IFERROR(AW39/AR39-1,"NA") -> 0.096962986 | AX40: =AX39/AS39-1 -> 0.06097561 | AY40: =AY39/AT39-1 -> -0.017142857 | AZ40: =AZ39/AU39-1 -> 0.25242718 | BA40: =BA39/AV39-1 -> 0.0575 | BB40: =IFERROR(BB39/AW39-1,"NA") -> 0.082912761 | BC40: =BC39/AX39-1 -> 0.034482759 | BD40: =BD39/AY39-1 -> -0.029069767 | BE40: =BE39/AZ39-1 -> -0.11111111 | BF40: =BF39/BA39-1 -> -0.17966903 | BG40: =IFERROR(BG39/BB39-1,"NA") -> -0.077896138 | BH40: =BH39/BC39-1 -> -0.066666667 | BI40: =BI39/BD39-1 -> 0.047904192 | BJ40: =BJ39/BE39-1 -> 0.011627907 | BK40: =BK39/BF39-1 -> 0.014409222 | BL40: =IFERROR(BL39/BG39-1,"NA") -> 0.00072202166 | BM40: =BM39/BH39-1 -> 0.089285714 | BN40: =BN39/BI39-1 -> 0.12 | BO40: =BO39/BJ39-1 -> 0.1954023 | BP40: =BP39/BK39-1 -> 0.1875 | BQ40: =IFERROR(BQ39/BL39-1,"NA") -> 0.14862915 | BR40: =BR39/BM39-1 -> 0.035519126 | BS40: =BS39/BN39-1 -> -0.030612245 | BT40: =BT39/BO39-1 -> -0.055651773 | BU40: =BU39/BP39-1 -> -0.028791329 | BV40: =IFERROR(BV39/BQ39-1,"NA") -> -0.021473563 | BW40: =BW39/BR39-1 -> 0.043152182 | BX40: =BX39/BS39-1 -> 0.044599392 | BY40: =BY39/BT39-1 -> 0.094596314 | BZ40: =BZ39/BU39-1 -> 0.088083708 | CA40: =IFERROR(CA39/BV39-1,"NA") -> 0.068187484 | CB40: =CB39/BW39-1 -> 0.029687516 | CC40: =CC39/BX39-1 -> 0.031308058 | CD40: =CD39/BY39-1 -> 0.039646007 | CE40: =CE39/BZ39-1 -> 0.044115775 | CF40: =IFERROR(CF39/CA39-1,"NA") -> 0.036477532
B41: % revenue | L41: =L39/L$31 -> 0.49278394 | M41: =M39/M$31 -> 0.51273764 | N41: =N39/N$31 -> 0.50129688 | O41: =O39/O$31 -> 0.46985447 | P41: =P39/P$31 -> 0.43472 | Q41: =Q39/Q$31 -> 0.48188804 | R41: =R39/R$31 -> 0.51778446 | S41: =S39/S$31 -> 0.47501986 | ... AZ41: =AZ39/AZ$31 -> 0.41837838 | BA41: =BA39/BA31 -> 0.48564868 | BB41: =BB39/BB$31 -> 0.39401889 | BC41: =BC39/BC$31 -> 0.43530834 | BD41: =BD39/BD$31 -> 0.47308782 | BE41: =BE39/BE31 -> 0.58305085 | BF41: =BF39/BF31 -> 0.60243056 | BG41: =BG39/BG$31 -> 0.51315302 | BH41: =BH39/BH$31 -> 0.45839018 | BI41: =BI39/BI$31 -> 0.46854083 | BJ41: =BJ39/BJ$31 -> 0.5 | BK41: =BK39/BK$31 -> 0.51461988 | BL41: =BL39/BL$31 -> 0.48461538 | BM41: =BM39/BM$31 -> 0.37082067 | BN41: =BN39/BN$31 -> 0.3862069 | BO41: =BO39/BO$31 -> 0.42362525 | BP41: =BP39/BP31 -> 0.51668727 | BQ41: =BQ39/BQ$31 -> 0.41972054 | BR41: =BR39/BR31 -> 0.35586854 | BS41: =BS39/BS31 -> 0.37623762 | BT41: =BT39/BT31 -> 0.35862525 | BU41: =BU39/BU31 -> 0.45168727 | BV41: =BV39/BV$31 -> 0.38283008 | BW41: =BW39/BW31 -> 0.34086854 | BX41: =BX39/BX31 -> 0.36123762 | BY41: =BY39/BY31 -> 0.36612525 | BZ41: =BZ39/BZ31 -> 0.45918727 | CA41: =CA39/CA$31 -> 0.37860674 | CB41: =CB39/CB31 -> 0.32836854 | CC41: =CC39/CC31 -> 0.34873762 | CD41: =CD39/CD31 -> 0.35612525 | CE41: =CE39/CE31 -> 0.44918727 | CF41: =CF39/CF$31 -> 0.3672992
B42: bps y/y | Q42: =(Q41-L41)*10000 -> -108.95901 | R42: =(R41-M41)*10000 -> 50.468203 | S42: =(S41-N41)*10000 -> -262.77015 | T42: =(T41-O41)*10000 -> -23.133774 | U42: =(U41-P41)*10000 -> 142.78748 | V42: =(V41-Q41)*10000 -> 72.562816 | W42: =(W41-R41)*10000 -> 35.155738 | X42: =(X41-S41)*10000 -> 50.589673 | ... CF42: =(CF41-CA41)*10000 -> -113.07546
...

Sheet IS
N1: 14Y | S1: 15Y | T1: CQ1 | U1: CQ2 | V1: CQ3 | W1: CQ4 | X1: 16Y | Y1: CQ1 | Z1: CQ2 | AA1: CQ3 | AB1: CQ4 | AC1: 17Y | AD1: CQ1 | AE1: CQ2 | AF1: CQ3 | AG1: CQ4 | AH1: 18Y | AI1: CQ1 | AJ1: CQ2 | AK1: CQ3 | AL1: CQ4 | AM1: 19Y | AN1: CQ1 | AO1: CQ2 | AP1: CQ3 | AQ1: CQ4 | AR1: 20Y
B3: Moody's (MCO)
B4: Quarterly & Annual Earnings Model
B5: ($ in Millions, except per share data)
E6: 2013A | J6: 2014A | O6: 2015A | T6: 2016A | Y6: 2017A | AD6: 2018A | AI6: 2019A | AN6: 2020A | AS6: 2021A | AX6: 2022A | BC6: 2023A | BH6: 2024A | BM6: 2025E | BR6: 2026E | BW6: 2027E
E7: 1Q13A | F7: 2Q13A | G7: 3Q13A | H7: 4Q13A | I7: 2013A | J7: 1Q14A | K7: 2Q14A | L7: 3Q14A | M7: 4Q14A | N7: 2014A | O7: 1Q15A | P7: 2Q15A | Q7: 3Q15A | R7: 4Q15A | S7: 2015A | T7: 1Q16A | U7: 2Q16A | V7: 3Q16A | W7: 4Q16A | X7: 2016A | Y7: 1Q17A | Z7: 2Q17A | AA7: 3Q17A | AB7: 4Q17A | AC7: 2017A | AD7: 1Q18A | AE7: 2Q18A | AF7: 3Q18A | AG7: 4Q18A | AH7: 2018A | AI7: 1Q19A | AJ7: 2Q19A | AK7: 3Q19A | AL7: 4Q19A | AM7: 2019A | AN7: 1Q20A | AO7: 2Q20A | AP7: 3Q20A | AQ7: 4Q20A | AR7: 2020A | AS7: 1Q21A | AT7: 2Q21A | AU7: 3Q21A | AV7: 4Q21A | AW7: 2021A | AX7: 1Q22A | AY7: 2Q22A | AZ7: 3Q22A | BA7: 4Q22A | BB7: 2022A | BC7: 1Q23A | BD7: 2Q23A | BE7: 3Q23A | BF7: 4Q23A | BG7: 2023A | BH7: 1Q24A | BI7: 2Q24A | BJ7: 3Q24A | BK7: 4Q24A | BL7: 2024A | BM7: 1Q25A | BN7: 2Q25A | BO7: 3Q25E | BP7: 4Q25E | BQ7: 2025E | BR7: 1Q26E | BS7: 2Q26E | BT7: 3Q26E | BU7: 4Q26E | BV7: 2026E | BW7: 1Q27E | BX7: 2Q27E | BY7: 3Q27E | BZ7: 4Q27E | CA7: 2027E
B9: MOODY'S INVESTOR SERVICE (RATINGS) | E9: =Segments!J31 -> 521.25 | F9: =Segments!K31 -> 537.3 | G9: =Segments!L31 -> 478.1 | H9: =Segments!M31 -> 526 | I9: =Segments!N31 -> 2062.65 | J9: =Segments!O31 -> 529.1 | K9: =Segments!P31 -> 625 | L9: =Segments!Q31 -> 546.6 | ... CA9: =Segments!CF31 -> 4695.729
B10: =Segments!B32 -> Reported growth % y/y | E10: =Segments!J32 -> 0.15167919 | F10: =Segments!K32 -> 0.21753909 | G10: =Segments!L32 -> 0.010141559 | H10: =Segments!M32 -> 0.012901983 | I10: =Segments!N32 -> 0.093373973 | J10: =Segments!O32 -> 0.015059952 | K10: =Segments!P32 -> 0.16322353 | L10: =Segments!Q32 -> 0.14327547 | ... CA10: =Segments!CF32 -> 0.06838617
B11: =Segments!B37 -> Reported growth % sequential | O11: =Segments!T37 -> 0.065829057 | P11: =Segments!U37 -> 0.06126515 | Q11: =Segments!V37 -> -0.1425219 | R11: =Segments!W37 -> -0.006385696 | T11: =Segments!Y37 -> -0.035806096 | U11: =Segments!Z37 -> 0.19139212 | V11: =Segments!AA37 -> -0.021259591 | W11: =Segments!AB37 -> -0.0073493386 | Y11: =Segments!AD37 -> 0.099374794 | Z11: =Segments!AE37 -> 0.027686321 | AA11: =Segments!AF37 -> 0.0109218 | AB11: =Segments!AG37 -> 0.043935465 | AD11: =Segments!AI37 -> -0.0066234304 | AE11: =Segments!AJ37 -> 0.045006251 | AF11: =Segments!AK37 -> -0.14289512 | AG11: =Segments!AL37 -> -0.076612903 | AI11: =Segments!AN37 -> 0.12546187 | AJ11: =Segments!AO37 -> 0.10192509 | AK11: =Segments!AP37 -> 0.011105092 | AL11: =Segments!AQ37 -> -0.035628181 | AN11: =Segments!AS37 -> 0.10277778 | AO11: =Segments!AT37 -> 0.1813602 | AP11: =Segments!AU37 -> -0.12046908 | AQ11: =Segments!AV37 -> -0.10909091 | AS11: =Segments!AX37 -> 0.40952381 | AT11: =Segments!AY37 -> -0.054054054 | AU11: =Segments!AZ37 -> -0.056122449 | AV11: =Segments!BA37 -> -0.058378378 | AX11: =Segments!BC37 -> -0.050516648 | AY11: =Segments!BD37 -> -0.14631197 | AZ11: =Segments!BE37 -> -0.16430595 | BA11: =Segments!BF37 -> -0.023728814 | BC11: =Segments!BH37 -> 0.27256944 | BD11: =Segments!BI37 -> 0.019099591 | BE11: =Segments!BJ37 -> -0.068273092 | BF11: =Segments!BK37 -> -0.017241379 | BH11: =Segments!BM37 -> 0.44298246 | BI11: =Segments!BN37 -> 0.028368794 | BJ11: =Segments!BO37 -> -0.032512315 | BK11: =Segments!BP37 -> -0.17617108 | BM11: =Segments!BR37 -> 0.31644005 | BN11: =Segments!BS37 -> -0.051643192 | BO11: =Segments!BT37 -> 0.084584158 | BP11: =Segments!BU37 -> -0.17952311 | BR11: =Segments!BW37 -> 0.29047314 | BS11: =Segments!BX37 -> -0.052584613 | BT11: =Segments!BY37 -> 0.068831898 | BU11: =Segments!BZ37 -> -0.18094794 | BW11: =Segments!CB37 -> 0.28875237 | BX11: =Segments!CC37 -> -0.053125998 | BY11: =Segments!CD37 -> 0.069397652 | BZ11: =Segments!CE37 -> -0.18208126
B12: =Segments!B33 -> M&A impact % y/y | J12: =Segments!O33 -> 0 | K12: =Segments!P33 -> 0.02 | L12: =Segments!Q33 -> 0.02 | M12: =Segments!R33 -> 0.02 | O12: =Segments!T33 -> 0.02 | P12: =Segments!U33 -> 0 | Q12: =Segments!V33 -> 0 | R12: =Segments!W33 -> 0 | S12: =Segments!X33 -> 0.0046703151 | T12: =Segments!Y33 -> 0 | U12: =Segments!Z33 -> 0 | V12: =Segments!AA33 -> 0 | ... CA12: =Segments!CF33 -> 0
B13: =Segments!B34 -> Organic growth % y/y | J13: =Segments!O34 -> 0.015059952 | K13: =Segments!P34 -> 0.14322353 | L13: =Segments!Q34 -> 0.12327547 | M13: =Segments!R34 -> 0.054334601 | O13: =Segments!T34 -> 0.11834814 | P13: =Segments!U34 -> 0.02272 | Q13: =Segments!V34 -> 0.0027442371 | R13: =Segments!W34 -> -0.036276765 | S13: =Segments!X34 -> 0.025517698 | T13: =Segments!Y34 -> -0.12817533 | U13: =Segments!Z34 -> -0.021276596 | V13: =Segments!AA34 -> 0.11713191 | ... CA13: =Segments!CF34 -> 0.06838617
B14: =Segments!B35 -> FX impact % y/y | J14: =Segments!O35 -> 0 | K14: =Segments!P35 -> 0.01 | L14: =Segments!Q35 -> 0 | M14: =Segments!R35 -> -0.03 | O14: =Segments!T35 -> -0.05 | P14: =Segments!U35 -> -0.05 | Q14: =Segments!V35 -> -0.05 | R14: =Segments!W35 -> -0.04 | S14: =Segments!X35 -> -0.047505958 | T14: =Segments!Y35 -> -0.014 | U14: =Segments!Z35 -> 0 | V14: =Segments!AA35 -> 0 | ... CA14: =Segments!CF35 -> -0.00099011186
B15: =Segments!B36 -> MIS organic constant currency growth % y/y | J15: =Segments!O36 -> 0.015059952 | K15: =Segments!P36 -> 0.13322353 | L15: =Segments!Q36 -> 0.12327547 | M15: =Segments!R36 -> 0.084334601 | O15: =Segments!T36 -> 0.16834814 | P15: =Segments!U36 -> 0.07272 | Q15: =Segments!V36 -> 0.052744237 | R15: =Segments!W36 -> 0.0037232348 | S15: =Segments!X36 -> 0.073023656 | T15: =Segments!Y36 -> -0.11417533 | U15: =Segments!Z36 -> -0.021276596 | V15: =Segments!AA36 -> 0.11713191 | ... CA15: =Segments!CF36 -> 0.069376282
B17: MOODY'S ANALYTICS | E17: =Segments!J95 -> 207.4 | F17: =Segments!K95 -> 216 | G17: =Segments!L95 -> 227.4 | H17: =Segments!M95 -> 253.2 | I17: =Segments!N95 -> 904 | J17: =Segments!O95 -> 238.1 | K17: =Segments!P95 -> 248.5 | L17: =Segments!Q95 -> 269.5 | ... CA17: =Segments!CF95 -> 4250.6292
B18: =Segments!B96 -> Reported growth % y/y | E18: =Segments!J96 -> 0.068521381 | F18: =Segments!K96 -> 0.082164329 | G18: =Segments!L96 -> 0.057674419 | H18: =Segments!M96 -> 0.078364566 | I18: =Segments!N96 -> 0.071724956 | J18: =Segments!O96 -> 0.14802314 | K18: =Segments!P96 -> 0.15046296 | L18: =Segments!Q96 -> 0.18513632 | ... CA18: =Segments!CF96 -> 0.085021332
B19: =Segments!B41 -> % revenue | J19: =Segments!O101 -> -0.059636651 | K19: =Segments!P101 -> 0.043679126 | L19: =Segments!Q101 -> 0.084507042 | M19: =Segments!R101 -> 0.15918367 | O19: =Segments!T101 -> -0.15717029 | P19: =Segments!U101 -> 0.059248006 | Q19: =Segments!V101 -> 0.028325565 | R19: =Segments!W101 -> 0.12029289 | T19: =Segments!Y101 -> -0.094304388 | U19: =Segments!Z101 -> 0.042268041 | V19: =Segments!AA101 -> 0.0049455984 | W19: =Segments!AB101 -> 0.096784777 | Y19: =Segments!AD101 -> -0.081663177 | Z19: =Segments!AE101 -> 0.022149837 | AA19: =Segments!AF101 -> 0.1749522 | AB19: =Segments!AG101 -> 0.19555194 | AD19: =Segments!AI101 -> -0.077132486 | AE19: =Segments!AJ101 -> 0.039331367 | AF19: =Segments!AK101 -> 0.031220435 | AG19: =Segments!AL101 -> 0.065825688 | AI19: =Segments!AN101 -> 0.01570906 | AJ19: =Segments!AO101 -> 0.006779661 | AK19: =Segments!AP101 -> 0.039351852 | AL19: =Segments!AQ101 -> 0.038671796 | AN19: =Segments!AS101 -> -0.033138402 | AO19: =Segments!AT101 -> 0.002016129 | AP19: =Segments!AU101 -> 0.068410463 | AQ19: =Segments!AV101 -> 0.04519774 | AS19: =Segments!AX101 -> 0.016216216 | AT19: =Segments!AY101 -> -0.72438672 | AU19: =Segments!AZ101 -> 0.04886562 | AV19: =Segments!BA101 -> 0.11148087 | AX19: =Segments!BC101 -> 0.040419162 | AY19: =Segments!BD101 -> -0.028776978 | AZ19: =Segments!BE101 -> 0.014814815 | BA19: =Segments!BF101 -> 0.042335766 | BC19: =Segments!BH101 -> 0.032212885 | BD19: =Segments!BI101 -> 0.013568521 | BE19: =Segments!BJ101 -> 0.038821954 | BF19: =Segments!BK101 -> 0.025773196 | BH19: =Segments!BM101 -> 0.0037688442 | BI19: =Segments!BN101 -> 0.0037546934 | BJ19: =Segments!BO101 -> 0.036159601 | BK19: =Segments!BP101 -> 0.038507822 | BM19: =Segments!BR101 -> -0.0046349942 | BN19: =Segments!BS101 -> 0.033760186 | BO19: =Segments!BT101 -> 0.023648649 | BP19: =Segments!BU101 -> 0.044513827 | BR19: =Segments!BW101 -> -0.0023252049 | BS19: =Segments!BX101 -> 0.010229794 | BT19: =Segments!BY101 -> 0.027147608 | BU19: =Segments!BZ101 -> 0.048329071 | BW19: =Segments!CB101 -> -0.0025439401 | BX19: =Segments!CC101 -> 0.010057253 | BY19: =Segments!CD101 -> 0.027297871 | BZ19: =Segments!CE101 -> 0.048489086
B20: =Segments!B97 -> M&A impact % y/y | J20: =Segments!O97 -> 0.05 | K20: =Segments!P97 -> 0.05 | L20: =Segments!Q97 -> 0.07 | M20: =Segments!R97 -> 0.055 | O20: =Segments!T97 -> 0.044 | P20: =Segments!U97 -> 0.05 | Q20: =Segments!V97 -> 0.015951763 | R20: =Segments!W97 -> 0 | S20: =Segments!X97 -> 0.025456621 | T20: =Segments!Y97 -> 0.0225 | U20: =Segments!Z97 -> 0.03 | V20: =Segments!AA97 -> 0.03 | ... CA20: =Segments!CF97 -> 0
B21: =Segments!B98 -> Organic growth % y/y | J21: =Segments!O98 -> 0.098023144 | K21: =Segments!P98 -> 0.10046296 | L21: =Segments!Q98 -> 0.11513632 | M21: =Segments!R98 -> 0.17880727 | O21: =Segments!T98 -> 0.061837883 | P21: =Segments!U98 -> 0.072334004 | Q21: =Segments!V98 -> 0.048241187 | R21: =Segments!W98 -> 0.028489117 | S21: =Segments!X98 -> 0.051099298 | T21: =Segments!Y98 -> 0.08270319 | U21: =Segments!Z98 -> 0.057486554 | V21: =Segments!AA98 -> 0.032761506 | ... CA21: =Segments!CF98 -> 0.085021332
B22: =Segments!B99 -> FX impact % y/y | J22: =Segments!O99 -> 0 | K22: =Segments!P99 -> 0.03 | L22: =Segments!Q99 -> 0.02 | M22: =Segments!R99 -> -0.03 | O22: =Segments!T99 -> -0.05 | P22: =Segments!U99 -> -0.06 | Q22: =Segments!V99 -> -0.05 | R22: =Segments!W99 -> -0.03 | S22: =Segments!X99 -> -0.046478241 | T22: =Segments!Y99 -> -0.02 | U22: =Segments!Z99 -> -0.01 | V22: =Segments!AA99 -> -0.03 | ... CA22: =Segments!CF99 -> -0.00045167309
B23: =Segments!B100 -> MA organic constant currency growth % y/y | J23: =Segments!O100 -> 0.098023144 | K23: =Segments!P100 -> 0.070462963 | L23: =Segments!Q100 -> 0.095136324 | M23: =Segments!R100 -> 0.20880727 | O23: =Segments!T100 -> 0.11183788 | P23: =Segments!U100 -> 0.132334 | Q23: =Segments!V100 -> 0.098241187 | R23: =Segments!W100 -> 0.058489117 | S23: =Segments!X100 -> 0.097577539 | T23: =Segments!Y100 -> 0.10270319 | U23: =Segments!Z100 -> 0.067486554 | V23: =Segments!AA100 -> 0.062761506 | ... CA23: =Segments!CF100 -> 0.085473005
B25: TOTAL revenue | E25: =E17+E9 -> 728.65 | F25: =F17+F9 -> 753.3 | G25: =G17+G9 -> 705.5 | H25: =H17+H9 -> 779.2 | I25: =I17+I9 -> 2966.65 | J25: =J17+J9 -> 767.2 | K25: =K17+K9 -> 873.5 | L25: =L17+L9 -> 816.1 | ... CA25: =CA17+CA9 -> 8946.3582
B26: Reported growth % y/y | I26: =Segments!N151 -> 0.089 | J26: =Segments!O151 -> 0.052906059 | K26: =Segments!P151 -> 0.15956458 | L26: =Segments!Q151 -> 0.15676825 | M26: =Segments!R151 -> 0.12615503 | N26: =Segments!S151 -> 0.12392766 | O26: =Segments!T151 -> 0.1282586 | P26: =Segments!U151 -> 0.051058958 | ... CA26: =Segments!CF151 -> 0.076225864
